1128=99=18135=X49=SAMPLE75=2017010134=28252=2017010106413864880044660=201701010641386488004465799=10000100268=1279=1269=148=17359555=6SZ683=354966270=10222.0271=3346=11023=1010=140
1128=99=18235=X49=SAMPLE75=2017010134=166052=2017010101402632398363260=201701010140263239836325799=10000100268=1279=1269=048=17359555=6SZ683=354967270=10202.0271=22346=81023=1010=179
1128=99=18035=X49=SAMPLE75=2017010134=369652=2017010110445780858652660=201701011044578085865265799=10000100268=1279=1269=048=17359555=6SZ683=354968270=10204.0271=4346=21023=810=086
1128=99=18135=X49=SAMPLE75=2017010134=91552=2017010107484475078326160=201701010748447507832615799=10000100268=1279=1269=048=17359555=6SZ683=354969270=10205.0271=51346=81023=710=146
1128=99=18235=X49=SAMPLE75=2017010134=442952=2017010105161568621481960=201701010516156862148195799=10000100268=1279=1269=148=17359555=6SZ683=354970270=10222.0271=33346=21023=1010=204
1128=99=18235=X49=SAMPLE75=2017010134=151652=2017010103032008431558660=201701010303200843155865799=10000100268=1279=1269=048=17359555=6SZ683=354971270=10202.0271=52346=91023=1010=216
1128=99=18135=X49=SAMPLE75=2017010134=329052=2017010101290843057203960=201701010129084305720395799=10000100268=1279=1269=148=17359555=6SZ683=354972270=10222.0271=3346=11023=1010=140
1128=99=18235=X49=SAMPLE75=2017010134=193552=2017010114055047116160360=201701011405504711616035799=10000100268=1279=1269=148=17359555=6SZ683=354973270=10222.0271=33346=21023=1010=180
1128=99=18135=X49=SAMPLE75=2017010134=149152=2017010104573343602798460=201701010457334360279845799=10000100268=1279=1269=148=17359555=6SZ683=354974270=10222.0271=3346=11023=1010=118
1128=99=18135=X49=SAMPLE75=2017010134=77152=2017010112283896561822860=201701011228389656182285799=10000100268=1279=1269=048=17359555=6SZ683=354975270=10205.0271=21346=71023=710=132
1128=99=18235=X49=SAMPLE75=2017010134=145952=2017010100551905720737960=201701010055190572073795799=10000100268=1279=1269=148=17359555=6SZ683=354976270=10222.0271=33346=21023=1010=174
1128=99=18135=X49=SAMPLE75=2017010134=29852=2017010100290074033835360=201701010029007403383535799=10000100268=1279=1269=048=17359555=6SZ683=354977270=10204.0271=34346=31023=810=136
1128=99=18135=X49=SAMPLE75=2017010134=345652=2017010107541504103413860=201701010754150410341385799=10000100268=1279=1269=148=17359555=6SZ683=354978270=10221.0271=51346=71023=910=151
1128=99=18135=X49=SAMPLE75=2017010134=375352=2017010106321734237287360=201701010632173423728735799=10000100268=1279=1269=048=17359555=6SZ683=354979270=10205.0271=51346=81023=710=165
1128=99=18135=X49=SAMPLE75=2017010134=316652=2017010114332806860001660=201701011433280686000165799=10000100268=1279=1269=148=17359555=6SZ683=354980270=10222.0271=3346=11023=1010=139
1128=99=18035=X49=SAMPLE75=2017010134=453752=2017010113521345919764160=201701011352134591976415799=10000100268=1279=1269=048=17359555=6SZ683=354981270=10204.0271=4346=21023=810=097
1128=99=18135=X49=SAMPLE75=2017010134=105252=2017010110000338391254260=201701011000033839125425799=10000100268=1279=1269=148=17359555=6SZ683=354982270=10221.0271=21346=61023=910=146
1128=99=18135=X49=SAMPLE75=2017010134=395252=2017010112424417815267260=201701011242441781526725799=10000100268=1279=1269=148=17359555=6SZ683=354983270=10221.0271=51346=71023=910=132
1128=99=18135=X49=SAMPLE75=2017010134=454152=2017010110573631384799760=201701011057363138479975799=10000100268=1279=1269=148=17359555=6SZ683=354984270=10221.0271=21346=61023=910=156
1128=99=18135=X49=SAMPLE75=2017010134=201352=2017010110143291637242460=201701011014329163724245799=10000100268=1279=1269=148=17359555=6SZ683=354985270=10221.0271=51346=71023=910=163
1128=99=18135=X49=SAMPLE75=2017010134=462652=2017010104020249176257060=201701010402024917625705799=10000100268=1279=1269=148=17359555=6SZ683=354986270=10221.0271=21346=61023=910=158
1128=99=18135=X49=SAMPLE75=2017010134=196052=2017010102271129584478560=201701010227112958447855799=10000100268=1279=1269=048=17359555=6SZ683=354987270=10205.0271=21346=71023=710=161
1128=99=18135=X49=SAMPLE75=2017010134=353352=2017010108504466959362660=201701010850446695936265799=10000100268=1279=1269=048=17359555=6SZ683=354988270=10204.0271=34346=31023=810=152
1128=99=18235=X49=SAMPLE75=2017010134=96252=2017010111083306859746060=201701011108330685974605799=10000100268=1279=1269=148=17359555=6SZ683=354989270=10222.0271=33346=21023=1010=169
1128=99=18135=X49=SAMPLE75=2017010134=490552=2017010104394761577412260=201701010439476157741225799=10000100268=1279=1269=048=17359555=6SZ683=354990270=10205.0271=51346=81023=710=140
1128=99=18035=X49=SAMPLE75=2017010134=33552=2017010111471115808407760=201701011147111580840775799=10000100268=1279=1269=048=17359555=6SZ683=354991270=10204.0271=4346=21023=810=081
1128=99=18135=X49=SAMPLE75=2017010134=288352=2017010108381881940356560=201701010838188194035655799=10000100268=1279=1269=148=17359555=6SZ683=354992270=10222.0271=3346=11023=1010=141
1128=99=18135=X49=SAMPLE75=2017010134=287052=2017010102034633551631560=201701010203463355163155799=10000100268=1279=1269=148=17359555=6SZ683=354993270=10221.0271=51346=71023=910=147
1128=99=18135=X49=SAMPLE75=2017010134=202252=2017010111522113530494860=201701011152211353049485799=10000100268=1279=1269=148=17359555=6SZ683=354994270=10221.0271=21346=61023=910=138
1128=99=18135=X49=SAMPLE75=2017010134=295752=2017010111354178584607860=201701011135417858460785799=10000100268=1279=1269=148=17359555=6SZ683=354995270=10221.0271=51346=71023=910=152
1128=99=18135=X49=SAMPLE75=2017010134=218652=2017010109140466402680360=201701010914046640268035799=10000100268=1279=1269=148=17359555=6SZ683=354996270=10221.0271=21346=61023=910=141
1128=99=18135=X49=SAMPLE75=2017010134=429652=2017010113513006044532660=201701011351300604453265799=10000100268=1279=1269=148=17359555=6SZ683=354997270=10221.0271=51346=71023=910=162
1128=99=18135=X49=SAMPLE75=2017010134=76452=2017010109474247735894860=201701010947424773589485799=10000100268=1279=1269=148=17359555=6SZ683=354998270=10221.0271=21346=61023=910=171
1128=99=18135=X49=SAMPLE75=2017010134=385552=2017010107580688856339360=201701010758068885633935799=10000100268=1279=1269=148=17359555=6SZ683=354999270=10221.0271=51346=71023=910=168
1128=99=18135=X49=SAMPLE75=2017010134=369752=2017010113110499741608360=201701011311049974160835799=10000100268=1279=1269=148=17359555=6SZ683=355000270=10221.0271=21346=61023=910=149
1128=99=18135=X49=SAMPLE75=2017010134=183752=2017010113164986379432160=201701011316498637943215799=10000100268=1279=1269=148=17359555=6SZ683=355001270=10221.0271=51346=71023=910=117
1128=99=18135=X49=SAMPLE75=2017010134=348652=2017010108525841990377860=201701010852584199037785799=10000100268=1279=1269=148=17359555=6SZ683=355002270=10221.0271=21346=61023=910=149
1128=99=18135=X49=SAMPLE75=2017010134=310152=2017010109574403942142960=201701010957440394214295799=10000100268=1279=1269=148=17359555=6SZ683=355003270=10221.0271=51346=71023=910=150
1128=99=18135=X49=SAMPLE75=2017010134=377952=2017010109313956143590560=201701010931395614359055799=10000100268=1279=1269=048=17359555=6SZ683=355004270=10205.0271=21346=71023=710=129
1128=99=18135=X49=SAMPLE75=2017010134=143652=2017010100142992861556060=201701010014299286155605799=10000100268=1279=1269=148=17359555=6SZ683=355005270=10221.0271=21346=61023=910=120
1128=99=18135=X49=SAMPLE75=2017010134=413452=2017010103384712520179060=201701010338471252017905799=10000100268=1279=1269=048=17359555=6SZ683=355006270=10205.0271=51346=81023=710=143
1128=99=18135=X49=SAMPLE75=2017010134=71952=2017010114072251370964960=201701011407225137096495799=10000100268=1279=1269=148=17359555=6SZ683=355007270=10221.0271=51346=71023=910=148
1128=99=18135=X49=SAMPLE75=2017010134=271952=2017010102485225737790160=201701010248522573779015799=10000100268=1279=1269=148=17359555=6SZ683=355008270=10221.0271=21346=61023=910=163
1128=99=18135=X49=SAMPLE75=2017010134=292952=2017010112484024231580060=201701011248402423158005799=10000100268=1279=1269=048=17359555=6SZ683=355009270=10205.0271=21346=71023=710=149
1128=99=18135=X49=SAMPLE75=2017010134=369752=2017010108321446234179260=201701010832144623417925799=10000100268=1279=1269=148=17359555=6SZ683=355010270=10221.0271=51346=71023=910=153
1128=99=18135=X49=SAMPLE75=2017010134=188152=2017010106272051212837760=201701010627205121283775799=10000100268=1279=1269=048=17359555=6SZ683=355011270=10205.0271=51346=81023=710=184
1128=99=18135=X49=SAMPLE75=2017010134=325852=2017010100595830127972560=201701010059583012797255799=10000100268=1279=1269=148=17359555=6SZ683=355012270=10221.0271=21346=61023=910=144
1128=99=18135=X49=SAMPLE75=2017010134=16352=2017010105013522030476160=201701010501352203047615799=10000100268=1279=1269=048=17359555=6SZ683=355013270=10205.0271=21346=71023=710=134
1128=99=18135=X49=SAMPLE75=2017010134=352952=2017010111371310020364160=201701011137131002036415799=10000100268=1279=1269=148=17359555=6SZ683=355014270=10221.0271=51346=71023=910=140
1128=99=18135=X49=SAMPLE75=2017010134=302952=2017010103543709145103460=201701010354370914510345799=10000100268=1279=1269=048=17359555=6SZ683=355015270=10205.0271=51346=81023=710=124
1128=99=18135=X49=SAMPLE75=2017010134=168452=2017010110351577558367760=201701011035157755836775799=10000100268=1279=1269=148=17359555=6SZ683=355016270=10221.0271=21346=61023=910=139
1128=99=18135=X49=SAMPLE75=2017010134=7052=2017010102594316541195860=201701010259431654119585799=10000100268=1279=1269=148=17359555=6SZ683=355017270=10221.0271=51346=71023=910=175
1128=99=18135=X49=SAMPLE75=2017010134=417952=2017010107245168035324660=201701010724516803532465799=10000100268=1279=1269=148=17359555=6SZ683=355018270=10221.0271=21346=61023=910=140
1128=99=18135=X49=SAMPLE75=2017010134=224252=2017010101403723737841860=201701010140372373784185799=10000100268=1279=1269=048=17359555=6SZ683=355019270=10205.0271=21346=71023=710=141
1128=99=18135=X49=SAMPLE75=2017010134=334352=2017010104375646641904560=201701010437564664190455799=10000100268=1279=1269=148=17359555=6SZ683=355020270=10221.0271=51346=71023=910=140
1128=99=18135=X49=SAMPLE75=2017010134=446552=2017010108063053046948660=201701010806305304694865799=10000100268=1279=1269=048=17359555=6SZ683=355021270=10205.0271=51346=81023=710=149
1128=99=18135=X49=SAMPLE75=2017010134=83052=2017010109015472370886760=201701010901547237088675799=10000100268=1279=1269=148=17359555=6SZ683=355022270=10221.0271=21346=61023=910=182
1128=99=18135=X49=SAMPLE75=2017010134=11052=2017010101432232829694860=201701010143223282969485799=10000100268=1279=1269=148=17359555=6SZ683=355023270=10221.0271=51346=71023=910=167
1128=99=18135=X49=SAMPLE75=2017010134=60052=2017010104533198112961260=201701010453319811296125799=10000100268=1279=1269=148=17359555=6SZ683=355024270=10221.0271=21346=61023=910=147
1128=99=18135=X49=SAMPLE75=2017010134=217952=2017010112322994158036660=201701011232299415803665799=10000100268=1279=1269=148=17359555=6SZ683=355025270=10221.0271=51346=71023=910=152
1128=99=18135=X49=SAMPLE75=2017010134=38652=2017010100100173986893160=201701010010017398689315799=10000100268=1279=1269=148=17359555=6SZ683=355026270=10221.0271=21346=61023=910=167
1128=99=18135=X49=SAMPLE75=2017010134=410652=2017010111291899115902560=201701011129189911590255799=10000100268=1279=1269=148=17359555=6SZ683=355027270=10221.0271=51346=71023=910=170
1128=99=18135=X49=SAMPLE75=2017010134=300752=2017010108125251361212560=201701010812525136121255799=10000100268=1279=1269=148=17359555=6SZ683=355028270=10221.0271=21346=61023=910=159
1128=99=18135=X49=SAMPLE75=2017010134=454252=2017010105370281660799160=201701010537028166079915799=10000100268=1279=1269=148=17359555=6SZ683=355029270=10221.0271=51346=71023=910=151
1128=99=18135=X49=SAMPLE75=2017010134=487952=2017010112265917314612660=201701011226591731461265799=10000100268=1279=1269=148=17359555=6SZ683=355030270=10221.0271=21346=61023=910=146
1128=99=18135=X49=SAMPLE75=2017010134=329252=2017010111420570278517760=201701011142057027851775799=10000100268=1279=1269=148=17359555=6SZ683=355031270=10221.0271=51346=71023=910=160
1128=99=18135=X49=SAMPLE75=2017010134=183052=2017010108431689692225660=201701010843168969222565799=10000100268=1279=1269=148=17359555=6SZ683=355032270=10221.0271=21346=61023=910=140
1128=99=18135=X49=SAMPLE75=2017010134=472852=2017010112120526487777560=201701011212052648777755799=10000100268=1279=1269=148=17359555=6SZ683=355033270=10221.0271=51346=71023=910=169
1128=99=18135=X49=SAMPLE75=2017010134=456852=2017010111474047036756360=201701011147404703675635799=10000100268=1279=1269=048=17359555=6SZ683=355034270=10205.0271=21346=71023=710=147
1128=99=18135=X49=SAMPLE75=2017010134=429452=2017010109130473646641060=201701010913047364664105799=10000100268=1279=1269=148=17359555=6SZ683=355035270=10221.0271=21346=61023=910=139
1128=99=18135=X49=SAMPLE75=2017010134=85552=2017010106005427535847360=201701010600542753584735799=10000100268=1279=1269=048=17359555=6SZ683=355036270=10205.0271=51346=81023=710=144
1128=99=18135=X49=SAMPLE75=2017010134=330052=2017010106593389597417660=201701010659338959741765799=10000100268=1279=1269=148=17359555=6SZ683=355037270=10221.0271=51346=71023=910=142
1128=99=18035=X49=SAMPLE75=2017010134=429852=2017010113082983389101760=201701011308298338910175799=10000100268=1279=1269=048=17359555=6SZ683=355038270=10206.0271=4346=21023=610=074
1128=99=18135=X49=SAMPLE75=2017010134=97452=2017010110315584369560260=201701011031558436956025799=10000100268=1279=1269=048=17359555=6SZ683=355039270=10207.0271=45346=81023=510=149
1128=99=18135=X49=SAMPLE75=2017010134=119152=2017010105465936728399460=201701010546593672839945799=10000100268=1279=1269=148=17359555=6SZ683=355040270=10221.0271=21346=61023=910=125
1128=99=18135=X49=SAMPLE75=2017010134=427152=2017010105272092264445360=201701010527209226444535799=10000100268=1279=1269=148=17359555=6SZ683=355041270=10221.0271=51346=71023=910=161
1128=99=18135=X49=SAMPLE75=2017010134=194352=2017010110571338403524660=201701011057133840352465799=10000100268=1279=1269=148=17359555=6SZ683=355042270=10221.0271=21346=61023=910=163
1128=99=18135=X49=SAMPLE75=2017010134=492252=2017010106263595227866860=201701010626359522786685799=10000100268=1279=1269=148=17359555=6SZ683=355043270=10221.0271=51346=71023=910=150
1128=99=18135=X49=SAMPLE75=2017010134=94852=2017010102245917501786560=201701010224591750178655799=10000100268=1279=1269=148=17359555=6SZ683=355044270=10221.0271=21346=61023=910=156
1128=99=18135=X49=SAMPLE75=2017010134=386952=2017010101453808652013860=201701010145380865201385799=10000100268=1279=1269=148=17359555=6SZ683=355045270=10221.0271=51346=71023=910=162
1128=99=18135=X49=SAMPLE75=2017010134=89452=2017010106422282733877360=201701010642228273387735799=10000100268=1279=1269=148=17359555=6SZ683=355046270=10221.0271=21346=61023=910=148
1128=99=18135=X49=SAMPLE75=2017010134=378152=2017010111073654970337260=201701011107365497033725799=10000100268=1279=1269=148=17359555=6SZ683=355047270=10221.0271=51346=71023=910=160
1128=99=18135=X49=SAMPLE75=2017010134=493252=2017010113463946245834860=201701011346394624583485799=10000100268=1279=1269=148=17359555=6SZ683=355048270=10221.0271=21346=61023=910=175
1128=99=18135=X49=SAMPLE75=2017010134=441752=2017010104575866294053260=201701010457586629405325799=10000100268=1279=1269=148=17359555=6SZ683=355049270=10221.0271=51346=71023=910=193
1128=99=18135=X49=SAMPLE75=2017010134=31552=2017010111134284905992960=201701011113428490599295799=10000100268=1279=1269=148=17359555=6SZ683=355050270=10221.0271=21346=61023=910=167
1128=99=18135=X49=SAMPLE75=2017010134=23152=2017010114170646718052260=201701011417064671805225799=10000100268=1279=1269=148=17359555=6SZ683=355051270=10221.0271=51346=71023=910=184
1128=99=18135=X49=SAMPLE75=2017010134=218752=2017010109422728998817960=201701010942272899881795799=10000100268=1279=1269=148=17359555=6SZ683=355052270=10221.0271=21346=61023=910=131
1128=99=18135=X49=SAMPLE75=2017010134=273352=2017010112473326426156760=201701011247332642615675799=10000100268=1279=1269=148=17359555=6SZ683=355053270=10221.0271=51346=71023=910=149
1128=99=18135=X49=SAMPLE75=2017010134=266052=2017010106370371475426260=201701010637037147542625799=10000100268=1279=1269=148=17359555=6SZ683=355054270=10221.0271=21346=61023=910=160
1128=99=18135=X49=SAMPLE75=2017010134=281452=2017010108162996668148560=201701010816299666814855799=10000100268=1279=1269=148=17359555=6SZ683=355055270=10221.0271=51346=71023=910=164
1128=99=18135=X49=SAMPLE75=2017010134=373252=2017010103031498825961260=201701010303149882596125799=10000100268=1279=1269=148=17359555=6SZ683=355056270=10221.0271=21346=61023=910=165
1128=99=18135=X49=SAMPLE75=2017010134=344652=2017010111240916246223860=201701011124091624622385799=10000100268=1279=1269=148=17359555=6SZ683=355057270=10221.0271=51346=71023=910=176
1128=99=18135=X49=SAMPLE75=2017010134=271052=2017010111331550908818960=201701011133155090881895799=10000100268=1279=1269=148=17359555=6SZ683=355058270=10221.0271=21346=61023=910=170
1128=99=18135=X49=SAMPLE75=2017010134=272052=2017010100274489115414160=201701010027448911541415799=10000100268=1279=1269=148=17359555=6SZ683=355059270=10221.0271=51346=71023=910=156
1128=99=18135=X49=SAMPLE75=2017010134=359152=2017010111272263557665660=201701011127226355766565799=10000100268=1279=1269=148=17359555=6SZ683=355060270=10221.0271=21346=61023=910=170
1128=99=18135=X49=SAMPLE75=2017010134=76252=2017010113264557730114060=201701011326455773011405799=10000100268=1279=1269=148=17359555=6SZ683=355061270=10221.0271=51346=71023=910=177
1128=99=18135=X49=SAMPLE75=2017010134=264652=2017010106475498330623360=201701010647549833062335799=10000100268=1279=1269=148=17359555=6SZ683=355062270=10221.0271=21346=61023=910=130
1128=99=18135=X49=SAMPLE75=2017010134=272052=2017010102372868794035160=201701010237286879403515799=10000100268=1279=1269=148=17359555=6SZ683=355063270=10221.0271=51346=71023=910=153
1128=99=18135=X49=SAMPLE75=2017010134=336552=2017010102191831913719960=201701010219183191371995799=10000100268=1279=1269=148=17359555=6SZ683=355064270=10221.0271=21346=61023=910=155
1128=99=18135=X49=SAMPLE75=2017010134=95652=2017010106061485112187060=201701010606148511218705799=10000100268=1279=1269=148=17359555=6SZ683=355065270=10221.0271=51346=71023=910=166
1128=99=18135=X49=SAMPLE75=2017010134=71652=2017010109154893852878060=201701010915489385287805799=10000100268=1279=1269=148=17359555=6SZ683=355066270=10221.0271=21346=61023=910=170
1128=99=18135=X49=SAMPLE75=2017010134=299252=2017010109205146292426560=201701010920514629242655799=10000100268=1279=1269=148=17359555=6SZ683=355067270=10221.0271=51346=71023=910=153
1128=99=18135=X49=SAMPLE75=2017010134=390652=2017010104300960671959660=201701010430096067195965799=10000100268=1279=1269=148=17359555=6SZ683=355068270=10221.0271=21346=61023=910=158
1128=99=18135=X49=SAMPLE75=2017010134=340852=2017010103331233606032160=201701010333123360603215799=10000100268=1279=1269=148=17359555=6SZ683=355069270=10221.0271=51346=71023=910=168
1128=99=18135=X49=SAMPLE75=2017010134=351852=2017010110174993886804660=201701011017499388680465799=10000100268=1279=1269=148=17359555=6SZ683=355070270=10221.0271=21346=61023=910=170
1128=99=18135=X49=SAMPLE75=2017010134=115452=2017010113572281963907360=201701011357228196390735799=10000100268=1279=1269=148=17359555=6SZ683=355071270=10221.0271=51346=71023=910=184
1128=99=18135=X49=SAMPLE75=2017010134=74152=2017010104505012782048160=201701010450501278204815799=10000100268=1279=1269=148=17359555=6SZ683=355072270=10221.0271=21346=61023=910=166
1128=99=18235=X49=SAMPLE75=2017010134=315152=2017010114001526338197160=201701011400152633819715799=10000100268=1279=1269=148=17359555=6SZ683=355073270=10222.0271=33346=21023=1010=221
1128=99=18135=X49=SAMPLE75=2017010134=413652=2017010111312014519161860=201701011131201451916185799=10000100268=1279=1269=148=17359555=6SZ683=355074270=10222.0271=3346=11023=1010=164
1128=99=18235=X49=SAMPLE75=2017010134=382452=2017010112075690955776560=201701011207569095577655799=10000100268=1279=1269=148=17359555=6SZ683=355075270=10222.0271=33346=21023=1010=194
1128=99=18135=X49=SAMPLE75=2017010134=180452=2017010102180412545896760=201701010218041254589675799=10000100268=1279=1269=148=17359555=6SZ683=355076270=10222.0271=3346=11023=1010=167
1128=99=18135=X49=SAMPLE75=2017010134=262752=2017010112443149105086660=201701011244314910508665799=10000100268=1279=1269=148=17359555=6SZ683=355077270=10221.0271=51346=71023=910=151
1128=99=18135=X49=SAMPLE75=2017010134=39352=2017010104293945018613060=201701010429394501861305799=10000100268=1279=1269=148=17359555=6SZ683=355078270=10221.0271=21346=61023=910=165
1128=99=18235=X49=SAMPLE75=2017010134=373452=2017010103594791124339360=201701010359479112433935799=10000100268=1279=1269=148=17359555=6SZ683=355079270=10222.0271=33346=21023=1010=219
1128=99=18135=X49=SAMPLE75=2017010134=390152=2017010103351997115653360=201701010335199711565335799=10000100268=1279=1269=048=17359555=6SZ683=355080270=10206.0271=34346=31023=610=182
1128=99=18135=X49=SAMPLE75=2017010134=292552=2017010105565557947745460=201701010556555794774545799=10000100268=1279=1269=048=17359555=6SZ683=355081270=10205.0271=21346=71023=710=167
1128=99=18135=X49=SAMPLE75=2017010134=13952=2017010102522384848912760=201701010252238484891275799=10000100268=1279=1269=148=17359555=6SZ683=355082270=10221.0271=51346=71023=910=169
1128=99=18135=X49=SAMPLE75=2017010134=169452=2017010113113999357934460=201701011311399935793445799=10000100268=1279=1269=148=17359555=6SZ683=355083270=10222.0271=3346=11023=1010=166
1128=99=18135=X49=SAMPLE75=2017010134=288752=2017010109474582296679760=201701010947458229667975799=10000100268=1279=1269=148=17359555=6SZ683=355084270=10221.0271=21346=61023=910=161
1128=99=18235=X49=SAMPLE75=2017010134=158352=2017010114212581099393460=201701011421258109939345799=10000100268=1279=1269=148=17359555=6SZ683=355085270=10222.0271=33346=21023=1010=201
1128=99=18135=X49=SAMPLE75=2017010134=109152=2017010105581339144073360=201701010558133914407335799=10000100268=1279=1269=148=17359555=6SZ683=355086270=10222.0271=3346=11023=1010=166
1128=99=18135=X49=SAMPLE75=2017010134=404352=2017010110223824243133060=201701011022382424313305799=10000100268=1279=1269=148=17359555=6SZ683=355087270=10221.0271=51346=71023=910=196
1128=99=18035=X49=SAMPLE75=2017010134=200152=2017010100224540747118560=201701010022454074711855799=10000100268=1279=1269=048=17359555=6SZ683=355088270=10206.0271=4346=21023=610=103
1128=99=18135=X49=SAMPLE75=2017010134=92552=2017010103560847181387660=201701010356084718138765799=10000100268=1279=1269=148=17359555=6SZ683=355089270=10221.0271=21346=61023=910=166
1128=99=18135=X49=SAMPLE75=2017010134=46152=2017010110014486407826160=201701011001448640782615799=10000100268=1279=1269=048=17359555=6SZ683=355090270=10206.0271=34346=31023=610=161
1128=99=18135=X49=SAMPLE75=2017010134=1852=2017010108332931954603260=201701010833293195460325799=10000100268=1279=1269=148=17359555=6SZ683=355091270=10221.0271=51346=71023=910=174
1128=99=18135=X49=SAMPLE75=2017010134=476952=2017010105475828394876960=201701010547582839487695799=10000100268=1279=1269=148=17359555=6SZ683=355092270=10221.0271=21346=61023=910=140
1128=99=18135=X49=SAMPLE75=2017010134=310352=2017010111030842128941060=201701011103084212894105799=10000100268=1279=1269=148=17359555=6SZ683=355093270=10221.0271=51346=71023=910=143
1128=99=18135=X49=SAMPLE75=2017010134=143252=2017010100413306115269660=201701010041330611526965799=10000100268=1279=1269=148=17359555=6SZ683=355094270=10221.0271=21346=61023=910=159
1128=99=18035=X49=SAMPLE75=2017010134=58152=2017010113495692084614960=201701011349569208461495799=10000100268=1279=1269=048=17359555=6SZ683=355095270=10206.0271=4346=21023=610=122
1128=99=18135=X49=SAMPLE75=2017010134=245752=2017010103253071561200860=201701010325307156120085799=10000100268=1279=1269=148=17359555=6SZ683=355096270=10221.0271=51346=71023=910=181
1128=99=18135=X49=SAMPLE75=2017010134=479152=2017010110031939488066260=201701011003193948806625799=10000100268=1279=1269=048=17359555=6SZ683=355097270=10206.0271=34346=31023=610=164
1128=99=18135=X49=SAMPLE75=2017010134=86652=2017010108051793243965760=201701010805179324396575799=10000100268=1279=1269=148=17359555=6SZ683=355098270=10221.0271=21346=61023=910=149
1128=99=18035=X49=SAMPLE75=2017010134=272352=2017010101010795969549060=201701010101079596954905799=10000100268=1279=1269=048=17359555=6SZ683=355099270=10206.0271=4346=21023=610=114
1128=99=18135=X49=SAMPLE75=2017010134=38852=2017010101035712997625760=201701010103571299762575799=10000100268=1279=1269=148=17359555=6SZ683=355100270=10221.0271=51346=71023=910=135
1128=99=18135=X49=SAMPLE75=2017010134=424352=2017010112582744609529660=201701011258274460952965799=10000100268=1279=1269=048=17359555=6SZ683=355101270=10206.0271=34346=31023=610=149
1128=99=18035=X49=SAMPLE75=2017010134=490552=2017010103370942702668960=201701010337094270266895799=10000100268=1279=1269=048=17359555=6SZ683=355102270=10206.0271=4346=21023=610=087
1128=99=18135=X49=SAMPLE75=2017010134=419052=2017010111231104162433960=201701011123110416243395799=10000100268=1279=1269=048=17359555=6SZ683=355103270=10206.0271=34346=31023=610=156
1128=99=18135=X49=SAMPLE75=2017010134=169452=2017010101411056048810060=201701010141105604881005799=10000100268=1279=1269=148=17359555=6SZ683=355104270=10221.0271=21346=61023=910=125
1128=99=18035=X49=SAMPLE75=2017010134=60952=2017010105525707945347560=201701010552570794534755799=10000100268=1279=1269=048=17359555=6SZ683=355105270=10206.0271=4346=21023=610=110
1128=99=18135=X49=SAMPLE75=2017010134=234752=2017010108234014057392560=201701010823401405739255799=10000100268=1279=1269=148=17359555=6SZ683=355106270=10221.0271=51346=71023=910=146
1128=99=18135=X49=SAMPLE75=2017010134=52852=2017010110473461595903660=201701011047346159590365799=10000100268=1279=1269=048=17359555=6SZ683=355107270=10206.0271=34346=31023=610=159
1128=99=18035=X49=SAMPLE75=2017010134=112152=2017010110364963509678960=201701011036496350967895799=10000100268=1279=1269=048=17359555=6SZ683=355108270=10206.0271=4346=21023=610=082
1128=99=18135=X49=SAMPLE75=2017010134=104052=2017010103382084563459760=201701010338208456345975799=10000100268=1279=1269=148=17359555=6SZ683=355109270=10221.0271=21346=61023=910=140
1128=99=18135=X49=SAMPLE75=2017010134=186552=2017010109092383147121160=201701010909238314712115799=10000100268=1279=1269=048=17359555=6SZ683=355110270=10206.0271=34346=31023=610=122
1128=99=18135=X49=SAMPLE75=2017010134=239352=2017010101514015020845260=201701010151401502084525799=10000100268=1279=1269=148=17359555=6SZ683=355111270=10221.0271=51346=71023=910=113
1128=99=18135=X49=SAMPLE75=2017010134=23752=2017010108451413307867260=201701010845141330786725799=10000100268=1279=1269=148=17359555=6SZ683=355112270=10221.0271=21346=61023=910=125
1128=99=18135=X49=SAMPLE75=2017010134=498352=2017010109150562141737360=201701010915056214173735799=10000100268=1279=1269=148=17359555=6SZ683=355113270=10220.0271=34346=31023=810=125
1128=99=18035=X49=SAMPLE75=2017010134=394252=2017010107382041639850960=201701010738204163985095799=10000100268=1279=1269=148=17359555=6SZ683=355114270=10220.0271=4346=21023=810=092
1128=99=18035=X49=SAMPLE75=2017010134=169052=2017010105061720089018360=201701010506172008901835799=10000100268=1279=1269=048=17359555=6SZ683=355115270=10206.0271=4346=21023=610=112
1128=99=18135=X49=SAMPLE75=2017010134=19852=2017010100145636177770060=201701010014563617777005799=10000100268=1279=1269=148=17359555=6SZ683=355116270=10220.0271=34346=31023=810=156
1128=99=18135=X49=SAMPLE75=2017010134=193652=2017010104185448034299760=201701010418544803429975799=10000100268=1279=1269=048=17359555=6SZ683=355117270=10206.0271=34346=31023=610=145
1128=99=18035=X49=SAMPLE75=2017010134=375152=2017010103511343331741760=201701010351134333174175799=10000100268=1279=1269=148=17359555=6SZ683=355118270=10220.0271=4346=21023=810=079
1128=99=18135=X49=SAMPLE75=2017010134=323652=2017010103071400045068360=201701010307140004506835799=10000100268=1279=1269=148=17359555=6SZ683=355119270=10220.0271=34346=31023=810=158
1128=99=18035=X49=SAMPLE75=2017010134=91752=2017010107193565081969860=201701010719356508196985799=10000100268=1279=1269=148=17359555=6SZ683=355120270=10220.0271=4346=21023=810=099
1128=99=18135=X49=SAMPLE75=2017010134=293152=2017010107404630912574960=201701010740463091257495799=10000100268=1279=1269=148=17359555=6SZ683=355121270=10220.0271=34346=31023=810=138
1128=99=18035=X49=SAMPLE75=2017010134=178952=2017010113380159182914160=201701011338015918291415799=10000100268=1279=1269=048=17359555=6SZ683=355122270=10206.0271=4346=21023=610=083
1128=99=18035=X49=SAMPLE75=2017010134=108252=2017010105011395469244960=201701010501139546924495799=10000100268=1279=1269=148=17359555=6SZ683=355123270=10220.0271=4346=21023=810=086
1128=99=18135=X49=SAMPLE75=2017010134=43352=2017010111302316555365160=201701011130231655536515799=10000100268=1279=1269=048=17359555=6SZ683=355124270=10206.0271=34346=31023=610=152
1128=99=18135=X49=SAMPLE75=2017010134=228552=2017010104102148097370860=201701010410214809737085799=10000100268=1279=1269=148=17359555=6SZ683=355125270=10220.0271=34346=31023=810=122
1128=99=18035=X49=SAMPLE75=2017010134=182352=2017010106441012643103660=201701010644101264310365799=10000100268=1279=1269=148=17359555=6SZ683=355126270=10220.0271=4346=21023=810=096
1128=99=18135=X49=SAMPLE75=2017010134=145852=2017010113130425449545160=201701011313042544954515799=10000100268=1279=1269=148=17359555=6SZ683=355127270=10220.0271=34346=31023=810=169
1128=99=18035=X49=SAMPLE75=2017010134=382652=2017010103402416769577460=201701010340241676957745799=10000100268=1279=1269=148=17359555=6SZ683=355128270=10220.0271=4346=21023=810=080
1128=99=18135=X49=SAMPLE75=2017010134=312452=2017010112060401677305960=201701011206040167730595799=10000100268=1279=1269=148=17359555=6SZ683=355129270=10221.0271=51346=71023=910=156
1128=99=18135=X49=SAMPLE75=2017010134=19752=2017010104335233494037060=201701010433523349403705799=10000100268=1279=1269=148=17359555=6SZ683=355130270=10221.0271=21346=61023=910=144
1128=99=18035=X49=SAMPLE75=2017010134=469852=2017010108412468029058660=201701010841246802905865799=10000100268=1279=1269=048=17359555=6SZ683=355131270=10206.0271=4346=21023=610=099
1128=99=18135=X49=SAMPLE75=2017010134=388352=2017010111281317180327460=201701011128131718032745799=10000100268=1279=1269=148=17359555=6SZ683=355132270=10220.0271=34346=31023=810=116
1128=99=18135=X49=SAMPLE75=2017010134=428852=2017010103425048168282060=201701010342504816828205799=10000100268=1279=1269=048=17359555=6SZ683=355133270=10206.0271=34346=31023=610=142
1128=99=18035=X49=SAMPLE75=2017010134=441752=2017010112093775572298860=201701011209377557229885799=10000100268=1279=1269=148=17359555=6SZ683=355134270=10220.0271=4346=21023=810=092
1128=99=18035=X49=SAMPLE75=2017010134=190752=2017010106075022135671760=201701010607502213567175799=10000100268=1279=1269=048=17359555=6SZ683=355135270=10206.0271=4346=21023=610=073
1128=99=18135=X49=SAMPLE75=2017010134=376552=2017010107563672303969060=201701010756367230396905799=10000100268=1279=1269=148=17359555=6SZ683=355136270=10220.0271=34346=31023=810=160
1128=99=18135=X49=SAMPLE75=2017010134=243952=2017010111172790966626460=201701011117279096662645799=10000100268=1279=1269=048=17359555=6SZ683=355137270=10206.0271=34346=31023=610=161
1128=99=18035=X49=SAMPLE75=2017010134=141752=2017010107264968427629660=201701010726496842762965799=10000100268=1279=1269=148=17359555=6SZ683=355138270=10220.0271=4346=21023=810=104
1128=99=18135=X49=SAMPLE75=2017010134=421652=2017010102505085962853460=201701010250508596285345799=10000100268=1279=1269=148=17359555=6SZ683=355139270=10220.0271=34346=31023=810=142
1128=99=18035=X49=SAMPLE75=2017010134=384452=2017010112340684388201060=201701011234068438820105799=10000100268=1279=1269=148=17359555=6SZ683=355140270=10220.0271=4346=21023=810=080
1128=99=18035=X49=SAMPLE75=2017010134=288752=2017010113264059899057760=201701011326405989905775799=10000100268=1279=1269=048=17359555=6SZ683=355141270=10206.0271=4346=21023=610=085
1128=99=18135=X49=SAMPLE75=2017010134=165852=2017010103370472321118560=201701010337047232111855799=10000100268=1279=1269=148=17359555=6SZ683=355142270=10221.0271=51346=71023=910=137
1128=99=18135=X49=SAMPLE75=2017010134=149152=2017010105360371800083060=201701010536037180008305799=10000100268=1279=1269=048=17359555=6SZ683=355143270=10206.0271=34346=31023=610=156
1128=99=18135=X49=SAMPLE75=2017010134=300152=2017010104073015074963560=201701010407301507496355799=10000100268=1279=1269=148=17359555=6SZ683=355144270=10221.0271=21346=61023=910=159
1128=99=18135=X49=SAMPLE75=2017010134=207952=2017010107472779313213060=201701010747277931321305799=10000100268=1279=1269=148=17359555=6SZ683=355145270=10221.0271=51346=71023=910=170
1128=99=18135=X49=SAMPLE75=2017010134=194152=2017010112275833083603460=201701011227583308360345799=10000100268=1279=1269=148=17359555=6SZ683=355146270=10221.0271=21346=61023=910=155
1128=99=18135=X49=SAMPLE75=2017010134=209752=2017010105590158512551360=201701010559015851255135799=10000100268=1279=1269=148=17359555=6SZ683=355147270=10221.0271=51346=71023=910=160
1128=99=18135=X49=SAMPLE75=2017010134=385652=2017010104155487006435860=201701010415548700643585799=10000100268=1279=1269=148=17359555=6SZ683=355148270=10221.0271=21346=61023=910=147
1128=99=18135=X49=SAMPLE75=2017010134=497352=2017010103562261234323160=201701010356226123432315799=10000100268=1279=1269=148=17359555=6SZ683=355149270=10221.0271=51346=71023=910=144
1128=99=18035=X49=SAMPLE75=2017010134=237952=2017010112202037246957860=201701011220203724695785799=10000100268=1279=1269=048=17359555=6SZ683=355150270=10206.0271=4346=21023=610=075
1128=99=18135=X49=SAMPLE75=2017010134=125152=2017010106033415757952160=201701010603341575795215799=10000100268=1279=1269=148=17359555=6SZ683=355151270=10221.0271=21346=61023=910=139
1128=99=18135=X49=SAMPLE75=2017010134=302152=2017010111302467662456960=201701011130246766245695799=10000100268=1279=1269=048=17359555=6SZ683=355152270=10206.0271=34346=31023=610=175
1128=99=18135=X49=SAMPLE75=2017010134=288752=2017010105510315572367160=201701010551031557236715799=10000100268=1279=1269=148=17359555=6SZ683=355153270=10221.0271=51346=71023=910=185
1128=99=18135=X49=SAMPLE75=2017010134=24252=2017010101355556284142560=201701010135555628414255799=10000100268=1279=1269=148=17359555=6SZ683=355154270=10221.0271=21346=61023=910=150
1128=99=18135=X49=SAMPLE75=2017010134=321452=2017010100434145934488060=201701010043414593448805799=10000100268=1279=1269=148=17359555=6SZ683=355155270=10220.0271=34346=31023=810=162
1128=99=18035=X49=SAMPLE75=2017010134=211052=2017010106394047703898860=201701010639404770389885799=10000100268=1279=1269=148=17359555=6SZ683=355156270=10220.0271=4346=21023=810=128
1128=99=18035=X49=SAMPLE75=2017010134=441752=2017010108440065290520660=201701010844006529052065799=10000100268=1279=1269=048=17359555=6SZ683=355157270=10206.0271=4346=21023=610=094
1128=99=18135=X49=SAMPLE75=2017010134=425952=2017010103094584567691760=201701010309458456769175799=10000100268=1279=1269=148=17359555=6SZ683=355158270=10220.0271=34346=31023=810=159
1128=99=18135=X49=SAMPLE75=2017010134=477552=2017010110285028267778760=201701011028502826777875799=10000100268=1279=1269=048=17359555=6SZ683=355159270=10206.0271=34346=31023=610=187
1128=99=18035=X49=SAMPLE75=2017010134=15752=2017010111370979100104660=201701011137097910010465799=10000100268=1279=1269=148=17359555=6SZ683=355160270=10220.0271=4346=21023=810=065
1128=99=18035=X49=SAMPLE75=2017010134=107152=2017010113444382587517560=201701011344438258751755799=10000100268=1279=1269=048=17359555=6SZ683=355161270=10206.0271=4346=21023=610=081
1128=99=18135=X49=SAMPLE75=2017010134=18652=2017010108280610853022860=201701010828061085302285799=10000100268=1279=1269=148=17359555=6SZ683=355162270=10220.0271=34346=31023=810=139
1128=99=18135=X49=SAMPLE75=2017010134=498952=2017010108434139747834860=201701010843413974783485799=10000100268=1279=1269=048=17359555=6SZ683=355163270=10206.0271=34346=31023=610=132
1128=99=18035=X49=SAMPLE75=2017010134=101052=2017010105165403464538560=201701010516540346453855799=10000100268=1279=1269=048=17359555=6SZ683=355164270=10206.0271=4346=21023=610=082
1128=99=18035=X49=SAMPLE75=2017010134=291552=2017010100304853703753760=201701010030485370375375799=10000100268=1279=1269=148=17359555=6SZ683=355165270=10220.0271=4346=21023=810=081
1128=99=18135=X49=SAMPLE75=2017010134=162452=2017010102000391658730560=201701010200039165873055799=10000100268=1279=1269=048=17359555=6SZ683=355166270=10206.0271=34346=31023=610=165
1128=99=18135=X49=SAMPLE75=2017010134=353452=2017010104521987062305760=201701010452198706230575799=10000100268=1279=1269=148=17359555=6SZ683=355167270=10220.0271=34346=31023=810=162
1128=99=18035=X49=SAMPLE75=2017010134=246052=2017010105553423360903860=201701010555342336090385799=10000100268=1279=1269=148=17359555=6SZ683=355168270=10220.0271=4346=21023=810=086
1128=99=18035=X49=SAMPLE75=2017010134=186552=2017010106081778257450860=201701010608177825745085799=10000100268=1279=1269=048=17359555=6SZ683=355169270=10206.0271=4346=21023=610=079
1128=99=18135=X49=SAMPLE75=2017010134=430252=2017010107540097494172360=201701010754009749417235799=10000100268=1279=1269=148=17359555=6SZ683=355170270=10220.0271=34346=31023=810=125
1128=99=18135=X49=SAMPLE75=2017010134=404952=2017010111531849493699860=201701011153184949369985799=10000100268=1279=1269=048=17359555=6SZ683=355171270=10206.0271=34346=31023=610=150
1128=99=18035=X49=SAMPLE75=2017010134=96252=2017010100314175621245260=201701010031417562124525799=10000100268=1279=1269=048=17359555=6SZ683=355172270=10206.0271=4346=21023=610=095
1128=99=18135=X49=SAMPLE75=2017010134=435552=2017010105352906867269160=201701010535290686726915799=10000100268=1279=1269=048=17359555=6SZ683=355173270=10206.0271=34346=31023=610=151
1128=99=18035=X49=SAMPLE75=2017010134=361652=2017010104060361732153260=201701010406036173215325799=10000100268=1279=1269=148=17359555=6SZ683=355174270=10220.0271=4346=21023=810=103
1128=99=18135=X49=SAMPLE75=2017010134=176252=2017010101381743202141960=201701010138174320214195799=10000100268=1279=1269=148=17359555=6SZ683=355175270=10221.0271=51346=71023=910=175
1128=99=18035=X49=SAMPLE75=2017010134=344652=2017010103354868018248460=201701010335486801824845799=10000100268=1279=1269=048=17359555=6SZ683=355176270=10206.0271=4346=21023=610=108
1128=99=18135=X49=SAMPLE75=2017010134=294752=2017010114082635463885560=201701011408263546388555799=10000100268=1279=1269=148=17359555=6SZ683=355177270=10221.0271=21346=61023=910=168
1128=99=18135=X49=SAMPLE75=2017010134=321752=2017010109583353455662860=201701010958335345566285799=10000100268=1279=1269=148=17359555=6SZ683=355178270=10220.0271=34346=31023=810=147
1128=99=18135=X49=SAMPLE75=2017010134=284152=2017010100325231991130960=201701010032523199113095799=10000100268=1279=1269=048=17359555=6SZ683=355179270=10206.0271=34346=31023=610=165
1128=99=18035=X49=SAMPLE75=2017010134=87052=2017010112411185178211260=201701011241118517821125799=10000100268=1279=1269=148=17359555=6SZ683=355180270=10220.0271=4346=21023=810=081
1128=99=18035=X49=SAMPLE75=2017010134=165652=2017010105103365454406660=201701010510336545440665799=10000100268=1279=1269=048=17359555=6SZ683=355181270=10206.0271=4346=21023=610=107
1128=99=18135=X49=SAMPLE75=2017010134=496052=2017010107202260987504360=201701010720226098750435799=10000100268=1279=1269=148=17359555=6SZ683=355182270=10221.0271=51346=71023=910=167
1128=99=18135=X49=SAMPLE75=2017010134=138552=2017010113284651989838560=201701011328465198983855799=10000100268=1279=1269=048=17359555=6SZ683=355183270=10206.0271=34346=31023=610=151
1128=99=18135=X49=SAMPLE75=2017010134=183652=2017010106560658285454660=201701010656065828545465799=10000100268=1279=1269=148=17359555=6SZ683=355184270=10221.0271=21346=61023=910=153
1128=99=18135=X49=SAMPLE75=2017010134=68752=2017010112095496881298860=201701011209549688129885799=10000100268=1279=1269=148=17359555=6SZ683=355185270=10220.0271=34346=31023=810=152
1128=99=18035=X49=SAMPLE75=2017010134=249052=2017010104334811691310260=201701010433481169131025799=10000100268=1279=1269=148=17359555=6SZ683=355186270=10220.0271=4346=21023=810=085
1128=99=18135=X49=SAMPLE75=2017010134=331352=2017010108260615615785060=201701010826061561578505799=10000100268=1279=1269=148=17359555=6SZ683=355187270=10221.0271=51346=71023=910=174
1128=99=18035=X49=SAMPLE75=2017010134=352652=2017010105315720792639660=201701010531572079263965799=10000100268=1279=1269=048=17359555=6SZ683=355188270=10206.0271=4346=21023=610=116
1128=99=18135=X49=SAMPLE75=2017010134=394452=2017010103335902102347060=201701010333590210234705799=10000100268=1279=1269=148=17359555=6SZ683=355189270=10221.0271=21346=61023=910=173
1128=99=18135=X49=SAMPLE75=2017010134=423452=2017010113503158554085060=201701011350315855408505799=10000100268=1279=1269=148=17359555=6SZ683=355190270=10220.0271=34346=31023=810=154
1128=99=18135=X49=SAMPLE75=2017010134=248852=2017010104262785445169960=201701010426278544516995799=10000100268=1279=1269=048=17359555=6SZ683=355191270=10206.0271=34346=31023=610=150
1128=99=18035=X49=SAMPLE75=2017010134=453352=2017010106015917841417860=201701010601591784141785799=10000100268=1279=1269=048=17359555=6SZ683=355192270=10206.0271=4346=21023=610=126
1128=99=18135=X49=SAMPLE75=2017010134=54952=2017010109475683650634360=201701010947568365063435799=10000100268=1279=1269=048=17359555=6SZ683=355193270=10206.0271=34346=31023=610=173
1128=99=18035=X49=SAMPLE75=2017010134=460452=2017010105381578885115560=201701010538157888511555799=10000100268=1279=1269=148=17359555=6SZ683=355194270=10220.0271=4346=21023=810=112
1128=99=18135=X49=SAMPLE75=2017010134=400452=2017010109164101862942060=201701010916410186294205799=10000100268=1279=1269=148=17359555=6SZ683=355195270=10220.0271=34346=31023=810=157
1128=99=18035=X49=SAMPLE75=2017010134=209552=2017010108404648816668660=201701010840464881666865799=10000100268=1279=1269=148=17359555=6SZ683=355196270=10220.0271=4346=21023=810=128
1128=99=18135=X49=SAMPLE75=2017010134=7052=2017010104442451375773760=201701010444245137577375799=10000100268=1279=1269=148=17359555=6SZ683=355197270=10220.0271=34346=31023=810=203
1128=99=18035=X49=SAMPLE75=2017010134=323852=2017010107342335123871160=201701010734233512387115799=10000100268=1279=1269=148=17359555=6SZ683=355198270=10220.0271=4346=21023=810=095
1128=99=18135=X49=SAMPLE75=2017010134=182352=2017010106243331592911760=201701010624333159291175799=10000100268=1279=1269=148=17359555=6SZ683=355199270=10220.0271=34346=31023=810=160
1128=99=18035=X49=SAMPLE75=2017010134=209652=2017010113552352464697260=201701011355235246469725799=10000100268=1279=1269=148=17359555=6SZ683=355200270=10220.0271=4346=21023=810=089
1128=99=18035=X49=SAMPLE75=2017010134=244752=2017010107151122888698960=201701010715112288869895799=10000100268=1279=1269=048=17359555=6SZ683=355201270=10206.0271=4346=21023=610=080
1128=99=18135=X49=SAMPLE75=2017010134=330052=2017010104462457171268760=201701010446245717126875799=10000100268=1279=1269=148=17359555=6SZ683=355202270=10220.0271=34346=31023=810=152
1128=99=18135=X49=SAMPLE75=2017010134=442752=2017010111460631628342960=201701011146063162834295799=10000100268=1279=1269=048=17359555=6SZ683=355203270=10206.0271=34346=31023=610=146
1128=99=18035=X49=SAMPLE75=2017010134=189252=2017010110215343742293260=201701011021534374229325799=10000100268=1279=1269=148=17359555=6SZ683=355204270=10220.0271=4346=21023=810=090
1128=99=18035=X49=SAMPLE75=2017010134=90452=2017010104242207534394860=201701010424220753439485799=10000100268=1279=1269=048=17359555=6SZ683=355205270=10206.0271=4346=21023=610=085
1128=99=18135=X49=SAMPLE75=2017010134=294352=2017010106353615994347760=201701010635361599434775799=10000100268=1279=1269=148=17359555=6SZ683=355206270=10220.0271=34346=31023=810=146
1128=99=18135=X49=SAMPLE75=2017010134=289752=2017010104370470587184760=201701010437047058718475799=10000100268=1279=1269=048=17359555=6SZ683=355207270=10206.0271=34346=31023=610=174
1128=99=18035=X49=SAMPLE75=2017010134=185352=2017010104553140308371860=201701010455314030837185799=10000100268=1279=1269=148=17359555=6SZ683=355208270=10220.0271=4346=21023=810=101
1128=99=18135=X49=SAMPLE75=2017010134=294952=2017010114003881703569760=201701011400388170356975799=10000100268=1279=1269=148=17359555=6SZ683=355209270=10220.0271=34346=31023=810=168
1128=99=18035=X49=SAMPLE75=2017010134=404052=2017010105462447461351360=201701010546244746135135799=10000100268=1279=1269=048=17359555=6SZ683=355210270=10206.0271=4346=21023=610=089
1128=99=18035=X49=SAMPLE75=2017010134=130352=2017010110582246835744760=201701011058224683574475799=10000100268=1279=1269=148=17359555=6SZ683=355211270=10220.0271=4346=21023=810=107
1128=99=18135=X49=SAMPLE75=2017010134=10352=2017010112400257511216660=201701011240025751121665799=10000100268=1279=1269=048=17359555=6SZ683=355212270=10205.0271=51346=81023=710=140
1128=99=18235=X49=SAMPLE75=2017010134=240652=2017010100165037781260360=201701010016503778126035799=10000100268=1279=1269=048=17359555=6SZ683=355213270=10202.0271=22346=81023=1010=198
1128=99=18235=X49=SAMPLE75=2017010134=410052=2017010112303833760774860=201701011230383376077485799=10000100268=1279=1269=048=17359555=6SZ683=355214270=10202.0271=52346=91023=1010=185
1128=99=18035=X49=SAMPLE75=2017010134=332652=2017010105342604745451560=201701010534260474545155799=10000100268=1279=1269=148=17359555=6SZ683=355215270=10214.0271=9346=71023=210=091
1128=99=18035=X49=SAMPLE75=2017010134=176552=2017010111231670728921760=201701011123167072892175799=10000100268=1279=1269=048=17359555=6SZ683=355216270=10210.0271=5346=31023=210=090
1128=99=18235=X49=SAMPLE75=2017010134=397952=2017010112540689265010860=201701011254068926501085799=10000100268=1279=1269=048=17359555=6SZ683=355217270=10202.0271=22346=81023=1010=175
1128=99=18135=X49=SAMPLE75=2017010134=471252=2017010109473335149929460=201701010947333514992945799=10000100268=1279=1269=148=17359555=6SZ683=355218270=10220.0271=34346=31023=810=167
1128=99=18135=X49=SAMPLE75=2017010134=15852=2017010110060934337612960=201701011006093433761295799=10000100268=1279=1269=048=17359555=6SZ683=355219270=10205.0271=21346=71023=710=174
1128=99=18135=X49=SAMPLE75=2017010134=426152=2017010108231036017156260=201701010823103601715625799=10000100268=1279=1269=048=17359555=6SZ683=355220270=10206.0271=34346=31023=610=157
1128=99=18035=X49=SAMPLE75=2017010134=180452=2017010103564152071776960=201701010356415207177695799=10000100268=1279=1269=148=17359555=6SZ683=355221270=10220.0271=4346=21023=810=087
1128=99=18135=X49=SAMPLE75=2017010134=273552=2017010114325100010821760=201701011432510001082175799=10000100268=1279=1269=148=17359555=6SZ683=355222270=10216.0271=12346=41023=410=137
1128=99=18235=X49=SAMPLE75=2017010134=213852=2017010112471044537104360=201701011247104453710435799=10000100268=1279=1269=048=17359555=6SZ683=355223270=10202.0271=52346=91023=1010=216
1128=99=18135=X49=SAMPLE75=2017010134=285552=2017010105012027581077360=201701010501202758107735799=10000100268=1279=1269=148=17359555=6SZ683=355224270=10220.0271=34346=31023=810=129
1128=99=18135=X49=SAMPLE75=2017010134=59752=2017010105125301341871260=201701010512530134187125799=10000100268=1279=1269=148=17359555=6SZ683=355225270=10216.0271=42346=51023=410=139
1128=99=18035=X49=SAMPLE75=2017010134=106252=2017010106352204917490260=201701010635220491749025799=10000100268=1279=1269=148=17359555=6SZ683=355226270=10220.0271=4346=21023=810=110
1128=99=18135=X49=SAMPLE75=2017010134=485352=2017010100560316218135460=201701010056031621813545799=10000100268=1279=1269=148=17359555=6SZ683=355227270=10220.0271=34346=31023=810=175
1128=99=18035=X49=SAMPLE75=2017010134=417552=2017010103364006712034560=201701010336400671203455799=10000100268=1279=1269=148=17359555=6SZ683=355228270=10220.0271=4346=21023=810=101
1128=99=18135=X49=SAMPLE75=2017010134=140052=2017010113123708407022360=201701011312370840702235799=10000100268=1279=1269=148=17359555=6SZ683=355229270=10220.0271=34346=31023=810=154
1128=99=18035=X49=SAMPLE75=2017010134=117452=2017010106470034526820060=201701010647003452682005799=10000100268=1279=1269=048=17359555=6SZ683=355230270=10206.0271=4346=21023=610=139
1128=99=18035=X49=SAMPLE75=2017010134=43652=2017010101073898133167560=201701010107389813316755799=10000100268=1279=1269=148=17359555=6SZ683=355231270=10220.0271=4346=21023=810=110
1128=99=18135=X49=SAMPLE75=2017010134=94152=2017010111542046010558660=201701011154204601055865799=10000100268=1279=1269=048=17359555=6SZ683=355232270=10206.0271=34346=31023=610=145
1128=99=18135=X49=SAMPLE75=2017010134=268652=2017010110185126271537060=201701011018512627153705799=10000100268=1279=1269=148=17359555=6SZ683=355233270=10220.0271=34346=31023=810=161
1128=99=18035=X49=SAMPLE75=2017010134=48152=2017010111245945557143660=201701011124594555714365799=10000100268=1279=1269=148=17359555=6SZ683=355234270=10220.0271=4346=21023=810=102
1128=99=18135=X49=SAMPLE75=2017010134=119252=2017010105120444872153160=201701010512044487215315799=10000100268=1279=1269=148=17359555=6SZ683=355235270=10220.0271=34346=31023=810=173
1128=99=18035=X49=SAMPLE75=2017010134=58752=2017010110563071937582560=201701011056307193758255799=10000100268=1279=1269=148=17359555=6SZ683=355236270=10220.0271=4346=21023=810=115
1128=99=18035=X49=SAMPLE75=2017010134=86952=2017010104472153493207860=201701010447215349320785799=10000100268=1279=1269=048=17359555=6SZ683=355237270=10206.0271=4346=21023=610=089
1128=99=18135=X49=SAMPLE75=2017010134=413652=2017010104580904747737560=201701010458090474773755799=10000100268=1279=1269=148=17359555=6SZ683=355238270=10221.0271=51346=71023=910=159
1128=99=18135=X49=SAMPLE75=2017010134=456052=2017010112085065585480460=201701011208506558548045799=10000100268=1279=1269=048=17359555=6SZ683=355239270=10206.0271=34346=31023=610=165
1128=99=18135=X49=SAMPLE75=2017010134=126552=2017010102041067676702860=201701010204106767670285799=10000100268=1279=1269=148=17359555=6SZ683=355240270=10221.0271=21346=61023=910=145
1128=99=18135=X49=SAMPLE75=2017010134=262552=2017010107194948904660560=201701010719494890466055799=10000100268=1279=1269=148=17359555=6SZ683=355241270=10220.0271=34346=31023=810=152
1128=99=18035=X49=SAMPLE75=2017010134=396352=2017010104352382648856760=201701010435238264885675799=10000100268=1279=1269=148=17359555=6SZ683=355242270=10220.0271=4346=21023=810=082
1128=99=18035=X49=SAMPLE75=2017010134=293452=2017010100235595359672660=201701010023559535967265799=10000100268=1279=1269=048=17359555=6SZ683=355243270=10206.0271=4346=21023=610=106
1128=99=18135=X49=SAMPLE75=2017010134=344052=2017010104080348264396360=201701010408034826439635799=10000100268=1279=1269=148=17359555=6SZ683=355244270=10220.0271=34346=31023=810=159
1128=99=18135=X49=SAMPLE75=2017010134=222552=2017010107021590356596660=201701010702159035659665799=10000100268=1279=1269=048=17359555=6SZ683=355245270=10206.0271=34346=31023=610=145
1128=99=18035=X49=SAMPLE75=2017010134=298952=2017010113352537569100660=201701011335253756910065799=10000100268=1279=1269=048=17359555=6SZ683=355246270=10206.0271=4346=21023=610=110
1128=99=18035=X49=SAMPLE75=2017010134=460352=2017010103062538997630460=201701010306253899763045799=10000100268=1279=1269=148=17359555=6SZ683=355247270=10220.0271=4346=21023=810=107
1128=99=18135=X49=SAMPLE75=2017010134=33352=2017010102075627277253960=201701010207562727725395799=10000100268=1279=1269=048=17359555=6SZ683=355248270=10206.0271=34346=31023=610=184
1128=99=18135=X49=SAMPLE75=2017010134=310552=2017010111143199863364660=201701011114319986336465799=10000100268=1279=1269=148=17359555=6SZ683=355249270=10220.0271=34346=31023=810=177
1128=99=18035=X49=SAMPLE75=2017010134=1352=2017010111090286107295060=201701011109028610729505799=10000100268=1279=1269=148=17359555=6SZ683=355250270=10220.0271=4346=21023=810=102
1128=99=18135=X49=SAMPLE75=2017010134=247152=2017010103465692835723460=201701010346569283572345799=10000100268=1279=1269=148=17359555=6SZ683=355251270=10221.0271=51346=71023=910=144
1128=99=18135=X49=SAMPLE75=2017010134=398052=2017010103582216081486060=201701010358221608148605799=10000100268=1279=1269=148=17359555=6SZ683=355252270=10221.0271=21346=61023=910=156
1128=99=18035=X49=SAMPLE75=2017010134=103352=2017010110034002636303560=201701011003400263630355799=10000100268=1279=1269=048=17359555=6SZ683=355253270=10206.0271=4346=21023=610=126
1128=99=18135=X49=SAMPLE75=2017010134=2352=2017010110243334551943260=201701011024333455194325799=10000100268=1279=1269=148=17359555=6SZ683=355254270=10220.0271=34346=31023=810=174
1128=99=18135=X49=SAMPLE75=2017010134=3152=2017010100415313476165860=201701010041531347616585799=10000100268=1279=1269=048=17359555=6SZ683=355255270=10206.0271=34346=31023=610=171
1128=99=18035=X49=SAMPLE75=2017010134=412852=2017010114144990899468760=201701011414499089946875799=10000100268=1279=1269=148=17359555=6SZ683=355256270=10220.0271=4346=21023=810=117
1128=99=18135=X49=SAMPLE75=2017010134=215152=2017010109235309124927160=201701010923530912492715799=10000100268=1279=1269=148=17359555=6SZ683=355257270=10221.0271=51346=71023=910=157
1128=99=18135=X49=SAMPLE75=2017010134=285552=2017010111375692467747460=201701011137569246774745799=10000100268=1279=1269=148=17359555=6SZ683=355258270=10221.0271=21346=61023=910=164
1128=99=18135=X49=SAMPLE75=2017010134=407052=2017010111450385582351260=201701011145038558235125799=10000100268=1279=1269=148=17359555=6SZ683=355259270=10221.0271=51346=71023=910=153
1128=99=18135=X49=SAMPLE75=2017010134=274152=2017010100535434493973260=201701010053543449397325799=10000100268=1279=1269=148=17359555=6SZ683=355260270=10221.0271=21346=61023=910=124
1128=99=18035=X49=SAMPLE75=2017010134=50752=2017010103102216694475660=201701010310221669447565799=10000100268=1279=1269=048=17359555=6SZ683=355261270=10206.0271=4346=21023=610=096
1128=99=18135=X49=SAMPLE75=2017010134=487852=2017010106282463570854960=201701010628246357085495799=10000100268=1279=1269=148=17359555=6SZ683=355262270=10221.0271=51346=71023=910=130
1128=99=18135=X49=SAMPLE75=2017010134=349452=2017010105530463670429560=201701010553046367042955799=10000100268=1279=1269=048=17359555=6SZ683=355263270=10206.0271=34346=31023=610=138
1128=99=18135=X49=SAMPLE75=2017010134=215552=2017010107430859142583660=201701010743085914258365799=10000100268=1279=1269=148=17359555=6SZ683=355264270=10221.0271=21346=61023=910=150
1128=99=18035=X49=SAMPLE75=2017010134=212652=2017010102440197371016360=201701010244019737101635799=10000100268=1279=1269=048=17359555=6SZ683=355265270=10206.0271=4346=21023=610=110
1128=99=18135=X49=SAMPLE75=2017010134=261152=2017010114232609409856760=201701011423260940985675799=10000100268=1279=1269=148=17359555=6SZ683=355266270=10220.0271=34346=31023=810=173
1128=99=18135=X49=SAMPLE75=2017010134=192752=2017010105083883466962360=201701010508388346696235799=10000100268=1279=1269=048=17359555=6SZ683=355267270=10206.0271=34346=31023=610=171
1128=99=18035=X49=SAMPLE75=2017010134=248752=2017010112343993955197660=201701011234399395519765799=10000100268=1279=1269=148=17359555=6SZ683=355268270=10220.0271=4346=21023=810=124
1128=99=18135=X49=SAMPLE75=2017010134=212952=2017010105212146937369760=201701010521214693736975799=10000100268=1279=1269=148=17359555=6SZ683=355269270=10221.0271=51346=71023=910=148
1128=99=18135=X49=SAMPLE75=2017010134=354452=2017010106144919076479160=201701010614491907647915799=10000100268=1279=1269=148=17359555=6SZ683=355270270=10221.0271=21346=61023=910=154
1128=99=18135=X49=SAMPLE75=2017010134=157352=2017010113531737346264760=201701011353173734626475799=10000100268=1279=1269=148=17359555=6SZ683=355271270=10221.0271=51346=71023=910=148
1128=99=18135=X49=SAMPLE75=2017010134=171152=2017010106373182870675960=201701010637318287067595799=10000100268=1279=1269=148=17359555=6SZ683=355272270=10221.0271=21346=61023=910=150
1128=99=18135=X49=SAMPLE75=2017010134=461552=2017010104051446614849860=201701010405144661484985799=10000100268=1279=1269=148=17359555=6SZ683=355273270=10221.0271=51346=71023=910=143
1128=99=18135=X49=SAMPLE75=2017010134=380052=2017010109291456465241460=201701010929145646524145799=10000100268=1279=1269=148=17359555=6SZ683=355274270=10221.0271=21346=61023=910=145
1128=99=18135=X49=SAMPLE75=2017010134=34952=2017010105024896032448360=201701010502489603244835799=10000100268=1279=1269=148=17359555=6SZ683=355275270=10221.0271=51346=71023=910=155
1128=99=18135=X49=SAMPLE75=2017010134=454252=2017010106270349672793260=201701010627034967279325799=10000100268=1279=1269=148=17359555=6SZ683=355276270=10221.0271=21346=61023=910=165
1128=99=18135=X49=SAMPLE75=2017010134=132752=2017010106122999093773060=201701010612299909377305799=10000100268=1279=1269=148=17359555=6SZ683=355277270=10220.0271=34346=31023=810=188
1128=99=18035=X49=SAMPLE75=2017010134=256652=2017010107363805996682760=201701010736380599668275799=10000100268=1279=1269=148=17359555=6SZ683=355278270=10220.0271=4346=21023=810=085
1128=99=18135=X49=SAMPLE75=2017010134=158652=2017010103115143429443360=201701010311514342944335799=10000100268=1279=1269=148=17359555=6SZ683=355279270=10221.0271=51346=71023=910=146
1128=99=18135=X49=SAMPLE75=2017010134=65152=2017010113561626733390860=201701011356162673339085799=10000100268=1279=1269=148=17359555=6SZ683=355280270=10221.0271=21346=61023=910=161
1128=99=18135=X49=SAMPLE75=2017010134=53752=2017010108420399856479160=201701010842039985647915799=10000100268=1279=1269=148=17359555=6SZ683=355281270=10221.0271=51346=71023=910=160
1128=99=18135=X49=SAMPLE75=2017010134=281752=2017010103594171966481660=201701010359417196648165799=10000100268=1279=1269=148=17359555=6SZ683=355282270=10221.0271=21346=61023=910=158
1128=99=18035=X49=SAMPLE75=2017010134=96352=2017010106412762820517760=201701010641276282051775799=10000100268=1279=1269=048=17359555=6SZ683=355283270=10206.0271=4346=21023=610=112
1128=99=18135=X49=SAMPLE75=2017010134=351052=2017010109182686805287960=201701010918268680528795799=10000100268=1279=1269=148=17359555=6SZ683=355284270=10221.0271=51346=71023=910=155
1128=99=18135=X49=SAMPLE75=2017010134=415652=2017010106325630075285960=201701010632563007528595799=10000100268=1279=1269=048=17359555=6SZ683=355285270=10206.0271=34346=31023=610=148
1128=99=18135=X49=SAMPLE75=2017010134=81552=2017010109411540994372860=201701010941154099437285799=10000100268=1279=1269=148=17359555=6SZ683=355286270=10221.0271=21346=61023=910=190
1128=99=18135=X49=SAMPLE75=2017010134=465352=2017010112204803814960460=201701011220480381496045799=10000100268=1279=1269=148=17359555=6SZ683=355287270=10221.0271=51346=71023=910=177
1128=99=18135=X49=SAMPLE75=2017010134=90452=2017010100152105295033160=201701010015210529503315799=10000100268=1279=1269=148=17359555=6SZ683=355288270=10221.0271=21346=61023=910=173
1128=99=18135=X49=SAMPLE75=2017010134=498052=2017010104412404600348160=201701010441240460034815799=10000100268=1279=1269=148=17359555=6SZ683=355289270=10221.0271=51346=71023=910=191
1128=99=18035=X49=SAMPLE75=2017010134=368152=2017010107555507443568860=201701010755550744356885799=10000100268=1279=1269=048=17359555=6SZ683=355290270=10206.0271=4346=21023=610=105
1128=99=18135=X49=SAMPLE75=2017010134=395552=2017010108030871845040160=201701010803087184504015799=10000100268=1279=1269=048=17359555=6SZ683=355291270=10207.0271=15346=71023=510=159
1128=99=18135=X49=SAMPLE75=2017010134=186052=2017010107053180360602260=201701010705318036060225799=10000100268=1279=1269=048=17359555=6SZ683=355292270=10208.0271=37346=51023=410=176
1128=99=18135=X49=SAMPLE75=2017010134=366752=2017010107154710230602060=201701010715471023060205799=10000100268=1279=1269=148=17359555=6SZ683=355293270=10221.0271=21346=61023=910=154
1128=99=18135=X49=SAMPLE75=2017010134=158152=2017010103245173780802060=201701010324517378080205799=10000100268=1279=1269=148=17359555=6SZ683=355294270=10216.0271=12346=41023=410=179
1128=99=18135=X49=SAMPLE75=2017010134=158052=2017010107593815746414960=201701010759381574641495799=10000100268=1279=1269=048=17359555=6SZ683=355295270=10203.0271=34346=31023=910=182
1128=99=18235=X49=SAMPLE75=2017010134=143652=2017010114241909217876160=201701011424190921787615799=10000100268=1279=1269=048=17359555=6SZ683=355296270=10202.0271=22346=81023=1010=218
1128=99=18135=X49=SAMPLE75=2017010134=257552=2017010113163608298217460=201701011316360829821745799=10000100268=1279=1269=048=17359555=6SZ683=355297270=10207.0271=45346=81023=510=169
1128=99=18135=X49=SAMPLE75=2017010134=354752=2017010110384675088766660=201701011038467508876665799=10000100268=1279=1269=048=17359555=6SZ683=355298270=10204.0271=34346=31023=810=167
1128=99=18135=X49=SAMPLE75=2017010134=157452=2017010106075941610918060=201701010607594161091805799=10000100268=1279=1269=148=17359555=6SZ683=355299270=10221.0271=51346=71023=910=174
1128=99=18035=X49=SAMPLE75=2017010134=203452=2017010113441863702623260=201701011344186370262325799=10000100268=1279=1269=048=17359555=6SZ683=355300270=10203.0271=4346=21023=910=132
1128=99=18135=X49=SAMPLE75=2017010134=191652=2017010102113124823545160=201701010211312482354515799=10000100268=1279=1269=148=17359555=6SZ683=355301270=10218.0271=34346=31023=610=167
1128=99=18035=X49=SAMPLE75=2017010134=307852=2017010100130039680935360=201701010013003968093535799=10000100268=1279=1269=048=17359555=6SZ683=355302270=10208.0271=7346=41023=410=118
1128=99=18035=X49=SAMPLE75=2017010134=159852=2017010101580054889151260=201701010158005488915125799=10000100268=1279=1269=048=17359555=6SZ683=355303270=10204.0271=4346=21023=810=100
1128=99=18135=X49=SAMPLE75=2017010134=472952=2017010109441370078046660=201701010944137007804665799=10000100268=1279=1269=048=17359555=6SZ683=355304270=10204.0271=34346=31023=810=163
1128=99=18035=X49=SAMPLE75=2017010134=151352=2017010102542887947161660=201701010254288794716165799=10000100268=1279=1269=048=17359555=6SZ683=355305270=10204.0271=4346=21023=810=083
1128=99=18135=X49=SAMPLE75=2017010134=313352=2017010104520704226976760=201701010452070422697675799=10000100268=1279=1269=048=17359555=6SZ683=355306270=10205.0271=51346=81023=710=160
1128=99=18235=X49=SAMPLE75=2017010134=394052=2017010110002850228749060=201701011000285022874905799=10000100268=1279=1269=048=17359555=6SZ683=355307270=10202.0271=52346=91023=1010=197
1128=99=18135=X49=SAMPLE75=2017010134=492552=2017010108131079432762360=201701010813107943276235799=10000100268=1279=1269=048=17359555=6SZ683=355308270=10205.0271=21346=71023=710=182
1128=99=18135=X49=SAMPLE75=2017010134=208052=2017010106050917158682760=201701010605091715868275799=10000100268=1279=1269=048=17359555=6SZ683=355309270=10205.0271=51346=81023=710=130
1128=99=18135=X49=SAMPLE75=2017010134=400252=2017010107304162807373460=201701010730416280737345799=10000100268=1279=1269=148=17359555=6SZ683=355310270=10221.0271=21346=61023=910=136
1128=99=18135=X49=SAMPLE75=2017010134=315552=2017010105031899679639460=201701010503189967963945799=10000100268=1279=1269=048=17359555=6SZ683=355311270=10205.0271=21346=71023=710=138
1128=99=18135=X49=SAMPLE75=2017010134=246852=2017010105173128687694960=201701010517312868769495799=10000100268=1279=1269=148=17359555=6SZ683=355312270=10221.0271=51346=71023=910=144
1128=99=18135=X49=SAMPLE75=2017010134=356652=2017010114112553867909960=201701011411255386790995799=10000100268=1279=1269=048=17359555=6SZ683=355313270=10205.0271=51346=81023=710=164
1128=99=18135=X49=SAMPLE75=2017010134=114952=2017010113522498094834860=201701011352249809483485799=10000100268=1279=1269=148=17359555=6SZ683=355314270=10221.0271=21346=61023=910=161
1128=99=18135=X49=SAMPLE75=2017010134=313952=2017010110093402277072760=201701011009340227707275799=10000100268=1279=1269=048=17359555=6SZ683=355315270=10205.0271=21346=71023=710=174
1128=99=18135=X49=SAMPLE75=2017010134=389052=2017010107443610373720660=201701010744361037372065799=10000100268=1279=1269=148=17359555=6SZ683=355316270=10221.0271=51346=71023=910=166
1128=99=18135=X49=SAMPLE75=2017010134=217152=2017010103245420951456960=201701010324542095145695799=10000100268=1279=1269=148=17359555=6SZ683=355317270=10221.0271=21346=61023=910=151
1128=99=18135=X49=SAMPLE75=2017010134=103452=2017010100581994005031060=201701010058199400503105799=10000100268=1279=1269=048=17359555=6SZ683=355318270=10208.0271=37346=51023=410=165
1128=99=18135=X49=SAMPLE75=2017010134=118352=2017010101414371821426360=201701010141437182142635799=10000100268=1279=1269=048=17359555=6SZ683=355319270=10204.0271=34346=31023=810=153
1128=99=18235=X49=SAMPLE75=2017010134=23452=2017010107535191198477360=201701010753519119847735799=10000100268=1279=1269=048=17359555=6SZ683=355320270=10202.0271=22346=81023=1010=196
1128=99=18135=X49=SAMPLE75=2017010134=111052=2017010105110802069140760=201701010511080206914075799=10000100268=1279=1269=148=17359555=6SZ683=355321270=10221.0271=51346=71023=910=158
1128=99=18035=X49=SAMPLE75=2017010134=68852=2017010102474058134257160=201701010247405813425715799=10000100268=1279=1269=048=17359555=6SZ683=355322270=10204.0271=4346=21023=810=106
1128=99=18235=X49=SAMPLE75=2017010134=118352=2017010108100761675059860=201701010810076167505985799=10000100268=1279=1269=048=17359555=6SZ683=355323270=10202.0271=52346=91023=1010=230
1128=99=18135=X49=SAMPLE75=2017010134=409152=2017010108172022314354860=201701010817202231435485799=10000100268=1279=1269=048=17359555=6SZ683=355324270=10204.0271=34346=31023=810=152
1128=99=18235=X49=SAMPLE75=2017010134=375152=2017010107424405763432860=201701010742440576343285799=10000100268=1279=1269=048=17359555=6SZ683=355325270=10202.0271=22346=81023=1010=200
1128=99=18135=X49=SAMPLE75=2017010134=486052=2017010109521135735281860=201701010952113573528185799=10000100268=1279=1269=148=17359555=6SZ683=355326270=10221.0271=21346=61023=910=154
1128=99=18035=X49=SAMPLE75=2017010134=293552=2017010109132136653930560=201701010913213665393055799=10000100268=1279=1269=048=17359555=6SZ683=355327270=10204.0271=4346=21023=810=096
1128=99=18035=X49=SAMPLE75=2017010134=156052=2017010100081576290068260=201701010008157629006825799=10000100268=1279=1269=048=17359555=6SZ683=355328270=10211.0271=4346=31023=110=077
1128=99=18035=X49=SAMPLE75=2017010134=119652=2017010102320019027280260=201701010232001902728025799=10000100268=1279=1269=048=17359555=6SZ683=355329270=10210.0271=4346=21023=210=089
1128=99=18135=X49=SAMPLE75=2017010134=78252=2017010104245454594096360=201701010424545459409635799=10000100268=1279=1269=048=17359555=6SZ683=355330270=10203.0271=34346=31023=910=127
1128=99=18035=X49=SAMPLE75=2017010134=294652=2017010105575531236439660=201701010557553123643965799=10000100268=1279=1269=148=17359555=6SZ683=355331270=10218.0271=4346=21023=610=102
1128=99=18035=X49=SAMPLE75=2017010134=119952=2017010101113612700298760=201701010111361270029875799=10000100268=1279=1269=048=17359555=6SZ683=355332270=10203.0271=4346=21023=910=074
1128=99=18135=X49=SAMPLE75=2017010134=119152=2017010108152699396554360=201701010815269939655435799=10000100268=1279=1269=048=17359555=6SZ683=355333270=10207.0271=15346=71023=510=130
1128=99=18135=X49=SAMPLE75=2017010134=27552=2017010109433748063911660=201701010943374806391165799=10000100268=1279=1269=148=17359555=6SZ683=355334270=10219.0271=59346=91023=710=156
1128=99=18135=X49=SAMPLE75=2017010134=135952=2017010111344588065050960=201701011134458806505095799=10000100268=1279=1269=048=17359555=6SZ683=355335270=10203.0271=34346=31023=910=141
1128=99=18235=X49=SAMPLE75=2017010134=186352=2017010107123401142924260=201701010712340114292425799=10000100268=1279=1269=048=17359555=6SZ683=355336270=10202.0271=52346=91023=1010=216
1128=99=18135=X49=SAMPLE75=2017010134=482552=2017010109113504136661860=201701010911350413666185799=10000100268=1279=1269=048=17359555=6SZ683=355337270=10207.0271=45346=81023=510=136
1128=99=18235=X49=SAMPLE75=2017010134=144752=2017010104245981023530660=201701010424598102353065799=10000100268=1279=1269=048=17359555=6SZ683=355338270=10202.0271=22346=81023=1010=174
1128=99=18135=X49=SAMPLE75=2017010134=309752=2017010111143260532058360=201701011114326053205835799=10000100268=1279=1269=148=17359555=6SZ683=355339270=10219.0271=29346=81023=710=170
1128=99=18135=X49=SAMPLE75=2017010134=131852=2017010107191832031780760=201701010719183203178075799=10000100268=1279=1269=048=17359555=6SZ683=355340270=10205.0271=29346=81023=710=130
1128=99=18135=X49=SAMPLE75=2017010134=461452=2017010107560072893383660=201701010756007289338365799=10000100268=1279=1269=048=17359555=6SZ683=355341270=10203.0271=42346=41023=910=139
1128=99=18135=X49=SAMPLE75=2017010134=167352=2017010108114730191721260=201701010811473019172125799=10000100268=1279=1269=048=17359555=6SZ683=355342270=10203.0271=12346=31023=910=150
1128=99=18135=X49=SAMPLE75=2017010134=497152=2017010105234921870296260=201701010523492187029625799=10000100268=1279=1269=148=17359555=6SZ683=355343270=10219.0271=59346=91023=710=153
1128=99=18135=X49=SAMPLE75=2017010134=417952=2017010108030678768229860=201701010803067876822985799=10000100268=1279=1269=148=17359555=6SZ683=355344270=10219.0271=29346=81023=710=173
1128=99=18135=X49=SAMPLE75=2017010134=326852=2017010100293178434828460=201701010029317843482845799=10000100268=1279=1269=148=17359555=6SZ683=355345270=10219.0271=21346=71023=710=157
1128=99=18135=X49=SAMPLE75=2017010134=137352=2017010103452356699920860=201701010345235669992085799=10000100268=1279=1269=048=17359555=6SZ683=355346270=10203.0271=42346=41023=910=143
1128=99=18135=X49=SAMPLE75=2017010134=461952=2017010105574929211865060=201701010557492921186505799=10000100268=1279=1269=048=17359555=6SZ683=355347270=10203.0271=12346=31023=910=178
1128=99=18135=X49=SAMPLE75=2017010134=495152=2017010112291018282934560=201701011229101828293455799=10000100268=1279=1269=148=17359555=6SZ683=355348270=10219.0271=51346=81023=710=181
1128=99=18135=X49=SAMPLE75=2017010134=79752=2017010113142223853437760=201701011314222385343775799=10000100268=1279=1269=048=17359555=6SZ683=355349270=10203.0271=42346=41023=910=161
1128=99=18135=X49=SAMPLE75=2017010134=271352=2017010109550913508041260=201701010955091350804125799=10000100268=1279=1269=048=17359555=6SZ683=355350270=10203.0271=12346=31023=910=169
1128=99=18135=X49=SAMPLE75=2017010134=187952=2017010113341816620404660=201701011334181662040465799=10000100268=1279=1269=148=17359555=6SZ683=355351270=10219.0271=21346=71023=710=138
1128=99=18135=X49=SAMPLE75=2017010134=475052=2017010100355324542110460=201701010035532454211045799=10000100268=1279=1269=048=17359555=6SZ683=355352270=10207.0271=15346=71023=510=159
1128=99=18035=X49=SAMPLE75=2017010134=459652=2017010112101873726201360=201701011210187372620135799=10000100268=1279=1269=048=17359555=6SZ683=355353270=10208.0271=7346=41023=410=090
1128=99=18135=X49=SAMPLE75=2017010134=219852=2017010110315918308844860=201701011031591830884485799=10000100268=1279=1269=148=17359555=6SZ683=355354270=10219.0271=51346=81023=710=155
1128=99=18135=X49=SAMPLE75=2017010134=54752=2017010112273459684331760=201701011227345968433175799=10000100268=1279=1269=048=17359555=6SZ683=355355270=10204.0271=34346=31023=810=161
1128=99=18135=X49=SAMPLE75=2017010134=262652=2017010109492290045243560=201701010949229004524355799=10000100268=1279=1269=048=17359555=6SZ683=355356270=10207.0271=45346=81023=510=172
1128=99=18135=X49=SAMPLE75=2017010134=257352=2017010108443218938872860=201701010844321893887285799=10000100268=1279=1269=048=17359555=6SZ683=355357270=10205.0271=59346=91023=710=168
1128=99=18035=X49=SAMPLE75=2017010134=470152=2017010103355817870452360=201701010335581787045235799=10000100268=1279=1269=148=17359555=6SZ683=355358270=10214.0271=8346=61023=210=068
1128=99=18135=X49=SAMPLE75=2017010134=41952=2017010105572422597038060=201701010557242259703805799=10000100268=1279=1269=148=17359555=6SZ683=355359270=10219.0271=21346=71023=710=162
1128=99=18035=X49=SAMPLE75=2017010134=482252=2017010101224902559336460=201701010122490255933645799=10000100268=1279=1269=048=17359555=6SZ683=355360270=10204.0271=4346=21023=810=106
1128=99=18135=X49=SAMPLE75=2017010134=289452=2017010103424267366885960=201701010342426736688595799=10000100268=1279=1269=048=17359555=6SZ683=355361270=10205.0271=29346=81023=710=157
1128=99=18135=X49=SAMPLE75=2017010134=308552=2017010104233242919545260=201701010423324291954525799=10000100268=1279=1269=148=17359555=6SZ683=355362270=10219.0271=51346=81023=710=144
1128=99=18035=X49=SAMPLE75=2017010134=188052=2017010100192909325939560=201701010019290932593955799=10000100268=1279=1269=148=17359555=6SZ683=355363270=10217.0271=3346=11023=510=084
1128=99=18135=X49=SAMPLE75=2017010134=214052=2017010103442657282976160=201701010344265728297615799=10000100268=1279=1269=148=17359555=6SZ683=355364270=10221.0271=51346=71023=910=142
1128=99=18135=X49=SAMPLE75=2017010134=98152=2017010104475665947753260=201701010447566594775325799=10000100268=1279=1269=048=17359555=6SZ683=355365270=10205.0271=59346=91023=710=156
1128=99=18135=X49=SAMPLE75=2017010134=467752=2017010109523439783055160=201701010952343978305515799=10000100268=1279=1269=148=17359555=6SZ683=355366270=10219.0271=21346=71023=710=187
1128=99=20835=X49=SAMPLE75=2017010134=86452=2017010100561547743159660=201701010056154774315965799=00000001268=1279=0269=248=17359555=6SZ683=355367270=10213.0271=1346=25797=137705=237=032=137=032=110=073
1128=99=15635=X49=SAMPLE75=2017010134=145752=2017010101572237471621060=201701010157223747162105799=00000010268=1279=0269=e48=17359555=6SZ683=355368271=1610=092
1128=99=25335=X49=SAMPLE75=2017010134=279152=2017010103364493097179160=201701010336449309717915799=10000100268=2279=2269=148=17359555=6SZ683=355369270=10213.0271=1346=11023=1279=0269=148=17359555=6SZ683=355370270=10223.0271=17346=41023=1010=236
1128=99=17935=X49=SAMPLE75=2017010134=7452=2017010109433744581296860=201701010943374458129685799=10000100268=1279=0269=048=17360055=6SH783=99078270=10265.0271=3346=11023=110=031
1128=99=17935=X49=SAMPLE75=2017010134=84052=2017010102594106199677960=201701010259410619967795799=10000100268=1279=0269=048=17360055=6SH783=99079270=10264.0271=3346=11023=210=021
1128=99=25135=X49=SAMPLE75=2017010134=489852=2017010103282551329513160=201701010328255132951315799=10000100268=2279=1269=048=17359555=6SZ683=355371270=10209.0271=5346=31023=3279=1269=048=17359555=6SZ683=355372270=10208.0271=6346=31023=410=142
1128=99=18035=X49=SAMPLE75=2017010134=70452=2017010102543911850498960=201701010254391185049895799=10000100268=1279=1269=148=17359555=6SZ683=355373270=10214.0271=9346=71023=110=072
1128=99=18135=X49=SAMPLE75=2017010134=272252=2017010110140308351666360=201701011014030835166635799=10000100268=1279=1269=148=17359555=6SZ683=355374270=10217.0271=33346=21023=410=166
1128=99=18135=X49=SAMPLE75=2017010134=230552=2017010102293506348893360=201701010229350634889335799=10000100268=1279=1269=148=17359555=6SZ683=355375270=10221.0271=21346=61023=810=164
1128=99=25135=X49=SAMPLE75=2017010134=244552=2017010110421016050452460=201701011042101605045245799=10000100268=2279=2269=048=17360055=6SH783=99080270=10265.0271=3346=11023=1279=0269=048=17360055=6SH783=99081270=10255.0271=53346=21023=1010=091
1128=99=25035=X49=SAMPLE75=2017010134=339752=2017010101001920239426460=201701010100192023942645799=10000100268=2279=2269=048=17360055=6SH783=99082270=10264.0271=3346=11023=1279=0269=048=17360055=6SH783=99083270=10254.0271=3346=11023=1010=036
1128=99=18035=X49=SAMPLE75=2017010134=147552=2017010112245996025952160=201701011224599602595215799=10000100268=1279=1269=148=17359555=6SZ683=355376270=10217.0271=3346=11023=410=114
1128=99=18135=X49=SAMPLE75=2017010134=406152=2017010101354011901996960=201701010135401190199695799=10000100268=1279=1269=148=17359555=6SZ683=355377270=10222.0271=33346=21023=910=185
1128=99=18135=X49=SAMPLE75=2017010134=141952=2017010105065755537029460=201701010506575553702945799=10000100268=1279=1269=048=17359555=6SZ683=355378270=10205.0271=29346=81023=710=195
1128=99=18135=X49=SAMPLE75=2017010134=395752=2017010114014283967637760=201701011401428396763775799=10000100268=1279=1269=148=17359555=6SZ683=355379270=10217.0271=33346=21023=410=191
1128=99=18135=X49=SAMPLE75=2017010134=431352=2017010109371991684335460=201701010937199168433545799=10000100268=1279=1269=148=17359555=6SZ683=355380270=10219.0271=51346=81023=610=176
1128=99=18035=X49=SAMPLE75=2017010134=310452=2017010103413592611537560=201701010341359261153755799=10000100268=1279=1269=148=17359555=6SZ683=355381270=10222.0271=3346=11023=910=119
1128=99=18135=X49=SAMPLE75=2017010134=62652=2017010103385398181318460=201701010338539818131845799=10000100268=1279=1269=048=17359555=6SZ683=355382270=10205.0271=59346=91023=710=195
1128=99=18135=X49=SAMPLE75=2017010134=439652=2017010106055786475928160=201701010605578647592815799=10000100268=1279=1269=048=17359555=6SZ683=355383270=10205.0271=29346=81023=710=179
1128=99=18035=X49=SAMPLE75=2017010134=223952=2017010107173981686874160=201701010717398168687415799=10000100268=1279=1269=048=17359555=6SZ683=355384270=10211.0271=3346=21023=110=088
1128=99=18135=X49=SAMPLE75=2017010134=9752=2017010101163554744059160=201701010116355474405915799=10000100268=1279=1269=048=17359555=6SZ683=355385270=10205.0271=59346=91023=710=193
1128=99=18235=X49=SAMPLE75=2017010134=398452=2017010107434001362195760=201701010743400136219575799=10000100268=1279=1269=048=17359555=6SZ683=355386270=10202.0271=52346=91023=1010=183
1128=99=18135=X49=SAMPLE75=2017010134=148552=2017010103284509957192360=201701010328450995719235799=10000100268=1279=1269=148=17359555=6SZ683=355387270=10219.0271=21346=71023=610=138
1128=99=18135=X49=SAMPLE75=2017010134=2752=2017010110332064152445760=201701011033206415244575799=10000100268=1279=1269=048=17359555=6SZ683=355388270=10207.0271=15346=71023=510=163
1128=99=18135=X49=SAMPLE75=2017010134=364352=2017010108372970437823660=201701010837297043782365799=10000100268=1279=1269=048=17359555=6SZ683=355389270=10204.0271=34346=31023=810=154
1128=99=18235=X49=SAMPLE75=2017010134=467752=2017010109520003746093160=201701010952000374609315799=10000100268=1279=1269=048=17359555=6SZ683=355390270=10202.0271=22346=81023=1010=193
1128=99=18135=X49=SAMPLE75=2017010134=139852=2017010108151257529108660=201701010815125752910865799=10000100268=1279=1269=148=17359555=6SZ683=355391270=10219.0271=51346=81023=610=145
1128=99=18035=X49=SAMPLE75=2017010134=417652=2017010105390321259847960=201701010539032125984795799=10000100268=1279=1269=048=17359555=6SZ683=355392270=10204.0271=4346=21023=810=090
1128=99=18135=X49=SAMPLE75=2017010134=323152=2017010111394107412661560=201701011139410741266155799=10000100268=1279=1269=048=17359555=6SZ683=355393270=10207.0271=45346=81023=510=167
1128=99=18135=X49=SAMPLE75=2017010134=320652=2017010105160530683493460=201701010516053068349345799=10000100268=1279=1269=148=17359555=6SZ683=355394270=10219.0271=21346=71023=610=170
1128=99=18135=X49=SAMPLE75=2017010134=405452=2017010112113075395179560=201701011211307539517955799=10000100268=1279=1269=048=17359555=6SZ683=355395270=10205.0271=29346=81023=710=149
1128=99=18135=X49=SAMPLE75=2017010134=365352=2017010111071000732836560=201701011107100073283655799=10000100268=1279=1269=148=17359555=6SZ683=355396270=10220.0271=34346=31023=710=159
1128=99=18135=X49=SAMPLE75=2017010134=360952=2017010112112023859283260=201701011211202385928325799=10000100268=1279=1269=048=17359555=6SZ683=355397270=10205.0271=59346=91023=710=175
1128=99=18135=X49=SAMPLE75=2017010134=40552=2017010102312473323617760=201701010231247332361775799=10000100268=1279=1269=048=17359555=6SZ683=355398270=10207.0271=15346=71023=510=142
1128=99=18135=X49=SAMPLE75=2017010134=192552=2017010112525561180289560=201701011252556118028955799=10000100268=1279=1269=048=17359555=6SZ683=355399270=10204.0271=34346=31023=810=138
1128=99=18135=X49=SAMPLE75=2017010134=262052=2017010112574840909133960=201701011257484090913395799=10000100268=1279=1269=048=17359555=6SZ683=355400270=10207.0271=45346=81023=510=171
1128=99=18035=X49=SAMPLE75=2017010134=347752=2017010101550309717591460=201701010155030971759145799=10000100268=1279=1269=048=17359555=6SZ683=355401270=10204.0271=4346=21023=810=086
1128=99=18035=X49=SAMPLE75=2017010134=297752=2017010101060610536128060=201701010106061053612805799=10000100268=1279=1269=148=17359555=6SZ683=355402270=10220.0271=4346=21023=710=081
1128=99=18135=X49=SAMPLE75=2017010134=470752=2017010100455272564200560=201701010045527256420055799=10000100268=1279=1269=148=17359555=6SZ683=355403270=10219.0271=51346=81023=610=148
1128=99=18135=X49=SAMPLE75=2017010134=380952=2017010110211946696207460=201701011021194669620745799=10000100268=1279=1269=048=17359555=6SZ683=355404270=10205.0271=29346=81023=710=160
1128=99=18135=X49=SAMPLE75=2017010134=144452=2017010103401838210051160=201701010340183821005115799=10000100268=1279=1269=048=17359555=6SZ683=355405270=10206.0271=34346=31023=610=172
1128=99=18235=X49=SAMPLE75=2017010134=165352=2017010104190349199054660=201701010419034919905465799=10000100268=1279=1269=048=17359555=6SZ683=355406270=10202.0271=52346=91023=1010=202
1128=99=18135=X49=SAMPLE75=2017010134=386652=2017010105282790999847360=201701010528279099984735799=10000100268=1279=1269=148=17359555=6SZ683=355407270=10221.0271=13346=51023=810=143
1128=99=18135=X49=SAMPLE75=2017010134=44152=2017010105385468187284360=201701010538546818728435799=10000100268=1279=1269=148=17359555=6SZ683=355408270=10223.0271=9346=31023=1010=136
1128=99=18135=X49=SAMPLE75=2017010134=30352=2017010114010225197483860=201701011401022519748385799=10000100268=1279=1269=048=17359555=6SZ683=355409270=10205.0271=21346=71023=710=137
1128=99=18035=X49=SAMPLE75=2017010134=207152=2017010112425330577145260=201701011242533057714525799=10000100268=1279=1269=048=17359555=6SZ683=355410270=10203.0271=4346=21023=910=071
1128=99=18035=X49=SAMPLE75=2017010134=219852=2017010113340921727739060=201701011334092172773905799=10000100268=1279=1269=048=17359555=6SZ683=355411270=10211.0271=4346=31023=110=094
1128=99=18035=X49=SAMPLE75=2017010134=410852=2017010114192154504904660=201701011419215450490465799=10000100268=1279=1269=048=17359555=6SZ683=355412270=10206.0271=4346=21023=610=108
1128=99=18135=X49=SAMPLE75=2017010134=378852=2017010113594239511548360=201701011359423951154835799=10000100268=1279=1269=148=17359555=6SZ683=355413270=10219.0271=21346=71023=610=165
1128=99=18135=X49=SAMPLE75=2017010134=298652=2017010104391154697939860=201701010439115469793985799=10000100268=1279=1269=048=17359555=6SZ683=355414270=10206.0271=34346=31023=610=158
1128=99=18135=X49=SAMPLE75=2017010134=389152=2017010101231497674662360=201701010123149767466235799=10000100268=1279=1269=148=17359555=6SZ683=355415270=10219.0271=51346=81023=610=171
1128=99=18035=X49=SAMPLE75=2017010134=112152=2017010104402895456558560=201701010440289545655855799=10000100268=1279=1269=048=17359555=6SZ683=355416270=10206.0271=4346=21023=610=114
1128=99=18135=X49=SAMPLE75=2017010134=9852=2017010102210369882413260=201701010221036988241325799=10000100268=1279=1269=048=17359555=6SZ683=355417270=10206.0271=34346=31023=610=163
1128=99=18135=X49=SAMPLE75=2017010134=64152=2017010103011322242568060=201701010301132224256805799=10000100268=1279=1269=148=17359555=6SZ683=355418270=10219.0271=21346=71023=610=165
1128=99=18135=X49=SAMPLE75=2017010134=284052=2017010105590158266251760=201701010559015826625175799=10000100268=1279=1269=148=17359555=6SZ683=355419270=10220.0271=34346=31023=710=171
1128=99=18035=X49=SAMPLE75=2017010134=486352=2017010101252677678474360=201701010125267767847435799=10000100268=1279=1269=148=17359555=6SZ683=355420270=10220.0271=4346=21023=710=101
1128=99=18135=X49=SAMPLE75=2017010134=117152=2017010100214463393197660=201701010021446339319765799=10000100268=1279=1269=148=17359555=6SZ683=355421270=10219.0271=51346=81023=610=151
1128=99=18135=X49=SAMPLE75=2017010134=398952=2017010113191788950772060=201701011319178895077205799=10000100268=1279=1269=148=17359555=6SZ683=355422270=10219.0271=21346=71023=610=175
1128=99=18035=X49=SAMPLE75=2017010134=402852=2017010111461059753507860=201701011146105975350785799=10000100268=1279=1269=048=17359555=6SZ683=355423270=10206.0271=4346=21023=610=132
1128=99=18135=X49=SAMPLE75=2017010134=370852=2017010109015763850373860=201701010901576385037385799=10000100268=1279=1269=148=17359555=6SZ683=355424270=10219.0271=51346=81023=610=179
1128=99=18135=X49=SAMPLE75=2017010134=493652=2017010114255465227611460=201701011425546522761145799=10000100268=1279=1269=048=17359555=6SZ683=355425270=10206.0271=34346=31023=610=178
1128=99=18135=X49=SAMPLE75=2017010134=471752=2017010113180914470152060=201701011318091447015205799=10000100268=1279=1269=148=17359555=6SZ683=355426270=10219.0271=21346=71023=610=184
1128=99=18135=X49=SAMPLE75=2017010134=90552=2017010106110050210594260=201701010611005021059425799=10000100268=1279=1269=148=17359555=6SZ683=355427270=10219.0271=51346=81023=610=192
1128=99=18135=X49=SAMPLE75=2017010134=168052=2017010109524708898235060=201701010952470889823505799=10000100268=1279=1269=148=17359555=6SZ683=355428270=10219.0271=21346=71023=610=185
1128=99=18135=X49=SAMPLE75=2017010134=221252=2017010112390747096904460=201701011239074709690445799=10000100268=1279=1269=148=17359555=6SZ683=355429270=10219.0271=51346=81023=610=172
1128=99=18135=X49=SAMPLE75=2017010134=195252=2017010110163716860711960=201701011016371686071195799=10000100268=1279=1269=148=17359555=6SZ683=355430270=10219.0271=21346=71023=610=171
1128=99=18135=X49=SAMPLE75=2017010134=16252=2017010101242825977637560=201701010124282597763755799=10000100268=1279=1269=148=17359555=6SZ683=355431270=10219.0271=51346=81023=610=184
1128=99=18135=X49=SAMPLE75=2017010134=387852=2017010110100992380649060=201701011010099238064905799=10000100268=1279=1269=148=17359555=6SZ683=355432270=10219.0271=21346=71023=610=173
1128=99=18135=X49=SAMPLE75=2017010134=206752=2017010106460542473699960=201701010646054247369995799=10000100268=1279=1269=148=17359555=6SZ683=355433270=10219.0271=51346=81023=610=183
1128=99=18135=X49=SAMPLE75=2017010134=482152=2017010113482634528965360=201701011348263452896535799=10000100268=1279=1269=148=17359555=6SZ683=355434270=10219.0271=21346=71023=610=193
1128=99=18135=X49=SAMPLE75=2017010134=216852=2017010113091857406606460=201701011309185740660645799=10000100268=1279=1269=148=17359555=6SZ683=355435270=10219.0271=51346=81023=610=215
1128=99=18035=X49=SAMPLE75=2017010134=183252=2017010103443005692700460=201701010344300569270045799=10000100268=1279=1269=048=17359555=6SZ683=355436270=10206.0271=4346=21023=610=125
1128=99=18135=X49=SAMPLE75=2017010134=425352=2017010100413690126553160=201701010041369012655315799=10000100268=1279=1269=048=17359555=6SZ683=355437270=10206.0271=34346=31023=610=157
1128=99=18135=X49=SAMPLE75=2017010134=119252=2017010110345245632248260=201701011034524563224825799=10000100268=1279=1269=148=17359555=6SZ683=355438270=10219.0271=21346=71023=610=171
1128=99=18035=X49=SAMPLE75=2017010134=334752=2017010107442801946368460=201701010744280194636845799=10000100268=1279=1269=048=17359555=6SZ683=355439270=10206.0271=4346=21023=610=119
1128=99=18135=X49=SAMPLE75=2017010134=202352=2017010113372984853500860=201701011337298485350085799=10000100268=1279=1269=148=17359555=6SZ683=355440270=10219.0271=51346=81023=610=162
1128=99=18135=X49=SAMPLE75=2017010134=445352=2017010110071715919915860=201701011007171591991585799=10000100268=1279=1269=048=17359555=6SZ683=355441270=10206.0271=34346=31023=610=153
1128=99=18135=X49=SAMPLE75=2017010134=214352=2017010109490792693441760=201701010949079269344175799=10000100268=1279=1269=148=17359555=6SZ683=355442270=10219.0271=21346=71023=610=167
1128=99=18035=X49=SAMPLE75=2017010134=188252=2017010111085047751081760=201701011108504775108175799=10000100268=1279=1269=048=17359555=6SZ683=355443270=10206.0271=4346=21023=610=129
1128=99=18135=X49=SAMPLE75=2017010134=145752=2017010103461962187980460=201701010346196218798045799=10000100268=1279=1269=148=17359555=6SZ683=355444270=10219.0271=51346=81023=610=176
1128=99=18135=X49=SAMPLE75=2017010134=269052=2017010102285715380957260=201701010228571538095725799=10000100268=1279=1269=048=17359555=6SZ683=355445270=10206.0271=34346=31023=610=170
1128=99=18135=X49=SAMPLE75=2017010134=93252=2017010110075793129038560=201701011007579312903855799=10000100268=1279=1269=148=17359555=6SZ683=355446270=10219.0271=21346=71023=610=137
1128=99=18035=X49=SAMPLE75=2017010134=425852=2017010105510603626771060=201701010551060362677105799=10000100268=1279=1269=048=17359555=6SZ683=355447270=10208.0271=7346=41023=410=064
1128=99=18135=X49=SAMPLE75=2017010134=335752=2017010111514965767711660=201701011151496576771165799=10000100268=1279=1269=148=17359555=6SZ683=355448270=10216.0271=13346=51023=310=143
1128=99=18135=X49=SAMPLE75=2017010134=348852=2017010102262689952731560=201701010226268995273155799=10000100268=1279=1269=148=17359555=6SZ683=355449270=10219.0271=51346=81023=610=157
1128=99=18135=X49=SAMPLE75=2017010134=412952=2017010103212858974327960=201701010321285897432795799=10000100268=1279=1269=148=17359555=6SZ683=355450270=10219.0271=21346=71023=610=165
1128=99=18135=X49=SAMPLE75=2017010134=338252=2017010106070551475160860=201701010607055147516085799=10000100268=1279=1269=148=17359555=6SZ683=355451270=10219.0271=51346=81023=610=153
1128=99=18035=X49=SAMPLE75=2017010134=495252=2017010113262478153137060=201701011326247815313705799=10000100268=1279=1269=048=17359555=6SZ683=355452270=10206.0271=4346=21023=610=062
1128=99=18135=X49=SAMPLE75=2017010134=341952=2017010111524965138480160=201701011152496513848015799=10000100268=1279=1269=148=17359555=6SZ683=355453270=10219.0271=21346=71023=610=128
1128=99=18135=X49=SAMPLE75=2017010134=207052=2017010104172304012199360=201701010417230401219935799=10000100268=1279=1269=048=17359555=6SZ683=355454270=10206.0271=34346=31023=610=125
1128=99=18135=X49=SAMPLE75=2017010134=207852=2017010111044073283025760=201701011104407328302575799=10000100268=1279=1269=148=17359555=6SZ683=355455270=10219.0271=51346=81023=610=148
1128=99=18235=X49=SAMPLE75=2017010134=199252=2017010114260302887259860=201701011426030288725985799=10000100268=1279=1269=048=17359555=6SZ683=355456270=10202.0271=22346=81023=1010=203
1128=99=18235=X49=SAMPLE75=2017010134=79952=2017010112402343030092660=201701011240234303009265799=10000100268=1279=1269=048=17359555=6SZ683=355457270=10202.0271=52346=91023=1010=201
1128=99=18135=X49=SAMPLE75=2017010134=291552=2017010104543182196173260=201701010454318219617325799=10000100268=1279=1269=148=17359555=6SZ683=355458270=10219.0271=21346=71023=610=136
1128=99=18135=X49=SAMPLE75=2017010134=193452=2017010108161271291462060=201701010816127129146205799=10000100268=1279=1269=148=17359555=6SZ683=355459270=10219.0271=51346=81023=610=159
1128=99=18135=X49=SAMPLE75=2017010134=380552=2017010113223257493727860=201701011322325749372785799=10000100268=1279=1269=148=17359555=6SZ683=355460270=10219.0271=21346=71023=610=109
1128=99=18135=X49=SAMPLE75=2017010134=492552=2017010101252437368791460=201701010125243736879145799=10000100268=1279=1269=148=17359555=6SZ683=355461270=10219.0271=51346=81023=610=149
1128=99=18035=X49=SAMPLE75=2017010134=193252=2017010111533977021416060=201701011153397702141605799=10000100268=1279=1269=048=17359555=6SZ683=355462270=10206.0271=4346=21023=610=056
1128=99=18135=X49=SAMPLE75=2017010134=251652=2017010112564316591668460=201701011256431659166845799=10000100268=1279=1269=148=17359555=6SZ683=355463270=10219.0271=21346=71023=610=118
1128=99=18135=X49=SAMPLE75=2017010134=19952=2017010105593652833506760=201701010559365283350675799=10000100268=1279=1269=048=17359555=6SZ683=355464270=10206.0271=34346=31023=610=136
1128=99=18135=X49=SAMPLE75=2017010134=356152=2017010109263715027645260=201701010926371502764525799=10000100268=1279=1269=148=17359555=6SZ683=355465270=10219.0271=51346=81023=610=145
1128=99=18235=X49=SAMPLE75=2017010134=207252=2017010111255206719072860=201701011125520671907285799=10000100268=1279=1269=048=17359555=6SZ683=355466270=10202.0271=22346=81023=1010=169
1128=99=18135=X49=SAMPLE75=2017010134=327852=2017010102031759044457460=201701010203175904445745799=10000100268=1279=1269=148=17359555=6SZ683=355467270=10219.0271=21346=71023=610=163
1128=99=18235=X49=SAMPLE75=2017010134=210952=2017010113391044265544060=201701011339104426554405799=10000100268=1279=1269=048=17359555=6SZ683=355468270=10202.0271=52346=91023=1010=187
1128=99=18135=X49=SAMPLE75=2017010134=369952=2017010107035106717221260=201701010703510671722125799=10000100268=1279=1269=148=17359555=6SZ683=355469270=10219.0271=51346=81023=610=165
1128=99=18035=X49=SAMPLE75=2017010134=399652=2017010104165263657837360=201701010416526365783735799=10000100268=1279=1269=048=17359555=6SZ683=355470270=10206.0271=4346=21023=610=087
1128=99=18135=X49=SAMPLE75=2017010134=31752=2017010113343583627950860=201701011334358362795085799=10000100268=1279=1269=148=17359555=6SZ683=355471270=10219.0271=21346=71023=610=154
1128=99=18135=X49=SAMPLE75=2017010134=362052=2017010104130528679284660=201701010413052867928465799=10000100268=1279=1269=048=17359555=6SZ683=355472270=10206.0271=34346=31023=610=148
1128=99=18135=X49=SAMPLE75=2017010134=385952=2017010112412067226708460=201701011241206722670845799=10000100268=1279=1269=148=17359555=6SZ683=355473270=10219.0271=51346=81023=610=154
1128=99=18135=X49=SAMPLE75=2017010134=130052=2017010107044785628962560=201701010704478562896255799=10000100268=1279=1269=148=17359555=6SZ683=355474270=10219.0271=21346=71023=610=139
1128=99=18135=X49=SAMPLE75=2017010134=120252=2017010112250974959779460=201701011225097495977945799=10000100268=1279=1269=148=17359555=6SZ683=355475270=10219.0271=51346=81023=610=155
1128=99=18235=X49=SAMPLE75=2017010134=337552=2017010109291704094787960=201701010929170409478795799=10000100268=1279=1269=048=17359555=6SZ683=355476270=10202.0271=22346=81023=1010=207
1128=99=18135=X49=SAMPLE75=2017010134=208252=2017010113481005466541360=201701011348100546654135799=10000100268=1279=1269=148=17359555=6SZ683=355477270=10219.0271=21346=71023=610=164
1128=99=18135=X49=SAMPLE75=2017010134=380852=2017010106192634310014060=201701010619263431001405799=10000100268=1279=1269=148=17359555=6SZ683=355478270=10219.0271=51346=81023=610=156
1128=99=18235=X49=SAMPLE75=2017010134=222352=2017010103404885886051360=201701010340488588605135799=10000100268=1279=1269=048=17359555=6SZ683=355479270=10202.0271=52346=91023=1010=234
1128=99=25335=X49=SAMPLE75=2017010134=34252=2017010100212885592276760=201701010021288559227675799=10000100268=2279=1269=048=17359555=6SZ683=355480270=10208.0271=10346=51023=4279=1269=048=17359555=6SZ683=355481270=10207.0271=42346=71023=510=004
1128=99=18235=X49=SAMPLE75=2017010134=60252=2017010112290412090303660=201701011229041209030365799=10000100268=1279=1269=048=17359555=6SZ683=355482270=10202.0271=22346=81023=1010=185
1128=99=18035=X49=SAMPLE75=2017010134=160752=2017010106413790013696560=201701010641379001369655799=10000100268=1279=1269=048=17359555=6SZ683=355483270=10206.0271=4346=21023=610=081
1128=99=18135=X49=SAMPLE75=2017010134=55652=2017010113433716692141160=201701011343371669214115799=10000100268=1279=1269=048=17359555=6SZ683=355484270=10206.0271=34346=31023=610=137
1128=99=18135=X49=SAMPLE75=2017010134=102852=2017010114192883218131660=201701011419288321813165799=10000100268=1279=1269=148=17359555=6SZ683=355485270=10219.0271=21346=71023=610=158
1128=99=18035=X49=SAMPLE75=2017010134=21252=2017010112573926169614360=201701011257392616961435799=10000100268=1279=1269=048=17359555=6SZ683=355486270=10206.0271=4346=21023=610=083
1128=99=18135=X49=SAMPLE75=2017010134=399152=2017010109220617377424560=201701010922061737742455799=10000100268=1279=1269=148=17359555=6SZ683=355487270=10222.0271=33346=21023=910=131
1128=99=18135=X49=SAMPLE75=2017010134=16452=2017010110191304638981260=201701011019130463898125799=10000100268=1279=1269=048=17359555=6SZ683=355488270=10205.0271=51346=81023=710=151
1128=99=27035=X49=SAMPLE75=2017010134=238552=2017010112472226692906960=201701011247222669290695799=00000001268=1279=0269=248=17359555=6SZ683=355489270=10214.0271=8346=75797=137705=737=032=837=032=137=032=137=032=137=032=137=621180789662532=137=032=310=051
1128=99=15635=X49=SAMPLE75=2017010134=137552=2017010100504602901402160=201701010050460290140215799=00000010268=1279=0269=e48=17359555=6SZ683=355490271=2410=085
1128=99=18035=X49=SAMPLE75=2017010134=260252=2017010109164659133969960=201701010916465913396995799=00000100268=1279=1269=148=17359555=6SZ683=355491270=10214.0271=1346=11023=110=089
1128=99=16935=X49=SAMPLE75=2017010134=120252=2017010104130130579944560=201701010413013057994455799=10001000268=1279=0269=748=17359555=6SZ683=355492270=10214.0286=25510=151
1128=99=17935=X49=SAMPLE75=2017010134=408852=2017010100125596606797860=201701010012559660679785799=10000100268=1279=0269=048=17360055=6SH783=99084270=10265.0271=3346=11023=110=047
1128=99=25135=X49=SAMPLE75=2017010134=480952=2017010107540923803726760=201701010754092380372675799=10000100268=2279=2269=148=17360055=6SH783=99085270=10270.0271=3346=11023=1279=0269=148=17360055=6SH783=99086270=10280.0271=53346=11023=1010=091
1128=99=18035=X49=SAMPLE75=2017010134=241052=2017010103292043041334760=201701010329204304133475799=10000100268=1279=0269=048=17359555=6SZ683=355493270=10212.0271=1346=11023=110=088
1128=99=17935=X49=SAMPLE75=2017010134=439652=2017010102335758677111960=201701010233575867711195799=10000100268=1279=0269=048=17360055=6SH783=99087270=10264.0271=3346=11023=210=039
1128=99=18035=X49=SAMPLE75=2017010134=35552=2017010100213484859125760=201701010021348485912575799=10000100268=1279=1269=148=17359555=6SZ683=355494270=10217.0271=3346=11023=410=101
1128=99=18135=X49=SAMPLE75=2017010134=217352=2017010100292233320225360=201701010029223332022535799=10000100268=1279=1269=048=17359555=6SZ683=355495270=10205.0271=21346=71023=810=163
1128=99=25135=X49=SAMPLE75=2017010134=117552=2017010101044682532583860=201701010104468253258385799=10000100268=2279=2269=048=17360055=6SH783=99088270=10265.0271=3346=11023=1279=0269=048=17360055=6SH783=99089270=10255.0271=53346=21023=1010=111
1128=99=18135=X49=SAMPLE75=2017010134=380652=2017010114053842507252760=201701011405384250725275799=10000100268=1279=1269=148=17359555=6SZ683=355496270=10221.0271=43346=61023=810=149
1128=99=18035=X49=SAMPLE75=2017010134=319352=2017010111450329316632960=201701011145032931663295799=10000100268=1279=1269=148=17359555=6SZ683=355497270=10222.0271=3346=11023=910=108
1128=99=18035=X49=SAMPLE75=2017010134=231452=2017010109154639931422160=201701010915463993142215799=10000100268=1279=1269=048=17359555=6SZ683=355498270=10212.0271=2346=21023=110=077
1128=99=18035=X49=SAMPLE75=2017010134=44152=2017010113161034737853660=201701011316103473785365799=10000100268=1279=1269=148=17359555=6SZ683=355499270=10214.0271=2346=21023=110=081
1128=99=24935=X49=SAMPLE75=2017010134=59552=2017010110142934105092460=201701011014293410509245799=10000100268=2279=1269=048=17360055=6SH783=99090270=10263.0271=5346=21023=2279=1269=048=17360055=6SH783=99091270=10261.0271=3346=11023=410=243
1128=99=18135=X49=SAMPLE75=2017010134=96352=2017010110445017243787560=201701011044501724378755799=10000100268=1279=1269=148=17359555=6SZ683=355500270=10218.0271=34346=31023=510=146
1128=99=18135=X49=SAMPLE75=2017010134=457952=2017010108510256323011260=201701010851025632301125799=10000100268=1279=1269=048=17359555=6SZ683=355501270=10205.0271=51346=81023=810=132
1128=99=18135=X49=SAMPLE75=2017010134=197352=2017010104340344040896560=201701010434034404089655799=10000100268=1279=1269=148=17359555=6SZ683=355502270=10220.0271=34346=31023=710=145
1128=99=18135=X49=SAMPLE75=2017010134=116152=2017010107135734264883760=201701010713573426488375799=10000100268=1279=1269=048=17359555=6SZ683=355503270=10206.0271=34346=31023=710=136
1128=99=18135=X49=SAMPLE75=2017010134=220652=2017010109093882134321260=201701010909388213432125799=10000100268=1279=1269=048=17359555=6SZ683=355504270=10205.0271=21346=71023=810=116
1128=99=18135=X49=SAMPLE75=2017010134=186552=2017010107251214123030860=201701010725121412303085799=10000100268=1279=1269=148=17359555=6SZ683=355505270=10221.0271=13346=51023=810=123
1128=99=18035=X49=SAMPLE75=2017010134=218852=2017010105361207151847860=201701010536120715184785799=10000100268=1279=1269=048=17359555=6SZ683=355506270=10206.0271=4346=21023=710=084
1128=99=18035=X49=SAMPLE75=2017010134=312552=2017010104021268841640660=201701010402126884164065799=10000100268=1279=1269=148=17359555=6SZ683=355507270=10220.0271=4346=21023=710=087
1128=99=18135=X49=SAMPLE75=2017010134=319052=2017010106310412450671260=201701010631041245067125799=10000100268=1279=1269=048=17359555=6SZ683=355508270=10207.0271=12346=61023=610=129
1128=99=18135=X49=SAMPLE75=2017010134=233252=2017010104020229632576060=201701010402022963257605799=10000100268=1279=1269=048=17359555=6SZ683=355509270=10208.0271=40346=61023=510=134
1128=99=18135=X49=SAMPLE75=2017010134=234852=2017010102124133187997460=201701010212413318799745799=10000100268=1279=1269=148=17359555=6SZ683=355510270=10219.0271=51346=81023=610=126
1128=99=18135=X49=SAMPLE75=2017010134=334752=2017010106273531528396660=201701010627353152839665799=10000100268=1279=1269=048=17359555=6SZ683=355511270=10208.0271=10346=51023=510=142
1128=99=18135=X49=SAMPLE75=2017010134=301952=2017010110334271134273360=201701011033427113427335799=10000100268=1279=1269=148=17359555=6SZ683=355512270=10219.0271=21346=71023=610=121
1128=99=18135=X49=SAMPLE75=2017010134=422652=2017010114040663569139560=201701011404066356913955799=10000100268=1279=1269=048=17359555=6SZ683=355513270=10205.0271=51346=81023=810=130
1128=99=18135=X49=SAMPLE75=2017010134=440252=2017010104462833157216760=201701010446283315721675799=10000100268=1279=1269=048=17359555=6SZ683=355514270=10208.0271=40346=61023=510=116
1128=99=18135=X49=SAMPLE75=2017010134=101152=2017010106351007852607260=201701010635100785260725799=10000100268=1279=1269=148=17359555=6SZ683=355515270=10219.0271=51346=81023=610=136
1128=99=18135=X49=SAMPLE75=2017010134=381952=2017010112120396326768260=201701011212039632676825799=10000100268=1279=1269=048=17359555=6SZ683=355516270=10205.0271=21346=71023=810=157
1128=99=18135=X49=SAMPLE75=2017010134=85152=2017010113513863682709260=201701011351386368270925799=10000100268=1279=1269=148=17359555=6SZ683=355517270=10219.0271=21346=71023=610=133
1128=99=18235=X49=SAMPLE75=2017010134=379352=2017010108551471813064660=201701010855147181306465799=10000100268=1279=1269=048=17359555=6SZ683=355518270=10203.0271=34346=31023=1010=187
1128=99=18135=X49=SAMPLE75=2017010134=297152=2017010108154944502148160=201701010815494450214815799=10000100268=1279=1269=148=17359555=6SZ683=355519270=10220.0271=34346=31023=710=149
1128=99=18035=X49=SAMPLE75=2017010134=273052=2017010104164250434585260=201701010416425043458525799=10000100268=1279=1269=148=17359555=6SZ683=355520270=10218.0271=4346=21023=510=074
1128=99=18135=X49=SAMPLE75=2017010134=375052=2017010100522072686293760=201701010052207268629375799=10000100268=1279=1269=048=17359555=6SZ683=355521270=10208.0271=10346=51023=510=167
1128=99=18135=X49=SAMPLE75=2017010134=347652=2017010104331353334676760=201701010433135333467675799=10000100268=1279=1269=148=17359555=6SZ683=355522270=10222.0271=33346=21023=910=164
1128=99=18135=X49=SAMPLE75=2017010134=143852=2017010113375724160368960=201701011337572416036895799=10000100268=1279=1269=048=17359555=6SZ683=355523270=10204.0271=34346=31023=910=151
1128=99=18035=X49=SAMPLE75=2017010134=233352=2017010112260529304367660=201701011226052930436765799=10000100268=1279=1269=148=17359555=6SZ683=355524270=10220.0271=4346=21023=710=069
1128=99=18135=X49=SAMPLE75=2017010134=18052=2017010106091485564198060=201701010609148556419805799=10000100268=1279=1269=148=17359555=6SZ683=355525270=10219.0271=51346=81023=610=155
1128=99=18135=X49=SAMPLE75=2017010134=200752=2017010109182217197433660=201701010918221719743365799=10000100268=1279=1269=048=17359555=6SZ683=355526270=10203.0271=4346=21023=1010=154
1128=99=18135=X49=SAMPLE75=2017010134=383152=2017010105524341563259460=201701010552434156325945799=10000100268=1279=1269=048=17359555=6SZ683=355527270=10208.0271=40346=61023=510=160
1128=99=18035=X49=SAMPLE75=2017010134=479652=2017010110581471206869460=201701011058147120686945799=10000100268=1279=1269=148=17359555=6SZ683=355528270=10222.0271=3346=11023=910=102
1128=99=18135=X49=SAMPLE75=2017010134=199752=2017010110425985019521560=201701011042598501952155799=10000100268=1279=1269=148=17359555=6SZ683=355529270=10221.0271=43346=61023=810=132
1128=99=18135=X49=SAMPLE75=2017010134=445252=2017010100380466157703060=201701010038046615770305799=10000100268=1279=1269=148=17359555=6SZ683=355530270=10219.0271=21346=71023=610=145
1128=99=18135=X49=SAMPLE75=2017010134=394052=2017010110532437424084460=201701011053243742408445799=10000100268=1279=1269=148=17359555=6SZ683=355531270=10218.0271=34346=31023=510=128
1128=99=18135=X49=SAMPLE75=2017010134=346052=2017010112030977716070960=201701011203097771607095799=10000100268=1279=1269=148=17359555=6SZ683=355532270=10221.0271=13346=51023=810=153
1128=99=18035=X49=SAMPLE75=2017010134=350252=2017010107364927716830760=201701010736492771683075799=10000100268=1279=1269=048=17359555=6SZ683=355533270=10204.0271=4346=21023=910=093
1128=99=18035=X49=SAMPLE75=2017010134=438152=2017010100061302611055560=201701010006130261105555799=10000100268=1279=1269=148=17359555=6SZ683=355534270=10218.0271=4346=21023=510=057
1128=99=18135=X49=SAMPLE75=2017010134=231552=2017010113452356894256560=201701011345235689425655799=10000100268=1279=1269=048=17359555=6SZ683=355535270=10208.0271=10346=51023=510=144
1128=99=18235=X49=SAMPLE75=2017010134=444852=2017010104435509418403060=201701010443550941840305799=10000100268=1279=1269=048=17359555=6SZ683=355536270=10203.0271=34346=31023=1010=170
1128=99=18135=X49=SAMPLE75=2017010134=128152=2017010107531570002626860=201701010753157000262685799=10000100268=1279=1269=148=17359555=6SZ683=355537270=10218.0271=34346=31023=510=146
1128=99=18135=X49=SAMPLE75=2017010134=422852=2017010108244780987349060=201701010824478098734905799=10000100268=1279=1269=048=17359555=6SZ683=355538270=10208.0271=40346=61023=510=169
1128=99=18135=X49=SAMPLE75=2017010134=166152=2017010106434406307263060=201701010643440630726305799=10000100268=1279=1269=148=17359555=6SZ683=355539270=10221.0271=43346=61023=810=146
1128=99=18135=X49=SAMPLE75=2017010134=4352=2017010108590269527693460=201701010859026952769345799=10000100268=1279=1269=048=17359555=6SZ683=355540270=10208.0271=10346=51023=510=125
1128=99=18135=X49=SAMPLE75=2017010134=362652=2017010108404430660321860=201701010840443066032185799=10000100268=1279=1269=148=17359555=6SZ683=355541270=10221.0271=13346=51023=810=133
1128=99=18135=X49=SAMPLE75=2017010134=277052=2017010106274388408607960=201701010627438840860795799=10000100268=1279=1269=048=17359555=6SZ683=355542270=10209.0271=35346=41023=410=137
1128=99=25135=X49=SAMPLE75=2017010134=257552=2017010113500222267365360=201701011350022226736535799=10000100268=2279=1269=048=17359555=6SZ683=355543270=10212.0271=3346=31023=1279=1269=048=17359555=6SZ683=355544270=10208.0271=9346=41023=510=147
1128=99=18135=X49=SAMPLE75=2017010134=485152=2017010105430753141204760=201701010543075314120475799=10000100268=1279=1269=048=17359555=6SZ683=355545270=10206.0271=34346=31023=710=163
1128=99=18135=X49=SAMPLE75=2017010134=91052=2017010109063801324237160=201701010906380132423715799=10000100268=1279=1269=048=17359555=6SZ683=355546270=10203.0271=4346=21023=1010=147
1128=99=18135=X49=SAMPLE75=2017010134=327152=2017010107471540107725760=201701010747154010772575799=10000100268=1279=1269=148=17359555=6SZ683=355547270=10220.0271=34346=31023=710=169
1128=99=18035=X49=SAMPLE75=2017010134=328452=2017010109092281571102060=201701010909228157110205799=10000100268=1279=1269=048=17359555=6SZ683=355548270=10206.0271=4346=21023=710=110
1128=99=18135=X49=SAMPLE75=2017010134=292052=2017010108095166977012460=201701010809516697701245799=10000100268=1279=1269=048=17359555=6SZ683=355549270=10206.0271=34346=31023=710=160
1128=99=18035=X49=SAMPLE75=2017010134=50852=2017010113290250582623260=201701011329025058262325799=10000100268=1279=1269=148=17359555=6SZ683=355550270=10220.0271=4346=21023=710=084
1128=99=18135=X49=SAMPLE75=2017010134=126052=2017010112415763190776560=201701011241576319077655799=10000100268=1279=1269=148=17359555=6SZ683=355551270=10221.0271=43346=61023=810=136
1128=99=18135=X49=SAMPLE75=2017010134=329052=2017010107494904981417660=201701010749490498141765799=10000100268=1279=1269=148=17359555=6SZ683=355552270=10221.0271=13346=51023=810=121
1128=99=18135=X49=SAMPLE75=2017010134=49552=2017010100321444383666960=201701010032144438366695799=10000100268=1279=1269=148=17359555=6SZ683=355553270=10220.0271=34346=31023=710=140
1128=99=18035=X49=SAMPLE75=2017010134=72852=2017010103032282522647260=201701010303228252264725799=10000100268=1279=1269=048=17359555=6SZ683=355554270=10209.0271=5346=31023=410=083
1128=99=18135=X49=SAMPLE75=2017010134=135852=2017010107413250748426660=201701010741325074842665799=10000100268=1279=1269=048=17359555=6SZ683=355555270=10205.0271=51346=81023=810=150
1128=99=18135=X49=SAMPLE75=2017010134=79752=2017010103233463925906660=201701010323346392590665799=10000100268=1279=1269=048=17359555=6SZ683=355556270=10205.0271=21346=71023=810=126
1128=99=18135=X49=SAMPLE75=2017010134=135252=2017010111370361067840760=201701011137036106784075799=10000100268=1279=1269=048=17359555=6SZ683=355557270=10209.0271=35346=41023=410=151
1128=99=18035=X49=SAMPLE75=2017010134=4152=2017010112572492342239460=201701011257249234223945799=10000100268=1279=1269=048=17359555=6SZ683=355558270=10211.0271=3346=21023=210=065
1128=99=18035=X49=SAMPLE75=2017010134=335952=2017010105481973526318360=201701010548197352631835799=10000100268=1279=1269=048=17359555=6SZ683=355559270=10212.0271=4346=41023=110=084
1128=99=18035=X49=SAMPLE75=2017010134=336852=2017010111251536372432760=201701011125153637243275799=10000100268=1279=1269=048=17359555=6SZ683=355560270=10206.0271=4346=21023=710=058
1128=99=18035=X49=SAMPLE75=2017010134=382152=2017010105260445274165660=201701010526044527416565799=10000100268=1279=1269=148=17359555=6SZ683=355561270=10220.0271=4346=21023=710=066
1128=99=18135=X49=SAMPLE75=2017010134=124152=2017010110075455215202860=201701011007545521520285799=10000100268=1279=1269=048=17359555=6SZ683=355562270=10206.0271=34346=31023=710=141
1128=99=18135=X49=SAMPLE75=2017010134=255652=2017010105042511616775760=201701010504251161677575799=10000100268=1279=1269=148=17359555=6SZ683=355563270=10220.0271=34346=31023=710=130
1128=99=18035=X49=SAMPLE75=2017010134=32052=2017010111435109012594960=201701011143510901259495799=10000100268=1279=1269=048=17359555=6SZ683=355564270=10206.0271=4346=21023=710=090
1128=99=18135=X49=SAMPLE75=2017010134=12952=2017010112320588836210860=201701011232058883621085799=10000100268=1279=1269=048=17359555=6SZ683=355565270=10206.0271=34346=31023=710=128
1128=99=25235=X49=SAMPLE75=2017010134=363552=2017010101080587520105660=201701010108058752010565799=10000100268=2279=1269=048=17359555=6SZ683=355566270=10212.0271=3346=31023=1279=1269=048=17359555=6SZ683=355567270=10208.0271=10346=51023=510=155
1128=99=18035=X49=SAMPLE75=2017010134=79152=2017010110293729259028560=201701011029372925902855799=10000100268=1279=1269=048=17359555=6SZ683=355568270=10209.0271=5346=31023=410=105
1128=99=18035=X49=SAMPLE75=2017010134=105452=2017010107592415556015260=201701010759241555601525799=10000100268=1279=1269=048=17359555=6SZ683=355569270=10206.0271=4346=21023=710=087
1128=99=18035=X49=SAMPLE75=2017010134=300752=2017010111151844760042160=201701011115184476004215799=10000100268=1279=1269=148=17359555=6SZ683=355570270=10220.0271=4346=21023=710=070
1128=99=18135=X49=SAMPLE75=2017010134=272052=2017010108510520776853960=201701010851052077685395799=10000100268=1279=1269=048=17359555=6SZ683=355571270=10208.0271=40346=61023=510=145
1128=99=18135=X49=SAMPLE75=2017010134=179952=2017010110565614496572960=201701011056561449657295799=10000100268=1279=1269=048=17359555=6SZ683=355572270=10206.0271=34346=31023=710=117
1128=99=18135=X49=SAMPLE75=2017010134=414652=2017010108365218642946760=201701010836521864294675799=10000100268=1279=1269=148=17359555=6SZ683=355573270=10220.0271=34346=31023=710=154
1128=99=18035=X49=SAMPLE75=2017010134=46052=2017010106153475001166860=201701010615347500116685799=10000100268=1279=1269=048=17359555=6SZ683=355574270=10206.0271=4346=21023=710=075
1128=99=18135=X49=SAMPLE75=2017010134=325552=2017010106430246343762660=201701010643024634376265799=10000100268=1279=1269=048=17359555=6SZ683=355575270=10206.0271=34346=31023=710=130
1128=99=18035=X49=SAMPLE75=2017010134=148452=2017010107432583291994660=201701010743258329199465799=10000100268=1279=1269=148=17359555=6SZ683=355576270=10220.0271=4346=21023=710=061
1128=99=18135=X49=SAMPLE75=2017010134=212752=2017010110123724825773260=201701011012372482577325799=10000100268=1279=1269=148=17359555=6SZ683=355577270=10221.0271=43346=61023=810=140
1128=99=18135=X49=SAMPLE75=2017010134=296052=2017010114305800290381160=201701011430580029038115799=10000100268=1279=1269=148=17359555=6SZ683=355578270=10221.0271=13346=51023=810=151
1128=99=18135=X49=SAMPLE75=2017010134=90152=2017010107200814724123260=201701010720081472412325799=10000100268=1279=1269=148=17359555=6SZ683=355579270=10221.0271=43346=61023=810=137
1128=99=18135=X49=SAMPLE75=2017010134=309352=2017010105434690483259260=201701010543469048325925799=10000100268=1279=1269=148=17359555=6SZ683=355580270=10221.0271=13346=51023=810=131
1128=99=18135=X49=SAMPLE75=2017010134=495652=2017010100291054869891160=201701010029105486989115799=10000100268=1279=1269=148=17359555=6SZ683=355581270=10220.0271=34346=31023=710=119
1128=99=18035=X49=SAMPLE75=2017010134=229952=2017010110042695804747360=201701011004269580474735799=10000100268=1279=1269=148=17359555=6SZ683=355582270=10220.0271=4346=21023=710=083
1128=99=18035=X49=SAMPLE75=2017010134=357452=2017010100110132733783960=201701010011013273378395799=10000100268=1279=1269=048=17359555=6SZ683=355583270=10206.0271=4346=21023=710=086
1128=99=18135=X49=SAMPLE75=2017010134=129952=2017010100563013491916960=201701010056301349191695799=10000100268=1279=1269=148=17359555=6SZ683=355584270=10221.0271=43346=61023=810=140
1128=99=18135=X49=SAMPLE75=2017010134=181152=2017010109374700341754860=201701010937470034175485799=10000100268=1279=1269=048=17359555=6SZ683=355585270=10206.0271=34346=31023=710=160
1128=99=18135=X49=SAMPLE75=2017010134=461952=2017010112192846201972760=201701011219284620197275799=10000100268=1279=1269=148=17359555=6SZ683=355586270=10221.0271=13346=51023=810=157
1128=99=18135=X49=SAMPLE75=2017010134=201052=2017010106001296418668460=201701010600129641866845799=10000100268=1279=1269=148=17359555=6SZ683=355587270=10220.0271=34346=31023=710=144
1128=99=18035=X49=SAMPLE75=2017010134=240052=2017010102012071582391860=201701010201207158239185799=10000100268=1279=1269=148=17359555=6SZ683=355588270=10220.0271=4346=21023=710=092
1128=99=18035=X49=SAMPLE75=2017010134=321152=2017010105312640991251460=201701010531264099125145799=10000100268=1279=1269=048=17359555=6SZ683=355589270=10206.0271=4346=21023=710=079
1128=99=18135=X49=SAMPLE75=2017010134=389352=2017010101012986847149960=201701010101298684714995799=10000100268=1279=1269=048=17359555=6SZ683=355590270=10208.0271=10346=51023=510=130
1128=99=18135=X49=SAMPLE75=2017010134=26952=2017010105262644403821860=201701010526264440382185799=10000100268=1279=1269=048=17359555=6SZ683=355591270=10209.0271=35346=41023=410=121
1128=99=25135=X49=SAMPLE75=2017010134=327852=2017010103481892629880460=201701010348189262988045799=10000100268=2279=1269=048=17359555=6SZ683=355592270=10212.0271=4346=41023=1279=1269=048=17359555=6SZ683=355593270=10208.0271=9346=41023=510=117
1128=99=18035=X49=SAMPLE75=2017010134=98652=2017010103224104235023160=201701010322410423502315799=10000100268=1279=1269=048=17359555=6SZ683=355594270=10212.0271=7346=51023=110=082
1128=99=17935=X49=SAMPLE75=2017010134=167652=2017010101023071200292960=201701010102307120029295799=10000100268=1279=0269=048=17360055=6SH783=99092270=10265.0271=3346=11023=110=015
1128=99=24935=X49=SAMPLE75=2017010134=102052=2017010113124965320978560=201701011312496532097855799=10000100268=2279=1269=048=17360055=6SH783=99093270=10264.0271=5346=21023=2279=1269=048=17360055=6SH783=99094270=10262.0271=3346=11023=410=243
1128=99=18135=X49=SAMPLE75=2017010134=92952=2017010102470137345934160=201701010247013734593415799=10000100268=1279=1269=148=17359555=6SZ683=355595270=10220.0271=34346=31023=710=137
1128=99=18135=X49=SAMPLE75=2017010134=335952=2017010113331137469377960=201701011333113746937795799=10000100268=1279=1269=048=17359555=6SZ683=355596270=10206.0271=34346=31023=710=132
1128=99=18035=X49=SAMPLE75=2017010134=468652=2017010109141808104609660=201701010914180810460965799=10000100268=1279=1269=148=17359555=6SZ683=355597270=10220.0271=4346=21023=710=110
1128=99=18135=X49=SAMPLE75=2017010134=106552=2017010107454335605684660=201701010745433560568465799=10000100268=1279=1269=148=17359555=6SZ683=355598270=10220.0271=34346=31023=710=145
1128=99=18035=X49=SAMPLE75=2017010134=75052=2017010114233006896400460=201701011423300689640045799=10000100268=1279=1269=048=17359555=6SZ683=355599270=10206.0271=4346=21023=710=103
1128=99=18135=X49=SAMPLE75=2017010134=489852=2017010103114699823923160=201701010311469982392315799=10000100268=1279=1269=048=17359555=6SZ683=355600270=10206.0271=34346=31023=710=126
1128=99=18035=X49=SAMPLE75=2017010134=275952=2017010108455630635202460=201701010845563063520245799=10000100268=1279=1269=148=17359555=6SZ683=355601270=10220.0271=4346=21023=710=096
1128=99=18135=X49=SAMPLE75=2017010134=465952=2017010113094283621015460=201701011309428362101545799=10000100268=1279=1269=148=17359555=6SZ683=355602270=10220.0271=34346=31023=710=144
1128=99=18035=X49=SAMPLE75=2017010134=435952=2017010108473912956630260=201701010847391295663025799=10000100268=1279=1269=148=17359555=6SZ683=355603270=10220.0271=4346=21023=710=091
1128=99=18035=X49=SAMPLE75=2017010134=9652=2017010110180529770854060=201701011018052977085405799=10000100268=1279=1269=048=17359555=6SZ683=355604270=10209.0271=5346=31023=410=097
1128=99=25235=X49=SAMPLE75=2017010134=467852=2017010112582853079949160=201701011258285307994915799=10000100268=2279=1269=048=17359555=6SZ683=355605270=10212.0271=6346=41023=1279=1269=048=17359555=6SZ683=355606270=10208.0271=10346=51023=510=184
1128=99=18135=X49=SAMPLE75=2017010134=273052=2017010111483992293304660=201701011148399229330465799=10000100268=1279=1269=048=17359555=6SZ683=355607270=10205.0271=51346=81023=810=160
1128=99=25135=X49=SAMPLE75=2017010134=187852=2017010104584233844907160=201701010458423384490715799=10000100268=2279=1269=048=17359555=6SZ683=355608270=10210.0271=5346=31023=3279=1269=048=17359555=6SZ683=355609270=10209.0271=4346=21023=410=151
1128=99=18135=X49=SAMPLE75=2017010134=136352=2017010112562101965088360=201701011256210196508835799=10000100268=1279=1269=148=17359555=6SZ683=355610270=10220.0271=34346=31023=710=134
1128=99=18135=X49=SAMPLE75=2017010134=416852=2017010100560387604426960=201701010056038760442695799=10000100268=1279=1269=048=17359555=6SZ683=355611270=10208.0271=40346=61023=510=135
1128=99=18135=X49=SAMPLE75=2017010134=397052=2017010114055838474903360=201701011405583847490335799=10000100268=1279=1269=048=17359555=6SZ683=355612270=10205.0271=21346=71023=810=130
1128=99=25135=X49=SAMPLE75=2017010134=235052=2017010107531304301584360=201701010753130430158435799=10000100268=2279=1269=048=17359555=6SZ683=355613270=10210.0271=4346=21023=3279=1269=048=17359555=6SZ683=355614270=10209.0271=5346=31023=410=117
1128=99=18035=X49=SAMPLE75=2017010134=394152=2017010104210868579078060=201701010421086857907805799=10000100268=1279=1269=048=17359555=6SZ683=355615270=10206.0271=4346=21023=710=102
1128=99=18135=X49=SAMPLE75=2017010134=58452=2017010112121231875954160=201701011212123187595415799=10000100268=1279=1269=048=17359555=6SZ683=355616270=10206.0271=34346=31023=710=143
1128=99=18035=X49=SAMPLE75=2017010134=368452=2017010106235108630685160=201701010623510863068515799=10000100268=1279=1269=148=17359555=6SZ683=355617270=10220.0271=4346=21023=710=100
1128=99=18035=X49=SAMPLE75=2017010134=250552=2017010102042873852695760=201701010204287385269575799=10000100268=1279=1269=048=17359555=6SZ683=355618270=10206.0271=4346=21023=710=105
1128=99=18135=X49=SAMPLE75=2017010134=34652=2017010112104315268084360=201701011210431526808435799=10000100268=1279=1269=148=17359555=6SZ683=355619270=10220.0271=34346=31023=710=127
1128=99=18135=X49=SAMPLE75=2017010134=143352=2017010103421756438357860=201701010342175643835785799=10000100268=1279=1269=048=17359555=6SZ683=355620270=10206.0271=34346=31023=710=151
1128=99=18035=X49=SAMPLE75=2017010134=270752=2017010100583719580553960=201701010058371958055395799=10000100268=1279=1269=048=17359555=6SZ683=355621270=10206.0271=4346=21023=710=104
1128=99=18035=X49=SAMPLE75=2017010134=257552=2017010100025473596037760=201701010002547359603775799=10000100268=1279=1269=148=17359555=6SZ683=355622270=10220.0271=4346=21023=710=107
1128=99=18135=X49=SAMPLE75=2017010134=290952=2017010108553320565498560=201701010855332056549855799=10000100268=1279=1269=048=17359555=6SZ683=355623270=10206.0271=34346=31023=710=098
1128=99=18035=X49=SAMPLE75=2017010134=314152=2017010105475975553010560=201701010547597555301055799=10000100268=1279=1269=048=17359555=6SZ683=355624270=10206.0271=4346=21023=710=077
1128=99=18135=X49=SAMPLE75=2017010134=13852=2017010104095948807647760=201701010409594880764775799=10000100268=1279=1269=148=17359555=6SZ683=355625270=10221.0271=43346=61023=810=112
1128=99=18135=X49=SAMPLE75=2017010134=262052=2017010103355364287760260=201701010335536428776025799=10000100268=1279=1269=048=17359555=6SZ683=355626270=10206.0271=34346=31023=710=149
1128=99=18035=X49=SAMPLE75=2017010134=105552=2017010105470633917110260=201701010547063391711025799=10000100268=1279=1269=048=17359555=6SZ683=355627270=10206.0271=4346=21023=710=048
1128=99=18135=X49=SAMPLE75=2017010134=280952=2017010112401881456165660=201701011240188145616565799=10000100268=1279=1269=148=17359555=6SZ683=355628270=10221.0271=13346=51023=810=105
1128=99=18135=X49=SAMPLE75=2017010134=107852=2017010114291501826886160=201701011429150182688615799=10000100268=1279=1269=148=17359555=6SZ683=355629270=10220.0271=34346=31023=710=120
1128=99=18135=X49=SAMPLE75=2017010134=259152=2017010111280789274543860=201701011128078927454385799=10000100268=1279=1269=048=17359555=6SZ683=355630270=10206.0271=34346=31023=710=134
1128=99=18135=X49=SAMPLE75=2017010134=43652=2017010110383764290274660=201701011038376429027465799=10000100268=1279=1269=048=17359555=6SZ683=355631270=10207.0271=42346=71023=610=139
1128=99=18035=X49=SAMPLE75=2017010134=223152=2017010102384351240465460=201701010238435124046545799=10000100268=1279=1269=048=17359555=6SZ683=355632270=10206.0271=4346=21023=710=095
1128=99=18035=X49=SAMPLE75=2017010134=379052=2017010105235938301859260=201701010523593830185925799=10000100268=1279=1269=148=17359555=6SZ683=355633270=10220.0271=4346=21023=710=057
1128=99=18135=X49=SAMPLE75=2017010134=334752=2017010109462287313231360=201701010946228731323135799=10000100268=1279=1269=048=17359555=6SZ683=355634270=10207.0271=12346=61023=610=131
1128=99=18235=X49=SAMPLE75=2017010134=314052=2017010103264389707329260=201701010326438970732925799=10000100268=1279=1269=148=17359555=6SZ683=355635270=10223.0271=39346=41023=1010=177
1128=99=18135=X49=SAMPLE75=2017010134=304852=2017010106300410614663360=201701010630041061466335799=10000100268=1279=1269=048=17359555=6SZ683=355636270=10207.0271=42346=71023=610=151
1128=99=18135=X49=SAMPLE75=2017010134=273652=2017010102481198940931860=201701010248119894093185799=10000100268=1279=1269=148=17359555=6SZ683=355637270=10223.0271=9346=31023=1010=116
1128=99=18135=X49=SAMPLE75=2017010134=95952=2017010114061041356998560=201701011406104135699855799=10000100268=1279=1269=148=17359555=6SZ683=355638270=10220.0271=34346=31023=710=138
1128=99=18035=X49=SAMPLE75=2017010134=272552=2017010102432968293817560=201701010243296829381755799=10000100268=1279=1269=048=17359555=6SZ683=355639270=10212.0271=5346=31023=110=082
1128=99=25135=X49=SAMPLE75=2017010134=488252=2017010105380643102828460=201701010538064310282845799=10000100268=2279=2269=048=17360055=6SH783=99095270=10265.0271=3346=11023=1279=0269=048=17360055=6SH783=99096270=10255.0271=53346=21023=1010=097
1128=99=18035=X49=SAMPLE75=2017010134=239152=2017010109072327479247960=201701010907232747924795799=10000100268=1279=1269=148=17359555=6SZ683=355640270=10220.0271=4346=21023=710=082
1128=99=18135=X49=SAMPLE75=2017010134=120952=2017010100521762939500160=201701010052176293950015799=10000100268=1279=1269=048=17359555=6SZ683=355641270=10207.0271=12346=61023=610=148
1128=99=18135=X49=SAMPLE75=2017010134=422852=2017010110201397210418760=201701011020139721041875799=10000100268=1279=1269=148=17359555=6SZ683=355642270=10221.0271=43346=61023=810=138
1128=99=18135=X49=SAMPLE75=2017010134=465752=2017010108581972079625460=201701010858197207962545799=10000100268=1279=1269=048=17359555=6SZ683=355643270=10207.0271=42346=71023=610=146
1128=99=18135=X49=SAMPLE75=2017010134=122952=2017010107342341906857760=201701010734234190685775799=10000100268=1279=1269=148=17359555=6SZ683=355644270=10221.0271=13346=51023=810=130
1128=99=18135=X49=SAMPLE75=2017010134=135352=2017010106544843498727660=201701010654484349872765799=10000100268=1279=1269=148=17359555=6SZ683=355645270=10220.0271=34346=31023=710=115
1128=99=18035=X49=SAMPLE75=2017010134=446352=2017010106575571961019760=201701010657557196101975799=10000100268=1279=1269=148=17359555=6SZ683=355646270=10220.0271=4346=21023=710=098
1128=99=18135=X49=SAMPLE75=2017010134=49152=2017010109251953807670960=201701010925195380767095799=10000100268=1279=1269=148=17359555=6SZ683=355647270=10221.0271=43346=61023=810=142
1128=99=18135=X49=SAMPLE75=2017010134=284252=2017010102253853894894860=201701010225385389489485799=10000100268=1279=1269=148=17359555=6SZ683=355648270=10221.0271=13346=51023=810=114
1128=99=18135=X49=SAMPLE75=2017010134=76052=2017010113033006355168060=201701011303300635516805799=10000100268=1279=1269=148=17359555=6SZ683=355649270=10220.0271=34346=31023=710=119
1128=99=18135=X49=SAMPLE75=2017010134=150052=2017010112512875581417460=201701011251287558141745799=10000100268=1279=1269=048=17359555=6SZ683=355650270=10207.0271=12346=61023=610=120
1128=99=18135=X49=SAMPLE75=2017010134=119252=2017010101205937353872460=201701010120593735387245799=10000100268=1279=1269=048=17359555=6SZ683=355651270=10207.0271=42346=71023=610=145
1128=99=18035=X49=SAMPLE75=2017010134=230952=2017010105184349178055060=201701010518434917805505799=10000100268=1279=1269=148=17359555=6SZ683=355652270=10220.0271=4346=21023=710=085
1128=99=18135=X49=SAMPLE75=2017010134=156852=2017010102301224276707760=201701010230122427670775799=10000100268=1279=1269=048=17359555=6SZ683=355653270=10207.0271=12346=61023=610=136
1128=99=18135=X49=SAMPLE75=2017010134=130052=2017010111491614934488660=201701011149161493448865799=10000100268=1279=1269=148=17359555=6SZ683=355654270=10220.0271=34346=31023=710=149
1128=99=18135=X49=SAMPLE75=2017010134=181752=2017010100420800750197960=201701010042080075019795799=10000100268=1279=1269=048=17359555=6SZ683=355655270=10207.0271=42346=71023=610=136
1128=99=18035=X49=SAMPLE75=2017010134=432552=2017010108114357854157360=201701010811435785415735799=10000100268=1279=1269=148=17359555=6SZ683=355656270=10220.0271=4346=21023=710=098
1128=99=18135=X49=SAMPLE75=2017010134=411852=2017010104305463778948260=201701010430546377894825799=10000100268=1279=1269=048=17359555=6SZ683=355657270=10207.0271=12346=61023=610=172
1128=99=18135=X49=SAMPLE75=2017010134=408952=2017010113002316992291160=201701011300231699229115799=10000100268=1279=1269=148=17359555=6SZ683=355658270=10220.0271=34346=31023=710=130
1128=99=18135=X49=SAMPLE75=2017010134=367852=2017010109001188032258560=201701010900118803225855799=10000100268=1279=1269=048=17359555=6SZ683=355659270=10207.0271=42346=71023=610=127
1128=99=18035=X49=SAMPLE75=2017010134=143452=2017010106300706595586560=201701010630070659558655799=10000100268=1279=1269=148=17359555=6SZ683=355660270=10220.0271=4346=21023=710=089
1128=99=18135=X49=SAMPLE75=2017010134=403752=2017010103333554640727060=201701010333355464072705799=10000100268=1279=1269=148=17359555=6SZ683=355661270=10220.0271=34346=31023=710=129
1128=99=18035=X49=SAMPLE75=2017010134=180452=2017010113070270106984060=201701011307027010698405799=10000100268=1279=1269=148=17359555=6SZ683=355662270=10220.0271=4346=21023=710=087
1128=99=18135=X49=SAMPLE75=2017010134=198452=2017010103550508529781960=201701010355050852978195799=10000100268=1279=1269=048=17359555=6SZ683=355663270=10207.0271=12346=61023=610=161
1128=99=18135=X49=SAMPLE75=2017010134=447352=2017010101423060539951060=201701010142306053995105799=10000100268=1279=1269=148=17359555=6SZ683=355664270=10221.0271=43346=61023=810=181
1128=99=18135=X49=SAMPLE75=2017010134=7452=2017010106333864783899360=201701010633386478389935799=10000100268=1279=1269=048=17359555=6SZ683=355665270=10207.0271=42346=71023=610=152
1128=99=18135=X49=SAMPLE75=2017010134=404452=2017010100075346068373760=201701010007534606837375799=10000100268=1279=1269=148=17359555=6SZ683=355666270=10221.0271=13346=51023=810=152
1128=99=18135=X49=SAMPLE75=2017010134=14452=2017010106542764257308360=201701010654276425730835799=10000100268=1279=1269=148=17359555=6SZ683=355667270=10220.0271=34346=31023=710=160
1128=99=18035=X49=SAMPLE75=2017010134=65652=2017010110572196164877860=201701011057219616487785799=10000100268=1279=1269=148=17359555=6SZ683=355668270=10220.0271=4346=21023=710=117
1128=99=18135=X49=SAMPLE75=2017010134=401152=2017010112331974738456860=201701011233197473845685799=10000100268=1279=1269=148=17359555=6SZ683=355669270=10221.0271=43346=61023=810=135
1128=99=18035=X49=SAMPLE75=2017010134=397752=2017010100543783138502160=201701010054378313850215799=10000100268=1279=1269=048=17359555=6SZ683=355670270=10212.0271=6346=41023=110=036
1128=99=17935=X49=SAMPLE75=2017010134=228852=2017010111095324215329060=201701011109532421532905799=10000100268=1279=0269=048=17360055=6SH783=99097270=10265.0271=3346=11023=110=254
1128=99=18135=X49=SAMPLE75=2017010134=168152=2017010112201973624458160=201701011220197362445815799=10000100268=1279=1269=048=17359555=6SZ683=355671270=10207.0271=12346=61023=610=130
1128=99=18135=X49=SAMPLE75=2017010134=465352=2017010113101181362519960=201701011310118136251995799=10000100268=1279=1269=148=17359555=6SZ683=355672270=10220.0271=34346=31023=710=136
1128=99=18135=X49=SAMPLE75=2017010134=255552=2017010102135956512736160=201701010213595651273615799=10000100268=1279=1269=148=17359555=6SZ683=355673270=10221.0271=13346=51023=810=130
1128=99=18135=X49=SAMPLE75=2017010134=198552=2017010104565955523979960=201701010456595552397995799=10000100268=1279=1269=048=17359555=6SZ683=355674270=10207.0271=42346=71023=610=140
1128=99=18035=X49=SAMPLE75=2017010134=41152=2017010104533042910445960=201701010453304291044595799=10000100268=1279=1269=148=17359555=6SZ683=355675270=10220.0271=4346=21023=710=086
1128=99=18135=X49=SAMPLE75=2017010134=190252=2017010101443214398809460=201701010144321439880945799=10000100268=1279=1269=048=17359555=6SZ683=355676270=10207.0271=12346=61023=610=137
1128=99=18135=X49=SAMPLE75=2017010134=14352=2017010110183405761944060=201701011018340576194405799=10000100268=1279=1269=148=17359555=6SZ683=355677270=10221.0271=43346=61023=810=133
1128=99=18135=X49=SAMPLE75=2017010134=130352=2017010101132381917011160=201701010113238191701115799=10000100268=1279=1269=048=17359555=6SZ683=355678270=10207.0271=42346=71023=610=149
1128=99=18135=X49=SAMPLE75=2017010134=372652=2017010113412720057899260=201701011341272005789925799=10000100268=1279=1269=148=17359555=6SZ683=355679270=10221.0271=13346=51023=810=151
1128=99=18135=X49=SAMPLE75=2017010134=152952=2017010101463340543524760=201701010146334054352475799=10000100268=1279=1269=148=17359555=6SZ683=355680270=10220.0271=34346=31023=710=134
1128=99=18035=X49=SAMPLE75=2017010134=193252=2017010102560090970289960=201701010256009097028995799=10000100268=1279=1269=148=17359555=6SZ683=355681270=10220.0271=4346=21023=710=077
1128=99=18135=X49=SAMPLE75=2017010134=51252=2017010107112122036789160=201701010711212203678915799=10000100268=1279=1269=148=17359555=6SZ683=355682270=10221.0271=43346=61023=810=147
1128=99=18135=X49=SAMPLE75=2017010134=100752=2017010111025504508772560=201701011102550450877255799=10000100268=1279=1269=148=17359555=6SZ683=355683270=10221.0271=13346=51023=810=154
1128=99=18135=X49=SAMPLE75=2017010134=263652=2017010102585014464505160=201701010258501446450515799=10000100268=1279=1269=148=17359555=6SZ683=355684270=10220.0271=34346=31023=710=156
1128=99=18135=X49=SAMPLE75=2017010134=174252=2017010105540036936855060=201701010554003693685505799=10000100268=1279=1269=048=17359555=6SZ683=355685270=10207.0271=12346=61023=610=140
1128=99=18135=X49=SAMPLE75=2017010134=446152=2017010102255119034100760=201701010225511903410075799=10000100268=1279=1269=048=17359555=6SZ683=355686270=10206.0271=34346=31023=710=145
1128=99=18035=X49=SAMPLE75=2017010134=256952=2017010111245174338521060=201701011124517433852105799=10000100268=1279=1269=048=17359555=6SZ683=355687270=10206.0271=4346=21023=710=108
1128=99=18135=X49=SAMPLE75=2017010134=285352=2017010102255388991323560=201701010225538899132355799=10000100268=1279=1269=048=17359555=6SZ683=355688270=10207.0271=42346=71023=610=161
1128=99=18035=X49=SAMPLE75=2017010134=476352=2017010109391575662379960=201701010939157566237995799=10000100268=1279=1269=148=17359555=6SZ683=355689270=10220.0271=4346=21023=710=093
1128=99=18135=X49=SAMPLE75=2017010134=79652=2017010101550992011607560=201701010155099201160755799=10000100268=1279=1269=048=17359555=6SZ683=355690270=10207.0271=12346=61023=610=140
1128=99=18135=X49=SAMPLE75=2017010134=286652=2017010101182251323427660=201701010118225132342765799=10000100268=1279=1269=148=17359555=6SZ683=355691270=10220.0271=34346=31023=710=139
1128=99=18135=X49=SAMPLE75=2017010134=29152=2017010103203714618645960=201701010320371461864595799=10000100268=1279=1269=048=17359555=6SZ683=355692270=10207.0271=42346=71023=610=131
1128=99=18035=X49=SAMPLE75=2017010134=110452=2017010111120178828953060=201701011112017882895305799=10000100268=1279=1269=148=17359555=6SZ683=355693270=10220.0271=4346=21023=710=092
1128=99=18135=X49=SAMPLE75=2017010134=485952=2017010110021827155408160=201701011002182715540815799=10000100268=1279=1269=048=17359555=6SZ683=355694270=10207.0271=12346=61023=610=166
1128=99=18135=X49=SAMPLE75=2017010134=241152=2017010103095419205159860=201701010309541920515985799=10000100268=1279=1269=148=17359555=6SZ683=355695270=10220.0271=34346=31023=710=155
1128=99=18135=X49=SAMPLE75=2017010134=126652=2017010109280172534177660=201701010928017253417765799=10000100268=1279=1269=048=17359555=6SZ683=355696270=10207.0271=42346=71023=610=177
1128=99=18035=X49=SAMPLE75=2017010134=400352=2017010114230250104067760=201701011423025010406775799=10000100268=1279=1269=148=17359555=6SZ683=355697270=10220.0271=4346=21023=710=086
1128=99=18135=X49=SAMPLE75=2017010134=32752=2017010104052661893443160=201701010405266189344315799=10000100268=1279=1269=148=17359555=6SZ683=355698270=10220.0271=34346=31023=710=136
1128=99=18035=X49=SAMPLE75=2017010134=411452=2017010111384309626947860=201701011138430962694785799=10000100268=1279=1269=148=17359555=6SZ683=355699270=10220.0271=4346=21023=710=116
1128=99=18135=X49=SAMPLE75=2017010134=236152=2017010109481758487859760=201701010948175848785975799=10000100268=1279=1269=148=17359555=6SZ683=355700270=10220.0271=34346=31023=710=138
1128=99=18035=X49=SAMPLE75=2017010134=184052=2017010107222020627106260=201701010722202062710625799=10000100268=1279=1269=148=17359555=6SZ683=355701270=10220.0271=4346=21023=710=088
1128=99=18135=X49=SAMPLE75=2017010134=14752=2017010107203226607389760=201701010720322660738975799=10000100268=1279=1269=048=17359555=6SZ683=355702270=10207.0271=12346=61023=610=131
1128=99=18135=X49=SAMPLE75=2017010134=144452=2017010101075413655709560=201701010107541365570955799=10000100268=1279=1269=148=17359555=6SZ683=355703270=10222.0271=33346=21023=910=142
1128=99=18135=X49=SAMPLE75=2017010134=108252=2017010108333099741519060=201701010833309974151905799=10000100268=1279=1269=048=17359555=6SZ683=355704270=10207.0271=42346=71023=610=126
1128=99=18135=X49=SAMPLE75=2017010134=377452=2017010113291234589367360=201701011329123458936735799=10000100268=1279=1269=148=17359555=6SZ683=355705270=10220.0271=34346=31023=710=136
1128=99=18035=X49=SAMPLE75=2017010134=122552=2017010102082019331330460=201701010208201933133045799=10000100268=1279=1269=148=17359555=6SZ683=355706270=10222.0271=3346=11023=910=095
1128=99=18035=X49=SAMPLE75=2017010134=352652=2017010112482420473103960=201701011248242047310395799=10000100268=1279=1269=148=17359555=6SZ683=355707270=10220.0271=4346=21023=710=082
1128=99=18135=X49=SAMPLE75=2017010134=406052=2017010107485347856223160=201701010748534785622315799=10000100268=1279=1269=148=17359555=6SZ683=355708270=10220.0271=34346=31023=710=125
1128=99=18135=X49=SAMPLE75=2017010134=418952=2017010107301941800192560=201701010730194180019255799=10000100268=1279=1269=048=17359555=6SZ683=355709270=10207.0271=12346=61023=610=130
1128=99=18035=X49=SAMPLE75=2017010134=50452=2017010101155549574430960=201701010115554957443095799=10000100268=1279=1269=148=17359555=6SZ683=355710270=10220.0271=4346=21023=710=077
1128=99=18135=X49=SAMPLE75=2017010134=2252=2017010109201163737286160=201701010920116373728615799=10000100268=1279=1269=048=17359555=6SZ683=355711270=10207.0271=42346=71023=610=128
1128=99=18135=X49=SAMPLE75=2017010134=354552=2017010111345652525533960=201701011134565252553395799=10000100268=1279=1269=148=17359555=6SZ683=355712270=10220.0271=34346=31023=710=117
1128=99=18135=X49=SAMPLE75=2017010134=364552=2017010114292939683236660=201701011429293968323665799=10000100268=1279=1269=148=17359555=6SZ683=355713270=10221.0271=12346=41023=810=131
1128=99=18035=X49=SAMPLE75=2017010134=87952=2017010111374675465569960=201701011137467546556995799=10000100268=1279=1269=148=17359555=6SZ683=355714270=10220.0271=4346=21023=710=095
1128=99=18135=X49=SAMPLE75=2017010134=361352=2017010109303667569319260=201701010930366756931925799=10000100268=1279=1269=048=17359555=6SZ683=355715270=10207.0271=12346=61023=610=132
1128=99=18135=X49=SAMPLE75=2017010134=152852=2017010111412059523426760=201701011141205952342675799=10000100268=1279=1269=148=17359555=6SZ683=355716270=10220.0271=34346=31023=710=155
1128=99=18135=X49=SAMPLE75=2017010134=37952=2017010111450815640332460=201701011145081564033245799=10000100268=1279=1269=048=17359555=6SZ683=355717270=10207.0271=42346=71023=610=132
1128=99=18135=X49=SAMPLE75=2017010134=358652=2017010102362923124676060=201701010236292312467605799=10000100268=1279=1269=048=17359555=6SZ683=355718270=10207.0271=12346=61023=610=137
1128=99=18135=X49=SAMPLE75=2017010134=79352=2017010109120253326259060=201701010912025332625905799=10000100268=1279=1269=048=17359555=6SZ683=355719270=10207.0271=42346=71023=610=170
1128=99=18035=X49=SAMPLE75=2017010134=132352=2017010109565585788228260=201701010956558578822825799=10000100268=1279=1269=148=17359555=6SZ683=355720270=10220.0271=4346=21023=710=094
1128=99=18135=X49=SAMPLE75=2017010134=365752=2017010112294829037758760=201701011229482903775875799=10000100268=1279=1269=148=17359555=6SZ683=355721270=10220.0271=34346=31023=710=155
1128=99=18135=X49=SAMPLE75=2017010134=306452=2017010100254211039210560=201701010025421103921055799=10000100268=1279=1269=048=17359555=6SZ683=355722270=10207.0271=12346=61023=610=150
1128=99=18035=X49=SAMPLE75=2017010134=23952=2017010112013895833996260=201701011201389583399625799=10000100268=1279=1269=148=17359555=6SZ683=355723270=10220.0271=4346=21023=710=086
1128=99=18135=X49=SAMPLE75=2017010134=321052=2017010112340289359071760=201701011234028935907175799=10000100268=1279=1269=048=17359555=6SZ683=355724270=10207.0271=42346=71023=610=122
1128=99=18135=X49=SAMPLE75=2017010134=106452=2017010103350136093010160=201701010335013609301015799=10000100268=1279=1269=148=17359555=6SZ683=355725270=10220.0271=34346=31023=710=151
1128=99=18035=X49=SAMPLE75=2017010134=150952=2017010100554268671112460=201701010055426867111245799=10000100268=1279=1269=148=17359555=6SZ683=355726270=10220.0271=4346=21023=710=105
1128=99=18135=X49=SAMPLE75=2017010134=492652=2017010102415410376153460=201701010241541037615345799=10000100268=1279=1269=148=17359555=6SZ683=355727270=10220.0271=34346=31023=710=146
1128=99=18035=X49=SAMPLE75=2017010134=238252=2017010103433581376362560=201701010343358137636255799=10000100268=1279=1269=148=17359555=6SZ683=355728270=10220.0271=4346=21023=710=088
1128=99=18135=X49=SAMPLE75=2017010134=179652=2017010105393631735658060=201701010539363173565805799=10000100268=1279=1269=048=17359555=6SZ683=355729270=10207.0271=12346=61023=610=143
1128=99=18135=X49=SAMPLE75=2017010134=479752=2017010107063230462620960=201701010706323046262095799=10000100268=1279=1269=148=17359555=6SZ683=355730270=10220.0271=34346=31023=710=150
1128=99=18135=X49=SAMPLE75=2017010134=296152=2017010105192599410735160=201701010519259941073515799=10000100268=1279=1269=048=17359555=6SZ683=355731270=10207.0271=42346=71023=610=154
1128=99=18135=X49=SAMPLE75=2017010134=111952=2017010102144085110542860=201701010214408511054285799=10000100268=1279=1269=048=17359555=6SZ683=355732270=10207.0271=12346=61023=610=137
1128=99=18035=X49=SAMPLE75=2017010134=307552=2017010114194971997349960=201701011419497199734995799=10000100268=1279=1269=148=17359555=6SZ683=355733270=10220.0271=4346=21023=710=084
1128=99=18135=X49=SAMPLE75=2017010134=161552=2017010108285287194718460=201701010828528719471845799=10000100268=1279=1269=048=17359555=6SZ683=355734270=10207.0271=42346=71023=610=125
1128=99=18135=X49=SAMPLE75=2017010134=146552=2017010106474666327271360=201701010647466632727135799=10000100268=1279=1269=148=17359555=6SZ683=355735270=10220.0271=34346=31023=710=121
1128=99=18135=X49=SAMPLE75=2017010134=173652=2017010113523725905836560=201701011352372590583655799=10000100268=1279=1269=148=17359555=6SZ683=355736270=10216.0271=14346=61023=310=168
1128=99=18035=X49=SAMPLE75=2017010134=186452=2017010101493664588729160=201701010149366458872915799=10000100268=1279=1269=148=17359555=6SZ683=355737270=10220.0271=4346=21023=710=102
1128=99=18135=X49=SAMPLE75=2017010134=21452=2017010107463714302536560=201701010746371430253655799=10000100268=1279=1269=048=17359555=6SZ683=355738270=10207.0271=12346=61023=610=141
1128=99=18135=X49=SAMPLE75=2017010134=424652=2017010112265616473682260=201701011226561647368225799=10000100268=1279=1269=148=17359555=6SZ683=355739270=10220.0271=34346=31023=710=154
1128=99=18135=X49=SAMPLE75=2017010134=104052=2017010109014805187060160=201701010901480518706015799=10000100268=1279=1269=048=17359555=6SZ683=355740270=10207.0271=42346=71023=610=159
1128=99=18035=X49=SAMPLE75=2017010134=347952=2017010106035331273260360=201701010603533127326035799=10000100268=1279=1269=148=17359555=6SZ683=355741270=10220.0271=4346=21023=710=077
1128=99=18135=X49=SAMPLE75=2017010134=195252=2017010106275289147675060=201701010627528914767505799=10000100268=1279=1269=048=17359555=6SZ683=355742270=10207.0271=12346=61023=610=142
1128=99=18135=X49=SAMPLE75=2017010134=184252=2017010100172395328318360=201701010017239532831835799=10000100268=1279=1269=148=17359555=6SZ683=355743270=10220.0271=34346=31023=710=141
1128=99=18135=X49=SAMPLE75=2017010134=101352=2017010103280950718886860=201701010328095071888685799=10000100268=1279=1269=048=17359555=6SZ683=355744270=10207.0271=42346=71023=610=129
1128=99=18135=X49=SAMPLE75=2017010134=266052=2017010110004386619741360=201701011000438661974135799=10000100268=1279=1269=048=17359555=6SZ683=355745270=10207.0271=12346=61023=610=130
1128=99=18135=X49=SAMPLE75=2017010134=496052=2017010102473998094204960=201701010247399809420495799=10000100268=1279=1269=048=17359555=6SZ683=355746270=10206.0271=34346=31023=710=137
1128=99=18035=X49=SAMPLE75=2017010134=126052=2017010105010273039195660=201701010501027303919565799=10000100268=1279=1269=148=17359555=6SZ683=355747270=10220.0271=4346=21023=710=101
1128=99=18135=X49=SAMPLE75=2017010134=29452=2017010109084976430889160=201701010908497643088915799=10000100268=1279=1269=148=17359555=6SZ683=355748270=10220.0271=34346=31023=710=162
1128=99=18035=X49=SAMPLE75=2017010134=121252=2017010112032072659638160=201701011203207265963815799=10000100268=1279=1269=148=17359555=6SZ683=355749270=10220.0271=4346=21023=710=088
1128=99=18135=X49=SAMPLE75=2017010134=417552=2017010111463089352693160=201701011146308935269315799=10000100268=1279=1269=148=17359555=6SZ683=355750270=10220.0271=34346=31023=710=154
1128=99=18035=X49=SAMPLE75=2017010134=3152=2017010103560161390799860=201701010356016139079985799=10000100268=1279=1269=148=17359555=6SZ683=355751270=10220.0271=4346=21023=710=084
1128=99=18135=X49=SAMPLE75=2017010134=151452=2017010114265076645942460=201701011426507664594245799=10000100268=1279=1269=148=17359555=6SZ683=355752270=10220.0271=34346=31023=710=141
1128=99=18035=X49=SAMPLE75=2017010134=117252=2017010102135581714242460=201701010213558171424245799=10000100268=1279=1269=148=17359555=6SZ683=355753270=10220.0271=4346=21023=710=070
1128=99=18135=X49=SAMPLE75=2017010134=156552=2017010103354183641755860=201701010335418364175585799=10000100268=1279=1269=148=17359555=6SZ683=355754270=10220.0271=34346=31023=710=129
1128=99=18035=X49=SAMPLE75=2017010134=229752=2017010103363560343799360=201701010336356034379935799=10000100268=1279=1269=148=17359555=6SZ683=355755270=10220.0271=4346=21023=710=100
1128=99=18135=X49=SAMPLE75=2017010134=166652=2017010107012757330527160=201701010701275733052715799=10000100268=1279=1269=148=17359555=6SZ683=355756270=10220.0271=34346=31023=710=145
1128=99=18035=X49=SAMPLE75=2017010134=251952=2017010112175341623771560=201701011217534162377155799=10000100268=1279=1269=148=17359555=6SZ683=355757270=10220.0271=4346=21023=710=117
1128=99=18135=X49=SAMPLE75=2017010134=147752=2017010112214458668212160=201701011221445866821215799=10000100268=1279=1269=148=17359555=6SZ683=355758270=10220.0271=34346=31023=710=140
1128=99=18035=X49=SAMPLE75=2017010134=149252=2017010108441237821623160=201701010844123782162315799=10000100268=1279=1269=148=17359555=6SZ683=355759270=10220.0271=4346=21023=710=087
1128=99=18135=X49=SAMPLE75=2017010134=88852=2017010102410194113849460=201701010241019411384945799=10000100268=1279=1269=148=17359555=6SZ683=355760270=10220.0271=34346=31023=710=127
1128=99=18035=X49=SAMPLE75=2017010134=218252=2017010104284291331390860=201701010428429133139085799=10000100268=1279=1269=148=17359555=6SZ683=355761270=10220.0271=4346=21023=710=064
1128=99=18135=X49=SAMPLE75=2017010134=474952=2017010105464755491745860=201701010546475549174585799=10000100268=1279=1269=148=17359555=6SZ683=355762270=10220.0271=34346=31023=710=146
1128=99=18035=X49=SAMPLE75=2017010134=373352=2017010113223364052533560=201701011322336405253355799=10000100268=1279=1269=148=17359555=6SZ683=355763270=10220.0271=4346=21023=710=108
1128=99=18135=X49=SAMPLE75=2017010134=188852=2017010112433564360678360=201701011243356436067835799=10000100268=1279=1269=148=17359555=6SZ683=355764270=10220.0271=34346=31023=710=175
1128=99=18035=X49=SAMPLE75=2017010134=122852=2017010110043976952065160=201701011004397695206515799=10000100268=1279=1269=148=17359555=6SZ683=355765270=10220.0271=4346=21023=710=116
1128=99=18135=X49=SAMPLE75=2017010134=382952=2017010111235101443375760=201701011123510144337575799=10000100268=1279=1269=148=17359555=6SZ683=355766270=10220.0271=34346=31023=710=168
1128=99=18035=X49=SAMPLE75=2017010134=85352=2017010110255091674863660=201701011025509167486365799=10000100268=1279=1269=148=17359555=6SZ683=355767270=10220.0271=4346=21023=710=094
1128=99=18135=X49=SAMPLE75=2017010134=177252=2017010106125098113370460=201701010612509811337045799=10000100268=1279=1269=148=17359555=6SZ683=355768270=10220.0271=34346=31023=710=132
1128=99=18035=X49=SAMPLE75=2017010134=199652=2017010102091445043357660=201701010209144504335765799=10000100268=1279=1269=148=17359555=6SZ683=355769270=10220.0271=4346=21023=710=101
1128=99=18135=X49=SAMPLE75=2017010134=365052=2017010112422589883273760=201701011242258988327375799=10000100268=1279=1269=148=17359555=6SZ683=355770270=10220.0271=34346=31023=710=130
1128=99=18035=X49=SAMPLE75=2017010134=172352=2017010109412779885356360=201701010941277988535635799=10000100268=1279=1269=148=17359555=6SZ683=355771270=10220.0271=4346=21023=710=108
1128=99=18135=X49=SAMPLE75=2017010134=274152=2017010108012763214432460=201701010801276321443245799=10000100268=1279=1269=148=17359555=6SZ683=355772270=10220.0271=34346=31023=710=142
1128=99=18035=X49=SAMPLE75=2017010134=401052=2017010104131991517900560=201701010413199151790055799=10000100268=1279=1269=148=17359555=6SZ683=355773270=10220.0271=4346=21023=710=096
1128=99=18135=X49=SAMPLE75=2017010134=471152=2017010101513100904404160=201701010151310090440415799=10000100268=1279=1269=148=17359555=6SZ683=355774270=10220.0271=34346=31023=710=147
1128=99=25135=X49=SAMPLE75=2017010134=149652=2017010108175643577640960=201701010817564357764095799=10000100268=2279=1269=048=17359555=6SZ683=355775270=10210.0271=5346=31023=3279=1269=048=17359555=6SZ683=355776270=10209.0271=4346=21023=410=138
1128=99=18035=X49=SAMPLE75=2017010134=314952=2017010102584509956431060=201701010258450995643105799=10000100268=1279=1269=048=17359555=6SZ683=355777270=10212.0271=5346=31023=110=071
1128=99=25135=X49=SAMPLE75=2017010134=209052=2017010107025755591030460=201701010702575559103045799=10000100268=2279=2269=048=17360055=6SH783=99098270=10265.0271=3346=11023=1279=0269=048=17360055=6SH783=99099270=10255.0271=53346=21023=1010=108
1128=99=18035=X49=SAMPLE75=2017010134=80452=2017010108492424796541660=201701010849242479654165799=10000100268=1279=1269=148=17359555=6SZ683=355778270=10220.0271=4346=21023=710=092
1128=99=18035=X49=SAMPLE75=2017010134=287852=2017010102454405463361960=201701010245440546336195799=10000100268=1279=1269=048=17359555=6SZ683=355779270=10206.0271=4346=21023=710=108
1128=99=18135=X49=SAMPLE75=2017010134=130452=2017010102210151187717860=201701010221015118771785799=10000100268=1279=1269=148=17359555=6SZ683=355780270=10220.0271=34346=31023=710=106
1128=99=18135=X49=SAMPLE75=2017010134=362252=2017010107175727832507260=201701010717572783250725799=10000100268=1279=1269=048=17359555=6SZ683=355781270=10206.0271=34346=31023=710=139
1128=99=18035=X49=SAMPLE75=2017010134=79852=2017010102355676885964160=201701010235567688596415799=10000100268=1279=1269=148=17359555=6SZ683=355782270=10220.0271=4346=21023=710=082
1128=99=18135=X49=SAMPLE75=2017010134=334952=2017010110530560801680960=201701011053056080168095799=10000100268=1279=1269=148=17359555=6SZ683=355783270=10220.0271=34346=31023=710=119
1128=99=18035=X49=SAMPLE75=2017010134=449752=2017010106562813039503760=201701010656281303950375799=10000100268=1279=1269=148=17359555=6SZ683=355784270=10220.0271=4346=21023=710=055
1128=99=18135=X49=SAMPLE75=2017010134=87452=2017010101434080764077260=201701010143408076407725799=10000100268=1279=1269=148=17359555=6SZ683=355785270=10220.0271=34346=31023=710=138
1128=99=18035=X49=SAMPLE75=2017010134=470852=2017010114310687588022860=201701011431068758802285799=10000100268=1279=1269=148=17359555=6SZ683=355786270=10220.0271=4346=21023=710=100
1128=99=18135=X49=SAMPLE75=2017010134=271352=2017010102220542018297560=201701010222054201829755799=10000100268=1279=1269=148=17359555=6SZ683=355787270=10220.0271=34346=31023=710=146
1128=99=18035=X49=SAMPLE75=2017010134=499452=2017010111484686040438760=201701011148468604043875799=10000100268=1279=1269=148=17359555=6SZ683=355788270=10220.0271=4346=21023=710=070
1128=99=18135=X49=SAMPLE75=2017010134=246952=2017010106381450900712760=201701010638145090071275799=10000100268=1279=1269=148=17359555=6SZ683=355789270=10220.0271=34346=31023=710=171
1128=99=18035=X49=SAMPLE75=2017010134=420352=2017010114124639262263560=201701011412463926226355799=10000100268=1279=1269=148=17359555=6SZ683=355790270=10220.0271=4346=21023=710=075
1128=99=18135=X49=SAMPLE75=2017010134=477852=2017010109244862788127960=201701010924486278812795799=10000100268=1279=1269=148=17359555=6SZ683=355791270=10220.0271=34346=31023=710=127
1128=99=18035=X49=SAMPLE75=2017010134=298052=2017010101200829603458860=201701010120082960345885799=10000100268=1279=1269=148=17359555=6SZ683=355792270=10220.0271=4346=21023=710=099
1128=99=18135=X49=SAMPLE75=2017010134=258752=2017010106243173916317460=201701010624317391631745799=10000100268=1279=1269=148=17359555=6SZ683=355793270=10220.0271=34346=31023=710=129
1128=99=18035=X49=SAMPLE75=2017010134=26052=2017010113442175245707960=201701011344217524570795799=10000100268=1279=1269=148=17359555=6SZ683=355794270=10220.0271=4346=21023=710=080
1128=99=18135=X49=SAMPLE75=2017010134=430052=2017010114052535366488960=201701011405253536648895799=10000100268=1279=1269=148=17359555=6SZ683=355795270=10220.0271=34346=31023=710=150
1128=99=18035=X49=SAMPLE75=2017010134=57952=2017010104305382279087460=201701010430538227908745799=10000100268=1279=1269=048=17359555=6SZ683=355796270=10212.0271=6346=41023=110=112
1128=99=17935=X49=SAMPLE75=2017010134=193152=2017010101133293547891860=201701010113329354789185799=10000100268=1279=0269=048=17360055=6SH783=99100270=10265.0271=3346=11023=110=009
1128=99=18035=X49=SAMPLE75=2017010134=298452=2017010107493703534474960=201701010749370353447495799=10000100268=1279=1269=148=17359555=6SZ683=355797270=10220.0271=4346=21023=710=088
1128=99=18135=X49=SAMPLE75=2017010134=94852=2017010109203753540158060=201701010920375354015805799=10000100268=1279=1269=148=17359555=6SZ683=355798270=10220.0271=34346=31023=710=147
1128=99=18035=X49=SAMPLE75=2017010134=167252=2017010109492211271867460=201701010949221127186745799=10000100268=1279=1269=048=17359555=6SZ683=355799270=10206.0271=4346=21023=710=086
1128=99=18135=X49=SAMPLE75=2017010134=35152=2017010101474655370090860=201701010147465537009085799=10000100268=1279=1269=048=17359555=6SZ683=355800270=10206.0271=34346=31023=710=137
1128=99=25335=X49=SAMPLE75=2017010134=286252=2017010103003334161624160=201701010300333416162415799=10000100268=2279=1269=148=17359555=6SZ683=355801270=10219.0271=18346=61023=6279=1269=148=17359555=6SZ683=355802270=10220.0271=37346=41023=710=225
1128=99=25335=X49=SAMPLE75=2017010134=21252=2017010107302716036260660=201701010730271603626065799=10000100268=2279=1269=148=17359555=6SZ683=355803270=10219.0271=21346=71023=6279=1269=148=17359555=6SZ683=355804270=10220.0271=34346=31023=710=235
1128=99=18035=X49=SAMPLE75=2017010134=395452=2017010105112652301654760=201701010511265230165475799=10000100268=1279=1269=148=17359555=6SZ683=355805270=10220.0271=4346=21023=710=077
1128=99=18135=X49=SAMPLE75=2017010134=91352=2017010101204526844591860=201701010120452684459185799=10000100268=1279=1269=148=17359555=6SZ683=355806270=10220.0271=34346=31023=710=123
1128=99=18035=X49=SAMPLE75=2017010134=224452=2017010102222890976683260=201701010222289097668325799=10000100268=1279=1269=148=17359555=6SZ683=355807270=10220.0271=4346=21023=710=093
1128=99=18135=X49=SAMPLE75=2017010134=306452=2017010101470031674349760=201701010147003167434975799=10000100268=1279=1269=148=17359555=6SZ683=355808270=10220.0271=34346=31023=710=152
1128=99=18035=X49=SAMPLE75=2017010134=272752=2017010101181996526064560=201701010118199652606455799=10000100268=1279=1269=148=17359555=6SZ683=355809270=10220.0271=4346=21023=710=070
1128=99=18135=X49=SAMPLE75=2017010134=149452=2017010110410759942274260=201701011041075994227425799=10000100268=1279=1269=148=17359555=6SZ683=355810270=10221.0271=42346=51023=810=137
1128=99=18135=X49=SAMPLE75=2017010134=272052=2017010107212149744466560=201701010721214974446655799=10000100268=1279=1269=148=17359555=6SZ683=355811270=10221.0271=12346=41023=810=108
1128=99=18135=X49=SAMPLE75=2017010134=134352=2017010110360242404682560=201701011036024240468255799=10000100268=1279=1269=148=17359555=6SZ683=355812270=10220.0271=34346=31023=710=100
1128=99=18035=X49=SAMPLE75=2017010134=60252=2017010113414252795482660=201701011341425279548265799=10000100268=1279=1269=148=17359555=6SZ683=355813270=10220.0271=4346=21023=710=091
1128=99=18135=X49=SAMPLE75=2017010134=492352=2017010107474953538045160=201701010747495353804515799=10000100268=1279=1269=148=17359555=6SZ683=355814270=10222.0271=33346=21023=910=143
1128=99=18035=X49=SAMPLE75=2017010134=279252=2017010112440853176111160=201701011244085317611115799=10000100268=1279=1269=148=17359555=6SZ683=355815270=10222.0271=3346=11023=910=111
1128=99=18135=X49=SAMPLE75=2017010134=336452=2017010109205563432870960=201701010920556343287095799=10000100268=1279=1269=148=17359555=6SZ683=355816270=10220.0271=34346=31023=710=138
1128=99=18035=X49=SAMPLE75=2017010134=1952=2017010109251336611521660=201701010925133661152165799=10000100268=1279=1269=148=17359555=6SZ683=355817270=10220.0271=4346=21023=710=083
1128=99=18135=X49=SAMPLE75=2017010134=237952=2017010109211268289487260=201701010921126828948725799=10000100268=1279=1269=148=17359555=6SZ683=355818270=10220.0271=34346=31023=710=169
1128=99=25335=X49=SAMPLE75=2017010134=193152=2017010113210001731848660=201701011321000173184865799=10000100268=2279=1269=148=17359555=6SZ683=355819270=10219.0271=18346=61023=6279=1269=148=17359555=6SZ683=355820270=10220.0271=37346=41023=710=240
1128=99=18035=X49=SAMPLE75=2017010134=174052=2017010111171360537743860=201701011117136053774385799=10000100268=1279=1269=148=17359555=6SZ683=355821270=10220.0271=7346=31023=710=107
1128=99=18135=X49=SAMPLE75=2017010134=473252=2017010109313999366926560=201701010931399936692655799=10000100268=1279=1269=148=17359555=6SZ683=355822270=10220.0271=37346=41023=710=151
1128=99=18035=X49=SAMPLE75=2017010134=72452=2017010101503167270656060=201701010150316727065605799=10000100268=1279=1269=148=17359555=6SZ683=355823270=10220.0271=7346=31023=710=113
1128=99=18135=X49=SAMPLE75=2017010134=328452=2017010111541682185329460=201701011154168218532945799=10000100268=1279=1269=148=17359555=6SZ683=355824270=10220.0271=37346=41023=710=159
1128=99=18035=X49=SAMPLE75=2017010134=118252=2017010104345844894380960=201701010434584489438095799=10000100268=1279=1269=148=17359555=6SZ683=355825270=10220.0271=7346=31023=710=109
1128=99=18135=X49=SAMPLE75=2017010134=170252=2017010106193966693798960=201701010619396669379895799=10000100268=1279=1269=148=17359555=6SZ683=355826270=10220.0271=37346=41023=710=147
1128=99=18035=X49=SAMPLE75=2017010134=222352=2017010110541105685910160=201701011054110568591015799=10000100268=1279=1269=148=17359555=6SZ683=355827270=10220.0271=7346=31023=710=085
1128=99=18135=X49=SAMPLE75=2017010134=370252=2017010107412450073070960=201701010741245007307095799=10000100268=1279=1269=148=17359555=6SZ683=355828270=10220.0271=37346=41023=710=149
1128=99=25335=X49=SAMPLE75=2017010134=418452=2017010108531748981302060=201701010853174898130205799=10000100268=2279=1269=148=17359555=6SZ683=355829270=10219.0271=21346=71023=6279=1269=148=17359555=6SZ683=355830270=10220.0271=34346=31023=710=231
1128=99=18035=X49=SAMPLE75=2017010134=382552=2017010109232327349554160=201701010923232734955415799=10000100268=1279=1269=148=17359555=6SZ683=355831270=10220.0271=4346=21023=710=097
1128=99=18135=X49=SAMPLE75=2017010134=277252=2017010111123325483278160=201701011112332548327815799=10000100268=1279=1269=148=17359555=6SZ683=355832270=10220.0271=34346=31023=710=172
1128=99=18035=X49=SAMPLE75=2017010134=378352=2017010114073893938192960=201701011407389393819295799=10000100268=1279=1269=148=17359555=6SZ683=355833270=10220.0271=4346=21023=710=077
1128=99=18135=X49=SAMPLE75=2017010134=40752=2017010109405209251639460=201701010940520925163945799=10000100268=1279=1269=148=17359555=6SZ683=355834270=10220.0271=34346=31023=710=161
1128=99=18035=X49=SAMPLE75=2017010134=483352=2017010106591792833366460=201701010659179283336645799=10000100268=1279=1269=148=17359555=6SZ683=355835270=10220.0271=4346=21023=710=081
1128=99=18135=X49=SAMPLE75=2017010134=487552=2017010107540298662045460=201701010754029866204545799=10000100268=1279=1269=148=17359555=6SZ683=355836270=10220.0271=34346=31023=710=157
1128=99=18035=X49=SAMPLE75=2017010134=116952=2017010110061305352983060=201701011006130535298305799=10000100268=1279=1269=148=17359555=6SZ683=355837270=10220.0271=4346=21023=710=105
1128=99=25235=X49=SAMPLE75=2017010134=91052=2017010111113683358516360=201701011111368335851635799=10000100268=2279=1269=148=17359555=6SZ683=355838270=10219.0271=18346=61023=6279=1269=148=17359555=6SZ683=355839270=10220.0271=7346=31023=710=232
1128=99=18135=X49=SAMPLE75=2017010134=22352=2017010103271893255576660=201701010327189325557665799=10000100268=1279=1269=148=17359555=6SZ683=355840270=10220.0271=37346=41023=710=155
1128=99=18035=X49=SAMPLE75=2017010134=121952=2017010105553666519272360=201701010555366651927235799=10000100268=1279=1269=148=17359555=6SZ683=355841270=10220.0271=7346=31023=710=111
1128=99=18135=X49=SAMPLE75=2017010134=205852=2017010110180612652015160=201701011018061265201515799=10000100268=1279=1269=148=17359555=6SZ683=355842270=10220.0271=37346=41023=710=168
1128=99=18035=X49=SAMPLE75=2017010134=44752=2017010109420005898039060=201701010942000589803905799=10000100268=1279=1269=148=17359555=6SZ683=355843270=10220.0271=7346=31023=710=092
1128=99=18135=X49=SAMPLE75=2017010134=232052=2017010102120722783531560=201701010212072278353155799=10000100268=1279=1269=148=17359555=6SZ683=355844270=10222.0271=33346=21023=910=155
1128=99=18035=X49=SAMPLE75=2017010134=152552=2017010110320487833786060=201701011032048783378605799=10000100268=1279=1269=148=17359555=6SZ683=355845270=10222.0271=3346=11023=910=100
1128=99=18135=X49=SAMPLE75=2017010134=259552=2017010106334130186486860=201701010633413018648685799=10000100268=1279=1269=148=17359555=6SZ683=355846270=10220.0271=37346=41023=710=162
1128=99=18035=X49=SAMPLE75=2017010134=248252=2017010113353240258268760=201701011335324025826875799=10000100268=1279=1269=148=17359555=6SZ683=355847270=10220.0271=7346=31023=710=104
1128=99=18135=X49=SAMPLE75=2017010134=149852=2017010112233551683552260=201701011223355168355225799=10000100268=1279=1269=148=17359555=6SZ683=355848270=10221.0271=42346=51023=810=156
1128=99=18135=X49=SAMPLE75=2017010134=75052=2017010114325155212375960=201701011432515521237595799=10000100268=1279=1269=148=17359555=6SZ683=355849270=10220.0271=37346=41023=710=136
1128=99=18135=X49=SAMPLE75=2017010134=79852=2017010114072453895293560=201701011407245389529355799=10000100268=1279=1269=148=17359555=6SZ683=355850270=10221.0271=12346=41023=810=142
1128=99=18035=X49=SAMPLE75=2017010134=488052=2017010114063510985173860=201701011406351098517385799=10000100268=1279=1269=148=17359555=6SZ683=355851270=10220.0271=7346=31023=710=111
1128=99=18135=X49=SAMPLE75=2017010134=44852=2017010101124789236631460=201701010112478923663145799=10000100268=1279=1269=148=17359555=6SZ683=355852270=10222.0271=33346=21023=910=152
1128=99=18035=X49=SAMPLE75=2017010134=60352=2017010104224629011048460=201701010422462901104845799=10000100268=1279=1269=148=17359555=6SZ683=355853270=10222.0271=3346=11023=910=110
1128=99=18135=X49=SAMPLE75=2017010134=405552=2017010106260381704410060=201701010626038170441005799=10000100268=1279=1269=148=17359555=6SZ683=355854270=10220.0271=37346=41023=710=160
1128=99=18035=X49=SAMPLE75=2017010134=242952=2017010113022806231245760=201701011302280623124575799=10000100268=1279=1269=148=17359555=6SZ683=355855270=10220.0271=7346=31023=710=109
1128=99=18135=X49=SAMPLE75=2017010134=304552=2017010102320479396814060=201701010232047939681405799=10000100268=1279=1269=148=17359555=6SZ683=355856270=10220.0271=37346=41023=710=178
1128=99=18035=X49=SAMPLE75=2017010134=448652=2017010114002300556107360=201701011400230055610735799=10000100268=1279=1269=148=17359555=6SZ683=355857270=10220.0271=7346=31023=710=136
1128=99=18135=X49=SAMPLE75=2017010134=175252=2017010102395436430791960=201701010239543643079195799=10000100268=1279=1269=148=17359555=6SZ683=355858270=10221.0271=42346=51023=810=180
1128=99=18135=X49=SAMPLE75=2017010134=253352=2017010109524565679581460=201701010952456567958145799=10000100268=1279=1269=148=17359555=6SZ683=355859270=10221.0271=12346=41023=810=180
1128=99=18135=X49=SAMPLE75=2017010134=180352=2017010114280949116428460=201701011428094911642845799=10000100268=1279=1269=148=17359555=6SZ683=355860270=10220.0271=37346=41023=710=164
1128=99=25335=X49=SAMPLE75=2017010134=9252=2017010105420361827442760=201701010542036182744275799=10000100268=2279=1269=148=17359555=6SZ683=355861270=10219.0271=21346=71023=6279=1269=148=17359555=6SZ683=355862270=10220.0271=34346=31023=710=003
1128=99=25335=X49=SAMPLE75=2017010134=237952=2017010105170689575430960=201701010517068957543095799=10000100268=2279=1269=148=17359555=6SZ683=355863270=10219.0271=18346=61023=6279=1269=148=17359555=6SZ683=355864270=10220.0271=37346=41023=710=027
1128=99=18035=X49=SAMPLE75=2017010134=48752=2017010101185883682154960=201701010118588368215495799=10000100268=1279=1269=148=17359555=6SZ683=355865270=10220.0271=7346=31023=710=113
1128=99=18135=X49=SAMPLE75=2017010134=352852=2017010112432620430326960=201701011243262043032695799=10000100268=1279=1269=148=17359555=6SZ683=355866270=10220.0271=37346=41023=710=162
1128=99=25335=X49=SAMPLE75=2017010134=454752=2017010102205796633329660=201701010220579663332965799=10000100268=2279=1269=148=17359555=6SZ683=355867270=10219.0271=21346=71023=6279=1269=148=17359555=6SZ683=355868270=10220.0271=34346=31023=710=010
1128=99=25135=X49=SAMPLE75=2017010134=228352=2017010100500412967355760=201701010050041296735575799=10000100268=2279=1269=048=17359555=6SZ683=355869270=10210.0271=4346=21023=3279=1269=048=17359555=6SZ683=355870270=10209.0271=5346=31023=410=144
1128=99=18035=X49=SAMPLE75=2017010134=491952=2017010102311334479769760=201701010231133447976975799=10000100268=1279=1269=148=17359555=6SZ683=355871270=10220.0271=4346=21023=710=079
1128=99=18135=X49=SAMPLE75=2017010134=66152=2017010107384098062593460=201701010738409806259345799=10000100268=1279=1269=148=17359555=6SZ683=355872270=10220.0271=34346=31023=710=151
1128=99=18035=X49=SAMPLE75=2017010134=381652=2017010109012618113149260=201701010901261811314925799=10000100268=1279=1269=148=17359555=6SZ683=355873270=10220.0271=4346=21023=710=094
1128=99=18135=X49=SAMPLE75=2017010134=363452=2017010110365156853672160=201701011036515685367215799=10000100268=1279=1269=148=17359555=6SZ683=355874270=10220.0271=34346=31023=710=149
1128=99=18035=X49=SAMPLE75=2017010134=111352=2017010112302370729037860=201701011230237072903785799=10000100268=1279=1269=148=17359555=6SZ683=355875270=10220.0271=4346=21023=710=128
1128=99=18135=X49=SAMPLE75=2017010134=175152=2017010103050209101532260=201701010305020910153225799=10000100268=1279=1269=148=17359555=6SZ683=355876270=10220.0271=34346=31023=710=160
1128=99=18035=X49=SAMPLE75=2017010134=228752=2017010110424822701769060=201701011042482270176905799=10000100268=1279=1269=148=17359555=6SZ683=355877270=10220.0271=4346=21023=710=130
1128=99=18135=X49=SAMPLE75=2017010134=208252=2017010106014385480275860=201701010601438548027585799=10000100268=1279=1269=148=17359555=6SZ683=355878270=10220.0271=34346=31023=710=170
1128=99=18035=X49=SAMPLE75=2017010134=429152=2017010104180305830045760=201701010418030583004575799=10000100268=1279=1269=148=17359555=6SZ683=355879270=10220.0271=4346=21023=710=099
1128=99=18135=X49=SAMPLE75=2017010134=135052=2017010109265061673236660=201701010926506167323665799=10000100268=1279=1269=148=17359555=6SZ683=355880270=10222.0271=33346=21023=910=147
1128=99=18035=X49=SAMPLE75=2017010134=455252=2017010100430190205318460=201701010043019020531845799=10000100268=1279=1269=148=17359555=6SZ683=355881270=10222.0271=3346=11023=910=099
1128=99=18135=X49=SAMPLE75=2017010134=217852=2017010111515858394033260=201701011151585839403325799=10000100268=1279=1269=148=17359555=6SZ683=355882270=10220.0271=34346=31023=710=144
1128=99=18035=X49=SAMPLE75=2017010134=203252=2017010100441280523719460=201701010044128052371945799=10000100268=1279=1269=148=17359555=6SZ683=355883270=10220.0271=4346=21023=710=078
1128=99=18135=X49=SAMPLE75=2017010134=180252=2017010113145027350326160=201701011314502735032615799=10000100268=1279=1269=148=17359555=6SZ683=355884270=10220.0271=34346=31023=710=147
1128=99=18035=X49=SAMPLE75=2017010134=493952=2017010106505630643983860=201701010650563064398385799=10000100268=1279=1269=148=17359555=6SZ683=355885270=10220.0271=4346=21023=710=107
1128=99=18135=X49=SAMPLE75=2017010134=181052=2017010108364056046545560=201701010836405604654555799=10000100268=1279=1269=148=17359555=6SZ683=355886270=10220.0271=34346=31023=710=164
1128=99=18035=X49=SAMPLE75=2017010134=7852=2017010107575202483089460=201701010757520248308945799=10000100268=1279=1269=148=17359555=6SZ683=355887270=10220.0271=4346=21023=710=099
1128=99=18135=X49=SAMPLE75=2017010134=952=2017010101041718472389560=201701010104171847238955799=10000100268=1279=1269=148=17359555=6SZ683=355888270=10220.0271=34346=31023=710=157
1128=99=25135=X49=SAMPLE75=2017010134=413052=2017010100371712986216760=201701010037171298621675799=10000100268=2279=1269=048=17359555=6SZ683=355889270=10210.0271=5346=31023=3279=1269=048=17359555=6SZ683=355890270=10209.0271=4346=21023=410=145
1128=99=18035=X49=SAMPLE75=2017010134=316952=2017010104353499269145460=201701010435349926914545799=10000100268=1279=1269=148=17359555=6SZ683=355891270=10220.0271=4346=21023=710=098
1128=99=18135=X49=SAMPLE75=2017010134=113052=2017010114321827694598760=201701011432182769459875799=10000100268=1279=1269=148=17359555=6SZ683=355892270=10220.0271=34346=31023=710=157
1128=99=18035=X49=SAMPLE75=2017010134=324452=2017010104532739209913460=201701010453273920991345799=10000100268=1279=1269=148=17359555=6SZ683=355893270=10220.0271=4346=21023=710=103
1128=99=18135=X49=SAMPLE75=2017010134=445952=2017010112193803244836760=201701011219380324483675799=10000100268=1279=1269=148=17359555=6SZ683=355894270=10222.0271=33346=21023=910=149
1128=99=18035=X49=SAMPLE75=2017010134=461252=2017010105262550567373860=201701010526255056737385799=10000100268=1279=1269=148=17359555=6SZ683=355895270=10222.0271=3346=11023=910=128
1128=99=18135=X49=SAMPLE75=2017010134=195952=2017010110073879118657560=201701011007387911865755799=10000100268=1279=1269=148=17359555=6SZ683=355896270=10221.0271=42346=51023=810=194
1128=99=18135=X49=SAMPLE75=2017010134=495252=2017010104550265033579460=201701010455026503357945799=10000100268=1279=1269=148=17359555=6SZ683=355897270=10220.0271=34346=31023=710=182
1128=99=18135=X49=SAMPLE75=2017010134=241852=2017010101593585650481660=201701010159358565048165799=10000100268=1279=1269=148=17359555=6SZ683=355898270=10221.0271=12346=41023=810=167
1128=99=18035=X49=SAMPLE75=2017010134=472252=2017010102573075253716360=201701010257307525371635799=10000100268=1279=1269=148=17359555=6SZ683=355899270=10220.0271=4346=21023=710=120
1128=99=18135=X49=SAMPLE75=2017010134=375652=2017010105195261625403060=201701010519526162540305799=10000100268=1279=1269=148=17359555=6SZ683=355900270=10220.0271=34346=31023=710=154
1128=99=18035=X49=SAMPLE75=2017010134=148352=2017010110185409238584360=201701011018540923858435799=10000100268=1279=1269=148=17359555=6SZ683=355901270=10220.0271=4346=21023=710=072
1128=99=18135=X49=SAMPLE75=2017010134=301352=2017010108423369670850160=201701010842336967085015799=10000100268=1279=1269=148=17359555=6SZ683=355902270=10220.0271=34346=31023=710=162
1128=99=18035=X49=SAMPLE75=2017010134=205152=2017010109455901789785960=201701010945590178978595799=10000100268=1279=1269=148=17359555=6SZ683=355903270=10220.0271=4346=21023=710=087
1128=99=18135=X49=SAMPLE75=2017010134=181952=2017010105013667966505260=201701010501366796650525799=10000100268=1279=1269=148=17359555=6SZ683=355904270=10220.0271=34346=31023=710=147
1128=99=18035=X49=SAMPLE75=2017010134=355052=2017010104010591146839860=201701010401059114683985799=10000100268=1279=1269=148=17359555=6SZ683=355905270=10220.0271=4346=21023=710=075
1128=99=18135=X49=SAMPLE75=2017010134=88252=2017010105472422314044260=201701010547242231404425799=10000100268=1279=1269=148=17359555=6SZ683=355906270=10220.0271=34346=31023=710=134
1128=99=18035=X49=SAMPLE75=2017010134=481252=2017010100271092740970560=201701010027109274097055799=10000100268=1279=1269=148=17359555=6SZ683=355907270=10220.0271=4346=21023=710=071
1128=99=18135=X49=SAMPLE75=2017010134=121352=2017010104230526767995160=201701010423052676799515799=10000100268=1279=1269=148=17359555=6SZ683=355908270=10220.0271=34346=31023=710=168
1128=99=18035=X49=SAMPLE75=2017010134=317352=2017010100273240703207260=201701010027324070320725799=10000100268=1279=1269=148=17359555=6SZ683=355909270=10217.0271=4346=21023=410=065
1128=99=18035=X49=SAMPLE75=2017010134=208752=2017010105595461731266760=201701010559546173126675799=10000100268=1279=1269=148=17359555=6SZ683=355910270=10220.0271=4346=21023=710=084
1128=99=18135=X49=SAMPLE75=2017010134=270952=2017010102273976359845560=201701010227397635984555799=10000100268=1279=1269=148=17359555=6SZ683=355911270=10220.0271=34346=31023=710=149
1128=99=18035=X49=SAMPLE75=2017010134=461952=2017010103500410108418060=201701010350041010841805799=10000100268=1279=0269=048=17359555=6SZ683=355912270=10213.0271=1346=11023=110=075
1128=99=17935=X49=SAMPLE75=2017010134=179852=2017010100412394773247160=201701010041239477324715799=00000100268=1279=0269=048=17360055=6SH783=99101270=10266.0271=3346=11023=110=013
1128=99=16835=X49=SAMPLE75=2017010134=308852=2017010110490739073304360=201701011049073907330435799=10001000268=1279=0269=N48=17360055=6SH783=99102270=10266.0286=25510=089
1128=99=18035=X49=SAMPLE75=2017010134=96652=2017010109084957194427060=201701010908495719442705799=10000100268=1279=1269=048=17359555=6SZ683=355913270=10212.0271=5346=31023=210=086
1128=99=25035=X49=SAMPLE75=2017010134=257152=2017010106342971223241460=201701010634297122324145799=10000100268=2279=2269=048=17360055=6SH783=99103270=10266.0271=3346=11023=1279=0269=048=17360055=6SH783=99104270=10256.0271=3346=11023=1010=246
1128=99=18035=X49=SAMPLE75=2017010134=481252=2017010107060836850169760=201701010706083685016975799=10000100268=1279=1269=148=17359555=6SZ683=355914270=10220.0271=4346=21023=710=086
1128=99=18135=X49=SAMPLE75=2017010134=193752=2017010110595860595385360=201701011059586059538535799=10000100268=1279=1269=148=17359555=6SZ683=355915270=10220.0271=34346=31023=710=138
1128=99=18035=X49=SAMPLE75=2017010134=285652=2017010112505135981326760=201701011250513598132675799=10000100268=1279=1269=048=17359555=6SZ683=355916270=10206.0271=4346=21023=810=091
1128=99=18135=X49=SAMPLE75=2017010134=163352=2017010107501302743009960=201701010750130274300995799=10000100268=1279=1269=048=17359555=6SZ683=355917270=10206.0271=34346=31023=810=189
1128=99=18035=X49=SAMPLE75=2017010134=308652=2017010104325185067219460=201701010432518506721945799=10000100268=1279=1269=048=17359555=6SZ683=355918270=10206.0271=4346=21023=810=085
1128=99=18135=X49=SAMPLE75=2017010134=304152=2017010110105567812782660=201701011010556781278265799=10000100268=1279=1269=048=17359555=6SZ683=355919270=10206.0271=34346=31023=810=164
1128=99=18035=X49=SAMPLE75=2017010134=112152=2017010107124697780261260=201701010712469778026125799=10000100268=1279=1269=148=17359555=6SZ683=355920270=10220.0271=4346=21023=710=095
1128=99=18035=X49=SAMPLE75=2017010134=103652=2017010101093147281694360=201701010109314728169435799=10000100268=1279=1269=048=17359555=6SZ683=355921270=10206.0271=4346=21023=810=094
1128=99=18135=X49=SAMPLE75=2017010134=218652=2017010107072103039049260=201701010707210303904925799=10000100268=1279=1269=048=17359555=6SZ683=355922270=10207.0271=42346=71023=710=152
1128=99=18135=X49=SAMPLE75=2017010134=468052=2017010105310205789316560=201701010531020578931655799=10000100268=1279=1269=148=17359555=6SZ683=355923270=10220.0271=34346=31023=710=150
1128=99=18135=X49=SAMPLE75=2017010134=478952=2017010108360227059184160=201701010836022705918415799=10000100268=1279=1269=048=17359555=6SZ683=355924270=10207.0271=12346=61023=710=138
1128=99=18135=X49=SAMPLE75=2017010134=397652=2017010107562852474254760=201701010756285247425475799=10000100268=1279=1269=048=17359555=6SZ683=355925270=10207.0271=42346=71023=710=126
1128=99=18135=X49=SAMPLE75=2017010134=160852=2017010110295344328866960=201701011029534432886695799=10000100268=1279=1269=048=17359555=6SZ683=355926270=10207.0271=12346=61023=710=146
1128=99=18035=X49=SAMPLE75=2017010134=225852=2017010113281044411855460=201701011328104441185545799=10000100268=1279=1269=148=17359555=6SZ683=355927270=10220.0271=4346=21023=710=082
1128=99=18035=X49=SAMPLE75=2017010134=192252=2017010113302529369121660=201701011330252936912165799=10000100268=1279=1269=048=17359555=6SZ683=355928270=10212.0271=4346=21023=210=095
1128=99=18135=X49=SAMPLE75=2017010134=294252=2017010109374845501687860=201701010937484550168785799=10000100268=1279=1269=048=17359555=6SZ683=355929270=10206.0271=34346=31023=810=152
1128=99=18135=X49=SAMPLE75=2017010134=342252=2017010111242474497411060=201701011124247449741105799=10000100268=1279=1269=148=17359555=6SZ683=355930270=10220.0271=34346=31023=710=154
1128=99=18135=X49=SAMPLE75=2017010134=116952=2017010108515101127274160=201701010851510112727415799=10000100268=1279=1269=048=17359555=6SZ683=355931270=10207.0271=42346=71023=710=145
1128=99=18035=X49=SAMPLE75=2017010134=60152=2017010102431812301766960=201701010243181230176695799=10000100268=1279=1269=048=17359555=6SZ683=355932270=10206.0271=4346=21023=810=096
1128=99=18135=X49=SAMPLE75=2017010134=243352=2017010100590888480151160=201701010059088848015115799=10000100268=1279=1269=048=17359555=6SZ683=355933270=10207.0271=12346=61023=710=118
1128=99=18035=X49=SAMPLE75=2017010134=216052=2017010100414817214994760=201701010041481721499475799=10000100268=1279=1269=148=17359555=6SZ683=355934270=10220.0271=4346=21023=710=070
1128=99=18135=X49=SAMPLE75=2017010134=72552=2017010113093270676611460=201701011309327067661145799=10000100268=1279=1269=048=17359555=6SZ683=355935270=10206.0271=34346=31023=810=134
1128=99=18135=X49=SAMPLE75=2017010134=209352=2017010112125097583163160=201701011212509758316315799=10000100268=1279=1269=148=17359555=6SZ683=355936270=10220.0271=34346=31023=710=146
1128=99=18135=X49=SAMPLE75=2017010134=20452=2017010112491999795478860=201701011249199979547885799=10000100268=1279=1269=048=17359555=6SZ683=355937270=10207.0271=42346=71023=710=127
1128=99=18035=X49=SAMPLE75=2017010134=419452=2017010100553746178118060=201701010055374617811805799=10000100268=1279=1269=048=17359555=6SZ683=355938270=10206.0271=4346=21023=810=077
1128=99=18035=X49=SAMPLE75=2017010134=337852=2017010108285148276706860=201701010828514827670685799=10000100268=1279=1269=148=17359555=6SZ683=355939270=10220.0271=4346=21023=710=084
1128=99=18135=X49=SAMPLE75=2017010134=81552=2017010112364707421837460=201701011236470742183745799=10000100268=1279=1269=148=17359555=6SZ683=355940270=10220.0271=34346=31023=710=096
1128=99=18135=X49=SAMPLE75=2017010134=327952=2017010108074193894732260=201701010807419389473225799=10000100268=1279=1269=048=17359555=6SZ683=355941270=10207.0271=12346=61023=710=124
1128=99=18135=X49=SAMPLE75=2017010134=400852=2017010112084072937865260=201701011208407293786525799=10000100268=1279=1269=048=17359555=6SZ683=355942270=10207.0271=42346=71023=710=130
1128=99=18035=X49=SAMPLE75=2017010134=57152=2017010103403552660748260=201701010340355266074825799=10000100268=1279=1269=148=17359555=6SZ683=355943270=10220.0271=4346=21023=710=053
1128=99=18135=X49=SAMPLE75=2017010134=407552=2017010100004659731906660=201701010000465973190665799=10000100268=1279=1269=148=17359555=6SZ683=355944270=10220.0271=34346=31023=710=136
1128=99=18135=X49=SAMPLE75=2017010134=296552=2017010102261372905234260=201701010226137290523425799=10000100268=1279=1269=048=17359555=6SZ683=355945270=10207.0271=12346=61023=710=130
1128=99=18135=X49=SAMPLE75=2017010134=261652=2017010107035073178988660=201701010703507317898865799=10000100268=1279=1269=048=17359555=6SZ683=355946270=10207.0271=42346=71023=710=138
1128=99=18035=X49=SAMPLE75=2017010134=163052=2017010111565260415509160=201701011156526041550915799=10000100268=1279=1269=148=17359555=6SZ683=355947270=10220.0271=4346=21023=710=071
1128=99=18135=X49=SAMPLE75=2017010134=376352=2017010109310152834319160=201701010931015283431915799=10000100268=1279=1269=148=17359555=6SZ683=355948270=10220.0271=34346=31023=710=143
1128=99=18035=X49=SAMPLE75=2017010134=339752=2017010103353803253730960=201701010335380325373095799=10000100268=1279=1269=148=17359555=6SZ683=355949270=10220.0271=4346=21023=710=097
1128=99=18135=X49=SAMPLE75=2017010134=452752=2017010108302313317379560=201701010830231331737955799=10000100268=1279=1269=048=17359555=6SZ683=355950270=10207.0271=12346=61023=710=128
1128=99=18135=X49=SAMPLE75=2017010134=324952=2017010111264675957089560=201701011126467595708955799=10000100268=1279=1269=148=17359555=6SZ683=355951270=10220.0271=34346=31023=710=153
1128=99=18135=X49=SAMPLE75=2017010134=48652=2017010113324736887320560=201701011332473688732055799=10000100268=1279=1269=048=17359555=6SZ683=355952270=10207.0271=42346=71023=710=171
1128=99=18035=X49=SAMPLE75=2017010134=158952=2017010100272521598593560=201701010027252159859355799=10000100268=1279=1269=148=17359555=6SZ683=355953270=10220.0271=4346=21023=710=092
