1128=99=18235=X49=SAMPLE75=2017010134=139052=2017010105303287467206660=201701010530328746720665799=10000100268=1279=1269=048=17359555=6SZ683=357902270=10212.0271=33346=111023=510=187
1128=99=18235=X49=SAMPLE75=2017010134=445952=2017010109210027741841660=201701010921002774184165799=10000100268=1279=1269=048=17359555=6SZ683=357903270=10212.0271=26346=101023=510=201
1128=99=18135=X49=SAMPLE75=2017010134=371652=2017010111080477422161160=201701011108047742216115799=10000100268=1279=1269=148=17359555=6SZ683=357904270=10221.0271=26346=91023=510=181
1128=99=18035=X49=SAMPLE75=2017010134=490452=2017010112232322020794760=201701011223232202079475799=10000100268=1279=1269=048=17359555=6SZ683=357905270=10216.0271=7346=71023=110=125
1128=99=18135=X49=SAMPLE75=2017010134=361352=2017010108190395766926360=201701010819039576692635799=10000100268=1279=1269=048=17359555=6SZ683=357906270=10215.0271=20346=91023=210=152
1128=99=18235=X49=SAMPLE75=2017010134=340152=2017010100360981906270760=201701010036098190627075799=10000100268=1279=1269=048=17359555=6SZ683=357907270=10212.0271=33346=111023=510=193
1128=99=20835=X49=SAMPLE75=2017010134=326652=2017010111554805825931360=201701011155480582593135799=00000001268=1279=0269=248=17359555=6SZ683=357908270=10216.0271=1346=25797=237705=237=032=137=032=110=104
1128=99=15635=X49=SAMPLE75=2017010134=428352=2017010110095349875775060=201701011009534987577505799=00000010268=1279=0269=e48=17359555=6SZ683=357909271=8010=117
1128=99=18035=X49=SAMPLE75=2017010134=293652=2017010108002654257436560=201701010800265425743655799=10000100268=1279=1269=048=17359555=6SZ683=357910270=10216.0271=6346=61023=110=122
1128=99=18035=X49=SAMPLE75=2017010134=370052=2017010102534791116888260=201701010253479111688825799=10000100268=1279=1269=148=17359555=6SZ683=357911270=10217.0271=2346=21023=110=127
1128=99=18035=X49=SAMPLE75=2017010134=184052=2017010109221756251791760=201701010922175625179175799=10000100268=1279=1269=148=17359555=6SZ683=357912270=10217.0271=3346=31023=110=120
1128=99=18035=X49=SAMPLE75=2017010134=59752=2017010101270150228425160=201701010127015022842515799=10000100268=1279=1269=148=17359555=6SZ683=357913270=10217.0271=4346=41023=110=118
1128=99=18035=X49=SAMPLE75=2017010134=183952=2017010106193856185916860=201701010619385618591685799=10000100268=1279=1269=048=17359555=6SZ683=357914270=10216.0271=5346=51023=110=131
1128=99=18035=X49=SAMPLE75=2017010134=335152=2017010100500985328403960=201701010050098532840395799=10000100268=1279=1269=048=17359555=6SZ683=357915270=10216.0271=4346=41023=110=115
1128=99=18035=X49=SAMPLE75=2017010134=123952=2017010114310468236280760=201701011431046823628075799=10000100268=1279=1269=048=17359555=6SZ683=357916270=10216.0271=3346=31023=110=124
1128=99=25035=X49=SAMPLE75=2017010134=314052=2017010112454985466930460=201701011245498546693045799=10000100268=2279=2269=048=17360055=6SH783=99398270=10269.0271=3346=11023=1279=0269=048=17360055=6SH783=99399270=10259.0271=3346=11023=1010=070
1128=99=18035=X49=SAMPLE75=2017010134=206252=2017010101160261652777960=201701010116026165277795799=10000100268=1279=1269=048=17359555=6SZ683=357917270=10216.0271=2346=21023=110=111
1128=99=18035=X49=SAMPLE75=2017010134=462252=2017010110345581889745760=201701011034558188974575799=10000100268=1279=1269=148=17359555=6SZ683=357918270=10217.0271=5346=51023=110=133
1128=99=18035=X49=SAMPLE75=2017010134=123952=2017010107180336341504960=201701010718033634150495799=10000100268=1279=1269=048=17359555=6SZ683=357919270=10216.0271=3346=31023=110=113
1128=99=18035=X49=SAMPLE75=2017010134=149252=2017010102101569575377260=201701010210156957537725799=10000100268=1279=1269=048=17359555=6SZ683=357920270=10216.0271=4346=41023=110=099
1128=99=18035=X49=SAMPLE75=2017010134=431652=2017010112344038854057960=201701011234403885405795799=10000100268=1279=1269=048=17359555=6SZ683=357921270=10216.0271=5346=51023=110=090
1128=99=18035=X49=SAMPLE75=2017010134=202152=2017010109550204004644860=201701010955020400464485799=10000100268=1279=1269=148=17359555=6SZ683=357922270=10217.0271=4346=41023=110=101
1128=99=18035=X49=SAMPLE75=2017010134=357552=2017010100540865600635560=201701010054086560063555799=10000100268=1279=1269=048=17359555=6SZ683=357923270=10216.0271=6346=61023=110=110
1128=99=17935=X49=SAMPLE75=2017010134=91452=2017010101120564550654160=201701010112056455065415799=10000100268=1279=0269=048=17360055=6SH783=99400270=10269.0271=3346=11023=110=012
1128=99=18235=X49=SAMPLE75=2017010134=174252=2017010111072050182367760=201701011107205018236775799=10000100268=1279=1269=048=17359555=6SZ683=357924270=10214.0271=19346=101023=310=225
1128=99=18235=X49=SAMPLE75=2017010134=115452=2017010101093672507712060=201701010109367250771205799=10000100268=1279=1269=048=17359555=6SZ683=357925270=10215.0271=21346=101023=210=227
1128=99=18035=X49=SAMPLE75=2017010134=304352=2017010103032102847733060=201701010303210284773305799=10000100268=1279=1269=048=17359555=6SZ683=357926270=10216.0271=5346=51023=110=115
1128=99=25035=X49=SAMPLE75=2017010134=183952=2017010103063262573047260=201701010306326257304725799=10000100268=2279=2269=048=17360055=6SH783=99401270=10269.0271=3346=11023=1279=0269=048=17360055=6SH783=99402270=10259.0271=3346=11023=1010=051
1128=99=18135=X49=SAMPLE75=2017010134=20752=2017010105174162084994660=201701010517416208499465799=10000100268=1279=1269=048=17359555=6SZ683=357927270=10208.0271=19346=41023=910=185
1128=99=18235=X49=SAMPLE75=2017010134=396652=2017010112150195476242960=201701011215019547624295799=10000100268=1279=1269=048=17359555=6SZ683=357928270=10215.0271=22346=111023=210=214
1128=99=18235=X49=SAMPLE75=2017010134=109452=2017010106513401589474560=201701010651340158947455799=10000100268=1279=1269=148=17359555=6SZ683=357929270=10221.0271=27346=101023=510=198
1128=99=18135=X49=SAMPLE75=2017010134=455952=2017010100260020317546460=201701010026002031754645799=10000100268=1279=1269=148=17359555=6SZ683=357930270=10223.0271=20346=51023=710=162
1128=99=18035=X49=SAMPLE75=2017010134=65452=2017010114030022886263660=201701011403002288626365799=10000100268=1279=1269=048=17359555=6SZ683=357931270=10216.0271=4346=41023=110=115
1128=99=18235=X49=SAMPLE75=2017010134=199752=2017010112353000872368660=201701011235300087236865799=10000100268=1279=1269=048=17359555=6SZ683=357932270=10215.0271=21346=101023=210=217
1128=99=18135=X49=SAMPLE75=2017010134=34352=2017010103245102325283760=201701010324510232528375799=10000100268=1279=1269=048=17359555=6SZ683=357933270=10208.0271=20346=51023=910=163
1128=99=20835=X49=SAMPLE75=2017010134=107252=2017010110062782921513260=201701011006278292151325799=00000001268=1279=0269=248=17359555=6SZ683=357934270=10217.0271=1346=25797=137705=237=032=137=032=110=073
1128=99=15635=X49=SAMPLE75=2017010134=195252=2017010102125832624390860=201701010212583262439085799=00000010268=1279=0269=e48=17359555=6SZ683=357935271=8110=089
1128=99=18035=X49=SAMPLE75=2017010134=284352=2017010101174695584166660=201701010117469558416665799=00000100268=1279=1269=148=17359555=6SZ683=357936270=10217.0271=3346=31023=110=097
1128=99=16935=X49=SAMPLE75=2017010134=57552=2017010110014745690611760=201701011001474569061175799=10001000268=1279=0269=748=17359555=6SZ683=357937270=10217.0286=25510=155
1128=99=18035=X49=SAMPLE75=2017010134=466852=2017010101012955410068860=201701010101295541006885799=10000100268=1279=1269=048=17359555=6SZ683=357938270=10216.0271=5346=51023=110=111
1128=99=18035=X49=SAMPLE75=2017010134=319252=2017010102071470003982160=201701010207147000398215799=10000100268=1279=1269=148=17359555=6SZ683=357939270=10217.0271=2346=21023=110=114
1128=99=18035=X49=SAMPLE75=2017010134=167252=2017010112523936371696160=201701011252393637169615799=10000100268=1279=1269=148=17359555=6SZ683=357940270=10217.0271=1346=11023=110=104
1128=99=18035=X49=SAMPLE75=2017010134=446952=2017010102214968484502260=201701010221496848450225799=10000100268=1279=1269=048=17359555=6SZ683=357941270=10216.0271=6346=61023=110=120
1128=99=17935=X49=SAMPLE75=2017010134=278952=2017010110133718474152260=201701011013371847415225799=10000100268=1279=0269=048=17360055=6SH783=99403270=10269.0271=3346=11023=110=043
1128=99=25435=X49=SAMPLE75=2017010134=162052=2017010101555891472821760=201701010155589147282175799=10000100268=2279=1269=048=17359555=6SZ683=357942270=10215.0271=22346=111023=2279=1269=048=17359555=6SZ683=357943270=10214.0271=18346=91023=310=037
1128=99=18035=X49=SAMPLE75=2017010134=433152=2017010104151426474049960=201701010415142647404995799=10000100268=1279=1269=148=17359555=6SZ683=357944270=10217.0271=2346=21023=110=114
1128=99=18035=X49=SAMPLE75=2017010134=5152=2017010113410863676514860=201701011341086367651485799=10000100268=1279=1269=148=17359555=6SZ683=357945270=10217.0271=1346=11023=110=107
1128=99=18035=X49=SAMPLE75=2017010134=194652=2017010104395419179355860=201701010439541917935585799=10000100268=1279=1269=148=17359555=6SZ683=357946270=10217.0271=2346=21023=110=127
1128=99=18035=X49=SAMPLE75=2017010134=473652=2017010102273320480967460=201701010227332048096745799=10000100268=1279=1269=148=17359555=6SZ683=357947270=10217.0271=3346=31023=110=139
1128=99=18035=X49=SAMPLE75=2017010134=118152=2017010109473096898316360=201701010947309689831635799=10000100268=1279=1269=148=17359555=6SZ683=357948270=10217.0271=4346=41023=110=144
1128=99=18035=X49=SAMPLE75=2017010134=188052=2017010102243764136386960=201701010224376413638695799=10000100268=1279=1269=048=17359555=6SZ683=357949270=10216.0271=5346=51023=110=113
1128=99=18035=X49=SAMPLE75=2017010134=253052=2017010114031166662514860=201701011403116666251485799=10000100268=1279=1269=048=17359555=6SZ683=357950270=10216.0271=4346=41023=110=123
1128=99=25035=X49=SAMPLE75=2017010134=333352=2017010103501422073942460=201701010350142207394245799=10000100268=2279=2269=048=17360055=6SH783=99404270=10269.0271=3346=11023=1279=0269=048=17360055=6SH783=99405270=10259.0271=3346=11023=1010=074
1128=99=18035=X49=SAMPLE75=2017010134=291352=2017010110123634734373260=201701011012363473437325799=10000100268=1279=1269=048=17359555=6SZ683=357951270=10216.0271=3346=31023=110=128
1128=99=18035=X49=SAMPLE75=2017010134=320452=2017010105215130564459660=201701010521513056445965799=10000100268=1279=1269=148=17359555=6SZ683=357952270=10217.0271=5346=51023=110=076
1128=99=18035=X49=SAMPLE75=2017010134=200552=2017010111305418485286160=201701011130541848528615799=10000100268=1279=1269=148=17359555=6SZ683=357953270=10217.0271=6346=61023=110=131
1128=99=17935=X49=SAMPLE75=2017010134=177552=2017010113390100074631060=201701011339010007463105799=10000100268=1279=0269=148=17360055=6SH783=99406270=10273.0271=3346=11023=110=053
1128=99=24935=X49=SAMPLE75=2017010134=360252=2017010113572874248644960=201701011357287424864495799=10000100268=2279=1269=148=17360055=6SH783=99407270=10274.0271=5346=21023=2279=1269=148=17360055=6SH783=99408270=10276.0271=3346=11023=410=028
1128=99=18035=X49=SAMPLE75=2017010134=153452=2017010111314114618897160=201701011131411461889715799=10000100268=1279=1269=148=17359555=6SZ683=357954270=10217.0271=5346=51023=110=152
1128=99=25135=X49=SAMPLE75=2017010134=287552=2017010114073945294679560=201701011407394529467955799=10000100268=2279=2269=148=17360055=6SH783=99409270=10273.0271=3346=11023=1279=0269=148=17360055=6SH783=99410270=10283.0271=61346=31023=1010=154
1128=99=18035=X49=SAMPLE75=2017010134=103652=2017010103052728940619960=201701010305272894061995799=10000100268=1279=1269=048=17359555=6SZ683=357955270=10216.0271=2346=21023=110=112
1128=99=25535=X49=SAMPLE75=2017010134=197852=2017010105143803564927460=201701010514380356492745799=10000100268=2279=1269=048=17359555=6SZ683=357956270=10215.0271=21346=101023=2279=1269=048=17359555=6SZ683=357957270=10214.0271=19346=101023=310=112
1128=99=21835=X49=SAMPLE75=2017010134=219952=2017010107253185058670060=201701010725318505867005799=00000001268=1279=0269=248=17359555=6SZ683=357958270=10216.0271=2346=35797=237705=337=032=237=032=137=032=110=006
1128=99=15635=X49=SAMPLE75=2017010134=370452=2017010107412418863898860=201701010741241886389885799=00000010268=1279=0269=e48=17359555=6SZ683=357959271=8310=101
1128=99=25335=X49=SAMPLE75=2017010134=271552=2017010114313867212344060=201701011431386721234405799=10000100268=2279=2269=048=17359555=6SZ683=357960270=10216.0271=2346=21023=1279=0269=048=17359555=6SZ683=357961270=10206.0271=39346=51023=1010=249
1128=99=17935=X49=SAMPLE75=2017010134=19052=2017010107220734131574360=201701010722073413157435799=10000100268=1279=0269=148=17360055=6SH783=99411270=10272.0271=3346=11023=110=009
1128=99=18035=X49=SAMPLE75=2017010134=474252=2017010112521626182840660=201701011252162618284065799=10000100268=1279=0269=148=17359555=6SZ683=357962270=10216.0271=1346=11023=110=086
1128=99=17935=X49=SAMPLE75=2017010134=330652=2017010103022851680180860=201701010302285168018085799=10000100268=1279=0269=148=17360055=6SH783=99412270=10273.0271=3346=11023=210=012
1128=99=18135=X49=SAMPLE75=2017010134=125652=2017010111371760664299660=201701011137176066429965799=10000100268=1279=1269=048=17359555=6SZ683=357963270=10215.0271=20346=91023=110=142
1128=99=25335=X49=SAMPLE75=2017010134=491552=2017010114283333682916060=201701011428333368291605799=10000100268=2279=1269=148=17359555=6SZ683=357964270=10220.0271=19346=81023=5279=1269=148=17359555=6SZ683=357965270=10221.0271=24346=91023=610=021
1128=99=18135=X49=SAMPLE75=2017010134=431952=2017010104185176142032860=201701010418517614203285799=10000100268=1279=1269=048=17359555=6SZ683=357966270=10215.0271=19346=81023=110=161
1128=99=22035=X49=SAMPLE75=2017010134=325852=2017010100252150906494060=201701010025215090649405799=00000001268=1279=0269=248=17359555=6SZ683=357967270=10216.0271=1346=25797=137705=237=032=137=621180795608032=110=176
1128=99=15635=X49=SAMPLE75=2017010134=394252=2017010101532531142074360=201701010153253114207435799=00000010268=1279=0269=e48=17359555=6SZ683=357968271=8410=104
1128=99=25335=X49=SAMPLE75=2017010134=408252=2017010113551121062454360=201701011355112106245435799=10000100268=2279=2269=148=17359555=6SZ683=357969270=10216.0271=1346=11023=1279=0269=148=17359555=6SZ683=357970270=10226.0271=15346=21023=1010=253
1128=99=18135=X49=SAMPLE75=2017010134=17952=2017010113435992370613860=201701011343599237061385799=10000100268=1279=1269=048=17359555=6SZ683=357971270=10215.0271=16346=71023=110=155
1128=99=25035=X49=SAMPLE75=2017010134=418752=2017010108222702437307160=201701010822270243730715799=10000100268=2279=2269=148=17360055=6SH783=99413270=10272.0271=3346=11023=1279=0269=148=17360055=6SH783=99414270=10282.0271=3346=11023=1010=029
1128=99=18135=X49=SAMPLE75=2017010134=71252=2017010113043468677130060=201701011304346867713005799=10000100268=1279=1269=048=17359555=6SZ683=357972270=10215.0271=17346=81023=110=166
1128=99=18035=X49=SAMPLE75=2017010134=415752=2017010104020498132628460=201701010402049813262845799=10000100268=1279=1269=148=17359555=6SZ683=357973270=10217.0271=6346=61023=110=113
1128=99=18135=X49=SAMPLE75=2017010134=234352=2017010114050747415851460=201701011405074741585145799=10000100268=1279=1269=148=17359555=6SZ683=357974270=10218.0271=17346=81023=210=167
1128=99=18135=X49=SAMPLE75=2017010134=10052=2017010113113945497049060=201701011311394549704905799=10000100268=1279=1269=148=17359555=6SZ683=357975270=10220.0271=18346=71023=410=170
1128=99=18035=X49=SAMPLE75=2017010134=41452=2017010100475981807927660=201701010047598180792765799=10000100268=1279=0269=148=17359555=6SZ683=357976270=10216.0271=1346=11023=110=117
1128=99=18135=X49=SAMPLE75=2017010134=83952=2017010112165885184675660=201701011216588518467565799=10000100268=1279=1269=048=17359555=6SZ683=357977270=10215.0271=16346=71023=110=172
1128=99=17935=X49=SAMPLE75=2017010134=122352=2017010109411952183778660=201701010941195218377865799=10000100268=1279=0269=148=17360055=6SH783=99415270=10272.0271=3346=11023=110=008
1128=99=18235=X49=SAMPLE75=2017010134=370652=2017010102141481417531960=201701010214148141753195799=10000100268=1279=1269=048=17359555=6SZ683=357978270=10212.0271=26346=101023=410=204
1128=99=18235=X49=SAMPLE75=2017010134=105752=2017010109115677742325460=201701010911567774232545799=10000100268=1279=1269=048=17359555=6SZ683=357979270=10212.0271=33346=111023=410=201
1128=99=22035=X49=SAMPLE75=2017010134=344852=2017010104585145180849960=201701010458514518084995799=00000001268=1279=0269=248=17359555=6SZ683=357980270=10216.0271=1346=25797=137705=237=032=137=621180795610232=110=211
1128=99=15635=X49=SAMPLE75=2017010134=453552=2017010106182680613069160=201701010618268061306915799=00000010268=1279=0269=e48=17359555=6SZ683=357981271=8510=134
1128=99=25335=X49=SAMPLE75=2017010134=393352=2017010106242182836648160=201701010624218283664815799=10000100268=2279=2269=148=17359555=6SZ683=357982270=10216.0271=1346=11023=1279=0269=148=17359555=6SZ683=357983270=10226.0271=15346=21023=1010=030
1128=99=18035=X49=SAMPLE75=2017010134=302852=2017010101185643640302560=201701010118564364030255799=10000100268=1279=0269=148=17359555=6SZ683=357984270=10216.0271=1346=11023=110=116
1128=99=25035=X49=SAMPLE75=2017010134=132952=2017010114204060262285260=201701011420406026228525799=10000100268=2279=2269=148=17360055=6SH783=99416270=10272.0271=3346=11023=1279=0269=148=17360055=6SH783=99417270=10282.0271=3346=11023=1010=069
1128=99=18135=X49=SAMPLE75=2017010134=353752=2017010103405431488131960=201701010340543148813195799=10000100268=1279=1269=048=17359555=6SZ683=357985270=10215.0271=17346=81023=110=190
1128=99=18135=X49=SAMPLE75=2017010134=99652=2017010103532083905466060=201701010353208390546605799=10000100268=1279=1269=048=17359555=6SZ683=357986270=10215.0271=16346=71023=110=174
1128=99=18135=X49=SAMPLE75=2017010134=435952=2017010110342768419505460=201701011034276841950545799=10000100268=1279=1269=048=17359555=6SZ683=357987270=10215.0271=17346=81023=110=184
1128=99=18135=X49=SAMPLE75=2017010134=37652=2017010100540491722095360=201701010054049172209535799=10000100268=1279=1269=048=17359555=6SZ683=357988270=10215.0271=16346=71023=110=171
1128=99=22035=X49=SAMPLE75=2017010134=455752=2017010111163660093188060=201701011116366009318805799=00000001268=1279=0269=248=17359555=6SZ683=357989270=10216.0271=1346=25797=137705=237=032=137=621180795613632=110=228
1128=99=15635=X49=SAMPLE75=2017010134=309552=2017010102465582288342160=201701010246558228834215799=00000010268=1279=0269=e48=17359555=6SZ683=357990271=8610=139
1128=99=25335=X49=SAMPLE75=2017010134=242652=2017010101590323927256760=201701010159032392725675799=10000100268=2279=2269=148=17359555=6SZ683=357991270=10216.0271=1346=11023=1279=0269=148=17359555=6SZ683=357992270=10226.0271=15346=21023=1010=034
1128=99=18135=X49=SAMPLE75=2017010134=198852=2017010101033357565835660=201701010103335756583565799=10000100268=1279=1269=048=17359555=6SZ683=357993270=10215.0271=15346=61023=110=174
1128=99=18135=X49=SAMPLE75=2017010134=188452=2017010100405952272694660=201701010040595227269465799=10000100268=1279=1269=048=17359555=6SZ683=357994270=10215.0271=16346=71023=110=168
1128=99=18035=X49=SAMPLE75=2017010134=314352=2017010101210092846256160=201701010121009284625615799=10000100268=1279=1269=148=17359555=6SZ683=357995270=10217.0271=5346=51023=110=121
1128=99=18035=X49=SAMPLE75=2017010134=476152=2017010104133762021499860=201701010413376202149985799=10000100268=1279=0269=048=17359555=6SZ683=357996270=10216.0271=1346=11023=110=128
1128=99=18135=X49=SAMPLE75=2017010134=266552=2017010100585280168469260=201701010058528016846925799=10000100268=1279=1269=048=17359555=6SZ683=357997270=10215.0271=17346=81023=210=180
1128=99=18035=X49=SAMPLE75=2017010134=414752=2017010102300048618482360=201701010230004861848235799=10000100268=1279=1269=148=17359555=6SZ683=357998270=10217.0271=4346=41023=110=116
1128=99=25135=X49=SAMPLE75=2017010134=405952=2017010110014889198002860=201701011001488919800285799=10000100268=2279=2269=148=17360055=6SH783=99418270=10273.0271=3346=11023=1279=0269=148=17360055=6SH783=99419270=10283.0271=61346=31023=1010=112
1128=99=20835=X49=SAMPLE75=2017010134=458152=2017010107030081128510960=201701010703008112851095799=00000001268=1279=0269=248=17359555=6SZ683=357999270=10216.0271=1346=25797=237705=237=032=137=032=110=106
1128=99=15635=X49=SAMPLE75=2017010134=373952=2017010111070812844745160=201701011107081284474515799=00000010268=1279=0269=e48=17359555=6SZ683=358000271=8710=102
1128=99=25335=X49=SAMPLE75=2017010134=168952=2017010106494462074738060=201701010649446207473805799=10000100268=2279=2269=048=17359555=6SZ683=358001270=10216.0271=1346=11023=1279=0269=048=17359555=6SZ683=358002270=10206.0271=39346=51023=1010=240
1128=99=18035=X49=SAMPLE75=2017010134=2352=2017010109364153489113060=201701010936415348911305799=10000100268=1279=0269=048=17359555=6SZ683=358003270=10216.0271=1346=11023=110=104
1128=99=20835=X49=SAMPLE75=2017010134=25252=2017010103455497788504360=201701010345549778850435799=00000001268=1279=0269=248=17359555=6SZ683=358004270=10216.0271=1346=25797=237705=237=032=137=032=110=067
1128=99=15635=X49=SAMPLE75=2017010134=223552=2017010112033350353412860=201701011203335035341285799=00000010268=1279=0269=e48=17359555=6SZ683=358005271=8810=109
1128=99=25335=X49=SAMPLE75=2017010134=465652=2017010100243901011797760=201701010024390101179775799=10000100268=2279=2269=048=17359555=6SZ683=358006270=10216.0271=1346=11023=1279=0269=048=17359555=6SZ683=358007270=10206.0271=39346=51023=1010=251
1128=99=18035=X49=SAMPLE75=2017010134=319652=2017010108595318522947260=201701010859531852294725799=10000100268=1279=1269=148=17359555=6SZ683=358008270=10217.0271=5346=51023=110=109
1128=99=18135=X49=SAMPLE75=2017010134=492252=2017010105383112215277360=201701010538311221527735799=10000100268=1279=1269=148=17359555=6SZ683=358009270=10217.0271=13346=61023=110=139
1128=99=18235=X49=SAMPLE75=2017010134=308752=2017010109482033314279560=201701010948203331427955799=10000100268=1279=1269=048=17359555=6SZ683=358010270=10212.0271=26346=101023=410=180
1128=99=17935=X49=SAMPLE75=2017010134=345652=2017010107173119128543460=201701010717311912854345799=10000100268=1279=0269=148=17360055=6SH783=99420270=10273.0271=3346=11023=110=025
1128=99=18035=X49=SAMPLE75=2017010134=45352=2017010109163510847846360=201701010916351084784635799=10000100268=1279=1269=148=17359555=6SZ683=358011270=10217.0271=5346=51023=110=105
1128=99=25135=X49=SAMPLE75=2017010134=49952=2017010113361914733683860=201701011336191473368385799=10000100268=2279=2269=148=17360055=6SH783=99421270=10273.0271=3346=11023=1279=0269=148=17360055=6SH783=99422270=10283.0271=61346=31023=1010=074
1128=99=18135=X49=SAMPLE75=2017010134=12652=2017010102055141422399260=201701010205514142239925799=10000100268=1279=1269=148=17359555=6SZ683=358012270=10217.0271=13346=61023=110=140
1128=99=17935=X49=SAMPLE75=2017010134=331752=2017010108531562750780360=201701010853156275078035799=10000100268=1279=0269=148=17360055=6SH783=99423270=10273.0271=3346=11023=110=054
1128=99=18035=X49=SAMPLE75=2017010134=338552=2017010113530267052827660=201701011353026705282765799=10000100268=1279=1269=148=17359555=6SZ683=358013270=10217.0271=5346=51023=110=114
1128=99=25135=X49=SAMPLE75=2017010134=423152=2017010102531422596137160=201701010253142259613715799=10000100268=2279=2269=148=17360055=6SH783=99424270=10273.0271=3346=11023=1279=0269=148=17360055=6SH783=99425270=10283.0271=61346=31023=1010=105
1128=99=18035=X49=SAMPLE75=2017010134=128852=2017010108194596070889260=201701010819459607088925799=10000100268=1279=0269=148=17359555=6SZ683=358014270=10216.0271=1346=11023=110=118
1128=99=17935=X49=SAMPLE75=2017010134=4352=2017010100070242760307460=201701010007024276030745799=10000100268=1279=0269=148=17360055=6SH783=99426270=10272.0271=3346=11023=110=056
1128=99=18035=X49=SAMPLE75=2017010134=232452=2017010114152388588348960=201701011415238858834895799=10000100268=1279=1269=148=17359555=6SZ683=358015270=10217.0271=6346=61023=210=131
1128=99=17935=X49=SAMPLE75=2017010134=394452=2017010102562146573005960=201701010256214657300595799=10000100268=1279=0269=148=17360055=6SH783=99427270=10273.0271=3346=11023=210=062
1128=99=25035=X49=SAMPLE75=2017010134=440952=2017010103244595171805060=201701010324459517180505799=10000100268=2279=2269=148=17360055=6SH783=99428270=10272.0271=3346=11023=1279=0269=148=17360055=6SH783=99429270=10282.0271=3346=11023=1010=070
1128=99=18135=X49=SAMPLE75=2017010134=351952=2017010107415230876611860=201701010741523087661185799=10000100268=1279=1269=148=17359555=6SZ683=358016270=10217.0271=14346=71023=210=169
1128=99=18135=X49=SAMPLE75=2017010134=274852=2017010100485745313481960=201701010048574531348195799=10000100268=1279=1269=148=17359555=6SZ683=358017270=10220.0271=25346=81023=510=181
1128=99=18035=X49=SAMPLE75=2017010134=267452=2017010106465642173851360=201701010646564217385135799=10000100268=1279=1269=148=17359555=6SZ683=358018270=10216.0271=2346=21023=110=113
1128=99=18035=X49=SAMPLE75=2017010134=374952=2017010105521673302217460=201701010552167330221745799=10000100268=1279=1269=048=17359555=6SZ683=358019270=10215.0271=9346=71023=110=102
1128=99=18035=X49=SAMPLE75=2017010134=438252=2017010111152150061436060=201701011115215006143605799=10000100268=1279=1269=048=17359555=6SZ683=358020270=10215.0271=8346=61023=110=100
1128=99=18035=X49=SAMPLE75=2017010134=322952=2017010113534215684750960=201701011353421568475095799=10000100268=1279=1269=048=17359555=6SZ683=358021270=10215.0271=7346=51023=110=090
1128=99=18035=X49=SAMPLE75=2017010134=343652=2017010109120498369619760=201701010912049836961975799=10000100268=1279=1269=048=17359555=6SZ683=358022270=10215.0271=6346=41023=110=090
1128=99=18035=X49=SAMPLE75=2017010134=159152=2017010106375124851497360=201701010637512485149735799=10000100268=1279=1269=148=17359555=6SZ683=358023270=10216.0271=3346=31023=110=109
1128=99=18035=X49=SAMPLE75=2017010134=386352=2017010101545258440730960=201701010154525844073095799=10000100268=1279=1269=048=17359555=6SZ683=358024270=10215.0271=5346=31023=110=106
1128=99=18035=X49=SAMPLE75=2017010134=388152=2017010113402540029131460=201701011340254002913145799=10000100268=1279=1269=148=17359555=6SZ683=358025270=10216.0271=4346=41023=110=107
1128=99=18035=X49=SAMPLE75=2017010134=201852=2017010111350343193402060=201701011135034319340205799=10000100268=1279=1269=048=17359555=6SZ683=358026270=10215.0271=6346=41023=110=103
1128=99=18035=X49=SAMPLE75=2017010134=255252=2017010106192153235078560=201701010619215323507855799=10000100268=1279=1269=148=17359555=6SZ683=358027270=10216.0271=5346=51023=110=129
1128=99=25335=X49=SAMPLE75=2017010134=433152=2017010112153554308798160=201701011215355430879815799=10000100268=2279=1269=048=17359555=6SZ683=358028270=10209.0271=39346=51023=7279=1269=048=17359555=6SZ683=358029270=10208.0271=23346=61023=810=030
1128=99=17935=X49=SAMPLE75=2017010134=499352=2017010113045540693151760=201701011304554069315175799=10000100268=1279=1269=048=17360055=6SH783=99430270=10268.0271=2346=11023=110=040
1128=99=32135=X49=SAMPLE75=2017010134=299552=2017010105081099452015160=201701010508109945201515799=10000100268=3279=2269=048=17360055=6SH783=99431270=10268.0271=2346=11023=1279=1269=048=17360055=6SH783=99432270=10265.0271=5346=21023=3279=0269=048=17360055=6SH783=99433270=10258.0271=53346=21023=1010=076
1128=99=17935=X49=SAMPLE75=2017010134=429452=2017010110422616469335660=201701011042261646933565799=10000100268=1279=0269=048=17360055=6SH783=99434270=10268.0271=3346=11023=110=043
1128=99=24935=X49=SAMPLE75=2017010134=329152=2017010104382580087721860=201701010438258008772185799=10000100268=2279=1269=048=17360055=6SH783=99435270=10266.0271=5346=21023=3279=1269=048=17360055=6SH783=99436270=10265.0271=3346=11023=410=015
1128=99=18035=X49=SAMPLE75=2017010134=98052=2017010113122089494981460=201701011312208949498145799=10000100268=1279=1269=048=17359555=6SZ683=358030270=10215.0271=5346=31023=110=109
1128=99=25135=X49=SAMPLE75=2017010134=148552=2017010113133655399542160=201701011313365539954215799=10000100268=2279=2269=048=17360055=6SH783=99437270=10268.0271=3346=11023=1279=0269=048=17360055=6SH783=99438270=10258.0271=53346=21023=1010=107
1128=99=18035=X49=SAMPLE75=2017010134=164952=2017010110091554062922160=201701011009155406292215799=10000100268=1279=1269=048=17359555=6SZ683=358031270=10215.0271=6346=41023=110=113
1128=99=17935=X49=SAMPLE75=2017010134=276552=2017010112570339381918160=201701011257033938191815799=10000100268=1279=0269=048=17360055=6SH783=99439270=10268.0271=3346=11023=110=064
1128=99=18135=X49=SAMPLE75=2017010134=205152=2017010102254565738293460=201701010225456573829345799=10000100268=1279=1269=148=17359555=6SZ683=358032270=10220.0271=18346=71023=510=149
1128=99=18035=X49=SAMPLE75=2017010134=404552=2017010106371998683561560=201701010637199868356155799=10000100268=1279=1269=048=17359555=6SZ683=358033270=10215.0271=5346=31023=110=082
1128=99=25135=X49=SAMPLE75=2017010134=375552=2017010113413200923177860=201701011341320092317785799=10000100268=2279=2269=048=17360055=6SH783=99440270=10268.0271=3346=11023=1279=0269=048=17360055=6SH783=99441270=10258.0271=53346=21023=1010=087
1128=99=25035=X49=SAMPLE75=2017010134=218552=2017010101223847082586860=201701010122384708258685799=10000100268=2279=1269=048=17360055=6SH783=99442270=10263.0271=3346=11023=5279=1269=048=17360055=6SH783=99443270=10259.0271=11346=21023=910=063
1128=99=18035=X49=SAMPLE75=2017010134=81452=2017010110130951709512260=201701011013095170951225799=10000100268=1279=1269=148=17359555=6SZ683=358034270=10216.0271=4346=41023=110=120
1128=99=18035=X49=SAMPLE75=2017010134=79952=2017010110520540515622360=201701011052054051562235799=10000100268=1279=1269=048=17359555=6SZ683=358035270=10215.0271=6346=41023=110=108
1128=99=18035=X49=SAMPLE75=2017010134=148452=2017010105041904528096660=201701010504190452809665799=10000100268=1279=1269=048=17359555=6SZ683=358036270=10215.0271=7346=51023=110=125
1128=99=17935=X49=SAMPLE75=2017010134=307552=2017010110383193873562660=201701011038319387356265799=10000100268=1279=0269=048=17360055=6SH783=99444270=10268.0271=3346=11023=110=057
1128=99=18035=X49=SAMPLE75=2017010134=204452=2017010104413503997140160=201701010441350399714015799=10000100268=1279=1269=048=17359555=6SZ683=358037270=10215.0271=6346=41023=110=127
1128=99=18035=X49=SAMPLE75=2017010134=176552=2017010111462392485115060=201701011146239248511505799=10000100268=1279=1269=148=17359555=6SZ683=358038270=10216.0271=3346=31023=110=118
1128=99=18035=X49=SAMPLE75=2017010134=36552=2017010101530482197819560=201701010153048219781955799=10000100268=1279=1269=148=17359555=6SZ683=358039270=10216.0271=2346=21023=110=136
1128=99=25335=X49=SAMPLE75=2017010134=356652=2017010103114078109008460=201701010311407810900845799=10000100268=2279=1269=048=17359555=6SZ683=358040270=10209.0271=42346=61023=7279=1269=048=17359555=6SZ683=358041270=10208.0271=20346=51023=810=010
1128=99=18035=X49=SAMPLE75=2017010134=89752=2017010103243113981405860=201701010324311398140585799=10000100268=1279=1269=148=17359555=6SZ683=358042270=10216.0271=1346=11023=110=106
1128=99=18135=X49=SAMPLE75=2017010134=384252=2017010104510603196988360=201701010451060319698835799=10000100268=1279=1269=048=17359555=6SZ683=358043270=10215.0271=14346=51023=110=146
1128=99=18135=X49=SAMPLE75=2017010134=77752=2017010107323216854333660=201701010732321685433365799=10000100268=1279=1269=048=17359555=6SZ683=358044270=10215.0271=15346=61023=110=166
1128=99=18135=X49=SAMPLE75=2017010134=177652=2017010113142699113519860=201701011314269911351985799=10000100268=1279=1269=048=17359555=6SZ683=358045270=10215.0271=16346=71023=110=158
1128=99=18135=X49=SAMPLE75=2017010134=359552=2017010113395938638011760=201701011339593863801175799=10000100268=1279=1269=148=17359555=6SZ683=358046270=10220.0271=25346=81023=510=155
1128=99=20835=X49=SAMPLE75=2017010134=199552=2017010109100201833656960=201701010910020183365695799=00000001268=1279=0269=248=17359555=6SZ683=358047270=10216.0271=1346=25797=137705=237=032=137=032=110=100
1128=99=15635=X49=SAMPLE75=2017010134=430852=2017010110454591564678260=201701011045459156467825799=00000010268=1279=0269=e48=17359555=6SZ683=358048271=8910=139
1128=99=25335=X49=SAMPLE75=2017010134=45752=2017010109225517455323060=201701010922551745532305799=10000100268=2279=2269=148=17359555=6SZ683=358049270=10216.0271=1346=11023=1279=0269=148=17359555=6SZ683=358050270=10226.0271=15346=21023=1010=017
1128=99=17935=X49=SAMPLE75=2017010134=132752=2017010103150005743371560=201701010315000574337155799=10000100268=1279=0269=048=17360055=6SH783=99445270=10269.0271=3346=11023=110=067
1128=99=18135=X49=SAMPLE75=2017010134=435452=2017010110192980221410460=201701011019298022141045799=10000100268=1279=1269=148=17359555=6SZ683=358051270=10217.0271=13346=61023=110=160
1128=99=18135=X49=SAMPLE75=2017010134=145052=2017010107055203085086560=201701010705520308508655799=10000100268=1279=1269=148=17359555=6SZ683=358052270=10217.0271=14346=71023=110=173
1128=99=18135=X49=SAMPLE75=2017010134=45052=2017010104375269522867360=201701010437526952286735799=10000100268=1279=1269=148=17359555=6SZ683=358053270=10218.0271=16346=71023=210=161
1128=99=25135=X49=SAMPLE75=2017010134=257652=2017010101460115318920560=201701010146011531892055799=10000100268=2279=2269=048=17360055=6SH783=99446270=10269.0271=3346=11023=1279=0269=048=17360055=6SH783=99447270=10259.0271=11346=21023=1010=124
1128=99=18135=X49=SAMPLE75=2017010134=478252=2017010106033487787993760=201701010603348778799375799=10000100268=1279=1269=148=17359555=6SZ683=358054270=10220.0271=18346=71023=410=172
1128=99=25335=X49=SAMPLE75=2017010134=133352=2017010108030632471487960=201701010803063247148795799=10000100268=2279=1269=148=17359555=6SZ683=358055270=10220.0271=26346=81023=4279=1269=148=17359555=6SZ683=358056270=10224.0271=36346=41023=810=018
1128=99=18035=X49=SAMPLE75=2017010134=425852=2017010106464192447690660=201701010646419244769065799=10000100268=1279=1269=148=17360055=6SH783=99448270=10279.0271=11346=21023=710=094
1128=99=25435=X49=SAMPLE75=2017010134=493952=2017010100315488256941760=201701010031548825694175799=10000100268=2279=1269=148=17359555=6SZ683=358057270=10220.0271=23346=71023=4279=1269=148=17359555=6SZ683=358058270=10221.0271=27346=101023=510=047
1128=99=18035=X49=SAMPLE75=2017010134=105552=2017010113143960712357060=201701011314396071235705799=10000100268=1279=1269=148=17359555=6SZ683=358059270=10217.0271=6346=61023=110=107
1128=99=18035=X49=SAMPLE75=2017010134=435352=2017010112420764944786260=201701011242076494478625799=10000100268=1279=1269=148=17359555=6SZ683=358060270=10217.0271=5346=51023=110=096
1128=99=25135=X49=SAMPLE75=2017010134=193352=2017010101590622312912160=201701010159062231291215799=10000100268=2279=2269=148=17360055=6SH783=99449270=10273.0271=3346=11023=1279=0269=148=17360055=6SH783=99450270=10283.0271=53346=21023=1010=090
1128=99=25335=X49=SAMPLE75=2017010134=482552=2017010113573187936046760=201701011357318793604675799=10000100268=2279=1269=148=17359555=6SZ683=358061270=10220.0271=15346=61023=4279=1269=148=17359555=6SZ683=358062270=10224.0271=44346=51023=810=251
1128=99=18135=X49=SAMPLE75=2017010134=127352=2017010103111132875632560=201701010311113287563255799=10000100268=1279=1269=048=17359555=6SZ683=358063270=10214.0271=18346=91023=210=166
1128=99=18135=X49=SAMPLE75=2017010134=409852=2017010102003386528712360=201701010200338652871235799=10000100268=1279=1269=048=17359555=6SZ683=358064270=10207.0271=21346=61023=910=151
1128=99=25135=X49=SAMPLE75=2017010134=343952=2017010109292407800769060=201701010929240780076905799=10000100268=2279=1269=148=17360055=6SH783=99451270=10279.0271=3346=11023=6279=1269=148=17360055=6SH783=99452270=10283.0271=61346=31023=1010=121
1128=99=18135=X49=SAMPLE75=2017010134=112852=2017010113362293402913860=201701011336229340291385799=10000100268=1279=1269=048=17359555=6SZ683=358065270=10215.0271=17346=81023=110=153
1128=99=18035=X49=SAMPLE75=2017010134=28952=2017010112101235374559160=201701011210123537455915799=10000100268=1279=0269=048=17359555=6SZ683=358066270=10216.0271=1346=11023=110=105
1128=99=17935=X49=SAMPLE75=2017010134=337952=2017010114324456650312860=201701011432445665031285799=10000100268=1279=0269=048=17360055=6SH783=99453270=10269.0271=3346=11023=110=068
1128=99=18035=X49=SAMPLE75=2017010134=77852=2017010100384690616635460=201701010038469061663545799=10000100268=1279=1269=148=17359555=6SZ683=358067270=10217.0271=4346=41023=110=128
1128=99=18135=X49=SAMPLE75=2017010134=140352=2017010103534070203070560=201701010353407020307055799=10000100268=1279=1269=048=17359555=6SZ683=358068270=10212.0271=25346=91023=510=180
1128=99=18035=X49=SAMPLE75=2017010134=5752=2017010100024223901539060=201701010002422390153905799=10000100268=1279=1269=048=17359555=6SZ683=358069270=10216.0271=2346=21023=110=088
1128=99=25135=X49=SAMPLE75=2017010134=55952=2017010108504498272582960=201701010850449827258295799=10000100268=2279=2269=048=17360055=6SH783=99454270=10269.0271=3346=11023=1279=0269=048=17360055=6SH783=99455270=10259.0271=11346=21023=1010=107
1128=99=18035=X49=SAMPLE75=2017010134=299152=2017010113472986351180860=201701011347298635118085799=10000100268=1279=1269=048=17359555=6SZ683=358070270=10216.0271=3346=31023=110=104
1128=99=18235=X49=SAMPLE75=2017010134=121552=2017010105125269669982460=201701010512526966998245799=10000100268=1279=1269=048=17359555=6SZ683=358071270=10212.0271=32346=101023=510=213
1128=99=18135=X49=SAMPLE75=2017010134=346252=2017010102472848969663760=201701010247284896966375799=10000100268=1279=1269=048=17359555=6SZ683=358072270=10212.0271=25346=91023=510=165
1128=99=18235=X49=SAMPLE75=2017010134=289152=2017010112554869276295060=201701011255486927629505799=10000100268=1279=1269=048=17359555=6SZ683=358073270=10212.0271=32346=101023=510=194
1128=99=18235=X49=SAMPLE75=2017010134=438752=2017010105152723141271960=201701010515272314127195799=10000100268=1279=1269=048=17359555=6SZ683=358074270=10207.0271=20346=51023=1010=188
1128=99=18235=X49=SAMPLE75=2017010134=445552=2017010109170501937304360=201701010917050193730435799=10000100268=1279=1269=048=17359555=6SZ683=358075270=10214.0271=19346=101023=310=196
1128=99=18035=X49=SAMPLE75=2017010134=130752=2017010107210476015152660=201701010721047601515265799=10000100268=1279=1269=048=17359555=6SZ683=358076270=10216.0271=4346=41023=110=110
1128=99=18135=X49=SAMPLE75=2017010134=43352=2017010113325891869807560=201701011332589186980755799=10000100268=1279=1269=048=17359555=6SZ683=358077270=10215.0271=20346=91023=210=192
1128=99=18035=X49=SAMPLE75=2017010134=480052=2017010107252027949103960=201701010725202794910395799=10000100268=1279=1269=048=17359555=6SZ683=358078270=10216.0271=5346=51023=110=120
1128=99=18135=X49=SAMPLE75=2017010134=88552=2017010107152950858522760=201701010715295085852275799=10000100268=1279=1269=148=17359555=6SZ683=358079270=10218.0271=17346=81023=210=173
1128=99=18035=X49=SAMPLE75=2017010134=228552=2017010112494753404774560=201701011249475340477455799=10000100268=1279=1269=048=17359555=6SZ683=358080270=10216.0271=4346=41023=110=130
1128=99=18035=X49=SAMPLE75=2017010134=318952=2017010101302623874762760=201701010130262387476275799=10000100268=1279=1269=048=17359555=6SZ683=358081270=10216.0271=3346=31023=110=120
1128=99=18035=X49=SAMPLE75=2017010134=208852=2017010104012784624391360=201701010401278462439135799=10000100268=1279=1269=048=17359555=6SZ683=358082270=10216.0271=2346=21023=110=127
1128=99=25135=X49=SAMPLE75=2017010134=131552=2017010102344549467493660=201701010234454946749365799=10000100268=2279=1269=048=17360055=6SH783=99456270=10263.0271=11346=21023=6279=1269=048=17360055=6SH783=99457270=10259.0271=3346=11023=1010=107
1128=99=25335=X49=SAMPLE75=2017010134=396352=2017010112334996888235560=201701011233499688823555799=10000100268=2279=1269=148=17359555=6SZ683=358083270=10220.0271=18346=71023=4279=1269=148=17359555=6SZ683=358084270=10221.0271=24346=91023=510=255
1128=99=25435=X49=SAMPLE75=2017010134=272352=2017010102182370006665660=201701010218237000666565799=10000100268=2279=1269=148=17359555=6SZ683=358085270=10220.0271=15346=61023=4279=1269=148=17359555=6SZ683=358086270=10221.0271=27346=101023=510=050
1128=99=18035=X49=SAMPLE75=2017010134=460252=2017010111080564933189660=201701011108056493318965799=10000100268=1279=1269=048=17359555=6SZ683=358087270=10216.0271=3346=31023=110=090
1128=99=18035=X49=SAMPLE75=2017010134=225952=2017010110363671344731360=201701011036367134473135799=10000100268=1279=1269=048=17359555=6SZ683=358088270=10216.0271=4346=41023=110=134
1128=99=18035=X49=SAMPLE75=2017010134=290952=2017010110135710041219560=201701011013571004121955799=10000100268=1279=1269=048=17359555=6SZ683=358089270=10216.0271=3346=31023=110=130
1128=99=25335=X49=SAMPLE75=2017010134=424152=2017010102421711799888560=201701010242171179988855799=10000100268=2279=1269=148=17359555=6SZ683=358090270=10220.0271=18346=71023=4279=1269=148=17359555=6SZ683=358091270=10221.0271=24346=91023=510=036
1128=99=18035=X49=SAMPLE75=2017010134=253652=2017010101354919598258960=201701010135491959825895799=10000100268=1279=1269=048=17359555=6SZ683=358092270=10216.0271=2346=21023=110=134
1128=99=18035=X49=SAMPLE75=2017010134=16652=2017010111414062936126060=201701011141406293612605799=10000100268=1279=1269=048=17359555=6SZ683=358093270=10216.0271=3346=31023=110=125
1128=99=18035=X49=SAMPLE75=2017010134=115152=2017010110183325885339260=201701011018332588533925799=10000100268=1279=1269=048=17359555=6SZ683=358094270=10216.0271=4346=41023=110=090
1128=99=18035=X49=SAMPLE75=2017010134=53852=2017010106463735476667860=201701010646373547666785799=10000100268=1279=1269=048=17359555=6SZ683=358095270=10216.0271=5346=51023=110=107
1128=99=18035=X49=SAMPLE75=2017010134=469152=2017010108254576320127360=201701010825457632012735799=10000100268=1279=1269=148=17359555=6SZ683=358096270=10217.0271=3346=31023=110=091
1128=99=18035=X49=SAMPLE75=2017010134=185652=2017010110332569977071160=201701011033256997707115799=10000100268=1279=1269=148=17359555=6SZ683=358097270=10217.0271=2346=21023=110=108
1128=99=18035=X49=SAMPLE75=2017010134=240952=2017010103062670027790460=201701010306267002779045799=10000100268=1279=1269=148=17359555=6SZ683=358098270=10217.0271=1346=11023=110=093
1128=99=18035=X49=SAMPLE75=2017010134=20552=2017010100111241845302660=201701010011124184530265799=10000100268=1279=1269=048=17359555=6SZ683=358099270=10216.0271=6346=61023=110=110
1128=99=17935=X49=SAMPLE75=2017010134=6252=2017010110323541612313760=201701011032354161231375799=10000100268=1279=0269=048=17360055=6SH783=99458270=10269.0271=3346=11023=110=050
1128=99=24935=X49=SAMPLE75=2017010134=330952=2017010110160810522283760=201701011016081052228375799=10000100268=2279=1269=048=17360055=6SH783=99459270=10268.0271=5346=21023=2279=1269=048=17360055=6SH783=99460270=10266.0271=3346=11023=410=049
1128=99=25435=X49=SAMPLE75=2017010134=430652=2017010101345252281903360=201701010134525228190335799=10000100268=2279=1269=148=17359555=6SZ683=358100270=10220.0271=15346=61023=4279=1269=148=17359555=6SZ683=358101270=10221.0271=27346=101023=510=023
1128=99=25335=X49=SAMPLE75=2017010134=301052=2017010101023422214637460=201701010102342221463745799=10000100268=2279=1269=148=17359555=6SZ683=358102270=10220.0271=18346=71023=4279=1269=148=17359555=6SZ683=358103270=10221.0271=24346=91023=510=233
1128=99=25435=X49=SAMPLE75=2017010134=177652=2017010104393700148827660=201701010439370014882765799=10000100268=2279=1269=148=17359555=6SZ683=358104270=10220.0271=15346=61023=4279=1269=148=17359555=6SZ683=358105270=10221.0271=27346=101023=510=042
1128=99=18035=X49=SAMPLE75=2017010134=151952=2017010103145430647032560=201701010314543064703255799=10000100268=1279=1269=148=17359555=6SZ683=358106270=10217.0271=2346=21023=110=105
1128=99=18035=X49=SAMPLE75=2017010134=456552=2017010110161062516021160=201701011016106251602115799=10000100268=1279=1269=148=17359555=6SZ683=358107270=10217.0271=3346=31023=110=104
1128=99=18035=X49=SAMPLE75=2017010134=83352=2017010114012440518322360=201701011401244051832235799=10000100268=1279=1269=048=17359555=6SZ683=358108270=10216.0271=5346=51023=110=119
1128=99=18035=X49=SAMPLE75=2017010134=217352=2017010112293113228506660=201701011229311322850665799=10000100268=1279=1269=048=17359555=6SZ683=358109270=10216.0271=4346=41023=110=111
1128=99=25035=X49=SAMPLE75=2017010134=471152=2017010110540004284175060=201701011054000428417505799=10000100268=2279=2269=048=17360055=6SH783=99461270=10269.0271=3346=11023=1279=0269=048=17360055=6SH783=99462270=10259.0271=3346=11023=1010=058
1128=99=18035=X49=SAMPLE75=2017010134=385952=2017010101140475965002860=201701010114047596500285799=10000100268=1279=1269=048=17359555=6SZ683=358110270=10216.0271=5346=51023=110=099
1128=99=18035=X49=SAMPLE75=2017010134=112152=2017010113015189643715460=201701011301518964371545799=10000100268=1279=1269=148=17359555=6SZ683=358111270=10217.0271=2346=21023=110=112
1128=99=18035=X49=SAMPLE75=2017010134=343852=2017010112424809127811060=201701011242480912781105799=10000100268=1279=1269=148=17359555=6SZ683=358112270=10217.0271=3346=31023=110=113
1128=99=18035=X49=SAMPLE75=2017010134=372452=2017010113583880009366860=201701011358388000936685799=10000100268=1279=1269=048=17359555=6SZ683=358113270=10216.0271=4346=41023=110=109
1128=99=18035=X49=SAMPLE75=2017010134=53752=2017010108504559251584160=201701010850455925158415799=10000100268=1279=1269=048=17359555=6SZ683=358114270=10216.0271=5346=51023=110=129
1128=99=18035=X49=SAMPLE75=2017010134=25752=2017010103504645242586460=201701010350464524258645799=10000100268=1279=1269=148=17359555=6SZ683=358115270=10217.0271=4346=41023=110=132
1128=99=18035=X49=SAMPLE75=2017010134=400352=2017010105570773216827960=201701010557077321682795799=10000100268=1279=1269=048=17359555=6SZ683=358116270=10216.0271=4346=41023=110=099
1128=99=18035=X49=SAMPLE75=2017010134=257152=2017010113102485091044060=201701011310248509104405799=10000100268=1279=1269=148=17359555=6SZ683=358117270=10217.0271=5346=51023=110=109
1128=99=18035=X49=SAMPLE75=2017010134=67752=2017010103433002869907860=201701010343300286990785799=10000100268=1279=1269=048=17359555=6SZ683=358118270=10216.0271=3346=31023=110=114
1128=99=18035=X49=SAMPLE75=2017010134=412952=2017010108240470888634660=201701010824047088863465799=10000100268=1279=1269=048=17359555=6SZ683=358119270=10216.0271=2346=21023=110=115
1128=99=18035=X49=SAMPLE75=2017010134=101652=2017010103201811345697560=201701010320181134569755799=10000100268=1279=1269=048=17359555=6SZ683=358120270=10216.0271=1346=11023=110=101
1128=99=18035=X49=SAMPLE75=2017010134=361252=2017010110113882990323560=201701011011388299032355799=10000100268=1279=1269=048=17359555=6SZ683=358121270=10216.0271=2346=21023=110=094
1128=99=18035=X49=SAMPLE75=2017010134=458652=2017010102411935998513960=201701010241193599851395799=10000100268=1279=1269=148=17359555=6SZ683=358122270=10217.0271=4346=41023=110=065
1128=99=18035=X49=SAMPLE75=2017010134=286352=2017010104483015942332260=201701010448301594233225799=10000100268=1279=1269=048=17359555=6SZ683=358123270=10216.0271=3346=31023=110=072
1128=99=18035=X49=SAMPLE75=2017010134=391752=2017010107401254345576860=201701010740125434557685799=10000100268=1279=1269=048=17359555=6SZ683=358124270=10216.0271=4346=41023=110=102
1128=99=18035=X49=SAMPLE75=2017010134=161252=2017010103395693773175760=201701010339569377317575799=10000100268=1279=1269=048=17359555=6SZ683=358125270=10216.0271=5346=51023=110=102
1128=99=18135=X49=SAMPLE75=2017010134=299352=2017010109440997724431860=201701010944099772443185799=10000100268=1279=1269=048=17359555=6SZ683=358126270=10212.0271=25346=91023=510=160
1128=99=18235=X49=SAMPLE75=2017010134=172652=2017010105313056764847060=201701010531305676484705799=10000100268=1279=1269=048=17359555=6SZ683=358127270=10212.0271=32346=101023=510=208
1128=99=18235=X49=SAMPLE75=2017010134=421852=2017010109032239265676560=201701010903223926567655799=10000100268=1279=1269=048=17359555=6SZ683=358128270=10207.0271=19346=51023=1010=235
1128=99=18135=X49=SAMPLE75=2017010134=327452=2017010102190478639426860=201701010219047863942685799=10000100268=1279=1269=048=17359555=6SZ683=358129270=10208.0271=19346=51023=910=188
1128=99=18135=X49=SAMPLE75=2017010134=107352=2017010108371306119271860=201701010837130611927185799=10000100268=1279=1269=048=17359555=6SZ683=358130270=10209.0271=41346=61023=810=192
1128=99=18135=X49=SAMPLE75=2017010134=445952=2017010114113470699391360=201701011411347069939135799=10000100268=1279=1269=048=17359555=6SZ683=358131270=10210.0271=29346=81023=710=204
1128=99=18235=X49=SAMPLE75=2017010134=492552=2017010101263163209613760=201701010126316320961375799=10000100268=1279=1269=048=17359555=6SZ683=358132270=10212.0271=31346=101023=510=235
1128=99=18135=X49=SAMPLE75=2017010134=104752=2017010106122453115501460=201701010612245311550145799=10000100268=1279=1269=048=17359555=6SZ683=358133270=10213.0271=17346=91023=410=183
1128=99=18235=X49=SAMPLE75=2017010134=483052=2017010105144540289900860=201701010514454028990085799=10000100268=1279=1269=048=17359555=6SZ683=358134270=10214.0271=18346=101023=310=254
1128=99=18135=X49=SAMPLE75=2017010134=402052=2017010101085368702090160=201701010108536870209015799=10000100268=1279=1269=048=17359555=6SZ683=358135270=10215.0271=19346=91023=210=238
1128=99=18135=X49=SAMPLE75=2017010134=246852=2017010101191897016158060=201701010119189701615805799=10000100268=1279=1269=148=17359555=6SZ683=358136270=10218.0271=16346=81023=210=186
1128=99=18135=X49=SAMPLE75=2017010134=353152=2017010106565270250672060=201701010656527025067205799=10000100268=1279=1269=148=17359555=6SZ683=358137270=10219.0271=14346=61023=310=215
1128=99=18135=X49=SAMPLE75=2017010134=60852=2017010110332672209759060=201701011033267220975905799=10000100268=1279=1269=148=17359555=6SZ683=358138270=10220.0271=14346=61023=410=197
1128=99=18235=X49=SAMPLE75=2017010134=349152=2017010100450701077789460=201701010045070107778945799=10000100268=1279=1269=148=17359555=6SZ683=358139270=10221.0271=26346=101023=510=239
1128=99=18135=X49=SAMPLE75=2017010134=337852=2017010114165886192258160=201701011416588619225815799=10000100268=1279=1269=148=17359555=6SZ683=358140270=10222.0271=29346=81023=610=217
1128=99=18135=X49=SAMPLE75=2017010134=279052=2017010113004325079647160=201701011300432507964715799=10000100268=1279=1269=148=17359555=6SZ683=358141270=10223.0271=19346=51023=710=165
1128=99=18035=X49=SAMPLE75=2017010134=308652=2017010102293699971243760=201701010229369997124375799=10000100268=1279=1269=048=17359555=6SZ683=358142270=10216.0271=4346=41023=110=068
1128=99=18035=X49=SAMPLE75=2017010134=223452=2017010102174025289338860=201701010217402528933885799=10000100268=1279=1269=148=17359555=6SZ683=358143270=10217.0271=5346=51023=110=089
1128=99=18035=X49=SAMPLE75=2017010134=134552=2017010105555807012256060=201701010555580701225605799=10000100268=1279=1269=148=17359555=6SZ683=358144270=10217.0271=4346=41023=110=121
1128=99=18035=X49=SAMPLE75=2017010134=320152=2017010101571920916811260=201701010157192091681125799=10000100268=1279=1269=048=17359555=6SZ683=358145270=10216.0271=5346=51023=110=115
1128=99=18035=X49=SAMPLE75=2017010134=144352=2017010112415779002771660=201701011241577900277165799=10000100268=1279=1269=048=17359555=6SZ683=358146270=10216.0271=4346=41023=110=108
1128=99=25335=X49=SAMPLE75=2017010134=353252=2017010105310420691855260=201701010531042069185525799=10000100268=2279=1269=148=17359555=6SZ683=358147270=10220.0271=17346=71023=4279=1269=148=17359555=6SZ683=358148270=10221.0271=23346=91023=510=016
1128=99=18035=X49=SAMPLE75=2017010134=307252=2017010113013484911100260=201701011301348491110025799=10000100268=1279=1269=048=17359555=6SZ683=358149270=10216.0271=3346=31023=110=088
1128=99=18035=X49=SAMPLE75=2017010134=491952=2017010106125773335022760=201701010612577333502275799=10000100268=1279=1269=048=17359555=6SZ683=358150270=10216.0271=2346=21023=110=101
1128=99=18035=X49=SAMPLE75=2017010134=357452=2017010102112118768829360=201701010211211876882935799=10000100268=1279=1269=048=17359555=6SZ683=358151270=10216.0271=1346=11023=110=087
1128=99=18035=X49=SAMPLE75=2017010134=450752=2017010105365772230803660=201701010536577223080365799=10000100268=1279=1269=048=17359555=6SZ683=358152270=10216.0271=2346=21023=110=118
1128=99=18035=X49=SAMPLE75=2017010134=194052=2017010100395180452705760=201701010039518045270575799=10000100268=1279=1269=048=17359555=6SZ683=358153270=10216.0271=3346=31023=110=100
1128=99=18035=X49=SAMPLE75=2017010134=462452=2017010105355208994313860=201701010535520899431385799=10000100268=1279=1269=048=17359555=6SZ683=358154270=10216.0271=4346=41023=110=104
1128=99=18035=X49=SAMPLE75=2017010134=292452=2017010101204151201580960=201701010120415120158095799=10000100268=1279=1269=048=17359555=6SZ683=358155270=10216.0271=3346=31023=110=118
1128=99=18035=X49=SAMPLE75=2017010134=285952=2017010104195802734270760=201701010419580273427075799=10000100268=1279=1269=148=17359555=6SZ683=358156270=10217.0271=5346=51023=110=138
1128=99=18035=X49=SAMPLE75=2017010134=223152=2017010109041700981725260=201701010904170098172525799=10000100268=1279=1269=048=17359555=6SZ683=358157270=10216.0271=2346=21023=110=142
1128=99=18035=X49=SAMPLE75=2017010134=425152=2017010101440760300696860=201701010144076030069685799=10000100268=1279=1269=048=17359555=6SZ683=358158270=10216.0271=1346=11023=110=131
1128=99=18035=X49=SAMPLE75=2017010134=426552=2017010104291029139807860=201701010429102913980785799=10000100268=1279=1269=048=17359555=6SZ683=358159270=10216.0271=2346=21023=110=139
1128=99=18035=X49=SAMPLE75=2017010134=144952=2017010112265760670370860=201701011226576067037085799=10000100268=1279=1269=048=17359555=6SZ683=358160270=10216.0271=3346=31023=110=125
1128=99=18035=X49=SAMPLE75=2017010134=442852=2017010112031065009648960=201701011203106500964895799=10000100268=1279=1269=048=17359555=6SZ683=358161270=10216.0271=4346=41023=110=119
1128=99=25435=X49=SAMPLE75=2017010134=35852=2017010102391438189940560=201701010239143818994055799=10000100268=2279=1269=148=17359555=6SZ683=358162270=10220.0271=14346=61023=4279=1269=148=17359555=6SZ683=358163270=10221.0271=26346=101023=510=050
1128=99=18035=X49=SAMPLE75=2017010134=242152=2017010104324983559661560=201701010432498355966155799=10000100268=1279=1269=148=17359555=6SZ683=358164270=10217.0271=4346=41023=110=119
1128=99=18035=X49=SAMPLE75=2017010134=298952=2017010100505506288095660=201701010050550628809565799=10000100268=1279=1269=048=17359555=6SZ683=358165270=10216.0271=5346=51023=110=123
1128=99=18035=X49=SAMPLE75=2017010134=375652=2017010110084005081299260=201701011008400508129925799=10000100268=1279=1269=048=17359555=6SZ683=358166270=10216.0271=4346=41023=110=111
1128=99=18135=X49=SAMPLE75=2017010134=27352=2017010106125123731927960=201701010612512373192795799=10000100268=1279=1269=148=17359555=6SZ683=358167270=10218.0271=15346=71023=210=192
1128=99=18235=X49=SAMPLE75=2017010134=109352=2017010101273118587613560=201701010127311858761355799=10000100268=1279=1269=048=17359555=6SZ683=358168270=10207.0271=18346=41023=1010=215
1128=99=18135=X49=SAMPLE75=2017010134=27652=2017010101554442985779860=201701010155444298577985799=10000100268=1279=1269=148=17359555=6SZ683=358169270=10223.0271=21346=61023=710=177
1128=99=18135=X49=SAMPLE75=2017010134=278552=2017010106371030498864160=201701010637103049886415799=10000100268=1279=1269=148=17359555=6SZ683=358170270=10225.0271=17346=31023=910=189
1128=99=18135=X49=SAMPLE75=2017010134=222152=2017010106114876296223660=201701010611487629622365799=10000100268=1279=1269=048=17359555=6SZ683=358171270=10211.0271=24346=91023=610=177
1128=99=18135=X49=SAMPLE75=2017010134=414052=2017010113451190644717060=201701011345119064471705799=10000100268=1279=1269=048=17359555=6SZ683=358172270=10209.0271=43346=71023=810=185
1128=99=18235=X49=SAMPLE75=2017010134=163952=2017010110581155167764560=201701011058115516776455799=10000100268=1279=1269=048=17359555=6SZ683=358173270=10207.0271=20346=51023=1010=215
1128=99=17935=X49=SAMPLE75=2017010134=356652=2017010102141450902844960=201701010214145090284495799=10000100268=1279=1269=148=17360055=6SH783=99463270=10274.0271=6346=31023=110=028
1128=99=17935=X49=SAMPLE75=2017010134=166552=2017010102292881582781460=201701010229288158278145799=10000100268=1279=1269=148=17360055=6SH783=99464270=10276.0271=4346=21023=310=034
1128=99=17935=X49=SAMPLE75=2017010134=57552=2017010102191412146002760=201701010219141214600275799=10000100268=1279=1269=148=17360055=6SH783=99465270=10278.0271=4346=21023=510=043
1128=99=17935=X49=SAMPLE75=2017010134=430252=2017010104572859132180660=201701010457285913218065799=10000100268=1279=1269=048=17360055=6SH783=99466270=10268.0271=6346=31023=110=063
1128=99=17935=X49=SAMPLE75=2017010134=187752=2017010100595881937791060=201701010059588193779105799=10000100268=1279=1269=048=17360055=6SH783=99467270=10266.0271=4346=21023=310=035
1128=99=17935=X49=SAMPLE75=2017010134=33952=2017010106592487635913260=201701010659248763591325799=10000100268=1279=1269=048=17360055=6SH783=99468270=10264.0271=4346=21023=510=038
1128=99=17935=X49=SAMPLE75=2017010134=53752=2017010109003448321500860=201701010900344832150085799=10000100268=1279=1269=148=17360055=6SH783=99469270=10275.0271=6346=31023=210=100
1128=99=17935=X49=SAMPLE75=2017010134=194752=2017010104490335303219660=201701010449033530321965799=10000100268=1279=1269=148=17360055=6SH783=99470270=10277.0271=4346=21023=410=078
1128=99=17935=X49=SAMPLE75=2017010134=15152=2017010112480349294976360=201701011248034929497635799=10000100268=1279=1269=048=17360055=6SH783=99471270=10267.0271=6346=31023=210=074
1128=99=17935=X49=SAMPLE75=2017010134=239952=2017010101124388270813260=201701010112438827081325799=10000100268=1279=1269=048=17360055=6SH783=99472270=10265.0271=4346=21023=410=085
1128=99=18035=X49=SAMPLE75=2017010134=7552=2017010106115803831188160=201701010611580383118815799=10000100268=1279=1269=148=17360055=6SH783=99473270=10280.0271=36346=21023=710=104
1128=99=18035=X49=SAMPLE75=2017010134=166252=2017010105114380456907260=201701010511438045690725799=10000100268=1279=1269=048=17360055=6SH783=99474270=10264.0271=37346=31023=510=092
1128=99=18035=X49=SAMPLE75=2017010134=452=2017010111542178024873760=201701011154217802487375799=10000100268=1279=1269=048=17360055=6SH783=99475270=10260.0271=36346=21023=910=093
1128=99=18135=X49=SAMPLE75=2017010134=342352=2017010114002075365503260=201701011400207536550325799=10000100268=1279=1269=148=17359555=6SZ683=358174270=10224.0271=43346=41023=810=153
1128=99=18135=X49=SAMPLE75=2017010134=241252=2017010110245662250801560=201701011024566225080155799=10000100268=1279=1269=148=17359555=6SZ683=358175270=10225.0271=18346=41023=910=153
1128=99=18035=X49=SAMPLE75=2017010134=22252=2017010106430077911758760=201701010643007791175875799=10000100268=1279=1269=148=17359555=6SZ683=358176270=10217.0271=5346=51023=110=114
1128=99=18035=X49=SAMPLE75=2017010134=244852=2017010104261589769655460=201701010426158976965545799=10000100268=1279=1269=048=17359555=6SZ683=358177270=10216.0271=3346=31023=110=112
1128=99=18035=X49=SAMPLE75=2017010134=90652=2017010106280620182015860=201701010628062018201585799=10000100268=1279=1269=048=17359555=6SZ683=358178270=10216.0271=2346=21023=110=095
1128=99=18035=X49=SAMPLE75=2017010134=134252=2017010112042779874271460=201701011204277987427145799=10000100268=1279=1269=048=17359555=6SZ683=358179270=10216.0271=1346=11023=110=116
1128=99=18035=X49=SAMPLE75=2017010134=412052=2017010101281485289643260=201701010128148528964325799=10000100268=1279=1269=048=17359555=6SZ683=358180270=10216.0271=2346=21023=110=093
1128=99=18035=X49=SAMPLE75=2017010134=133152=2017010100182699374787960=201701010018269937478795799=10000100268=1279=1269=048=17359555=6SZ683=358181270=10216.0271=3346=31023=110=098
1128=99=18035=X49=SAMPLE75=2017010134=346352=2017010104531161406653660=201701010453116140665365799=10000100268=1279=1269=048=17359555=6SZ683=358182270=10216.0271=4346=41023=110=099
1128=99=18035=X49=SAMPLE75=2017010134=489152=2017010110395489119573360=201701011039548911957335799=10000100268=1279=1269=148=17359555=6SZ683=358183270=10217.0271=4346=41023=110=111
1128=99=18135=X49=SAMPLE75=2017010134=207352=2017010106162513602636860=201701010616251360263685799=10000100268=1279=1269=048=17359555=6SZ683=358184270=10208.0271=18346=41023=910=175
1128=99=18235=X49=SAMPLE75=2017010134=139052=2017010112021423921653160=201701011202142392165315799=10000100268=1279=1269=048=17359555=6SZ683=358185270=10215.0271=20346=101023=210=199
1128=99=18135=X49=SAMPLE75=2017010134=421952=2017010111040472005509760=201701011104047200550975799=10000100268=1279=1269=148=17359555=6SZ683=358186270=10220.0271=15346=71023=410=146
1128=99=18135=X49=SAMPLE75=2017010134=215052=2017010113093638697366060=201701011309363869736605799=10000100268=1279=1269=048=17359555=6SZ683=358187270=10212.0271=24346=91023=510=174
1128=99=18235=X49=SAMPLE75=2017010134=88952=2017010103254142704439960=201701010325414270443995799=10000100268=1279=1269=048=17359555=6SZ683=358188270=10212.0271=31346=101023=510=225
1128=99=18135=X49=SAMPLE75=2017010134=288052=2017010103381159345199260=201701010338115934519925799=10000100268=1279=1269=048=17359555=6SZ683=358189270=10212.0271=24346=91023=510=188
1128=99=18235=X49=SAMPLE75=2017010134=467752=2017010112103242952235660=201701011210324295223565799=10000100268=1279=1269=048=17359555=6SZ683=358190270=10212.0271=31346=101023=510=188
1128=99=18135=X49=SAMPLE75=2017010134=258552=2017010107364936896573760=201701010736493689657375799=10000100268=1279=1269=048=17359555=6SZ683=358191270=10212.0271=24346=91023=510=188
1128=99=18235=X49=SAMPLE75=2017010134=427852=2017010100545746906392260=201701010054574690639225799=10000100268=1279=1269=048=17359555=6SZ683=358192270=10212.0271=31346=101023=510=211
1128=99=25435=X49=SAMPLE75=2017010134=276252=2017010106135664403469360=201701010613566440346935799=10000100268=2279=1269=048=17359555=6SZ683=358193270=10215.0271=21346=111023=2279=1269=048=17359555=6SZ683=358194270=10214.0271=17346=91023=310=049
1128=99=18135=X49=SAMPLE75=2017010134=203252=2017010106031704284512760=201701010603170428451275799=10000100268=1279=1269=048=17359555=6SZ683=358195270=10212.0271=24346=91023=510=161
1128=99=18235=X49=SAMPLE75=2017010134=208252=2017010105344637777040260=201701010534463777704025799=10000100268=1279=1269=048=17359555=6SZ683=358196270=10212.0271=31346=101023=510=209
1128=99=18135=X49=SAMPLE75=2017010134=492952=2017010106094225909757160=201701010609422590975715799=10000100268=1279=1269=048=17359555=6SZ683=358197270=10212.0271=24346=91023=510=168
1128=99=18235=X49=SAMPLE75=2017010134=9352=2017010107163082628183160=201701010716308262818315799=10000100268=1279=1269=048=17359555=6SZ683=358198270=10212.0271=31346=101023=510=228
1128=99=18035=X49=SAMPLE75=2017010134=258952=2017010107540385882322260=201701010754038588232225799=10000100268=1279=1269=148=17359555=6SZ683=358199270=10217.0271=3346=31023=110=141
1128=99=18035=X49=SAMPLE75=2017010134=54152=2017010111460049071131160=201701011146004907113115799=10000100268=1279=1269=048=17359555=6SZ683=358200270=10216.0271=5346=51023=110=116
1128=99=18035=X49=SAMPLE75=2017010134=160252=2017010103260446934023860=201701010326044693402385799=10000100268=1279=1269=148=17359555=6SZ683=358201270=10217.0271=4346=41023=110=097
1128=99=18035=X49=SAMPLE75=2017010134=223252=2017010103235240052624260=201701010323524005262425799=10000100268=1279=1269=048=17359555=6SZ683=358202270=10216.0271=4346=41023=110=100
1128=99=18035=X49=SAMPLE75=2017010134=217952=2017010113130258121881460=201701011313025812188145799=10000100268=1279=1269=048=17359555=6SZ683=358203270=10216.0271=3346=31023=110=097
1128=99=18035=X49=SAMPLE75=2017010134=167752=2017010104514239608540660=201701010451423960854065799=10000100268=1279=1269=148=17359555=6SZ683=358204270=10217.0271=5346=51023=110=115
1128=99=18035=X49=SAMPLE75=2017010134=487852=2017010112313268265355460=201701011231326826535545799=10000100268=1279=1269=048=17359555=6SZ683=358205270=10216.0271=2346=21023=110=119
1128=99=25535=X49=SAMPLE75=2017010134=317452=2017010101331240050582360=201701010133124005058235799=10000100268=2279=1269=048=17359555=6SZ683=358206270=10215.0271=20346=101023=2279=1269=048=17359555=6SZ683=358207270=10214.0271=18346=101023=310=097
1128=99=18035=X49=SAMPLE75=2017010134=352752=2017010109163546579854160=201701010916354657985415799=10000100268=1279=1269=048=17359555=6SZ683=358208270=10216.0271=3346=31023=110=112
1128=99=18035=X49=SAMPLE75=2017010134=469652=2017010110334098470667460=201701011033409847066745799=10000100268=1279=1269=048=17359555=6SZ683=358209270=10216.0271=4346=41023=110=101
1128=99=25435=X49=SAMPLE75=2017010134=360052=2017010100331899105780660=201701010033189910578065799=10000100268=2279=1269=048=17359555=6SZ683=358210270=10215.0271=21346=111023=2279=1269=048=17359555=6SZ683=358211270=10214.0271=17346=91023=310=049
1128=99=18035=X49=SAMPLE75=2017010134=167452=2017010108384201411056460=201701010838420141105645799=10000100268=1279=1269=148=17359555=6SZ683=358212270=10217.0271=4346=41023=110=129
1128=99=25535=X49=SAMPLE75=2017010134=54252=2017010100494470719214060=201701010049447071921405799=10000100268=2279=1269=048=17359555=6SZ683=358213270=10215.0271=20346=101023=2279=1269=048=17359555=6SZ683=358214270=10214.0271=18346=101023=310=076
1128=99=18035=X49=SAMPLE75=2017010134=70352=2017010100054486045465660=201701010005448604546565799=10000100268=1279=1269=048=17359555=6SZ683=358215270=10216.0271=3346=31023=110=105
1128=99=18035=X49=SAMPLE75=2017010134=202352=2017010110373186265519360=201701011037318626551935799=10000100268=1279=1269=148=17359555=6SZ683=358216270=10217.0271=5346=51023=110=085
1128=99=18035=X49=SAMPLE75=2017010134=413152=2017010102491384647508660=201701010249138464750865799=10000100268=1279=1269=048=17359555=6SZ683=358217270=10216.0271=4346=41023=110=104
1128=99=25435=X49=SAMPLE75=2017010134=363252=2017010108092022692586660=201701010809202269258665799=10000100268=2279=1269=048=17359555=6SZ683=358218270=10215.0271=21346=111023=2279=1269=048=17359555=6SZ683=358219270=10214.0271=17346=91023=310=025
1128=99=25535=X49=SAMPLE75=2017010134=377752=2017010105091886851472560=201701010509188685147255799=10000100268=2279=1269=048=17359555=6SZ683=358220270=10215.0271=20346=101023=2279=1269=048=17359555=6SZ683=358221270=10214.0271=18346=101023=310=075
1128=99=18035=X49=SAMPLE75=2017010134=212352=2017010104053081967049160=201701010405308196704915799=10000100268=1279=1269=148=17359555=6SZ683=358222270=10217.0271=4346=41023=110=108
1128=99=18035=X49=SAMPLE75=2017010134=19352=2017010100295598889017560=201701010029559888901755799=10000100268=1279=1269=148=17359555=6SZ683=358223270=10217.0271=5346=51023=110=123
1128=99=25335=X49=SAMPLE75=2017010134=459352=2017010107035705546759060=201701010703570554675905799=10000100268=2279=1269=148=17359555=6SZ683=358224270=10220.0271=18346=81023=4279=1269=148=17359555=6SZ683=358225270=10221.0271=23346=91023=510=008
1128=99=18035=X49=SAMPLE75=2017010134=302752=2017010111541328103699460=201701011154132810369945799=10000100268=1279=1269=148=17359555=6SZ683=358226270=10217.0271=4346=41023=110=112
1128=99=18035=X49=SAMPLE75=2017010134=265352=2017010106393815992514760=201701010639381599251475799=10000100268=1279=1269=048=17359555=6SZ683=358227270=10216.0271=3346=31023=110=095
1128=99=18035=X49=SAMPLE75=2017010134=113852=2017010106534995026838560=201701010653499502683855799=10000100268=1279=1269=048=17359555=6SZ683=358228270=10216.0271=2346=21023=110=083
1128=99=18035=X49=SAMPLE75=2017010134=410252=2017010105453346224942460=201701010545334622494245799=10000100268=1279=1269=048=17359555=6SZ683=358229270=10216.0271=1346=11023=110=101
1128=99=20835=X49=SAMPLE75=2017010134=147752=2017010108114511026803060=201701010811451102680305799=00000001268=1279=0269=248=17359555=6SZ683=358230270=10216.0271=1346=25797=237705=237=032=137=032=110=060
1128=99=15635=X49=SAMPLE75=2017010134=122452=2017010108243660751279860=201701010824366075127985799=00000010268=1279=0269=e48=17359555=6SZ683=358231271=9010=098
1128=99=25335=X49=SAMPLE75=2017010134=441852=2017010110274455599185660=201701011027445559918565799=10000100268=2279=2269=048=17359555=6SZ683=358232270=10216.0271=1346=11023=1279=0269=048=17359555=6SZ683=358233270=10206.0271=39346=61023=1010=249
1128=99=17935=X49=SAMPLE75=2017010134=57952=2017010100190005555780760=201701010019000555578075799=10000100268=1279=0269=148=17360055=6SH783=99476270=10272.0271=3346=11023=110=039
1128=99=17935=X49=SAMPLE75=2017010134=80752=2017010114132738660418460=201701011413273866041845799=10000100268=1279=0269=148=17360055=6SH783=99477270=10273.0271=1346=11023=210=055
1128=99=17935=X49=SAMPLE75=2017010134=284252=2017010113525217198090360=201701011352521719809035799=10000100268=1279=1269=048=17360055=6SH783=99478270=10268.0271=5346=21023=110=066
1128=99=18135=X49=SAMPLE75=2017010134=189252=2017010100591251979149860=201701010059125197914985799=10000100268=1279=1269=048=17359555=6SZ683=358234270=10211.0271=22346=81023=510=170
1128=99=18035=X49=SAMPLE75=2017010134=78152=2017010107211157337994760=201701010721115733799475799=10000100268=1279=1269=148=17360055=6SH783=99479270=10276.0271=37346=31023=510=115
1128=99=17935=X49=SAMPLE75=2017010134=460452=2017010113380910338832960=201701011338091033883295799=10000100268=1279=1269=148=17360055=6SH783=99480270=10273.0271=4346=21023=210=027
1128=99=25035=X49=SAMPLE75=2017010134=362452=2017010102202092666982860=201701010220209266698285799=10000100268=2279=2269=148=17360055=6SH783=99481270=10272.0271=3346=11023=1279=0269=148=17360055=6SH783=99482270=10282.0271=3346=11023=1010=053
1128=99=17935=X49=SAMPLE75=2017010134=145752=2017010114023113020348460=201701011402311302034845799=10000100268=1279=1269=148=17360055=6SH783=99483270=10273.0271=1346=11023=110=028
1128=99=18135=X49=SAMPLE75=2017010134=457252=2017010112304533863727060=201701011230453386372705799=10000100268=1279=1269=048=17359555=6SZ683=358235270=10212.0271=24346=91023=410=157
1128=99=25135=X49=SAMPLE75=2017010134=23652=2017010106234150706242960=201701010623415070624295799=10000100268=2279=1269=048=17360055=6SH783=99484270=10263.0271=3346=11023=6279=1269=048=17360055=6SH783=99485270=10259.0271=11346=21023=1010=125
1128=99=25135=X49=SAMPLE75=2017010134=361852=2017010108353800314394060=201701010835380031439405799=10000100268=2279=2269=148=17360055=6SH783=99486270=10273.0271=1346=11023=1279=0269=148=17360055=6SH783=99487270=10283.0271=61346=31023=1010=114
1128=99=17935=X49=SAMPLE75=2017010134=426352=2017010107074792822569460=201701010707479282256945799=10000100268=1279=1269=148=17360055=6SH783=99488270=10276.0271=4346=21023=310=065
1128=99=18035=X49=SAMPLE75=2017010134=176752=2017010103445256609386460=201701010344525660938645799=10000100268=1279=0269=048=17359555=6SZ683=358236270=10216.0271=1346=11023=110=109
1128=99=17935=X49=SAMPLE75=2017010134=429852=2017010106212838739213560=201701010621283873921355799=10000100268=1279=0269=048=17360055=6SH783=99489270=10269.0271=3346=11023=110=064
1128=99=17935=X49=SAMPLE75=2017010134=124052=2017010113010277709504960=201701011301027770950495799=10000100268=1279=1269=048=17360055=6SH783=99490270=10268.0271=6346=31023=210=069
1128=99=18135=X49=SAMPLE75=2017010134=120852=2017010103081624847786060=201701010308162484778605799=10000100268=1279=1269=048=17359555=6SZ683=358237270=10211.0271=24346=91023=610=174
1128=99=25335=X49=SAMPLE75=2017010134=203552=2017010112222642585821160=201701011222264258582115799=10000100268=2279=2269=048=17359555=6SZ683=358238270=10216.0271=1346=11023=1279=0269=048=17359555=6SZ683=358239270=10206.0271=39346=61023=1010=024
1128=99=17935=X49=SAMPLE75=2017010134=189652=2017010102085572468282160=201701010208557246828215799=10000100268=1279=1269=048=17360055=6SH783=99491270=10268.0271=5346=21023=210=071
1128=99=18035=X49=SAMPLE75=2017010134=182552=2017010103364631543303860=201701010336463154330385799=10000100268=1279=1269=148=17359555=6SZ683=358240270=10217.0271=5346=51023=110=130
1128=99=18135=X49=SAMPLE75=2017010134=164152=2017010102591940395810760=201701010259194039581075799=10000100268=1279=1269=048=17359555=6SZ683=358241270=10211.0271=22346=81023=510=176
1128=99=25135=X49=SAMPLE75=2017010134=137652=2017010103305162872511660=201701010330516287251165799=10000100268=2279=2269=048=17360055=6SH783=99492270=10269.0271=3346=11023=1279=0269=048=17360055=6SH783=99493270=10259.0271=11346=21023=1010=122
1128=99=18035=X49=SAMPLE75=2017010134=178252=2017010107050740769936660=201701010705074076993665799=10000100268=1279=0269=048=17359555=6SZ683=358242270=10216.0271=1346=11023=110=104
1128=99=17935=X49=SAMPLE75=2017010134=310752=2017010100250193834275760=201701010025019383427575799=10000100268=1279=1269=048=17360055=6SH783=99494270=10268.0271=6346=31023=110=078
1128=99=18135=X49=SAMPLE75=2017010134=298752=2017010106313793284424060=201701010631379328442405799=10000100268=1279=1269=048=17359555=6SZ683=358243270=10211.0271=24346=91023=610=164
1128=99=25335=X49=SAMPLE75=2017010134=443652=2017010106521787912517160=201701010652178791251715799=10000100268=2279=2269=048=17359555=6SZ683=358244270=10216.0271=1346=11023=1279=0269=048=17359555=6SZ683=358245270=10206.0271=39346=61023=1010=019
1128=99=17935=X49=SAMPLE75=2017010134=333752=2017010107072198369548160=201701010707219836954815799=10000100268=1279=1269=048=17360055=6SH783=99495270=10268.0271=5346=21023=110=084
1128=99=18135=X49=SAMPLE75=2017010134=116052=2017010106474210197283760=201701010647421019728375799=10000100268=1279=1269=048=17359555=6SZ683=358246270=10211.0271=22346=81023=510=176
1128=99=18035=X49=SAMPLE75=2017010134=195852=2017010101032625418424760=201701010103262541842475799=10000100268=1279=0269=048=17359555=6SZ683=358247270=10216.0271=1346=11023=110=121
1128=99=25335=X49=SAMPLE75=2017010134=406052=2017010106035527512152360=201701010603552751215235799=10000100268=2279=2269=048=17359555=6SZ683=358248270=10216.0271=1346=11023=1279=0269=048=17359555=6SZ683=358249270=10206.0271=39346=61023=1010=016
1128=99=17935=X49=SAMPLE75=2017010134=85752=2017010102510089762530560=201701010251008976253055799=10000100268=1279=1269=048=17360055=6SH783=99496270=10268.0271=6346=31023=110=075
1128=99=18035=X49=SAMPLE75=2017010134=408852=2017010110134021703536660=201701011013402170353665799=10000100268=1279=0269=048=17359555=6SZ683=358250270=10216.0271=1346=11023=110=093
1128=99=18135=X49=SAMPLE75=2017010134=46752=2017010101501857710019560=201701010150185771001955799=10000100268=1279=1269=048=17359555=6SZ683=358251270=10211.0271=24346=91023=610=190
1128=99=25335=X49=SAMPLE75=2017010134=117052=2017010104503251396154860=201701010450325139615485799=10000100268=2279=2269=048=17359555=6SZ683=358252270=10216.0271=1346=11023=1279=0269=048=17359555=6SZ683=358253270=10206.0271=39346=61023=1010=008
1128=99=17935=X49=SAMPLE75=2017010134=134152=2017010106590499593362060=201701010659049959336205799=10000100268=1279=1269=048=17360055=6SH783=99497270=10268.0271=5346=21023=110=091
1128=99=18135=X49=SAMPLE75=2017010134=224452=2017010114221993341789360=201701011422199334178935799=10000100268=1279=1269=048=17359555=6SZ683=358254270=10211.0271=22346=81023=510=199
1128=99=18035=X49=SAMPLE75=2017010134=186052=2017010110562971900135260=201701011056297190013525799=10000100268=1279=0269=048=17359555=6SZ683=358255270=10216.0271=1346=11023=110=117
1128=99=17935=X49=SAMPLE75=2017010134=62152=2017010103504072781200560=201701010350407278120055799=10000100268=1279=0269=048=17360055=6SH783=99498270=10269.0271=3346=11023=110=058
1128=99=17935=X49=SAMPLE75=2017010134=372752=2017010107044845143552160=201701010704484514355215799=10000100268=1279=1269=048=17360055=6SH783=99499270=10268.0271=6346=31023=210=083
1128=99=18135=X49=SAMPLE75=2017010134=272352=2017010114261889901253660=201701011426188990125365799=10000100268=1279=1269=048=17359555=6SZ683=358256270=10211.0271=24346=91023=610=187
1128=99=25335=X49=SAMPLE75=2017010134=11452=2017010109580290015727760=201701010958029001572775799=10000100268=2279=2269=048=17359555=6SZ683=358257270=10216.0271=1346=11023=1279=0269=048=17359555=6SZ683=358258270=10206.0271=39346=61023=1010=011
1128=99=17935=X49=SAMPLE75=2017010134=395152=2017010110535551365080460=201701011053555136508045799=10000100268=1279=1269=048=17360055=6SH783=99500270=10268.0271=5346=21023=210=069
1128=99=18135=X49=SAMPLE75=2017010134=355752=2017010101070236788108460=201701010107023678810845799=10000100268=1279=1269=048=17359555=6SZ683=358259270=10211.0271=22346=81023=510=202
1128=99=25135=X49=SAMPLE75=2017010134=80352=2017010105552133250345960=201701010555213325034595799=10000100268=2279=2269=048=17360055=6SH783=99501270=10269.0271=3346=11023=1279=0269=048=17360055=6SH783=99502270=10259.0271=11346=21023=1010=108
1128=99=18035=X49=SAMPLE75=2017010134=467452=2017010105144003027429860=201701010514400302742985799=10000100268=1279=0269=048=17359555=6SZ683=358260270=10216.0271=1346=11023=110=144
1128=99=17935=X49=SAMPLE75=2017010134=263352=2017010114022801313225260=201701011402280131322525799=10000100268=1279=1269=048=17360055=6SH783=99503270=10268.0271=6346=31023=110=066
1128=99=18135=X49=SAMPLE75=2017010134=469552=2017010112214520902791260=201701011221452090279125799=10000100268=1279=1269=048=17359555=6SZ683=358261270=10211.0271=24346=91023=610=193
1128=99=25335=X49=SAMPLE75=2017010134=221152=2017010110253252022332860=201701011025325202233285799=10000100268=2279=2269=048=17359555=6SZ683=358262270=10216.0271=1346=11023=1279=0269=048=17359555=6SZ683=358263270=10206.0271=39346=61023=1010=002
1128=99=17935=X49=SAMPLE75=2017010134=145352=2017010107354551444912260=201701010735455144491225799=10000100268=1279=1269=048=17360055=6SH783=99504270=10268.0271=5346=21023=110=055
1128=99=18135=X49=SAMPLE75=2017010134=293952=2017010104183322705419660=201701010418332270541965799=10000100268=1279=1269=048=17359555=6SZ683=358264270=10211.0271=22346=81023=510=180
1128=99=18035=X49=SAMPLE75=2017010134=263152=2017010108554653153288060=201701010855465315328805799=10000100268=1279=0269=048=17359555=6SZ683=358265270=10216.0271=1346=11023=110=105
1128=99=17935=X49=SAMPLE75=2017010134=364652=2017010100060526318970360=201701010006052631897035799=10000100268=1279=1269=048=17360055=6SH783=99505270=10268.0271=6346=31023=110=066
1128=99=18135=X49=SAMPLE75=2017010134=489652=2017010113141880952062960=201701011314188095206295799=10000100268=1279=1269=048=17359555=6SZ683=358266270=10211.0271=24346=91023=610=168
1128=99=18235=X49=SAMPLE75=2017010134=245252=2017010113560666244083260=201701011356066624408325799=10000100268=1279=1269=048=17359555=6SZ683=358267270=10212.0271=31346=101023=510=208
1128=99=25335=X49=SAMPLE75=2017010134=401752=2017010113052099897415060=201701011305209989741505799=10000100268=2279=2269=048=17359555=6SZ683=358268270=10216.0271=1346=11023=1279=0269=048=17359555=6SZ683=358269270=10206.0271=39346=61023=1010=023
1128=99=17935=X49=SAMPLE75=2017010134=497952=2017010102570012256147760=201701010257001225614775799=10000100268=1279=1269=048=17360055=6SH783=99506270=10268.0271=5346=21023=110=057
1128=99=18135=X49=SAMPLE75=2017010134=307552=2017010111010628731644360=201701011101062873164435799=10000100268=1279=1269=048=17359555=6SZ683=358270270=10211.0271=22346=81023=510=164
1128=99=18035=X49=SAMPLE75=2017010134=258852=2017010109572824730070660=201701010957282473007065799=10000100268=1279=0269=048=17359555=6SZ683=358271270=10216.0271=1346=11023=110=113
1128=99=17935=X49=SAMPLE75=2017010134=305252=2017010103170634134980660=201701010317063413498065799=10000100268=1279=1269=048=17360055=6SH783=99507270=10268.0271=6346=31023=110=054
1128=99=18135=X49=SAMPLE75=2017010134=60252=2017010111262680832492260=201701011126268083249225799=10000100268=1279=1269=048=17359555=6SZ683=358272270=10211.0271=24346=91023=610=181
1128=99=25335=X49=SAMPLE75=2017010134=52152=2017010105202264771575660=201701010520226477157565799=10000100268=2279=2269=048=17359555=6SZ683=358273270=10216.0271=1346=11023=1279=0269=048=17359555=6SZ683=358274270=10206.0271=39346=61023=1010=249
1128=99=17935=X49=SAMPLE75=2017010134=207952=2017010102300771725620860=201701010230077172562085799=10000100268=1279=1269=048=17360055=6SH783=99508270=10268.0271=5346=21023=110=058
1128=99=18135=X49=SAMPLE75=2017010134=174152=2017010101022081784077660=201701010102208178407765799=10000100268=1279=1269=048=17359555=6SZ683=358275270=10211.0271=22346=81023=510=166
1128=99=18035=X49=SAMPLE75=2017010134=33252=2017010104571311142534060=201701010457131114253405799=10000100268=1279=0269=048=17359555=6SZ683=358276270=10216.0271=1346=11023=110=117
1128=99=17935=X49=SAMPLE75=2017010134=255352=2017010104590112892203160=201701010459011289220315799=10000100268=1279=1269=048=17360055=6SH783=99509270=10268.0271=6346=31023=110=051
1128=99=25335=X49=SAMPLE75=2017010134=464952=2017010106055512824934360=201701010605551282493435799=10000100268=2279=2269=048=17359555=6SZ683=358277270=10216.0271=1346=11023=1279=0269=048=17359555=6SZ683=358278270=10206.0271=39346=61023=1010=018
1128=99=17935=X49=SAMPLE75=2017010134=88052=2017010106181430241391560=201701010618143024139155799=10000100268=1279=1269=048=17360055=6SH783=99510270=10268.0271=5346=21023=110=039
1128=99=18035=X49=SAMPLE75=2017010134=320752=2017010104454811087588660=201701010445481108758865799=10000100268=1279=0269=048=17359555=6SZ683=358279270=10216.0271=1346=11023=110=114
1128=99=17935=X49=SAMPLE75=2017010134=272452=2017010112471618529744460=201701011247161852974445799=10000100268=1279=1269=048=17360055=6SH783=99511270=10268.0271=6346=31023=110=048
1128=99=18135=X49=SAMPLE75=2017010134=103052=2017010112503584527573460=201701011250358452757345799=10000100268=1279=1269=048=17359555=6SZ683=358280270=10211.0271=24346=91023=610=166
1128=99=25335=X49=SAMPLE75=2017010134=350152=2017010103543192825042160=201701010354319282504215799=10000100268=2279=2269=048=17359555=6SZ683=358281270=10216.0271=1346=11023=1279=0269=048=17359555=6SZ683=358282270=10206.0271=39346=61023=1010=243
1128=99=17935=X49=SAMPLE75=2017010134=290552=2017010110454335226291360=201701011045433522629135799=10000100268=1279=1269=048=17360055=6SH783=99512270=10268.0271=5346=21023=110=058
1128=99=18135=X49=SAMPLE75=2017010134=214852=2017010109463143628050960=201701010946314362805095799=10000100268=1279=1269=048=17359555=6SZ683=358283270=10211.0271=22346=81023=510=162
1128=99=18035=X49=SAMPLE75=2017010134=280152=2017010103483426287249460=201701010348342628724945799=10000100268=1279=0269=048=17359555=6SZ683=358284270=10216.0271=1346=11023=110=117
1128=99=17935=X49=SAMPLE75=2017010134=2552=2017010101183907734592960=201701010118390773459295799=10000100268=1279=1269=048=17360055=6SH783=99513270=10268.0271=6346=31023=110=054
1128=99=18135=X49=SAMPLE75=2017010134=107352=2017010100072056562512660=201701010007205656251265799=10000100268=1279=1269=048=17359555=6SZ683=358285270=10211.0271=24346=91023=610=168
1128=99=25335=X49=SAMPLE75=2017010134=255452=2017010103341205020595260=201701010334120502059525799=10000100268=2279=2269=048=17359555=6SZ683=358286270=10216.0271=1346=11023=1279=0269=048=17359555=6SZ683=358287270=10206.0271=39346=61023=1010=005
1128=99=17935=X49=SAMPLE75=2017010134=237852=2017010101304720963308560=201701010130472096330855799=10000100268=1279=1269=048=17360055=6SH783=99514270=10268.0271=5346=21023=110=040
1128=99=18135=X49=SAMPLE75=2017010134=14552=2017010110523922296507760=201701011052392229650775799=10000100268=1279=1269=048=17359555=6SZ683=358288270=10211.0271=22346=81023=510=157
1128=99=18035=X49=SAMPLE75=2017010134=392752=2017010114233228301701160=201701011423322830170115799=10000100268=1279=0269=048=17359555=6SZ683=358289270=10216.0271=1346=11023=110=138
1128=99=17935=X49=SAMPLE75=2017010134=491352=2017010111140124567944960=201701011114012456794495799=10000100268=1279=1269=048=17360055=6SH783=99515270=10268.0271=6346=31023=110=079
1128=99=18135=X49=SAMPLE75=2017010134=84352=2017010108545770992596560=201701010854577099259655799=10000100268=1279=1269=048=17359555=6SZ683=358290270=10211.0271=24346=91023=610=172
1128=99=25335=X49=SAMPLE75=2017010134=287952=2017010100594464225879960=201701010059446422587995799=10000100268=2279=2269=048=17359555=6SZ683=358291270=10216.0271=1346=11023=1279=0269=048=17359555=6SZ683=358292270=10206.0271=39346=61023=1010=002
1128=99=17935=X49=SAMPLE75=2017010134=465152=2017010113122343387086260=201701011312234338708625799=10000100268=1279=1269=048=17360055=6SH783=99516270=10268.0271=5346=21023=110=077
1128=99=18135=X49=SAMPLE75=2017010134=26752=2017010107380174034801260=201701010738017403480125799=10000100268=1279=1269=048=17359555=6SZ683=358293270=10211.0271=22346=81023=510=186
1128=99=18135=X49=SAMPLE75=2017010134=388552=2017010102001594917598860=201701010200159491759885799=10000100268=1279=1269=048=17359555=6SZ683=358294270=10212.0271=24346=91023=410=189
1128=99=18235=X49=SAMPLE75=2017010134=383952=2017010110211736694569560=201701011021173669456955799=10000100268=1279=1269=048=17359555=6SZ683=358295270=10212.0271=31346=101023=410=245
1128=99=18035=X49=SAMPLE75=2017010134=390452=2017010102464393772775960=201701010246439377277595799=10000100268=1279=0269=048=17359555=6SZ683=358296270=10216.0271=1346=11023=110=122
1128=99=17935=X49=SAMPLE75=2017010134=109452=2017010102585685833414060=201701010258568583341405799=10000100268=1279=0269=048=17360055=6SH783=99517270=10269.0271=3346=11023=110=053
1128=99=17935=X49=SAMPLE75=2017010134=307252=2017010109325461465260660=201701010932546146526065799=10000100268=1279=1269=048=17360055=6SH783=99518270=10268.0271=6346=31023=210=061
1128=99=18135=X49=SAMPLE75=2017010134=323252=2017010104203054881759160=201701010420305488175915799=10000100268=1279=1269=048=17359555=6SZ683=358297270=10211.0271=24346=91023=610=163
1128=99=25335=X49=SAMPLE75=2017010134=470352=2017010106200058406755360=201701010620005840675535799=10000100268=2279=2269=048=17359555=6SZ683=358298270=10216.0271=1346=11023=1279=0269=048=17359555=6SZ683=358299270=10206.0271=39346=61023=1010=025
1128=99=17935=X49=SAMPLE75=2017010134=4952=2017010105505894166414960=201701010550589416641495799=10000100268=1279=1269=048=17360055=6SH783=99519270=10268.0271=5346=21023=210=043
1128=99=18135=X49=SAMPLE75=2017010134=75352=2017010105561678708051260=201701010556167870805125799=10000100268=1279=1269=048=17359555=6SZ683=358300270=10211.0271=22346=81023=510=156
1128=99=25135=X49=SAMPLE75=2017010134=38552=2017010105023510188262260=201701010502351018826225799=10000100268=2279=2269=048=17360055=6SH783=99520270=10269.0271=3346=11023=1279=0269=048=17360055=6SH783=99521270=10259.0271=11346=21023=1010=096
1128=99=18035=X49=SAMPLE75=2017010134=149352=2017010101210722936404260=201701010121072293640425799=10000100268=1279=0269=048=17359555=6SZ683=358301270=10216.0271=1346=11023=110=122
1128=99=17935=X49=SAMPLE75=2017010134=466852=2017010111452092503440760=201701011145209250344075799=10000100268=1279=1269=048=17360055=6SH783=99522270=10268.0271=6346=31023=110=083
1128=99=18135=X49=SAMPLE75=2017010134=145852=2017010107444893449018360=201701010744489344901835799=10000100268=1279=1269=048=17359555=6SZ683=358302270=10211.0271=24346=91023=610=184
1128=99=18035=X49=SAMPLE75=2017010134=2652=2017010109414448870312660=201701010941444887031265799=10000100268=1279=1269=048=17359555=6SZ683=358303270=10216.0271=2346=21023=110=105
1128=99=18135=X49=SAMPLE75=2017010134=283352=2017010107125835358010160=201701010712583535801015799=10000100268=1279=1269=048=17359555=6SZ683=358304270=10212.0271=24346=91023=510=175
1128=99=18235=X49=SAMPLE75=2017010134=174252=2017010101084104639871260=201701010108410463987125799=10000100268=1279=1269=048=17359555=6SZ683=358305270=10212.0271=31346=101023=510=216
1128=99=25435=X49=SAMPLE75=2017010134=248452=2017010102044482562817760=201701010204448256281775799=10000100268=2279=1269=148=17359555=6SZ683=358306270=10220.0271=15346=71023=4279=1269=148=17359555=6SZ683=358307270=10221.0271=26346=101023=510=065
1128=99=18035=X49=SAMPLE75=2017010134=231252=2017010108421409577099360=201701010842140957709935799=10000100268=1279=1269=148=17359555=6SZ683=358308270=10217.0271=4346=41023=110=122
1128=99=18035=X49=SAMPLE75=2017010134=327152=2017010112050348848548560=201701011205034884854855799=10000100268=1279=1269=048=17359555=6SZ683=358309270=10216.0271=3346=31023=110=148
1128=99=18035=X49=SAMPLE75=2017010134=414052=2017010101375593985780660=201701010137559398578065799=10000100268=1279=1269=048=17359555=6SZ683=358310270=10216.0271=2346=21023=110=119
1128=99=18035=X49=SAMPLE75=2017010134=412952=2017010107195668724100560=201701010719566872410055799=10000100268=1279=1269=048=17359555=6SZ683=358311270=10216.0271=1346=11023=110=097
1128=99=25335=X49=SAMPLE75=2017010134=432452=2017010113250027803186460=201701011325002780318645799=10000100268=2279=1269=148=17359555=6SZ683=358312270=10220.0271=18346=81023=4279=1269=148=17359555=6SZ683=358313270=10221.0271=23346=91023=510=009
1128=99=18035=X49=SAMPLE75=2017010134=188552=2017010113125171035180660=201701011312517103518065799=10000100268=1279=1269=148=17359555=6SZ683=358314270=10217.0271=5346=51023=110=118
1128=99=18035=X49=SAMPLE75=2017010134=411552=2017010110400130724282860=201701011040013072428285799=10000100268=1279=1269=048=17359555=6SZ683=358315270=10216.0271=2346=21023=110=108
1128=99=18035=X49=SAMPLE75=2017010134=152852=2017010107344120251576460=201701010734412025157645799=10000100268=1279=1269=048=17359555=6SZ683=358316270=10216.0271=3346=31023=110=114
1128=99=25435=X49=SAMPLE75=2017010134=9352=2017010112184531775636860=201701011218453177563685799=10000100268=2279=1269=148=17359555=6SZ683=358317270=10220.0271=15346=71023=4279=1269=148=17359555=6SZ683=358318270=10221.0271=26346=101023=510=057
1128=99=25335=X49=SAMPLE75=2017010134=136952=2017010100345609357514760=201701010034560935751475799=10000100268=2279=1269=148=17359555=6SZ683=358319270=10220.0271=18346=81023=4279=1269=148=17359555=6SZ683=358320270=10221.0271=23346=91023=510=007
1128=99=25435=X49=SAMPLE75=2017010134=318852=2017010102122263244742260=201701010212226324474225799=10000100268=2279=1269=148=17359555=6SZ683=358321270=10220.0271=15346=71023=4279=1269=148=17359555=6SZ683=358322270=10221.0271=26346=101023=510=057
1128=99=18035=X49=SAMPLE75=2017010134=167552=2017010104282358164745460=201701010428235816474545799=10000100268=1279=1269=148=17359555=6SZ683=358323270=10217.0271=4346=41023=110=136
1128=99=18035=X49=SAMPLE75=2017010134=277852=2017010105220411602815060=201701010522041160281505799=10000100268=1279=1269=048=17359555=6SZ683=358324270=10216.0271=4346=41023=110=130
1128=99=18035=X49=SAMPLE75=2017010134=367952=2017010113330016148767260=201701011333001614876725799=10000100268=1279=1269=148=17359555=6SZ683=358325270=10217.0271=5346=51023=110=129
1128=99=18235=X49=SAMPLE75=2017010134=384852=2017010105540635045185260=201701010554063504518525799=10000100268=1279=1269=048=17359555=6SZ683=358326270=10213.0271=18346=101023=410=218
1128=99=18235=X49=SAMPLE75=2017010134=290752=2017010100451946730690560=201701010045194673069055799=10000100268=1279=1269=148=17359555=6SZ683=358327270=10221.0271=27346=111023=510=227
1128=99=18035=X49=SAMPLE75=2017010134=197452=2017010104230443901226960=201701010423044390122695799=10000100268=1279=1269=048=17359555=6SZ683=358328270=10216.0271=3346=31023=110=132
1128=99=18035=X49=SAMPLE75=2017010134=380252=2017010113284641257728260=201701011328464125772825799=10000100268=1279=1269=148=17359555=6SZ683=358329270=10217.0271=4346=41023=110=119
1128=99=18035=X49=SAMPLE75=2017010134=134652=2017010114030429231465960=201701011403042923146595799=10000100268=1279=1269=148=17359555=6SZ683=358330270=10217.0271=5346=51023=110=088
1128=99=18035=X49=SAMPLE75=2017010134=234552=2017010104174443959358460=201701010417444395935845799=10000100268=1279=1269=148=17359555=6SZ683=358331270=10217.0271=4346=41023=110=123
1128=99=18135=X49=SAMPLE75=2017010134=54652=2017010107595813359469860=201701010759581335946985799=10000100268=1279=1269=048=17359555=6SZ683=358332270=10212.0271=24346=91023=510=161
1128=99=18235=X49=SAMPLE75=2017010134=203452=2017010112401559015817660=201701011240155901581765799=10000100268=1279=1269=048=17359555=6SZ683=358333270=10212.0271=31346=101023=510=217
1128=99=18135=X49=SAMPLE75=2017010134=48952=2017010102525995233041560=201701010252599523304155799=10000100268=1279=1269=048=17359555=6SZ683=358334270=10212.0271=24346=91023=510=139
1128=99=25135=X49=SAMPLE75=2017010134=267252=2017010103451308888214960=201701010345130888821495799=10000100268=2279=1269=048=17360055=6SH783=99523270=10263.0271=11346=21023=6279=1269=048=17360055=6SH783=99524270=10259.0271=3346=11023=1010=095
1128=99=18235=X49=SAMPLE75=2017010134=119652=2017010111495396692366760=201701011149539669236675799=10000100268=1279=1269=048=17359555=6SZ683=358335270=10212.0271=31346=101023=510=193
1128=99=18135=X49=SAMPLE75=2017010134=261452=2017010109033482739548260=201701010903348273954825799=10000100268=1279=1269=048=17359555=6SZ683=358336270=10212.0271=24346=91023=510=181
1128=99=18235=X49=SAMPLE75=2017010134=30752=2017010114245354566844060=201701011424535456684405799=10000100268=1279=1269=048=17359555=6SZ683=358337270=10212.0271=31346=101023=510=221
1128=99=18135=X49=SAMPLE75=2017010134=200452=2017010105505801765432960=201701010550580176543295799=10000100268=1279=1269=048=17359555=6SZ683=358338270=10212.0271=24346=91023=510=177
1128=99=18235=X49=SAMPLE75=2017010134=91652=2017010105114147097045660=201701010511414709704565799=10000100268=1279=1269=048=17359555=6SZ683=358339270=10212.0271=31346=101023=510=209
1128=99=18135=X49=SAMPLE75=2017010134=187152=2017010110564016385811060=201701011056401638581105799=10000100268=1279=1269=048=17359555=6SZ683=358340270=10212.0271=24346=91023=510=177
1128=99=18135=X49=SAMPLE75=2017010134=7852=2017010105151403504795260=201701010515140350479525799=10000100268=1279=1269=148=17359555=6SZ683=358341270=10220.0271=14346=61023=410=125
1128=99=18035=X49=SAMPLE75=2017010134=185552=2017010108442577275997260=201701010844257727599725799=10000100268=1279=1269=048=17359555=6SZ683=358342270=10216.0271=2346=21023=110=099
1128=99=18035=X49=SAMPLE75=2017010134=245552=2017010109410708552847460=201701010941070855284745799=10000100268=1279=1269=148=17359555=6SZ683=358343270=10217.0271=5346=51023=110=118
1128=99=18035=X49=SAMPLE75=2017010134=133252=2017010113583734174790460=201701011358373417479045799=10000100268=1279=1269=048=17359555=6SZ683=358344270=10216.0271=1346=11023=110=103
1128=99=25335=X49=SAMPLE75=2017010134=132052=2017010103350076380360860=201701010335007638036085799=10000100268=2279=2269=048=17359555=6SZ683=358345270=10216.0271=1346=11023=1279=0269=048=17359555=6SZ683=358346270=10206.0271=39346=61023=1010=011
1128=99=17935=X49=SAMPLE75=2017010134=246252=2017010112283217642533860=201701011228321764253385799=10000100268=1279=1269=048=17360055=6SH783=99525270=10268.0271=5346=21023=110=047
1128=99=18135=X49=SAMPLE75=2017010134=347652=2017010100002704875913960=201701010000270487591395799=10000100268=1279=1269=048=17359555=6SZ683=358347270=10211.0271=22346=81023=510=174
1128=99=18235=X49=SAMPLE75=2017010134=487252=2017010108460148596218560=201701010846014859621855799=10000100268=1279=1269=048=17359555=6SZ683=358348270=10212.0271=25346=101023=410=214
1128=99=18135=X49=SAMPLE75=2017010134=208352=2017010109505315388582260=201701010950531538858225799=10000100268=1279=1269=048=17359555=6SZ683=358349270=10213.0271=17346=91023=310=150
1128=99=18135=X49=SAMPLE75=2017010134=137652=2017010107041100122198960=201701010704110012219895799=10000100268=1279=1269=148=17359555=6SZ683=358350270=10220.0271=15346=71023=410=174
1128=99=25435=X49=SAMPLE75=2017010134=479352=2017010109380323692139360=201701010938032369213935799=10000100268=2279=1269=148=17359555=6SZ683=358351270=10220.0271=18346=81023=4279=1269=148=17359555=6SZ683=358352270=10221.0271=24346=101023=510=064
1128=99=18035=X49=SAMPLE75=2017010134=433852=2017010114203215577473060=201701011420321557747305799=10000100268=1279=1269=048=17360055=6SH783=99526270=10263.0271=12346=31023=610=067
1128=99=25135=X49=SAMPLE75=2017010134=401952=2017010104580094306279060=201701010458009430627905799=10000100268=2279=1269=048=17360055=6SH783=99527270=10263.0271=4346=21023=6279=1269=048=17360055=6SH783=99528270=10259.0271=11346=21023=1010=124
1128=99=18135=X49=SAMPLE75=2017010134=493652=2017010106090865314685960=201701010609086531468595799=10000100268=1279=1269=048=17359555=6SZ683=358353270=10215.0271=12346=91023=110=170
1128=99=18235=X49=SAMPLE75=2017010134=106052=2017010101022721899514560=201701010102272189951455799=10000100268=1279=1269=048=17359555=6SZ683=358354270=10215.0271=13346=101023=110=214
1128=99=18135=X49=SAMPLE75=2017010134=88052=2017010114023144671444960=201701011402314467144495799=10000100268=1279=1269=048=17359555=6SZ683=358355270=10215.0271=12346=91023=110=172
1128=99=18135=X49=SAMPLE75=2017010134=431352=2017010106542848941294360=201701010654284894129435799=10000100268=1279=1269=048=17359555=6SZ683=358356270=10214.0271=17346=91023=210=165
1128=99=18135=X49=SAMPLE75=2017010134=414452=2017010106233148032846160=201701010623314803284615799=10000100268=1279=1269=048=17359555=6SZ683=358357270=10208.0271=19346=51023=810=175
1128=99=25335=X49=SAMPLE75=2017010134=453852=2017010114304082239789060=201701011430408223978905799=10000100268=2279=1269=048=17359555=6SZ683=358358270=10212.0271=17346=91023=4279=1269=048=17359555=6SZ683=358359270=10208.0271=27346=61023=810=012
1128=99=18135=X49=SAMPLE75=2017010134=88952=2017010105352179535572760=201701010535217953557275799=10000100268=1279=1269=048=17359555=6SZ683=358360270=10215.0271=11346=81023=110=138
1128=99=18135=X49=SAMPLE75=2017010134=26652=2017010113354462282057760=201701011335446228205775799=10000100268=1279=1269=048=17359555=6SZ683=358361270=10207.0271=21346=61023=910=148
1128=99=18035=X49=SAMPLE75=2017010134=116452=2017010112523972037893460=201701011252397203789345799=10000100268=1279=0269=048=17359555=6SZ683=358362270=10216.0271=1346=11023=110=099
1128=99=17935=X49=SAMPLE75=2017010134=478752=2017010107523813773655660=201701010752381377365565799=10000100268=1279=0269=048=17360055=6SH783=99529270=10269.0271=3346=11023=110=052
1128=99=17935=X49=SAMPLE75=2017010134=316352=2017010109385687410152460=201701010938568741015245799=10000100268=1279=1269=048=17360055=6SH783=99530270=10268.0271=6346=31023=210=046
1128=99=18035=X49=SAMPLE75=2017010134=142352=2017010101192851118422360=201701010119285111842235799=10000100268=1279=1269=148=17359555=6SZ683=358363270=10217.0271=4346=41023=110=125
1128=99=18135=X49=SAMPLE75=2017010134=308852=2017010101350243245088660=201701010135024324508865799=10000100268=1279=1269=048=17359555=6SZ683=358364270=10211.0271=24346=91023=610=154
1128=99=18035=X49=SAMPLE75=2017010134=431852=2017010103431163183805060=201701010343116318380505799=10000100268=1279=1269=048=17359555=6SZ683=358365270=10216.0271=2346=21023=110=104
1128=99=18235=X49=SAMPLE75=2017010134=404652=2017010113495275134093060=201701011349527513409305799=10000100268=1279=1269=048=17359555=6SZ683=358366270=10207.0271=20346=51023=1010=206
1128=99=18135=X49=SAMPLE75=2017010134=122952=2017010110050390911557760=201701011005039091155775799=10000100268=1279=1269=048=17359555=6SZ683=358367270=10215.0271=12346=91023=210=160
1128=99=18035=X49=SAMPLE75=2017010134=38352=2017010103121505085843860=201701010312150508584385799=10000100268=1279=1269=048=17359555=6SZ683=358368270=10216.0271=3346=31023=110=109
1128=99=18035=X49=SAMPLE75=2017010134=32152=2017010114264062632358060=201701011426406263235805799=10000100268=1279=1269=048=17359555=6SZ683=358369270=10216.0271=4346=41023=110=103
1128=99=18035=X49=SAMPLE75=2017010134=134452=2017010112281685617456160=201701011228168561745615799=10000100268=1279=1269=048=17359555=6SZ683=358370270=10216.0271=5346=51023=110=105
1128=99=25135=X49=SAMPLE75=2017010134=439152=2017010104495953783875560=201701010449595378387555799=10000100268=2279=2269=048=17360055=6SH783=99531270=10269.0271=3346=11023=1279=0269=048=17360055=6SH783=99532270=10259.0271=11346=21023=1010=102
1128=99=18235=X49=SAMPLE75=2017010134=234452=2017010100583657964603660=201701010058365796460365799=10000100268=1279=1269=048=17359555=6SZ683=358371270=10215.0271=20346=101023=210=191
1128=99=18235=X49=SAMPLE75=2017010134=219852=2017010103181468836308860=201701010318146883630885799=10000100268=1279=1269=048=17359555=6SZ683=358372270=10212.0271=24346=101023=510=190
1128=99=25435=X49=SAMPLE75=2017010134=290552=2017010108443570762695460=201701010844357076269545799=10000100268=2279=1269=048=17359555=6SZ683=358373270=10212.0271=32346=111023=5279=1269=048=17359555=6SZ683=358374270=10208.0271=19346=51023=910=079
1128=99=18235=X49=SAMPLE75=2017010134=477052=2017010106512328813737460=201701010651232881373745799=10000100268=1279=1269=048=17359555=6SZ683=358375270=10212.0271=25346=101023=510=200
1128=99=25435=X49=SAMPLE75=2017010134=375152=2017010111401546343551560=201701011140154634355155799=10000100268=2279=1269=148=17359555=6SZ683=358376270=10220.0271=15346=71023=4279=1269=148=17359555=6SZ683=358377270=10221.0271=27346=111023=510=067
1128=99=18235=X49=SAMPLE75=2017010134=173952=2017010112015569839350460=201701011201556983935045799=10000100268=1279=1269=048=17359555=6SZ683=358378270=10215.0271=21346=111023=210=211
1128=99=18035=X49=SAMPLE75=2017010134=473452=2017010109342296928701760=201701010934229692870175799=10000100268=1279=1269=048=17359555=6SZ683=358379270=10216.0271=4346=41023=110=115
1128=99=18035=X49=SAMPLE75=2017010134=65852=2017010105460306558174060=201701010546030655817405799=10000100268=1279=1269=148=17359555=6SZ683=358380270=10217.0271=5346=51023=110=135
1128=99=18235=X49=SAMPLE75=2017010134=47452=2017010103213186950153560=201701010321318695015355799=10000100268=1279=1269=048=17359555=6SZ683=358381270=10215.0271=24346=121023=210=205
1128=99=18135=X49=SAMPLE75=2017010134=220652=2017010110105140825990860=201701011010514082599085799=10000100268=1279=1269=148=17359555=6SZ683=358382270=10219.0271=15346=71023=310=169
1128=99=18135=X49=SAMPLE75=2017010134=149852=2017010107505527362436760=201701010750552736243675799=10000100268=1279=1269=148=17359555=6SZ683=358383270=10218.0271=17346=81023=210=180
1128=99=18035=X49=SAMPLE75=2017010134=499352=2017010111244682271487960=201701011124468227148795799=10000100268=1279=1269=048=17359555=6SZ683=358384270=10216.0271=3346=31023=110=100
1128=99=18235=X49=SAMPLE75=2017010134=90352=2017010109374679694623660=201701010937467969462365799=10000100268=1279=1269=048=17359555=6SZ683=358385270=10215.0271=25346=131023=210=233
1128=99=18235=X49=SAMPLE75=2017010134=110252=2017010109404964116611860=201701010940496411661185799=10000100268=1279=1269=048=17359555=6SZ683=358386270=10213.0271=18346=101023=410=234
1128=99=25135=X49=SAMPLE75=2017010134=249752=2017010107432372274512860=201701010743237227451285799=10000100268=2279=1269=048=17360055=6SH783=99533270=10263.0271=12346=31023=6279=1269=048=17360055=6SH783=99534270=10259.0271=3346=11023=1010=104
1128=99=25435=X49=SAMPLE75=2017010134=142352=2017010113575174201029160=201701011357517420102915799=10000100268=2279=1269=048=17359555=6SZ683=358387270=10215.0271=26346=141023=2279=1269=048=17359555=6SZ683=358388270=10214.0271=16346=81023=310=086
1128=99=18035=X49=SAMPLE75=2017010134=356352=2017010106064926228950160=201701010606492622895015799=10000100268=1279=1269=148=17359555=6SZ683=358389270=10217.0271=4346=41023=110=139
1128=99=18035=X49=SAMPLE75=2017010134=129652=2017010107111511575224360=201701010711151157522435799=10000100268=1279=1269=048=17359555=6SZ683=358390270=10216.0271=4346=41023=110=119
1128=99=18135=X49=SAMPLE75=2017010134=119452=2017010102012210395588260=201701010201221039558825799=10000100268=1279=1269=048=17359555=6SZ683=358391270=10214.0271=17346=91023=310=180
1128=99=18235=X49=SAMPLE75=2017010134=204152=2017010112493411380636960=201701011249341138063695799=10000100268=1279=1269=048=17359555=6SZ683=358392270=10212.0271=32346=111023=510=193
1128=99=18235=X49=SAMPLE75=2017010134=184952=2017010101524455179860760=201701010152445517986075799=10000100268=1279=1269=048=17359555=6SZ683=358393270=10212.0271=25346=101023=510=196
1128=99=18035=X49=SAMPLE75=2017010134=435452=2017010104360165992190760=201701010436016599219075799=10000100268=1279=1269=048=17359555=6SZ683=358394270=10216.0271=3346=31023=110=080
1128=99=18235=X49=SAMPLE75=2017010134=318752=2017010106343795470327660=201701010634379547032765799=10000100268=1279=1269=048=17359555=6SZ683=358395270=10214.0271=20346=101023=310=186
1128=99=18135=X49=SAMPLE75=2017010134=72152=2017010111443773479337160=201701011144377347933715799=10000100268=1279=1269=148=17359555=6SZ683=358396270=10219.0271=17346=81023=310=160
1128=99=18135=X49=SAMPLE75=2017010134=133252=2017010106023200016448860=201701010602320001644885799=10000100268=1279=1269=148=17359555=6SZ683=358397270=10222.0271=30346=91023=610=178
1128=99=25535=X49=SAMPLE75=2017010134=159852=2017010110183291462442660=201701011018329146244265799=10000100268=2279=1269=048=17359555=6SZ683=358398270=10215.0271=25346=131023=2279=1269=048=17359555=6SZ683=358399270=10214.0271=21346=111023=310=101
1128=99=18235=X49=SAMPLE75=2017010134=171852=2017010108230213891256960=201701010823021389125695799=10000100268=1279=1269=048=17359555=6SZ683=358400270=10213.0271=19346=111023=410=183
1128=99=18035=X49=SAMPLE75=2017010134=75452=2017010108082466286748860=201701010808246628674885799=10000100268=1279=1269=148=17359555=6SZ683=358401270=10217.0271=5346=51023=110=104
1128=99=18235=X49=SAMPLE75=2017010134=207152=2017010101431246718655360=201701010143124671865535799=10000100268=1279=1269=048=17359555=6SZ683=358402270=10213.0271=22346=121023=410=212
1128=99=18135=X49=SAMPLE75=2017010134=351052=2017010113543505757468260=201701011354350575746825799=10000100268=1279=1269=148=17359555=6SZ683=358403270=10220.0271=17346=81023=410=153
1128=99=18235=X49=SAMPLE75=2017010134=371452=2017010103132209504316960=201701010313220950431695799=10000100268=1279=1269=048=17359555=6SZ683=358404270=10212.0271=26346=111023=510=208
1128=99=18135=X49=SAMPLE75=2017010134=329452=2017010110150240852653260=201701011015024085265325799=10000100268=1279=1269=148=17359555=6SZ683=358405270=10223.0271=22346=71023=710=167
1128=99=18035=X49=SAMPLE75=2017010134=441052=2017010112265130098430360=201701011226513009843035799=10000100268=1279=1269=048=17359555=6SZ683=358406270=10216.0271=4346=41023=110=094
1128=99=18035=X49=SAMPLE75=2017010134=74652=2017010104352909742013360=201701010435290974201335799=10000100268=1279=1269=148=17359555=6SZ683=358407270=10217.0271=4346=41023=110=099
1128=99=18035=X49=SAMPLE75=2017010134=304552=2017010103215664013668660=201701010321566401366865799=10000100268=1279=1269=148=17359555=6SZ683=358408270=10217.0271=3346=31023=110=086
1128=99=18235=X49=SAMPLE75=2017010134=280952=2017010108573446277169260=201701010857344627716925799=10000100268=1279=1269=048=17359555=6SZ683=358409270=10212.0271=29346=121023=510=184
1128=99=18135=X49=SAMPLE75=2017010134=412752=2017010112520517898601360=201701011252051789860135799=10000100268=1279=1269=148=17359555=6SZ683=358410270=10224.0271=44346=51023=810=146
1128=99=18235=X49=SAMPLE75=2017010134=322752=2017010113571449051539660=201701011357144905153965799=10000100268=1279=1269=148=17359555=6SZ683=358411270=10221.0271=29346=121023=510=184
1128=99=25235=X49=SAMPLE75=2017010134=92052=2017010110324801129262260=201701011032480112926225799=10000100268=2279=1269=148=17359555=6SZ683=358412270=10217.0271=2346=21023=1279=1269=148=17359555=6SZ683=358413270=10218.0271=18346=91023=210=196
1128=99=25535=X49=SAMPLE75=2017010134=8252=2017010109560883376754460=201701010956088337675445799=10000100268=2279=1269=048=17359555=6SZ683=358414270=10215.0271=26346=141023=2279=1269=048=17359555=6SZ683=358415270=10214.0271=20346=101023=310=092
1128=99=25335=X49=SAMPLE75=2017010134=490152=2017010104071553577593760=201701010407155357759375799=10000100268=2279=1269=048=17359555=6SZ683=358416270=10210.0271=32346=91023=7279=1269=048=17359555=6SZ683=358417270=10209.0271=40346=61023=810=010
1128=99=18235=X49=SAMPLE75=2017010134=359252=2017010107365143963594560=201701010736514396359455799=10000100268=1279=1269=048=17359555=6SZ683=358418270=10211.0271=25346=101023=610=201
1128=99=25435=X49=SAMPLE75=2017010134=411552=2017010108545979484642960=201701010854597948464295799=10000100268=2279=1269=148=17359555=6SZ683=358419270=10221.0271=28346=111023=5279=1269=148=17359555=6SZ683=358420270=10223.0271=23346=81023=710=038
1128=99=18135=X49=SAMPLE75=2017010134=258252=2017010107493351915181360=201701010749335191518135799=10000100268=1279=1269=148=17359555=6SZ683=358421270=10220.0271=16346=71023=410=151
1128=99=18035=X49=SAMPLE75=2017010134=74552=2017010105580612967299860=201701010558061296729985799=10000100268=1279=1269=148=17359555=6SZ683=358422270=10217.0271=3346=31023=110=112
1128=99=18235=X49=SAMPLE75=2017010134=359952=2017010106001976020388160=201701010600197602038815799=10000100268=1279=1269=048=17359555=6SZ683=358423270=10212.0271=36346=131023=510=179
1128=99=18035=X49=SAMPLE75=2017010134=222452=2017010106225040750935660=201701010622504075093565799=10000100268=1279=1269=148=17359555=6SZ683=358424270=10217.0271=4346=41023=110=098
1128=99=18235=X49=SAMPLE75=2017010134=251752=2017010106360262523647160=201701010636026252364715799=10000100268=1279=1269=048=17359555=6SZ683=358425270=10212.0271=29346=121023=510=197
1128=99=18035=X49=SAMPLE75=2017010134=56552=2017010101364401522232460=201701010136440152223245799=10000100268=1279=1269=048=17359555=6SZ683=358426270=10216.0271=3346=31023=110=105
1128=99=25335=X49=SAMPLE75=2017010134=399152=2017010107015695123467060=201701010701569512346705799=10000100268=2279=1269=048=17359555=6SZ683=358427270=10210.0271=29346=81023=7279=1269=048=17359555=6SZ683=358428270=10209.0271=43346=71023=810=033
1128=99=18235=X49=SAMPLE75=2017010134=482852=2017010100440642602263960=201701010044064260226395799=10000100268=1279=1269=148=17359555=6SZ683=358429270=10226.0271=16346=31023=1010=216
1128=99=18235=X49=SAMPLE75=2017010134=265652=2017010104011185909222560=201701010401118590922255799=10000100268=1279=1269=048=17359555=6SZ683=358430270=10212.0271=36346=131023=510=203
1128=99=18135=X49=SAMPLE75=2017010134=78152=2017010102364336058460260=201701010236433605846025799=10000100268=1279=1269=048=17359555=6SZ683=358431270=10210.0271=30346=91023=710=166
1128=99=18235=X49=SAMPLE75=2017010134=752=2017010100111113923308560=201701010011111392330855799=10000100268=1279=1269=048=17359555=6SZ683=358432270=10212.0271=29346=121023=510=207
1128=99=18135=X49=SAMPLE75=2017010134=35152=2017010114245759001231160=201701011424575900123115799=10000100268=1279=1269=048=17359555=6SZ683=358433270=10208.0271=20346=61023=910=143
1128=99=25435=X49=SAMPLE75=2017010134=382252=2017010104095132460138660=201701010409513246013865799=10000100268=2279=1269=048=17359555=6SZ683=358434270=10210.0271=33346=101023=7279=1269=048=17359555=6SZ683=358435270=10209.0271=40346=61023=810=061
1128=99=18235=X49=SAMPLE75=2017010134=63352=2017010106033364587440460=201701010603336458744045799=10000100268=1279=1269=048=17359555=6SZ683=358436270=10207.0271=21346=61023=1010=214
1128=99=25335=X49=SAMPLE75=2017010134=116252=2017010100040093455645560=201701010004009345564555799=10000100268=2279=1269=048=17359555=6SZ683=358437270=10210.0271=30346=91023=7279=1269=048=17359555=6SZ683=358438270=10209.0271=43346=71023=810=023
1128=99=25435=X49=SAMPLE75=2017010134=334652=2017010106232965581717560=201701010623296558171755799=10000100268=2279=1269=048=17359555=6SZ683=358439270=10210.0271=33346=101023=7279=1269=048=17359555=6SZ683=358440270=10209.0271=40346=61023=810=060
1128=99=25335=X49=SAMPLE75=2017010134=359952=2017010104540775926358860=201701010454077592635885799=10000100268=2279=1269=048=17359555=6SZ683=358441270=10210.0271=30346=91023=7279=1269=048=17359555=6SZ683=358442270=10209.0271=43346=71023=810=035
1128=99=25435=X49=SAMPLE75=2017010134=317452=2017010110370489044416760=201701011037048904441675799=10000100268=2279=1269=048=17359555=6SZ683=358443270=10210.0271=33346=101023=7279=1269=048=17359555=6SZ683=358444270=10209.0271=40346=61023=810=053
1128=99=25335=X49=SAMPLE75=2017010134=115952=2017010108353048862470660=201701010835304886247065799=10000100268=2279=1269=048=17359555=6SZ683=358445270=10210.0271=30346=91023=7279=1269=048=17359555=6SZ683=358446270=10209.0271=43346=71023=810=249
1128=99=18235=X49=SAMPLE75=2017010134=372452=2017010111011687660835760=201701011101168766083575799=10000100268=1279=1269=048=17359555=6SZ683=358447270=10212.0271=36346=131023=510=227
1128=99=18235=X49=SAMPLE75=2017010134=127352=2017010104061997108003760=201701010406199710800375799=10000100268=1279=1269=048=17359555=6SZ683=358448270=10212.0271=29346=121023=510=229
1128=99=18035=X49=SAMPLE75=2017010134=349952=2017010111365537476806560=201701011136553747680655799=10000100268=1279=1269=048=17359555=6SZ683=358449270=10216.0271=2346=21023=110=127
1128=99=18035=X49=SAMPLE75=2017010134=242552=2017010109270118564428860=201701010927011856442885799=10000100268=1279=1269=048=17359555=6SZ683=358450270=10216.0271=1346=11023=110=139
1128=99=18235=X49=SAMPLE75=2017010134=178052=2017010109423780252764160=201701010942378025276415799=10000100268=1279=1269=048=17359555=6SZ683=358451270=10211.0271=28346=111023=610=234
1128=99=18235=X49=SAMPLE75=2017010134=399652=2017010103074419980152960=201701010307441998015295799=10000100268=1279=1269=148=17359555=6SZ683=358452270=10222.0271=32346=101023=610=224
1128=99=25235=X49=SAMPLE75=2017010134=296552=2017010104512139522931160=201701010451213952293115799=10000100268=2279=1269=148=17359555=6SZ683=358453270=10217.0271=5346=51023=1279=1269=148=17359555=6SZ683=358454270=10218.0271=17346=81023=210=237
1128=99=25335=X49=SAMPLE75=2017010134=39252=2017010113075565613472560=201701011307556561347255799=10000100268=2279=2269=048=17359555=6SZ683=358455270=10216.0271=1346=11023=1279=0269=048=17359555=6SZ683=358456270=10206.0271=39346=61023=1010=027
1128=99=17935=X49=SAMPLE75=2017010134=289752=2017010106332782840931460=201701010633278284093145799=10000100268=1279=1269=048=17360055=6SH783=99535270=10268.0271=5346=21023=110=074
1128=99=18235=X49=SAMPLE75=2017010134=338552=2017010106230069793912760=201701010623006979391275799=10000100268=1279=1269=048=17359555=6SZ683=358457270=10211.0271=26346=101023=510=241
1128=99=18235=X49=SAMPLE75=2017010134=33352=2017010101022603879323960=201701010102260387932395799=10000100268=1279=1269=048=17359555=6SZ683=358458270=10206.0271=40346=71023=1010=246
1128=99=25535=X49=SAMPLE75=2017010134=443252=2017010102445595931049160=201701010244559593104915799=10000100268=2279=1269=048=17359555=6SZ683=358459270=10215.0271=25346=131023=1279=1269=048=17359555=6SZ683=358460270=10214.0271=21346=111023=210=111
1128=99=18135=X49=SAMPLE75=2017010134=100752=2017010108165621972221860=201701010816562197222185799=10000100268=1279=1269=148=17359555=6SZ683=358461270=10220.0271=17346=81023=410=181
1128=99=18035=X49=SAMPLE75=2017010134=228852=2017010110564298427426160=201701011056429842742615799=10000100268=1279=0269=048=17359555=6SZ683=358462270=10216.0271=1346=11023=110=154
1128=99=17935=X49=SAMPLE75=2017010134=406352=2017010107531169241609460=201701010753116924160945799=10000100268=1279=0269=048=17360055=6SH783=99536270=10269.0271=3346=11023=110=088
1128=99=17935=X49=SAMPLE75=2017010134=441252=2017010113230690365582760=201701011323069036558275799=10000100268=1279=1269=048=17360055=6SH783=99537270=10268.0271=6346=31023=210=087
1128=99=18235=X49=SAMPLE75=2017010134=400252=2017010111295558578876760=201701011129555857887675799=10000100268=1279=1269=048=17359555=6SZ683=358463270=10211.0271=28346=111023=610=247
1128=99=18035=X49=SAMPLE75=2017010134=267352=2017010100464732222207760=201701010046473222220775799=10000100268=1279=1269=048=17359555=6SZ683=358464270=10216.0271=2346=21023=110=129
1128=99=18035=X49=SAMPLE75=2017010134=305052=2017010102050674264618360=201701010205067426461835799=10000100268=1279=1269=048=17359555=6SZ683=358465270=10216.0271=1346=11023=110=131
1128=99=18035=X49=SAMPLE75=2017010134=447252=2017010101134815762772760=201701010113481576277275799=10000100268=1279=1269=048=17359555=6SZ683=358466270=10216.0271=2346=21023=110=138
1128=99=18035=X49=SAMPLE75=2017010134=229452=2017010101140797275544060=201701010114079727554405799=10000100268=1279=1269=048=17359555=6SZ683=358467270=10216.0271=3346=31023=110=144
1128=99=18035=X49=SAMPLE75=2017010134=294852=2017010109195937802940560=201701010919593780294055799=10000100268=1279=1269=048=17359555=6SZ683=358468270=10216.0271=2346=21023=110=114
1128=99=18035=X49=SAMPLE75=2017010134=93952=2017010109054285549190660=201701010905428554919065799=10000100268=1279=1269=048=17359555=6SZ683=358469270=10216.0271=1346=11023=110=130
1128=99=18235=X49=SAMPLE75=2017010134=136852=2017010108042350605328460=201701010804235060532845799=10000100268=1279=1269=048=17359555=6SZ683=358470270=10212.0271=36346=131023=510=223
1128=99=25335=X49=SAMPLE75=2017010134=296452=2017010113094645427479060=201701011309464542747905799=10000100268=2279=2269=048=17359555=6SZ683=358471270=10216.0271=1346=11023=1279=0269=048=17359555=6SZ683=358472270=10206.0271=40346=71023=1010=255
1128=99=17935=X49=SAMPLE75=2017010134=50552=2017010108040678631410660=201701010804067863141065799=10000100268=1279=1269=048=17360055=6SH783=99538270=10268.0271=5346=21023=210=061
1128=99=18235=X49=SAMPLE75=2017010134=258652=2017010106124835040124660=201701010612483504012465799=10000100268=1279=1269=048=17359555=6SZ683=358473270=10211.0271=26346=101023=510=215
1128=99=25035=X49=SAMPLE75=2017010134=483052=2017010106031895871369260=201701010603189587136925799=10000100268=2279=2269=048=17360055=6SH783=99539270=10269.0271=3346=11023=1279=0269=048=17360055=6SH783=99540270=10259.0271=3346=11023=1010=055
1128=99=18035=X49=SAMPLE75=2017010134=362352=2017010108055266580741560=201701010805526658074155799=10000100268=1279=0269=048=17359555=6SZ683=358474270=10216.0271=1346=11023=110=120
1128=99=17935=X49=SAMPLE75=2017010134=281752=2017010105584539756563960=201701010558453975656395799=10000100268=1279=1269=048=17360055=6SH783=99541270=10268.0271=6346=31023=110=064
1128=99=18235=X49=SAMPLE75=2017010134=445352=2017010103125497079975760=201701010312549707997575799=10000100268=1279=1269=048=17359555=6SZ683=358475270=10211.0271=28346=111023=610=211
1128=99=18235=X49=SAMPLE75=2017010134=103752=2017010110185609843633860=201701011018560984363385799=10000100268=1279=1269=048=17359555=6SZ683=358476270=10212.0271=29346=121023=510=214
1128=99=20835=X49=SAMPLE75=2017010134=271652=2017010106042493976299960=201701010604249397629995799=00000001268=1279=0269=248=17359555=6SZ683=358477270=10216.0271=1346=25797=237705=237=032=137=032=110=098
1128=99=15635=X49=SAMPLE75=2017010134=3552=2017010113251789831422160=201701011325178983142215799=00000010268=1279=0269=e48=17359555=6SZ683=358478271=9110=112
1128=99=25335=X49=SAMPLE75=2017010134=105352=2017010104401960364640260=201701010440196036464025799=10000100268=2279=2269=048=17359555=6SZ683=358479270=10216.0271=1346=11023=1279=0269=048=17359555=6SZ683=358480270=10206.0271=40346=71023=1010=003
1128=99=17935=X49=SAMPLE75=2017010134=9052=2017010114103718923120260=201701011410371892312025799=10000100268=1279=0269=148=17360055=6SH783=99542270=10272.0271=3346=11023=110=055
1128=99=17935=X49=SAMPLE75=2017010134=493852=2017010108462720720438860=201701010846272072043885799=10000100268=1279=1269=048=17360055=6SH783=99543270=10268.0271=5346=21023=110=055
1128=99=17935=X49=SAMPLE75=2017010134=75352=2017010113341492617813260=201701011334149261781325799=10000100268=1279=0269=148=17360055=6SH783=99544270=10273.0271=1346=11023=210=050
1128=99=18235=X49=SAMPLE75=2017010134=145852=2017010113125236394304660=201701011312523639430465799=10000100268=1279=1269=048=17359555=6SZ683=358481270=10211.0271=26346=101023=510=226
1128=99=18035=X49=SAMPLE75=2017010134=432252=2017010102014633835862660=201701010201463383586265799=10000100268=1279=1269=148=17360055=6SH783=99545270=10276.0271=37346=31023=510=114
1128=99=17935=X49=SAMPLE75=2017010134=299352=2017010114294931102465260=201701011429493110246525799=10000100268=1279=1269=148=17360055=6SH783=99546270=10273.0271=4346=21023=210=065
1128=99=18035=X49=SAMPLE75=2017010134=76452=2017010101202307505285260=201701010120230750528525799=10000100268=1279=0269=048=17359555=6SZ683=358482270=10216.0271=1346=11023=110=120
1128=99=17935=X49=SAMPLE75=2017010134=13052=2017010111040066140649460=201701011104006614064945799=10000100268=1279=0269=048=17360055=6SH783=99547270=10269.0271=3346=11023=110=084
1128=99=17935=X49=SAMPLE75=2017010134=52152=2017010101090487895822760=201701010109048789582275799=10000100268=1279=1269=048=17360055=6SH783=99548270=10268.0271=6346=31023=210=073
1128=99=18235=X49=SAMPLE75=2017010134=409752=2017010100393619420603960=201701010039361942060395799=10000100268=1279=1269=048=17359555=6SZ683=358483270=10211.0271=28346=111023=610=238
1128=99=25035=X49=SAMPLE75=2017010134=113852=2017010113584338348728860=201701011358433834872885799=10000100268=2279=2269=148=17360055=6SH783=99549270=10272.0271=3346=11023=1279=0269=148=17360055=6SH783=99550270=10282.0271=3346=11023=1010=053
1128=99=17935=X49=SAMPLE75=2017010134=494452=2017010114174370375954060=201701011417437037595405799=10000100268=1279=1269=148=17360055=6SH783=99551270=10273.0271=1346=11023=110=055
1128=99=18235=X49=SAMPLE75=2017010134=240652=2017010114115081924253760=201701011411508192425375799=10000100268=1279=1269=048=17359555=6SZ683=358484270=10212.0271=36346=131023=510=254
1128=99=25035=X49=SAMPLE75=2017010134=127852=2017010101113747389538260=201701010111374738953825799=10000100268=2279=2269=048=17360055=6SH783=99552270=10269.0271=3346=11023=1279=0269=048=17360055=6SH783=99553270=10259.0271=3346=11023=1010=093
1128=99=18235=X49=SAMPLE75=2017010134=151952=2017010106433205183203560=201701010643320518320355799=10000100268=1279=1269=048=17359555=6SZ683=358485270=10212.0271=29346=121023=510=225
1128=99=18235=X49=SAMPLE75=2017010134=284152=2017010108261673300520360=201701010826167330052035799=10000100268=1279=1269=048=17359555=6SZ683=358486270=10212.0271=36346=131023=510=238
1128=99=25135=X49=SAMPLE75=2017010134=150652=2017010112043653051215660=201701011204365305121565799=10000100268=2279=2269=148=17360055=6SH783=99554270=10273.0271=1346=11023=1279=0269=148=17360055=6SH783=99555270=10283.0271=61346=31023=1010=148
1128=99=17935=X49=SAMPLE75=2017010134=41652=2017010112130591865049060=201701011213059186504905799=10000100268=1279=1269=148=17360055=6SH783=99556270=10276.0271=4346=21023=310=093
1128=99=18035=X49=SAMPLE75=2017010134=345452=2017010101180926543931360=201701010118092654393135799=10000100268=1279=1269=048=17359555=6SZ683=358487270=10216.0271=2346=21023=110=152
1128=99=18035=X49=SAMPLE75=2017010134=374452=2017010104560855574127560=201701010456085557412755799=10000100268=1279=1269=048=17359555=6SZ683=358488270=10216.0271=3346=31023=110=136
1128=99=18235=X49=SAMPLE75=2017010134=32852=2017010112362245903857660=201701011236224590385765799=10000100268=1279=1269=048=17359555=6SZ683=358489270=10212.0271=29346=121023=510=253
1128=99=18035=X49=SAMPLE75=2017010134=221152=2017010106011460924411360=201701010601146092441135799=10000100268=1279=1269=048=17359555=6SZ683=358490270=10216.0271=4346=41023=110=149
1128=99=25535=X49=SAMPLE75=2017010134=102152=2017010108533758486412360=201701010853375848641235799=10000100268=2279=1269=048=17359555=6SZ683=358491270=10215.0271=26346=141023=2279=1269=048=17359555=6SZ683=358492270=10214.0271=20346=101023=310=126
1128=99=18235=X49=SAMPLE75=2017010134=324052=2017010107103344056012860=201701010710334405601285799=10000100268=1279=1269=048=17359555=6SZ683=358493270=10212.0271=36346=131023=510=244
1128=99=18235=X49=SAMPLE75=2017010134=28052=2017010104101055816180360=201701010410105581618035799=10000100268=1279=1269=048=17359555=6SZ683=358494270=10212.0271=29346=121023=510=231
1128=99=18235=X49=SAMPLE75=2017010134=216252=2017010111560473979192960=201701011156047397919295799=10000100268=1279=1269=048=17359555=6SZ683=358495270=10212.0271=36346=131023=510=232
1128=99=18135=X49=SAMPLE75=2017010134=230352=2017010113553153273319260=201701011355315327331925799=10000100268=1279=1269=148=17359555=6SZ683=358496270=10218.0271=18346=91023=210=196
1128=99=18235=X49=SAMPLE75=2017010134=58252=2017010101425582226647060=201701010142558222664705799=10000100268=1279=1269=048=17359555=6SZ683=358497270=10212.0271=29346=121023=510=237
1128=99=18235=X49=SAMPLE75=2017010134=485652=2017010103321532253954560=201701010332153225395455799=10000100268=1279=1269=048=17359555=6SZ683=358498270=10210.0271=33346=101023=710=000
1128=99=18135=X49=SAMPLE75=2017010134=188852=2017010104561195268679860=201701010456119526867985799=10000100268=1279=1269=148=17359555=6SZ683=358499270=10223.0271=25346=91023=710=217
1128=99=18235=X49=SAMPLE75=2017010134=134652=2017010104120898680927160=201701010412089868092715799=10000100268=1279=1269=048=17359555=6SZ683=358500270=10211.0271=29346=121023=610=236
1128=99=18235=X49=SAMPLE75=2017010134=186752=2017010100220476397719960=201701010022047639771995799=10000100268=1279=1269=048=17359555=6SZ683=358501270=10212.0271=36346=131023=510=180
1128=99=18235=X49=SAMPLE75=2017010134=96952=2017010105142979969414460=201701010514297996941445799=10000100268=1279=1269=048=17359555=6SZ683=358502270=10210.0271=34346=111023=710=181
1128=99=18035=X49=SAMPLE75=2017010134=80052=2017010103121937405579660=201701010312193740557965799=10000100268=1279=1269=048=17359555=6SZ683=358503270=10216.0271=3346=31023=110=080
1128=99=18135=X49=SAMPLE75=2017010134=24152=2017010104072535683059660=201701010407253568305965799=10000100268=1279=1269=048=17359555=6SZ683=358504270=10209.0271=46346=81023=810=167
1128=99=18135=X49=SAMPLE75=2017010134=403652=2017010106372119625633760=201701010637211962563375799=10000100268=1279=1269=148=17359555=6SZ683=358505270=10224.0271=46346=61023=810=159
1128=99=18135=X49=SAMPLE75=2017010134=127252=2017010112045077312451460=201701011204507731245145799=10000100268=1279=1269=148=17359555=6SZ683=358506270=10220.0271=18346=91023=410=160
1128=99=18035=X49=SAMPLE75=2017010134=344552=2017010101400564743615860=201701010140056474361585799=10000100268=1279=1269=048=17359555=6SZ683=358507270=10216.0271=2346=21023=110=110
1128=99=18035=X49=SAMPLE75=2017010134=459852=2017010112273106906010360=201701011227310690601035799=10000100268=1279=1269=048=17359555=6SZ683=358508270=10216.0271=3346=31023=110=101
1128=99=18235=X49=SAMPLE75=2017010134=251952=2017010111472642824316260=201701011147264282431625799=10000100268=1279=1269=048=17359555=6SZ683=358509270=10212.0271=29346=121023=510=228
1128=99=18035=X49=SAMPLE75=2017010134=67652=2017010114261297319703560=201701011426129731970355799=10000100268=1279=1269=048=17359555=6SZ683=358510270=10216.0271=2346=21023=110=086
1128=99=18135=X49=SAMPLE75=2017010134=47552=2017010114144016776892960=201701011414401677689295799=10000100268=1279=1269=048=17359555=6SZ683=358511270=10208.0271=23346=71023=910=156
1128=99=18135=X49=SAMPLE75=2017010134=432852=2017010113000849240608860=201701011300084924060885799=10000100268=1279=1269=148=17359555=6SZ683=358512270=10225.0271=20346=51023=910=164
1128=99=18135=X49=SAMPLE75=2017010134=123752=2017010114163311663982960=201701011416331166398295799=10000100268=1279=1269=048=17359555=6SZ683=358513270=10208.0271=24346=81023=910=179
1128=99=18235=X49=SAMPLE75=2017010134=49252=2017010109233983574160960=201701010923398357416095799=10000100268=1279=1269=148=17359555=6SZ683=358514270=10221.0271=29346=121023=510=223
1128=99=18035=X49=SAMPLE75=2017010134=202552=2017010100455853033696060=201701010045585303369605799=10000100268=1279=1269=048=17359555=6SZ683=358515270=10216.0271=1346=11023=110=106
1128=99=18035=X49=SAMPLE75=2017010134=200252=2017010108585632482322760=201701010858563248232275799=10000100268=1279=1269=048=17359555=6SZ683=358516270=10216.0271=2346=21023=110=081
1128=99=25535=X49=SAMPLE75=2017010134=54752=2017010114095765477516960=201701011409576547751695799=10000100268=2279=1269=048=17359555=6SZ683=358517270=10215.0271=25346=131023=2279=1269=048=17359555=6SZ683=358518270=10214.0271=21346=111023=310=072
1128=99=18035=X49=SAMPLE75=2017010134=85052=2017010107501790542786160=201701010750179054278615799=10000100268=1279=1269=048=17359555=6SZ683=358519270=10216.0271=1346=11023=110=083
1128=99=18135=X49=SAMPLE75=2017010134=332552=2017010101100571267677560=201701010110057126767755799=10000100268=1279=1269=048=17359555=6SZ683=358520270=10209.0271=47346=91023=810=193
1128=99=18235=X49=SAMPLE75=2017010134=137752=2017010102171272468537360=201701010217127246853735799=10000100268=1279=1269=048=17359555=6SZ683=358521270=10207.0271=24346=71023=1010=212
1128=99=18235=X49=SAMPLE75=2017010134=498852=2017010110030508256436760=201701011003050825643675799=10000100268=1279=1269=148=17359555=6SZ683=358522270=10226.0271=18346=41023=1010=216
1128=99=18135=X49=SAMPLE75=2017010134=305052=2017010111084465378514460=201701011108446537851445799=10000100268=1279=1269=148=17359555=6SZ683=358523270=10225.0271=21346=61023=910=150
1128=99=25335=X49=SAMPLE75=2017010134=410352=2017010105130578227055060=201701010513057822705505799=10000100268=2279=2269=048=17359555=6SZ683=358524270=10216.0271=1346=11023=1279=0269=048=17359555=6SZ683=358525270=10206.0271=40346=71023=1010=224
1128=99=17935=X49=SAMPLE75=2017010134=94552=2017010111065578992550860=201701011106557899255085799=10000100268=1279=1269=048=17360055=6SH783=99557270=10268.0271=5346=21023=110=037
1128=99=18235=X49=SAMPLE75=2017010134=471752=2017010106294370049486860=201701010629437004948685799=10000100268=1279=1269=048=17359555=6SZ683=358526270=10211.0271=27346=111023=510=209
1128=99=25535=X49=SAMPLE75=2017010134=440752=2017010100194525228169260=201701010019452522816925799=10000100268=2279=1269=148=17359555=6SZ683=358527270=10220.0271=21346=101023=4279=1269=148=17359555=6SZ683=358528270=10221.0271=26346=111023=510=103
1128=99=18235=X49=SAMPLE75=2017010134=158852=2017010107400721037709060=201701010740072103770905799=10000100268=1279=1269=048=17359555=6SZ683=358529270=10206.0271=43346=81023=1010=228
1128=99=18135=X49=SAMPLE75=2017010134=200752=2017010109352863611766260=201701010935286361176625799=10000100268=1279=1269=048=17359555=6SZ683=358530270=10207.0271=25346=81023=910=177
1128=99=25435=X49=SAMPLE75=2017010134=221352=2017010112331262942047760=201701011233126294204775799=10000100268=2279=1269=148=17359555=6SZ683=358531270=10221.0271=27346=121023=5279=1269=148=17359555=6SZ683=358532270=10223.0271=24346=81023=710=026
1128=99=18235=X49=SAMPLE75=2017010134=455752=2017010114160914291938960=201701011416091429193895799=10000100268=1279=1269=048=17359555=6SZ683=358533270=10215.0271=17346=121023=110=189
1128=99=18235=X49=SAMPLE75=2017010134=304952=2017010106305550042311360=201701010630555004231135799=10000100268=1279=1269=048=17359555=6SZ683=358534270=10215.0271=25346=131023=110=209
1128=99=18035=X49=SAMPLE75=2017010134=331752=2017010102463735785192860=201701010246373578519285799=10000100268=1279=0269=048=17359555=6SZ683=358535270=10216.0271=1346=11023=110=101
1128=99=17935=X49=SAMPLE75=2017010134=365052=2017010110255518643660760=201701011025551864366075799=10000100268=1279=0269=048=17360055=6SH783=99558270=10269.0271=3346=11023=110=064
1128=99=17935=X49=SAMPLE75=2017010134=373952=2017010109072912412133060=201701010907291241213305799=10000100268=1279=1269=048=17360055=6SH783=99559270=10268.0271=6346=31023=210=066
1128=99=18235=X49=SAMPLE75=2017010134=470452=2017010111373461204579160=201701011137346120457915799=10000100268=1279=1269=048=17359555=6SZ683=358536270=10211.0271=29346=121023=610=219
1128=99=25335=X49=SAMPLE75=2017010134=1352=2017010102004270966839360=201701010200427096683935799=10000100268=2279=2269=048=17359555=6SZ683=358537270=10216.0271=1346=11023=1279=0269=048=17359555=6SZ683=358538270=10206.0271=43346=81023=1010=011
1128=99=17935=X49=SAMPLE75=2017010134=382352=2017010110214915394701460=201701011021491539470145799=10000100268=1279=1269=048=17360055=6SH783=99560270=10268.0271=5346=21023=210=067
1128=99=18235=X49=SAMPLE75=2017010134=357652=2017010107321995740290260=201701010732199574029025799=10000100268=1279=1269=048=17359555=6SZ683=358539270=10211.0271=27346=111023=510=221
1128=99=25035=X49=SAMPLE75=2017010134=495252=2017010102223501257356560=201701010222350125735655799=10000100268=2279=2269=048=17360055=6SH783=99561270=10269.0271=3346=11023=1279=0269=048=17360055=6SH783=99562270=10259.0271=3346=11023=1010=061
1128=99=18035=X49=SAMPLE75=2017010134=9052=2017010107520033442200760=201701010752003344220075799=10000100268=1279=0269=048=17359555=6SZ683=358540270=10216.0271=1346=11023=110=116
1128=99=17935=X49=SAMPLE75=2017010134=50152=2017010112262851113209160=201701011226285111320915799=10000100268=1279=1269=048=17360055=6SH783=99563270=10268.0271=6346=31023=110=050
1128=99=18235=X49=SAMPLE75=2017010134=497552=2017010105202057697918360=201701010520205769791835799=10000100268=1279=1269=048=17359555=6SZ683=358541270=10211.0271=29346=121023=610=213
1128=99=25335=X49=SAMPLE75=2017010134=136052=2017010114035463888603260=201701011403546388860325799=10000100268=2279=2269=048=17359555=6SZ683=358542270=10216.0271=1346=11023=1279=0269=048=17359555=6SZ683=358543270=10206.0271=43346=81023=1010=002
1128=99=17935=X49=SAMPLE75=2017010134=76352=2017010109181139280393160=201701010918113928039315799=10000100268=1279=1269=048=17360055=6SH783=99564270=10268.0271=5346=21023=110=073
1128=99=18235=X49=SAMPLE75=2017010134=411852=2017010105470731279074260=201701010547073127907425799=10000100268=1279=1269=048=17359555=6SZ683=358544270=10211.0271=27346=111023=510=222
1128=99=18035=X49=SAMPLE75=2017010134=451852=2017010101000552082296060=201701010100055208229605799=10000100268=1279=0269=048=17359555=6SZ683=358545270=10216.0271=1346=11023=110=104
1128=99=17935=X49=SAMPLE75=2017010134=228852=2017010107000192926425460=201701010700019292642545799=10000100268=1279=1269=048=17360055=6SH783=99565270=10268.0271=6346=31023=110=064
1128=99=18235=X49=SAMPLE75=2017010134=160252=2017010102502206372828460=201701010250220637282845799=10000100268=1279=1269=048=17359555=6SZ683=358546270=10211.0271=29346=121023=610=211
1128=99=25335=X49=SAMPLE75=2017010134=101852=2017010100031568877337160=201701010003156887733715799=10000100268=2279=2269=048=17359555=6SZ683=358547270=10216.0271=1346=11023=1279=0269=048=17359555=6SZ683=358548270=10206.0271=43346=81023=1010=023
1128=99=17935=X49=SAMPLE75=2017010134=65352=2017010113385048476778560=201701011338504847677855799=10000100268=1279=1269=048=17360055=6SH783=99566270=10268.0271=5346=21023=110=065
1128=99=18235=X49=SAMPLE75=2017010134=41552=2017010105153856295482160=201701010515385629548215799=10000100268=1279=1269=048=17359555=6SZ683=358549270=10211.0271=27346=111023=510=230
1128=99=18035=X49=SAMPLE75=2017010134=294252=2017010110515056888453160=201701011051505688845315799=10000100268=1279=0269=048=17359555=6SZ683=358550270=10216.0271=1346=11023=110=097
1128=99=17935=X49=SAMPLE75=2017010134=244152=2017010108433363471755560=201701010843336347175555799=10000100268=1279=0269=048=17360055=6SH783=99567270=10269.0271=3346=11023=110=065
1128=99=17935=X49=SAMPLE75=2017010134=379052=2017010102564367822778060=201701010256436782277805799=10000100268=1279=1269=048=17360055=6SH783=99568270=10268.0271=6346=31023=210=098
1128=99=18235=X49=SAMPLE75=2017010134=432152=2017010113512596081223160=201701011351259608122315799=10000100268=1279=1269=048=17359555=6SZ683=358551270=10211.0271=29346=121023=610=220
1128=99=25335=X49=SAMPLE75=2017010134=50252=2017010108203001023380060=201701010820300102338005799=10000100268=2279=2269=048=17359555=6SZ683=358552270=10216.0271=1346=11023=1279=0269=048=17359555=6SZ683=358553270=10206.0271=43346=81023=1010=242
1128=99=17935=X49=SAMPLE75=2017010134=469152=2017010107500347014579060=201701010750034701457905799=10000100268=1279=1269=048=17360055=6SH783=99569270=10268.0271=5346=21023=210=038
1128=99=18235=X49=SAMPLE75=2017010134=455652=2017010105595240129467160=201701010559524012946715799=10000100268=1279=1269=048=17359555=6SZ683=358554270=10211.0271=27346=111023=510=195
1128=99=25035=X49=SAMPLE75=2017010134=393452=2017010113145705978301960=201701011314570597830195799=10000100268=2279=2269=048=17360055=6SH783=99570270=10269.0271=3346=11023=1279=0269=048=17360055=6SH783=99571270=10259.0271=3346=11023=1010=050
1128=99=18035=X49=SAMPLE75=2017010134=9752=2017010103442498710152260=201701010344249871015225799=10000100268=1279=0269=048=17359555=6SZ683=358555270=10216.0271=1346=11023=110=098
1128=99=17935=X49=SAMPLE75=2017010134=48652=2017010100452047574022660=201701010045204757402265799=10000100268=1279=1269=048=17360055=6SH783=99572270=10268.0271=6346=31023=110=057
1128=99=18235=X49=SAMPLE75=2017010134=216352=2017010102331587742463360=201701010233158774246335799=10000100268=1279=1269=048=17359555=6SZ683=358556270=10211.0271=29346=121023=610=202
1128=99=25335=X49=SAMPLE75=2017010134=109052=2017010108564725782939260=201701010856472578293925799=10000100268=2279=2269=048=17359555=6SZ683=358557270=10216.0271=1346=11023=1279=0269=048=17359555=6SZ683=358558270=10206.0271=43346=81023=1010=010
1128=99=18035=X49=SAMPLE75=2017010134=290352=2017010104384136242271360=201701010438413624227135799=10000100268=1279=0269=048=17359555=6SZ683=358559270=10216.0271=1346=11023=110=109
1128=99=17935=X49=SAMPLE75=2017010134=378352=2017010113460315302684260=201701011346031530268425799=10000100268=1279=1269=048=17360055=6SH783=99573270=10268.0271=5346=21023=110=045
1128=99=18235=X49=SAMPLE75=2017010134=438952=2017010102421127536395860=201701010242112753639585799=10000100268=1279=1269=048=17359555=6SZ683=358560270=10211.0271=27346=111023=610=191
1128=99=25335=X49=SAMPLE75=2017010134=112252=2017010113170649355740660=201701011317064935574065799=10000100268=2279=2269=048=17359555=6SZ683=358561270=10216.0271=1346=11023=1279=0269=048=17359555=6SZ683=358562270=10206.0271=43346=81023=1010=243
1128=99=18035=X49=SAMPLE75=2017010134=119852=2017010110242989193006960=201701011024298919300695799=10000100268=1279=0269=048=17359555=6SZ683=358563270=10216.0271=1346=11023=110=117
1128=99=17935=X49=SAMPLE75=2017010134=385952=2017010103581221316861360=201701010358122131686135799=10000100268=1279=0269=048=17360055=6SH783=99574270=10269.0271=3346=11023=110=058
1128=99=17935=X49=SAMPLE75=2017010134=331952=2017010110104488494630360=201701011010448849463035799=10000100268=1279=1269=048=17360055=6SH783=99575270=10268.0271=6346=31023=210=078
1128=99=18235=X49=SAMPLE75=2017010134=288952=2017010108381779264899260=201701010838177926489925799=10000100268=1279=1269=048=17359555=6SZ683=358564270=10211.0271=29346=121023=610=239
1128=99=25335=X49=SAMPLE75=2017010134=234352=2017010108253782246034560=201701010825378224603455799=10000100268=2279=2269=048=17359555=6SZ683=358565270=10216.0271=1346=11023=1279=0269=048=17359555=6SZ683=358566270=10206.0271=43346=81023=1010=017
1128=99=17935=X49=SAMPLE75=2017010134=24852=2017010105441700994049960=201701010544170099404995799=10000100268=1279=1269=048=17360055=6SH783=99576270=10268.0271=5346=21023=210=083
1128=99=18235=X49=SAMPLE75=2017010134=133152=2017010101270908215695660=201701010127090821569565799=10000100268=1279=1269=048=17359555=6SZ683=358567270=10211.0271=27346=111023=510=243
1128=99=25035=X49=SAMPLE75=2017010134=47752=2017010107481255996438960=201701010748125599643895799=10000100268=2279=2269=048=17360055=6SH783=99577270=10269.0271=3346=11023=1279=0269=048=17360055=6SH783=99578270=10259.0271=3346=11023=1010=092
1128=99=18035=X49=SAMPLE75=2017010134=249352=2017010104395287029238160=201701010439528702923815799=10000100268=1279=0269=048=17359555=6SZ683=358568270=10216.0271=1346=11023=110=097
1128=99=17935=X49=SAMPLE75=2017010134=345752=2017010105592775800639260=201701010559277580063925799=10000100268=1279=0269=048=17360055=6SH783=99579270=10269.0271=3346=11023=110=058
1128=99=17935=X49=SAMPLE75=2017010134=96252=2017010103100787660961160=201701010310078766096115799=10000100268=1279=1269=048=17360055=6SH783=99580270=10268.0271=6346=31023=210=049
1128=99=18235=X49=SAMPLE75=2017010134=422052=2017010113185350626762560=201701011318535062676255799=10000100268=1279=1269=048=17359555=6SZ683=358569270=10211.0271=29346=121023=610=230
1128=99=25335=X49=SAMPLE75=2017010134=396752=2017010101140591157989260=201701010114059115798925799=10000100268=2279=2269=048=17359555=6SZ683=358570270=10216.0271=1346=11023=1279=0269=048=17359555=6SZ683=358571270=10206.0271=43346=81023=1010=001
1128=99=17935=X49=SAMPLE75=2017010134=14552=2017010102282045351302960=201701010228204535130295799=10000100268=1279=1269=048=17360055=6SH783=99581270=10268.0271=5346=21023=210=050
1128=99=18235=X49=SAMPLE75=2017010134=343552=2017010106285238085246860=201701010628523808524685799=10000100268=1279=1269=048=17359555=6SZ683=358572270=10211.0271=27346=111023=510=226
1128=99=25035=X49=SAMPLE75=2017010134=116652=2017010114310800245551760=201701011431080024555175799=10000100268=2279=2269=048=17360055=6SH783=99582270=10269.0271=3346=11023=1279=0269=048=17360055=6SH783=99583270=10259.0271=3346=11023=1010=076
1128=99=18035=X49=SAMPLE75=2017010134=361152=2017010112495988552658560=201701011249598855265855799=10000100268=1279=0269=048=17359555=6SZ683=358573270=10216.0271=1346=11023=110=090
1128=99=17935=X49=SAMPLE75=2017010134=298852=2017010112025491273964460=201701011202549127396445799=10000100268=1279=1269=048=17360055=6SH783=99584270=10268.0271=6346=31023=110=039
1128=99=18235=X49=SAMPLE75=2017010134=334052=2017010100072682467431160=201701010007268246743115799=10000100268=1279=1269=048=17359555=6SZ683=358574270=10211.0271=29346=121023=610=212
1128=99=25335=X49=SAMPLE75=2017010134=120752=2017010102124982782984160=201701010212498278298415799=10000100268=2279=2269=048=17359555=6SZ683=358575270=10216.0271=1346=11023=1279=0269=048=17359555=6SZ683=358576270=10206.0271=43346=81023=1010=022
1128=99=17935=X49=SAMPLE75=2017010134=134552=2017010106155883014400160=201701010615588301440015799=10000100268=1279=1269=048=17360055=6SH783=99585270=10268.0271=5346=21023=110=062
1128=99=18235=X49=SAMPLE75=2017010134=449352=2017010112004091944668460=201701011200409194466845799=10000100268=1279=1269=048=17359555=6SZ683=358577270=10211.0271=27346=111023=510=219
1128=99=18035=X49=SAMPLE75=2017010134=34252=2017010112320947952388060=201701011232094795238805799=10000100268=1279=0269=048=17359555=6SZ683=358578270=10216.0271=1346=11023=110=119
1128=99=17935=X49=SAMPLE75=2017010134=113252=2017010100355680414096460=201701010035568041409645799=10000100268=1279=1269=048=17360055=6SH783=99586270=10268.0271=6346=31023=110=063
1128=99=18235=X49=SAMPLE75=2017010134=381952=2017010102161724810342560=201701010216172481034255799=10000100268=1279=1269=048=17359555=6SZ683=358579270=10211.0271=29346=121023=610=231
1128=99=25335=X49=SAMPLE75=2017010134=53252=2017010105195557231737460=201701010519555723173745799=10000100268=2279=2269=048=17359555=6SZ683=358580270=10216.0271=1346=11023=1279=0269=048=17359555=6SZ683=358581270=10206.0271=43346=81023=1010=008
1128=99=17935=X49=SAMPLE75=2017010134=448452=2017010113432099708007060=201701011343209970800705799=10000100268=1279=1269=048=17360055=6SH783=99587270=10268.0271=5346=21023=110=078
1128=99=18235=X49=SAMPLE75=2017010134=420352=2017010104464373126146060=201701010446437312614605799=10000100268=1279=1269=048=17359555=6SZ683=358582270=10211.0271=27346=111023=510=219
1128=99=18035=X49=SAMPLE75=2017010134=494852=2017010109183883705547560=201701010918388370554755799=10000100268=1279=0269=048=17359555=6SZ683=358583270=10216.0271=1346=11023=110=115
1128=99=17935=X49=SAMPLE75=2017010134=393152=2017010103221131434579660=201701010322113143457965799=10000100268=1279=0269=048=17360055=6SH783=99588270=10269.0271=3346=11023=110=070
1128=99=17935=X49=SAMPLE75=2017010134=299652=2017010101454368652096560=201701010145436865209655799=10000100268=1279=1269=048=17360055=6SH783=99589270=10268.0271=6346=31023=210=087
1128=99=18235=X49=SAMPLE75=2017010134=387452=2017010100544969542233360=201701010054496954223335799=10000100268=1279=1269=048=17359555=6SZ683=358584270=10211.0271=29346=121023=610=225
1128=99=25335=X49=SAMPLE75=2017010134=1652=2017010112564740199642460=201701011256474019964245799=10000100268=2279=2269=048=17359555=6SZ683=358585270=10216.0271=1346=11023=1279=0269=048=17359555=6SZ683=358586270=10206.0271=43346=81023=1010=027
1128=99=17935=X49=SAMPLE75=2017010134=97552=2017010100371753721179960=201701010037175372117995799=10000100268=1279=1269=048=17360055=6SH783=99590270=10268.0271=5346=21023=210=075
1128=99=18235=X49=SAMPLE75=2017010134=300852=2017010113204311481602160=201701011320431148160215799=10000100268=1279=1269=048=17359555=6SZ683=358587270=10211.0271=27346=111023=510=206
1128=99=25035=X49=SAMPLE75=2017010134=320052=2017010102344599825431260=201701010234459982543125799=10000100268=2279=2269=048=17360055=6SH783=99591270=10269.0271=3346=11023=1279=0269=048=17360055=6SH783=99592270=10259.0271=3346=11023=1010=068
1128=99=18035=X49=SAMPLE75=2017010134=322452=2017010103020418907615860=201701010302041890761585799=10000100268=1279=0269=048=17359555=6SZ683=358588270=10216.0271=1346=11023=110=142
1128=99=17935=X49=SAMPLE75=2017010134=334952=2017010108202368755318060=201701010820236875531805799=10000100268=1279=1269=048=17360055=6SH783=99593270=10268.0271=6346=31023=110=074
1128=99=18235=X49=SAMPLE75=2017010134=104652=2017010112445289545795560=201701011244528954579555799=10000100268=1279=1269=048=17359555=6SZ683=358589270=10211.0271=29346=121023=610=248
1128=99=25335=X49=SAMPLE75=2017010134=124752=2017010101424423094275260=201701010142442309427525799=10000100268=2279=2269=048=17359555=6SZ683=358590270=10216.0271=1346=11023=1279=0269=048=17359555=6SZ683=358591270=10206.0271=43346=81023=1010=040
1128=99=17935=X49=SAMPLE75=2017010134=7552=2017010105572539645476860=201701010557253964547685799=10000100268=1279=1269=048=17360055=6SH783=99594270=10268.0271=5346=21023=110=063
1128=99=18235=X49=SAMPLE75=2017010134=101452=2017010111545973814697160=201701011154597381469715799=10000100268=1279=1269=048=17359555=6SZ683=358592270=10211.0271=27346=111023=510=229
1128=99=18035=X49=SAMPLE75=2017010134=80852=2017010109514194462141260=201701010951419446214125799=10000100268=1279=0269=048=17359555=6SZ683=358593270=10216.0271=1346=11023=110=102
1128=99=17935=X49=SAMPLE75=2017010134=16852=2017010111404014027971860=201701011140401402797185799=10000100268=1279=0269=048=17360055=6SH783=99595270=10269.0271=3346=11023=110=062
1128=99=17935=X49=SAMPLE75=2017010134=332252=2017010114021444680682460=201701011402144468068245799=10000100268=1279=1269=048=17360055=6SH783=99596270=10268.0271=6346=31023=210=053
1128=99=18235=X49=SAMPLE75=2017010134=480052=2017010101034264368029760=201701010103426436802975799=10000100268=1279=1269=048=17359555=6SZ683=358594270=10211.0271=29346=121023=610=208
1128=99=25335=X49=SAMPLE75=2017010134=233452=2017010106010892396081760=201701010601089239608175799=10000100268=2279=2269=048=17359555=6SZ683=358595270=10216.0271=1346=11023=1279=0269=048=17359555=6SZ683=358596270=10206.0271=43346=81023=1010=251
1128=99=17935=X49=SAMPLE75=2017010134=346252=2017010111221041653974560=201701011122104165397455799=10000100268=1279=1269=048=17360055=6SH783=99597270=10268.0271=5346=21023=210=051
1128=99=18235=X49=SAMPLE75=2017010134=193852=2017010112392670969989260=201701011239267096998925799=10000100268=1279=1269=048=17359555=6SZ683=358597270=10211.0271=27346=111023=510=217
1128=99=25035=X49=SAMPLE75=2017010134=163852=2017010101374461083519660=201701010137446108351965799=10000100268=2279=2269=048=17360055=6SH783=99598270=10269.0271=3346=11023=1279=0269=048=17360055=6SH783=99599270=10259.0271=3346=11023=1010=065
1128=99=25435=X49=SAMPLE75=2017010134=434952=2017010113303392820018260=201701011330339282001825799=10000100268=2279=1269=048=17359555=6SZ683=358598270=10212.0271=21346=111023=4279=1269=048=17359555=6SZ683=358599270=10208.0271=32346=91023=810=085
1128=99=25135=X49=SAMPLE75=2017010134=61452=2017010108563944574710260=201701010856394457471025799=10000100268=2279=1269=048=17360055=6SH783=99600270=10263.0271=4346=21023=6279=1269=048=17360055=6SH783=99601270=10259.0271=11346=21023=1010=104
1128=99=18035=X49=SAMPLE75=2017010134=64852=2017010107311673670385960=201701010731167367038595799=10000100268=1279=0269=048=17359555=6SZ683=358600270=10216.0271=1346=11023=110=104
1128=99=17935=X49=SAMPLE75=2017010134=23852=2017010111141734543710060=201701011114173454371005799=10000100268=1279=0269=048=17360055=6SH783=99602270=10269.0271=3346=11023=110=051
1128=99=17935=X49=SAMPLE75=2017010134=328252=2017010106114602752383660=201701010611460275238365799=10000100268=1279=1269=048=17360055=6SH783=99603270=10268.0271=6346=31023=210=064
1128=99=18235=X49=SAMPLE75=2017010134=490152=2017010102184229401240860=201701010218422940124085799=10000100268=1279=1269=048=17359555=6SZ683=358601270=10211.0271=29346=121023=610=211
1128=99=18235=X49=SAMPLE75=2017010134=9452=2017010109210343112334660=201701010921034311233465799=10000100268=1279=1269=048=17359555=6SZ683=358602270=10208.0271=33346=101023=910=226
1128=99=25335=X49=SAMPLE75=2017010134=410352=2017010113590621780003560=201701011359062178000355799=10000100268=2279=2269=048=17359555=6SZ683=358603270=10216.0271=1346=11023=1279=0269=048=17359555=6SZ683=358604270=10206.0271=43346=81023=1010=238
1128=99=17935=X49=SAMPLE75=2017010134=258952=2017010114331571495214460=201701011433157149521445799=10000100268=1279=1269=048=17360055=6SH783=99604270=10268.0271=5346=21023=210=049
1128=99=18235=X49=SAMPLE75=2017010134=96752=2017010100201325928846160=201701010020132592884615799=10000100268=1279=1269=048=17359555=6SZ683=358605270=10211.0271=27346=111023=510=212
1128=99=18235=X49=SAMPLE75=2017010134=139652=2017010107145153409381160=201701010714515340938115799=10000100268=1279=1269=048=17359555=6SZ683=358606270=10215.0271=17346=121023=110=210
1128=99=25135=X49=SAMPLE75=2017010134=49152=2017010103262755909777360=201701010326275590977735799=10000100268=2279=2269=048=17360055=6SH783=99605270=10269.0271=3346=11023=1279=0269=048=17360055=6SH783=99606270=10259.0271=11346=21023=1010=112
1128=99=18235=X49=SAMPLE75=2017010134=176552=2017010107425636881720360=201701010742563688172035799=10000100268=1279=1269=048=17359555=6SZ683=358607270=10215.0271=25346=131023=110=219
1128=99=18235=X49=SAMPLE75=2017010134=381452=2017010106465487996546460=201701010646548799654645799=10000100268=1279=1269=048=17359555=6SZ683=358608270=10215.0271=17346=121023=110=235
1128=99=18235=X49=SAMPLE75=2017010134=425552=2017010106422540965239760=201701010642254096523975799=10000100268=1279=1269=048=17359555=6SZ683=358609270=10215.0271=16346=111023=110=226
1128=99=18235=X49=SAMPLE75=2017010134=486852=2017010106044258804954860=201701010604425880495485799=10000100268=1279=1269=048=17359555=6SZ683=358610270=10215.0271=13346=101023=110=215
1128=99=18135=X49=SAMPLE75=2017010134=21352=2017010113513220513730960=201701011351322051373095799=10000100268=1279=1269=048=17359555=6SZ683=358611270=10215.0271=12346=91023=110=187
1128=99=18135=X49=SAMPLE75=2017010134=118252=2017010113264195455237260=201701011326419545523725799=10000100268=1279=1269=048=17359555=6SZ683=358612270=10207.0271=26346=91023=910=201
1128=99=18135=X49=SAMPLE75=2017010134=339852=2017010106141873615573260=201701010614187361557325799=10000100268=1279=1269=148=17359555=6SZ683=358613270=10217.0271=13346=61023=110=155
1128=99=18135=X49=SAMPLE75=2017010134=330152=2017010100120779699149560=201701010012077969914955799=10000100268=1279=1269=048=17359555=6SZ683=358614270=10215.0271=11346=81023=110=183
1128=99=18035=X49=SAMPLE75=2017010134=210052=2017010114121485180352960=201701011412148518035295799=10000100268=1279=0269=148=17359555=6SZ683=358615270=10216.0271=1346=11023=110=121
1128=99=17935=X49=SAMPLE75=2017010134=71852=2017010103414307652529960=201701010341430765252995799=10000100268=1279=0269=148=17360055=6SH783=99607270=10272.0271=3346=11023=110=064
1128=99=17935=X49=SAMPLE75=2017010134=4552=2017010104243658875086860=201701010424365887508685799=10000100268=1279=0269=148=17360055=6SH783=99608270=10273.0271=3346=11023=210=059
1128=99=17935=X49=SAMPLE75=2017010134=291752=2017010107590006562761060=201701010759000656276105799=10000100268=1279=1269=148=17360055=6SH783=99609270=10272.0271=6346=21023=110=076
1128=99=17935=X49=SAMPLE75=2017010134=176552=2017010109552495683231560=201701010955249568323155799=10000100268=1279=1269=148=17360055=6SH783=99610270=10273.0271=4346=21023=210=058
1128=99=18235=X49=SAMPLE75=2017010134=417452=2017010113340890628079960=201701011334089062807995799=10000100268=1279=1269=148=17359555=6SZ683=358616270=10221.0271=29346=131023=610=250
1128=99=18135=X49=SAMPLE75=2017010134=52052=2017010111265678991406460=201701011126567899140645799=10000100268=1279=1269=048=17359555=6SZ683=358617270=10215.0271=10346=71023=110=168
1128=99=18035=X49=SAMPLE75=2017010134=329652=2017010108161769406804160=201701010816176940680415799=10000100268=1279=1269=148=17360055=6SH783=99611270=10276.0271=37346=31023=510=104
1128=99=18135=X49=SAMPLE75=2017010134=181452=2017010113495591501595160=201701011349559150159515799=10000100268=1279=1269=148=17359555=6SZ683=358618270=10217.0271=14346=71023=210=176
1128=99=18135=X49=SAMPLE75=2017010134=367452=2017010114112058965417060=201701011411205896541705799=10000100268=1279=1269=148=17359555=6SZ683=358619270=10223.0271=23346=71023=810=196
1128=99=18235=X49=SAMPLE75=2017010134=185152=2017010111413394900936460=201701011141339490093645799=10000100268=1279=1269=148=17359555=6SZ683=358620270=10218.0271=19346=101023=310=212
1128=99=18035=X49=SAMPLE75=2017010134=64452=2017010100470629261659060=201701010047062926165905799=10000100268=1279=1269=048=17359555=6SZ683=358621270=10215.0271=9346=61023=110=132
1128=99=18035=X49=SAMPLE75=2017010134=12752=2017010102343155260670160=201701010234315526067015799=10000100268=1279=1269=148=17359555=6SZ683=358622270=10216.0271=2346=21023=110=119
1128=99=18135=X49=SAMPLE75=2017010134=73252=2017010104590195102809360=201701010459019510280935799=10000100268=1279=1269=148=17359555=6SZ683=358623270=10217.0271=16346=81023=210=185
1128=99=18035=X49=SAMPLE75=2017010134=332952=2017010105480833927200060=201701010548083392720005799=10000100268=1279=1269=148=17359555=6SZ683=358624270=10216.0271=3346=31023=110=103
1128=99=17935=X49=SAMPLE75=2017010134=28052=2017010106174311072271460=201701010617431107227145799=10000100268=1279=1269=148=17360055=6SH783=99612270=10272.0271=3346=11023=110=038
1128=99=18035=X49=SAMPLE75=2017010134=487652=2017010104534767327552460=201701010453476732755245799=10000100268=1279=1269=048=17359555=6SZ683=358625270=10215.0271=7346=51023=110=136
1128=99=18235=X49=SAMPLE75=2017010134=101452=2017010111223345413465460=201701011122334541346545799=10000100268=1279=1269=048=17359555=6SZ683=358626270=10213.0271=21346=111023=310=198
1128=99=18035=X49=SAMPLE75=2017010134=226852=2017010105563289416877960=201701010556328941687795799=10000100268=1279=1269=148=17359555=6SZ683=358627270=10216.0271=4346=41023=110=127
1128=99=18035=X49=SAMPLE75=2017010134=344652=2017010102543202793450060=201701010254320279345005799=10000100268=1279=1269=148=17359555=6SZ683=358628270=10216.0271=5346=51023=110=145
1128=99=18135=X49=SAMPLE75=2017010134=27952=2017010104510785661086860=201701010451078566108685799=10000100268=1279=1269=148=17359555=6SZ683=358629270=10219.0271=18346=91023=410=187
1128=99=25035=X49=SAMPLE75=2017010134=303052=2017010107034254758919060=201701010703425475891905799=10000100268=2279=2269=148=17360055=6SH783=99613270=10272.0271=3346=11023=1279=0269=148=17360055=6SH783=99614270=10282.0271=3346=11023=1010=052
1128=99=18235=X49=SAMPLE75=2017010134=276452=2017010104492991300520660=201701010449299130052065799=10000100268=1279=1269=148=17359555=6SZ683=358630270=10220.0271=28346=111023=510=198
1128=99=18035=X49=SAMPLE75=2017010134=68752=2017010111305262316627660=201701011130526231662765799=10000100268=1279=1269=148=17359555=6SZ683=358631270=10216.0271=4346=41023=110=132
1128=99=25435=X49=SAMPLE75=2017010134=168052=2017010108363532645176960=201701010836353264517695799=10000100268=2279=1269=148=17359555=6SZ683=358632270=10220.0271=36346=121023=5279=1269=148=17359555=6SZ683=358633270=10224.0271=38346=51023=910=075
1128=99=18035=X49=SAMPLE75=2017010134=410552=2017010110200630121246560=201701011020063012124655799=10000100268=1279=1269=148=17360055=6SH783=99615270=10279.0271=11346=21023=710=105
1128=99=18135=X49=SAMPLE75=2017010134=226352=2017010110182157188902460=201701011018215718890245799=10000100268=1279=1269=148=17359555=6SZ683=358634270=10217.0271=17346=91023=210=197
1128=99=18135=X49=SAMPLE75=2017010134=268152=2017010100363156369247260=201701010036315636924725799=10000100268=1279=1269=048=17359555=6SZ683=358635270=10207.0271=25346=81023=910=187
1128=99=18235=X49=SAMPLE75=2017010134=164252=2017010110300828010599360=201701011030082801059935799=10000100268=1279=1269=048=17359555=6SZ683=358636270=10214.0271=22346=121023=210=229
1128=99=18235=X49=SAMPLE75=2017010134=393352=2017010112452407037228060=201701011245240703722805799=10000100268=1279=1269=048=17359555=6SZ683=358637270=10214.0271=19346=111023=210=210
1128=99=18235=X49=SAMPLE75=2017010134=306052=2017010107382577676855660=201701010738257767685565799=10000100268=1279=1269=148=17359555=6SZ683=358638270=10217.0271=19346=101023=210=004
1128=99=18235=X49=SAMPLE75=2017010134=260252=2017010101103495633207260=201701010110349563320725799=10000100268=1279=1269=048=17359555=6SZ683=358639270=10214.0271=20346=121023=210=255
1128=99=18135=X49=SAMPLE75=2017010134=23952=2017010106534361985396960=201701010653436198539695799=10000100268=1279=1269=148=17359555=6SZ683=358640270=10218.0271=18346=91023=310=213
1128=99=18235=X49=SAMPLE75=2017010134=8752=2017010113014708718003860=201701011301470871800385799=10000100268=1279=1269=148=17359555=6SZ683=358641270=10217.0271=20346=111023=210=233
1128=99=18035=X49=SAMPLE75=2017010134=205852=2017010103371092121486660=201701010337109212148665799=10000100268=1279=1269=148=17359555=6SZ683=358642270=10216.0271=3346=31023=110=084
1128=99=18035=X49=SAMPLE75=2017010134=290952=2017010108593814431259260=201701010859381443125925799=10000100268=1279=1269=048=17359555=6SZ683=358643270=10215.0271=8346=61023=110=104
1128=99=18035=X49=SAMPLE75=2017010134=413752=2017010102013454846009160=201701010201345484600915799=10000100268=1279=1269=148=17359555=6SZ683=358644270=10216.0271=2346=21023=110=092
1128=99=18035=X49=SAMPLE75=2017010134=55052=2017010112513760593433760=201701011251376059343375799=10000100268=1279=1269=148=17359555=6SZ683=358645270=10216.0271=1346=11023=110=100
1128=99=25335=X49=SAMPLE75=2017010134=372352=2017010105411250920915260=201701010541125092091525799=10000100268=2279=2269=148=17359555=6SZ683=358646270=10216.0271=1346=11023=1279=0269=148=17359555=6SZ683=358647270=10226.0271=18346=41023=1010=224
1128=99=17935=X49=SAMPLE75=2017010134=57452=2017010111015034691433060=201701011101503469143305799=10000100268=1279=1269=148=17360055=6SH783=99616270=10273.0271=3346=11023=110=019
1128=99=18235=X49=SAMPLE75=2017010134=458352=2017010102193551180069360=201701010219355118006935799=10000100268=1279=1269=148=17359555=6SZ683=358648270=10221.0271=27346=121023=510=197
1128=99=17935=X49=SAMPLE75=2017010134=282152=2017010113193821274212260=201701011319382127421225799=10000100268=1279=1269=148=17360055=6SH783=99617270=10276.0271=4346=21023=410=033
1128=99=18035=X49=SAMPLE75=2017010134=214352=2017010104412624212117560=201701010441262421211755799=10000100268=1279=1269=048=17359555=6SZ683=358649270=10215.0271=9346=71023=110=091
1128=99=18235=X49=SAMPLE75=2017010134=329252=2017010108282791275462560=201701010828279127546255799=10000100268=1279=1269=148=17359555=6SZ683=358650270=10217.0271=19346=101023=110=195
1128=99=18235=X49=SAMPLE75=2017010134=15052=2017010102362387709950060=201701010236238770995005799=10000100268=1279=1269=048=17359555=6SZ683=358651270=10214.0271=23346=131023=210=197
1128=99=25435=X49=SAMPLE75=2017010134=168952=2017010103340669391788460=201701010334066939178845799=10000100268=2279=1269=148=17359555=6SZ683=358652270=10220.0271=28346=111023=4279=1269=148=17359555=6SZ683=358653270=10224.0271=46346=61023=810=045
1128=99=17935=X49=SAMPLE75=2017010134=283552=2017010105543033091253560=201701010554303309125355799=10000100268=1279=1269=148=17360055=6SH783=99618270=10279.0271=3346=11023=710=043
1128=99=18135=X49=SAMPLE75=2017010134=124652=2017010102201046266257560=201701010220104626625755799=10000100268=1279=1269=148=17359555=6SZ683=358654270=10217.0271=11346=91023=110=178
1128=99=18135=X49=SAMPLE75=2017010134=98652=2017010102310841062316760=201701010231084106231675799=10000100268=1279=1269=148=17359555=6SZ683=358655270=10219.0271=17346=81023=310=154
1128=99=18135=X49=SAMPLE75=2017010134=438952=2017010108184411460022160=201701010818441146002215799=10000100268=1279=1269=148=17359555=6SZ683=358656270=10217.0271=10346=81023=110=151
1128=99=18035=X49=SAMPLE75=2017010134=379452=2017010104223806067218660=201701010422380606721865799=10000100268=1279=1269=148=17359555=6SZ683=358657270=10217.0271=8346=71023=110=089
1128=99=18135=X49=SAMPLE75=2017010134=164452=2017010105251575982704760=201701010525157598270475799=10000100268=1279=1269=148=17359555=6SZ683=358658270=10218.0271=16346=81023=210=160
1128=99=18135=X49=SAMPLE75=2017010134=311552=2017010106574274807350660=201701010657427480735065799=10000100268=1279=1269=048=17359555=6SZ683=358659270=10215.0271=10346=81023=110=156
1128=99=18235=X49=SAMPLE75=2017010134=495152=2017010100401033834010360=201701010040103383401035799=10000100268=1279=1269=048=17359555=6SZ683=358660270=10214.0271=22346=121023=210=197
1128=99=18135=X49=SAMPLE75=2017010134=469452=2017010105380503349087960=201701010538050334908795799=10000100268=1279=1269=048=17359555=6SZ683=358661270=10207.0271=26346=91023=910=171
1128=99=18135=X49=SAMPLE75=2017010134=398252=2017010101233001424980060=201701010123300142498005799=10000100268=1279=1269=148=17359555=6SZ683=358662270=10218.0271=15346=71023=210=179
1128=99=18135=X49=SAMPLE75=2017010134=379852=2017010113540229449019760=201701011354022944901975799=10000100268=1279=1269=148=17359555=6SZ683=358663270=10223.0271=24346=81023=710=172
1128=99=18135=X49=SAMPLE75=2017010134=348852=2017010114210542389717860=201701011421054238971785799=10000100268=1279=1269=048=17359555=6SZ683=358664270=10215.0271=12346=91023=110=146
1128=99=18235=X49=SAMPLE75=2017010134=353052=2017010103554954849940460=201701010355495484994045799=10000100268=1279=1269=148=17359555=6SZ683=358665270=10220.0271=21346=101023=410=226
1128=99=18235=X49=SAMPLE75=2017010134=477552=2017010105040863417620660=201701010504086341762065799=10000100268=1279=1269=048=17359555=6SZ683=358666270=10214.0271=21346=111023=210=222
1128=99=18235=X49=SAMPLE75=2017010134=83952=2017010101574349469271560=201701010157434946927155799=10000100268=1279=1269=048=17359555=6SZ683=358667270=10215.0271=13346=101023=110=213
1128=99=18135=X49=SAMPLE75=2017010134=177052=2017010108371109103315460=201701010837110910331545799=10000100268=1279=1269=148=17359555=6SZ683=358668270=10218.0271=17346=81023=210=170
1128=99=18135=X49=SAMPLE75=2017010134=4252=2017010101092608218932260=201701010109260821893225799=10000100268=1279=1269=148=17359555=6SZ683=358669270=10218.0271=15346=71023=210=173
1128=99=18135=X49=SAMPLE75=2017010134=400252=2017010113410648902414160=201701011341064890241415799=10000100268=1279=1269=148=17359555=6SZ683=358670270=10218.0271=16346=81023=210=186
1128=99=18035=X49=SAMPLE75=2017010134=60352=2017010109284569724388660=201701010928456972438865799=10000100268=1279=0269=048=17359555=6SZ683=358671270=10216.0271=1346=11023=110=098
1128=99=17935=X49=SAMPLE75=2017010134=257652=2017010104491266035527160=201701010449126603552715799=10000100268=1279=0269=048=17360055=6SH783=99619270=10269.0271=3346=11023=110=048
1128=99=17935=X49=SAMPLE75=2017010134=169952=2017010112042220609948060=201701011204222060994805799=10000100268=1279=1269=048=17360055=6SH783=99620270=10268.0271=6346=31023=210=050
1128=99=18235=X49=SAMPLE75=2017010134=109652=2017010113172958220361660=201701011317295822036165799=10000100268=1279=1269=048=17359555=6SZ683=358672270=10211.0271=29346=121023=610=227
1128=99=18235=X49=SAMPLE75=2017010134=134352=2017010103330346206962260=201701010333034620696225799=10000100268=1279=1269=048=17359555=6SZ683=358673270=10207.0271=25346=81023=1010=211
1128=99=18235=X49=SAMPLE75=2017010134=374252=2017010104041930395519660=201701010404193039551965799=10000100268=1279=1269=048=17359555=6SZ683=358674270=10214.0271=22346=121023=310=228
1128=99=25335=X49=SAMPLE75=2017010134=78152=2017010106485325549621960=201701010648532554962195799=10000100268=2279=2269=048=17359555=6SZ683=358675270=10216.0271=1346=11023=1279=0269=048=17359555=6SZ683=358676270=10206.0271=43346=81023=1010=025
1128=99=18235=X49=SAMPLE75=2017010134=64852=2017010111000903875843660=201701011100090387584365799=10000100268=1279=1269=048=17359555=6SZ683=358677270=10215.0271=16346=111023=110=212
1128=99=18135=X49=SAMPLE75=2017010134=240252=2017010102313067730114060=201701010231306773011405799=10000100268=1279=1269=148=17359555=6SZ683=358678270=10218.0271=18346=91023=210=185
1128=99=17935=X49=SAMPLE75=2017010134=100552=2017010108200309665254060=201701010820030966525405799=10000100268=1279=1269=048=17360055=6SH783=99621270=10268.0271=5346=21023=210=030
1128=99=18235=X49=SAMPLE75=2017010134=169452=2017010113124407402548160=201701011312440740254815799=10000100268=1279=1269=048=17359555=6SZ683=358679270=10211.0271=27346=111023=510=215
1128=99=25135=X49=SAMPLE75=2017010134=355952=2017010103220402343474360=201701010322040234347435799=10000100268=2279=2269=048=17360055=6SH783=99622270=10269.0271=3346=11023=1279=0269=048=17360055=6SH783=99623270=10259.0271=11346=21023=1010=084
1128=99=18035=X49=SAMPLE75=2017010134=466352=2017010100580058566625060=201701010058005856662505799=10000100268=1279=1269=148=17359555=6SZ683=358680270=10217.0271=6346=61023=110=109
1128=99=18235=X49=SAMPLE75=2017010134=210252=2017010109051281909234060=201701010905128190923405799=10000100268=1279=1269=048=17359555=6SZ683=358681270=10211.0271=28346=121023=510=217
1128=99=18235=X49=SAMPLE75=2017010134=357352=2017010109511586167576060=201701010951158616757605799=10000100268=1279=1269=048=17359555=6SZ683=358682270=10215.0271=24346=121023=110=222
1128=99=18035=X49=SAMPLE75=2017010134=205552=2017010100225319850521260=201701010022531985052125799=10000100268=1279=0269=048=17359555=6SZ683=358683270=10216.0271=1346=11023=110=109
1128=99=17935=X49=SAMPLE75=2017010134=112252=2017010110514357080856260=201701011051435708085625799=10000100268=1279=0269=048=17360055=6SH783=99624270=10269.0271=3346=11023=110=050
1128=99=17935=X49=SAMPLE75=2017010134=427252=2017010100054432936961260=201701010005443293696125799=10000100268=1279=1269=048=17360055=6SH783=99625270=10268.0271=6346=31023=210=057
1128=99=18235=X49=SAMPLE75=2017010134=176952=2017010112223187950649560=201701011222318795064955799=10000100268=1279=1269=048=17359555=6SZ683=358684270=10211.0271=30346=131023=610=227
1128=99=25335=X49=SAMPLE75=2017010134=380152=2017010104171160835177760=201701010417116083517775799=10000100268=2279=2269=048=17359555=6SZ683=358685270=10216.0271=1346=11023=1279=0269=048=17359555=6SZ683=358686270=10206.0271=43346=81023=1010=018
1128=99=17935=X49=SAMPLE75=2017010134=398852=2017010100122109487011860=201701010012210948701185799=10000100268=1279=1269=048=17360055=6SH783=99626270=10268.0271=5346=21023=210=067
1128=99=18235=X49=SAMPLE75=2017010134=387152=2017010101165207496925360=201701010116520749692535799=10000100268=1279=1269=048=17359555=6SZ683=358687270=10211.0271=28346=121023=510=224
1128=99=25135=X49=SAMPLE75=2017010134=449452=2017010109031194712598860=201701010903119471259885799=10000100268=2279=2269=048=17360055=6SH783=99627270=10269.0271=3346=11023=1279=0269=048=17360055=6SH783=99628270=10259.0271=11346=21023=1010=120
1128=99=18135=X49=SAMPLE75=2017010134=223252=2017010101105437394390060=201701010110543739439005799=10000100268=1279=1269=148=17359555=6SZ683=358688270=10220.0271=20346=91023=410=185
1128=99=18035=X49=SAMPLE75=2017010134=289852=2017010110591611914512760=201701011059161191451275799=10000100268=1279=0269=048=17359555=6SZ683=358689270=10216.0271=1346=11023=110=124
1128=99=17935=X49=SAMPLE75=2017010134=203852=2017010114141487029941460=201701011414148702994145799=10000100268=1279=1269=048=17360055=6SH783=99629270=10268.0271=6346=31023=110=080
1128=99=18235=X49=SAMPLE75=2017010134=161852=2017010106574257013485660=201701010657425701348565799=10000100268=1279=1269=048=17359555=6SZ683=358690270=10211.0271=30346=131023=610=230
1128=99=25335=X49=SAMPLE75=2017010134=25052=2017010110555112486981560=201701011055511248698155799=10000100268=2279=2269=048=17359555=6SZ683=358691270=10216.0271=1346=11023=1279=0269=048=17359555=6SZ683=358692270=10206.0271=43346=81023=1010=029
1128=99=17935=X49=SAMPLE75=2017010134=124652=2017010101335133565671260=201701010133513356567125799=10000100268=1279=1269=048=17360055=6SH783=99630270=10268.0271=5346=21023=110=057
1128=99=18235=X49=SAMPLE75=2017010134=488052=2017010105462917168493260=201701010546291716849325799=10000100268=1279=1269=048=17359555=6SZ683=358693270=10211.0271=28346=121023=510=210
1128=99=18035=X49=SAMPLE75=2017010134=452452=2017010100200209661919860=201701010020020966191985799=10000100268=1279=0269=048=17359555=6SZ683=358694270=10216.0271=1346=11023=110=121
1128=99=17935=X49=SAMPLE75=2017010134=185452=2017010100165468342866760=201701010016546834286675799=10000100268=1279=1269=048=17360055=6SH783=99631270=10268.0271=6346=31023=110=063
1128=99=18235=X49=SAMPLE75=2017010134=335652=2017010112212550385238560=201701011221255038523855799=10000100268=1279=1269=048=17359555=6SZ683=358695270=10211.0271=30346=131023=610=234
1128=99=25335=X49=SAMPLE75=2017010134=192752=2017010108092731533533160=201701010809273153353315799=10000100268=2279=2269=048=17359555=6SZ683=358696270=10216.0271=1346=11023=1279=0269=048=17359555=6SZ683=358697270=10206.0271=43346=81023=1010=049
1128=99=17935=X49=SAMPLE75=2017010134=354252=2017010111352079186154860=201701011135207918615485799=10000100268=1279=1269=048=17360055=6SH783=99632270=10268.0271=5346=21023=110=067
1128=99=18235=X49=SAMPLE75=2017010134=97352=2017010113405117459211660=201701011340511745921165799=10000100268=1279=1269=048=17359555=6SZ683=358698270=10211.0271=28346=121023=510=241
1128=99=18035=X49=SAMPLE75=2017010134=154352=2017010114250913331803860=201701011425091333180385799=10000100268=1279=0269=048=17359555=6SZ683=358699270=10216.0271=1346=11023=110=127
1128=99=17935=X49=SAMPLE75=2017010134=154352=2017010108192449337845060=201701010819244933784505799=10000100268=1279=1269=048=17360055=6SH783=99633270=10268.0271=6346=31023=110=041
1128=99=18235=X49=SAMPLE75=2017010134=190252=2017010110210531279053660=201701011021053127905365799=10000100268=1279=1269=048=17359555=6SZ683=358700270=10211.0271=30346=131023=610=203
1128=99=25335=X49=SAMPLE75=2017010134=221152=2017010110510680840074160=201701011051068084007415799=10000100268=2279=2269=048=17359555=6SZ683=358701270=10216.0271=1346=11023=1279=0269=048=17359555=6SZ683=358702270=10206.0271=43346=81023=1010=010
1128=99=17935=X49=SAMPLE75=2017010134=331952=2017010100313808074163960=201701010031380807416395799=10000100268=1279=1269=048=17360055=6SH783=99634270=10268.0271=5346=21023=110=050
1128=99=18235=X49=SAMPLE75=2017010134=447352=2017010106251171067309660=201701010625117106730965799=10000100268=1279=1269=048=17359555=6SZ683=358703270=10211.0271=28346=121023=510=228
1128=99=18235=X49=SAMPLE75=2017010134=14452=2017010106305251131089260=201701010630525113108925799=10000100268=1279=1269=048=17359555=6SZ683=358704270=10211.0271=27346=111023=510=221
1128=99=18035=X49=SAMPLE75=2017010134=339252=2017010100243816502067760=201701010024381650206775799=10000100268=1279=0269=048=17359555=6SZ683=358705270=10216.0271=1346=11023=110=132
1128=99=17935=X49=SAMPLE75=2017010134=14352=2017010113542008964322660=201701011354200896432265799=10000100268=1279=0269=048=17360055=6SH783=99635270=10269.0271=3346=11023=110=046
1128=99=17935=X49=SAMPLE75=2017010134=291552=2017010101512195660668660=201701010151219566066865799=10000100268=1279=1269=048=17360055=6SH783=99636270=10268.0271=6346=31023=210=066
1128=99=18235=X49=SAMPLE75=2017010134=126452=2017010111210834942616260=201701011121083494261625799=10000100268=1279=1269=048=17359555=6SZ683=358706270=10211.0271=29346=121023=610=226
1128=99=25335=X49=SAMPLE75=2017010134=239552=2017010111160171866371960=201701011116017186637195799=10000100268=2279=2269=048=17359555=6SZ683=358707270=10216.0271=1346=11023=1279=0269=048=17359555=6SZ683=358708270=10206.0271=43346=81023=1010=010
1128=99=17935=X49=SAMPLE75=2017010134=205652=2017010102074668292900460=201701010207466829290045799=10000100268=1279=1269=048=17360055=6SH783=99637270=10268.0271=5346=21023=210=068
1128=99=18235=X49=SAMPLE75=2017010134=27952=2017010108350097584767360=201701010835009758476735799=10000100268=1279=1269=048=17359555=6SZ683=358709270=10211.0271=27346=111023=510=238
1128=99=25135=X49=SAMPLE75=2017010134=340852=2017010107095119934568360=201701010709511993456835799=10000100268=2279=2269=048=17360055=6SH783=99638270=10269.0271=3346=11023=1279=0269=048=17360055=6SH783=99639270=10259.0271=11346=21023=1010=147
1128=99=18235=X49=SAMPLE75=2017010134=116452=2017010107220120342995960=201701010722012034299595799=10000100268=1279=1269=048=17359555=6SZ683=358710270=10211.0271=26346=101023=510=229
1128=99=18235=X49=SAMPLE75=2017010134=327652=2017010101471725464794760=201701010147172546479475799=10000100268=1279=1269=048=17359555=6SZ683=358711270=10215.0271=16346=111023=110=196
1128=99=18235=X49=SAMPLE75=2017010134=443152=2017010109063735455925160=201701010906373545592515799=10000100268=1279=1269=048=17359555=6SZ683=358712270=10215.0271=15346=101023=110=249
1128=99=18135=X49=SAMPLE75=2017010134=42952=2017010101463740371451060=201701010146374037145105799=10000100268=1279=1269=048=17359555=6SZ683=358713270=10215.0271=12346=91023=110=139
1128=99=18135=X49=SAMPLE75=2017010134=57252=2017010102445892040441260=201701010244589204044125799=10000100268=1279=1269=148=17359555=6SZ683=358714270=10218.0271=16346=81023=210=152
1128=99=18235=X49=SAMPLE75=2017010134=486352=2017010102540895984302660=201701010254089598430265799=10000100268=1279=1269=048=17359555=6SZ683=358715270=10214.0271=21346=111023=210=197
1128=99=18135=X49=SAMPLE75=2017010134=121552=2017010105483259055027860=201701010548325905502785799=10000100268=1279=1269=048=17359555=6SZ683=358716270=10207.0271=26346=91023=910=165
1128=99=18235=X49=SAMPLE75=2017010134=261352=2017010105434552270497460=201701010543455227049745799=10000100268=1279=1269=048=17359555=6SZ683=358717270=10211.0271=27346=111023=510=206
1128=99=18135=X49=SAMPLE75=2017010134=300852=2017010107185287138212360=201701010718528713821235799=10000100268=1279=1269=048=17359555=6SZ683=358718270=10215.0271=11346=81023=110=183
1128=99=25435=X49=SAMPLE75=2017010134=159952=2017010112024974516349160=201701011202497451634915799=10000100268=2279=1269=048=17359555=6SZ683=358719270=10209.0271=44346=81023=7279=1269=048=17359555=6SZ683=358720270=10208.0271=36346=111023=810=084
1128=99=18035=X49=SAMPLE75=2017010134=233152=2017010105493303887269460=201701010549330388726945799=10000100268=1279=1269=148=17359555=6SZ683=358721270=10217.0271=8346=71023=110=148
1128=99=18135=X49=SAMPLE75=2017010134=385452=2017010110424317672750160=201701011042431767275015799=10000100268=1279=1269=148=17359555=6SZ683=358722270=10218.0271=18346=91023=210=199
1128=99=18135=X49=SAMPLE75=2017010134=222752=2017010108534581753891660=201701010853458175389165799=10000100268=1279=1269=048=17359555=6SZ683=358723270=10215.0271=10346=71023=110=182
1128=99=18035=X49=SAMPLE75=2017010134=324152=2017010101562484260592560=201701010156248426059255799=10000100268=1279=0269=148=17359555=6SZ683=358724270=10216.0271=1346=11023=110=132
1128=99=17935=X49=SAMPLE75=2017010134=317452=2017010109335778869937560=201701010933577886993755799=10000100268=1279=0269=148=17360055=6SH783=99640270=10272.0271=3346=11023=110=072
1128=99=17935=X49=SAMPLE75=2017010134=143752=2017010101473809313643560=201701010147380931364355799=10000100268=1279=1269=148=17360055=6SH783=99641270=10273.0271=4346=21023=210=060
1128=99=18035=X49=SAMPLE75=2017010134=321452=2017010113021102155737660=201701011302110215573765799=10000100268=1279=1269=148=17360055=6SH783=99642270=10276.0271=37346=31023=510=121
1128=99=18235=X49=SAMPLE75=2017010134=196952=2017010114030032169194460=201701011403003216919445799=10000100268=1279=1269=148=17359555=6SZ683=358725270=10221.0271=29346=131023=610=254
1128=99=18035=X49=SAMPLE75=2017010134=227052=2017010111052303958848560=201701011105230395884855799=10000100268=1279=1269=148=17359555=6SZ683=358726270=10216.0271=2346=21023=110=142
1128=99=18035=X49=SAMPLE75=2017010134=284952=2017010101281235263174760=201701010128123526317475799=10000100268=1279=1269=148=17359555=6SZ683=358727270=10216.0271=3346=31023=110=141
1128=99=18035=X49=SAMPLE75=2017010134=496452=2017010104561739956317360=201701010456173995631735799=10000100268=1279=1269=148=17359555=6SZ683=358728270=10217.0271=9346=81023=210=150
1128=99=18035=X49=SAMPLE75=2017010134=65552=2017010113355819198987360=201701011335581919898735799=10000100268=1279=1269=148=17359555=6SZ683=358729270=10216.0271=2346=21023=110=116
1128=99=18035=X49=SAMPLE75=2017010134=7852=2017010104165736724679160=201701010416573672467915799=10000100268=1279=1269=048=17359555=6SZ683=358730270=10215.0271=8346=61023=110=119
1128=99=18135=X49=SAMPLE75=2017010134=253952=2017010104295816748546860=201701010429581674854685799=10000100268=1279=1269=048=17359555=6SZ683=358731270=10207.0271=25346=81023=910=180
1128=99=18235=X49=SAMPLE75=2017010134=308152=2017010104424443839386860=201701010442444383938685799=10000100268=1279=1269=048=17359555=6SZ683=358732270=10214.0271=22346=121023=210=217
1128=99=18135=X49=SAMPLE75=2017010134=98752=2017010100145768523399860=201701010014576852339985799=10000100268=1279=1269=148=17359555=6SZ683=358733270=10223.0271=23346=71023=810=194
1128=99=18235=X49=SAMPLE75=2017010134=484452=2017010105351980984631860=201701010535198098463185799=10000100268=1279=1269=148=17359555=6SZ683=358734270=10218.0271=19346=101023=310=239
1128=99=18035=X49=SAMPLE75=2017010134=398052=2017010112165779020252960=201701011216577902025295799=10000100268=1279=1269=148=17359555=6SZ683=358735270=10216.0271=3346=31023=110=130
1128=99=25535=X49=SAMPLE75=2017010134=198052=2017010101294770070711860=201701010129477007071185799=10000100268=2279=1269=048=17359555=6SZ683=358736270=10214.0271=21346=111023=2279=1269=048=17359555=6SZ683=358737270=10213.0271=22346=121023=310=131
1128=99=25135=X49=SAMPLE75=2017010134=493352=2017010109002207368169060=201701010900220736816905799=10000100268=2279=1269=148=17359555=6SZ683=358738270=10216.0271=4346=41023=1279=1269=148=17359555=6SZ683=358739270=10217.0271=8346=71023=210=181
1128=99=18035=X49=SAMPLE75=2017010134=248952=2017010109204485063457560=201701010920448506345755799=10000100268=1279=1269=048=17359555=6SZ683=358740270=10215.0271=7346=51023=110=156
1128=99=25335=X49=SAMPLE75=2017010134=195752=2017010106510441339632560=201701010651044133963255799=10000100268=2279=1269=148=17359555=6SZ683=358741270=10219.0271=20346=91023=4279=1269=148=17359555=6SZ683=358742270=10220.0271=17346=81023=510=039
1128=99=18135=X49=SAMPLE75=2017010134=330252=2017010101361654315737860=201701010136165431573785799=10000100268=1279=1269=148=17359555=6SZ683=358743270=10220.0271=18346=91023=510=196
1128=99=18035=X49=SAMPLE75=2017010134=315652=2017010113322061573666460=201701011332206157366645799=10000100268=1279=1269=148=17359555=6SZ683=358744270=10216.0271=5346=51023=110=145
1128=99=25035=X49=SAMPLE75=2017010134=466352=2017010109364488925353060=201701010936448892535305799=10000100268=2279=2269=148=17360055=6SH783=99643270=10272.0271=3346=11023=1279=0269=148=17360055=6SH783=99644270=10282.0271=3346=11023=1010=082
1128=99=18135=X49=SAMPLE75=2017010134=480452=2017010100165169366643560=201701010016516936664355799=10000100268=1279=1269=148=17359555=6SZ683=358745270=10217.0271=16346=81023=210=206
1128=99=18035=X49=SAMPLE75=2017010134=101952=2017010110485776906385460=201701011048577690638545799=10000100268=1279=1269=048=17359555=6SZ683=358746270=10215.0271=6346=41023=110=164
1128=99=18035=X49=SAMPLE75=2017010134=423852=2017010108570439069186760=201701010857043906918675799=10000100268=1279=1269=048=17359555=6SZ683=358747270=10215.0271=5346=31023=110=150
1128=99=18035=X49=SAMPLE75=2017010134=82052=2017010108045992486544160=201701010804599248654415799=10000100268=1279=1269=148=17359555=6SZ683=358748270=10216.0271=6346=61023=110=156
1128=99=17935=X49=SAMPLE75=2017010134=400752=2017010112494515389122560=201701011249451538912255799=10000100268=1279=1269=048=17360055=6SH783=99645270=10268.0271=2346=11023=110=069
1128=99=32135=X49=SAMPLE75=2017010134=373352=2017010100184830249845260=201701010018483024984525799=10000100268=3279=2269=048=17360055=6SH783=99646270=10268.0271=2346=11023=1279=1269=048=17360055=6SH783=99647270=10265.0271=6346=31023=3279=0269=048=17360055=6SH783=99648270=10258.0271=53346=21023=1010=132
1128=99=17935=X49=SAMPLE75=2017010134=81052=2017010109164476156337960=201701010916447615633795799=10000100268=1279=0269=148=17360055=6SH783=99649270=10272.0271=3346=11023=110=087
