1128=99=18135=X49=SAMPLE75=2016101134=28252=2007112820250947659897660=200711282025094765989765799=10000100268=1279=1269=148=17359555=6SZ683=354966270=10222.0271=3346=11023=1010=140
1128=99=18235=X49=SAMPLE75=2016101134=166052=2001122309530891308868860=200112230953089130886885799=10000100268=1279=1269=048=17359555=6SZ683=354967270=10202.0271=22346=81023=1010=179
1128=99=18035=X49=SAMPLE75=2016101134=369652=2012091222340997372716860=201209122234099737271685799=10000100268=1279=1269=048=17359555=6SZ683=354968270=10204.0271=4346=21023=810=086
1128=99=18135=X49=SAMPLE75=2016101134=91552=2009032511365739532659260=200903251136573953265925799=10000100268=1279=1269=048=17359555=6SZ683=354969270=10205.0271=51346=81023=710=146
1128=99=18235=X49=SAMPLE75=2016101134=442952=2006032417313668803945660=200603241731366880394565799=10000100268=1279=1269=148=17359555=6SZ683=354970270=10222.0271=33346=21023=1010=204
1128=99=18235=X49=SAMPLE75=2016101134=151652=2003081115310995814216060=200308111531099581421605799=10000100268=1279=1269=048=17359555=6SZ683=354971270=10202.0271=52346=91023=1010=216
1128=99=18135=X49=SAMPLE75=2016101134=329052=2001100303340969855794460=200110030334096985579445799=10000100268=1279=1269=148=17359555=6SZ683=354972270=10222.0271=3346=11023=1010=140
1128=99=18235=X49=SAMPLE75=2016101134=193552=2016082718225774211852860=201608271822577421185285799=10000100268=1279=1269=148=17359555=6SZ683=354973270=10222.0271=33346=21023=1010=180
1128=99=18135=X49=SAMPLE75=2016101134=149152=2005111004470500041644860=200511100447050004164485799=10000100268=1279=1269=148=17359555=6SZ683=354974270=10222.0271=3346=11023=1010=118
1128=99=18135=X49=SAMPLE75=2016101134=77152=2014092816593975147481660=201409281659397514748165799=10000100268=1279=1269=048=17359555=6SZ683=354975270=10205.0271=21346=71023=710=132
1128=99=18235=X49=SAMPLE75=2016101134=145952=2001020121003995288806460=200102012100399528880645799=10000100268=1279=1269=148=17359555=6SZ683=354976270=10222.0271=33346=21023=1010=174
1128=99=18135=X49=SAMPLE75=2016101134=29852=2000072716091350237440860=200007271609135023744085799=10000100268=1279=1269=048=17359555=6SZ683=354977270=10204.0271=34346=31023=810=136
1128=99=18135=X49=SAMPLE75=2016101134=345652=2009050401520820757728060=200905040152082075772805799=10000100268=1279=1269=148=17359555=6SZ683=354978270=10221.0271=51346=71023=910=151
1128=99=18135=X49=SAMPLE75=2016101134=375352=2007092213313411009212860=200709221331341100921285799=10000100268=1279=1269=048=17359555=6SZ683=354979270=10205.0271=51346=81023=710=165
1128=99=18135=X49=SAMPLE75=2016101134=316652=2017031411195423034048060=201703141119542303404805799=10000100268=1279=1269=148=17359555=6SZ683=354980270=10222.0271=3346=11023=1010=139
1128=99=18035=X49=SAMPLE75=2016101134=453752=2016052119490536854144060=201605211949053685414405799=10000100268=1279=1269=048=17359555=6SZ683=354981270=10204.0271=4346=21023=810=097
1128=99=18135=X49=SAMPLE75=2016101134=105252=2011102522382799101804860=201110252238279910180485799=10000100268=1279=1269=148=17359555=6SZ683=354982270=10221.0271=21346=61023=910=146
1128=99=18135=X49=SAMPLE75=2016101134=395252=2015010800412970671315260=201501080041297067131525799=10000100268=1279=1269=148=17359555=6SZ683=354983270=10221.0271=51346=71023=910=132
1128=99=18135=X49=SAMPLE75=2016101134=454152=2012121220482618628409660=201212122048261862840965799=10000100268=1279=1269=148=17359555=6SZ683=354984270=10221.0271=21346=61023=910=156
1128=99=18135=X49=SAMPLE75=2016101134=201352=2012020704182776044652860=201202070418277604465285799=10000100268=1279=1269=148=17359555=6SZ683=354985270=10221.0271=51346=71023=910=163
1128=99=18135=X49=SAMPLE75=2016101134=462652=2004100621342640977590460=200410062134264097759045799=10000100268=1279=1269=148=17359555=6SZ683=354986270=10221.0271=21346=61023=910=158
1128=99=18135=X49=SAMPLE75=2016101134=196052=2002112415513678043456060=200211241551367804345605799=10000100268=1279=1269=048=17359555=6SZ683=354987270=10205.0271=21346=71023=710=161
1128=99=18135=X49=SAMPLE75=2016101134=353352=2010061409545450385638460=201006140954545038563845799=10000100268=1279=1269=048=17359555=6SZ683=354988270=10204.0271=34346=31023=810=152
1128=99=18235=X49=SAMPLE75=2016101134=96252=2013030114182491822924860=201303011418249182292485799=10000100268=1279=1269=148=17359555=6SZ683=354989270=10222.0271=33346=21023=1010=169
1128=99=18135=X49=SAMPLE75=2016101134=490552=2005070510233354315859260=200507051023335431585925799=10000100268=1279=1269=048=17359555=6SZ683=354990270=10205.0271=51346=81023=710=140
1128=99=18035=X49=SAMPLE75=2016101134=33552=2013120411303073538905660=201312041130307353890565799=10000100268=1279=1269=048=17359555=6SZ683=354991270=10204.0271=4346=21023=810=081
1128=99=18135=X49=SAMPLE75=2016101134=288352=2010031700050676803411260=201003170005067680341125799=10000100268=1279=1269=148=17359555=6SZ683=354992270=10222.0271=3346=11023=1010=141
1128=99=18135=X49=SAMPLE75=2016101134=287052=2002060905451425439248060=200206090545142543924805799=10000100268=1279=1269=148=17359555=6SZ683=354993270=10221.0271=51346=71023=910=147
1128=99=18135=X49=SAMPLE75=2016101134=202252=2014011015191421172908860=201401101519142117290885799=10000100268=1279=1269=148=17359555=6SZ683=354994270=10221.0271=21346=61023=910=138
1128=99=18135=X49=SAMPLE75=2016101134=295752=2013091220100135113235260=201309122010013511323525799=10000100268=1279=1269=148=17359555=6SZ683=354995270=10221.0271=51346=71023=910=152
1128=99=18135=X49=SAMPLE75=2016101134=218652=2010112905440221566579260=201011290544022156657925799=10000100268=1279=1269=148=17359555=6SZ683=354996270=10221.0271=21346=61023=910=141
1128=99=18135=X49=SAMPLE75=2016101134=429652=2016051614572781084339260=201605161457278108433925799=10000100268=1279=1269=148=17359555=6SZ683=354997270=10221.0271=51346=71023=910=162
1128=99=18135=X49=SAMPLE75=2016101134=76452=2011072903020067465107260=201107290302006746510725799=10000100268=1279=1269=148=17359555=6SZ683=354998270=10221.0271=21346=61023=910=171
1128=99=18135=X49=SAMPLE75=2016101134=385552=2009053120535736490854460=200905312053573649085445799=10000100268=1279=1269=148=17359555=6SZ683=354999270=10221.0271=51346=71023=910=168
1128=99=18135=X49=SAMPLE75=2016101134=369752=2015073021592487660204860=201507302159248766020485799=10000100268=1279=1269=148=17359555=6SZ683=355000270=10221.0271=21346=61023=910=149
1128=99=18135=X49=SAMPLE75=2016101134=183752=2015091006104588002419260=201509100610458800241925799=10000100268=1279=1269=148=17359555=6SZ683=355001270=10221.0271=51346=71023=910=117
1128=99=18135=X49=SAMPLE75=2016101134=348652=2010063010430304285036860=201006301043030428503685799=10000100268=1279=1269=148=17359555=6SZ683=355002270=10221.0271=21346=61023=910=149
1128=99=18135=X49=SAMPLE75=2016101134=310152=2011100905443277717907260=201110090544327771790725799=10000100268=1279=1269=148=17359555=6SZ683=355003270=10221.0271=51346=71023=910=150
1128=99=18135=X49=SAMPLE75=2016101134=377952=2011040416415971194246460=201104041641597119424645799=10000100268=1279=1269=048=17359555=6SZ683=355004270=10205.0271=21346=71023=710=129
1128=99=18135=X49=SAMPLE75=2016101134=143652=2000041406482332783858860=200004140648233278385885799=10000100268=1279=1269=148=17359555=6SZ683=355005270=10221.0271=21346=61023=910=120
1128=99=18135=X49=SAMPLE75=2016101134=413452=2004042215040820537249660=200404221504082053724965799=10000100268=1279=1269=048=17359555=6SZ683=355006270=10205.0271=51346=81023=710=143
1128=99=18135=X49=SAMPLE75=2016101134=71952=2016090719112034139532860=201609071911203413953285799=10000100268=1279=1269=148=17359555=6SZ683=355007270=10221.0271=51346=71023=910=148
1128=99=18135=X49=SAMPLE75=2016101134=271952=2003042914453225450350460=200304291445322545035045799=10000100268=1279=1269=148=17359555=6SZ683=355008270=10221.0271=21346=61023=910=163
1128=99=18135=X49=SAMPLE75=2016101134=292952=2015021917054358391366460=201502191705435839136645799=10000100268=1279=1269=048=17359555=6SZ683=355009270=10205.0271=21346=71023=710=149
1128=99=18135=X49=SAMPLE75=2016101134=369752=2010020107491200432467260=201002010749120043246725799=10000100268=1279=1269=148=17359555=6SZ683=355010270=10221.0271=51346=71023=910=153
1128=99=18135=X49=SAMPLE75=2016101134=188152=2007081723321322235088060=200708172332132223508805799=10000100268=1279=1269=048=17359555=6SZ683=355011270=10205.0271=51346=81023=710=184
1128=99=18135=X49=SAMPLE75=2016101134=325852=2001030708241129224375260=200103070824112922437525799=10000100268=1279=1269=148=17359555=6SZ683=355012270=10221.0271=21346=61023=910=144
1128=99=18135=X49=SAMPLE75=2016101134=16352=2005120904241132299785660=200512090424113229978565799=10000100268=1279=1269=048=17359555=6SZ683=355013270=10205.0271=21346=71023=710=134
1128=99=18135=X49=SAMPLE75=2016101134=352952=2013092318524638895385660=201309231852463889538565799=10000100268=1279=1269=148=17359555=6SZ683=355014270=10221.0271=51346=71023=910=140
1128=99=18135=X49=SAMPLE75=2016101134=302952=2004081412084382021104060=200408141208438202110405799=10000100268=1279=1269=048=17359555=6SZ683=355015270=10205.0271=51346=81023=710=124
1128=99=18135=X49=SAMPLE75=2016101134=168452=2012070504023546424499260=201207050402354642449925799=10000100268=1279=1269=148=17359555=6SZ683=355016270=10221.0271=21346=61023=910=139
1128=99=18135=X49=SAMPLE75=2016101134=7052=2003071615261524278507260=200307161526152427850725799=10000100268=1279=1269=148=17359555=6SZ683=355017270=10221.0271=51346=71023=910=175
1128=99=18135=X49=SAMPLE75=2016101134=417952=2008100416380361716768060=200810041638036171676805799=10000100268=1279=1269=148=17359555=6SZ683=355018270=10221.0271=21346=61023=910=140
1128=99=18135=X49=SAMPLE75=2016101134=224252=2001122417170046884443260=200112241717004688444325799=10000100268=1279=1269=048=17359555=6SZ683=355019270=10205.0271=21346=71023=710=141
1128=99=18135=X49=SAMPLE75=2016101134=334352=2005062202364470767264060=200506220236447076726405799=10000100268=1279=1269=148=17359555=6SZ683=355020270=10221.0271=51346=71023=910=140
1128=99=18135=X49=SAMPLE75=2016101134=446552=2009073105531938186240060=200907310553193818624005799=10000100268=1279=1269=048=17359555=6SZ683=355021270=10205.0271=51346=81023=710=149
1128=99=18135=X49=SAMPLE75=2016101134=83052=2010090217403375629548860=201009021740337562954885799=10000100268=1279=1269=148=17359555=6SZ683=355022270=10221.0271=21346=61023=910=182
1128=99=18135=X49=SAMPLE75=2016101134=11052=2002011312151491957085660=200201131215149195708565799=10000100268=1279=1269=148=17359555=6SZ683=355023270=10221.0271=51346=71023=910=167
1128=99=18135=X49=SAMPLE75=2016101134=60052=2005101206064183301728060=200510120606418330172805799=10000100268=1279=1269=148=17359555=6SZ683=355024270=10221.0271=21346=61023=910=147
1128=99=18135=X49=SAMPLE75=2016101134=217952=2014102609305306552396860=201410260930530655239685799=10000100268=1279=1269=148=17359555=6SZ683=355025270=10221.0271=51346=71023=910=152
1128=99=18135=X49=SAMPLE75=2016101134=38652=2000031303131451903394160=200003130313145190339415799=10000100268=1279=1269=148=17359555=6SZ683=355026270=10221.0271=21346=61023=910=167
1128=99=18135=X49=SAMPLE75=2016101134=410652=2013072822511852245408060=201307282251185224540805799=10000100268=1279=1269=148=17359555=6SZ683=355027270=10221.0271=51346=71023=910=170
1128=99=18135=X49=SAMPLE75=2016101134=300752=2009091500514863951494460=200909150051486395149445799=10000100268=1279=1269=148=17359555=6SZ683=355028270=10221.0271=21346=61023=910=159
1128=99=18135=X49=SAMPLE75=2016101134=454252=2006082105330236521612860=200608210533023652161285799=10000100268=1279=1269=148=17359555=6SZ683=355029270=10221.0271=51346=71023=910=151
1128=99=18135=X49=SAMPLE75=2016101134=487952=2014091617530721107814460=201409161753072110781445799=10000100268=1279=1269=148=17359555=6SZ683=355030270=10221.0271=21346=61023=910=146
1128=99=18135=X49=SAMPLE75=2016101134=329252=2013102820421255608761660=201310282042125560876165799=10000100268=1279=1269=148=17359555=6SZ683=355031270=10221.0271=51346=71023=910=160
1128=99=18135=X49=SAMPLE75=2016101134=183052=2010042117393557191347260=201004211739355719134725799=10000100268=1279=1269=148=17359555=6SZ683=355032270=10221.0271=21346=61023=910=140
1128=99=18135=X49=SAMPLE75=2016101134=472852=2014060114051909877728060=201406011405190987772805799=10000100268=1279=1269=148=17359555=6SZ683=355033270=10221.0271=51346=71023=910=169
1128=99=18135=X49=SAMPLE75=2016101134=456852=2013120723501694180870460=201312072350169418087045799=10000100268=1279=1269=048=17359555=6SZ683=355034270=10205.0271=21346=71023=710=147
1128=99=18135=X49=SAMPLE75=2016101134=429452=2010112201190821465286460=201011220119082146528645799=10000100268=1279=1269=148=17359555=6SZ683=355035270=10221.0271=21346=61023=910=139
1128=99=18135=X49=SAMPLE75=2016101134=85552=2007020819533542732857660=200702081953354273285765799=10000100268=1279=1269=048=17359555=6SZ683=355036270=10205.0271=51346=81023=710=144
1128=99=18135=X49=SAMPLE75=2016101134=330052=2008040517554764752908860=200804051755476475290885799=10000100268=1279=1269=148=17359555=6SZ683=355037270=10221.0271=51346=71023=910=142
1128=99=18035=X49=SAMPLE75=2016101134=429852=2015071207344164634451260=201507120734416463445125799=10000100268=1279=1269=048=17359555=6SZ683=355038270=10206.0271=4346=21023=610=074
1128=99=18135=X49=SAMPLE75=2016101134=97452=2012061104495832100070460=201206110449583210007045799=10000100268=1279=1269=048=17359555=6SZ683=355039270=10207.0271=45346=81023=510=149
1128=99=18135=X49=SAMPLE75=2016101134=119152=2006103117502972528236860=200610311750297252823685799=10000100268=1279=1269=148=17359555=6SZ683=355040270=10221.0271=21346=61023=910=125
1128=99=18135=X49=SAMPLE75=2016101134=427152=2006061211253645231433660=200606121125364523143365799=10000100268=1279=1269=148=17359555=6SZ683=355041270=10221.0271=51346=71023=910=161
1128=99=18135=X49=SAMPLE75=2016101134=194352=2012121002500348086611260=201212100250034808661125799=10000100268=1279=1269=148=17359555=6SZ683=355042270=10221.0271=21346=61023=910=163
1128=99=18135=X49=SAMPLE75=2016101134=492252=2007081215200995507046460=200708121520099550704645799=10000100268=1279=1269=148=17359555=6SZ683=355043270=10221.0271=51346=71023=910=150
1128=99=18135=X49=SAMPLE75=2016101134=94852=2002110819444039329099260=200211081944403932909925799=10000100268=1279=1269=148=17359555=6SZ683=355044270=10221.0271=21346=61023=910=156
1128=99=18135=X49=SAMPLE75=2016101134=386952=2002012918500153874764860=200201291850015387476485799=10000100268=1279=1269=148=17359555=6SZ683=355045270=10221.0271=51346=71023=910=162
1128=99=18135=X49=SAMPLE75=2016101134=89452=2007120403310939391078460=200712040331093939107845799=10000100268=1279=1269=148=17359555=6SZ683=355046270=10221.0271=21346=61023=910=148
1128=99=18135=X49=SAMPLE75=2016101134=378152=2013022219415014273676860=201302221941501427367685799=10000100268=1279=1269=148=17359555=6SZ683=355047270=10221.0271=51346=71023=910=160
1128=99=18135=X49=SAMPLE75=2016101134=493252=2016041118534675276288060=201604111853467527628805799=10000100268=1279=1269=148=17359555=6SZ683=355048270=10221.0271=21346=61023=910=175
1128=99=18135=X49=SAMPLE75=2016101134=441752=2005111305214048214473660=200511130521404821447365799=10000100268=1279=1269=148=17359555=6SZ683=355049270=10221.0271=51346=71023=910=193
1128=99=18135=X49=SAMPLE75=2016101134=31552=2013040717325825998457660=201304071732582599845765799=10000100268=1279=1269=148=17359555=6SZ683=355050270=10221.0271=21346=61023=910=167
1128=99=18135=X49=SAMPLE75=2016101134=23152=2016111619140407603161660=201611161914040760316165799=10000100268=1279=1269=148=17359555=6SZ683=355051270=10221.0271=51346=71023=910=184
1128=99=18135=X49=SAMPLE75=2016101134=218752=2011062108134360992358460=201106210813436099235845799=10000100268=1279=1269=148=17359555=6SZ683=355052270=10221.0271=21346=61023=910=131
1128=99=18135=X49=SAMPLE75=2016101134=273352=2015021116234171732787260=201502111623417173278725799=10000100268=1279=1269=148=17359555=6SZ683=355053270=10221.0271=51346=71023=910=149
1128=99=18135=X49=SAMPLE75=2016101134=266052=2007102621252677023420860=200710262125267702342085799=10000100268=1279=1269=148=17359555=6SZ683=355054270=10221.0271=21346=61023=910=160
1128=99=18135=X49=SAMPLE75=2016101134=281452=2009101102284908811302460=200910110228490881130245799=10000100268=1279=1269=148=17359555=6SZ683=355055270=10221.0271=51346=71023=910=164
1128=99=18135=X49=SAMPLE75=2016101134=373252=2003081100512376900033660=200308110051237690003365799=10000100268=1279=1269=148=17359555=6SZ683=355056270=10221.0271=21346=61023=910=165
1128=99=18135=X49=SAMPLE75=2016101134=344652=2013062119280645359795260=201306211928064535979525799=10000100268=1279=1269=148=17359555=6SZ683=355057270=10221.0271=51346=71023=910=176
1128=99=18135=X49=SAMPLE75=2016101134=271052=2013082607191677296864060=201308260719167729686405799=10000100268=1279=1269=148=17359555=6SZ683=355058270=10221.0271=21346=61023=910=170
1128=99=18135=X49=SAMPLE75=2016101134=272052=2000071813560075145298660=200007181356007514529865799=10000100268=1279=1269=148=17359555=6SZ683=355059270=10221.0271=51346=71023=910=156
1128=99=18135=X49=SAMPLE75=2016101134=359152=2013071500054300235321660=201307150005430023532165799=10000100268=1279=1269=148=17359555=6SZ683=355060270=10221.0271=21346=61023=910=170
1128=99=18135=X49=SAMPLE75=2016101134=76252=2015112016032848427584060=201511201603284842758405799=10000100268=1279=1269=148=17359555=6SZ683=355061270=10221.0271=51346=71023=910=177
1128=99=18135=X49=SAMPLE75=2016101134=264652=2008011223082313959958460=200801122308231395995845799=10000100268=1279=1269=148=17359555=6SZ683=355062270=10221.0271=21346=61023=910=130
1128=99=18135=X49=SAMPLE75=2016101134=272052=2003020616064233999828860=200302061606423399982885799=10000100268=1279=1269=148=17359555=6SZ683=355063270=10221.0271=51346=71023=910=153
1128=99=18135=X49=SAMPLE75=2016101134=336552=2002092823053625648056060=200209282305362564805605799=10000100268=1279=1269=148=17359555=6SZ683=355064270=10221.0271=21346=61023=910=155
1128=99=18135=X49=SAMPLE75=2016101134=95652=2007031906114839730848060=200703190611483973084805799=10000100268=1279=1269=148=17359555=6SZ683=355065270=10221.0271=51346=71023=910=166
1128=99=18135=X49=SAMPLE75=2016101134=71652=2010121117435134150643260=201012111743513415064325799=10000100268=1279=1269=148=17359555=6SZ683=355066270=10221.0271=21346=61023=910=170
1128=99=18135=X49=SAMPLE75=2016101134=299252=2011011700060409930963260=201101170006040993096325799=10000100268=1279=1269=148=17359555=6SZ683=355067270=10221.0271=51346=71023=910=153
1128=99=18135=X49=SAMPLE75=2016101134=390652=2005042703263926781680060=200504270326392678168005799=10000100268=1279=1269=148=17359555=6SZ683=355068270=10221.0271=21346=61023=910=158
1128=99=18135=X49=SAMPLE75=2016101134=340852=2004031311521561986820860=200403131152156198682085799=10000100268=1279=1269=148=17359555=6SZ683=355069270=10221.0271=51346=71023=910=168
1128=99=18135=X49=SAMPLE75=2016101134=351852=2012030119083061589516860=201203011908306158951685799=10000100268=1279=1269=148=17359555=6SZ683=355070270=10221.0271=21346=61023=910=170
1128=99=18135=X49=SAMPLE75=2016101134=115452=2016062721505787445331260=201606272150578744533125799=10000100268=1279=1269=148=17359555=6SZ683=355071270=10221.0271=51346=71023=910=184
1128=99=18135=X49=SAMPLE75=2016101134=74152=2005092220271574868054460=200509222027157486805445799=10000100268=1279=1269=148=17359555=6SZ683=355072270=10221.0271=21346=61023=910=166
1128=99=18235=X49=SAMPLE75=2016101134=315152=2016071813582697675827260=201607181358269767582725799=10000100268=1279=1269=148=17359555=6SZ683=355073270=10222.0271=33346=21023=1010=221
1128=99=18135=X49=SAMPLE75=2016101134=413652=2013081211245582561043260=201308121124558256104325799=10000100268=1279=1269=148=17359555=6SZ683=355074270=10222.0271=3346=11023=1010=164
1128=99=18235=X49=SAMPLE75=2016101134=382452=2014050219334134458937660=201405021933413445893765799=10000100268=1279=1269=148=17359555=6SZ683=355075270=10222.0271=33346=21023=1010=194
1128=99=18135=X49=SAMPLE75=2016101134=180452=2002092001381025578377660=200209200138102557837765799=10000100268=1279=1269=148=17359555=6SZ683=355076270=10222.0271=3346=11023=1010=167
1128=99=18135=X49=SAMPLE75=2016101134=262752=2015012021253797336556860=201501202125379733655685799=10000100268=1279=1269=148=17359555=6SZ683=355077270=10221.0271=51346=71023=910=151
1128=99=18135=X49=SAMPLE75=2016101134=39352=2005042312405839129596860=200504231240583912959685799=10000100268=1279=1269=148=17359555=6SZ683=355078270=10221.0271=21346=61023=910=165
1128=99=18235=X49=SAMPLE75=2016101134=373452=2004092018224985558185660=200409201822498555818565799=10000100268=1279=1269=148=17359555=6SZ683=355079270=10222.0271=33346=21023=1010=219
1128=99=18135=X49=SAMPLE75=2016101134=390152=2004032819044854439750460=200403281904485443975045799=10000100268=1279=1269=048=17359555=6SZ683=355080270=10206.0271=34346=31023=610=182
1128=99=18135=X49=SAMPLE75=2016101134=292552=2007011105092785921334460=200701110509278592133445799=10000100268=1279=1269=048=17359555=6SZ683=355081270=10205.0271=21346=71023=710=167
1128=99=18135=X49=SAMPLE75=2016101134=13952=2003052423303879963772860=200305242330387996377285799=10000100268=1279=1269=148=17359555=6SZ683=355082270=10221.0271=51346=71023=910=169
1128=99=18135=X49=SAMPLE75=2016101134=169452=2015080402400954894406460=201508040240095489440645799=10000100268=1279=1269=148=17359555=6SZ683=355083270=10222.0271=3346=11023=1010=166
1128=99=18135=X49=SAMPLE75=2016101134=288752=2011072912391616084556860=201107291239161608455685799=10000100268=1279=1269=148=17359555=6SZ683=355084270=10221.0271=21346=61023=910=161
1128=99=18235=X49=SAMPLE75=2016101134=158352=2016121721221397068896060=201612172122139706889605799=10000100268=1279=1269=148=17359555=6SZ683=355085270=10222.0271=33346=21023=1010=201
1128=99=18135=X49=SAMPLE75=2016101134=109152=2007012013012838318176060=200701201301283831817605799=10000100268=1279=1269=148=17359555=6SZ683=355086270=10222.0271=3346=11023=1010=166
1128=99=18135=X49=SAMPLE75=2016101134=404352=2012040508355080955398460=201204050835508095539845799=10000100268=1279=1269=148=17359555=6SZ683=355087270=10221.0271=51346=71023=910=196
1128=99=18035=X49=SAMPLE75=2016101134=200152=2000061216184114233671260=200006121618411423367125799=10000100268=1279=1269=048=17359555=6SZ683=355088270=10206.0271=4346=21023=610=103
1128=99=18135=X49=SAMPLE75=2016101134=92552=2004082511025130958816060=200408251102513095881605799=10000100268=1279=1269=148=17359555=6SZ683=355089270=10221.0271=21346=61023=910=166
1128=99=18135=X49=SAMPLE75=2016101134=46152=2011110702354716884512060=201111070235471688451205799=10000100268=1279=1269=048=17359555=6SZ683=355090270=10206.0271=34346=31023=610=161
1128=99=18135=X49=SAMPLE75=2016101134=1852=2010021007105665577600060=201002100710566557760005799=10000100268=1279=1269=148=17359555=6SZ683=355091270=10221.0271=51346=71023=910=174
1128=99=18135=X49=SAMPLE75=2016101134=476952=2006110719204105598188860=200611071920410559818885799=10000100268=1279=1269=148=17359555=6SZ683=355092270=10221.0271=21346=61023=910=140
1128=99=18135=X49=SAMPLE75=2016101134=310352=2013012116165678006208060=201301211616567800620805799=10000100268=1279=1269=148=17359555=6SZ683=355093270=10221.0271=51346=71023=910=143
1128=99=18135=X49=SAMPLE75=2016101134=143252=2000102520355726094393260=200010252035572609439325799=10000100268=1279=1269=148=17359555=6SZ683=355094270=10221.0271=21346=61023=910=159
1128=99=18035=X49=SAMPLE75=2016101134=58152=2016050510590835164416060=201605051059083516441605799=10000100268=1279=1269=048=17359555=6SZ683=355095270=10206.0271=4346=21023=610=122
1128=99=18135=X49=SAMPLE75=2016101134=245752=2004011803463695268592060=200401180346369526859205799=10000100268=1279=1269=148=17359555=6SZ683=355096270=10221.0271=51346=71023=910=181
1128=99=18135=X49=SAMPLE75=2016101134=479152=2011111810334880764076860=201111181033488076407685799=10000100268=1279=1269=048=17359555=6SZ683=355097270=10206.0271=34346=31023=610=164
1128=99=18135=X49=SAMPLE75=2016101134=86652=2009072213010888381113660=200907221301088838111365799=10000100268=1279=1269=148=17359555=6SZ683=355098270=10221.0271=21346=61023=910=149
1128=99=18035=X49=SAMPLE75=2016101134=272352=2001031516484205485966460=200103151648420548596645799=10000100268=1279=1269=048=17359555=6SZ683=355099270=10206.0271=4346=21023=610=114
1128=99=18135=X49=SAMPLE75=2016101134=38852=2001040423310768306564860=200104042331076830656485799=10000100268=1279=1269=148=17359555=6SZ683=355100270=10221.0271=51346=71023=910=135
1128=99=18135=X49=SAMPLE75=2016101134=424352=2015050102292110080371260=201505010229211008037125799=10000100268=1279=1269=048=17359555=6SZ683=355101270=10206.0271=34346=31023=610=149
1128=99=18035=X49=SAMPLE75=2016101134=490552=2004041021591327083462460=200404102159132708346245799=10000100268=1279=1269=048=17359555=6SZ683=355102270=10206.0271=4346=21023=610=087
1128=99=18135=X49=SAMPLE75=2016101134=419052=2013061420150221664665660=201306142015022166466565799=10000100268=1279=1269=048=17359555=6SZ683=355103270=10206.0271=34346=31023=610=156
1128=99=18135=X49=SAMPLE75=2016101134=169452=2001122817091491957627260=200112281709149195762725799=10000100268=1279=1269=148=17359555=6SZ683=355104270=10221.0271=21346=61023=910=125
1128=99=18035=X49=SAMPLE75=2016101134=60952=2006121314591133612064060=200612131459113361206405799=10000100268=1279=1269=048=17359555=6SZ683=355105270=10206.0271=4346=21023=610=110
1128=99=18135=X49=SAMPLE75=2016101134=234752=2009120116055687472876860=200912011605568747287685799=10000100268=1279=1269=148=17359555=6SZ683=355106270=10221.0271=51346=71023=910=146
1128=99=18135=X49=SAMPLE75=2016101134=52852=2012100117420141851846460=201210011742014185184645799=10000100268=1279=1269=048=17359555=6SZ683=355107270=10206.0271=34346=31023=610=159
1128=99=18035=X49=SAMPLE75=2016101134=112152=2012071610042745239942460=201207161004274523994245799=10000100268=1279=1269=048=17359555=6SZ683=355108270=10206.0271=4346=21023=610=082
1128=99=18135=X49=SAMPLE75=2016101134=104052=2004041911273603054947260=200404191127360305494725799=10000100268=1279=1269=148=17359555=6SZ683=355109270=10221.0271=21346=61023=910=140
1128=99=18135=X49=SAMPLE75=2016101134=186552=2010102613455823517088060=201010261345582351708805799=10000100268=1279=1269=048=17359555=6SZ683=355110270=10206.0271=34346=31023=610=122
1128=99=18135=X49=SAMPLE75=2016101134=239352=2002031404295794097640060=200203140429579409764005799=10000100268=1279=1269=148=17359555=6SZ683=355111270=10221.0271=51346=71023=910=113
1128=99=18135=X49=SAMPLE75=2016101134=23752=2010050518565141553728060=201005051856514155372805799=10000100268=1279=1269=148=17359555=6SZ683=355112270=10221.0271=21346=61023=910=125
1128=99=18135=X49=SAMPLE75=2016101134=498352=2010120613061528041721660=201012061306152804172165799=10000100268=1279=1269=148=17359555=6SZ683=355113270=10220.0271=34346=31023=810=125
1128=99=18035=X49=SAMPLE75=2016101134=394252=2009010915230401096307260=200901091523040109630725799=10000100268=1279=1269=148=17359555=6SZ683=355114270=10220.0271=4346=21023=810=092
1128=99=18035=X49=SAMPLE75=2016101134=169052=2006011123395640811782460=200601112339564081178245799=10000100268=1279=1269=048=17359555=6SZ683=355115270=10206.0271=4346=21023=610=112
1128=99=18135=X49=SAMPLE75=2016101134=19852=2000041710511874515415460=200004171051187451541545799=10000100268=1279=1269=148=17359555=6SZ683=355116270=10220.0271=34346=31023=810=156
1128=99=18135=X49=SAMPLE75=2016101134=193652=2005020505051555453948860=200502050505155545394885799=10000100268=1279=1269=048=17359555=6SZ683=355117270=10206.0271=34346=31023=610=145
1128=99=18035=X49=SAMPLE75=2016101134=375152=2004072102124999050100860=200407210212499905010085799=10000100268=1279=1269=148=17359555=6SZ683=355118270=10220.0271=4346=21023=810=079
1128=99=18135=X49=SAMPLE75=2016101134=323652=2003090816295871004923260=200309081629587100492325799=10000100268=1279=1269=148=17359555=6SZ683=355119270=10220.0271=34346=31023=810=158
1128=99=18035=X49=SAMPLE75=2016101134=91752=2008082719242007494704060=200808271924200749470405799=10000100268=1279=1269=148=17359555=6SZ683=355120270=10220.0271=4346=21023=810=099
1128=99=18135=X49=SAMPLE75=2016101134=293152=2009012703071628750832060=200901270307162875083205799=10000100268=1279=1269=148=17359555=6SZ683=355121270=10220.0271=34346=31023=810=138
1128=99=18035=X49=SAMPLE75=2016101134=178952=2016020916575153772601660=201602091657515377260165799=10000100268=1279=1269=048=17359555=6SZ683=355122270=10206.0271=4346=21023=610=083
1128=99=18035=X49=SAMPLE75=2016101134=108252=2005120615130690063337660=200512061513069006333765799=10000100268=1279=1269=148=17359555=6SZ683=355123270=10220.0271=4346=21023=810=086
1128=99=18135=X49=SAMPLE75=2016101134=43352=2013080515285059059724860=201308051528505905972485799=10000100268=1279=1269=048=17359555=6SZ683=355124270=10206.0271=34346=31023=610=152
1128=99=18135=X49=SAMPLE75=2016101134=228552=2004120517103178059590460=200412051710317805959045799=10000100268=1279=1269=148=17359555=6SZ683=355125270=10220.0271=34346=31023=810=122
1128=99=18035=X49=SAMPLE75=2016101134=182352=2007121700130718706768060=200712170013071870676805799=10000100268=1279=1269=148=17359555=6SZ683=355126270=10220.0271=4346=21023=810=096
1128=99=18135=X49=SAMPLE75=2016101134=145852=2015081405051359766579260=201508140505135976657925799=10000100268=1279=1269=148=17359555=6SZ683=355127270=10220.0271=34346=31023=810=169
1128=99=18035=X49=SAMPLE75=2016101134=382652=2004050406153708525132860=200405040615370852513285799=10000100268=1279=1269=148=17359555=6SZ683=355128270=10220.0271=4346=21023=810=080
1128=99=18135=X49=SAMPLE75=2016101134=312452=2014041906454600534393660=201404190645460053439365799=10000100268=1279=1269=148=17359555=6SZ683=355129270=10221.0271=51346=71023=910=156
1128=99=18135=X49=SAMPLE75=2016101134=19752=2005052320141477045264060=200505232014147704526405799=10000100268=1279=1269=148=17359555=6SZ683=355130270=10221.0271=21346=61023=910=144
1128=99=18035=X49=SAMPLE75=2016101134=469852=2010040806481934264115260=201004080648193426411525799=10000100268=1279=1269=048=17359555=6SZ683=355131270=10206.0271=4346=21023=610=099
1128=99=18135=X49=SAMPLE75=2016101134=388352=2013072101290595561900860=201307210129059556190085799=10000100268=1279=1269=148=17359555=6SZ683=355132270=10220.0271=34346=31023=810=116
1128=99=18135=X49=SAMPLE75=2016101134=428852=2004052119123310638508860=200405211912331063850885799=10000100268=1279=1269=048=17359555=6SZ683=355133270=10206.0271=34346=31023=610=142
1128=99=18035=X49=SAMPLE75=2016101134=441752=2014051421414112430624060=201405142141411243062405799=10000100268=1279=1269=148=17359555=6SZ683=355134270=10220.0271=4346=21023=810=092
1128=99=18035=X49=SAMPLE75=2016101134=190752=2007033016343757516624060=200703301634375751662405799=10000100268=1279=1269=048=17359555=6SZ683=355135270=10206.0271=4346=21023=610=073
1128=99=18135=X49=SAMPLE75=2016101134=376552=2009052101290645321779260=200905210129064532177925799=10000100268=1279=1269=148=17359555=6SZ683=355136270=10220.0271=34346=31023=810=160
1128=99=18135=X49=SAMPLE75=2016101134=243952=2013050417025798011379260=201305041702579801137925799=10000100268=1279=1269=048=17359555=6SZ683=355137270=10206.0271=34346=31023=610=161
1128=99=18035=X49=SAMPLE75=2016101134=141752=2008101820074790896067260=200810182007479089606725799=10000100268=1279=1269=148=17359555=6SZ683=355138270=10220.0271=4346=21023=810=104
1128=99=18135=X49=SAMPLE75=2016101134=421652=2003051319584321234497660=200305131958432123449765799=10000100268=1279=1269=148=17359555=6SZ683=355139270=10220.0271=34346=31023=810=142
1128=99=18035=X49=SAMPLE75=2016101134=384452=2014110700175147792524860=201411070017514779252485799=10000100268=1279=1269=148=17359555=6SZ683=355140270=10220.0271=4346=21023=810=080
1128=99=18035=X49=SAMPLE75=2016101134=288752=2015112001434663745587260=201511200143466374558725799=10000100268=1279=1269=048=17359555=6SZ683=355141270=10206.0271=4346=21023=610=085
1128=99=18135=X49=SAMPLE75=2016101134=165852=2004041008271182695201660=200404100827118269520165799=10000100268=1279=1269=148=17359555=6SZ683=355142270=10221.0271=51346=71023=910=137
1128=99=18135=X49=SAMPLE75=2016101134=149152=2006081403310907255168060=200608140331090725516805799=10000100268=1279=1269=048=17359555=6SZ683=355143270=10206.0271=34346=31023=610=156
1128=99=18135=X49=SAMPLE75=2016101134=300152=2004111504151355383337660=200411150415135538333765799=10000100268=1279=1269=148=17359555=6SZ683=355144270=10221.0271=21346=61023=910=159
1128=99=18135=X49=SAMPLE75=2016101134=207952=2009031606115905664774460=200903160611590566477445799=10000100268=1279=1269=148=17359555=6SZ683=355145270=10221.0271=51346=71023=910=170
1128=99=18135=X49=SAMPLE75=2016101134=194152=2014092320043372603129660=201409232004337260312965799=10000100268=1279=1269=148=17359555=6SZ683=355146270=10221.0271=21346=61023=910=155
1128=99=18135=X49=SAMPLE75=2016101134=209752=2007012607403763381004860=200701260740376338100485799=10000100268=1279=1269=148=17359555=6SZ683=355147270=10221.0271=51346=71023=910=160
1128=99=18135=X49=SAMPLE75=2016101134=385652=2005011416203740632358460=200501141620374063235845799=10000100268=1279=1269=148=17359555=6SZ683=355148270=10221.0271=21346=61023=910=147
1128=99=18135=X49=SAMPLE75=2016101134=497352=2004082703434452742416060=200408270343445274241605799=10000100268=1279=1269=148=17359555=6SZ683=355149270=10221.0271=51346=71023=910=144
1128=99=18035=X49=SAMPLE75=2016101134=237952=2014073022310535025363260=201407302231053502536325799=10000100268=1279=1269=048=17359555=6SZ683=355150270=10206.0271=4346=21023=610=075
1128=99=18135=X49=SAMPLE75=2016101134=125152=2007022723522905899654460=200702272352290589965445799=10000100268=1279=1269=148=17359555=6SZ683=355151270=10221.0271=21346=61023=910=139
1128=99=18135=X49=SAMPLE75=2016101134=302152=2013080519493526552896060=201308051949352655289605799=10000100268=1279=1269=048=17359555=6SZ683=355152270=10206.0271=34346=31023=610=175
1128=99=18135=X49=SAMPLE75=2016101134=288752=2006112923132507541836860=200611292313250754183685799=10000100268=1279=1269=148=17359555=6SZ683=355153270=10221.0271=51346=71023=910=185
1128=99=18135=X49=SAMPLE75=2016101134=24252=2001112022535150159981660=200111202253515015998165799=10000100268=1279=1269=148=17359555=6SZ683=355154270=10221.0271=21346=61023=910=150
1128=99=18135=X49=SAMPLE75=2016101134=321452=2000111006001375184428460=200011100600137518442845799=10000100268=1279=1269=148=17359555=6SZ683=355155270=10220.0271=34346=31023=810=162
1128=99=18035=X49=SAMPLE75=2016101134=211052=2007111416254661738832060=200711141625466173883205799=10000100268=1279=1269=148=17359555=6SZ683=355156270=10220.0271=4346=21023=810=128
1128=99=18035=X49=SAMPLE75=2016101134=441752=2010042623322873586137660=201004262332287358613765799=10000100268=1279=1269=048=17359555=6SZ683=355157270=10206.0271=4346=21023=610=094
1128=99=18135=X49=SAMPLE75=2016101134=425952=2003092621214145929734460=200309262121414592973445799=10000100268=1279=1269=148=17359555=6SZ683=355158270=10220.0271=34346=31023=810=159
1128=99=18135=X49=SAMPLE75=2016101134=477552=2012051922574565646566460=201205192257456564656645799=10000100268=1279=1269=048=17359555=6SZ683=355159270=10206.0271=34346=31023=610=187
1128=99=18035=X49=SAMPLE75=2016101134=15752=2013092309210050152742460=201309230921005015274245799=10000100268=1279=1269=148=17359555=6SZ683=355160270=10220.0271=4346=21023=810=065
1128=99=18035=X49=SAMPLE75=2016101134=107152=2016032822115627588934460=201603282211562758893445799=10000100268=1279=1269=048=17359555=6SZ683=355161270=10206.0271=4346=21023=610=081
1128=99=18135=X49=SAMPLE75=2016101134=18652=2010010213173538928812860=201001021317353892881285799=10000100268=1279=1269=148=17359555=6SZ683=355162270=10220.0271=34346=31023=810=139
1128=99=18135=X49=SAMPLE75=2016101134=498952=2010042416083374679526460=201004241608337467952645799=10000100268=1279=1269=048=17359555=6SZ683=355163270=10206.0271=34346=31023=610=132
1128=99=18035=X49=SAMPLE75=2016101134=101052=2006032907510344732086460=200603290751034473208645799=10000100268=1279=1269=048=17359555=6SZ683=355164270=10206.0271=4346=21023=610=082
1128=99=18035=X49=SAMPLE75=2016101134=291552=2000080914171342415107260=200008091417134241510725799=10000100268=1279=1269=148=17359555=6SZ683=355165270=10220.0271=4346=21023=810=081
1128=99=18135=X49=SAMPLE75=2016101134=162452=2002051313505026893916860=200205131350502689391685799=10000100268=1279=1269=048=17359555=6SZ683=355166270=10206.0271=34346=31023=610=165
1128=99=18135=X49=SAMPLE75=2016101134=353452=2005100314383930113849660=200510031438393011384965799=10000100268=1279=1269=148=17359555=6SZ683=355167270=10220.0271=34346=31023=810=162
1128=99=18035=X49=SAMPLE75=2016101134=246052=2007010111071542249984060=200701011107154224998405799=10000100268=1279=1269=148=17359555=6SZ683=355168270=10220.0271=4346=21023=810=086
1128=99=18035=X49=SAMPLE75=2016101134=186552=2007040223521305168457660=200704022352130516845765799=10000100268=1279=1269=048=17359555=6SZ683=355169270=10206.0271=4346=21023=610=079
1128=99=18135=X49=SAMPLE75=2016101134=430252=2009050209233307190400060=200905020923330719040005799=10000100268=1279=1269=148=17359555=6SZ683=355170270=10220.0271=34346=31023=810=125
1128=99=18135=X49=SAMPLE75=2016101134=404952=2014011712200492364608060=201401171220049236460805799=10000100268=1279=1269=048=17359555=6SZ683=355171270=10206.0271=34346=31023=610=150
1128=99=18035=X49=SAMPLE75=2016101134=96252=2000081523235976086248460=200008152323597608624845799=10000100268=1279=1269=048=17359555=6SZ683=355172270=10206.0271=4346=21023=610=095
1128=99=18135=X49=SAMPLE75=2016101134=435552=2006080923495267008131260=200608092349526700813125799=10000100268=1279=1269=048=17359555=6SZ683=355173270=10206.0271=34346=31023=610=151
1128=99=18035=X49=SAMPLE75=2016101134=361652=2004110419173936914854460=200411041917393691485445799=10000100268=1279=1269=148=17359555=6SZ683=355174270=10220.0271=4346=21023=810=103
1128=99=18135=X49=SAMPLE75=2016101134=176252=2001120723033100287408060=200112072303310028740805799=10000100268=1279=1269=148=17359555=6SZ683=355175270=10221.0271=51346=71023=910=175
1128=99=18035=X49=SAMPLE75=2016101134=344652=2004040105402977631524860=200404010540297763152485799=10000100268=1279=1269=048=17359555=6SZ683=355176270=10206.0271=4346=21023=610=108
1128=99=18135=X49=SAMPLE75=2016101134=294752=2016091510505403338182460=201609151050540333818245799=10000100268=1279=1269=148=17359555=6SZ683=355177270=10221.0271=21346=61023=910=168
1128=99=18135=X49=SAMPLE75=2016101134=321752=2011101504075535021062460=201110150407553502106245799=10000100268=1279=1269=148=17359555=6SZ683=355178270=10220.0271=34346=31023=810=147
1128=99=18135=X49=SAMPLE75=2016101134=284152=2000082410244835167609260=200008241024483516760925799=10000100268=1279=1269=048=17359555=6SZ683=355179270=10206.0271=34346=31023=610=165
1128=99=18035=X49=SAMPLE75=2016101134=87052=2014122723031168423302460=201412272303116842330245799=10000100268=1279=1269=148=17359555=6SZ683=355180270=10220.0271=4346=21023=810=081
1128=99=18035=X49=SAMPLE75=2016101134=165652=2006021117291477670291260=200602111729147767029125799=10000100268=1279=1269=048=17359555=6SZ683=355181270=10206.0271=4346=21023=610=107
1128=99=18135=X49=SAMPLE75=2016101134=496052=2008090210301999879244860=200809021030199987924485799=10000100268=1279=1269=148=17359555=6SZ683=355182270=10221.0271=51346=71023=910=167
1128=99=18135=X49=SAMPLE75=2016101134=138552=2015120504001509168083260=201512050400150916808325799=10000100268=1279=1269=048=17359555=6SZ683=355183270=10206.0271=34346=31023=610=151
1128=99=18135=X49=SAMPLE75=2016101134=183652=2008031121284636145376060=200803112128463614537605799=10000100268=1279=1269=148=17359555=6SZ683=355184270=10221.0271=21346=61023=910=153
1128=99=18135=X49=SAMPLE75=2016101134=68752=2014051623125025885184060=201405162312502588518405799=10000100268=1279=1269=148=17359555=6SZ683=355185270=10220.0271=34346=31023=810=152
1128=99=18035=X49=SAMPLE75=2016101134=249052=2005052308060258165187260=200505230806025816518725799=10000100268=1279=1269=148=17359555=6SZ683=355186270=10220.0271=4346=21023=810=085
1128=99=18135=X49=SAMPLE75=2016101134=331352=2009121904110975315078460=200912190411097531507845799=10000100268=1279=1269=148=17359555=6SZ683=355187270=10221.0271=51346=71023=910=174
1128=99=18035=X49=SAMPLE75=2016101134=352652=2006071514180804927843260=200607151418080492784325799=10000100268=1279=1269=048=17359555=6SZ683=355188270=10206.0271=4346=21023=610=116
1128=99=18135=X49=SAMPLE75=2016101134=394452=2004031902105726381928060=200403190210572638192805799=10000100268=1279=1269=148=17359555=6SZ683=355189270=10221.0271=21346=61023=910=173
1128=99=18135=X49=SAMPLE75=2016101134=423452=2016050914423598754758460=201605091442359875475845799=10000100268=1279=1269=148=17359555=6SZ683=355190270=10220.0271=34346=31023=810=154
1128=99=18135=X49=SAMPLE75=2016101134=248852=2005033113271641159913660=200503311327164115991365799=10000100268=1279=1269=048=17359555=6SZ683=355191270=10206.0271=34346=31023=610=150
1128=99=18035=X49=SAMPLE75=2016101134=453352=2007021614365757241974460=200702161436575724197445799=10000100268=1279=1269=048=17359555=6SZ683=355192270=10206.0271=4346=21023=610=126
1128=99=18135=X49=SAMPLE75=2016101134=54952=2011073020200659118566460=201107302020065911856645799=10000100268=1279=1269=048=17359555=6SZ683=355193270=10206.0271=34346=31023=610=173
1128=99=18035=X49=SAMPLE75=2016101134=460452=2006082923291965169465660=200608292329196516946565799=10000100268=1279=1269=148=17359555=6SZ683=355194270=10220.0271=4346=21023=810=112
1128=99=18135=X49=SAMPLE75=2016101134=400452=2010121723333754053657660=201012172333375405365765799=10000100268=1279=1269=148=17359555=6SZ683=355195270=10220.0271=34346=31023=810=157
1128=99=18035=X49=SAMPLE75=2016101134=209552=2010040316552176990809660=201004031655217699080965799=10000100268=1279=1269=148=17359555=6SZ683=355196270=10220.0271=4346=21023=810=128
1128=99=18135=X49=SAMPLE75=2016101134=7052=2005080715014796891036860=200508071501479689103685799=10000100268=1279=1269=148=17359555=6SZ683=355197270=10220.0271=34346=31023=810=203
1128=99=18035=X49=SAMPLE75=2016101134=323852=2008121205201946755504060=200812120520194675550405799=10000100268=1279=1269=148=17359555=6SZ683=355198270=10220.0271=4346=21023=810=095
1128=99=18135=X49=SAMPLE75=2016101134=182352=2007072822301094772268860=200707282230109477226885799=10000100268=1279=1269=148=17359555=6SZ683=355199270=10220.0271=34346=31023=810=160
1128=99=18035=X49=SAMPLE75=2016101134=209652=2016061314373124168851260=201606131437312416885125799=10000100268=1279=1269=148=17359555=6SZ683=355200270=10220.0271=4346=21023=810=089
1128=99=18035=X49=SAMPLE75=2016101134=244752=2008072702391441574611260=200807270239144157461125799=10000100268=1279=1269=048=17359555=6SZ683=355201270=10206.0271=4346=21023=610=080
1128=99=18135=X49=SAMPLE75=2016101134=330052=2005082200262251877849660=200508220026225187784965799=10000100268=1279=1269=148=17359555=6SZ683=355202270=10220.0271=34346=31023=810=152
1128=99=18135=X49=SAMPLE75=2016101134=442752=2013112616563852776755260=201311261656385277675525799=10000100268=1279=1269=048=17359555=6SZ683=355203270=10206.0271=34346=31023=610=146
1128=99=18035=X49=SAMPLE75=2016101134=189252=2012033023410967858272060=201203302341096785827205799=10000100268=1279=1269=148=17359555=6SZ683=355204270=10220.0271=4346=21023=810=090
1128=99=18035=X49=SAMPLE75=2016101134=90452=2005031611350464708873660=200503161135046470887365799=10000100268=1279=1269=048=17359555=6SZ683=355205270=10206.0271=4346=21023=610=085
1128=99=18135=X49=SAMPLE75=2016101134=294352=2007101609311739582675260=200710160931173958267525799=10000100268=1279=1269=148=17359555=6SZ683=355206270=10220.0271=34346=31023=810=146
1128=99=18135=X49=SAMPLE75=2016101134=289752=2005061521412955064608060=200506152141295506460805799=10000100268=1279=1269=048=17359555=6SZ683=355207270=10206.0271=34346=31023=610=174
1128=99=18035=X49=SAMPLE75=2016101134=185352=2005102613411273753676860=200510261341127375367685799=10000100268=1279=1269=148=17359555=6SZ683=355208270=10220.0271=4346=21023=810=101
1128=99=18135=X49=SAMPLE75=2016101134=294952=2016072109434344036480060=201607210943434403648005799=10000100268=1279=1269=148=17359555=6SZ683=355209270=10220.0271=34346=31023=810=168
1128=99=18035=X49=SAMPLE75=2016101134=404052=2006102713265783633625660=200610271326578363362565799=10000100268=1279=1269=048=17359555=6SZ683=355210270=10206.0271=4346=21023=610=089
1128=99=18035=X49=SAMPLE75=2016101134=130352=2012121809345514763308860=201212180934551476330885799=10000100268=1279=1269=148=17359555=6SZ683=355211270=10220.0271=4346=21023=810=107
1128=99=18135=X49=SAMPLE75=2016101134=10352=2014121915442568894240060=201412191544256889424005799=10000100268=1279=1269=048=17359555=6SZ683=355212270=10205.0271=51346=81023=710=140
1128=99=18235=X49=SAMPLE75=2016101134=240652=2000050102525535602482660=200005010252553560248265799=10000100268=1279=1269=048=17359555=6SZ683=355213270=10202.0271=22346=81023=1010=198
1128=99=18235=X49=SAMPLE75=2016101134=410052=2014101300245412910393660=201410130024541291039365799=10000100268=1279=1269=048=17359555=6SZ683=355214270=10202.0271=52346=91023=1010=185
1128=99=18035=X49=SAMPLE75=2016101134=332652=2006080210305935677107260=200608021030593567710725799=10000100268=1279=1269=148=17359555=6SZ683=355215270=10214.0271=9346=71023=210=091
1128=99=18035=X49=SAMPLE75=2016101134=176552=2013061512323903311424060=201306151232390331142405799=10000100268=1279=1269=048=17359555=6SZ683=355216270=10210.0271=5346=31023=210=090
1128=99=18235=X49=SAMPLE75=2016101134=397952=2015033020514540501171260=201503302051454050117125799=10000100268=1279=1269=048=17359555=6SZ683=355217270=10202.0271=22346=81023=1010=175
1128=99=18135=X49=SAMPLE75=2016101134=471252=2011072800460095137708860=201107280046009513770885799=10000100268=1279=1269=148=17359555=6SZ683=355218270=10220.0271=34346=31023=810=167
1128=99=18135=X49=SAMPLE75=2016101134=15852=2011120819301151090086460=201112081930115109008645799=10000100268=1279=1269=048=17359555=6SZ683=355219270=10205.0271=21346=71023=710=174
1128=99=18135=X49=SAMPLE75=2016101134=426152=2009112802245464505760060=200911280224546450576005799=10000100268=1279=1269=048=17359555=6SZ683=355220270=10206.0271=34346=31023=610=157
1128=99=18035=X49=SAMPLE75=2016101134=180452=2004082910073863123478460=200408291007386312347845799=10000100268=1279=1269=148=17359555=6SZ683=355221270=10220.0271=4346=21023=810=087
1128=99=18135=X49=SAMPLE75=2016101134=273552=2017031000395899366752060=201703100039589936675205799=10000100268=1279=1269=148=17359555=6SZ683=355222270=10216.0271=12346=41023=410=137
1128=99=18235=X49=SAMPLE75=2016101134=213852=2015020822435902882336060=201502082243590288233605799=10000100268=1279=1269=048=17359555=6SZ683=355223270=10202.0271=52346=91023=1010=216
1128=99=18135=X49=SAMPLE75=2016101134=285552=2005120709240699040665660=200512070924069904066565799=10000100268=1279=1269=148=17359555=6SZ683=355224270=10220.0271=34346=31023=810=129
1128=99=18135=X49=SAMPLE75=2016101134=59752=2006022810253070423804860=200602281025307042380485799=10000100268=1279=1269=148=17359555=6SZ683=355225270=10216.0271=42346=51023=410=139
1128=99=18035=X49=SAMPLE75=2016101134=106252=2007101416552557991027260=200710141655255799102725799=10000100268=1279=1269=148=17359555=6SZ683=355226270=10220.0271=4346=21023=810=110
1128=99=18135=X49=SAMPLE75=2016101134=485352=2001020703540358505254860=200102070354035850525485799=10000100268=1279=1269=148=17359555=6SZ683=355227270=10220.0271=34346=31023=810=175
1128=99=18035=X49=SAMPLE75=2016101134=417552=2004040709305566995827260=200404070930556699582725799=10000100268=1279=1269=148=17359555=6SZ683=355228270=10220.0271=4346=21023=810=101
1128=99=18135=X49=SAMPLE75=2016101134=140052=2015081022543621777036860=201508102254362177703685799=10000100268=1279=1269=148=17359555=6SZ683=355229270=10220.0271=34346=31023=810=154
1128=99=18035=X49=SAMPLE75=2016101134=117452=2008010609561972328102460=200801060956197232810245799=10000100268=1279=1269=048=17359555=6SZ683=355230270=10206.0271=4346=21023=610=139
1128=99=18035=X49=SAMPLE75=2016101134=43652=2001050113472372419289660=200105011347237241928965799=10000100268=1279=1269=148=17359555=6SZ683=355231270=10220.0271=4346=21023=810=110
1128=99=18135=X49=SAMPLE75=2016101134=94152=2014012422362260479859260=201401242236226047985925799=10000100268=1279=1269=048=17359555=6SZ683=355232270=10206.0271=34346=31023=610=145
1128=99=18135=X49=SAMPLE75=2016101134=268652=2012030903334788622374460=201203090333478862237445799=10000100268=1279=1269=148=17359555=6SZ683=355233270=10220.0271=34346=31023=810=161
1128=99=18035=X49=SAMPLE75=2016101134=48152=2013062720090886397024060=201306272009088639702405799=10000100268=1279=1269=148=17359555=6SZ683=355234270=10220.0271=4346=21023=810=102
1128=99=18135=X49=SAMPLE75=2016101134=119252=2006022214421112858179260=200602221442111285817925799=10000100268=1279=1269=148=17359555=6SZ683=355235270=10220.0271=34346=31023=810=173
1128=99=18035=X49=SAMPLE75=2016101134=58752=2012120500043345053856060=201212050004334505385605799=10000100268=1279=1269=148=17359555=6SZ683=355236270=10220.0271=4346=21023=810=115
1128=99=18035=X49=SAMPLE75=2016101134=86952=2005082820192393060960060=200508282019239306096005799=10000100268=1279=1269=048=17359555=6SZ683=355237270=10206.0271=4346=21023=610=089
1128=99=18135=X49=SAMPLE75=2016101134=413652=2005111411135854554073660=200511141113585455407365799=10000100268=1279=1269=148=17359555=6SZ683=355238270=10221.0271=51346=71023=910=159
1128=99=18135=X49=SAMPLE75=2016101134=456052=2014050906105012666726460=201405090610501266672645799=10000100268=1279=1269=048=17359555=6SZ683=355239270=10206.0271=34346=31023=610=165
1128=99=18135=X49=SAMPLE75=2016101134=126552=2002061203465406434505660=200206120346540643450565799=10000100268=1279=1269=148=17359555=6SZ683=355240270=10221.0271=21346=61023=910=145
1128=99=18135=X49=SAMPLE75=2016101134=262552=2008082911124994636579260=200808291112499463657925799=10000100268=1279=1269=148=17359555=6SZ683=355241270=10220.0271=34346=31023=810=152
1128=99=18035=X49=SAMPLE75=2016101134=396352=2005060319272958269091260=200506031927295826909125799=10000100268=1279=1269=148=17359555=6SZ683=355242270=10220.0271=4346=21023=810=082
1128=99=18035=X49=SAMPLE75=2016101134=293452=2000062103162666735636660=200006210316266673563665799=10000100268=1279=1269=048=17359555=6SZ683=355243270=10206.0271=4346=21023=610=106
1128=99=18135=X49=SAMPLE75=2016101134=344052=2004111904085384876928060=200411190408538487692805799=10000100268=1279=1269=148=17359555=6SZ683=355244270=10220.0271=34346=31023=810=159
1128=99=18135=X49=SAMPLE75=2016101134=222552=2008042504011990895532860=200804250401199089553285799=10000100268=1279=1269=048=17359555=6SZ683=355245270=10206.0271=34346=31023=610=145
1128=99=18035=X49=SAMPLE75=2016101134=298952=2016012123310402951065660=201601212331040295106565799=10000100268=1279=1269=048=17359555=6SZ683=355246270=10206.0271=4346=21023=610=110
1128=99=18035=X49=SAMPLE75=2016101134=460352=2003090220383846058617660=200309022038384605861765799=10000100268=1279=1269=148=17359555=6SZ683=355247270=10220.0271=4346=21023=810=107
1128=99=18135=X49=SAMPLE75=2016101134=33352=2002070904493681135724860=200207090449368113572485799=10000100268=1279=1269=048=17359555=6SZ683=355248270=10206.0271=34346=31023=610=184
1128=99=18135=X49=SAMPLE75=2016101134=310552=2013041314563271714265660=201304131456327171426565799=10000100268=1279=1269=148=17359555=6SZ683=355249270=10220.0271=34346=31023=810=177
1128=99=18035=X49=SAMPLE75=2016101134=1352=2013030504001962153843260=201303050400196215384325799=10000100268=1279=1269=148=17359555=6SZ683=355250270=10220.0271=4346=21023=810=102
1128=99=18135=X49=SAMPLE75=2016101134=247152=2004062008142432207510460=200406200814243220751045799=10000100268=1279=1269=148=17359555=6SZ683=355251270=10221.0271=51346=71023=910=144
1128=99=18135=X49=SAMPLE75=2016101134=398052=2004091011401494678252860=200409101140149467825285799=10000100268=1279=1269=148=17359555=6SZ683=355252270=10221.0271=21346=61023=910=156
1128=99=18035=X49=SAMPLE75=2016101134=103352=2011112021544566755027260=201111202154456675502725799=10000100268=1279=1269=048=17359555=6SZ683=355253270=10206.0271=4346=21023=610=126
1128=99=18135=X49=SAMPLE75=2016101134=2352=2012041903443436886227260=201204190344343688622725799=10000100268=1279=1269=148=17359555=6SZ683=355254270=10220.0271=34346=31023=810=174
1128=99=18135=X49=SAMPLE75=2016101134=3152=2000102806210334619375260=200010280621033461937525799=10000100268=1279=1269=048=17359555=6SZ683=355255270=10206.0271=34346=31023=610=171
1128=99=18035=X49=SAMPLE75=2016101134=412852=2016103110201658550406460=201610311020165855040645799=10000100268=1279=1269=148=17359555=6SZ683=355256270=10220.0271=4346=21023=810=117
1128=99=18135=X49=SAMPLE75=2016101134=215152=2011020718382784297593660=201102071838278429759365799=10000100268=1279=1269=148=17359555=6SZ683=355257270=10221.0271=51346=71023=910=157
1128=99=18135=X49=SAMPLE75=2016101134=285552=2013092900565606524608060=201309290056560652460805799=10000100268=1279=1269=148=17359555=6SZ683=355258270=10221.0271=21346=61023=910=164
1128=99=18135=X49=SAMPLE75=2016101134=407052=2013111905142516737177660=201311190514251673717765799=10000100268=1279=1269=148=17359555=6SZ683=355259270=10221.0271=51346=71023=910=153
1128=99=18135=X49=SAMPLE75=2016101134=274152=2001012217172560072690460=200101221717256007269045799=10000100268=1279=1269=148=17359555=6SZ683=355260270=10221.0271=21346=61023=910=124
1128=99=18035=X49=SAMPLE75=2016101134=50752=2003100105512517478323260=200310010551251747832325799=10000100268=1279=1269=048=17359555=6SZ683=355261270=10206.0271=4346=21023=610=096
1128=99=18135=X49=SAMPLE75=2016101134=487852=2007082516004924206281660=200708251600492420628165799=10000100268=1279=1269=148=17359555=6SZ683=355262270=10221.0271=51346=71023=910=130
1128=99=18135=X49=SAMPLE75=2016101134=349452=2006121412432656917856060=200612141243265691785605799=10000100268=1279=1269=048=17359555=6SZ683=355263270=10206.0271=34346=31023=610=138
1128=99=18135=X49=SAMPLE75=2016101134=215552=2009021304275460106406460=200902130427546010640645799=10000100268=1279=1269=148=17359555=6SZ683=355264270=10221.0271=21346=61023=910=150
1128=99=18035=X49=SAMPLE75=2016101134=212652=2003032519360681087926460=200303251936068108792645799=10000100268=1279=1269=048=17359555=6SZ683=355265270=10206.0271=4346=21023=610=110
1128=99=18135=X49=SAMPLE75=2016101134=261152=2017010107245229718841660=201701010724522971884165799=10000100268=1279=1269=148=17359555=6SZ683=355266270=10220.0271=34346=31023=810=173
1128=99=18135=X49=SAMPLE75=2016101134=192752=2006012823084386443440060=200601282308438644344005799=10000100268=1279=1269=048=17359555=6SZ683=355267270=10206.0271=34346=31023=610=171
1128=99=18035=X49=SAMPLE75=2016101134=248752=2014111023302266106342460=201411102330226610634245799=10000100268=1279=1269=148=17359555=6SZ683=355268270=10220.0271=4346=21023=810=124
1128=99=18135=X49=SAMPLE75=2016101134=212952=2006043009155175310105660=200604300915517531010565799=10000100268=1279=1269=148=17359555=6SZ683=355269270=10221.0271=51346=71023=910=148
1128=99=18135=X49=SAMPLE75=2016101134=354452=2007051921572930047792060=200705192157293004779205799=10000100268=1279=1269=148=17359555=6SZ683=355270270=10221.0271=21346=61023=910=154
1128=99=18135=X49=SAMPLE75=2016101134=157352=2016052911404854546624060=201605291140485454662405799=10000100268=1279=1269=148=17359555=6SZ683=355271270=10221.0271=51346=71023=910=148
1128=99=18135=X49=SAMPLE75=2016101134=171152=2007103006180409389980860=200710300618040938998085799=10000100268=1279=1269=148=17359555=6SZ683=355272270=10221.0271=21346=61023=910=150
1128=99=18135=X49=SAMPLE75=2016101134=461552=2004102921525892173657660=200410292152589217365765799=10000100268=1279=1269=148=17359555=6SZ683=355273270=10221.0271=51346=71023=910=143
1128=99=18135=X49=SAMPLE75=2016101134=380052=2011031807313785462560060=201103180731378546256005799=10000100268=1279=1269=148=17359555=6SZ683=355274270=10221.0271=21346=61023=910=145
1128=99=18135=X49=SAMPLE75=2016101134=34952=2005121800325339161843260=200512180032533916184325799=10000100268=1279=1269=148=17359555=6SZ683=355275270=10221.0271=51346=71023=910=155
1128=99=18135=X49=SAMPLE75=2016101134=454252=2007081522342770240105660=200708152234277024010565799=10000100268=1279=1269=148=17359555=6SZ683=355276270=10221.0271=21346=61023=910=165
1128=99=18135=X49=SAMPLE75=2016101134=132752=2007050305283565648099260=200705030528356564809925799=10000100268=1279=1269=148=17359555=6SZ683=355277270=10220.0271=34346=31023=810=188
1128=99=18035=X49=SAMPLE75=2016101134=256652=2008122808534542496793660=200812280853454249679365799=10000100268=1279=1269=148=17359555=6SZ683=355278270=10220.0271=4346=21023=810=085
1128=99=18135=X49=SAMPLE75=2016101134=158652=2003101122405186502192060=200310112240518650219205799=10000100268=1279=1269=148=17359555=6SZ683=355279270=10221.0271=51346=71023=910=146
1128=99=18135=X49=SAMPLE75=2016101134=65152=2016061922214177932710460=201606192221417793271045799=10000100268=1279=1269=148=17359555=6SZ683=355280270=10221.0271=21346=61023=910=161
1128=99=18135=X49=SAMPLE75=2016101134=53752=2010041223550564818592060=201004122355056481859205799=10000100268=1279=1269=148=17359555=6SZ683=355281270=10221.0271=51346=71023=910=160
1128=99=18135=X49=SAMPLE75=2016101134=281752=2004092000334675517257660=200409200033467551725765799=10000100268=1279=1269=148=17359555=6SZ683=355282270=10221.0271=21346=61023=910=158
1128=99=18035=X49=SAMPLE75=2016101134=96352=2007112712420630360774460=200711271242063036077445799=10000100268=1279=1269=048=17359555=6SZ683=355283270=10206.0271=4346=21023=610=112
1128=99=18135=X49=SAMPLE75=2016101134=351052=2010123016051520779974460=201012301605152077997445799=10000100268=1279=1269=148=17359555=6SZ683=355284270=10221.0271=51346=71023=910=155
1128=99=18135=X49=SAMPLE75=2016101134=415652=2007092705355982947772860=200709270535598294777285799=10000100268=1279=1269=048=17359555=6SZ683=355285270=10206.0271=34346=31023=610=148
1128=99=18135=X49=SAMPLE75=2016101134=81552=2011061217245868617779260=201106121724586861777925799=10000100268=1279=1269=148=17359555=6SZ683=355286270=10221.0271=21346=61023=910=190
1128=99=18135=X49=SAMPLE75=2016101134=465352=2014080306061497527923260=201408030606149752792325799=10000100268=1279=1269=148=17359555=6SZ683=355287270=10221.0271=51346=71023=910=177
1128=99=18135=X49=SAMPLE75=2016101134=90452=2000042009533155252248260=200004200953315525224825799=10000100268=1279=1269=148=17359555=6SZ683=355288270=10221.0271=21346=61023=910=173
1128=99=18135=X49=SAMPLE75=2016101134=498052=2005071623490316067001660=200507162349031606700165799=10000100268=1279=1269=148=17359555=6SZ683=355289270=10221.0271=51346=71023=910=191
1128=99=18035=X49=SAMPLE75=2016101134=368152=2009051601391686979705660=200905160139168697970565799=10000100268=1279=1269=048=17359555=6SZ683=355290270=10206.0271=4346=21023=610=105
1128=99=18135=X49=SAMPLE75=2016101134=395552=2009070701153308197939260=200907070115330819793925799=10000100268=1279=1269=048=17359555=6SZ683=355291270=10207.0271=15346=71023=510=159
1128=99=18135=X49=SAMPLE75=2016101134=186052=2008051815374705580412860=200805181537470558041285799=10000100268=1279=1269=048=17359555=6SZ683=355292270=10208.0271=37346=51023=410=176
1128=99=18135=X49=SAMPLE75=2016101134=366752=2008073109513334057260860=200807310951333405726085799=10000100268=1279=1269=148=17359555=6SZ683=355293270=10221.0271=21346=61023=910=154
1128=99=18135=X49=SAMPLE75=2016101134=158152=2004011311375990153073660=200401131137599015307365799=10000100268=1279=1269=148=17359555=6SZ683=355294270=10216.0271=12346=41023=410=179
1128=99=18135=X49=SAMPLE75=2016101134=158052=2009061119281151600057660=200906111928115160005765799=10000100268=1279=1269=048=17359555=6SZ683=355295270=10203.0271=34346=31023=910=182
1128=99=18235=X49=SAMPLE75=2016101134=143652=2017010715532070257369660=201701071553207025736965799=10000100268=1279=1269=048=17359555=6SZ683=355296270=10202.0271=22346=81023=1010=218
1128=99=18135=X49=SAMPLE75=2016101134=257552=2015090814304033296569660=201509081430403329656965799=10000100268=1279=1269=048=17359555=6SZ683=355297270=10207.0271=45346=81023=510=169
1128=99=18135=X49=SAMPLE75=2016101134=354752=2012073011003182474086460=201207301100318247408645799=10000100268=1279=1269=048=17359555=6SZ683=355298270=10204.0271=34346=31023=810=167
1128=99=18135=X49=SAMPLE75=2016101134=157452=2007033119013143563865660=200703311901314356386565799=10000100268=1279=1269=148=17359555=6SZ683=355299270=10221.0271=51346=71023=910=174
1128=99=18035=X49=SAMPLE75=2016101134=203452=2016032521431213788723260=201603252143121378872325799=10000100268=1279=1269=048=17359555=6SZ683=355300270=10203.0271=4346=21023=910=132
1128=99=18135=X49=SAMPLE75=2016101134=191652=2002080323185769283164860=200208032318576928316485799=10000100268=1279=1269=148=17359555=6SZ683=355301270=10218.0271=34346=31023=610=167
1128=99=18035=X49=SAMPLE75=2016101134=307852=2000040313131520083401160=200004031313152008340115799=10000100268=1279=1269=048=17359555=6SZ683=355302270=10208.0271=7346=41023=410=118
1128=99=18035=X49=SAMPLE75=2016101134=159852=2002042818545031039552060=200204281854503103955205799=10000100268=1279=1269=048=17359555=6SZ683=355303270=10204.0271=4346=21023=810=100
1128=99=18135=X49=SAMPLE75=2016101134=472952=2011070402214517591840060=201107040221451759184005799=10000100268=1279=1269=048=17359555=6SZ683=355304270=10204.0271=34346=31023=810=163
1128=99=18035=X49=SAMPLE75=2016101134=151352=2003060823132884976230460=200306082313288497623045799=10000100268=1279=1269=048=17359555=6SZ683=355305270=10204.0271=4346=21023=810=083
1128=99=18135=X49=SAMPLE75=2016101134=313352=2005100201435976315078460=200510020143597631507845799=10000100268=1279=1269=048=17359555=6SZ683=355306270=10205.0271=51346=81023=710=160
1128=99=18235=X49=SAMPLE75=2016101134=394052=2011102822532543346585660=201110282253254334658565799=10000100268=1279=1269=048=17359555=6SZ683=355307270=10202.0271=52346=91023=1010=197
1128=99=18135=X49=SAMPLE75=2016101134=492552=2009091705264433616390460=200909170526443361639045799=10000100268=1279=1269=048=17359555=6SZ683=355308270=10205.0271=21346=71023=710=182
1128=99=18135=X49=SAMPLE75=2016101134=208052=2007031109133861271104060=200703110913386127110405799=10000100268=1279=1269=048=17359555=6SZ683=355309270=10205.0271=51346=81023=710=130
1128=99=18135=X49=SAMPLE75=2016101134=400252=2008111515255282968617660=200811151525528296861765799=10000100268=1279=1269=148=17359555=6SZ683=355310270=10221.0271=21346=61023=910=136
1128=99=18135=X49=SAMPLE75=2016101134=315552=2005122114574643684601660=200512211457464368460165799=10000100268=1279=1269=048=17359555=6SZ683=355311270=10205.0271=21346=71023=710=138
1128=99=18135=X49=SAMPLE75=2016101134=246852=2006040219012087963388860=200604021901208796338885799=10000100268=1279=1269=148=17359555=6SZ683=355312270=10221.0271=51346=71023=910=144
1128=99=18135=X49=SAMPLE75=2016101134=356652=2016100622211918329305660=201610062221191832930565799=10000100268=1279=1269=048=17359555=6SZ683=355313270=10205.0271=51346=81023=710=164
1128=99=18135=X49=SAMPLE75=2016101134=114952=2016052304563308102880060=201605230456330810288005799=10000100268=1279=1269=148=17359555=6SZ683=355314270=10221.0271=21346=61023=910=161
1128=99=18135=X49=SAMPLE75=2016101134=313952=2012010208215716989516860=201201020821571698951685799=10000100268=1279=1269=048=17359555=6SZ683=355315270=10205.0271=21346=71023=710=174
1128=99=18135=X49=SAMPLE75=2016101134=389052=2009022316141746331776060=200902231614174633177605799=10000100268=1279=1269=148=17359555=6SZ683=355316270=10221.0271=51346=71023=910=166
1128=99=18135=X49=SAMPLE75=2016101134=217152=2004011318443853097396860=200401131844385309739685799=10000100268=1279=1269=148=17359555=6SZ683=355317270=10221.0271=21346=61023=910=151
1128=99=18135=X49=SAMPLE75=2016101134=103452=2001022313244986964375260=200102231324498696437525799=10000100268=1279=1269=048=17359555=6SZ683=355318270=10208.0271=37346=51023=410=165
1128=99=18135=X49=SAMPLE75=2016101134=118352=2002010116325224299295260=200201011632522429929525799=10000100268=1279=1269=048=17359555=6SZ683=355319270=10204.0271=34346=31023=810=153
1128=99=18235=X49=SAMPLE75=2016101134=23452=2009050107184315581004860=200905010718431558100485799=10000100268=1279=1269=048=17359555=6SZ683=355320270=10202.0271=22346=81023=1010=196
1128=99=18135=X49=SAMPLE75=2016101134=111052=2006021520212126608329660=200602152021212660832965799=10000100268=1279=1269=148=17359555=6SZ683=355321270=10221.0271=51346=71023=910=158
1128=99=18035=X49=SAMPLE75=2016101134=68852=2003042100322621565302460=200304210032262156530245799=10000100268=1279=1269=048=17359555=6SZ683=355322270=10204.0271=4346=21023=810=106
1128=99=18235=X49=SAMPLE75=2016101134=118352=2009082606261873773881660=200908260626187377388165799=10000100268=1279=1269=048=17359555=6SZ683=355323270=10202.0271=52346=91023=1010=230
1128=99=18135=X49=SAMPLE75=2016101134=409152=2009101703032792022131260=200910170303279202213125799=10000100268=1279=1269=048=17359555=6SZ683=355324270=10204.0271=34346=31023=810=152
1128=99=18235=X49=SAMPLE75=2016101134=375152=2009021005524207945200060=200902100552420794520005799=10000100268=1279=1269=048=17359555=6SZ683=355325270=10202.0271=22346=81023=1010=200
1128=99=18135=X49=SAMPLE75=2016101134=486052=2011083008352797003321660=201108300835279700332165799=10000100268=1279=1269=148=17359555=6SZ683=355326270=10221.0271=21346=61023=910=154
1128=99=18035=X49=SAMPLE75=2016101134=293552=2010112401090014681497660=201011240109001468149765799=10000100268=1279=1269=048=17359555=6SZ683=355327270=10204.0271=4346=21023=810=096
1128=99=18035=X49=SAMPLE75=2016101134=156052=2000022910191951142745960=200002291019195114274595799=10000100268=1279=1269=048=17359555=6SZ683=355328270=10211.0271=4346=31023=110=077
1128=99=18035=X49=SAMPLE75=2016101134=119652=2002122907004401795129660=200212290700440179512965799=10000100268=1279=1269=048=17359555=6SZ683=355329270=10210.0271=4346=21023=210=089
1128=99=18135=X49=SAMPLE75=2016101134=78252=2005032009000161801107260=200503200900016180110725799=10000100268=1279=1269=048=17359555=6SZ683=355330270=10203.0271=34346=31023=910=127
1128=99=18035=X49=SAMPLE75=2016101134=294652=2007011809001071630755260=200701180900107163075525799=10000100268=1279=1269=148=17359555=6SZ683=355331270=10218.0271=4346=21023=610=102
1128=99=18035=X49=SAMPLE75=2016101134=119952=2001053000034776689002460=200105300003477668900245799=10000100268=1279=1269=048=17359555=6SZ683=355332270=10203.0271=4346=21023=910=074
1128=99=18135=X49=SAMPLE75=2016101134=119152=2009100313173925872051260=200910031317392587205125799=10000100268=1279=1269=048=17359555=6SZ683=355333270=10207.0271=15346=71023=510=130
1128=99=18135=X49=SAMPLE75=2016101134=27552=2011062918091702280390460=201106291809170228039045799=10000100268=1279=1269=148=17359555=6SZ683=355334270=10219.0271=59346=91023=710=156
1128=99=18135=X49=SAMPLE75=2016101134=135952=2013090603182098838412860=201309060318209883841285799=10000100268=1279=1269=048=17359555=6SZ683=355335270=10203.0271=34346=31023=910=141
1128=99=18235=X49=SAMPLE75=2016101134=186352=2008070806194939738160060=200807080619493973816005799=10000100268=1279=1269=048=17359555=6SZ683=355336270=10202.0271=52346=91023=1010=216
1128=99=18135=X49=SAMPLE75=2016101134=482552=2010111107145793211897660=201011110714579321189765799=10000100268=1279=1269=048=17359555=6SZ683=355337270=10207.0271=45346=81023=510=136
1128=99=18235=X49=SAMPLE75=2016101134=144752=2005032100084478435097660=200503210008447843509765799=10000100268=1279=1269=048=17359555=6SZ683=355338270=10202.0271=22346=81023=1010=174
1128=99=18135=X49=SAMPLE75=2016101134=309752=2013041316405728929868860=201304131640572892986885799=10000100268=1279=1269=148=17359555=6SZ683=355339270=10219.0271=29346=81023=710=170
1128=99=18135=X49=SAMPLE75=2016101134=131852=2008082517321274551136060=200808251732127455113605799=10000100268=1279=1269=048=17359555=6SZ683=355340270=10205.0271=29346=81023=710=130
1128=99=18135=X49=SAMPLE75=2016101134=461452=2009051617551443985670460=200905161755144398567045799=10000100268=1279=1269=048=17359555=6SZ683=355341270=10203.0271=42346=41023=910=139
1128=99=18135=X49=SAMPLE75=2016101134=167352=2009090705140393252057660=200909070514039325205765799=10000100268=1279=1269=048=17359555=6SZ683=355342270=10203.0271=12346=31023=910=150
1128=99=18135=X49=SAMPLE75=2016101134=497152=2006051802202670725340860=200605180220267072534085799=10000100268=1279=1269=148=17359555=6SZ683=355343270=10219.0271=59346=91023=710=153
1128=99=18135=X49=SAMPLE75=2016101134=417952=2009070619420744510700860=200907061942074451070085799=10000100268=1279=1269=148=17359555=6SZ683=355344270=10219.0271=29346=81023=710=173
1128=99=18135=X49=SAMPLE75=2016101134=326852=2000073109280193541016860=200007310928019354101685799=10000100268=1279=1269=148=17359555=6SZ683=355345270=10219.0271=21346=71023=710=157
1128=99=18135=X49=SAMPLE75=2016101134=137352=2004060903380703098518460=200406090338070309851845799=10000100268=1279=1269=048=17359555=6SZ683=355346270=10203.0271=42346=41023=910=143
1128=99=18135=X49=SAMPLE75=2016101134=461952=2007011715405554134908860=200701171540555413490885799=10000100268=1279=1269=048=17359555=6SZ683=355347270=10203.0271=12346=31023=910=178
1128=99=18135=X49=SAMPLE75=2016101134=495152=2014100210465811356857660=201410021046581135685765799=10000100268=1279=1269=148=17359555=6SZ683=355348270=10219.0271=51346=81023=710=181
1128=99=18135=X49=SAMPLE75=2016101134=79752=2015082313260162134873660=201508231326016213487365799=10000100268=1279=1269=048=17359555=6SZ683=355349270=10203.0271=42346=41023=910=161
1128=99=18135=X49=SAMPLE75=2016101134=271352=2011092016033884846675260=201109201603388484667525799=10000100268=1279=1269=048=17359555=6SZ683=355350270=10203.0271=12346=31023=910=169
1128=99=18135=X49=SAMPLE75=2016101134=187952=2016011322084918410028860=201601132208491841002885799=10000100268=1279=1269=148=17359555=6SZ683=355351270=10219.0271=21346=71023=710=138
1128=99=18135=X49=SAMPLE75=2016101134=475052=2000091502562430152348860=200009150256243015234885799=10000100268=1279=1269=048=17359555=6SZ683=355352270=10207.0271=15346=71023=510=159
1128=99=18035=X49=SAMPLE75=2016101134=459652=2014051919350867239571260=201405191935086723957125799=10000100268=1279=1269=048=17359555=6SZ683=355353270=10208.0271=7346=41023=410=090
1128=99=18135=X49=SAMPLE75=2016101134=219852=2012061114252318808390460=201206111425231880839045799=10000100268=1279=1269=148=17359555=6SZ683=355354270=10219.0271=51346=81023=710=155
1128=99=18135=X49=SAMPLE75=2016101134=54752=2014092023464486230764860=201409202346448623076485799=10000100268=1279=1269=048=17359555=6SZ683=355355270=10204.0271=34346=31023=810=161
1128=99=18135=X49=SAMPLE75=2016101134=262652=2011081003560578914560060=201108100356057891456005799=10000100268=1279=1269=048=17359555=6SZ683=355356270=10207.0271=45346=81023=510=172
1128=99=18135=X49=SAMPLE75=2016101134=257352=2010043018154827375449660=201004301815482737544965799=10000100268=1279=1269=048=17359555=6SZ683=355357270=10205.0271=59346=91023=710=168
1128=99=18035=X49=SAMPLE75=2016101134=470152=2004040208595646574545660=200404020859564657454565799=10000100268=1279=1269=148=17359555=6SZ683=355358270=10214.0271=8346=61023=210=068
1128=99=18135=X49=SAMPLE75=2016101134=41952=2007011415335688252633660=200701141533568825263365799=10000100268=1279=1269=148=17359555=6SZ683=355359270=10219.0271=21346=71023=710=162
1128=99=18035=X49=SAMPLE75=2016101134=482252=2001081816003203020541660=200108181600320302054165799=10000100268=1279=1269=048=17359555=6SZ683=355360270=10204.0271=4346=21023=810=106
1128=99=18135=X49=SAMPLE75=2016101134=289452=2004052020442731561272060=200405202044273156127205799=10000100268=1279=1269=048=17359555=6SZ683=355361270=10205.0271=29346=81023=710=157
1128=99=18135=X49=SAMPLE75=2016101134=308552=2005031012445216036940860=200503101244521603694085799=10000100268=1279=1269=148=17359555=6SZ683=355362270=10219.0271=51346=81023=710=144
1128=99=18035=X49=SAMPLE75=2016101134=188052=2000052003303624632030260=200005200330362463203025799=10000100268=1279=1269=148=17359555=6SZ683=355363270=10217.0271=3346=11023=510=084
1128=99=18135=X49=SAMPLE75=2016101134=214052=2004060207394070288638460=200406020739407028863845799=10000100268=1279=1269=148=17359555=6SZ683=355364270=10221.0271=51346=71023=910=142
1128=99=18135=X49=SAMPLE75=2016101134=98152=2005090201222746112048060=200509020122274611204805799=10000100268=1279=1269=048=17359555=6SZ683=355365270=10205.0271=59346=91023=710=156
1128=99=18135=X49=SAMPLE75=2016101134=467752=2011090202523751854547260=201109020252375185454725799=10000100268=1279=1269=148=17359555=6SZ683=355366270=10219.0271=21346=71023=710=187
1128=99=20835=X49=SAMPLE75=2016101134=86452=2001020815195373249080860=200102081519537324908085799=00000001268=1279=0269=248=17359555=6SZ683=355367270=10213.0271=1346=25797=137705=237=032=137=032=110=073
1128=99=15635=X49=SAMPLE75=2016101134=145752=2002042405050692838038460=200204240505069283803845799=00000010268=1279=0269=e48=17359555=6SZ683=355368271=1610=092
1128=99=25335=X49=SAMPLE75=2016101134=279152=2004040723302243230193660=200404072330224323019365799=10000100268=2279=2269=148=17359555=6SZ683=355369270=10213.0271=1346=11023=1279=0269=148=17359555=6SZ683=355370270=10223.0271=17346=41023=1010=236
1128=99=17935=X49=SAMPLE75=2016101134=7452=2011062918030975378259260=201106291803097537825925799=10000100268=1279=0269=048=17360055=6SH783=99078270=10265.0271=3346=11023=110=031
1128=99=17935=X49=SAMPLE75=2016101134=84052=2003071609224966975393660=200307160922496697539365799=10000100268=1279=0269=048=17360055=6SH783=99079270=10264.0271=3346=11023=210=021
1128=99=25135=X49=SAMPLE75=2016101134=489852=2004020802400924398083260=200402080240092439808325799=10000100268=2279=1269=048=17359555=6SZ683=355371270=10209.0271=5346=31023=3279=1269=048=17359555=6SZ683=355372270=10208.0271=6346=31023=410=142
1128=99=18035=X49=SAMPLE75=2016101134=70452=2003061004405368593590460=200306100440536859359045799=10000100268=1279=1269=148=17359555=6SZ683=355373270=10214.0271=9346=71023=110=072
1128=99=18135=X49=SAMPLE75=2016101134=272252=2012020314272538836307260=201202031427253883630725799=10000100268=1279=1269=148=17359555=6SZ683=355374270=10217.0271=33346=21023=410=166
1128=99=18135=X49=SAMPLE75=2016101134=230552=2002121121284185765038460=200212112128418576503845799=10000100268=1279=1269=148=17359555=6SZ683=355375270=10221.0271=21346=61023=810=164
1128=99=25135=X49=SAMPLE75=2016101134=244552=2012082320130809327340860=201208232013080932734085799=10000100268=2279=2269=048=17360055=6SH783=99080270=10265.0271=3346=11023=1279=0269=048=17360055=6SH783=99081270=10255.0271=53346=21023=1010=091
1128=99=25035=X49=SAMPLE75=2016101134=339752=2001030920320329387755260=200103092032032938775525799=10000100268=2279=2269=048=17360055=6SH783=99082270=10264.0271=3346=11023=1279=0269=048=17360055=6SH783=99083270=10254.0271=3346=11023=1010=036
1128=99=18035=X49=SAMPLE75=2016101134=147552=2014090210530351882246460=201409021053035188224645799=10000100268=1279=1269=148=17359555=6SZ683=355376270=10217.0271=3346=11023=410=114
1128=99=18135=X49=SAMPLE75=2016101134=406152=2001111902274857840588860=200111190227485784058885799=10000100268=1279=1269=148=17359555=6SZ683=355377270=10222.0271=33346=21023=910=185
1128=99=18135=X49=SAMPLE75=2016101134=141952=2006011619453381372969660=200601161945338137296965799=10000100268=1279=1269=048=17359555=6SZ683=355378270=10205.0271=29346=81023=710=195
1128=99=18135=X49=SAMPLE75=2016101134=395752=2016072901543861494400060=201607290154386149440005799=10000100268=1279=1269=148=17359555=6SZ683=355379270=10217.0271=33346=21023=410=191
1128=99=18135=X49=SAMPLE75=2016101134=431352=2011051511533082488793660=201105151153308248879365799=10000100268=1279=1269=148=17359555=6SZ683=355380270=10219.0271=51346=81023=610=176
1128=99=18035=X49=SAMPLE75=2016101134=310452=2004051220422199310580860=200405122042219931058085799=10000100268=1279=1269=148=17359555=6SZ683=355381270=10222.0271=3346=11023=910=119
1128=99=18135=X49=SAMPLE75=2016101134=62652=2004042310471807494435260=200404231047180749443525799=10000100268=1279=1269=048=17359555=6SZ683=355382270=10205.0271=59346=91023=710=195
1128=99=18135=X49=SAMPLE75=2016101134=439652=2007031705185884277584060=200703170518588427758405799=10000100268=1279=1269=048=17359555=6SZ683=355383270=10205.0271=29346=81023=710=179
1128=99=18035=X49=SAMPLE75=2016101134=223952=2008081322081756670412860=200808132208175667041285799=10000100268=1279=1269=048=17359555=6SZ683=355384270=10211.0271=3346=21023=110=088
1128=99=18135=X49=SAMPLE75=2016101134=9752=2001070421301033652601660=200107042130103365260165799=10000100268=1279=1269=048=17359555=6SZ683=355385270=10205.0271=59346=91023=710=193
1128=99=18235=X49=SAMPLE75=2016101134=398452=2009021622514506976096060=200902162251450697609605799=10000100268=1279=1269=048=17359555=6SZ683=355386270=10202.0271=52346=91023=1010=183
1128=99=18135=X49=SAMPLE75=2016101134=148552=2004021011010875379625660=200402101101087537962565799=10000100268=1279=1269=148=17359555=6SZ683=355387270=10219.0271=21346=71023=610=138
1128=99=18135=X49=SAMPLE75=2016101134=2752=2012062108464421310784060=201206210846442131078405799=10000100268=1279=1269=048=17359555=6SZ683=355388270=10207.0271=15346=71023=510=163
1128=99=18135=X49=SAMPLE75=2016101134=364352=2010031102454327764940860=201003110245432776494085799=10000100268=1279=1269=048=17359555=6SZ683=355389270=10204.0271=34346=31023=810=154
1128=99=18235=X49=SAMPLE75=2016101134=467752=2011082900011211958745660=201108290001121195874565799=10000100268=1279=1269=048=17359555=6SZ683=355390270=10202.0271=22346=81023=1010=193
1128=99=18135=X49=SAMPLE75=2016101134=139852=2009100119483137598489660=200910011948313759848965799=10000100268=1279=1269=148=17359555=6SZ683=355391270=10219.0271=51346=81023=610=145
1128=99=18035=X49=SAMPLE75=2016101134=417652=2006090415551974643728060=200609041555197464372805799=10000100268=1279=1269=048=17359555=6SZ683=355392270=10204.0271=4346=21023=810=090
1128=99=18135=X49=SAMPLE75=2016101134=323152=2013101112345161921395260=201310111234516192139525799=10000100268=1279=1269=048=17359555=6SZ683=355393270=10207.0271=45346=81023=510=167
1128=99=18135=X49=SAMPLE75=2016101134=320652=2006032311391218234364860=200603231139121823436485799=10000100268=1279=1269=148=17359555=6SZ683=355394270=10219.0271=21346=71023=610=170
1128=99=18135=X49=SAMPLE75=2016101134=405452=2014052810463584886137660=201405281046358488613765799=10000100268=1279=1269=048=17359555=6SZ683=355395270=10205.0271=29346=81023=710=149
1128=99=18135=X49=SAMPLE75=2016101134=365352=2013021915184950629241660=201302191518495062924165799=10000100268=1279=1269=148=17359555=6SZ683=355396270=10220.0271=34346=31023=710=159
1128=99=18135=X49=SAMPLE75=2016101134=360952=2014052704312479293075260=201405270431247929307525799=10000100268=1279=1269=048=17359555=6SZ683=355397270=10205.0271=59346=91023=710=175
1128=99=18135=X49=SAMPLE75=2016101134=40552=2002122501000183305984060=200212250100018330598405799=10000100268=1279=1269=048=17359555=6SZ683=355398270=10207.0271=15346=71023=510=142
1128=99=18135=X49=SAMPLE75=2016101134=192552=2015032207462424069286460=201503220746242406928645799=10000100268=1279=1269=048=17359555=6SZ683=355399270=10204.0271=34346=31023=810=138
1128=99=18135=X49=SAMPLE75=2016101134=262052=2015042610092994798348860=201504261009299479834885799=10000100268=1279=1269=048=17359555=6SZ683=355400270=10207.0271=45346=81023=510=171
1128=99=18035=X49=SAMPLE75=2016101134=347752=2002040712224794622146460=200204071222479462214645799=10000100268=1279=1269=048=17359555=6SZ683=355401270=10204.0271=4346=21023=810=086
1128=99=18035=X49=SAMPLE75=2016101134=297752=2001042010345682554743260=200104201034568255474325799=10000100268=1279=1269=148=17359555=6SZ683=355402270=10220.0271=4346=21023=710=081
1128=99=18135=X49=SAMPLE75=2016101134=470752=2000112523393318931003260=200011252339331893100325799=10000100268=1279=1269=148=17359555=6SZ683=355403270=10219.0271=51346=81023=610=148
1128=99=18135=X49=SAMPLE75=2016101134=380952=2012032621562821702073660=201203262156282170207365799=10000100268=1279=1269=048=17359555=6SZ683=355404270=10205.0271=29346=81023=710=160
1128=99=18135=X49=SAMPLE75=2016101134=144452=2004050313363463941960060=200405031336346394196005799=10000100268=1279=1269=048=17359555=6SZ683=355405270=10206.0271=34346=31023=610=172
1128=99=18235=X49=SAMPLE75=2016101134=165352=2005020607002808404544060=200502060700280840454405799=10000100268=1279=1269=048=17359555=6SZ683=355406270=10202.0271=52346=91023=1010=202
1128=99=18135=X49=SAMPLE75=2016101134=386652=2006062012082598619923260=200606201208259861992325799=10000100268=1279=1269=148=17359555=6SZ683=355407270=10221.0271=13346=51023=810=143
1128=99=18135=X49=SAMPLE75=2016101134=44152=2006090315224289380176060=200609031522428938017605799=10000100268=1279=1269=148=17359555=6SZ683=355408270=10223.0271=9346=31023=1010=136
1128=99=18135=X49=SAMPLE75=2016101134=30352=2016072405081232684966460=201607240508123268496645799=10000100268=1279=1269=048=17359555=6SZ683=355409270=10205.0271=21346=71023=710=137
1128=99=18035=X49=SAMPLE75=2016101134=207152=2015010902552440699430460=201501090255244069943045799=10000100268=1279=1269=048=17359555=6SZ683=355410270=10203.0271=4346=21023=910=071
1128=99=18035=X49=SAMPLE75=2016101134=219852=2016011220234641430873660=201601122023464143087365799=10000100268=1279=1269=048=17359555=6SZ683=355411270=10211.0271=4346=31023=110=094
1128=99=18035=X49=SAMPLE75=2016101134=410852=2016120223494683591091260=201612022349468359109125799=10000100268=1279=1269=048=17359555=6SZ683=355412270=10206.0271=4346=21023=610=108
1128=99=18135=X49=SAMPLE75=2016101134=378852=2016071415231077615481660=201607141523107761548165799=10000100268=1279=1269=148=17359555=6SZ683=355413270=10219.0271=21346=71023=610=165
1128=99=18135=X49=SAMPLE75=2016101134=298652=2005070102364122468675260=200507010236412246867525799=10000100268=1279=1269=048=17359555=6SZ683=355414270=10206.0271=34346=31023=610=158
1128=99=18135=X49=SAMPLE75=2016101134=389152=2001082118401409790881660=200108211840140979088165799=10000100268=1279=1269=148=17359555=6SZ683=355415270=10219.0271=51346=81023=610=171
1128=99=18035=X49=SAMPLE75=2016101134=112152=2005071009185373712742460=200507100918537371274245799=10000100268=1279=1269=048=17359555=6SZ683=355416270=10206.0271=4346=21023=610=114
1128=99=18135=X49=SAMPLE75=2016101134=9852=2002101114160851789510460=200210111416085178951045799=10000100268=1279=1269=048=17359555=6SZ683=355417270=10206.0271=34346=31023=610=163
1128=99=18135=X49=SAMPLE75=2016101134=64152=2003072710313898694672060=200307271031389869467205799=10000100268=1279=1269=148=17359555=6SZ683=355418270=10219.0271=21346=71023=610=165
1128=99=18135=X49=SAMPLE75=2016101134=284052=2007012607394112390777660=200701260739411239077765799=10000100268=1279=1269=148=17359555=6SZ683=355419270=10220.0271=34346=31023=710=171
1128=99=18035=X49=SAMPLE75=2016101134=486352=2001090613514495689739260=200109061351449568973925799=10000100268=1279=1269=148=17359555=6SZ683=355420270=10220.0271=4346=21023=710=101
1128=99=18135=X49=SAMPLE75=2016101134=117152=2000060509274968849891060=200006050927496884989105799=10000100268=1279=1269=148=17359555=6SZ683=355421270=10219.0271=51346=81023=610=151
1128=99=18135=X49=SAMPLE75=2016101134=398952=2015092800012503693203260=201509280001250369320325799=10000100268=1279=1269=148=17359555=6SZ683=355422270=10219.0271=21346=71023=610=175
1128=99=18035=X49=SAMPLE75=2016101134=402852=2013112705145137490028860=201311270514513749002885799=10000100268=1279=1269=048=17359555=6SZ683=355423270=10206.0271=4346=21023=610=132
1128=99=18135=X49=SAMPLE75=2016101134=370852=2010090302023454919001660=201009030202345491900165799=10000100268=1279=1269=148=17359555=6SZ683=355424270=10219.0271=51346=81023=610=179
1128=99=18135=X49=SAMPLE75=2016101134=493652=2017011902482825751852860=201701190248282575185285799=10000100268=1279=1269=048=17359555=6SZ683=355425270=10206.0271=34346=31023=610=178
1128=99=18135=X49=SAMPLE75=2016101134=471752=2015091918143428024716860=201509191814342802471685799=10000100268=1279=1269=148=17359555=6SZ683=355426270=10219.0271=21346=71023=610=184
1128=99=18135=X49=SAMPLE75=2016101134=90552=2007042212003611758777660=200704221200361175877765799=10000100268=1279=1269=148=17359555=6SZ683=355427270=10219.0271=51346=81023=610=192
1128=99=18135=X49=SAMPLE75=2016101134=168052=2011090315231136925241660=201109031523113692524165799=10000100268=1279=1269=148=17359555=6SZ683=355428270=10219.0271=21346=71023=610=185
1128=99=18135=X49=SAMPLE75=2016101134=221252=2014121301112382312300860=201412130111238231230085799=10000100268=1279=1269=148=17359555=6SZ683=355429270=10219.0271=51346=81023=610=172
1128=99=18135=X49=SAMPLE75=2016101134=195252=2012022201453783303219260=201202220145378330321925799=10000100268=1279=1269=148=17359555=6SZ683=355430270=10219.0271=21346=71023=610=171
1128=99=18135=X49=SAMPLE75=2016101134=16252=2001083013302714831892060=200108301330271483189205799=10000100268=1279=1269=148=17359555=6SZ683=355431270=10219.0271=51346=81023=610=184
1128=99=18135=X49=SAMPLE75=2016101134=387852=2012010615385145305984060=201201061538514530598405799=10000100268=1279=1269=148=17359555=6SZ683=355432270=10219.0271=21346=71023=610=173
1128=99=18135=X49=SAMPLE75=2016101134=206752=2007123019552573609251260=200712301955257360925125799=10000100268=1279=1269=148=17359555=6SZ683=355433270=10219.0271=51346=81023=610=183
1128=99=18135=X49=SAMPLE75=2016101134=482152=2016042414222250228710460=201604241422225022871045799=10000100268=1279=1269=148=17359555=6SZ683=355434270=10219.0271=21346=71023=610=193
1128=99=18135=X49=SAMPLE75=2016101134=216852=2015071803463911739347260=201507180346391173934725799=10000100268=1279=1269=148=17359555=6SZ683=355435270=10219.0271=51346=81023=610=215
1128=99=18035=X49=SAMPLE75=2016101134=183252=2004060217410124553222460=200406021741012455322245799=10000100268=1279=1269=048=17359555=6SZ683=355436270=10206.0271=4346=21023=610=125
1128=99=18135=X49=SAMPLE75=2016101134=425352=2000102607384592377781660=200010260738459237778165799=10000100268=1279=1269=048=17359555=6SZ683=355437270=10206.0271=34346=31023=610=157
1128=99=18135=X49=SAMPLE75=2016101134=119252=2012070208554680490438460=201207020855468049043845799=10000100268=1279=1269=148=17359555=6SZ683=355438270=10219.0271=21346=71023=610=171
1128=99=18035=X49=SAMPLE75=2016101134=334752=2009022216582785470054460=200902221658278547005445799=10000100268=1279=1269=048=17359555=6SZ683=355439270=10206.0271=4346=21023=610=119
1128=99=18135=X49=SAMPLE75=2016101134=202352=2016020521365491416076860=201602052136549141607685799=10000100268=1279=1269=148=17359555=6SZ683=355440270=10219.0271=51346=81023=610=162
1128=99=18135=X49=SAMPLE75=2016101134=445352=2011121622355694892640060=201112162235569489264005799=10000100268=1279=1269=048=17359555=6SZ683=355441270=10206.0271=34346=31023=610=153
1128=99=18135=X49=SAMPLE75=2016101134=214352=2011080808510435346560060=201108080851043534656005799=10000100268=1279=1269=148=17359555=6SZ683=355442270=10219.0271=21346=71023=610=167
1128=99=18035=X49=SAMPLE75=2016101134=188252=2013030316215850340601660=201303031621585034060165799=10000100268=1279=1269=048=17359555=6SZ683=355443270=10206.0271=4346=21023=610=129
1128=99=18135=X49=SAMPLE75=2016101134=145752=2004061520541647962987260=200406152054164796298725799=10000100268=1279=1269=148=17359555=6SZ683=355444270=10219.0271=51346=81023=610=176
1128=99=18135=X49=SAMPLE75=2016101134=269052=2002120708243700488206460=200212070824370048820645799=10000100268=1279=1269=048=17359555=6SZ683=355445270=10206.0271=34346=31023=610=170
1128=99=18135=X49=SAMPLE75=2016101134=93252=2011122119540431642393660=201112211954043164239365799=10000100268=1279=1269=148=17359555=6SZ683=355446270=10219.0271=21346=71023=610=137
1128=99=18035=X49=SAMPLE75=2016101134=425852=2006113007300701683980860=200611300730070168398085799=10000100268=1279=1269=048=17359555=6SZ683=355447270=10208.0271=7346=41023=410=064
1128=99=18135=X49=SAMPLE75=2016101134=335752=2014010620434954491360060=201401062043495449136005799=10000100268=1279=1269=148=17359555=6SZ683=355448270=10216.0271=13346=51023=310=143
1128=99=18135=X49=SAMPLE75=2016101134=348852=2002111908072993305025660=200211190807299330502565799=10000100268=1279=1269=148=17359555=6SZ683=355449270=10219.0271=51346=81023=610=157
1128=99=18135=X49=SAMPLE75=2016101134=412952=2003122003100666326489660=200312200310066632648965799=10000100268=1279=1269=148=17359555=6SZ683=355450270=10219.0271=21346=71023=610=165
1128=99=18135=X49=SAMPLE75=2016101134=338252=2007032507564166435360060=200703250756416643536005799=10000100268=1279=1269=148=17359555=6SZ683=355451270=10219.0271=51346=81023=610=153
1128=99=18035=X49=SAMPLE75=2016101134=495252=2015111804120135651424060=201511180412013565142405799=10000100268=1279=1269=048=17359555=6SZ683=355452270=10206.0271=4346=21023=610=062
1128=99=18135=X49=SAMPLE75=2016101134=341952=2014011401200056172915260=201401140120005617291525799=10000100268=1279=1269=148=17359555=6SZ683=355453270=10219.0271=21346=71023=610=128
1128=99=18135=X49=SAMPLE75=2016101134=207052=2005012506001532700780860=200501250600153270078085799=10000100268=1279=1269=048=17359555=6SZ683=355454270=10206.0271=34346=31023=610=125
1128=99=18135=X49=SAMPLE75=2016101134=207852=2013020117503844492198460=201302011750384449219845799=10000100268=1279=1269=148=17359555=6SZ683=355455270=10219.0271=51346=81023=610=148
1128=99=18235=X49=SAMPLE75=2016101134=199252=2017012002541885959206460=201701200254188595920645799=10000100268=1279=1269=048=17359555=6SZ683=355456270=10202.0271=22346=81023=1010=203
1128=99=18235=X49=SAMPLE75=2016101134=79952=2014122203432999026406460=201412220343299902640645799=10000100268=1279=1269=048=17359555=6SZ683=355457270=10202.0271=52346=91023=1010=201
1128=99=18135=X49=SAMPLE75=2016101134=291552=2005101910155054573670460=200510191015505457367045799=10000100268=1279=1269=148=17359555=6SZ683=355458270=10219.0271=21346=71023=610=136
1128=99=18135=X49=SAMPLE75=2016101134=193452=2009100900492373551782460=200910090049237355178245799=10000100268=1279=1269=148=17359555=6SZ683=355459270=10219.0271=51346=81023=610=159
1128=99=18135=X49=SAMPLE75=2016101134=380552=2015102108080880628595260=201510210808088062859525799=10000100268=1279=1269=148=17359555=6SZ683=355460270=10219.0271=21346=71023=610=109
1128=99=18135=X49=SAMPLE75=2016101134=492552=2001090606565431733739260=200109060656543173373925799=10000100268=1279=1269=148=17359555=6SZ683=355461270=10219.0271=51346=81023=610=149
1128=99=18035=X49=SAMPLE75=2016101134=193252=2014012001313375333888060=201401200131337533388805799=10000100268=1279=1269=048=17359555=6SZ683=355462270=10206.0271=4346=21023=610=056
1128=99=18135=X49=SAMPLE75=2016101134=251652=2015041814265256007443260=201504181426525600744325799=10000100268=1279=1269=148=17359555=6SZ683=355463270=10219.0271=21346=71023=610=118
1128=99=18135=X49=SAMPLE75=2016101134=19952=2007013012115857085020860=200701301211585708502085799=10000100268=1279=1269=048=17359555=6SZ683=355464270=10206.0271=34346=31023=610=136
1128=99=18135=X49=SAMPLE75=2016101134=356152=2011022710375713927392060=201102271037571392739205799=10000100268=1279=1269=148=17359555=6SZ683=355465270=10219.0271=51346=81023=610=145
1128=99=18235=X49=SAMPLE75=2016101134=207252=2013070403301212395219260=201307040330121239521925799=10000100268=1279=1269=048=17359555=6SZ683=355466270=10202.0271=22346=81023=1010=169
1128=99=18135=X49=SAMPLE75=2016101134=327852=2002060519025478057150460=200206051902547805715045799=10000100268=1279=1269=148=17359555=6SZ683=355467270=10219.0271=21346=71023=610=163
1128=99=18235=X49=SAMPLE75=2016101134=210952=2016021723012992362931260=201602172301299236293125799=10000100268=1279=1269=048=17359555=6SZ683=355468270=10202.0271=52346=91023=1010=187
1128=99=18135=X49=SAMPLE75=2016101134=369952=2008050613480668625270460=200805061348066862527045799=10000100268=1279=1269=148=17359555=6SZ683=355469270=10219.0271=51346=81023=610=165
1128=99=18035=X49=SAMPLE75=2016101134=399652=2005012114315570014217660=200501211431557001421765799=10000100268=1279=1269=048=17359555=6SZ683=355470270=10206.0271=4346=21023=610=087
1128=99=18135=X49=SAMPLE75=2016101134=31752=2016011600583176140627260=201601160058317614062725799=10000100268=1279=1269=148=17359555=6SZ683=355471270=10219.0271=21346=71023=610=154
1128=99=18135=X49=SAMPLE75=2016101134=362052=2004122508262834138726460=200412250826283413872645799=10000100268=1279=1269=048=17359555=6SZ683=355472270=10206.0271=34346=31023=610=148
1128=99=18135=X49=SAMPLE75=2016101134=385952=2014122900243747130451260=201412290024374713045125799=10000100268=1279=1269=148=17359555=6SZ683=355473270=10219.0271=51346=81023=610=154
1128=99=18135=X49=SAMPLE75=2016101134=130052=2008051309110727566857660=200805130911072756685765799=10000100268=1279=1269=148=17359555=6SZ683=355474270=10219.0271=21346=71023=610=139
1128=99=18135=X49=SAMPLE75=2016101134=120252=2014090315023132667910460=201409031502313266791045799=10000100268=1279=1269=148=17359555=6SZ683=355475270=10219.0271=51346=81023=610=155
1128=99=18235=X49=SAMPLE75=2016101134=337552=2011031814382887710124860=201103181438288771012485799=10000100268=1279=1269=048=17359555=6SZ683=355476270=10202.0271=22346=81023=1010=207
1128=99=18135=X49=SAMPLE75=2016101134=208252=2016042215300455373164860=201604221530045537316485799=10000100268=1279=1269=148=17359555=6SZ683=355477270=10219.0271=21346=71023=610=164
1128=99=18135=X49=SAMPLE75=2016101134=380852=2007062203193100057056060=200706220319310005705605799=10000100268=1279=1269=148=17359555=6SZ683=355478270=10219.0271=51346=81023=610=156
1128=99=18235=X49=SAMPLE75=2016101134=222352=2004050705172612655947260=200405070517261265594725799=10000100268=1279=1269=048=17359555=6SZ683=355479270=10202.0271=52346=91023=1010=234
1128=99=25335=X49=SAMPLE75=2016101134=34252=2000060312041190175559260=200006031204119017555925799=10000100268=2279=1269=048=17359555=6SZ683=355480270=10208.0271=10346=51023=4279=1269=048=17359555=6SZ683=355481270=10207.0271=42346=71023=510=004
1128=99=18235=X49=SAMPLE75=2016101134=60252=2014100117200097811571260=201410011720009781157125799=10000100268=1279=1269=048=17359555=6SZ683=355482270=10202.0271=22346=81023=1010=185
1128=99=18035=X49=SAMPLE75=2016101134=160752=2007112818145011638316860=200711281814501163831685799=10000100268=1279=1269=048=17359555=6SZ683=355483270=10206.0271=4346=21023=610=081
1128=99=18135=X49=SAMPLE75=2016101134=55652=2016032022234600940544060=201603202223460094054405799=10000100268=1279=1269=048=17359555=6SZ683=355484270=10206.0271=34346=31023=610=137
1128=99=18135=X49=SAMPLE75=2016101134=102852=2016120320472234943891260=201612032047223494389125799=10000100268=1279=1269=148=17359555=6SZ683=355485270=10219.0271=21346=71023=610=158
1128=99=18035=X49=SAMPLE75=2016101134=21252=2015042507500705518713660=201504250750070551871365799=10000100268=1279=1269=048=17359555=6SZ683=355486270=10206.0271=4346=21023=610=083
1128=99=18135=X49=SAMPLE75=2016101134=399152=2011012523013170947225660=201101252301317094722565799=10000100268=1279=1269=148=17359555=6SZ683=355487270=10222.0271=33346=21023=910=131
1128=99=18135=X49=SAMPLE75=2016101134=16452=2012031118131781138419260=201203111813178113841925799=10000100268=1279=1269=048=17359555=6SZ683=355488270=10205.0271=51346=81023=710=151
1128=99=27035=X49=SAMPLE75=2016101134=238552=2015021008433390420505660=201502100843339042050565799=00000001268=1279=0269=248=17359555=6SZ683=355489270=10214.0271=8346=75797=137705=737=032=837=032=137=032=137=032=137=032=137=621180789662532=137=032=310=051
1128=99=15635=X49=SAMPLE75=2016101134=137552=2000123103295941064772860=200012310329594106477285799=00000010268=1279=0269=e48=17359555=6SZ683=355490271=2410=085
1128=99=18035=X49=SAMPLE75=2016101134=260252=2010121815344367983891260=201012181534436798389125799=00000100268=1279=1269=148=17359555=6SZ683=355491270=10214.0271=1346=11023=110=089
1128=99=16935=X49=SAMPLE75=2016101134=120252=2004122420591451985385660=200412242059145198538565799=10001000268=1279=0269=748=17359555=6SZ683=355492270=10214.0286=25510=151
1128=99=17935=X49=SAMPLE75=2016101134=408852=2000040300282394531845060=200004030028239453184505799=10000100268=1279=0269=048=17360055=6SH783=99084270=10265.0271=3346=11023=110=047
1128=99=25135=X49=SAMPLE75=2016101134=480952=2009050309090795832768060=200905030909079583276805799=10000100268=2279=2269=148=17360055=6SH783=99085270=10270.0271=3346=11023=1279=0269=148=17360055=6SH783=99086270=10280.0271=53346=11023=1010=091
1128=99=18035=X49=SAMPLE75=2016101134=241052=2004021416395344679374460=200402141639534467937445799=10000100268=1279=0269=048=17359555=6SZ683=355493270=10212.0271=1346=11023=110=088
1128=99=17935=X49=SAMPLE75=2016101134=439652=2003011208454528031120060=200301120845452803112005799=10000100268=1279=0269=048=17360055=6SH783=99087270=10264.0271=3346=11023=210=039
1128=99=18035=X49=SAMPLE75=2016101134=35552=2000060405183958252583860=200006040518395825258385799=10000100268=1279=1269=148=17359555=6SZ683=355494270=10217.0271=3346=11023=410=101
1128=99=18135=X49=SAMPLE75=2016101134=217352=2000073006163225525749260=200007300616322552574925799=10000100268=1279=1269=048=17359555=6SZ683=355495270=10205.0271=21346=71023=810=163
1128=99=25135=X49=SAMPLE75=2016101134=117552=2001041022292868457232860=200104102229286845723285799=10000100268=2279=2269=048=17360055=6SH783=99088270=10265.0271=3346=11023=1279=0269=048=17360055=6SH783=99089270=10255.0271=53346=21023=1010=111
1128=99=18135=X49=SAMPLE75=2016101134=380652=2016082607411270752140860=201608260741127075214085799=10000100268=1279=1269=148=17359555=6SZ683=355496270=10221.0271=43346=61023=810=149
1128=99=18035=X49=SAMPLE75=2016101134=319352=2013111903362342207488060=201311190336234220748805799=10000100268=1279=1269=148=17359555=6SZ683=355497270=10222.0271=3346=11023=910=108
1128=99=18035=X49=SAMPLE75=2016101134=231452=2010121110241557415590460=201012111024155741559045799=10000100268=1279=1269=048=17359555=6SZ683=355498270=10212.0271=2346=21023=110=077
1128=99=18035=X49=SAMPLE75=2016101134=44152=2015090512271698186931260=201509051227169818693125799=10000100268=1279=1269=148=17359555=6SZ683=355499270=10214.0271=2346=21023=110=081
1128=99=24935=X49=SAMPLE75=2016101134=59552=2012020617593674782528060=201202061759367478252805799=10000100268=2279=1269=048=17360055=6SH783=99090270=10263.0271=5346=21023=2279=1269=048=17360055=6SH783=99091270=10261.0271=3346=11023=410=243
1128=99=18135=X49=SAMPLE75=2016101134=96352=2012091200341122958368060=201209120034112295836805799=10000100268=1279=1269=148=17359555=6SZ683=355500270=10218.0271=34346=31023=510=146
1128=99=18135=X49=SAMPLE75=2016101134=457952=2010061613221746952422460=201006161322174695242245799=10000100268=1279=1269=048=17359555=6SZ683=355501270=10205.0271=51346=81023=810=132
1128=99=18135=X49=SAMPLE75=2016101134=197352=2005052504104467892748860=200505250410446789274885799=10000100268=1279=1269=148=17359555=6SZ683=355502270=10220.0271=34346=31023=710=145
1128=99=18135=X49=SAMPLE75=2016101134=116152=2008071806041113425728060=200807180604111342572805799=10000100268=1279=1269=048=17359555=6SZ683=355503270=10206.0271=34346=31023=710=136
1128=99=18135=X49=SAMPLE75=2016101134=220652=2010102808522349958284860=201010280852234995828485799=10000100268=1279=1269=048=17359555=6SZ683=355504270=10205.0271=21346=71023=810=116
1128=99=18135=X49=SAMPLE75=2016101134=186552=2008100703285396931475260=200810070328539693147525799=10000100268=1279=1269=148=17359555=6SZ683=355505270=10221.0271=13346=51023=810=123
1128=99=18035=X49=SAMPLE75=2016101134=218852=2006081503322975639824060=200608150332297563982405799=10000100268=1279=1269=048=17359555=6SZ683=355506270=10206.0271=4346=21023=710=084
1128=99=18035=X49=SAMPLE75=2016101134=312552=2004100802535601120988860=200410080253560112098885799=10000100268=1279=1269=148=17359555=6SZ683=355507270=10220.0271=4346=21023=710=087
1128=99=18135=X49=SAMPLE75=2016101134=319052=2007091318512968395955260=200709131851296839595525799=10000100268=1279=1269=048=17359555=6SZ683=355508270=10207.0271=12346=61023=610=129
1128=99=18135=X49=SAMPLE75=2016101134=233252=2004100621000199154377660=200410062100019915437765799=10000100268=1279=1269=048=17359555=6SZ683=355509270=10208.0271=40346=61023=510=134
1128=99=18135=X49=SAMPLE75=2016101134=234852=2002081208564519815928060=200208120856451981592805799=10000100268=1279=1269=148=17359555=6SZ683=355510270=10219.0271=51346=81023=610=126
1128=99=18135=X49=SAMPLE75=2016101134=334752=2007081918063212214179260=200708191806321221417925799=10000100268=1279=1269=048=17359555=6SZ683=355511270=10208.0271=10346=51023=510=142
1128=99=18135=X49=SAMPLE75=2016101134=301952=2012062400160223151955260=201206240016022315195525799=10000100268=1279=1269=148=17359555=6SZ683=355512270=10219.0271=21346=71023=610=121
1128=99=18135=X49=SAMPLE75=2016101134=422652=2016081507361892483872060=201608150736189248387205799=10000100268=1279=1269=048=17359555=6SZ683=355513270=10205.0271=51346=81023=810=130
1128=99=18135=X49=SAMPLE75=2016101134=440252=2005082211145578065337660=200508221114557806533765799=10000100268=1279=1269=048=17359555=6SZ683=355514270=10208.0271=40346=61023=510=116
1128=99=18135=X49=SAMPLE75=2016101134=101152=2007101306282539651548860=200710130628253965154885799=10000100268=1279=1269=148=17359555=6SZ683=355515270=10219.0271=51346=81023=610=136
1128=99=18135=X49=SAMPLE75=2016101134=381952=2014060110184558175449660=201406011018455817544965799=10000100268=1279=1269=048=17359555=6SZ683=355516270=10205.0271=21346=71023=810=157
1128=99=18135=X49=SAMPLE75=2016101134=85152=2016051715353844270380860=201605171535384427038085799=10000100268=1279=1269=148=17359555=6SZ683=355517270=10219.0271=21346=71023=610=133
1128=99=18235=X49=SAMPLE75=2016101134=379352=2010071618493555359673660=201007161849355535967365799=10000100268=1279=1269=048=17359555=6SZ683=355518270=10203.0271=34346=31023=1010=187
1128=99=18135=X49=SAMPLE75=2016101134=297152=2009100605524128549228860=200910060552412854922885799=10000100268=1279=1269=148=17359555=6SZ683=355519270=10220.0271=34346=31023=710=149
1128=99=18035=X49=SAMPLE75=2016101134=273052=2005012009224888078537660=200501200922488807853765799=10000100268=1279=1269=148=17359555=6SZ683=355520270=10218.0271=4346=21023=510=074
1128=99=18135=X49=SAMPLE75=2016101134=375052=2001011111565170475948060=200101111156517047594805799=10000100268=1279=1269=048=17359555=6SZ683=355521270=10208.0271=10346=51023=510=167
1128=99=18135=X49=SAMPLE75=2016101134=347652=2005051904354119843017660=200505190435411984301765799=10000100268=1279=1269=148=17359555=6SZ683=355522270=10222.0271=33346=21023=910=164
1128=99=18135=X49=SAMPLE75=2016101134=143852=2016020904251027958508860=201602090425102795850885799=10000100268=1279=1269=048=17359555=6SZ683=355523270=10204.0271=34346=31023=910=151
1128=99=18035=X49=SAMPLE75=2016101134=233352=2014091006501831278470460=201409100650183127847045799=10000100268=1279=1269=148=17359555=6SZ683=355524270=10220.0271=4346=21023=710=069
1128=99=18135=X49=SAMPLE75=2016101134=18052=2007040920033336812262460=200704092003333681226245799=10000100268=1279=1269=148=17359555=6SZ683=355525270=10219.0271=51346=81023=610=155
1128=99=18135=X49=SAMPLE75=2016101134=200752=2010123002335283355078460=201012300233528335507845799=10000100268=1279=1269=048=17359555=6SZ683=355526270=10203.0271=4346=21023=1010=154
1128=99=18135=X49=SAMPLE75=2016101134=383152=2006121123394375716208060=200612112339437571620805799=10000100268=1279=1269=048=17359555=6SZ683=355527270=10208.0271=40346=61023=510=160
1128=99=18035=X49=SAMPLE75=2016101134=479652=2012121711145408159328060=201212171114540815932805799=10000100268=1279=1269=148=17359555=6SZ683=355528270=10222.0271=3346=11023=910=102
1128=99=18135=X49=SAMPLE75=2016101134=199752=2012082919100628747692860=201208291910062874769285799=10000100268=1279=1269=148=17359555=6SZ683=355529270=10221.0271=43346=61023=810=132
1128=99=18135=X49=SAMPLE75=2016101134=445252=2000093021013714397196860=200009302101371439719685799=10000100268=1279=1269=148=17359555=6SZ683=355530270=10219.0271=21346=71023=610=145
1128=99=18135=X49=SAMPLE75=2016101134=394052=2012111215562108263648060=201211121556210826364805799=10000100268=1279=1269=148=17359555=6SZ683=355531270=10218.0271=34346=31023=510=128
1128=99=18135=X49=SAMPLE75=2016101134=346052=2014032909264282472160060=201403290926428247216005799=10000100268=1279=1269=148=17359555=6SZ683=355532270=10221.0271=13346=51023=810=153
1128=99=18035=X49=SAMPLE75=2016101134=350252=2008122917092758703900860=200812291709275870390085799=10000100268=1279=1269=048=17359555=6SZ683=355533270=10204.0271=4346=21023=910=093
1128=99=18035=X49=SAMPLE75=2016101134=438152=2000021417121872166077660=200002141712187216607765799=10000100268=1279=1269=148=17359555=6SZ683=355534270=10218.0271=4346=21023=510=057
1128=99=18135=X49=SAMPLE75=2016101134=231552=2016040216304789917632060=201604021630478991763205799=10000100268=1279=1269=048=17359555=6SZ683=355535270=10208.0271=10346=51023=510=144
1128=99=18235=X49=SAMPLE75=2016101134=444852=2005080402225014518454460=200508040222501451845445799=10000100268=1279=1269=048=17359555=6SZ683=355536270=10203.0271=34346=31023=1010=170
1128=99=18135=X49=SAMPLE75=2016101134=128152=2009042623071227646182460=200904262307122764618245799=10000100268=1279=1269=148=17359555=6SZ683=355537270=10218.0271=34346=31023=510=146
1128=99=18135=X49=SAMPLE75=2016101134=422852=2009120918455801276281660=200912091845580127628165799=10000100268=1279=1269=048=17359555=6SZ683=355538270=10208.0271=40346=61023=510=169
1128=99=18135=X49=SAMPLE75=2016101134=166152=2007121321130826719168060=200712132113082671916805799=10000100268=1279=1269=148=17359555=6SZ683=355539270=10221.0271=43346=61023=810=146
1128=99=18135=X49=SAMPLE75=2016101134=4352=2010081302431682114508860=201008130243168211450885799=10000100268=1279=1269=048=17359555=6SZ683=355540270=10208.0271=10346=51023=510=125
1128=99=18135=X49=SAMPLE75=2016101134=362652=2010040310374926773856060=201004031037492677385605799=10000100268=1279=1269=148=17359555=6SZ683=355541270=10221.0271=13346=51023=810=133
1128=99=18135=X49=SAMPLE75=2016101134=277052=2007082018453799028966460=200708201845379902896645799=10000100268=1279=1269=048=17359555=6SZ683=355542270=10209.0271=35346=41023=410=137
1128=99=25135=X49=SAMPLE75=2016101134=257552=2016050602122271406457660=201605060212227140645765799=10000100268=2279=1269=048=17359555=6SZ683=355543270=10212.0271=3346=31023=1279=1269=048=17359555=6SZ683=355544270=10208.0271=9346=41023=510=147
1128=99=18135=X49=SAMPLE75=2016101134=485152=2006100322494340733715260=200610032249434073371525799=10000100268=1279=1269=048=17359555=6SZ683=355545270=10206.0271=34346=31023=710=163
1128=99=18135=X49=SAMPLE75=2016101134=91052=2010100616405505212806460=201010061640550521280645799=10000100268=1279=1269=048=17359555=6SZ683=355546270=10203.0271=4346=21023=1010=147
1128=99=18135=X49=SAMPLE75=2016101134=327152=2009031418315110962892860=200903141831511096289285799=10000100268=1279=1269=148=17359555=6SZ683=355547270=10220.0271=34346=31023=710=169
1128=99=18035=X49=SAMPLE75=2016101134=328452=2010102610492128097708860=201010261049212809770885799=10000100268=1279=1269=048=17359555=6SZ683=355548270=10206.0271=4346=21023=710=110
1128=99=18135=X49=SAMPLE75=2016101134=292052=2009082408325568250790460=200908240832556825079045799=10000100268=1279=1269=048=17359555=6SZ683=355549270=10206.0271=34346=31023=710=160
1128=99=18035=X49=SAMPLE75=2016101134=50852=2015120701581149342579260=201512070158114934257925799=10000100268=1279=1269=148=17359555=6SZ683=355550270=10220.0271=4346=21023=710=084
1128=99=18135=X49=SAMPLE75=2016101134=126052=2015010210441977779801660=201501021044197777980165799=10000100268=1279=1269=148=17359555=6SZ683=355551270=10221.0271=43346=61023=810=136
1128=99=18135=X49=SAMPLE75=2016101134=329052=2009040204345454439680060=200904020434545443968005799=10000100268=1279=1269=148=17359555=6SZ683=355552270=10221.0271=13346=51023=810=121
1128=99=18135=X49=SAMPLE75=2016101134=49552=2000081921263104600722460=200008192126310460072245799=10000100268=1279=1269=148=17359555=6SZ683=355553270=10220.0271=34346=31023=710=140
1128=99=18035=X49=SAMPLE75=2016101134=72852=2003081123234456657512060=200308112323445665751205799=10000100268=1279=1269=048=17359555=6SZ683=355554270=10209.0271=5346=31023=410=083
1128=99=18135=X49=SAMPLE75=2016101134=135852=2009020116010243406800060=200902011601024340680005799=10000100268=1279=1269=048=17359555=6SZ683=355555270=10205.0271=51346=81023=810=150
1128=99=18135=X49=SAMPLE75=2016101134=79752=2004010405485081548630460=200401040548508154863045799=10000100268=1279=1269=048=17359555=6SZ683=355556270=10205.0271=21346=71023=810=126
1128=99=18135=X49=SAMPLE75=2016101134=135252=2013092215324089861491260=201309221532408986149125799=10000100268=1279=1269=048=17359555=6SZ683=355557270=10209.0271=35346=41023=410=151
1128=99=18035=X49=SAMPLE75=2016101134=4152=2015042314344296980083260=201504231434429698008325799=10000100268=1279=1269=048=17359555=6SZ683=355558270=10211.0271=3346=21023=210=065
1128=99=18035=X49=SAMPLE75=2016101134=335952=2006111009024699102707260=200611100902469910270725799=10000100268=1279=1269=048=17359555=6SZ683=355559270=10212.0271=4346=41023=110=084
1128=99=18035=X49=SAMPLE75=2016101134=336852=2013062917540293503692860=201306291754029350369285799=10000100268=1279=1269=048=17359555=6SZ683=355560270=10206.0271=4346=21023=710=058
1128=99=18035=X49=SAMPLE75=2016101134=382152=2006060307242180833811260=200606030724218083381125799=10000100268=1279=1269=148=17359555=6SZ683=355561270=10220.0271=4346=21023=710=066
1128=99=18135=X49=SAMPLE75=2016101134=124152=2011122110102285296889660=201112211010228529688965799=10000100268=1279=1269=048=17359555=6SZ683=355562270=10206.0271=34346=31023=710=141
1128=99=18135=X49=SAMPLE75=2016101134=255652=2005122913105916672496060=200512291310591667249605799=10000100268=1279=1269=148=17359555=6SZ683=355563270=10220.0271=34346=31023=710=130
1128=99=18035=X49=SAMPLE75=2016101134=32052=2013111011522118512889660=201311101152211851288965799=10000100268=1279=1269=048=17359555=6SZ683=355564270=10206.0271=4346=21023=710=090
1128=99=18135=X49=SAMPLE75=2016101134=12952=2014102312163850151763260=201410231216385015176325799=10000100268=1279=1269=048=17359555=6SZ683=355565270=10206.0271=34346=31023=710=128
1128=99=25235=X49=SAMPLE75=2016101134=363552=2001050419094403876003260=200105041909440387600325799=10000100268=2279=1269=048=17359555=6SZ683=355566270=10212.0271=3346=31023=1279=1269=048=17359555=6SZ683=355567270=10208.0271=10346=51023=510=155
1128=99=18035=X49=SAMPLE75=2016101134=79152=2012052514111907968704060=201205251411190796870405799=10000100268=1279=1269=048=17359555=6SZ683=355568270=10209.0271=5346=31023=410=105
1128=99=18035=X49=SAMPLE75=2016101134=105452=2009061003102773208499260=200906100310277320849925799=10000100268=1279=1269=048=17359555=6SZ683=355569270=10206.0271=4346=21023=710=087
1128=99=18035=X49=SAMPLE75=2016101134=300752=2013041904332909485683260=201304190433290948568325799=10000100268=1279=1269=148=17359555=6SZ683=355570270=10220.0271=4346=21023=710=070
1128=99=18135=X49=SAMPLE75=2016101134=272052=2010061620583656733542460=201006162058365673354245799=10000100268=1279=1269=048=17359555=6SZ683=355571270=10208.0271=40346=61023=510=145
1128=99=18135=X49=SAMPLE75=2016101134=179952=2012120801122344602131260=201212080112234460213125799=10000100268=1279=1269=048=17359555=6SZ683=355572270=10206.0271=34346=31023=710=117
1128=99=18135=X49=SAMPLE75=2016101134=414652=2010030614484903755993660=201003061448490375599365799=10000100268=1279=1269=148=17359555=6SZ683=355573270=10220.0271=34346=31023=710=154
1128=99=18035=X49=SAMPLE75=2016101134=46052=2007052509012317613836860=200705250901231761383685799=10000100268=1279=1269=048=17359555=6SZ683=355574270=10206.0271=4346=21023=710=075
1128=99=18135=X49=SAMPLE75=2016101134=325552=2007120821320461724275260=200712082132046172427525799=10000100268=1279=1269=048=17359555=6SZ683=355575270=10206.0271=34346=31023=710=130
1128=99=18035=X49=SAMPLE75=2016101134=148452=2009021506032367214438460=200902150603236721443845799=10000100268=1279=1269=148=17359555=6SZ683=355576270=10220.0271=4346=21023=710=061
1128=99=18135=X49=SAMPLE75=2016101134=212752=2012012407294501386771260=201201240729450138677125799=10000100268=1279=1269=148=17359555=6SZ683=355577270=10221.0271=43346=61023=810=140
1128=99=18135=X49=SAMPLE75=2016101134=296052=2017022411323585877888060=201702241132358587788805799=10000100268=1279=1269=148=17359555=6SZ683=355578270=10221.0271=13346=51023=810=151
1128=99=18135=X49=SAMPLE75=2016101134=90152=2008083116525096476544060=200808311652509647654405799=10000100268=1279=1269=148=17359555=6SZ683=355579270=10221.0271=43346=61023=810=137
1128=99=18135=X49=SAMPLE75=2016101134=309352=2006100816062164090694460=200610081606216409069445799=10000100268=1279=1269=148=17359555=6SZ683=355580270=10221.0271=13346=51023=810=131
1128=99=18135=X49=SAMPLE75=2016101134=495652=2000072820221598120993260=200007282022159812099325799=10000100268=1279=1269=148=17359555=6SZ683=355581270=10220.0271=34346=31023=710=119
1128=99=18035=X49=SAMPLE75=2016101134=229952=2011112612550740497926460=201111261255074049792645799=10000100268=1279=1269=148=17359555=6SZ683=355582270=10220.0271=4346=21023=710=083
1128=99=18035=X49=SAMPLE75=2016101134=357452=2000032006391729613306460=200003200639172961330645799=10000100268=1279=1269=048=17359555=6SZ683=355583270=10206.0271=4346=21023=710=086
1128=99=18135=X49=SAMPLE75=2016101134=129952=2001021009300162756131260=200102100930016275613125799=10000100268=1279=1269=148=17359555=6SZ683=355584270=10221.0271=43346=61023=810=140
1128=99=18135=X49=SAMPLE75=2016101134=181152=2011051817483695127616060=201105181748369512761605799=10000100268=1279=1269=048=17359555=6SZ683=355585270=10206.0271=34346=31023=710=160
1128=99=18135=X49=SAMPLE75=2016101134=461952=2014072417083145798956860=201407241708314579895685799=10000100268=1279=1269=148=17359555=6SZ683=355586270=10221.0271=13346=51023=810=157
1128=99=18135=X49=SAMPLE75=2016101134=201052=2007020321012096338595260=200702032101209633859525799=10000100268=1279=1269=148=17359555=6SZ683=355587270=10220.0271=34346=31023=710=144
1128=99=18035=X49=SAMPLE75=2016101134=240052=2002052218474599823649660=200205221847459982364965799=10000100268=1279=1269=148=17359555=6SZ683=355588270=10220.0271=4346=21023=710=092
1128=99=18035=X49=SAMPLE75=2016101134=321152=2006071121410198448025660=200607112141019844802565799=10000100268=1279=1269=048=17359555=6SZ683=355589270=10206.0271=4346=21023=710=079
1128=99=18135=X49=SAMPLE75=2016101134=389352=2001031807502805388819260=200103180750280538881925799=10000100268=1279=1269=048=17359555=6SZ683=355590270=10208.0271=10346=51023=510=130
1128=99=18135=X49=SAMPLE75=2016101134=26952=2006060522402902557798460=200606052240290255779845799=10000100268=1279=1269=048=17359555=6SZ683=355591270=10209.0271=35346=41023=410=121
1128=99=25135=X49=SAMPLE75=2016101134=327852=2004063004083596279600060=200406300408359627960005799=10000100268=2279=1269=048=17359555=6SZ683=355592270=10212.0271=4346=41023=1279=1269=048=17359555=6SZ683=355593270=10208.0271=9346=41023=510=117
1128=99=18035=X49=SAMPLE75=2016101134=98652=2003122819364992846681660=200312281936499284668165799=10000100268=1279=1269=048=17359555=6SZ683=355594270=10212.0271=7346=51023=110=082
1128=99=17935=X49=SAMPLE75=2016101134=167652=2001032514532191023220060=200103251453219102322005799=10000100268=1279=0269=048=17360055=6SH783=99092270=10265.0271=3346=11023=110=015
1128=99=24935=X49=SAMPLE75=2016101134=102052=2015081211024628625548860=201508121102462862554885799=10000100268=2279=1269=048=17360055=6SH783=99093270=10264.0271=5346=21023=2279=1269=048=17360055=6SH783=99094270=10262.0271=3346=11023=410=243
1128=99=18135=X49=SAMPLE75=2016101134=92952=2003041607440425104638460=200304160744042510463845799=10000100268=1279=1269=148=17359555=6SZ683=355595270=10220.0271=34346=31023=710=137
1128=99=18135=X49=SAMPLE75=2016101134=335952=2016010521580614988454460=201601052158061498845445799=10000100268=1279=1269=048=17359555=6SZ683=355596270=10206.0271=34346=31023=710=132
1128=99=18035=X49=SAMPLE75=2016101134=468652=2010113020182073684544060=201011302018207368454405799=10000100268=1279=1269=148=17359555=6SZ683=355597270=10220.0271=4346=21023=710=110
1128=99=18135=X49=SAMPLE75=2016101134=106552=2009030317424691743507260=200903031742469174350725799=10000100268=1279=1269=148=17359555=6SZ683=355598270=10220.0271=34346=31023=710=145
1128=99=18035=X49=SAMPLE75=2016101134=75052=2017010118492923175564860=201701011849292317556485799=10000100268=1279=1269=048=17359555=6SZ683=355599270=10206.0271=4346=21023=710=103
1128=99=18135=X49=SAMPLE75=2016101134=489852=2003101109544665161590460=200310110954466516159045799=10000100268=1279=1269=048=17359555=6SZ683=355600270=10206.0271=34346=31023=710=126
1128=99=18035=X49=SAMPLE75=2016101134=275952=2010051020153065327948860=201005102015306532794885799=10000100268=1279=1269=148=17359555=6SZ683=355601270=10220.0271=4346=21023=710=096
1128=99=18135=X49=SAMPLE75=2016101134=465952=2015072101340694067833660=201507210134069406783365799=10000100268=1279=1269=148=17359555=6SZ683=355602270=10220.0271=34346=31023=710=144
1128=99=18035=X49=SAMPLE75=2016101134=435952=2010052304045990454310460=201005230404599045431045799=10000100268=1279=1269=148=17359555=6SZ683=355603270=10220.0271=4346=21023=710=091
1128=99=18035=X49=SAMPLE75=2016101134=9652=2012030315180198451244860=201203031518019845124485799=10000100268=1279=1269=048=17359555=6SZ683=355604270=10209.0271=5346=31023=410=097
1128=99=25235=X49=SAMPLE75=2016101134=467852=2015050105343136586304060=201505010534313658630405799=10000100268=2279=1269=048=17359555=6SZ683=355605270=10212.0271=6346=41023=1279=1269=048=17359555=6SZ683=355606270=10208.0271=10346=51023=510=184
1128=99=18135=X49=SAMPLE75=2016101134=273052=2013121502505616207680060=201312150250561620768005799=10000100268=1279=1269=048=17359555=6SZ683=355607270=10205.0271=51346=81023=810=160
1128=99=25135=X49=SAMPLE75=2016101134=187852=2005111811000762604300860=200511181100076260430085799=10000100268=2279=1269=048=17359555=6SZ683=355608270=10210.0271=5346=31023=3279=1269=048=17359555=6SZ683=355609270=10209.0271=4346=21023=410=151
1128=99=18135=X49=SAMPLE75=2016101134=136352=2015041522432091408787260=201504152243209140878725799=10000100268=1279=1269=148=17359555=6SZ683=355610270=10220.0271=34346=31023=710=134
1128=99=18135=X49=SAMPLE75=2016101134=416852=2001020705571044604080460=200102070557104460408045799=10000100268=1279=1269=048=17359555=6SZ683=355611270=10208.0271=40346=61023=510=135
1128=99=18135=X49=SAMPLE75=2016101134=397052=2016082817061066164121660=201608281706106616412165799=10000100268=1279=1269=048=17359555=6SZ683=355612270=10205.0271=21346=71023=810=130
1128=99=25135=X49=SAMPLE75=2016101134=235052=2009042615282197433440060=200904261528219743344005799=10000100268=2279=1269=048=17359555=6SZ683=355613270=10210.0271=4346=21023=3279=1269=048=17359555=6SZ683=355614270=10209.0271=5346=31023=410=117
1128=99=18035=X49=SAMPLE75=2016101134=394152=2005022107111910431926460=200502210711191043192645799=10000100268=1279=1269=048=17359555=6SZ683=355615270=10206.0271=4346=21023=710=102
1128=99=18135=X49=SAMPLE75=2016101134=58452=2014060210204343351744060=201406021020434335174405799=10000100268=1279=1269=048=17359555=6SZ683=355616270=10206.0271=34346=31023=710=143
1128=99=18035=X49=SAMPLE75=2016101134=368452=2007072320593564117100860=200707232059356411710085799=10000100268=1279=1269=148=17359555=6SZ683=355617270=10220.0271=4346=21023=710=100
1128=99=18035=X49=SAMPLE75=2016101134=250552=2002061407442998264092860=200206140744299826409285799=10000100268=1279=1269=048=17359555=6SZ683=355618270=10206.0271=4346=21023=710=105
1128=99=18135=X49=SAMPLE75=2016101134=34652=2014052217484406236569660=201405221748440623656965799=10000100268=1279=1269=148=17359555=6SZ683=355619270=10220.0271=34346=31023=710=127
1128=99=18135=X49=SAMPLE75=2016101134=143352=2004051720294479871227260=200405172029447987122725799=10000100268=1279=1269=048=17359555=6SZ683=355620270=10206.0271=34346=31023=710=151
1128=99=18035=X49=SAMPLE75=2016101134=270752=2001022515032705995568860=200102251503270599556885799=10000100268=1279=1269=048=17359555=6SZ683=355621270=10206.0271=4346=21023=710=104
1128=99=18035=X49=SAMPLE75=2016101134=257552=2000012122431052308306660=200001212243105230830665799=10000100268=1279=1269=148=17359555=6SZ683=355622270=10220.0271=4346=21023=710=107
1128=99=18135=X49=SAMPLE75=2016101134=290952=2010071900003896038496060=201007190000389603849605799=10000100268=1279=1269=048=17359555=6SZ683=355623270=10206.0271=34346=31023=710=098
1128=99=18035=X49=SAMPLE75=2016101134=314152=2006110723334415176579260=200611072333441517657925799=10000100268=1279=1269=048=17359555=6SZ683=355624270=10206.0271=4346=21023=710=077
1128=99=18135=X49=SAMPLE75=2016101134=13852=2004120301532539953913660=200412030153253995391365799=10000100268=1279=1269=148=17359555=6SZ683=355625270=10221.0271=43346=61023=810=112
1128=99=18135=X49=SAMPLE75=2016101134=262052=2004040119563910447264060=200404011956391044726405799=10000100268=1279=1269=048=17359555=6SZ683=355626270=10206.0271=34346=31023=710=149
1128=99=18035=X49=SAMPLE75=2016101134=105552=2006110113525526499945660=200611011352552649994565799=10000100268=1279=1269=048=17359555=6SZ683=355627270=10206.0271=4346=21023=710=048
1128=99=18135=X49=SAMPLE75=2016101134=280952=2014122114260203209977660=201412211426020320997765799=10000100268=1279=1269=148=17359555=6SZ683=355628270=10221.0271=13346=51023=810=105
1128=99=18135=X49=SAMPLE75=2016101134=107852=2017021203150045563276860=201702120315004556327685799=10000100268=1279=1269=148=17359555=6SZ683=355629270=10220.0271=34346=31023=710=120
1128=99=18135=X49=SAMPLE75=2016101134=259152=2013072010160071666169660=201307201016007166616965799=10000100268=1279=1269=048=17359555=6SZ683=355630270=10206.0271=34346=31023=710=134
1128=99=18135=X49=SAMPLE75=2016101134=43652=2012072908471001101260860=201207290847100110126085799=10000100268=1279=1269=048=17359555=6SZ683=355631270=10207.0271=42346=71023=610=139
1128=99=18035=X49=SAMPLE75=2016101134=223152=2003021515223249235681660=200302151522324923568165799=10000100268=1279=1269=048=17359555=6SZ683=355632270=10206.0271=4346=21023=710=095
1128=99=18035=X49=SAMPLE75=2016101134=379052=2006051907343151751619260=200605190734315175161925799=10000100268=1279=1269=148=17359555=6SZ683=355633270=10220.0271=4346=21023=710=057
1128=99=18135=X49=SAMPLE75=2016101134=334752=2011071913583884370944060=201107191358388437094405799=10000100268=1279=1269=048=17359555=6SZ683=355634270=10207.0271=12346=61023=610=131
1128=99=18235=X49=SAMPLE75=2016101134=314052=2004012622184336861086460=200401262218433686108645799=10000100268=1279=1269=148=17359555=6SZ683=355635270=10223.0271=39346=41023=1010=177
1128=99=18135=X49=SAMPLE75=2016101134=304852=2007090614104697761673660=200709061410469776167365799=10000100268=1279=1269=048=17359555=6SZ683=355636270=10207.0271=42346=71023=610=151
1128=99=18135=X49=SAMPLE75=2016101134=273652=2003042418535179916315260=200304241853517991631525799=10000100268=1279=1269=148=17359555=6SZ683=355637270=10223.0271=9346=31023=1010=116
1128=99=18135=X49=SAMPLE75=2016101134=95952=2016083003422965512940860=201608300342296551294085799=10000100268=1279=1269=148=17359555=6SZ683=355638270=10220.0271=34346=31023=710=138
1128=99=18035=X49=SAMPLE75=2016101134=272552=2003032122414252443084860=200303212241425244308485799=10000100268=1279=1269=048=17359555=6SZ683=355639270=10212.0271=5346=31023=110=082
1128=99=25135=X49=SAMPLE75=2016101134=488252=2006082820331023588150460=200608282033102358815045799=10000100268=2279=2269=048=17360055=6SH783=99095270=10265.0271=3346=11023=1279=0269=048=17360055=6SH783=99096270=10255.0271=53346=21023=1010=097
1128=99=18035=X49=SAMPLE75=2016101134=239152=2010101202534585933824060=201010120253458593382405799=10000100268=1279=1269=148=17359555=6SZ683=355640270=10220.0271=4346=21023=710=082
1128=99=18135=X49=SAMPLE75=2016101134=120952=2001011103020839635897260=200101110302083963589725799=10000100268=1279=1269=048=17359555=6SZ683=355641270=10207.0271=12346=61023=610=148
1128=99=18135=X49=SAMPLE75=2016101134=422852=2012031901295230636121660=201203190129523063612165799=10000100268=1279=1269=148=17359555=6SZ683=355642270=10221.0271=43346=61023=810=138
1128=99=18135=X49=SAMPLE75=2016101134=465752=2010080723044058257971260=201008072304405825797125799=10000100268=1279=1269=048=17359555=6SZ683=355643270=10207.0271=42346=71023=610=146
1128=99=18135=X49=SAMPLE75=2016101134=122952=2008121205305767553472060=200812120530576755347205799=10000100268=1279=1269=148=17359555=6SZ683=355644270=10221.0271=13346=51023=810=130
1128=99=18135=X49=SAMPLE75=2016101134=135352=2008030212374564209699260=200803021237456420969925799=10000100268=1279=1269=148=17359555=6SZ683=355645270=10220.0271=34346=31023=710=115
1128=99=18035=X49=SAMPLE75=2016101134=446352=2008032423270611981401660=200803242327061198140165799=10000100268=1279=1269=148=17359555=6SZ683=355646270=10220.0271=4346=21023=710=098
1128=99=18135=X49=SAMPLE75=2016101134=49152=2011021803195246779577660=201102180319524677957765799=10000100268=1279=1269=148=17359555=6SZ683=355647270=10221.0271=43346=61023=810=142
1128=99=18135=X49=SAMPLE75=2016101134=284252=2002111312591624799684860=200211131259162479968485799=10000100268=1279=1269=148=17359555=6SZ683=355648270=10221.0271=13346=51023=810=114
1128=99=18135=X49=SAMPLE75=2016101134=76052=2015060609052196602963260=201506060905219660296325799=10000100268=1279=1269=148=17359555=6SZ683=355649270=10220.0271=34346=31023=710=119
1128=99=18135=X49=SAMPLE75=2016101134=150052=2015031121521044688620860=201503112152104468862085799=10000100268=1279=1269=048=17359555=6SZ683=355650270=10207.0271=12346=61023=610=120
1128=99=18135=X49=SAMPLE75=2016101134=119252=2001080512320652447037660=200108051232065244703765799=10000100268=1279=1269=048=17359555=6SZ683=355651270=10207.0271=42346=71023=610=145
1128=99=18035=X49=SAMPLE75=2016101134=230952=2006041110445328436809660=200604111044532843680965799=10000100268=1279=1269=148=17359555=6SZ683=355652270=10220.0271=4346=21023=710=085
1128=99=18135=X49=SAMPLE75=2016101134=156852=2002121608262502800888060=200212160826250280088805799=10000100268=1279=1269=048=17359555=6SZ683=355653270=10207.0271=12346=61023=610=136
1128=99=18135=X49=SAMPLE75=2016101134=130052=2013121911041299098668860=201312191104129909866885799=10000100268=1279=1269=148=17359555=6SZ683=355654270=10220.0271=34346=31023=710=149
1128=99=18135=X49=SAMPLE75=2016101134=181752=2000103001081925947098460=200010300108192594709845799=10000100268=1279=1269=048=17359555=6SZ683=355655270=10207.0271=42346=71023=610=136
1128=99=18035=X49=SAMPLE75=2016101134=432552=2009090618303056195014460=200909061830305619501445799=10000100268=1279=1269=148=17359555=6SZ683=355656270=10220.0271=4346=21023=710=098
1128=99=18135=X49=SAMPLE75=2016101134=411852=2005050212590862721836860=200505021259086272183685799=10000100268=1279=1269=048=17359555=6SZ683=355657270=10207.0271=12346=61023=610=172
1128=99=18135=X49=SAMPLE75=2016101134=408952=2015051423232878708870460=201505142323287870887045799=10000100268=1279=1269=148=17359555=6SZ683=355658270=10220.0271=34346=31023=710=130
1128=99=18135=X49=SAMPLE75=2016101134=367852=2010082109454629896569660=201008210945462989656965799=10000100268=1279=1269=048=17359555=6SZ683=355659270=10207.0271=42346=71023=610=127
1128=99=18035=X49=SAMPLE75=2016101134=143452=2007090622413951528988860=200709062241395152898885799=10000100268=1279=1269=148=17359555=6SZ683=355660270=10220.0271=4346=21023=710=089
1128=99=18135=X49=SAMPLE75=2016101134=403752=2004031606381190749488060=200403160638119074948805799=10000100268=1279=1269=148=17359555=6SZ683=355661270=10220.0271=34346=31023=710=129
1128=99=18035=X49=SAMPLE75=2016101134=180452=2015070120510656809971260=201507012051065680997125799=10000100268=1279=1269=148=17359555=6SZ683=355662270=10220.0271=4346=21023=710=087
1128=99=18135=X49=SAMPLE75=2016101134=198452=2004081720401612005910460=200408172040161200591045799=10000100268=1279=1269=048=17359555=6SZ683=355663270=10207.0271=12346=61023=610=161
1128=99=18135=X49=SAMPLE75=2016101134=447352=2002010707262511161747260=200201070726251116174725799=10000100268=1279=1269=148=17359555=6SZ683=355664270=10221.0271=43346=61023=810=181
1128=99=18135=X49=SAMPLE75=2016101134=7452=2007100207251313654457660=200710020725131365445765799=10000100268=1279=1269=048=17359555=6SZ683=355665270=10207.0271=42346=71023=610=152
1128=99=18135=X49=SAMPLE75=2016101134=404452=2000022618092816033802460=200002261809281603380245799=10000100268=1279=1269=148=17359555=6SZ683=355666270=10221.0271=13346=51023=810=152
1128=99=18135=X49=SAMPLE75=2016101134=14452=2008022900482973642339260=200802290048297364233925799=10000100268=1279=1269=148=17359555=6SZ683=355667270=10220.0271=34346=31023=710=160
1128=99=18035=X49=SAMPLE75=2016101134=65652=2012121103283421391782460=201212110328342139178245799=10000100268=1279=1269=148=17359555=6SZ683=355668270=10220.0271=4346=21023=710=117
1128=99=18135=X49=SAMPLE75=2016101134=401152=2014110108455297778745660=201411010845529777874565799=10000100268=1279=1269=148=17359555=6SZ683=355669270=10221.0271=43346=61023=810=135
1128=99=18035=X49=SAMPLE75=2016101134=397752=2001012722240015703988860=200101272224001570398885799=10000100268=1279=1269=048=17359555=6SZ683=355670270=10212.0271=6346=41023=110=036
1128=99=17935=X49=SAMPLE75=2016101134=228852=2013031104554135909555260=201303110455413590955525799=10000100268=1279=0269=048=17360055=6SH783=99097270=10265.0271=3346=11023=110=254
1128=99=18135=X49=SAMPLE75=2016101134=168152=2014073020391311406252860=201407302039131140625285799=10000100268=1279=1269=048=17359555=6SZ683=355671270=10207.0271=12346=61023=610=130
1128=99=18135=X49=SAMPLE75=2016101134=465352=2015072412555679231929660=201507241255567923192965799=10000100268=1279=1269=148=17359555=6SZ683=355672270=10220.0271=34346=31023=710=136
1128=99=18135=X49=SAMPLE75=2016101134=255552=2002082118012264031734460=200208211801226403173445799=10000100268=1279=1269=148=17359555=6SZ683=355673270=10221.0271=13346=51023=810=130
1128=99=18135=X49=SAMPLE75=2016101134=198552=2005110603172610154214460=200511060317261015421445799=10000100268=1279=1269=048=17359555=6SZ683=355674270=10207.0271=42346=71023=610=140
1128=99=18035=X49=SAMPLE75=2016101134=41152=2005101201374662847472060=200510120137466284747205799=10000100268=1279=1269=148=17359555=6SZ683=355675270=10220.0271=4346=21023=710=086
1128=99=18135=X49=SAMPLE75=2016101134=190252=2002012121063471686526460=200201212106347168652645799=10000100268=1279=1269=048=17359555=6SZ683=355676270=10207.0271=12346=61023=610=137
1128=99=18135=X49=SAMPLE75=2016101134=14352=2012030702022232529977660=201203070202223252997765799=10000100268=1279=1269=148=17359555=6SZ683=355677270=10221.0271=43346=61023=810=133
1128=99=18135=X49=SAMPLE75=2016101134=130352=2001061121533852307840860=200106112153385230784085799=10000100268=1279=1269=048=17359555=6SZ683=355678270=10207.0271=42346=71023=610=149
1128=99=18135=X49=SAMPLE75=2016101134=372652=2016030508275577415244860=201603050827557741524485799=10000100268=1279=1269=148=17359555=6SZ683=355679270=10221.0271=13346=51023=810=151
1128=99=18135=X49=SAMPLE75=2016101134=152952=2002020509585418271319260=200202050958541827131925799=10000100268=1279=1269=148=17359555=6SZ683=355680270=10220.0271=34346=31023=710=134
1128=99=18035=X49=SAMPLE75=2016101134=193252=2003061923593136938393660=200306192359313693839365799=10000100268=1279=1269=148=17359555=6SZ683=355681270=10220.0271=4346=21023=710=077
1128=99=18135=X49=SAMPLE75=2016101134=51252=2008062912534368530780860=200806291253436853078085799=10000100268=1279=1269=148=17359555=6SZ683=355682270=10221.0271=43346=61023=810=147
1128=99=18135=X49=SAMPLE75=2016101134=100752=2013012001455171276396860=201301200145517127639685799=10000100268=1279=1269=148=17359555=6SZ683=355683270=10221.0271=13346=51023=810=154
1128=99=18135=X49=SAMPLE75=2016101134=263652=2003071006530604785000060=200307100653060478500005799=10000100268=1279=1269=148=17359555=6SZ683=355684270=10220.0271=34346=31023=710=156
1128=99=18135=X49=SAMPLE75=2016101134=174252=2006122105031827889766460=200612210503182788976645799=10000100268=1279=1269=048=17359555=6SZ683=355685270=10207.0271=12346=61023=610=140
1128=99=18135=X49=SAMPLE75=2016101134=446152=2002111501230856651358460=200211150123085665135845799=10000100268=1279=1269=048=17359555=6SZ683=355686270=10206.0271=34346=31023=710=145
1128=99=18035=X49=SAMPLE75=2016101134=256952=2013062621561284750112060=201306262156128475011205799=10000100268=1279=1269=048=17359555=6SZ683=355687270=10206.0271=4346=21023=710=108
1128=99=18135=X49=SAMPLE75=2016101134=285352=2002111509090872050043260=200211150909087205004325799=10000100268=1279=1269=048=17359555=6SZ683=355688270=10207.0271=42346=71023=610=161
1128=99=18035=X49=SAMPLE75=2016101134=476352=2011052909090021792185660=201105290909002179218565799=10000100268=1279=1269=148=17359555=6SZ683=355689270=10220.0271=4346=21023=710=093
1128=99=18135=X49=SAMPLE75=2016101134=79652=2002040808002455355894460=200204080800245535589445799=10000100268=1279=1269=048=17359555=6SZ683=355690270=10207.0271=12346=61023=610=140
1128=99=18135=X49=SAMPLE75=2016101134=286652=2001071717143832358817660=200107171714383235881765799=10000100268=1279=1269=148=17359555=6SZ683=355691270=10220.0271=34346=31023=710=139
1128=99=18135=X49=SAMPLE75=2016101134=29152=2003121323093544022523260=200312132309354402252325799=10000100268=1279=1269=048=17359555=6SZ683=355692270=10207.0271=42346=71023=610=131
1128=99=18035=X49=SAMPLE75=2016101134=110452=2013032614452584378150460=201303261445258437815045799=10000100268=1279=1269=148=17359555=6SZ683=355693270=10220.0271=4346=21023=710=092
1128=99=18135=X49=SAMPLE75=2016101134=485952=2011111102404297160755260=201111110240429716075525799=10000100268=1279=1269=048=17359555=6SZ683=355694270=10207.0271=12346=61023=610=166
1128=99=18135=X49=SAMPLE75=2016101134=241152=2003092721215488352824060=200309272121548835282405799=10000100268=1279=1269=148=17359555=6SZ683=355695270=10220.0271=34346=31023=710=155
1128=99=18135=X49=SAMPLE75=2016101134=126652=2011030913564368153420860=201103091356436815342085799=10000100268=1279=1269=048=17359555=6SZ683=355696270=10207.0271=42346=71023=610=177
1128=99=18035=X49=SAMPLE75=2016101134=400352=2016122911301375451987260=201612291130137545198725799=10000100268=1279=1269=148=17359555=6SZ683=355697270=10220.0271=4346=21023=710=086
1128=99=18135=X49=SAMPLE75=2016101134=32752=2004103108501561068294460=200410310850156106829445799=10000100268=1279=1269=148=17359555=6SZ683=355698270=10220.0271=34346=31023=710=136
1128=99=18035=X49=SAMPLE75=2016101134=411452=2013100413453057315532860=201310041345305731553285799=10000100268=1279=1269=148=17359555=6SZ683=355699270=10220.0271=4346=21023=710=116
1128=99=18135=X49=SAMPLE75=2016101134=236152=2011080208000888323596860=201108020800088832359685799=10000100268=1279=1269=148=17359555=6SZ683=355700270=10220.0271=34346=31023=710=138
1128=99=18035=X49=SAMPLE75=2016101134=184052=2008091612484715344358460=200809161248471534435845799=10000100268=1279=1269=148=17359555=6SZ683=355701270=10220.0271=4346=21023=710=088
1128=99=18135=X49=SAMPLE75=2016101134=14752=2008090314155944217200060=200809031415594421720005799=10000100268=1279=1269=048=17359555=6SZ683=355702270=10207.0271=12346=61023=610=131
1128=99=18135=X49=SAMPLE75=2016101134=144452=2001050309232060084193660=200105030923206008419365799=10000100268=1279=1269=148=17359555=6SZ683=355703270=10222.0271=33346=21023=910=142
1128=99=18135=X49=SAMPLE75=2016101134=108252=2010021011585527823558460=201002101158552782355845799=10000100268=1279=1269=048=17359555=6SZ683=355704270=10207.0271=42346=71023=610=126
1128=99=18135=X49=SAMPLE75=2016101134=377452=2015120806160854965977660=201512080616085496597765799=10000100268=1279=1269=148=17359555=6SZ683=355705270=10220.0271=34346=31023=710=136
1128=99=18035=X49=SAMPLE75=2016101134=122552=2002071201383009613372860=200207120138300961337285799=10000100268=1279=1269=148=17359555=6SZ683=355706270=10222.0271=3346=11023=910=095
1128=99=18035=X49=SAMPLE75=2016101134=352652=2015021718542806311468860=201502171854280631146885799=10000100268=1279=1269=148=17359555=6SZ683=355707270=10220.0271=4346=21023=710=082
1128=99=18135=X49=SAMPLE75=2016101134=406052=2009032612414416201420860=200903261241441620142085799=10000100268=1279=1269=148=17359555=6SZ683=355708270=10220.0271=34346=31023=710=125
1128=99=18135=X49=SAMPLE75=2016101134=418952=2008111223305936632761660=200811122330593663276165799=10000100268=1279=1269=048=17359555=6SZ683=355709270=10207.0271=12346=61023=610=130
1128=99=18035=X49=SAMPLE75=2016101134=50452=2001063002161557208879260=200106300216155720887925799=10000100268=1279=1269=148=17359555=6SZ683=355710270=10220.0271=4346=21023=710=077
1128=99=18135=X49=SAMPLE75=2016101134=2252=2011011205292520117100860=201101120529252011710085799=10000100268=1279=1269=048=17359555=6SZ683=355711270=10207.0271=42346=71023=610=128
1128=99=18135=X49=SAMPLE75=2016101134=354552=2013090709542683721459260=201309070954268372145925799=10000100268=1279=1269=148=17359555=6SZ683=355712270=10220.0271=34346=31023=710=117
1128=99=18135=X49=SAMPLE75=2016101134=364552=2017021320364015872473660=201702132036401587247365799=10000100268=1279=1269=148=17359555=6SZ683=355713270=10221.0271=12346=41023=810=131
1128=99=18035=X49=SAMPLE75=2016101134=87952=2013092719394112125516860=201309271939411212551685799=10000100268=1279=1269=148=17359555=6SZ683=355714270=10220.0271=4346=21023=710=095
1128=99=18135=X49=SAMPLE75=2016101134=361352=2011032803442559554060860=201103280344255955406085799=10000100268=1279=1269=048=17359555=6SZ683=355715270=10207.0271=12346=61023=610=132
1128=99=18135=X49=SAMPLE75=2016101134=152852=2013102310530886908185660=201310231053088690818565799=10000100268=1279=1269=148=17359555=6SZ683=355716270=10220.0271=34346=31023=710=155
1128=99=18135=X49=SAMPLE75=2016101134=37952=2013111917350492726368060=201311191735049272636805799=10000100268=1279=1269=048=17359555=6SZ683=355717270=10207.0271=42346=71023=610=132
1128=99=18135=X49=SAMPLE75=2016101134=358652=2003013013023971385523260=200301301302397138552325799=10000100268=1279=1269=048=17359555=6SZ683=355718270=10207.0271=12346=61023=610=137
1128=99=18135=X49=SAMPLE75=2016101134=79352=2010111414193235018611260=201011141419323501861125799=10000100268=1279=1269=048=17359555=6SZ683=355719270=10207.0271=42346=71023=610=170
1128=99=18035=X49=SAMPLE75=2016101134=132352=2011100311050735694188860=201110031105073569418885799=10000100268=1279=1269=148=17359555=6SZ683=355720270=10220.0271=4346=21023=710=094
1128=99=18135=X49=SAMPLE75=2016101134=365752=2014100700233993402329660=201410070023399340232965799=10000100268=1279=1269=148=17359555=6SZ683=355721270=10220.0271=34346=31023=710=155
1128=99=18135=X49=SAMPLE75=2016101134=306452=2000070320411938962015860=200007032041193896201585799=10000100268=1279=1269=048=17359555=6SZ683=355722270=10207.0271=12346=61023=610=150
1128=99=18035=X49=SAMPLE75=2016101134=23952=2014031812084330601952060=201403181208433060195205799=10000100268=1279=1269=148=17359555=6SZ683=355723270=10220.0271=4346=21023=710=086
1128=99=18135=X49=SAMPLE75=2016101134=321052=2014110612533770071648060=201411061253377007164805799=10000100268=1279=1269=048=17359555=6SZ683=355724270=10207.0271=42346=71023=610=122
1128=99=18135=X49=SAMPLE75=2016101134=106452=2004032613313323771604860=200403261331332377160485799=10000100268=1279=1269=148=17359555=6SZ683=355725270=10220.0271=34346=31023=710=151
1128=99=18035=X49=SAMPLE75=2016101134=150952=2001020416592440765242860=200102041659244076524285799=10000100268=1279=1269=148=17359555=6SZ683=355726270=10220.0271=4346=21023=710=105
1128=99=18135=X49=SAMPLE75=2016101134=492652=2003031011423703816014460=200303101142370381601445799=10000100268=1279=1269=148=17359555=6SZ683=355727270=10220.0271=34346=31023=710=146
1128=99=18035=X49=SAMPLE75=2016101134=238252=2004052705370849210772860=200405270537084921077285799=10000100268=1279=1269=148=17359555=6SZ683=355728270=10220.0271=4346=21023=710=088
1128=99=18135=X49=SAMPLE75=2016101134=179652=2006090815091917601702460=200609081509191760170245799=10000100268=1279=1269=048=17359555=6SZ683=355729270=10207.0271=12346=61023=610=143
1128=99=18135=X49=SAMPLE75=2016101134=479752=2008052521403421616806460=200805252140342161680645799=10000100268=1279=1269=148=17359555=6SZ683=355730270=10220.0271=34346=31023=710=150
1128=99=18135=X49=SAMPLE75=2016101134=296152=2006041613013418083129660=200604161301341808312965799=10000100268=1279=1269=048=17359555=6SZ683=355731270=10207.0271=42346=71023=610=154
1128=99=18135=X49=SAMPLE75=2016101134=111952=2002082616481092930876860=200208261648109293087685799=10000100268=1279=1269=048=17359555=6SZ683=355732270=10207.0271=12346=61023=610=137
1128=99=18035=X49=SAMPLE75=2016101134=307552=2016120608515548749516860=201612060851554874951685799=10000100268=1279=1269=148=17359555=6SZ683=355733270=10220.0271=4346=21023=710=084
1128=99=18135=X49=SAMPLE75=2016101134=161552=2010010803482538532646460=201001080348253853264645799=10000100268=1279=1269=048=17359555=6SZ683=355734270=10207.0271=42346=71023=610=125
1128=99=18135=X49=SAMPLE75=2016101134=146552=2008011123104346119337660=200801112310434611933765799=10000100268=1279=1269=148=17359555=6SZ683=355735270=10220.0271=34346=31023=710=121
1128=99=18135=X49=SAMPLE75=2016101134=173652=2016052416140916285600060=201605241614091628560005799=10000100268=1279=1269=148=17359555=6SZ683=355736270=10216.0271=14346=61023=310=168
1128=99=18035=X49=SAMPLE75=2016101134=186452=2002022709100620137279260=200202270910062013727925799=10000100268=1279=1269=148=17359555=6SZ683=355737270=10220.0271=4346=21023=710=102
1128=99=18135=X49=SAMPLE75=2016101134=21452=2009031004271364019481660=200903100427136401948165799=10000100268=1279=1269=048=17359555=6SZ683=355738270=10207.0271=12346=61023=610=141
1128=99=18135=X49=SAMPLE75=2016101134=424652=2014091609110121388601660=201409160911012138860165799=10000100268=1279=1269=148=17359555=6SZ683=355739270=10220.0271=34346=31023=710=154
1128=99=18135=X49=SAMPLE75=2016101134=104052=2010090122264894378707260=201009012226489437870725799=10000100268=1279=1269=048=17359555=6SZ683=355740270=10207.0271=42346=71023=610=159
1128=99=18035=X49=SAMPLE75=2016101134=347952=2007030206575655633411260=200703020657565563341125799=10000100268=1279=1269=148=17359555=6SZ683=355741270=10220.0271=4346=21023=710=077
1128=99=18135=X49=SAMPLE75=2016101134=195252=2007082120400601765091260=200708212040060176509125799=10000100268=1279=1269=048=17359555=6SZ683=355742270=10207.0271=12346=61023=610=142
1128=99=18135=X49=SAMPLE75=2016101134=184252=2000050503284329992822460=200005050328432999282245799=10000100268=1279=1269=148=17359555=6SZ683=355743270=10220.0271=34346=31023=710=141
1128=99=18135=X49=SAMPLE75=2016101134=101352=2004020604364477585840060=200402060436447758584005799=10000100268=1279=1269=048=17359555=6SZ683=355744270=10207.0271=42346=71023=610=129
1128=99=18135=X49=SAMPLE75=2016101134=266052=2011103019041025417408060=201110301904102541740805799=10000100268=1279=1269=048=17359555=6SZ683=355745270=10207.0271=12346=61023=610=130
1128=99=18135=X49=SAMPLE75=2016101134=496052=2003042022482516272182460=200304202248251627218245799=10000100268=1279=1269=048=17359555=6SZ683=355746270=10206.0271=34346=31023=710=137
1128=99=18035=X49=SAMPLE75=2016101134=126052=2005120506543419783068860=200512050654341978306885799=10000100268=1279=1269=148=17359555=6SZ683=355747270=10220.0271=4346=21023=710=101
1128=99=18135=X49=SAMPLE75=2016101134=29452=2010102211432417581824060=201010221143241758182405799=10000100268=1279=1269=148=17359555=6SZ683=355748270=10220.0271=34346=31023=710=162
1128=99=18035=X49=SAMPLE75=2016101134=121252=2014033016560056578803260=201403301656005657880325799=10000100268=1279=1269=148=17359555=6SZ683=355749270=10220.0271=4346=21023=710=088
1128=99=18135=X49=SAMPLE75=2016101134=417552=2013112915370990968614460=201311291537099096861445799=10000100268=1279=1269=148=17359555=6SZ683=355750270=10220.0271=34346=31023=710=154
1128=99=18035=X49=SAMPLE75=2016101134=3152=2004082415181269536163260=200408241518126953616325799=10000100268=1279=1269=148=17359555=6SZ683=355751270=10220.0271=4346=21023=710=084
1128=99=18135=X49=SAMPLE75=2016101134=151452=2017012520132959096025660=201701252013295909602565799=10000100268=1279=1269=148=17359555=6SZ683=355752270=10220.0271=34346=31023=710=141
1128=99=18035=X49=SAMPLE75=2016101134=117252=2002082107142040863086460=200208210714204086308645799=10000100268=1279=1269=148=17359555=6SZ683=355753270=10220.0271=4346=21023=710=070
1128=99=18135=X49=SAMPLE75=2016101134=156552=2004033109582755104043260=200403310958275510404325799=10000100268=1279=1269=148=17359555=6SZ683=355754270=10220.0271=34346=31023=710=129
1128=99=18035=X49=SAMPLE75=2016101134=229752=2004040620394791893268860=200404062039479189326885799=10000100268=1279=1269=148=17359555=6SZ683=355755270=10220.0271=4346=21023=710=100
1128=99=18135=X49=SAMPLE75=2016101134=166652=2008041908572123204646460=200804190857212320464645799=10000100268=1279=1269=148=17359555=6SZ683=355756270=10220.0271=34346=31023=710=145
1128=99=18035=X49=SAMPLE75=2016101134=251952=2014071307405542312025660=201407130740554231202565799=10000100268=1279=1269=148=17359555=6SZ683=355757270=10220.0271=4346=21023=710=117
1128=99=18135=X49=SAMPLE75=2016101134=147752=2014081000455371297580860=201408100045537129758085799=10000100268=1279=1269=148=17359555=6SZ683=355758270=10220.0271=34346=31023=710=140
1128=99=18035=X49=SAMPLE75=2016101134=149252=2010042809145134032256060=201004280914513403225605799=10000100268=1279=1269=148=17359555=6SZ683=355759270=10220.0271=4346=21023=710=087
1128=99=18135=X49=SAMPLE75=2016101134=88852=2003030405381217559204860=200303040538121755920485799=10000100268=1279=1269=148=17359555=6SZ683=355760270=10220.0271=34346=31023=710=127
1128=99=18035=X49=SAMPLE75=2016101134=218252=2005041618003175342332860=200504161800317534233285799=10000100268=1279=1269=148=17359555=6SZ683=355761270=10220.0271=4346=21023=710=064
1128=99=18135=X49=SAMPLE75=2016101134=474952=2006103007500669449936060=200610300750066944993605799=10000100268=1279=1269=148=17359555=6SZ683=355762270=10220.0271=34346=31023=710=146
1128=99=18035=X49=SAMPLE75=2016101134=373352=2015102111104849282009660=201510211110484928200965799=10000100268=1279=1269=148=17359555=6SZ683=355763270=10220.0271=4346=21023=710=108
1128=99=18135=X49=SAMPLE75=2016101134=188852=2015011404422446376704060=201501140442244637670405799=10000100268=1279=1269=148=17359555=6SZ683=355764270=10220.0271=34346=31023=710=175
1128=99=18035=X49=SAMPLE75=2016101134=122852=2011112801460456273280060=201111280146045627328005799=10000100268=1279=1269=148=17359555=6SZ683=355765270=10220.0271=4346=21023=710=116
1128=99=18135=X49=SAMPLE75=2016101134=382952=2013061915124881912384060=201306191512488191238405799=10000100268=1279=1269=148=17359555=6SZ683=355766270=10220.0271=34346=31023=710=168
1128=99=18035=X49=SAMPLE75=2016101134=85352=2012042810532012016844860=201204281053201201684485799=10000100268=1279=1269=148=17359555=6SZ683=355767270=10220.0271=4346=21023=710=094
1128=99=18135=X49=SAMPLE75=2016101134=177252=2007050517505899578796860=200705051750589957879685799=10000100268=1279=1269=148=17359555=6SZ683=355768270=10220.0271=34346=31023=710=132
1128=99=18035=X49=SAMPLE75=2016101134=199652=2002071813442409492292860=200207181344240949229285799=10000100268=1279=1269=148=17359555=6SZ683=355769270=10220.0271=4346=21023=710=101
1128=99=18135=X49=SAMPLE75=2016101134=365052=2015010520025607169644860=201501052002560716964485799=10000100268=1279=1269=148=17359555=6SZ683=355770270=10220.0271=34346=31023=710=130
1128=99=18035=X49=SAMPLE75=2016101134=172352=2011061405020459244921660=201106140502045924492165799=10000100268=1279=1269=148=17359555=6SZ683=355771270=10220.0271=4346=21023=710=108
1128=99=18135=X49=SAMPLE75=2016101134=274152=2009062422243938865958460=200906242224393886595845799=10000100268=1279=1269=148=17359555=6SZ683=355772270=10220.0271=34346=31023=710=142
1128=99=18035=X49=SAMPLE75=2016101134=401052=2004122702311460874630460=200412270231146087463045799=10000100268=1279=1269=148=17359555=6SZ683=355773270=10220.0271=4346=21023=710=096
1128=99=18135=X49=SAMPLE75=2016101134=471152=2002031302113687112647260=200203130211368711264725799=10000100268=1279=1269=148=17359555=6SZ683=355774270=10220.0271=34346=31023=710=147
1128=99=25135=X49=SAMPLE75=2016101134=149652=2009102111132133411865660=200910211113213341186565799=10000100268=2279=1269=048=17359555=6SZ683=355775270=10210.0271=5346=31023=3279=1269=048=17359555=6SZ683=355776270=10209.0271=4346=21023=410=138
1128=99=18035=X49=SAMPLE75=2016101134=314952=2003070916220756386017660=200307091622075638601765799=10000100268=1279=1269=048=17359555=6SZ683=355777270=10212.0271=5346=31023=110=071
1128=99=25135=X49=SAMPLE75=2016101134=209052=2008043003501387326044860=200804300350138732604485799=10000100268=2279=2269=048=17360055=6SH783=99098270=10265.0271=3346=11023=1279=0269=048=17360055=6SH783=99099270=10255.0271=53346=21023=1010=108
1128=99=18035=X49=SAMPLE75=2016101134=80452=2010060418301222278508860=201006041830122227850885799=10000100268=1279=1269=148=17359555=6SZ683=355778270=10220.0271=4346=21023=710=092
1128=99=18035=X49=SAMPLE75=2016101134=287852=2003040701170137974252860=200304070117013797425285799=10000100268=1279=1269=048=17359555=6SZ683=355779270=10206.0271=4346=21023=710=108
1128=99=18135=X49=SAMPLE75=2016101134=130452=2002101107582147286329660=200210110758214728632965799=10000100268=1279=1269=148=17359555=6SZ683=355780270=10220.0271=34346=31023=710=106
1128=99=18135=X49=SAMPLE75=2016101134=362252=2008081600213599819971260=200808160021359981997125799=10000100268=1279=1269=048=17359555=6SZ683=355781270=10206.0271=34346=31023=710=139
1128=99=18035=X49=SAMPLE75=2016101134=79852=2003012615385430170129660=200301261538543017012965799=10000100268=1279=1269=148=17359555=6SZ683=355782270=10220.0271=4346=21023=710=082
1128=99=18135=X49=SAMPLE75=2016101134=334952=2012111009560245759059260=201211100956024575905925799=10000100268=1279=1269=148=17359555=6SZ683=355783270=10220.0271=34346=31023=710=119
1128=99=18035=X49=SAMPLE75=2016101134=449752=2008031411270135985619260=200803141127013598561925799=10000100268=1279=1269=148=17359555=6SZ683=355784270=10220.0271=4346=21023=710=055
1128=99=18135=X49=SAMPLE75=2016101134=87452=2002011517244590914091260=200201151724459091409125799=10000100268=1279=1269=148=17359555=6SZ683=355785270=10220.0271=34346=31023=710=138
1128=99=18035=X49=SAMPLE75=2016101134=470852=2017022513031855433638460=201702251303185543363845799=10000100268=1279=1269=148=17359555=6SZ683=355786270=10220.0271=4346=21023=710=100
1128=99=18135=X49=SAMPLE75=2016101134=271352=2002101823501779137596860=200210182350177913759685799=10000100268=1279=1269=148=17359555=6SZ683=355787270=10220.0271=34346=31023=710=146
1128=99=18035=X49=SAMPLE75=2016101134=499452=2013121522474907094387260=201312152247490709438725799=10000100268=1279=1269=148=17359555=6SZ683=355788270=10220.0271=4346=21023=710=070
1128=99=18135=X49=SAMPLE75=2016101134=246952=2007110409043089945852860=200711040904308994585285799=10000100268=1279=1269=148=17359555=6SZ683=355789270=10220.0271=34346=31023=710=171
1128=99=18035=X49=SAMPLE75=2016101134=420352=2016101614561731367558460=201610161456173136755845799=10000100268=1279=1269=148=17359555=6SZ683=355790270=10220.0271=4346=21023=710=075
1128=99=18135=X49=SAMPLE75=2016101134=477852=2011021410234110184147260=201102141023411018414725799=10000100268=1279=1269=148=17359555=6SZ683=355791270=10220.0271=34346=31023=710=127
1128=99=18035=X49=SAMPLE75=2016101134=298052=2001073009345859533064060=200107300934585953306405799=10000100268=1279=1269=148=17359555=6SZ683=355792270=10220.0271=4346=21023=710=099
1128=99=18135=X49=SAMPLE75=2016101134=258752=2007072817564759324345660=200707281756475932434565799=10000100268=1279=1269=148=17359555=6SZ683=355793270=10220.0271=34346=31023=710=129
1128=99=18035=X49=SAMPLE75=2016101134=26052=2016032606385007472966460=201603260638500747296645799=10000100268=1279=1269=148=17359555=6SZ683=355794270=10220.0271=4346=21023=710=080
1128=99=18135=X49=SAMPLE75=2016101134=430052=2016082418032926638163260=201608241803292663816325799=10000100268=1279=1269=148=17359555=6SZ683=355795270=10220.0271=34346=31023=710=150
1128=99=18035=X49=SAMPLE75=2016101134=57952=2005050210381561143430460=200505021038156114343045799=10000100268=1279=1269=048=17359555=6SZ683=355796270=10212.0271=6346=41023=110=112
1128=99=17935=X49=SAMPLE75=2016101134=193152=2001061300071602019016060=200106130007160201901605799=10000100268=1279=0269=048=17360055=6SH783=99100270=10265.0271=3346=11023=110=009
1128=99=18035=X49=SAMPLE75=2016101134=298452=2009033118002099473043260=200903311800209947304325799=10000100268=1279=1269=148=17359555=6SZ683=355797270=10220.0271=4346=21023=710=088
1128=99=18135=X49=SAMPLE75=2016101134=94852=2011011507594302768979260=201101150759430276897925799=10000100268=1279=1269=148=17359555=6SZ683=355798270=10220.0271=34346=31023=710=147
1128=99=18035=X49=SAMPLE75=2016101134=167252=2011081001384378608307260=201108100138437860830725799=10000100268=1279=1269=048=17359555=6SZ683=355799270=10206.0271=4346=21023=710=086
1128=99=18135=X49=SAMPLE75=2016101134=35152=2002021404254768968203260=200202140425476896820325799=10000100268=1279=1269=048=17359555=6SZ683=355800270=10206.0271=34346=31023=710=137
1128=99=25335=X49=SAMPLE75=2016101134=286252=2003072215470003807812860=200307221547000380781285799=10000100268=2279=1269=148=17359555=6SZ683=355801270=10219.0271=18346=61023=6279=1269=148=17359555=6SZ683=355802270=10220.0271=37346=41023=710=225
1128=99=25335=X49=SAMPLE75=2016101134=21252=2008111321471590587014460=200811132147159058701445799=10000100268=2279=1269=148=17359555=6SZ683=355803270=10219.0271=21346=71023=6279=1269=148=17359555=6SZ683=355804270=10220.0271=34346=31023=710=235
1128=99=18035=X49=SAMPLE75=2016101134=395452=2006021801342743602307260=200602180134274360230725799=10000100268=1279=1269=148=17359555=6SZ683=355805270=10220.0271=4346=21023=710=077
1128=99=18135=X49=SAMPLE75=2016101134=91352=2001080319571210642332060=200108031957121064233205799=10000100268=1279=1269=148=17359555=6SZ683=355806270=10220.0271=34346=31023=710=123
1128=99=18035=X49=SAMPLE75=2016101134=224452=2002102119250527892689660=200210211925052789268965799=10000100268=1279=1269=148=17359555=6SZ683=355807270=10220.0271=4346=21023=710=093
1128=99=18135=X49=SAMPLE75=2016101134=306452=2002020815241806860153660=200202081524180686015365799=10000100268=1279=1269=148=17359555=6SZ683=355808270=10220.0271=34346=31023=710=152
1128=99=18035=X49=SAMPLE75=2016101134=272752=2001071709544535548484860=200107170954453554848485799=10000100268=1279=1269=148=17359555=6SZ683=355809270=10220.0271=4346=21023=710=070
1128=99=18135=X49=SAMPLE75=2016101134=149452=2012081608121662193100860=201208160812166219310085799=10000100268=1279=1269=148=17359555=6SZ683=355810270=10221.0271=42346=51023=810=137
1128=99=18135=X49=SAMPLE75=2016101134=272052=2008090911540788480598460=200809091154078848059845799=10000100268=1279=1269=148=17359555=6SZ683=355811270=10221.0271=12346=41023=810=108
1128=99=18135=X49=SAMPLE75=2016101134=134352=2012071018122752056889660=201207101812275205688965799=10000100268=1279=1269=148=17359555=6SZ683=355812270=10220.0271=34346=31023=710=100
1128=99=18035=X49=SAMPLE75=2016101134=60252=2016030704331162793024060=201603070433116279302405799=10000100268=1279=1269=148=17359555=6SZ683=355813270=10220.0271=4346=21023=710=091
1128=99=18135=X49=SAMPLE75=2016101134=492352=2009031820433084045350460=200903182043308404535045799=10000100268=1279=1269=148=17359555=6SZ683=355814270=10222.0271=33346=21023=910=143
1128=99=18035=X49=SAMPLE75=2016101134=279252=2015011803192409079648060=201501180319240907964805799=10000100268=1279=1269=148=17359555=6SZ683=355815270=10222.0271=3346=11023=910=111
1128=99=18135=X49=SAMPLE75=2016101134=336452=2011011712035592478233660=201101171203559247823365799=10000100268=1279=1269=148=17359555=6SZ683=355816270=10220.0271=34346=31023=710=138
1128=99=18035=X49=SAMPLE75=2016101134=1952=2011021709335761817856060=201102170933576181785605799=10000100268=1279=1269=148=17359555=6SZ683=355817270=10220.0271=4346=21023=710=083
1128=99=18135=X49=SAMPLE75=2016101134=237952=2011011913065245740268860=201101191306524574026885799=10000100268=1279=1269=148=17359555=6SZ683=355818270=10220.0271=34346=31023=710=169
1128=99=25335=X49=SAMPLE75=2016101134=193152=2015101005491189004332860=201510100549118900433285799=10000100268=2279=1269=148=17359555=6SZ683=355819270=10219.0271=18346=61023=6279=1269=148=17359555=6SZ683=355820270=10220.0271=37346=41023=710=240
1128=99=18035=X49=SAMPLE75=2016101134=174052=2013050223511806099552060=201305022351180609955205799=10000100268=1279=1269=148=17359555=6SZ683=355821270=10220.0271=7346=31023=710=107
1128=99=18135=X49=SAMPLE75=2016101134=473252=2011040417540908200691260=201104041754090820069125799=10000100268=1279=1269=148=17359555=6SZ683=355822270=10220.0271=37346=41023=710=151
1128=99=18035=X49=SAMPLE75=2016101134=72452=2002030523285178413807260=200203052328517841380725799=10000100268=1279=1269=148=17359555=6SZ683=355823270=10220.0271=7346=31023=710=113
1128=99=18135=X49=SAMPLE75=2016101134=328452=2014012412060661533523260=201401241206066153352325799=10000100268=1279=1269=148=17359555=6SZ683=355824270=10220.0271=37346=41023=710=159
1128=99=18035=X49=SAMPLE75=2016101134=118252=2005053118255634994668860=200505311825563499466885799=10000100268=1279=1269=148=17359555=6SZ683=355825270=10220.0271=7346=31023=710=109
1128=99=18135=X49=SAMPLE75=2016101134=170252=2007062317384821987011260=200706231738482198701125799=10000100268=1279=1269=148=17359555=6SZ683=355826270=10220.0271=37346=41023=710=147
1128=99=18035=X49=SAMPLE75=2016101134=222352=2012111806134624324684860=201211180613462432468485799=10000100268=1279=1269=148=17359555=6SZ683=355827270=10220.0271=7346=31023=710=085
1128=99=18135=X49=SAMPLE75=2016101134=370252=2009013116581490307932860=200901311658149030793285799=10000100268=1279=1269=148=17359555=6SZ683=355828270=10220.0271=37346=41023=710=149
1128=99=25335=X49=SAMPLE75=2016101134=418452=2010070217323665705868860=201007021732366570586885799=10000100268=2279=1269=148=17359555=6SZ683=355829270=10219.0271=21346=71023=6279=1269=148=17359555=6SZ683=355830270=10220.0271=34346=31023=710=231
1128=99=18035=X49=SAMPLE75=2016101134=382552=2011020404493468155174460=201102040449346815517445799=10000100268=1279=1269=148=17359555=6SZ683=355831270=10220.0271=4346=21023=710=097
1128=99=18135=X49=SAMPLE75=2016101134=277252=2013033009164512825664060=201303300916451282566405799=10000100268=1279=1269=148=17359555=6SZ683=355832270=10220.0271=34346=31023=710=172
1128=99=18035=X49=SAMPLE75=2016101134=378352=2016090918230535616704060=201609091823053561670405799=10000100268=1279=1269=148=17359555=6SZ683=355833270=10220.0271=4346=21023=710=077
1128=99=18135=X49=SAMPLE75=2016101134=40752=2011060922181280975808060=201106092218128097580805799=10000100268=1279=1269=148=17359555=6SZ683=355834270=10220.0271=34346=31023=710=161
1128=99=18035=X49=SAMPLE75=2016101134=483352=2008040319574089713724860=200804031957408971372485799=10000100268=1279=1269=148=17359555=6SZ683=355835270=10220.0271=4346=21023=710=081
1128=99=18135=X49=SAMPLE75=2016101134=487552=2009050215090921227328060=200905021509092122732805799=10000100268=1279=1269=148=17359555=6SZ683=355836270=10220.0271=34346=31023=710=157
1128=99=18035=X49=SAMPLE75=2016101134=116952=2011120906084058771545660=201112090608405877154565799=10000100268=1279=1269=148=17359555=6SZ683=355837270=10220.0271=4346=21023=710=105
1128=99=25235=X49=SAMPLE75=2016101134=91052=2013032314571289107116860=201303231457128910711685799=10000100268=2279=1269=148=17359555=6SZ683=355838270=10219.0271=18346=61023=6279=1269=148=17359555=6SZ683=355839270=10220.0271=7346=31023=710=232
1128=99=18135=X49=SAMPLE75=2016101134=22352=2004013103062271996043260=200401310306227199604325799=10000100268=1279=1269=148=17359555=6SZ683=355840270=10220.0271=37346=41023=710=155
1128=99=18035=X49=SAMPLE75=2016101134=121952=2007010118054478729952060=200701011805447872995205799=10000100268=1279=1269=148=17359555=6SZ683=355841270=10220.0271=7346=31023=710=111
1128=99=18135=X49=SAMPLE75=2016101134=205852=2012030317402072289561660=201203031740207228956165799=10000100268=1279=1269=148=17359555=6SZ683=355842270=10220.0271=37346=41023=710=168
1128=99=18035=X49=SAMPLE75=2016101134=44752=2011061801503943838604860=201106180150394383860485799=10000100268=1279=1269=148=17359555=6SZ683=355843270=10220.0271=7346=31023=710=092
1128=99=18135=X49=SAMPLE75=2016101134=232052=2002080806492616407132860=200208080649261640713285799=10000100268=1279=1269=148=17359555=6SZ683=355844270=10222.0271=33346=21023=910=155
1128=99=18035=X49=SAMPLE75=2016101134=152552=2012061206465263651500860=201206120646526365150085799=10000100268=1279=1269=148=17359555=6SZ683=355845270=10222.0271=3346=11023=910=100
1128=99=18135=X49=SAMPLE75=2016101134=259552=2007100215025972264771260=200710021502597226477125799=10000100268=1279=1269=148=17359555=6SZ683=355846270=10220.0271=37346=41023=710=162
1128=99=18035=X49=SAMPLE75=2016101134=248252=2016012219412924051500860=201601221941292405150085799=10000100268=1279=1269=148=17359555=6SZ683=355847270=10220.0271=7346=31023=710=104
1128=99=18135=X49=SAMPLE75=2016101134=149852=2014082307542853776044860=201408230754285377604485799=10000100268=1279=1269=148=17359555=6SZ683=355848270=10221.0271=42346=51023=810=156
1128=99=18135=X49=SAMPLE75=2016101134=75052=2017031002122408543276860=201703100212240854327685799=10000100268=1279=1269=148=17359555=6SZ683=355849270=10220.0271=37346=41023=710=136
1128=99=18135=X49=SAMPLE75=2016101134=79852=2016090800571166438848060=201609080057116643884805799=10000100268=1279=1269=148=17359555=6SZ683=355850270=10221.0271=12346=41023=810=142
1128=99=18035=X49=SAMPLE75=2016101134=488052=2016090202444006549747260=201609020244400654974725799=10000100268=1279=1269=148=17359555=6SZ683=355851270=10220.0271=7346=31023=710=111
1128=99=18135=X49=SAMPLE75=2016101134=44852=2001060714315042664635260=200106071431504266463525799=10000100268=1279=1269=148=17359555=6SZ683=355852270=10222.0271=33346=21023=910=152
1128=99=18035=X49=SAMPLE75=2016101134=60352=2005030423593564946678460=200503042359356494667845799=10000100268=1279=1269=148=17359555=6SZ683=355853270=10222.0271=3346=11023=910=110
1128=99=18135=X49=SAMPLE75=2016101134=405552=2007080818511758841859260=200708081851175884185925799=10000100268=1279=1269=148=17359555=6SZ683=355854270=10220.0271=37346=41023=710=160
1128=99=18035=X49=SAMPLE75=2016101134=242952=2015052922414748638828860=201505292241474863882885799=10000100268=1279=1269=148=17359555=6SZ683=355855270=10220.0271=7346=31023=710=109
1128=99=18135=X49=SAMPLE75=2016101134=304552=2002122920150057213408060=200212292015005721340805799=10000100268=1279=1269=148=17359555=6SZ683=355856270=10220.0271=37346=41023=710=178
1128=99=18035=X49=SAMPLE75=2016101134=448652=2016071912112795192947260=201607191211279519294725799=10000100268=1279=1269=148=17359555=6SZ683=355857270=10220.0271=7346=31023=710=136
1128=99=18135=X49=SAMPLE75=2016101134=175252=2003022403125476708206460=200302240312547670820645799=10000100268=1279=1269=148=17359555=6SZ683=355858270=10221.0271=42346=51023=810=180
1128=99=18135=X49=SAMPLE75=2016101134=253352=2011090311143770149350460=201109031114377014935045799=10000100268=1279=1269=148=17359555=6SZ683=355859270=10221.0271=12346=41023=810=180
1128=99=18135=X49=SAMPLE75=2016101134=180352=2017020406423510300230460=201702040642351030023045799=10000100268=1279=1269=148=17359555=6SZ683=355860270=10220.0271=37346=41023=710=164
1128=99=25335=X49=SAMPLE75=2016101134=9252=2006092606562314459184060=200609260656231445918405799=10000100268=2279=1269=148=17359555=6SZ683=355861270=10219.0271=21346=71023=6279=1269=148=17359555=6SZ683=355862270=10220.0271=34346=31023=710=003
1128=99=25335=X49=SAMPLE75=2016101134=237952=2006033020495989194563260=200603302049598919456325799=10000100268=2279=1269=148=17359555=6SZ683=355863270=10219.0271=18346=61023=6279=1269=148=17359555=6SZ683=355864270=10220.0271=37346=41023=710=027
1128=99=18035=X49=SAMPLE75=2016101134=48752=2001072201444795638651260=200107220144479563865125799=10000100268=1279=1269=148=17359555=6SZ683=355865270=10220.0271=7346=31023=710=113
1128=99=18135=X49=SAMPLE75=2016101134=352852=2015011301323529486336060=201501130132352948633605799=10000100268=1279=1269=148=17359555=6SZ683=355866270=10220.0271=37346=41023=710=162
1128=99=25335=X49=SAMPLE75=2016101134=454752=2002101021461564905494460=200210102146156490549445799=10000100268=2279=1269=148=17359555=6SZ683=355867270=10219.0271=21346=71023=6279=1269=148=17359555=6SZ683=355868270=10220.0271=34346=31023=710=010
1128=99=25135=X49=SAMPLE75=2016101134=228352=2000122602570996205629260=200012260257099620562925799=10000100268=2279=1269=048=17359555=6SZ683=355869270=10210.0271=4346=21023=3279=1269=048=17359555=6SZ683=355870270=10209.0271=5346=31023=410=144
1128=99=18035=X49=SAMPLE75=2016101134=491952=2002122316134623620369660=200212231613462362036965799=10000100268=1279=1269=148=17359555=6SZ683=355871270=10220.0271=4346=21023=710=079
1128=99=18135=X49=SAMPLE75=2016101134=66152=2009011202310474456451260=200901120231047445645125799=10000100268=1279=1269=148=17359555=6SZ683=355872270=10220.0271=34346=31023=710=151
1128=99=18035=X49=SAMPLE75=2016101134=381652=2010083007310579227923260=201008300731057922792325799=10000100268=1279=1269=148=17359555=6SZ683=355873270=10220.0271=4346=21023=710=094
1128=99=18135=X49=SAMPLE75=2016101134=363452=2012071615353985029734460=201207161535398502973445799=10000100268=1279=1269=148=17359555=6SZ683=355874270=10220.0271=34346=31023=710=149
1128=99=18035=X49=SAMPLE75=2016101134=111352=2014101106164825048064060=201410110616482504806405799=10000100268=1279=1269=148=17359555=6SZ683=355875270=10220.0271=4346=21023=710=128
1128=99=18135=X49=SAMPLE75=2016101134=175152=2003082320585056950523260=200308232058505695052325799=10000100268=1279=1269=148=17359555=6SZ683=355876270=10220.0271=34346=31023=710=160
1128=99=18035=X49=SAMPLE75=2016101134=228752=2012082809423311047648060=201208280942331104764805799=10000100268=1279=1269=148=17359555=6SZ683=355877270=10220.0271=4346=21023=710=130
1128=99=18135=X49=SAMPLE75=2016101134=208252=2007021418302878069468860=200702141830287806946885799=10000100268=1279=1269=148=17359555=6SZ683=355878270=10220.0271=34346=31023=710=170
1128=99=18035=X49=SAMPLE75=2016101134=429152=2005013001074095385932860=200501300107409538593285799=10000100268=1279=1269=148=17359555=6SZ683=355879270=10220.0271=4346=21023=710=099
1128=99=18135=X49=SAMPLE75=2016101134=135052=2011030101211992458304060=201103010121199245830405799=10000100268=1279=1269=148=17359555=6SZ683=355880270=10222.0271=33346=21023=910=147
1128=99=18035=X49=SAMPLE75=2016101134=455252=2000110512113762617885660=200011051211376261788565799=10000100268=1279=1269=148=17359555=6SZ683=355881270=10222.0271=3346=11023=910=099
1128=99=18135=X49=SAMPLE75=2016101134=217852=2014010722230515730048060=201401072223051573004805799=10000100268=1279=1269=148=17359555=6SZ683=355882270=10220.0271=34346=31023=710=144
1128=99=18035=X49=SAMPLE75=2016101134=203252=2000111400110214408224460=200011140011021440822445799=10000100268=1279=1269=148=17359555=6SZ683=355883270=10220.0271=4346=21023=710=078
1128=99=18135=X49=SAMPLE75=2016101134=180252=2015082622031464910188860=201508262203146491018885799=10000100268=1279=1269=148=17359555=6SZ683=355884270=10220.0271=34346=31023=710=147
1128=99=18035=X49=SAMPLE75=2016101134=493952=2008020316465352662380860=200802031646535266238085799=10000100268=1279=1269=148=17359555=6SZ683=355885270=10220.0271=4346=21023=710=107
1128=99=18135=X49=SAMPLE75=2016101134=181052=2010030505210574472672060=201003050521057447267205799=10000100268=1279=1269=148=17359555=6SZ683=355886270=10220.0271=34346=31023=710=164
1128=99=18035=X49=SAMPLE75=2016101134=7852=2009053002055645641977660=200905300205564564197765799=10000100268=1279=1269=148=17359555=6SZ683=355887270=10220.0271=4346=21023=710=099
1128=99=18135=X49=SAMPLE75=2016101134=952=2001040709124465979104060=200104070912446597910405799=10000100268=1279=1269=148=17359555=6SZ683=355888270=10220.0271=34346=31023=710=157
1128=99=25135=X49=SAMPLE75=2016101134=413052=2000092504163339547882460=200009250416333954788245799=10000100268=2279=1269=048=17359555=6SZ683=355889270=10210.0271=5346=31023=3279=1269=048=17359555=6SZ683=355890270=10209.0271=4346=21023=410=145
1128=99=18035=X49=SAMPLE75=2016101134=316952=2005060503340520376448060=200506050334052037644805799=10000100268=1279=1269=148=17359555=6SZ683=355891270=10220.0271=4346=21023=710=098
1128=99=18135=X49=SAMPLE75=2016101134=113052=2017030602281296533900860=201703060228129653390085799=10000100268=1279=1269=148=17359555=6SZ683=355892270=10220.0271=34346=31023=710=157
1128=99=18035=X49=SAMPLE75=2016101134=324452=2005101116531219279366460=200510111653121927936645799=10000100268=1279=1269=148=17359555=6SZ683=355893270=10220.0271=4346=21023=710=103
1128=99=18135=X49=SAMPLE75=2016101134=445952=2014072520392515557785660=201407252039251555778565799=10000100268=1279=1269=148=17359555=6SZ683=355894270=10222.0271=33346=21023=910=149
1128=99=18035=X49=SAMPLE75=2016101134=461252=2006060519575963194416060=200606051957596319441605799=10000100268=1279=1269=148=17359555=6SZ683=355895270=10222.0271=3346=11023=910=128
1128=99=18135=X49=SAMPLE75=2016101134=195952=2011121912483974099398460=201112191248397409939845799=10000100268=1279=1269=148=17359555=6SZ683=355896270=10221.0271=42346=51023=810=194
1128=99=18135=X49=SAMPLE75=2016101134=495252=2005102302564861116259260=200510230256486111625925799=10000100268=1279=1269=148=17359555=6SZ683=355897270=10220.0271=34346=31023=710=182
1128=99=18135=X49=SAMPLE75=2016101134=241852=2002051005063650787643260=200205100506365078764325799=10000100268=1279=1269=148=17359555=6SZ683=355898270=10221.0271=12346=41023=810=167
1128=99=18035=X49=SAMPLE75=2016101134=472252=2003063018280770204089660=200306301828077020408965799=10000100268=1279=1269=148=17359555=6SZ683=355899270=10220.0271=4346=21023=710=120
1128=99=18135=X49=SAMPLE75=2016101134=375652=2006041917365113474505660=200604191736511347450565799=10000100268=1279=1269=148=17359555=6SZ683=355900270=10220.0271=34346=31023=710=154
1128=99=18035=X49=SAMPLE75=2016101134=148352=2012030911400630000748860=201203091140063000074885799=10000100268=1279=1269=148=17359555=6SZ683=355901270=10220.0271=4346=21023=710=072
1128=99=18135=X49=SAMPLE75=2016101134=301352=2010041613195629951769660=201004161319562995176965799=10000100268=1279=1269=148=17359555=6SZ683=355902270=10220.0271=34346=31023=710=162
1128=99=18035=X49=SAMPLE75=2016101134=205152=2011071617195506837260860=201107161719550683726085799=10000100268=1279=1269=148=17359555=6SZ683=355903270=10220.0271=4346=21023=710=087
1128=99=18135=X49=SAMPLE75=2016101134=181952=2005120908344232981500860=200512090834423298150085799=10000100268=1279=1269=148=17359555=6SZ683=355904270=10220.0271=34346=31023=710=147
1128=99=18035=X49=SAMPLE75=2016101134=355052=2004093002461856828204860=200409300246185682820485799=10000100268=1279=1269=148=17359555=6SZ683=355905270=10220.0271=4346=21023=710=075
1128=99=18135=X49=SAMPLE75=2016101134=88252=2006110317193498760569660=200611031719349876056965799=10000100268=1279=1269=148=17359555=6SZ683=355906270=10220.0271=34346=31023=710=134
1128=99=18035=X49=SAMPLE75=2016101134=481252=2000071412130118683020660=200007141213011868302065799=10000100268=1279=1269=148=17359555=6SZ683=355907270=10220.0271=4346=21023=710=071
1128=99=18135=X49=SAMPLE75=2016101134=121352=2005030706352760412598460=200503070635276041259845799=10000100268=1279=1269=148=17359555=6SZ683=355908270=10220.0271=34346=31023=710=168
1128=99=18035=X49=SAMPLE75=2016101134=317352=2000071702005175639838860=200007170200517563983885799=10000100268=1279=1269=148=17359555=6SZ683=355909270=10217.0271=4346=21023=410=065
1128=99=18035=X49=SAMPLE75=2016101134=208752=2007020116134140376992060=200702011613414037699205799=10000100268=1279=1269=148=17359555=6SZ683=355910270=10220.0271=4346=21023=710=084
1128=99=18135=X49=SAMPLE75=2016101134=270952=2002112801450290710936060=200211280145029071093605799=10000100268=1279=1269=148=17359555=6SZ683=355911270=10220.0271=34346=31023=710=149
1128=99=18035=X49=SAMPLE75=2016101134=461952=2004071218433881966022460=200407121843388196602245799=10000100268=1279=0269=048=17359555=6SZ683=355912270=10213.0271=1346=11023=110=075
1128=99=17935=X49=SAMPLE75=2016101134=179852=2000102418223632695917260=200010241822363269591725799=00000100268=1279=0269=048=17360055=6SH783=99101270=10266.0271=3346=11023=110=013
1128=99=16835=X49=SAMPLE75=2016101134=308852=2012101220341286608115260=201210122034128660811525799=10001000268=1279=0269=N48=17360055=6SH783=99102270=10266.0286=25510=089
1128=99=18035=X49=SAMPLE75=2016101134=96652=2010102211094425867404860=201010221109442586740485799=10000100268=1279=1269=048=17359555=6SZ683=355913270=10212.0271=5346=31023=210=086
1128=99=25035=X49=SAMPLE75=2016101134=257152=2007100810193165702768060=200710081019316570276805799=10000100268=2279=2269=048=17360055=6SH783=99103270=10266.0271=3346=11023=1279=0269=048=17360055=6SH783=99104270=10256.0271=3346=11023=1010=246
1128=99=18035=X49=SAMPLE75=2016101134=481252=2008052300481688260758460=200805230048168826075845799=10000100268=1279=1269=148=17359555=6SZ683=355914270=10220.0271=4346=21023=710=086
1128=99=18135=X49=SAMPLE75=2016101134=193752=2012122922075409597606460=201212292207540959760645799=10000100268=1279=1269=148=17359555=6SZ683=355915270=10220.0271=34346=31023=710=138
1128=99=18035=X49=SAMPLE75=2016101134=285652=2015030710154608907129660=201503071015460890712965799=10000100268=1279=1269=048=17359555=6SZ683=355916270=10206.0271=4346=21023=810=091
1128=99=18135=X49=SAMPLE75=2016101134=163352=2009040501330448921382460=200904050133044892138245799=10000100268=1279=1269=048=17359555=6SZ683=355917270=10206.0271=34346=31023=810=189
1128=99=18035=X49=SAMPLE75=2016101134=308652=2005051614121414682662460=200505161412141468266245799=10000100268=1279=1269=048=17359555=6SZ683=355918270=10206.0271=4346=21023=810=085
1128=99=18135=X49=SAMPLE75=2016101134=304152=2012011203152886732972860=201201120315288673297285799=10000100268=1279=1269=048=17359555=6SZ683=355919270=10206.0271=34346=31023=810=164
1128=99=18035=X49=SAMPLE75=2016101134=112152=2008070919364628566972860=200807091936462856697285799=10000100268=1279=1269=148=17359555=6SZ683=355920270=10220.0271=4346=21023=710=095
1128=99=18035=X49=SAMPLE75=2016101134=103652=2001051501253547937081660=200105150125354793708165799=10000100268=1279=1269=048=17359555=6SZ683=355921270=10206.0271=4346=21023=810=094
1128=99=18135=X49=SAMPLE75=2016101134=218652=2008053117511557163548860=200805311751155716354885799=10000100268=1279=1269=048=17359555=6SZ683=355922270=10207.0271=42346=71023=710=152
1128=99=18135=X49=SAMPLE75=2016101134=468052=2006070823364667370201660=200607082336466737020165799=10000100268=1279=1269=148=17359555=6SZ683=355923270=10220.0271=34346=31023=710=150
1128=99=18135=X49=SAMPLE75=2016101134=478952=2010022815111991852614460=201002281511199185261445799=10000100268=1279=1269=048=17359555=6SZ683=355924270=10207.0271=12346=61023=710=138
1128=99=18135=X49=SAMPLE75=2016101134=397652=2009052001515602470752060=200905200151560247075205799=10000100268=1279=1269=048=17359555=6SZ683=355925270=10207.0271=42346=71023=710=126
1128=99=18135=X49=SAMPLE75=2016101134=160852=2012052712380626099705660=201205271238062609970565799=10000100268=1279=1269=048=17359555=6SZ683=355926270=10207.0271=12346=61023=710=146
1128=99=18035=X49=SAMPLE75=2016101134=225852=2015113020093875905478460=201511302009387590547845799=10000100268=1279=1269=148=17359555=6SZ683=355927270=10220.0271=4346=21023=710=082
1128=99=18035=X49=SAMPLE75=2016101134=192252=2015121700073404683052860=201512170007340468305285799=10000100268=1279=1269=048=17359555=6SZ683=355928270=10212.0271=4346=21023=210=095
1128=99=18135=X49=SAMPLE75=2016101134=294252=2011051821580967336281660=201105182158096733628165799=10000100268=1279=1269=048=17359555=6SZ683=355929270=10206.0271=34346=31023=810=152
1128=99=18135=X49=SAMPLE75=2016101134=342252=2013062316145128431417660=201306231614512843141765799=10000100268=1279=1269=148=17359555=6SZ683=355930270=10220.0271=34346=31023=710=154
1128=99=18135=X49=SAMPLE75=2016101134=116952=2010062208441698128038460=201006220844169812803845799=10000100268=1279=1269=048=17359555=6SZ683=355931270=10207.0271=42346=71023=710=145
1128=99=18035=X49=SAMPLE75=2016101134=60152=2003032013255821710736060=200303201325582171073605799=10000100268=1279=1269=048=17359555=6SZ683=355932270=10206.0271=4346=21023=810=096
1128=99=18135=X49=SAMPLE75=2016101134=243352=2001030110133335253948860=200103011013333525394885799=10000100268=1279=1269=048=17359555=6SZ683=355933270=10207.0271=12346=61023=710=118
1128=99=18035=X49=SAMPLE75=2016101134=216052=2000102716041520867496460=200010271604152086749645799=10000100268=1279=1269=148=17359555=6SZ683=355934270=10220.0271=4346=21023=710=070
1128=99=18135=X49=SAMPLE75=2016101134=72552=2015071920241183343161660=201507192024118334316165799=10000100268=1279=1269=048=17359555=6SZ683=355935270=10206.0271=34346=31023=810=134
1128=99=18135=X49=SAMPLE75=2016101134=209352=2014060701323291321638460=201406070132329132163845799=10000100268=1279=1269=148=17359555=6SZ683=355936270=10220.0271=34346=31023=710=146
1128=99=18135=X49=SAMPLE75=2016101134=20452=2015022411243989651801660=201502241124398965180165799=10000100268=1279=1269=048=17359555=6SZ683=355937270=10207.0271=42346=71023=710=127
1128=99=18035=X49=SAMPLE75=2016101134=419452=2001020401572466936624460=200102040157246693662445799=10000100268=1279=1269=048=17359555=6SZ683=355938270=10206.0271=4346=21023=810=077
1128=99=18035=X49=SAMPLE75=2016101134=337852=2010010723480503024000060=201001072348050302400005799=10000100268=1279=1269=148=17359555=6SZ683=355939270=10220.0271=4346=21023=710=084
1128=99=18135=X49=SAMPLE75=2016101134=81552=2014112605135305997414460=201411260513530599741445799=10000100268=1279=1269=148=17359555=6SZ683=355940270=10220.0271=34346=31023=710=096
1128=99=18135=X49=SAMPLE75=2016101134=327952=2009080819173688662067260=200908081917368866206725799=10000100268=1279=1269=048=17359555=6SZ683=355941270=10207.0271=12346=61023=710=124
1128=99=18135=X49=SAMPLE75=2016101134=400852=2014050801343760139168060=201405080134376013916805799=10000100268=1279=1269=048=17359555=6SZ683=355942270=10207.0271=42346=71023=710=130
1128=99=18035=X49=SAMPLE75=2016101134=57152=2004050514552809925731260=200405051455280992573125799=10000100268=1279=1269=148=17359555=6SZ683=355943270=10220.0271=4346=21023=710=053
1128=99=18135=X49=SAMPLE75=2016101134=407552=2000010614034173785968160=200001061403417378596815799=10000100268=1279=1269=148=17359555=6SZ683=355944270=10220.0271=34346=31023=710=136
1128=99=18135=X49=SAMPLE75=2016101134=296552=2002111718133679377280060=200211171813367937728005799=10000100268=1279=1269=048=17359555=6SZ683=355945270=10207.0271=12346=61023=710=130
1128=99=18135=X49=SAMPLE75=2016101134=261652=2008050612490977818278460=200805061249097781827845799=10000100268=1279=1269=048=17359555=6SZ683=355946270=10207.0271=42346=71023=710=138
1128=99=18035=X49=SAMPLE75=2016101134=163052=2014021204170137638681660=201402120417013763868165799=10000100268=1279=1269=148=17359555=6SZ683=355947270=10220.0271=4346=21023=710=071
1128=99=18135=X49=SAMPLE75=2016101134=376352=2011033103135057555104060=201103310313505755510405799=10000100268=1279=1269=148=17359555=6SZ683=355948270=10220.0271=34346=31023=710=143
1128=99=18035=X49=SAMPLE75=2016101134=339752=2004033023013667742464060=200403302301366774246405799=10000100268=1279=1269=148=17359555=6SZ683=355949270=10220.0271=4346=21023=710=097
1128=99=18135=X49=SAMPLE75=2016101134=452752=2010011823285274472742460=201001182328527447274245799=10000100268=1279=1269=048=17359555=6SZ683=355950270=10207.0271=12346=61023=710=128
1128=99=18135=X49=SAMPLE75=2016101134=324952=2013071016493260898860860=201307101649326089886085799=10000100268=1279=1269=148=17359555=6SZ683=355951270=10220.0271=34346=31023=710=153
1128=99=18135=X49=SAMPLE75=2016101134=48652=2016010300524131033574460=201601030052413103357445799=10000100268=1279=1269=048=17359555=6SZ683=355952270=10207.0271=42346=71023=710=171
1128=99=18035=X49=SAMPLE75=2016101134=158952=2000071605193162679097860=200007160519316267909785799=10000100268=1279=1269=148=17359555=6SZ683=355953270=10220.0271=4346=21023=710=092
