1128=99=12735=f49=SAMPLE34=295652=2017010107314937037488960=2017010107314937037488975=201701015799=000000001151=6S326=18327=11174=010=138
1128=99=51135=d49=SAMPLE75=2017010134=128152=201701010235363453432505799=00000000980=A779=201610091605332737526211180=3141300=6255=6SH048=2492922=8200=2020031151=6S6937=6S167=FUT461=FFCXSX9779=N462=4207=XCME15=USD1142=F562=11140=9999969=1.01146=0.09787=1.0E-41141=11022=GBX264=10864=2865=51145=20150316-21:49:00.000000000865=71145=20200316-14:16:00.000000000870=1871=24872=00000000000001000010000000001111996=CHF1147=1250001149=11501.01148=10701.01143=60.01150=11101.0731=0000001110=24060=20170101023536345343250
1128=99=51035=d49=SAMPLE75=2017010134=468152=201701011125566739651845799=00000000980=A779=201610091605332737526211180=3141300=6255=6SH148=264022=8200=2021031151=6S6937=6S167=FUT461=FFCXSX9779=N462=4207=XCME15=USD1142=F562=11140=9999969=1.01146=0.09787=1.0E-41141=11022=GBX264=10864=2865=51145=20160314-21:49:00.000000000865=71145=20210315-14:16:00.000000000870=1871=24872=00000000000001000010000000001111996=CHF1147=1250001149=11799.01148=10999.01143=60.01150=11399.0731=0000001110=21460=20170101112556673965184
1128=99=51135=d49=SAMPLE75=2017010134=291752=201701010710559724621935799=00000000980=A779=201610091605332737526211180=3141300=6255=6SH748=17360022=8200=2017031151=6S6937=6S167=FUT461=FFCXSX9779=N462=4207=XCME15=USD1142=F562=11140=9999969=1.01146=0.09787=1.0E-41141=11022=GBX264=10864=2865=51145=20130809-21:49:00.000000000865=71145=20170313-14:16:00.000000000870=1871=24872=00000000000001000010000000001111996=CHF1147=1250001149=10707.01148=9907.01143=60.01150=10307.0731=0000001110=25260=20170101071055972462193
1128=99=51235=d49=SAMPLE75=2017010134=198352=201701010113179998240955799=00000000980=A779=201610091605332737526211180=3141300=6255=6SH848=17364022=8200=2018031151=6S6937=6S167=FUT461=FFCXSX9779=N462=4207=XCME15=USD1142=F562=11140=9999969=1.01146=0.09787=1.0E-41141=11022=GBX264=10864=2865=51145=20130809-21:49:00.000000000865=71145=20180319-14:16:00.000000000870=1871=24872=00000000000001000010000000001111996=CHF1147=1250001149=10953.01148=10153.01143=60.01150=10553.0731=0000001110=05660=20170101011317999824095
1128=99=50935=d49=SAMPLE75=2017010134=479052=201701010528134524346405799=00000000980=A779=201610091605332737526211180=3141300=6255=6SH948=78722=8200=2019031151=6S6937=6S167=FUT461=FFCXSX9779=N462=4207=XCME15=USD1142=F562=11140=9999969=1.01146=0.09787=1.0E-41141=11022=GBX264=10864=2865=51145=20140317-21:49:00.000000000865=71145=20190318-14:16:00.000000000870=1871=24872=00000000000001000010000000001111996=CHF1147=1250001149=11217.01148=10417.01143=60.01150=10817.0731=0000001110=17660=20170101052813452434640
1128=99=51135=d49=SAMPLE75=2017010134=188952=201701010742389190670745799=00000000980=A779=201610091605332737526211180=3141300=6255=6SM048=8738422=8200=2020061151=6S6937=6S167=FUT461=FFCXSX9779=N462=4207=XCME15=USD1142=F562=11140=9999969=1.01146=0.09787=1.0E-41141=11022=GBX264=10864=2865=51145=20150615-21:49:00.000000000865=71145=20200615-14:16:00.000000000870=1871=24872=00000000000001000010000000001111996=CHF1147=1250001149=11574.01148=10774.01143=60.01150=11174.0731=0000001110=02060=20170101074238919067074
1128=99=51135=d49=SAMPLE75=2017010134=192252=201701010321316099143235799=00000000980=A779=201610091605332737526211180=3141300=6255=6SM148=7610222=8200=2021061151=6S6937=6S167=FUT461=FFCXSX9779=N462=4207=XCME15=USD1142=F562=11140=9999969=1.01146=0.09787=1.0E-41141=11022=GBX264=10864=2865=51145=20160613-21:49:00.000000000865=71145=20210614-14:16:00.000000000870=1871=24872=00000000000001000010000000001111996=CHF1147=1250001149=11876.01148=11076.01143=60.01150=11476.0731=0000001110=25560=20170101032131609914323
1128=99=51135=d49=SAMPLE75=2017010134=416052=201701010623395587448295799=00000000980=A779=201610091605332737526211180=3141300=6255=6SM748=17360322=8200=2017061151=6S6937=6S167=FUT461=FFCXSX9779=N462=4207=XCME15=USD1142=F562=11140=9999969=1.01146=0.09787=1.0E-41141=11022=GBX264=10864=2865=51145=20130809-21:49:00.000000000865=71145=20170619-14:16:00.000000000870=1871=24872=00000000000001000010000000001111996=CHF1147=1250001149=10769.01148=9969.01143=60.01150=10369.0731=0000001110=04660=20170101062339558744829
1128=99=51235=d49=SAMPLE75=2017010134=126252=201701010837113745227745799=00000000980=A779=201610091605332737526211180=3141300=6255=6SM848=17364122=8200=2018061151=6S6937=6S167=FUT461=FFCXSX9779=N462=4207=XCME15=USD1142=F562=11140=9999969=1.01146=0.09787=1.0E-41141=11022=GBX264=10864=2865=51145=20130809-21:49:00.000000000865=71145=20180618-14:16:00.000000000870=1871=24872=00000000000001000010000000001111996=CHF1147=1250001149=11017.01148=10217.01143=60.01150=10617.0731=0000001110=05460=20170101083711374522774
1128=99=13135=f49=SAMPLE34=289852=2017010105395691562717360=2017010105395691562717375=201701015799=000000001151=6S326=21327=01174=410=046
1128=99=18035=X49=SAMPLE75=2017010134=234452=2017010101105890541592060=201701010110589054159205799=10000100268=1279=0269=148=17359555=6SZ683=354045270=10270.0271=3346=11023=310=086
1128=99=18035=X49=SAMPLE75=2017010134=246252=2017010103290225084511260=201701010329022508451125799=10000100268=1279=0269=148=17359555=6SZ683=354046270=10276.0271=3346=11023=410=108
1128=99=18035=X49=SAMPLE75=2017010134=498652=2017010102165692270207260=201701010216569227020725799=10000100268=1279=0269=048=17359555=6SZ683=354047270=10196.0271=4346=11023=110=103
1128=99=18035=X49=SAMPLE75=2017010134=420452=2017010113445954387865460=201701011344595438786545799=10000100268=1279=0269=048=17359555=6SZ683=354048270=10176.0271=2346=11023=210=101
1128=99=18035=X49=SAMPLE75=2017010134=54852=2017010108534650074560760=201701010853465007456075799=10000100268=1279=0269=048=17359555=6SZ683=354049270=10134.0271=2346=11023=810=091
1128=99=18035=X49=SAMPLE75=2017010134=401252=2017010105570964007686560=201701010557096400768655799=10000100268=1279=0269=048=17359555=6SZ683=354050270=10144.0271=2346=11023=710=077
1128=99=18035=X49=SAMPLE75=2017010134=475652=2017010100120981929357660=201701010012098192935765799=10000100268=1279=1269=148=17359555=6SZ683=354051270=10310.0271=4346=21023=810=077
1128=99=18035=X49=SAMPLE75=2017010134=115052=2017010101190934640318260=201701010119093464031825799=10000100268=1279=0269=148=17359555=6SZ683=354052270=10306.0271=2346=11023=710=080
1128=99=18035=X49=SAMPLE75=2017010134=492552=2017010113345477913552660=201701011334547791355265799=10000100268=1279=1269=148=17359555=6SZ683=354053270=10310.0271=6346=31023=910=094
1128=99=18035=X49=SAMPLE75=2017010134=319252=2017010100501585292464660=201701010050158529246465799=10000100268=1279=0269=048=17359555=6SZ683=354054270=10146.0271=4346=11023=710=120
1128=99=18035=X49=SAMPLE75=2017010134=173452=2017010103215112898908760=201701010321511289890875799=10000100268=1279=0269=048=17359555=6SZ683=354055270=10188.0271=1346=11023=210=079
1128=99=18035=X49=SAMPLE75=2017010134=150552=2017010110355890358059060=201701011035589035805905799=10000100268=1279=0269=148=17359555=6SZ683=354056270=10279.0271=2346=11023=510=070
1128=99=18035=X49=SAMPLE75=2017010134=304352=2017010110013449118066160=201701011001344911806615799=10000100268=1279=1269=148=17359555=6SZ683=354057270=10279.0271=3346=21023=510=120
1128=99=18035=X49=SAMPLE75=2017010134=141652=2017010100320318925937060=201701010032031892593705799=10000100268=1279=0269=148=17359555=6SZ683=354058270=10254.0271=1346=11023=110=097
1128=99=18035=X49=SAMPLE75=2017010134=56452=2017010109531290550237260=201701010953129055023725799=10000100268=1279=0269=148=17359555=6SZ683=354059270=10281.0271=2346=11023=710=078
1128=99=18035=X49=SAMPLE75=2017010134=433652=2017010105375524818339560=201701010537552481833955799=10000100268=1279=0269=148=17359555=6SZ683=354060270=10255.0271=2346=11023=210=074
1128=99=18035=X49=SAMPLE75=2017010134=454952=2017010105533469707685060=201701010553346970768505799=10000100268=1279=1269=148=17359555=6SZ683=354061270=10279.0271=4346=31023=710=068
1128=99=96435=X49=SAMPLE75=2017010134=24552=2017010109213656811245560=201701010921365681124555799=00000100268=12279=2269=048=17359555=6SZ683=354062270=10196.0271=4346=11023=1279=2269=048=17359555=6SZ683=354063270=10188.0271=1346=11023=1279=2269=048=17359555=6SZ683=354064270=10176.0271=2346=11023=1279=2269=048=17359555=6SZ683=354065270=10161.0271=1346=11023=1279=2269=048=17359555=6SZ683=354066270=10156.0271=4346=11023=1279=0269=048=17359555=6SZ683=354067270=10154.0271=12346=51023=1279=0269=048=17359555=6SZ683=354068270=10142.0271=1346=11023=7279=0269=048=17359555=6SZ683=354069270=10134.0271=2346=11023=8279=0269=048=17359555=6SZ683=354070270=10125.0271=1346=11023=9279=0269=048=17359555=6SZ683=354071270=10118.0271=1346=11023=10279=0269=148=17359555=6SZ683=354072270=10154.0271=6346=11023=1279=0269=148=17359555=6SZ683=354073270=10180.0271=2346=11023=210=166
1128=99=16735=X49=SAMPLE75=2017010134=277052=2017010113090522874507360=201701011309052287450735799=10001000268=1279=0269=448=17359555=6SZ683=354074270=10154.0286=510=046
1128=99=89435=X49=SAMPLE75=2017010134=399452=2017010105380817171870560=201701010538081717187055799=10000100268=11279=0269=048=17359555=6SZ683=354075270=10196.0271=4346=11023=1279=0269=048=17359555=6SZ683=354076270=10188.0271=1346=11023=2279=0269=048=17359555=6SZ683=354077270=10176.0271=2346=11023=3279=0269=048=17359555=6SZ683=354078270=10161.0271=1346=11023=4279=0269=048=17359555=6SZ683=354079270=10156.0271=4346=11023=5279=2269=048=17359555=6SZ683=354080270=10154.0271=12346=51023=6279=0269=048=17359555=6SZ683=354081270=10143.0271=2346=11023=10279=2269=148=17359555=6SZ683=354082270=10154.0271=6346=11023=1279=2269=148=17359555=6SZ683=354083270=10180.0271=2346=11023=1279=0269=148=17359555=6SZ683=354084270=10300.0271=1346=11023=9279=0269=148=17359555=6SZ683=354085270=10305.0271=2346=11023=1010=205
1128=99=18035=X49=SAMPLE75=2017010134=458552=2017010100212515410335160=201701010021251541033515799=10000100268=1279=1269=048=17359555=6SZ683=354086270=10196.0271=7346=21023=110=105
1128=99=18135=X49=SAMPLE75=2017010134=303752=2017010105442178586768560=201701010544217858676855799=10000100268=1279=1269=048=17359555=6SZ683=354087270=10196.0271=10346=31023=110=185
1128=99=18135=X49=SAMPLE75=2017010134=231852=2017010104140092411059860=201701010414009241105985799=10000100268=1279=1269=048=17359555=6SZ683=354088270=10196.0271=13346=41023=110=140
1128=99=18135=X49=SAMPLE75=2017010134=123052=2017010104580004180307760=201701010458000418030775799=10000100268=1279=1269=048=17359555=6SZ683=354089270=10196.0271=16346=51023=110=165
1128=99=18135=X49=SAMPLE75=2017010134=249852=2017010100535210913367760=201701010053521091336775799=10000100268=1279=1269=048=17359555=6SZ683=354090270=10196.0271=19346=61023=110=158
1128=99=18135=X49=SAMPLE75=2017010134=62752=2017010113180145981235660=201701011318014598123565799=10000100268=1279=1269=048=17359555=6SZ683=354091270=10196.0271=22346=71023=110=174
1128=99=18135=X49=SAMPLE75=2017010134=394852=2017010107042650470675760=201701010704265047067575799=10000100268=1279=1269=048=17359555=6SZ683=354092270=10196.0271=25346=81023=110=171
1128=99=18135=X49=SAMPLE75=2017010134=268552=2017010104574289649885960=201701010457428964988595799=10000100268=1279=1269=048=17359555=6SZ683=354093270=10196.0271=28346=91023=110=146
1128=99=18035=X49=SAMPLE75=2017010134=72552=2017010108002385164388860=201701010800238516438885799=10000100268=1279=0269=148=17359555=6SZ683=354094270=10229.0271=3346=11023=110=098
1128=99=18035=X49=SAMPLE75=2017010134=66352=2017010108103894831711760=201701010810389483171175799=10000100268=1279=1269=148=17359555=6SZ683=354095270=10229.0271=6346=21023=110=100
1128=99=18035=X49=SAMPLE75=2017010134=128652=2017010111194177101548660=201701011119417710154865799=10000100268=1279=1269=148=17359555=6SZ683=354096270=10229.0271=9346=31023=110=119
1128=99=18135=X49=SAMPLE75=2017010134=183152=2017010109563693272182660=201701010956369327218265799=10000100268=1279=1269=148=17359555=6SZ683=354097270=10229.0271=12346=41023=110=156
1128=99=18135=X49=SAMPLE75=2017010134=46852=2017010107473311228417660=201701010747331122841765799=10000100268=1279=1269=148=17359555=6SZ683=354098270=10229.0271=15346=51023=110=172
1128=99=18135=X49=SAMPLE75=2017010134=493452=2017010100070269124095460=201701010007026912409545799=10000100268=1279=1269=148=17359555=6SZ683=354099270=10229.0271=18346=61023=110=183
1128=99=18135=X49=SAMPLE75=2017010134=429752=2017010101311602839304960=201701010131160283930495799=10000100268=1279=1269=148=17359555=6SZ683=354100270=10229.0271=21346=71023=110=146
1128=99=18135=X49=SAMPLE75=2017010134=353052=2017010107044747322295160=201701010704474732229515799=10000100268=1279=1269=148=17359555=6SZ683=354101270=10229.0271=24346=81023=110=159
1128=99=18135=X49=SAMPLE75=2017010134=233052=2017010106105448283131160=201701010610544828313115799=10000100268=1279=1269=148=17359555=6SZ683=354102270=10229.0271=27346=91023=110=166
1128=99=18235=X49=SAMPLE75=2017010134=17852=2017010106303901408277060=201701010630390140827705799=10000100268=1279=1269=148=17359555=6SZ683=354103270=10229.0271=30346=101023=110=193
1128=99=18035=X49=SAMPLE75=2017010134=7552=2017010100022855255333060=201701010002285525533305799=10000100268=1279=0269=048=17359555=6SZ683=354104270=10197.0271=1346=11023=110=104
1128=99=18035=X49=SAMPLE75=2017010134=94252=2017010111103674387088760=201701011110367438708875799=10000100268=1279=1269=048=17359555=6SZ683=354105270=10197.0271=4346=21023=110=101
1128=99=18035=X49=SAMPLE75=2017010134=321452=2017010106205108914731860=201701010620510891473185799=10000100268=1279=1269=048=17359555=6SZ683=354106270=10197.0271=7346=31023=110=093
1128=99=18135=X49=SAMPLE75=2017010134=487352=2017010106095623398280860=201701010609562339828085799=10000100268=1279=1269=048=17359555=6SZ683=354107270=10197.0271=10346=41023=110=152
1128=99=18135=X49=SAMPLE75=2017010134=340252=2017010102521918283033660=201701010252191828303365799=10000100268=1279=1269=048=17359555=6SZ683=354108270=10197.0271=13346=51023=110=168
1128=99=18135=X49=SAMPLE75=2017010134=203952=2017010108021893222845460=201701010802189322284545799=10000100268=1279=0269=148=17359555=6SZ683=354109270=10277.0271=12346=11023=810=170
1128=99=18035=X49=SAMPLE75=2017010134=290652=2017010113401336450330160=201701011340133645033015799=10000100268=1279=0269=148=17359555=6SZ683=354110270=10216.0271=1346=11023=110=110
1128=99=18135=X49=SAMPLE75=2017010134=98552=2017010106254371375455360=201701010625437137545535799=10000100268=1279=0269=148=17359555=6SZ683=354111270=10250.0271=10346=11023=310=117
1128=99=18035=X49=SAMPLE75=2017010134=461952=2017010110493024713085060=201701011049302471308505799=10000100268=1279=0269=048=17359555=6SZ683=354112270=10157.0271=3346=11023=610=090
1128=99=18035=X49=SAMPLE75=2017010134=27552=2017010100135569606276060=201701010013556960627605799=10000100268=1279=0269=148=17359555=6SZ683=354113270=10228.0271=3346=11023=210=094
1128=99=18135=X49=SAMPLE75=2017010134=103552=2017010100221550854375160=201701010022155085437515799=10000100268=1279=0269=048=17359555=6SZ683=354114270=10155.0271=10346=11023=810=143
1128=99=18035=X49=SAMPLE75=2017010134=406052=2017010100333613968274160=201701010033361396827415799=10000100268=1279=1269=148=17359555=6SZ683=354115270=10228.0271=6346=21023=210=123
1128=99=18035=X49=SAMPLE75=2017010134=326452=2017010102580080862905060=201701010258008086290505799=10000100268=1279=0269=148=17359555=6SZ683=354116270=10227.0271=3346=11023=210=124
1128=99=18035=X49=SAMPLE75=2017010134=468252=2017010101003753368736360=201701010100375336873635799=10000100268=1279=1269=148=17359555=6SZ683=354117270=10228.0271=9346=31023=310=129
1128=99=18135=X49=SAMPLE75=2017010134=356252=2017010103241499296610160=201701010324149929661015799=10000100268=1279=1269=148=17359555=6SZ683=354118270=10228.0271=12346=41023=310=148
1128=99=18135=X49=SAMPLE75=2017010134=424652=2017010102013914317910760=201701010201391431791075799=10000100268=1279=1269=148=17359555=6SZ683=354119270=10228.0271=15346=51023=310=181
1128=99=18135=X49=SAMPLE75=2017010134=102852=2017010109152859758757460=201701010915285975875745799=10000100268=1279=1269=148=17359555=6SZ683=354120270=10228.0271=18346=61023=310=167
1128=99=18035=X49=SAMPLE75=2017010134=89052=2017010101115307693007260=201701010111530769300725799=10000100268=1279=1269=148=17359555=6SZ683=354121270=10227.0271=6346=21023=210=095
1128=99=25235=X49=SAMPLE75=2017010134=458052=2017010107121982344490660=201701010712198234449065799=10000100268=2279=0269=148=17359555=6SZ683=354122270=10226.0271=3346=11023=2279=1269=148=17359555=6SZ683=354123270=10228.0271=15346=51023=410=198
1128=99=18035=X49=SAMPLE75=2017010134=158852=2017010109203158652213760=201701010920315865221375799=10000100268=1279=1269=148=17359555=6SZ683=354124270=10227.0271=9346=31023=310=112
1128=99=18135=X49=SAMPLE75=2017010134=375252=2017010104285426237183860=201701010428542623718385799=10000100268=1279=1269=148=17359555=6SZ683=354125270=10227.0271=12346=41023=310=166
1128=99=18135=X49=SAMPLE75=2017010134=245652=2017010113580335799276460=201701011358033579927645799=10000100268=1279=1269=148=17359555=6SZ683=354126270=10227.0271=15346=51023=310=159
1128=99=18135=X49=SAMPLE75=2017010134=402652=2017010109130824015361060=201701010913082401536105799=10000100268=1279=1269=148=17359555=6SZ683=354127270=10227.0271=18346=61023=310=173
1128=99=18035=X49=SAMPLE75=2017010134=209252=2017010105225750163198760=201701010522575016319875799=10000100268=1279=1269=148=17359555=6SZ683=354128270=10226.0271=6346=21023=210=123
1128=99=25235=X49=SAMPLE75=2017010134=370052=2017010113265282025250660=201701011326528202525065799=10000100268=2279=0269=148=17359555=6SZ683=354129270=10225.0271=3346=11023=2279=1269=148=17359555=6SZ683=354130270=10227.0271=15346=51023=410=205
1128=99=18035=X49=SAMPLE75=2017010134=289852=2017010110332661553345860=201701011033266155334585799=10000100268=1279=1269=148=17359555=6SZ683=354131270=10226.0271=9346=31023=310=108
1128=99=18135=X49=SAMPLE75=2017010134=166652=2017010108262022062334760=201701010826202206233475799=10000100268=1279=1269=148=17359555=6SZ683=354132270=10226.0271=12346=41023=310=168
1128=99=18135=X49=SAMPLE75=2017010134=34952=2017010102554603648465560=201701010255460364846555799=10000100268=1279=1269=148=17359555=6SZ683=354133270=10226.0271=15346=51023=310=164
1128=99=18135=X49=SAMPLE75=2017010134=223452=2017010108431921775395060=201701010843192177539505799=10000100268=1279=1269=148=17359555=6SZ683=354134270=10226.0271=18346=61023=310=151
1128=99=18135=X49=SAMPLE75=2017010134=256752=2017010113070066391338560=201701011307006639133855799=10000100268=1279=1269=148=17359555=6SZ683=354135270=10229.0271=27346=91023=610=180
1128=99=18135=X49=SAMPLE75=2017010134=478952=2017010111560898170118760=201701011156089817011875799=10000100268=1279=1269=148=17359555=6SZ683=354136270=10229.0271=24346=81023=610=164
1128=99=18135=X49=SAMPLE75=2017010134=297652=2017010100303084266069960=201701010030308426606995799=10000100268=1279=1269=148=17359555=6SZ683=354137270=10229.0271=21346=71023=610=167
1128=99=18135=X49=SAMPLE75=2017010134=417752=2017010110043555012595560=201701011004355501259555799=10000100268=1279=1269=148=17359555=6SZ683=354138270=10229.0271=18346=61023=610=189
1128=99=18135=X49=SAMPLE75=2017010134=235952=2017010104572567323722060=201701010457256732372205799=10000100268=1279=1269=148=17359555=6SZ683=354139270=10229.0271=15346=51023=610=174
1128=99=18135=X49=SAMPLE75=2017010134=198152=2017010113461972019300360=201701011346197201930035799=10000100268=1279=1269=148=17359555=6SZ683=354140270=10229.0271=12346=41023=610=176
1128=99=18035=X49=SAMPLE75=2017010134=361252=2017010104320757755077860=201701010432075775507785799=10000100268=1279=1269=148=17359555=6SZ683=354141270=10229.0271=9346=31023=610=120
1128=99=18035=X49=SAMPLE75=2017010134=39652=2017010101525320323756060=201701010152532032375605799=10000100268=1279=1269=148=17359555=6SZ683=354142270=10229.0271=6346=21023=610=112
1128=99=18035=X49=SAMPLE75=2017010134=67052=2017010112521590739716660=201701011252159073971665799=10000100268=1279=1269=148=17359555=6SZ683=354143270=10229.0271=3346=11023=610=128
1128=99=25235=X49=SAMPLE75=2017010134=1452=2017010109470090260251060=201701010947009026025105799=10000100268=2279=2269=148=17359555=6SZ683=354144270=10229.0271=3346=11023=6279=0269=148=17359555=6SZ683=354145270=10265.0271=1346=11023=1010=224
1128=99=18135=X49=SAMPLE75=2017010134=337152=2017010112172711008988760=201701011217271100898875799=10000100268=1279=1269=148=17359555=6SZ683=354146270=10227.0271=12346=41023=410=163
1128=99=18035=X49=SAMPLE75=2017010134=84452=2017010101074691170593560=201701010107469117059355799=10000100268=1279=1269=148=17359555=6SZ683=354147270=10227.0271=9346=31023=410=099
1128=99=18035=X49=SAMPLE75=2017010134=455552=2017010114125497296110560=201701011412549729611055799=10000100268=1279=1269=148=17359555=6SZ683=354148270=10227.0271=6346=21023=410=107
1128=99=18035=X49=SAMPLE75=2017010134=497552=2017010110255248870737160=201701011025524887073715799=10000100268=1279=1269=148=17359555=6SZ683=354149270=10227.0271=3346=11023=410=137
1128=99=25235=X49=SAMPLE75=2017010134=461452=2017010112422242038145060=201701011242224203814505799=10000100268=2279=2269=148=17359555=6SZ683=354150270=10227.0271=3346=11023=4279=0269=148=17359555=6SZ683=354151270=10270.0271=3346=11023=1010=185
1128=99=18135=X49=SAMPLE75=2017010134=326352=2017010105243636932350860=201701010524363693235085799=10000100268=1279=1269=148=17359555=6SZ683=354152270=10226.0271=15346=51023=310=186
1128=99=18135=X49=SAMPLE75=2017010134=313452=2017010108351707201135460=201701010835170720113545799=10000100268=1279=1269=148=17359555=6SZ683=354153270=10226.0271=12346=41023=310=171
1128=99=18035=X49=SAMPLE75=2017010134=236052=2017010108580704852670560=201701010858070485267055799=10000100268=1279=1269=148=17359555=6SZ683=354154270=10226.0271=9346=31023=310=134
1128=99=18035=X49=SAMPLE75=2017010134=159952=2017010105155299730373760=201701010515529973037375799=10000100268=1279=1269=148=17359555=6SZ683=354155270=10226.0271=6346=21023=310=118
1128=99=18035=X49=SAMPLE75=2017010134=184352=2017010103001336401972260=201701010300133640197225799=10000100268=1279=1269=148=17359555=6SZ683=354156270=10226.0271=3346=11023=310=120
1128=99=18135=X49=SAMPLE75=2017010134=176552=2017010107365484635312260=201701010736548463531225799=10000100268=1279=1269=148=17359555=6SZ683=354157270=10228.0271=12346=41023=410=171
1128=99=18035=X49=SAMPLE75=2017010134=484052=2017010106021720559334660=201701010602172055933465799=10000100268=1279=1269=148=17359555=6SZ683=354158270=10228.0271=9346=31023=410=139
1128=99=18035=X49=SAMPLE75=2017010134=34052=2017010104582366624908260=201701010458236662490825799=10000100268=1279=1269=148=17359555=6SZ683=354159270=10228.0271=6346=21023=410=131
1128=99=18035=X49=SAMPLE75=2017010134=463952=2017010101421117082555660=201701010142111708255565799=10000100268=1279=1269=148=17359555=6SZ683=354160270=10228.0271=3346=11023=410=126
1128=99=25135=X49=SAMPLE75=2017010134=281652=2017010108521592015551660=201701010852159201555165799=10000100268=2279=2269=148=17359555=6SZ683=354161270=10225.0271=3346=11023=2279=0269=148=17359555=6SZ683=354162270=10249.0271=1346=11023=410=166
1128=99=25235=X49=SAMPLE75=2017010134=186552=2017010106063137431692860=201701010606313743169285799=10000100268=2279=2269=148=17359555=6SZ683=354163270=10228.0271=3346=11023=3279=0269=148=17359555=6SZ683=354164270=10276.0271=3346=11023=1010=221
1128=99=25335=X49=SAMPLE75=2017010134=20052=2017010100570959446116960=201701010057095944611695799=10000100268=2279=2269=148=17359555=6SZ683=354165270=10226.0271=3346=11023=2279=0269=148=17359555=6SZ683=354166270=10277.0271=12346=11023=1010=023
1128=99=18035=X49=SAMPLE75=2017010134=249652=2017010103103359616536860=201701010310335961653685799=10000100268=1279=0269=148=17359555=6SZ683=354167270=10227.0271=3346=11023=210=119
1128=99=18035=X49=SAMPLE75=2017010134=170152=2017010106045859626684560=201701010604585962668455799=10000100268=1279=1269=148=17359555=6SZ683=354168270=10227.0271=6346=21023=210=128
1128=99=18035=X49=SAMPLE75=2017010134=176152=2017010112453476047784260=201701011245347604778425799=10000100268=1279=0269=148=17359555=6SZ683=354169270=10226.0271=3346=11023=210=127
1128=99=18035=X49=SAMPLE75=2017010134=19152=2017010108465446010748260=201701010846544601074825799=10000100268=1279=1269=148=17359555=6SZ683=354170270=10227.0271=9346=31023=310=128
1128=99=18035=X49=SAMPLE75=2017010134=321452=2017010103382908129650960=201701010338290812965095799=10000100268=1279=1269=148=17359555=6SZ683=354171270=10227.0271=6346=21023=310=108
1128=99=18035=X49=SAMPLE75=2017010134=234152=2017010104382650814521160=201701010438265081452115799=10000100268=1279=1269=148=17359555=6SZ683=354172270=10227.0271=3346=11023=310=061
1128=99=25235=X49=SAMPLE75=2017010134=48352=2017010113370580219761660=201701011337058021976165799=10000100268=2279=2269=148=17359555=6SZ683=354173270=10227.0271=3346=11023=3279=0269=148=17359555=6SZ683=354174270=10276.0271=3346=11023=1010=204
1128=99=25335=X49=SAMPLE75=2017010134=282852=2017010113455474543242660=201701011345547454324265799=10000100268=2279=2269=148=17359555=6SZ683=354175270=10226.0271=3346=11023=2279=0269=148=17359555=6SZ683=354176270=10277.0271=12346=11023=1010=227
1128=99=18035=X49=SAMPLE75=2017010134=174052=2017010100015452463555160=201701010001545246355515799=10000100268=1279=1269=148=17359555=6SZ683=354177270=10216.0271=4346=21023=110=128
1128=99=18035=X49=SAMPLE75=2017010134=194852=2017010106155044929677460=201701010615504492967745799=10000100268=1279=1269=148=17359555=6SZ683=354178270=10216.0271=7346=31023=110=137
1128=99=18035=X49=SAMPLE75=2017010134=200752=2017010107412711710516460=201701010741271171051645799=10000100268=1279=0269=148=17359555=6SZ683=354179270=10225.0271=3346=11023=210=104
1128=99=18035=X49=SAMPLE75=2017010134=38452=2017010103443284454948360=201701010344328445494835799=10000100268=1279=1269=148=17359555=6SZ683=354180270=10225.0271=6346=21023=210=110
1128=99=18035=X49=SAMPLE75=2017010134=205952=2017010112051793302720360=201701011205179330272035799=10000100268=1279=1269=148=17359555=6SZ683=354181270=10225.0271=9346=31023=210=070
1128=99=18135=X49=SAMPLE75=2017010134=118252=2017010106345494787847360=201701010634549478784735799=10000100268=1279=1269=148=17359555=6SZ683=354182270=10225.0271=12346=41023=210=136
1128=99=18135=X49=SAMPLE75=2017010134=179452=2017010112031183088600060=201701011203118308860005799=10000100268=1279=1269=148=17359555=6SZ683=354183270=10225.0271=15346=51023=210=158
1128=99=18035=X49=SAMPLE75=2017010134=220452=2017010105215411252411460=201701010521541125241145799=10000100268=1279=0269=148=17359555=6SZ683=354184270=10224.0271=3346=11023=210=094
1128=99=18135=X49=SAMPLE75=2017010134=1152=2017010106544474744259160=201701010654447474425915799=10000100268=1279=1269=148=17359555=6SZ683=354185270=10225.0271=18346=61023=310=144
1128=99=18035=X49=SAMPLE75=2017010134=81952=2017010107410768071695160=201701010741076807169515799=10000100268=1279=0269=148=17359555=6SZ683=354186270=10223.0271=3346=11023=210=119
1128=99=18035=X49=SAMPLE75=2017010134=45252=2017010100143470022925760=201701010014347002292575799=10000100268=1279=1269=148=17359555=6SZ683=354187270=10223.0271=6346=21023=210=113
1128=99=18035=X49=SAMPLE75=2017010134=370852=2017010110104855851037960=201701011010485585103795799=10000100268=1279=0269=148=17359555=6SZ683=354188270=10222.0271=2346=11023=210=075
1128=99=18035=X49=SAMPLE75=2017010134=263052=2017010100035154737715160=201701010003515473771515799=10000100268=1279=0269=148=17359555=6SZ683=354189270=10221.0271=3346=11023=210=104
1128=99=18035=X49=SAMPLE75=2017010134=46052=2017010105090602339008660=201701010509060233900865799=10000100268=1279=1269=148=17359555=6SZ683=354190270=10221.0271=6346=21023=210=074
1128=99=18035=X49=SAMPLE75=2017010134=383652=2017010104293432027951260=201701010429343202795125799=10000100268=1279=1269=148=17359555=6SZ683=354191270=10221.0271=9346=31023=210=119
1128=99=32335=X49=SAMPLE75=2017010134=21152=2017010108384766291813860=201701010838476629181385799=10000100268=3279=0269=148=17359555=6SZ683=354192270=10220.0271=3346=11023=2279=2269=148=17359555=6SZ683=354193270=10224.0271=3346=11023=6279=0269=148=17359555=6SZ683=354194270=10255.0271=2346=11023=1010=009
1128=99=18035=X49=SAMPLE75=2017010134=233652=2017010101485786297176460=201701010148578629717645799=10000100268=1279=0269=148=17359555=6SZ683=354195270=10219.0271=3346=11023=210=123
1128=99=25235=X49=SAMPLE75=2017010134=201752=2017010110132264735446860=201701011013226473544685799=10000100268=2279=2269=148=17359555=6SZ683=354196270=10222.0271=2346=11023=5279=0269=148=17359555=6SZ683=354197270=10255.0271=2346=11023=1010=228
1128=99=18035=X49=SAMPLE75=2017010134=291252=2017010106592046454471060=201701010659204645447105799=10000100268=1279=1269=148=17359555=6SZ683=354198270=10219.0271=6346=21023=210=115
1128=99=18035=X49=SAMPLE75=2017010134=247952=2017010105485044399840360=201701010548504439984035799=10000100268=1279=1269=148=17359555=6SZ683=354199270=10219.0271=9346=31023=210=132
1128=99=25235=X49=SAMPLE75=2017010134=364952=2017010107065757244611760=201701010706575724461175799=10000100268=2279=2269=148=17359555=6SZ683=354200270=10220.0271=3346=11023=3279=0269=148=17359555=6SZ683=354201270=10263.0271=2346=11023=1010=170
1128=99=18035=X49=SAMPLE75=2017010134=166052=2017010100243354336826860=201701010024335433682685799=10000100268=1279=0269=148=17359555=6SZ683=354202270=10231.0271=3346=11023=610=061
1128=99=18035=X49=SAMPLE75=2017010134=401852=2017010107542331303577160=201701010754233130357715799=10000100268=1279=1269=148=17359555=6SZ683=354203270=10231.0271=6346=21023=610=078
1128=99=18035=X49=SAMPLE75=2017010134=304352=2017010102130283258033860=201701010213028325803385799=10000100268=1279=1269=148=17359555=6SZ683=354204270=10231.0271=9346=31023=610=083
1128=99=18135=X49=SAMPLE75=2017010134=421952=2017010111283516582433760=201701011128351658243375799=10000100268=1279=1269=148=17359555=6SZ683=354205270=10231.0271=12346=41023=610=147
1128=99=18135=X49=SAMPLE75=2017010134=38752=2017010107024099772616360=201701010702409977261635799=10000100268=1279=1269=148=17359555=6SZ683=354206270=10231.0271=15346=51023=610=161
1128=99=18135=X49=SAMPLE75=2017010134=275052=2017010108355833438101560=201701010835583343810155799=10000100268=1279=1269=148=17359555=6SZ683=354207270=10231.0271=18346=61023=610=162
1128=99=18135=X49=SAMPLE75=2017010134=304952=2017010100362356363643660=201701010036235636364365799=10000100268=1279=1269=148=17359555=6SZ683=354208270=10231.0271=21346=71023=610=152
1128=99=18135=X49=SAMPLE75=2017010134=285352=2017010110035989457321960=201701011003598945732195799=10000100268=1279=1269=148=17359555=6SZ683=354209270=10231.0271=24346=81023=610=183
1128=99=18135=X49=SAMPLE75=2017010134=321752=2017010109135607182761060=201701010913560718276105799=10000100268=1279=1269=148=17359555=6SZ683=354210270=10231.0271=27346=91023=610=156
1128=99=18035=X49=SAMPLE75=2017010134=163652=2017010106254589401631760=201701010625458940163175799=10000100268=1279=1269=148=17359555=6SZ683=354211270=10216.0271=6346=21023=110=132
1128=99=18035=X49=SAMPLE75=2017010134=230752=2017010110303829944203360=201701011030382994420335799=10000100268=1279=0269=148=17359555=6SZ683=354212270=10218.0271=3346=11023=210=107
1128=99=18035=X49=SAMPLE75=2017010134=192752=2017010111031713967854160=201701011103171396785415799=10000100268=1279=0269=048=17359555=6SZ683=354213270=10201.0271=3346=11023=110=071
1128=99=18035=X49=SAMPLE75=2017010134=430952=2017010111295014475045560=201701011129501447504555799=10000100268=1279=1269=048=17359555=6SZ683=354214270=10201.0271=6346=21023=110=113
1128=99=18035=X49=SAMPLE75=2017010134=416752=2017010102074108310007760=201701010207410831000775799=10000100268=1279=1269=048=17359555=6SZ683=354215270=10201.0271=9346=31023=110=130
1128=99=18135=X49=SAMPLE75=2017010134=435452=2017010103215396317114860=201701010321539631711485799=10000100268=1279=1269=048=17359555=6SZ683=354216270=10201.0271=12346=41023=110=170
1128=99=18135=X49=SAMPLE75=2017010134=149352=2017010108101891281304960=201701010810189128130495799=10000100268=1279=1269=048=17359555=6SZ683=354217270=10201.0271=15346=51023=110=142
1128=99=18135=X49=SAMPLE75=2017010134=334652=2017010103581075665693360=201701010358107566569335799=10000100268=1279=1269=048=17359555=6SZ683=354218270=10201.0271=18346=61023=110=145
1128=99=18135=X49=SAMPLE75=2017010134=317752=2017010107205624011235260=201701010720562401123525799=10000100268=1279=1269=048=17359555=6SZ683=354219270=10201.0271=21346=71023=110=180
1128=99=18135=X49=SAMPLE75=2017010134=62052=2017010107165371193827160=201701010716537119382715799=10000100268=1279=1269=048=17359555=6SZ683=354220270=10201.0271=24346=81023=110=146
1128=99=18135=X49=SAMPLE75=2017010134=499652=2017010111091386150356960=201701011109138615035695799=10000100268=1279=1269=048=17359555=6SZ683=354221270=10201.0271=27346=91023=110=162
1128=99=18135=X49=SAMPLE75=2017010134=458852=2017010114183741257383460=201701011418374125738345799=10000100268=1279=1269=148=17359555=6SZ683=354222270=10219.0271=10346=41023=310=141
1128=99=18135=X49=SAMPLE75=2017010134=329052=2017010108123858754779560=201701010812385875477955799=10000100268=1279=1269=148=17359555=6SZ683=354223270=10219.0271=13346=51023=310=174
1128=99=18135=X49=SAMPLE75=2017010134=484552=2017010113272437943668860=201701011327243794366885799=10000100268=1279=1269=148=17359555=6SZ683=354224270=10219.0271=16346=61023=310=169
1128=99=18035=X49=SAMPLE75=2017010134=91352=2017010111325826483667960=201701011132582648366795799=10000100268=1279=1269=148=17359555=6SZ683=354225270=10218.0271=4346=21023=210=133
1128=99=25235=X49=SAMPLE75=2017010134=244352=2017010106003442030478160=201701010600344203047815799=10000100268=2279=0269=048=17359555=6SZ683=354226270=10202.0271=1346=11023=1279=1269=048=17359555=6SZ683=354227270=10197.0271=12346=41023=310=233
1128=99=18035=X49=SAMPLE75=2017010134=143252=2017010110524508520062960=201701011052450852006295799=10000100268=1279=0269=048=17359555=6SZ683=354228270=10170.0271=1346=11023=710=130
1128=99=18035=X49=SAMPLE75=2017010134=225152=2017010110005082257442860=201701011000508225744285799=10000100268=1279=1269=048=17359555=6SZ683=354229270=10202.0271=4346=21023=110=099
1128=99=18035=X49=SAMPLE75=2017010134=277652=2017010113380725612195160=201701011338072561219515799=10000100268=1279=1269=048=17359555=6SZ683=354230270=10202.0271=7346=31023=110=076
1128=99=18135=X49=SAMPLE75=2017010134=241652=2017010106292363656362760=201701010629236365636275799=10000100268=1279=1269=048=17359555=6SZ683=354231270=10202.0271=10346=41023=110=127
1128=99=18135=X49=SAMPLE75=2017010134=5952=2017010114180061779897960=201701011418006177989795799=10000100268=1279=1269=048=17359555=6SZ683=354232270=10202.0271=13346=51023=110=145
1128=99=18135=X49=SAMPLE75=2017010134=21352=2017010108314495389681660=201701010831449538968165799=10000100268=1279=1269=048=17359555=6SZ683=354233270=10202.0271=16346=61023=110=161
1128=99=18135=X49=SAMPLE75=2017010134=353152=2017010111143523143198760=201701011114352314319875799=10000100268=1279=1269=048=17359555=6SZ683=354234270=10202.0271=19346=71023=110=154
1128=99=18035=X49=SAMPLE75=2017010134=121452=2017010114153829410142660=201701011415382941014265799=10000100268=1279=0269=048=17359555=6SZ683=354235270=10205.0271=3346=11023=110=085
1128=99=18035=X49=SAMPLE75=2017010134=155752=2017010102104829802178560=201701010210482980217855799=10000100268=1279=1269=148=17359555=6SZ683=354236270=10218.0271=1346=11023=210=098
1128=99=18035=X49=SAMPLE75=2017010134=430152=2017010101304899289349760=201701010130489928934975799=10000100268=1279=1269=048=17359555=6SZ683=354237270=10205.0271=6346=21023=110=099
1128=99=18035=X49=SAMPLE75=2017010134=44752=2017010109211617219656460=201701010921161721965645799=10000100268=1279=1269=048=17359555=6SZ683=354238270=10205.0271=9346=31023=110=132
1128=99=18135=X49=SAMPLE75=2017010134=105852=2017010102252830766408660=201701010225283076640865799=10000100268=1279=1269=048=17359555=6SZ683=354239270=10205.0271=12346=41023=110=155
1128=99=18135=X49=SAMPLE75=2017010134=41552=2017010109103069823968960=201701010910306982396895799=10000100268=1279=1269=048=17359555=6SZ683=354240270=10205.0271=15346=51023=110=172
1128=99=18135=X49=SAMPLE75=2017010134=16452=2017010109321865807522160=201701010932186580752215799=10000100268=1279=1269=048=17359555=6SZ683=354241270=10205.0271=18346=61023=110=132
1128=99=18035=X49=SAMPLE75=2017010134=177352=2017010104320732836617160=201701010432073283661715799=10000100268=1279=1269=148=17359555=6SZ683=354242270=10216.0271=9346=31023=110=101
1128=99=18035=X49=SAMPLE75=2017010134=161552=2017010110484069876890560=201701011048406987689055799=10000100268=1279=0269=048=17359555=6SZ683=354243270=10200.0271=1346=11023=410=108
1128=99=18035=X49=SAMPLE75=2017010134=197152=2017010110180936830063760=201701011018093683006375799=10000100268=1279=0269=048=17359555=6SZ683=354244270=10195.0271=1346=11023=710=138
1128=99=18135=X49=SAMPLE75=2017010134=209152=2017010105391796096971860=201701010539179609697185799=10000100268=1279=1269=148=17359555=6SZ683=354245270=10221.0271=10346=41023=410=141
1128=99=18035=X49=SAMPLE75=2017010134=69652=2017010101083126882982260=201701010108312688298225799=10000100268=1279=0269=148=17359555=6SZ683=354246270=10226.0271=1346=11023=710=103
1128=99=13135=f49=SAMPLE34=488352=2017010104404510958935960=2017010104404510958935975=201701015799=000000001151=6S326=21327=01174=110=067
1128=99=18035=X49=SAMPLE75=2017010134=34352=2017010109122928066667660=201701010912292806666765799=10000100268=1279=0269=048=17359555=6SZ683=354247270=10206.0271=5346=11023=110=124
1128=99=18035=X49=SAMPLE75=2017010134=254452=2017010107145799129899460=201701010714579912989945799=10000100268=1279=0269=048=17359555=6SZ683=354248270=10207.0271=3346=11023=110=075
1128=99=18035=X49=SAMPLE75=2017010134=131252=2017010111261080650213460=201701011126108065021345799=10000100268=1279=1269=048=17359555=6SZ683=354249270=10207.0271=6346=21023=110=134
1128=99=18035=X49=SAMPLE75=2017010134=76052=2017010105073677594299960=201701010507367759429995799=10000100268=1279=0269=148=17359555=6SZ683=354250270=10215.0271=2346=11023=110=099
1128=99=18035=X49=SAMPLE75=2017010134=106252=2017010106440456935123460=201701010644045693512345799=10000100268=1279=1269=148=17359555=6SZ683=354251270=10215.0271=5346=21023=110=126
1128=99=18035=X49=SAMPLE75=2017010134=378952=2017010100465423571227260=201701010046542357122725799=10000100268=1279=1269=148=17359555=6SZ683=354252270=10215.0271=8346=31023=110=127
1128=99=18135=X49=SAMPLE75=2017010134=157652=2017010110313136610238660=201701011031313661023865799=10000100268=1279=1269=148=17359555=6SZ683=354253270=10215.0271=11346=41023=110=176
1128=99=18135=X49=SAMPLE75=2017010134=435852=2017010114274751248278460=201701011427475124827845799=10000100268=1279=1269=148=17359555=6SZ683=354254270=10215.0271=14346=51023=110=168
1128=99=18035=X49=SAMPLE75=2017010134=341552=2017010103463240667470160=201701010346324066747015799=10000100268=1279=0269=048=17359555=6SZ683=354255270=10208.0271=2346=11023=110=141
1128=99=18135=X49=SAMPLE75=2017010134=127652=2017010108523352453776960=201701010852335245377695799=10000100268=1279=1269=148=17359555=6SZ683=354256270=10215.0271=17346=61023=110=162
1128=99=18035=X49=SAMPLE75=2017010134=92352=2017010114223450924453560=201701011422345092445355799=10000100268=1279=1269=048=17359555=6SZ683=354257270=10206.0271=6346=21023=310=123
1128=99=18035=X49=SAMPLE75=2017010134=26952=2017010112410131803973760=201701011241013180397375799=10000100268=1279=1269=048=17359555=6SZ683=354258270=10207.0271=7346=31023=210=119
1128=99=18235=X49=SAMPLE75=2017010134=190552=2017010101513291786906460=201701010151329178690645799=10000100268=1279=0269=148=17359555=6SZ683=354259270=10233.0271=32346=11023=1010=196
1128=99=18035=X49=SAMPLE75=2017010134=452552=2017010102013567490358560=201701010201356749035855799=10000100268=1279=0269=148=17359555=6SZ683=354260270=10220.0271=8346=11023=510=101
1128=99=18135=X49=SAMPLE75=2017010134=105152=2017010105352387648939960=201701010535238764893995799=10000100268=1279=1269=148=17359555=6SZ683=354261270=10225.0271=34346=71023=810=160
1128=99=18135=X49=SAMPLE75=2017010134=62252=2017010107502212046140060=201701010750221204614005799=10000100268=1279=1269=148=17359555=6SZ683=354262270=10225.0271=50346=81023=810=158
1128=99=18135=X49=SAMPLE75=2017010134=459152=2017010102505556711941260=201701010250555671194125799=10000100268=1279=1269=148=17359555=6SZ683=354263270=10220.0271=16346=21023=510=148
1128=99=18135=X49=SAMPLE75=2017010134=302652=2017010102581587557091360=201701010258158755709135799=10000100268=1279=1269=148=17359555=6SZ683=354264270=10220.0271=24346=31023=510=138
1128=99=18035=X49=SAMPLE75=2017010134=452452=2017010102161222106837160=201701010216122210683715799=10000100268=1279=0269=048=17359555=6SZ683=354265270=10211.0271=4346=11023=110=114
1128=99=18035=X49=SAMPLE75=2017010134=319452=2017010109211407391815960=201701010921140739181595799=00000100268=1279=0269=048=17359555=6SZ683=354266270=10215.0271=4346=11023=110=135
1128=99=16735=X49=SAMPLE75=2017010134=364752=2017010101365317207216960=201701010136531720721695799=10001000268=1279=0269=448=17359555=6SZ683=354267270=10215.0286=510=088
1128=99=18035=X49=SAMPLE75=2017010134=142352=2017010107103419539659360=201701010710341953965935799=10000100268=1279=1269=148=17359555=6SZ683=354268270=10218.0271=9346=21023=310=123
1128=99=18135=X49=SAMPLE75=2017010134=39152=2017010112102415561324760=201701011210241556132475799=10000100268=1279=1269=148=17359555=6SZ683=354269270=10220.0271=32346=41023=510=165
1128=99=18135=X49=SAMPLE75=2017010134=347952=2017010112103554932822460=201701011210355493282245799=10000100268=1279=1269=148=17359555=6SZ683=354270270=10223.0271=22346=31023=710=177
1128=99=18135=X49=SAMPLE75=2017010134=436452=2017010113373380869927460=201701011337338086992745799=10000100268=1279=1269=148=17359555=6SZ683=354271270=10215.0271=18346=71023=110=192
1128=99=18135=X49=SAMPLE75=2017010134=286452=2017010103512009832083060=201701010351200983208305799=10000100268=1279=1269=148=17359555=6SZ683=354272270=10215.0271=19346=81023=110=174
1128=99=18135=X49=SAMPLE75=2017010134=314452=2017010105472376033917960=201701010547237603391795799=10000100268=1279=1269=148=17359555=6SZ683=354273270=10215.0271=20346=91023=110=193
1128=99=39435=X49=SAMPLE75=2017010134=79152=2017010112435608709387260=201701011243560870938725799=00000100268=4279=2269=048=17359555=6SZ683=354274270=10215.0271=4346=11023=1279=0269=048=17359555=6SZ683=354275270=10214.0271=4346=11023=1279=0269=148=17359555=6SZ683=354276270=10214.0271=4346=41023=1279=1269=148=17359555=6SZ683=354277270=10215.0271=17346=61023=210=046
1128=99=16735=X49=SAMPLE75=2017010134=7152=2017010103555512189798660=201701010355551218979865799=10001000268=1279=0269=448=17359555=6SZ683=354278270=10214.0286=510=066
1128=99=18035=X49=SAMPLE75=2017010134=106552=2017010112485388342039660=201701011248538834203965799=10000100268=1279=1269=148=17359555=6SZ683=354279270=10214.0271=5346=51023=110=149
1128=99=18035=X49=SAMPLE75=2017010134=446852=2017010104015890214423960=201701010401589021442395799=10000100268=1279=1269=148=17359555=6SZ683=354280270=10214.0271=6346=61023=110=129
1128=99=18035=X49=SAMPLE75=2017010134=181852=2017010110211397936938960=201701011021139793693895799=10000100268=1279=1269=148=17359555=6SZ683=354281270=10214.0271=7346=71023=110=136
1128=99=18035=X49=SAMPLE75=2017010134=6152=2017010112284366911645360=201701011228436691164535799=10000100268=1279=1269=148=17359555=6SZ683=354282270=10214.0271=8346=81023=110=131
1128=99=18035=X49=SAMPLE75=2017010134=94952=2017010111390211050706760=201701011139021105070675799=10000100268=1279=1269=148=17359555=6SZ683=354283270=10214.0271=9346=91023=110=156
1128=99=18235=X49=SAMPLE75=2017010134=439452=2017010111320561699824360=201701011132056169982435799=10000100268=1279=1269=148=17359555=6SZ683=354284270=10214.0271=10346=101023=110=221
1128=99=18235=X49=SAMPLE75=2017010134=75152=2017010106223051424216960=201701010622305142421695799=10000100268=1279=1269=148=17359555=6SZ683=354285270=10214.0271=11346=111023=110=211
1128=99=18135=X49=SAMPLE75=2017010134=449052=2017010113464943739489160=201701011346494373948915799=10000100268=1279=1269=048=17359555=6SZ683=354286270=10208.0271=23346=21023=310=174
1128=99=32335=X49=SAMPLE75=2017010134=401452=2017010101354828763343060=201701010135482876334305799=00000100268=3279=2269=048=17359555=6SZ683=354287270=10214.0271=4346=11023=1279=0269=048=17359555=6SZ683=354288270=10212.0271=4346=11023=1279=0269=148=17359555=6SZ683=354289270=10212.0271=21346=11023=110=253
1128=99=16735=X49=SAMPLE75=2017010134=327652=2017010107331727005545260=201701010733172700554525799=10001000268=1279=0269=448=17359555=6SZ683=354290270=10212.0286=510=067
1128=99=18135=X49=SAMPLE75=2017010134=477852=2017010111121470517777360=201701011112147051777735799=10000100268=1279=1269=048=17359555=6SZ683=354291270=10207.0271=28346=41023=410=167
1128=99=18135=X49=SAMPLE75=2017010134=111252=2017010100104920088226760=201701010010492008822675799=10000100268=1279=0269=148=17359555=6SZ683=354292270=10213.0271=21346=11023=210=155
1128=99=18135=X49=SAMPLE75=2017010134=498552=2017010110390981093345760=201701011039098109334575799=10000100268=1279=1269=048=17359555=6SZ683=354293270=10206.0271=27346=31023=510=177
1128=99=18235=X49=SAMPLE75=2017010134=130552=2017010112054357366134660=201701011205435736613465799=10000100268=1279=1269=148=17359555=6SZ683=354294270=10214.0271=32346=121023=310=238
1128=99=18135=X49=SAMPLE75=2017010134=84452=2017010112111826461730560=201701011211182646173055799=10000100268=1279=0269=048=17359555=6SZ683=354295270=10204.0271=30346=11023=710=182
1128=99=18135=X49=SAMPLE75=2017010134=372052=2017010107565156045427260=201701010756515604542725799=10000100268=1279=0269=048=17359555=6SZ683=354296270=10203.0271=30346=11023=810=185
1128=99=18135=X49=SAMPLE75=2017010134=336752=2017010102484600717035960=201701010248460071703595799=10000100268=1279=1269=148=17359555=6SZ683=354297270=10220.0271=62346=51023=810=180
1128=99=18135=X49=SAMPLE75=2017010134=155352=2017010106334828679755660=201701010633482867975565799=10000100268=1279=0269=148=17359555=6SZ683=354298270=10217.0271=30346=11023=610=193
1128=99=18135=X49=SAMPLE75=2017010134=451552=2017010105401449452768360=201701010540144945276835799=10000100268=1279=1269=148=17359555=6SZ683=354299270=10216.0271=39346=41023=510=206
1128=99=18235=X49=SAMPLE75=2017010134=187652=2017010114135017357943760=201701011413501735794375799=10000100268=1279=1269=148=17359555=6SZ683=354300270=10214.0271=33346=131023=310=225
1128=99=13135=f49=SAMPLE34=200352=2017010113293821921284460=2017010113293821921284475=201701015799=000000001151=6S326=15327=01174=010=027
1128=99=22035=X49=SAMPLE75=2017010134=493452=2017010112115758289438560=201701011211575828943855799=00000001268=1279=0269=248=17359555=6SZ683=354301270=10212.0271=4346=25797=037705=237=032=437=621180788979332=410=153
1128=99=15535=X49=SAMPLE75=2017010134=98752=2017010101232711044372560=201701010123271104437255799=00000010268=1279=0269=e48=17359555=6SZ683=354302271=410=241
1128=99=32535=X49=SAMPLE75=2017010134=320552=2017010101065769247964460=201701010106576924796445799=00000100268=3279=2269=048=17359555=6SZ683=354303270=10212.0271=4346=11023=1279=0269=048=17359555=6SZ683=354304270=10200.0271=31346=21023=10279=1269=148=17359555=6SZ683=354305270=10212.0271=17346=11023=110=249
1128=99=28735=X49=SAMPLE75=2017010134=349452=2017010103372086868656960=201701010337208686865695799=00001000268=3279=0269=748=17359555=6SZ683=354306270=10212.0286=255279=0269=848=17359555=6SZ683=354307270=10212.0286=255279=0269=448=17359555=6SZ683=354308270=10212.0286=010=161
1128=99=13135=f49=SAMPLE34=284752=2017010100554319000637260=2017010100554319000637275=201701015799=000000001151=6S326=17327=01174=010=033
1128=99=18235=X49=SAMPLE75=2017010134=120952=2017010107580142358591260=201701010758014235859125799=00000100268=1279=1269=148=17359555=6SZ683=354309270=10214.0271=32346=121023=310=138
1128=99=22935=X49=SAMPLE75=2017010134=354452=2017010101465058363135260=201701010146505836313525799=10001000268=2279=0269=N48=17359555=6SZ683=354310270=10211.0286=255279=0269=O48=17359555=6SZ683=354311270=10212.0286=25510=205
1128=99=18235=X49=SAMPLE75=2017010134=30552=2017010103072028483012260=201701010307202848301225799=10000100268=1279=1269=148=17359555=6SZ683=354312270=10214.0271=31346=111023=310=155
1128=99=18235=X49=SAMPLE75=2017010134=259352=2017010101045219674755060=201701010104521967475505799=10000100268=1279=1269=148=17359555=6SZ683=354313270=10214.0271=30346=101023=310=133
1128=99=18135=X49=SAMPLE75=2017010134=272752=2017010108262372914507360=201701010826237291450735799=10000100268=1279=1269=148=17359555=6SZ683=354314270=10214.0271=29346=91023=310=110
1128=99=18135=X49=SAMPLE75=2017010134=69152=2017010105370465798485260=201701010537046579848525799=10000100268=1279=1269=148=17359555=6SZ683=354315270=10214.0271=28346=81023=310=105
1128=99=18135=X49=SAMPLE75=2017010134=292752=2017010104065632725004760=201701010406563272500475799=10000100268=1279=1269=148=17359555=6SZ683=354316270=10214.0271=27346=71023=310=083
1128=99=18135=X49=SAMPLE75=2017010134=337852=2017010103485691672251960=201701010348569167225195799=10000100268=1279=1269=148=17359555=6SZ683=354317270=10214.0271=26346=61023=310=111
1128=99=18135=X49=SAMPLE75=2017010134=171952=2017010101520482301164460=201701010152048230116445799=10000100268=1279=1269=148=17359555=6SZ683=354318270=10214.0271=25346=51023=310=094
1128=99=18135=X49=SAMPLE75=2017010134=156052=2017010101443873120927760=201701010144387312092775799=10000100268=1279=1269=148=17359555=6SZ683=354319270=10215.0271=47346=71023=410=133
1128=99=18135=X49=SAMPLE75=2017010134=273452=2017010100251603178914960=201701010025160317891495799=10000100268=1279=1269=148=17359555=6SZ683=354320270=10215.0271=17346=61023=410=104
1128=99=18035=X49=SAMPLE75=2017010134=105152=2017010102002826672711660=201701010200282667271165799=10000100268=1279=1269=148=17359555=6SZ683=354321270=10218.0271=1346=11023=710=062
1128=99=18135=X49=SAMPLE75=2017010134=442752=2017010107214382295981160=201701010721438229598115799=10000100268=1279=1269=048=17359555=6SZ683=354322270=10206.0271=28346=41023=410=134
1128=99=18135=X49=SAMPLE75=2017010134=64952=2017010103375895125912660=201701010337589512591265799=10000100268=1279=1269=148=17359555=6SZ683=354323270=10220.0271=63346=61023=910=101
1128=99=18035=X49=SAMPLE75=2017010134=237652=2017010106453004528477260=201701010645300452847725799=10000100268=1279=1269=048=17359555=6SZ683=354324270=10206.0271=7346=31023=410=053
1128=99=25335=X49=SAMPLE75=2017010134=32752=2017010101375169441380360=201701010137516944138035799=10000100268=2279=2269=148=17359555=6SZ683=354325270=10213.0271=21346=11023=2279=0269=148=17359555=6SZ683=354326270=10222.0271=8346=11023=1010=188
1128=99=18135=X49=SAMPLE75=2017010134=296252=2017010102070497597369960=201701010207049759736995799=10000100268=1279=1269=048=17359555=6SZ683=354327270=10200.0271=1346=11023=1010=101
1128=99=18035=X49=SAMPLE75=2017010134=473752=2017010103343325854119660=201701010334332585411965799=10000100268=1279=1269=148=17359555=6SZ683=354328270=10216.0271=9346=31023=410=097
1128=99=18135=X49=SAMPLE75=2017010134=22752=2017010108465505232794360=201701010846550523279435799=10000100268=1279=1269=148=17359555=6SZ683=354329270=10216.0271=39346=41023=410=126
1128=99=18035=X49=SAMPLE75=2017010134=129552=2017010101190368736999960=201701010119036873699995799=10000100268=1279=1269=048=17359555=6SZ683=354330270=10208.0271=2346=11023=210=049
1128=99=25335=X49=SAMPLE75=2017010134=95752=2017010113574203878092160=201701011357420387809215799=10000100268=2279=2269=148=17359555=6SZ683=354331270=10212.0271=17346=11023=1279=0269=148=17359555=6SZ683=354332270=10223.0271=6346=21023=1010=199
1128=99=18035=X49=SAMPLE75=2017010134=442352=2017010109022975638181160=201701010902297563818115799=10000100268=1279=1269=148=17359555=6SZ683=354333270=10214.0271=4346=41023=110=064
1128=99=18035=X49=SAMPLE75=2017010134=9652=2017010103210399106858160=201701010321039910685815799=10000100268=1279=1269=048=17359555=6SZ683=354334270=10207.0271=7346=31023=310=083
1128=99=18135=X49=SAMPLE75=2017010134=396252=2017010104291243670045960=201701010429124367004595799=10000100268=1279=1269=148=17359555=6SZ683=354335270=10220.0271=33346=51023=710=111
1128=99=25435=X49=SAMPLE75=2017010134=208252=2017010106422937639157460=201701010642293763915745799=10000100268=2279=2269=048=17359555=6SZ683=354336270=10203.0271=30346=11023=7279=0269=048=17359555=6SZ683=354337270=10199.0271=30346=11023=1010=249
1128=99=25435=X49=SAMPLE75=2017010134=3752=2017010109002782882099460=201701010900278288209945799=10000100268=2279=2269=148=17359555=6SZ683=354338270=10217.0271=30346=11023=4279=0269=148=17359555=6SZ683=354339270=10225.0271=50346=81023=1010=009
1128=99=25435=X49=SAMPLE75=2017010134=476252=2017010100481751333426360=201701010048175133342635799=10000100268=2279=2269=048=17359555=6SZ683=354340270=10204.0271=30346=11023=6279=0269=048=17359555=6SZ683=354341270=10197.0271=12346=41023=1010=001
1128=99=18135=X49=SAMPLE75=2017010134=314352=2017010109580773786721760=201701010958077378672175799=10000100268=1279=1269=148=17359555=6SZ683=354342270=10222.0271=38346=21023=810=131
1128=99=18135=X49=SAMPLE75=2017010134=395752=2017010102462121043913060=201701010246212104391305799=10000100268=1279=0269=148=17359555=6SZ683=354343270=10217.0271=30346=11023=410=117
1128=99=18135=X49=SAMPLE75=2017010134=356552=2017010101142493700936360=201701010114249370093635799=10000100268=1279=0269=048=17359555=6SZ683=354344270=10203.0271=30346=11023=610=113
1128=99=18135=X49=SAMPLE75=2017010134=36152=2017010103563163639212060=201701010356316363921205799=10000100268=1279=0269=048=17359555=6SZ683=354345270=10204.0271=30346=11023=610=109
1128=99=18035=X49=SAMPLE75=2017010134=321552=2017010104422339527537760=201701010442233952753775799=10000100268=1279=1269=148=17359555=6SZ683=354346270=10222.0271=8346=11023=910=077
1128=99=18235=X49=SAMPLE75=2017010134=47952=2017010101344344142508660=201701010134434414250865799=10000100268=1279=1269=048=17359555=6SZ683=354347270=10200.0271=31346=21023=1010=170
1128=99=18035=X49=SAMPLE75=2017010134=391952=2017010105472359761069060=201701010547235976106905799=10000100268=1279=1269=048=17359555=6SZ683=354348270=10207.0271=8346=41023=310=104
1128=99=18235=X49=SAMPLE75=2017010134=454452=2017010103342283932303360=201701010334228393230335799=10000100268=1279=1269=148=17359555=6SZ683=354349270=10223.0271=36346=31023=1010=182
1128=99=18135=X49=SAMPLE75=2017010134=207852=2017010110070796709265560=201701011007079670926555799=10000100268=1279=1269=048=17359555=6SZ683=354350270=10200.0271=1346=11023=1010=107
1128=99=18235=X49=SAMPLE75=2017010134=310752=2017010107585055132937060=201701010758505513293705799=10000100268=1279=1269=048=17359555=6SZ683=354351270=10200.0271=31346=21023=1010=175
1128=99=18135=X49=SAMPLE75=2017010134=26352=2017010109085260079554160=201701010908526007955415799=10000100268=1279=0269=148=17359555=6SZ683=354352270=10212.0271=21346=11023=110=115
1128=99=18135=X49=SAMPLE75=2017010134=433052=2017010100245304591289660=201701010024530459128965799=10000100268=1279=0269=148=17359555=6SZ683=354353270=10213.0271=21346=11023=210=127
1128=99=18135=X49=SAMPLE75=2017010134=120652=2017010108215916692310960=201701010821591669231095799=10000100268=1279=1269=148=17359555=6SZ683=354354270=10214.0271=25346=51023=310=140
1128=99=18135=X49=SAMPLE75=2017010134=298052=2017010110584292503420760=201701011058429250342075799=10000100268=1279=1269=048=17359555=6SZ683=354355270=10200.0271=1346=11023=1010=111
1128=99=25335=X49=SAMPLE75=2017010134=348752=2017010113402279087595060=201701011340227908759505799=10000100268=2279=2269=148=17359555=6SZ683=354356270=10212.0271=21346=11023=1279=0269=148=17359555=6SZ683=354357270=10222.0271=8346=11023=1010=238
1128=99=18135=X49=SAMPLE75=2017010134=109552=2017010102225726764352260=201701010222572676435225799=10000100268=1279=1269=148=17359555=6SZ683=354358270=10215.0271=38346=71023=310=153
1128=99=18035=X49=SAMPLE75=2017010134=11352=2017010108382757925838560=201701010838275792583855799=00000100268=1279=0269=048=17359555=6SZ683=354359270=10212.0271=1346=11023=110=083
1128=99=16935=X49=SAMPLE75=2017010134=363352=2017010113513706500689960=201701011351370650068995799=10001000268=1279=0269=N48=17359555=6SZ683=354360270=10212.0286=25510=161
1128=99=25335=X49=SAMPLE75=2017010134=195352=2017010111270365045447860=201701011127036504544785799=10000100268=2279=2269=148=17359555=6SZ683=354361270=10217.0271=30346=11023=5279=0269=148=17359555=6SZ683=354362270=10223.0271=6346=21023=1010=218
1128=99=25335=X49=SAMPLE75=2017010134=169452=2017010111432425673258060=201701011143242567325805799=10000100268=2279=2269=048=17359555=6SZ683=354363270=10203.0271=30346=11023=8279=0269=048=17359555=6SZ683=354364270=10200.0271=1346=11023=1010=204
1128=99=18135=X49=SAMPLE75=2017010134=415152=2017010114183003481924060=201701011418300348192405799=10000100268=1279=0269=148=17359555=6SZ683=354365270=10217.0271=30346=11023=510=137
1128=99=18135=X49=SAMPLE75=2017010134=228852=2017010100422106228759960=201701010042210622875995799=10000100268=1279=0269=048=17359555=6SZ683=354366270=10203.0271=30346=11023=810=134
1128=99=18035=X49=SAMPLE75=2017010134=155652=2017010111582905774726760=201701011158290577472675799=10000100268=1279=1269=048=17359555=6SZ683=354367270=10207.0271=9346=51023=410=113
1128=99=29935=X49=SAMPLE75=2017010134=422952=2017010109242156770363460=201701010924215677036345799=00000001268=2279=0269=248=17359555=6SZ683=354368270=10212.0271=1346=25797=2279=0269=248=17359555=6SZ683=354369270=10211.0271=1346=25797=237705=437=032=137=032=137=032=137=032=110=212
1128=99=15535=X49=SAMPLE75=2017010134=357552=2017010106345901916475060=201701010634590191647505799=00000010268=1279=0269=e48=17359555=6SZ683=354370271=610=019
1128=99=32435=X49=SAMPLE75=2017010134=52352=2017010101502126280635860=201701010150212628063585799=00000100268=3279=2269=048=17359555=6SZ683=354371270=10212.0271=1346=11023=1279=1269=048=17359555=6SZ683=354372270=10211.0271=3346=11023=1279=0269=048=17359555=6SZ683=354373270=10200.0271=31346=21023=1010=232
1128=99=16935=X49=SAMPLE75=2017010134=74352=2017010111401856431465160=201701011140185643146515799=10001000268=1279=0269=848=17359555=6SZ683=354374270=10211.0286=25510=134
1128=99=20835=X49=SAMPLE75=2017010134=497552=2017010106562994995853860=201701010656299499585385799=00000001268=1279=0269=248=17359555=6SZ683=354375270=10211.0271=3346=25797=237705=237=032=337=032=310=040
1128=99=15535=X49=SAMPLE75=2017010134=243452=2017010108564726979515060=201701010856472697951505799=00000010268=1279=0269=e48=17359555=6SZ683=354376271=910=026
1128=99=25335=X49=SAMPLE75=2017010134=134252=2017010103093857046381260=201701010309385704638125799=10000100268=2279=2269=048=17359555=6SZ683=354377270=10211.0271=3346=11023=1279=0269=048=17359555=6SZ683=354378270=10197.0271=12346=41023=1010=227
1128=99=18035=X49=SAMPLE75=2017010134=386852=2017010108382083499858060=201701010838208349985805799=10000100268=1279=0269=048=17359555=6SZ683=354379270=10209.0271=1346=11023=110=092
1128=99=18135=X49=SAMPLE75=2017010134=289152=2017010101011769451362360=201701010101176945136235799=10000100268=1279=1269=048=17359555=6SZ683=354380270=10209.0271=22346=21023=110=118
1128=99=18035=X49=SAMPLE75=2017010134=315852=2017010112011621970035260=201701011201162197003525799=10000100268=1279=0269=048=17359555=6SZ683=354381270=10210.0271=1346=11023=110=050
1128=99=18135=X49=SAMPLE75=2017010134=153752=2017010113202708465312160=201701011320270846531215799=10000100268=1279=1269=048=17359555=6SZ683=354382270=10208.0271=23346=21023=310=110
1128=99=18135=X49=SAMPLE75=2017010134=327352=2017010107163192594763660=201701010716319259476365799=10000100268=1279=1269=048=17359555=6SZ683=354383270=10209.0271=21346=11023=210=119
1128=99=18335=X49=SAMPLE75=2017010134=446752=2017010103533540368391660=201701010353354036839165799=10000100268=1279=1269=048=17359555=6SZ683=354384270=10201.0271=35346=101023=1010=242
1128=99=18335=X49=SAMPLE75=2017010134=246852=2017010104143062547699060=201701010414306254769905799=10000100268=1279=1269=048=17359555=6SZ683=354385270=10201.0271=65346=111023=1010=221
1128=99=18335=X49=SAMPLE75=2017010134=44852=2017010101283663448513760=201701010128366344851375799=10000100268=1279=1269=048=17359555=6SZ683=354386270=10201.0271=35346=101023=1010=233
1128=99=18335=X49=SAMPLE75=2017010134=114552=2017010104274775301287760=201701010427477530128775799=10000100268=1279=1269=048=17359555=6SZ683=354387270=10201.0271=65346=111023=1010=235
1128=99=18335=X49=SAMPLE75=2017010134=246452=2017010111252625952116260=201701011125262595211625799=10000100268=1279=1269=048=17359555=6SZ683=354388270=10201.0271=35346=101023=1010=217
1128=99=18335=X49=SAMPLE75=2017010134=168852=2017010110324956565434760=201701011032495656543475799=10000100268=1279=1269=048=17359555=6SZ683=354389270=10201.0271=65346=111023=1010=244
1128=99=18335=X49=SAMPLE75=2017010134=77152=2017010110260408696249560=201701011026040869624955799=10000100268=1279=1269=048=17359555=6SZ683=354390270=10201.0271=35346=101023=1010=237
1128=99=18335=X49=SAMPLE75=2017010134=206452=2017010112563323883020660=201701011256332388302065799=10000100268=1279=1269=048=17359555=6SZ683=354391270=10201.0271=65346=111023=1010=240
1128=99=18335=X49=SAMPLE75=2017010134=399052=2017010109350339396435260=201701010935033939643525799=10000100268=1279=1269=048=17359555=6SZ683=354392270=10201.0271=35346=101023=1010=233
1128=99=18335=X49=SAMPLE75=2017010134=279352=2017010108235829356274960=201701010823582935627495799=10000100268=1279=1269=048=17359555=6SZ683=354393270=10201.0271=65346=111023=1010=247
1128=99=17835=X49=SAMPLE75=2017010134=146552=2017010109342219686646960=201701010934221968664695799=00000100268=1279=0269=048=17362455=6SU783=2565270=10363.0271=2346=11023=110=231
1128=99=16735=X49=SAMPLE75=2017010134=219852=2017010111324213123022660=201701011132421312302265799=10001000268=1279=0269=N48=17362455=6SU783=2566270=10363.0286=25510=052
1128=99=17835=X49=SAMPLE75=2017010134=320352=2017010104240010564866360=201701010424001056486635799=00000100268=1279=0269=148=17362455=6SU783=2567270=10414.0271=2346=11023=110=225
1128=99=16735=X49=SAMPLE75=2017010134=450952=2017010110111827399024760=201701011011182739902475799=10001000268=1279=0269=O48=17362455=6SU783=2568270=10414.0286=25510=046
1128=99=18335=X49=SAMPLE75=2017010134=454252=2017010105283575536040360=201701010528357553604035799=10000100268=1279=1269=048=17359555=6SZ683=354394270=10201.0271=35346=101023=1010=230
1128=99=18335=X49=SAMPLE75=2017010134=98752=2017010107182236165085360=201701010718223616508535799=10000100268=1279=1269=048=17359555=6SZ683=354395270=10201.0271=65346=111023=1010=226
1128=99=17835=X49=SAMPLE75=2017010134=160952=2017010108243718128372560=201701010824371812837255799=00000100268=1279=0269=048=17360355=6SM783=7518270=10251.0271=2346=11023=110=219
1128=99=22535=X49=SAMPLE75=2017010134=446452=2017010111495772598137660=201701011149577259813765799=10001000268=2279=0269=N48=17360355=6SM783=7519270=10251.0286=255279=0269=O48=17360355=6SM783=7520270=14000.0286=25510=016
1128=99=17835=X49=SAMPLE75=2017010134=180252=2017010114015157925623260=201701011401515792562325799=00000100268=1279=0269=148=17360355=6SM783=7521270=10408.0271=2346=11023=110=238
1128=99=16735=X49=SAMPLE75=2017010134=153852=2017010110051426038009160=201701011005142603800915799=10001000268=1279=0269=O48=17360355=6SM783=7522270=10408.0286=25510=059
1128=99=18335=X49=SAMPLE75=2017010134=296252=2017010108363852525457060=201701010836385252545705799=10000100268=1279=1269=048=17359555=6SZ683=354396270=10201.0271=35346=101023=1010=221
1128=99=18335=X49=SAMPLE75=2017010134=92352=2017010111455643455237960=201701011145564345523795799=10000100268=1279=1269=048=17359555=6SZ683=354397270=10201.0271=65346=111023=1010=245
1128=99=25235=X49=SAMPLE75=2017010134=81952=2017010104281785616243060=201701010428178561624305799=10000100268=2279=1269=048=17359555=6SZ683=354398270=10206.0271=6346=21023=5279=1269=048=17359555=6SZ683=354399270=10204.0271=31346=21023=710=198
1128=99=18135=X49=SAMPLE75=2017010134=48752=2017010113372041389171860=201701011337204138917185799=10000100268=1279=1269=048=17359555=6SZ683=354400270=10203.0271=31346=21023=810=121
1128=99=17935=X49=SAMPLE75=2017010134=124952=2017010114213977307700760=201701011421397730770075799=00000100268=1279=0269=048=17360055=6SH783=98999270=10262.0271=3346=11023=110=030
1128=99=22735=X49=SAMPLE75=2017010134=41752=2017010104300478611108260=201701010430047861110825799=10001000268=2279=0269=N48=17360055=6SH783=99000270=10262.0286=255279=0269=O48=17360055=6SH783=99001270=10500.0286=25510=102
1128=99=17935=X49=SAMPLE75=2017010134=381652=2017010108130066073746760=201701010813006607374675799=00000100268=1279=0269=148=17360055=6SH783=99002270=10269.0271=3346=11023=110=025
1128=99=16835=X49=SAMPLE75=2017010134=456252=2017010106465027875772460=201701010646502787577245799=10001000268=1279=0269=O48=17360055=6SH783=99003270=10269.0286=25510=101
1128=99=17935=X49=SAMPLE75=2017010134=132952=2017010109220267554481360=201701010922026755448135799=10000100268=1279=0269=048=17360055=6SH783=99004270=10261.0271=3346=11023=210=005
1128=99=17935=X49=SAMPLE75=2017010134=60952=2017010105433459254588660=201701010543345925458865799=10000100268=1279=0269=148=17360055=6SH783=99005270=10270.0271=3346=11023=210=021
1128=99=17935=X49=SAMPLE75=2017010134=459752=2017010108540965355101860=201701010854096535510185799=10000100268=1279=0269=148=17360055=6SH783=99006270=10271.0271=3346=11023=310=016
1128=99=17935=X49=SAMPLE75=2017010134=192052=2017010103295271735823160=201701010329527173582315799=10000100268=1279=0269=048=17360055=6SH783=99007270=10260.0271=3346=11023=310=029
1128=99=17935=X49=SAMPLE75=2017010134=90152=2017010108061851524333560=201701010806185152433355799=10000100268=1279=0269=048=17360055=6SH783=99008270=10259.0271=3346=11023=410=032
1128=99=17935=X49=SAMPLE75=2017010134=42152=2017010110234798031190460=201701011023479803119045799=10000100268=1279=0269=148=17360055=6SH783=99009270=10272.0271=3346=11023=410=034
1128=99=17935=X49=SAMPLE75=2017010134=409352=2017010113312796909731760=201701011331279690973175799=10000100268=1279=0269=048=17360055=6SH783=99010270=10258.0271=3346=11023=510=017
1128=99=17935=X49=SAMPLE75=2017010134=224652=2017010112590051429934260=201701011259005142993425799=10000100268=1279=0269=048=17360055=6SH783=99011270=10257.0271=3346=11023=610=007
1128=99=17935=X49=SAMPLE75=2017010134=272452=2017010106082426382651360=201701010608242638265135799=10000100268=1279=0269=148=17360055=6SH783=99012270=10273.0271=3346=11023=510=009
1128=99=17935=X49=SAMPLE75=2017010134=77752=2017010105014461811123560=201701010501446181112355799=10000100268=1279=0269=148=17360055=6SH783=99013270=10274.0271=3346=11023=610=029
1128=99=17935=X49=SAMPLE75=2017010134=493452=2017010109081962392169460=201701010908196239216945799=10000100268=1279=0269=048=17360055=6SH783=99014270=10256.0271=3346=11023=710=025
1128=99=17935=X49=SAMPLE75=2017010134=364552=2017010103281324110328260=201701010328132411032825799=10000100268=1279=0269=148=17360055=6SH783=99015270=10275.0271=3346=11023=710=039
1128=99=17935=X49=SAMPLE75=2017010134=211952=2017010111424954224779760=201701011142495422477975799=10000100268=1279=0269=148=17360055=6SH783=99016270=10276.0271=3346=11023=810=030
1128=99=17935=X49=SAMPLE75=2017010134=75052=2017010108161089807663060=201701010816108980766305799=10000100268=1279=0269=048=17360055=6SH783=99017270=10255.0271=3346=11023=810=042
1128=99=17935=X49=SAMPLE75=2017010134=299252=2017010106590142578547960=201701010659014257854795799=10000100268=1279=0269=148=17360055=6SH783=99018270=10277.0271=3346=11023=910=022
1128=99=17935=X49=SAMPLE75=2017010134=48352=2017010109253054566626660=201701010925305456662665799=10000100268=1279=0269=048=17360055=6SH783=99019270=10254.0271=3346=11023=910=032
1128=99=18035=X49=SAMPLE75=2017010134=379152=2017010110282999617493560=201701011028299961749355799=10000100268=1279=0269=148=17360055=6SH783=99020270=10278.0271=3346=11023=1010=081
1128=99=18035=X49=SAMPLE75=2017010134=132352=2017010112060663053669560=201701011206066305366955799=10000100268=1279=0269=048=17360055=6SH783=99021270=10253.0271=3346=11023=1010=057
1128=99=17935=X49=SAMPLE75=2017010134=320352=2017010106441571324088860=201701010644157132408885799=00000100268=1279=0269=148=17360355=6SM783=7523270=10352.0271=15346=11023=110=025
1128=99=16735=X49=SAMPLE75=2017010134=31552=2017010106311885804245860=201701010631188580424585799=10001000268=1279=0269=O48=17360355=6SM783=7524270=10352.0286=25510=049
1128=99=17935=X49=SAMPLE75=2017010134=482852=2017010109335481918468460=201701010933548191846845799=10000100268=1279=0269=148=17360355=6SM783=7525270=10356.0271=10346=11023=210=032
1128=99=17935=X49=SAMPLE75=2017010134=41552=2017010102241006053886460=201701010224100605388645799=00000100268=1279=0269=048=17360355=6SM783=7526270=10303.0271=15346=11023=110=009
1128=99=16735=X49=SAMPLE75=2017010134=80552=2017010101375365470473260=201701010137536547047325799=10001000268=1279=0269=N48=17360355=6SM783=7527270=10303.0286=25510=033
1128=99=17935=X49=SAMPLE75=2017010134=411752=2017010102224194953154260=201701010222419495315425799=10000100268=1279=0269=148=17360355=6SM783=7528270=10366.0271=30346=11023=310=030
1128=99=17935=X49=SAMPLE75=2017010134=312652=2017010102174826079769960=201701010217482607976995799=10000100268=1279=0269=048=17360355=6SM783=7529270=10299.0271=10346=11023=210=048
1128=99=17935=X49=SAMPLE75=2017010134=79652=2017010109462964873198860=201701010946296487319885799=10000100268=1279=0269=048=17360355=6SM783=7530270=10289.0271=30346=11023=310=024
1128=99=24735=X49=SAMPLE75=2017010134=124452=2017010105554066347567360=201701010555406634756735799=00000100268=2279=0269=048=17360355=6SM783=7531270=10304.0271=2346=11023=1279=2269=048=17360355=6SM783=7532270=10251.0271=2346=11023=510=122
1128=99=16735=X49=SAMPLE75=2017010134=228552=2017010109525364157812060=201701010952536415781205799=10001000268=1279=0269=N48=17360355=6SM783=7533270=10304.0286=25510=031
1128=99=24735=X49=SAMPLE75=2017010134=389952=2017010106241997058030460=201701010624199705803045799=00000100268=2279=0269=148=17360355=6SM783=7534270=10351.0271=2346=11023=1279=2269=148=17360355=6SM783=7535270=10408.0271=2346=11023=510=150
1128=99=16735=X49=SAMPLE75=2017010134=2952=2017010108223478533074060=201701010822347853307405799=10001000268=1279=0269=O48=17360355=6SM783=7536270=10351.0286=25510=051
1128=99=18335=X49=SAMPLE75=2017010134=167852=2017010105290566691434360=201701010529056669143435799=10000100268=1279=1269=048=17359555=6SZ683=354401270=10201.0271=35346=101023=1010=239
1128=99=24935=X49=SAMPLE75=2017010134=53752=2017010112510734765421960=201701011251073476542195799=10000100268=2279=1269=048=17360355=6SM783=7537270=10304.0271=17346=21023=1279=2269=048=17360355=6SM783=7538270=10303.0271=15346=11023=210=245
1128=99=18335=X49=SAMPLE75=2017010134=243952=2017010105024409455390760=201701010502440945539075799=10000100268=1279=1269=048=17359555=6SZ683=354402270=10201.0271=65346=111023=1010=234
1128=99=18335=X49=SAMPLE75=2017010134=93052=2017010109261599550433960=201701010926159955043395799=10000100268=1279=1269=048=17359555=6SZ683=354403270=10201.0271=35346=101023=1010=224
1128=99=18335=X49=SAMPLE75=2017010134=496552=2017010107562594638611860=201701010756259463861185799=10000100268=1279=1269=048=17359555=6SZ683=354404270=10201.0271=65346=111023=1010=211
1128=99=18335=X49=SAMPLE75=2017010134=143152=2017010107140237188140960=201701010714023718814095799=10000100268=1279=1269=048=17359555=6SZ683=354405270=10201.0271=35346=101023=1010=214
1128=99=18335=X49=SAMPLE75=2017010134=190152=2017010107160640703837160=201701010716064070383715799=10000100268=1279=1269=048=17359555=6SZ683=354406270=10201.0271=65346=111023=1010=237
1128=99=18035=X49=SAMPLE75=2017010134=293852=2017010108184442361972360=201701010818444236197235799=10000100268=1279=1269=048=17359555=6SZ683=354407270=10210.0271=2346=21023=110=056
1128=99=18135=X49=SAMPLE75=2017010134=413452=2017010106464749519595060=201701010646474951959505799=10000100268=1279=1269=148=17359555=6SZ683=354408270=10213.0271=22346=21023=110=112
1128=99=18335=X49=SAMPLE75=2017010134=162752=2017010110361208984422260=201701011036120898442225799=10000100268=1279=1269=048=17359555=6SZ683=354409270=10201.0271=35346=101023=1010=224
1128=99=18335=X49=SAMPLE75=2017010134=121552=2017010102540192910066060=201701010254019291006605799=10000100268=1279=1269=048=17359555=6SZ683=354410270=10201.0271=65346=111023=1010=205
1128=99=18335=X49=SAMPLE75=2017010134=226152=2017010107151435648731460=201701010715143564873145799=10000100268=1279=1269=048=17359555=6SZ683=354411270=10201.0271=35346=101023=1010=229
1128=99=18335=X49=SAMPLE75=2017010134=329152=2017010103184269724575360=201701010318426972457535799=10000100268=1279=1269=048=17359555=6SZ683=354412270=10201.0271=65346=111023=1010=231
1128=99=18335=X49=SAMPLE75=2017010134=361352=2017010105073483386562160=201701010507348338656215799=10000100268=1279=1269=048=17359555=6SZ683=354413270=10201.0271=35346=101023=1010=200
1128=99=18335=X49=SAMPLE75=2017010134=102652=2017010109490892016638160=201701010949089201663815799=10000100268=1279=1269=048=17359555=6SZ683=354414270=10201.0271=65346=111023=1010=223
1128=99=18335=X49=SAMPLE75=2017010134=401752=2017010108212164704753560=201701010821216470475355799=10000100268=1279=1269=048=17359555=6SZ683=354415270=10201.0271=35346=101023=1010=225
1128=99=18335=X49=SAMPLE75=2017010134=273652=2017010107212573210768460=201701010721257321076845799=10000100268=1279=1269=048=17359555=6SZ683=354416270=10201.0271=65346=111023=1010=238
1128=99=22035=X49=SAMPLE75=2017010134=174652=2017010103014564951138560=201701010301456495113855799=00000001268=1279=0269=248=17359555=6SZ683=354417270=10213.0271=1346=25797=137705=237=032=137=621180789248332=110=187
1128=99=15635=X49=SAMPLE75=2017010134=122352=2017010102432526510510160=201701010243252651051015799=00000010268=1279=0269=e48=17359555=6SZ683=354418271=1010=094
1128=99=18135=X49=SAMPLE75=2017010134=153652=2017010106302938204452760=201701010630293820445275799=00000100268=1279=1269=148=17359555=6SZ683=354419270=10213.0271=21346=21023=110=154
1128=99=16935=X49=SAMPLE75=2017010134=249752=2017010109132352006574760=201701010913235200657475799=10001000268=1279=0269=748=17359555=6SZ683=354420270=10213.0286=25510=155
1128=99=17935=X49=SAMPLE75=2017010134=472352=2017010111330748539348660=201701011133074853934865799=00000100268=1279=0269=048=17360055=6SH783=99022270=10264.0271=3346=11023=110=015
1128=99=16835=X49=SAMPLE75=2017010134=1152=2017010105311691568154160=201701010531169156815415799=10001000268=1279=0269=N48=17360055=6SH783=99023270=10264.0286=25510=091
1128=99=17935=X49=SAMPLE75=2017010134=473352=2017010108063722256485960=201701010806372225648595799=10000100268=1279=0269=048=17360055=6SH783=99024270=10263.0271=3346=11023=210=015
1128=99=25035=X49=SAMPLE75=2017010134=370352=2017010108321582960608660=201701010832158296060865799=10000100268=2279=2269=048=17360055=6SH783=99025270=10264.0271=3346=11023=1279=0269=048=17360055=6SH783=99026270=10254.0271=3346=11023=1010=011
1128=99=18135=X49=SAMPLE75=2017010134=182052=2017010100342944322162260=201701010034294432216225799=10000100268=1279=1269=048=17359555=6SZ683=354421270=10207.0271=30346=61023=410=114
1128=99=18335=X49=SAMPLE75=2017010134=346752=2017010106371143250057160=201701010637114325005715799=10000100268=1279=1269=048=17359555=6SZ683=354422270=10201.0271=35346=101023=1010=234
1128=99=18335=X49=SAMPLE75=2017010134=31052=2017010111191458273486360=201701011119145827348635799=10000100268=1279=1269=048=17359555=6SZ683=354423270=10201.0271=65346=111023=1010=217
1128=99=18335=X49=SAMPLE75=2017010134=7752=2017010112085122033261260=201701011208512203326125799=10000100268=1279=1269=048=17359555=6SZ683=354424270=10201.0271=35346=101023=1010=234
1128=99=18335=X49=SAMPLE75=2017010134=250052=2017010111302866016657660=201701011130286601665765799=10000100268=1279=1269=048=17359555=6SZ683=354425270=10201.0271=65346=111023=1010=213
1128=99=20835=X49=SAMPLE75=2017010134=410852=2017010109071413250927560=201701010907141325092755799=00000001268=1279=0269=248=17359555=6SZ683=354426270=10210.0271=1346=25797=237705=237=032=137=032=110=063
1128=99=15635=X49=SAMPLE75=2017010134=68452=2017010113123000683474760=201701011312300068347475799=00000010268=1279=0269=e48=17359555=6SZ683=354427271=1110=064
1128=99=18035=X49=SAMPLE75=2017010134=136552=2017010112234632884760460=201701011223463288476045799=00000100268=1279=1269=048=17359555=6SZ683=354428270=10210.0271=1346=11023=110=067
1128=99=16935=X49=SAMPLE75=2017010134=340952=2017010112161370456563460=201701011216137045656345799=10001000268=1279=0269=848=17359555=6SZ683=354429270=10210.0286=25510=131
1128=99=17935=X49=SAMPLE75=2017010134=46252=2017010112165421203794160=201701011216542120379415799=00000100268=1279=0269=148=17360055=6SH783=99027270=10268.0271=3346=11023=110=013
1128=99=16835=X49=SAMPLE75=2017010134=189652=2017010110244405531457060=201701011024440553145705799=10001000268=1279=0269=O48=17360055=6SH783=99028270=10268.0286=25510=089
1128=99=25235=X49=SAMPLE75=2017010134=363852=2017010101313535383343960=201701010131353538334395799=10000100268=2279=2269=048=17359555=6SZ683=354430270=10210.0271=1346=11023=1279=0269=048=17359555=6SZ683=354431270=10200.0271=1346=11023=1010=165
1128=99=25035=X49=SAMPLE75=2017010134=48452=2017010101443023216771860=201701010144302321677185799=10000100268=2279=2269=048=17360055=6SH783=99029270=10263.0271=3346=11023=1279=0269=048=17360055=6SH783=99030270=10253.0271=3346=11023=1010=039
1128=99=24935=X49=SAMPLE75=2017010134=5452=2017010102105005750969160=201701010210500575096915799=10000100268=2279=1269=148=17360355=6SM783=7539270=10351.0271=17346=21023=1279=2269=148=17360355=6SM783=7540270=10352.0271=15346=11023=210=004
1128=99=18035=X49=SAMPLE75=2017010134=321252=2017010105353076415361460=201701010535307641536145799=10000100268=1279=0269=048=17359555=6SZ683=354432270=10210.0271=1346=11023=110=080
1128=99=18135=X49=SAMPLE75=2017010134=452652=2017010111163775172558060=201701011116377517255805799=10000100268=1279=1269=048=17359555=6SZ683=354433270=10209.0271=22346=21023=210=160
1128=99=25035=X49=SAMPLE75=2017010134=324952=2017010110333001317820260=201701011033300131782025799=10000100268=2279=2269=148=17360055=6SH783=99031270=10268.0271=3346=11023=1279=0269=148=17360055=6SH783=99032270=10278.0271=3346=11023=1010=011
1128=99=18035=X49=SAMPLE75=2017010134=243652=2017010100171610627590160=201701010017161062759015799=10000100268=1279=1269=048=17359555=6SZ683=354434270=10210.0271=2346=21023=110=064
1128=99=18335=X49=SAMPLE75=2017010134=369752=2017010108474550901714260=201701010847455090171425799=10000100268=1279=1269=048=17359555=6SZ683=354435270=10201.0271=35346=101023=1010=210
1128=99=18335=X49=SAMPLE75=2017010134=497752=2017010100423278158636460=201701010042327815863645799=10000100268=1279=1269=048=17359555=6SZ683=354436270=10201.0271=65346=111023=1010=219
1128=99=18335=X49=SAMPLE75=2017010134=90152=2017010111523067685790060=201701011152306768579005799=10000100268=1279=1269=048=17359555=6SZ683=354437270=10201.0271=35346=101023=1010=243
1128=99=18335=X49=SAMPLE75=2017010134=266552=2017010106470149776237560=201701010647014977623755799=10000100268=1279=1269=048=17359555=6SZ683=354438270=10201.0271=65346=111023=1010=220
1128=99=18335=X49=SAMPLE75=2017010134=396652=2017010101272484659047160=201701010127248465904715799=10000100268=1279=1269=048=17359555=6SZ683=354439270=10201.0271=35346=101023=1010=001
1128=99=18335=X49=SAMPLE75=2017010134=382752=2017010106405291355464960=201701010640529135546495799=10000100268=1279=1269=048=17359555=6SZ683=354440270=10201.0271=65346=111023=1010=244
1128=99=18035=X49=SAMPLE75=2017010134=133752=2017010113191432247370560=201701011319143224737055799=10000100268=1279=1269=148=17359555=6SZ683=354441270=10216.0271=9346=31023=410=087
1128=99=18135=X49=SAMPLE75=2017010134=331052=2017010112172474110248860=201701011217247411024885799=10000100268=1279=1269=148=17359555=6SZ683=354442270=10216.0271=39346=41023=410=155
1128=99=18335=X49=SAMPLE75=2017010134=288152=2017010104480677004684360=201701010448067700468435799=10000100268=1279=1269=048=17359555=6SZ683=354443270=10201.0271=35346=101023=1010=231
1128=99=18135=X49=SAMPLE75=2017010134=26352=2017010105173069462825460=201701010517306946282545799=10000100268=1279=1269=048=17359555=6SZ683=354444270=10205.0271=48346=71023=610=173
1128=99=18035=X49=SAMPLE75=2017010134=100252=2017010108373664924202660=201701010837366492420265799=10000100268=1279=1269=048=17359555=6SZ683=354445270=10204.0271=1346=11023=710=092
1128=99=25335=X49=SAMPLE75=2017010134=234952=2017010100583689679500360=201701010058368967950035799=10000100268=2279=2269=148=17359555=6SZ683=354446270=10217.0271=30346=11023=5279=0269=148=17359555=6SZ683=354447270=10223.0271=6346=21023=1010=235
1128=99=18335=X49=SAMPLE75=2017010134=45552=2017010110290658423115560=201701011029065842311555799=10000100268=1279=1269=048=17359555=6SZ683=354448270=10201.0271=65346=111023=1010=249
1128=99=18135=X49=SAMPLE75=2017010134=66152=2017010113164101868152260=201701011316410186815225799=10000100268=1279=1269=048=17359555=6SZ683=354449270=10205.0271=18346=61023=610=154
1128=99=18135=X49=SAMPLE75=2017010134=252152=2017010102162815966680960=201701010216281596668095799=10000100268=1279=1269=148=17359555=6SZ683=354450270=10218.0271=31346=21023=510=150
1128=99=18135=X49=SAMPLE75=2017010134=181952=2017010106261648389186960=201701010626164838918695799=10000100268=1279=1269=048=17359555=6SZ683=354451270=10205.0271=48346=71023=610=159
1128=99=18035=X49=SAMPLE75=2017010134=133752=2017010107510880654607860=201701010751088065460785799=10000100268=1279=1269=148=17359555=6SZ683=354452270=10218.0271=1346=11023=510=071
1128=99=18135=X49=SAMPLE75=2017010134=157352=2017010114064208081265160=201701011406420808126515799=10000100268=1279=0269=148=17359555=6SZ683=354453270=10217.0271=30346=11023=510=128
1128=99=18335=X49=SAMPLE75=2017010134=402652=2017010110263914090818760=201701011026391409081875799=10000100268=1279=1269=048=17359555=6SZ683=354454270=10201.0271=35346=101023=1010=244
1128=99=18335=X49=SAMPLE75=2017010134=1752=2017010112142374240115460=201701011214237424011545799=10000100268=1279=1269=048=17359555=6SZ683=354455270=10201.0271=65346=111023=1010=248
1128=99=18335=X49=SAMPLE75=2017010134=53452=2017010109561849120198660=201701010956184912019865799=10000100268=1279=1269=048=17359555=6SZ683=354456270=10201.0271=35346=101023=1010=234
1128=99=18335=X49=SAMPLE75=2017010134=212752=2017010112312412986891760=201701011231241298689175799=10000100268=1279=1269=048=17359555=6SZ683=354457270=10201.0271=65346=111023=1010=250
1128=99=18335=X49=SAMPLE75=2017010134=49852=2017010108502423807597060=201701010850242380759705799=10000100268=1279=1269=048=17359555=6SZ683=354458270=10201.0271=35346=101023=1010=235
1128=99=18335=X49=SAMPLE75=2017010134=235052=2017010112115398839133860=201701011211539883913385799=10000100268=1279=1269=048=17359555=6SZ683=354459270=10201.0271=65346=111023=1010=238
1128=99=18335=X49=SAMPLE75=2017010134=91152=2017010108135593785278360=201701010813559378527835799=10000100268=1279=1269=048=17359555=6SZ683=354460270=10201.0271=66346=121023=1010=246
1128=99=18335=X49=SAMPLE75=2017010134=409452=2017010109280708015648460=201701010928070801564845799=10000100268=1279=1269=048=17359555=6SZ683=354461270=10201.0271=36346=111023=1010=243
1128=99=18335=X49=SAMPLE75=2017010134=395652=2017010104481506658511060=201701010448150665851105799=10000100268=1279=1269=048=17359555=6SZ683=354462270=10201.0271=66346=121023=1010=222
1128=99=25435=X49=SAMPLE75=2017010134=83852=2017010111050508032681160=201701011105050803268115799=10000100268=2279=2269=148=17359555=6SZ683=354463270=10222.0271=8346=11023=10279=0269=148=17359555=6SZ683=354464270=10223.0271=36346=31023=1010=025
1128=99=18335=X49=SAMPLE75=2017010134=391452=2017010112262308701192460=201701011226230870119245799=10000100268=1279=1269=048=17359555=6SZ683=354465270=10201.0271=58346=111023=1010=232
1128=99=18135=X49=SAMPLE75=2017010134=76352=2017010108024331072154560=201701010802433107215455799=10000100268=1279=1269=148=17359555=6SZ683=354466270=10220.0271=25346=41023=810=143
1128=99=18135=X49=SAMPLE75=2017010134=387552=2017010110203007375186360=201701011020300737518635799=10000100268=1279=1269=148=17359555=6SZ683=354467270=10223.0271=6346=21023=1010=169
1128=99=18235=X49=SAMPLE75=2017010134=393252=2017010108263087349151760=201701010826308734915175799=10000100268=1279=1269=148=17359555=6SZ683=354468270=10223.0271=36346=31023=1010=175
1128=99=18135=X49=SAMPLE75=2017010134=217052=2017010105172806687943060=201701010517280668794305799=10000100268=1279=1269=148=17359555=6SZ683=354469270=10223.0271=6346=21023=1010=147
1128=99=18235=X49=SAMPLE75=2017010134=85252=2017010105041463159781460=201701010504146315978145799=10000100268=1279=1269=148=17359555=6SZ683=354470270=10223.0271=36346=31023=1010=204
1128=99=18135=X49=SAMPLE75=2017010134=334452=2017010102535053651411760=201701010253505365141175799=10000100268=1279=1269=148=17359555=6SZ683=354471270=10223.0271=6346=21023=1010=153
1128=99=18235=X49=SAMPLE75=2017010134=351752=2017010109564026968578460=201701010956402696857845799=10000100268=1279=1269=148=17359555=6SZ683=354472270=10223.0271=36346=31023=1010=214
1128=99=18135=X49=SAMPLE75=2017010134=154452=2017010102571486018028460=201701010257148601802845799=10000100268=1279=1269=148=17359555=6SZ683=354473270=10223.0271=6346=21023=1010=155
1128=99=18335=X49=SAMPLE75=2017010134=488652=2017010101343977969978060=201701010134397796997805799=10000100268=1279=1269=048=17359555=6SZ683=354474270=10201.0271=28346=101023=1010=007
1128=99=18235=X49=SAMPLE75=2017010134=482252=2017010109431984575000660=201701010943198457500065799=10000100268=1279=1269=148=17359555=6SZ683=354475270=10223.0271=36346=31023=1010=218
1128=99=18335=X49=SAMPLE75=2017010134=484852=2017010103501280339782560=201701010350128033978255799=10000100268=1279=1269=048=17359555=6SZ683=354476270=10201.0271=58346=111023=1010=021
1128=99=18135=X49=SAMPLE75=2017010134=161452=2017010100451777688121160=201701010045177768812115799=10000100268=1279=1269=148=17359555=6SZ683=354477270=10223.0271=6346=21023=1010=160
1128=99=18335=X49=SAMPLE75=2017010134=83152=2017010106574086361826560=201701010657408636182655799=10000100268=1279=1269=048=17359555=6SZ683=354478270=10201.0271=28346=101023=1010=246
1128=99=18335=X49=SAMPLE75=2017010134=135452=2017010110183129199373060=201701011018312919937305799=10000100268=1279=1269=048=17359555=6SZ683=354479270=10201.0271=58346=111023=1010=008
1128=99=18035=X49=SAMPLE75=2017010134=71352=2017010109054676366841160=201701010905467636684115799=10000100268=1279=1269=148=17359555=6SZ683=354480270=10216.0271=9346=31023=410=130
1128=99=18235=X49=SAMPLE75=2017010134=334652=2017010104191142512271060=201701010419114251227105799=10000100268=1279=1269=148=17359555=6SZ683=354481270=10223.0271=36346=31023=1010=213
1128=99=18135=X49=SAMPLE75=2017010134=48352=2017010104523663583411060=201701010452366358341105799=10000100268=1279=1269=148=17359555=6SZ683=354482270=10216.0271=39346=41023=410=181
1128=99=18135=X49=SAMPLE75=2017010134=65852=2017010113111801981898960=201701011311180198189895799=10000100268=1279=1269=148=17359555=6SZ683=354483270=10223.0271=6346=21023=1010=170
1128=99=18235=X49=SAMPLE75=2017010134=247252=2017010108351172131906760=201701010835117213190675799=10000100268=1279=1269=148=17359555=6SZ683=354484270=10223.0271=36346=31023=1010=217
1128=99=18335=X49=SAMPLE75=2017010134=175752=2017010100215245190368660=201701010021524519036865799=10000100268=1279=1269=048=17359555=6SZ683=354485270=10201.0271=28346=101023=1010=014
1128=99=18335=X49=SAMPLE75=2017010134=212652=2017010100414237666736560=201701010041423766673655799=10000100268=1279=1269=048=17359555=6SZ683=354486270=10201.0271=58346=111023=1010=212
1128=99=18035=X49=SAMPLE75=2017010134=42652=2017010100391372266024860=201701010039137226602485799=10000100268=1279=1269=048=17359555=6SZ683=354487270=10207.0271=9346=51023=410=079
1128=99=18035=X49=SAMPLE75=2017010134=378752=2017010104592984165997060=201701010459298416599705799=10000100268=1279=1269=148=17359555=6SZ683=354488270=10214.0271=4346=41023=210=073
1128=99=18035=X49=SAMPLE75=2017010134=148552=2017010107074548109489860=201701010707454810948985799=10000100268=1279=1269=048=17359555=6SZ683=354489270=10209.0271=1346=11023=210=058
1128=99=18035=X49=SAMPLE75=2017010134=218552=2017010104012204916855060=201701010401220491685505799=10000100268=1279=1269=048=17359555=6SZ683=354490270=10208.0271=2346=11023=310=056
1128=99=18035=X49=SAMPLE75=2017010134=244052=2017010108361739171028960=201701010836173917102895799=10000100268=1279=1269=148=17359555=6SZ683=354491270=10213.0271=1346=11023=110=042
1128=99=18135=X49=SAMPLE75=2017010134=474852=2017010111141850022236160=201701011114185002223615799=10000100268=1279=1269=148=17359555=6SZ683=354492270=10215.0271=17346=61023=310=122
1128=99=25335=X49=SAMPLE75=2017010134=221252=2017010113255390522386960=201701011325539052238695799=10000100268=2279=2269=148=17359555=6SZ683=354493270=10213.0271=1346=11023=1279=0269=148=17359555=6SZ683=354494270=10225.0271=50346=81023=1010=182
1128=99=25035=X49=SAMPLE75=2017010134=131752=2017010107543721330998560=201701010754372133099855799=10000100268=2279=2269=148=17360055=6SH783=99033270=10269.0271=3346=11023=1279=0269=148=17360055=6SH783=99034270=10279.0271=3346=11023=1010=250
1128=99=18035=X49=SAMPLE75=2017010134=208552=2017010103561456825950060=201701010356145682595005799=10000100268=1279=0269=048=17359555=6SZ683=354495270=10211.0271=1346=11023=110=059
1128=99=18035=X49=SAMPLE75=2017010134=308552=2017010107041613721446660=201701010704161372144665799=10000100268=1279=1269=048=17359555=6SZ683=354496270=10208.0271=3346=21023=410=059
1128=99=25135=X49=SAMPLE75=2017010134=499352=2017010107343381796037860=201701010734338179603785799=10000100268=2279=2269=148=17360055=6SH783=99035270=10270.0271=3346=11023=1279=0269=148=17360055=6SH783=99036270=10280.0271=53346=11023=1010=058
1128=99=17935=X49=SAMPLE75=2017010134=499752=2017010111425801929386860=201701011142580192938685799=10000100268=1279=0269=048=17360055=6SH783=99037270=10264.0271=3346=11023=110=254
1128=99=18035=X49=SAMPLE75=2017010134=491052=2017010106415242949446660=201701010641524294944665799=10000100268=1279=1269=048=17359555=6SZ683=354497270=10210.0271=1346=11023=210=066
1128=99=17935=X49=SAMPLE75=2017010134=59252=2017010109220168697080560=201701010922016869708055799=10000100268=1279=0269=048=17360055=6SH783=99038270=10263.0271=3346=11023=210=243
1128=99=18035=X49=SAMPLE75=2017010134=108252=2017010109001737146397560=201701010900173714639755799=10000100268=1279=1269=048=17359555=6SZ683=354498270=10211.0271=2346=21023=110=047
1128=99=18035=X49=SAMPLE75=2017010134=258552=2017010106032799191836860=201701010603279919183685799=10000100268=1279=1269=148=17359555=6SZ683=354499270=10214.0271=5346=51023=110=083
1128=99=25035=X49=SAMPLE75=2017010134=394352=2017010108260686055328660=201701010826068605532865799=10000100268=2279=2269=048=17360055=6SH783=99039270=10264.0271=3346=11023=1279=0269=048=17360055=6SH783=99040270=10254.0271=3346=11023=1010=245
1128=99=18035=X49=SAMPLE75=2017010134=368152=2017010104043784576402460=201701010404378457640245799=10000100268=1279=1269=148=17359555=6SZ683=354500270=10223.0271=6346=21023=910=082
1128=99=18035=X49=SAMPLE75=2017010134=351352=2017010106104541501960960=201701010610454150196095799=10000100268=1279=1269=148=17359555=6SZ683=354501270=10216.0271=9346=31023=310=056
1128=99=18135=X49=SAMPLE75=2017010134=447652=2017010108125530204033660=201701010812553020403365799=10000100268=1279=1269=148=17359555=6SZ683=354502270=10223.0271=36346=31023=910=127
1128=99=18135=X49=SAMPLE75=2017010134=185952=2017010111244930172670760=201701011124493017267075799=10000100268=1279=1269=148=17359555=6SZ683=354503270=10216.0271=39346=41023=310=124
1128=99=18035=X49=SAMPLE75=2017010134=369852=2017010101481243984445760=201701010148124398444575799=10000100268=1279=1269=148=17359555=6SZ683=354504270=10223.0271=6346=21023=910=071
1128=99=18135=X49=SAMPLE75=2017010134=134952=2017010106385084168886660=201701010638508416888665799=10000100268=1279=1269=148=17359555=6SZ683=354505270=10223.0271=36346=31023=910=137
1128=99=18035=X49=SAMPLE75=2017010134=437852=2017010101512106012565260=201701010151210601256525799=10000100268=1279=1269=148=17359555=6SZ683=354506270=10223.0271=6346=21023=910=063
1128=99=18135=X49=SAMPLE75=2017010134=284852=2017010104273728102958660=201701010427372810295865799=10000100268=1279=1269=148=17359555=6SZ683=354507270=10223.0271=36346=31023=910=146
1128=99=18035=X49=SAMPLE75=2017010134=97852=2017010108035061536642760=201701010803506153664275799=10000100268=1279=1269=148=17359555=6SZ683=354508270=10223.0271=6346=21023=910=079
1128=99=18135=X49=SAMPLE75=2017010134=459252=2017010106072265830344560=201701010607226583034455799=10000100268=1279=1269=148=17359555=6SZ683=354509270=10223.0271=36346=31023=910=117
1128=99=18135=X49=SAMPLE75=2017010134=115052=2017010112050698494231860=201701011205069849423185799=10000100268=1279=1269=148=17359555=6SZ683=354510270=10220.0271=17346=31023=710=136
1128=99=18235=X49=SAMPLE75=2017010134=354752=2017010112120019428851060=201701011212001942885105799=10000100268=1279=1269=148=17359555=6SZ683=354511270=10225.0271=34346=71023=1010=183
1128=99=18035=X49=SAMPLE75=2017010134=457052=2017010110102840723437860=201701011010284072343785799=10000100268=1279=1269=148=17359555=6SZ683=354512270=10220.0271=9346=21023=710=087
1128=99=18235=X49=SAMPLE75=2017010134=461552=2017010102300575286074260=201701010230057528607425799=10000100268=1279=1269=148=17359555=6SZ683=354513270=10225.0271=18346=61023=1010=178
1128=99=18035=X49=SAMPLE75=2017010134=456952=2017010104580175336444360=201701010458017533644435799=10000100268=1279=1269=148=17359555=6SZ683=354514270=10220.0271=1346=11023=710=082
1128=99=18035=X49=SAMPLE75=2017010134=438352=2017010108351872580441860=201701010835187258044185799=10000100268=1279=1269=148=17359555=6SZ683=354515270=10223.0271=6346=21023=910=078
1128=99=18135=X49=SAMPLE75=2017010134=300252=2017010104234146461631260=201701010423414646163125799=10000100268=1279=1269=148=17359555=6SZ683=354516270=10223.0271=36346=31023=910=143
1128=99=18035=X49=SAMPLE75=2017010134=442852=2017010111355620850153560=201701011135562085015355799=10000100268=1279=1269=148=17359555=6SZ683=354517270=10223.0271=6346=21023=910=083
1128=99=18135=X49=SAMPLE75=2017010134=261052=2017010104160974914363260=201701010416097491436325799=10000100268=1279=1269=148=17359555=6SZ683=354518270=10223.0271=36346=31023=910=173
1128=99=18035=X49=SAMPLE75=2017010134=138252=2017010101453623116880060=201701010145362311688005799=10000100268=1279=0269=148=17359555=6SZ683=354519270=10213.0271=1346=11023=110=081
1128=99=18035=X49=SAMPLE75=2017010134=161352=2017010113220541829305760=201701011322054182930575799=10000100268=1279=1269=148=17359555=6SZ683=354520270=10213.0271=2346=21023=110=087
1128=99=17935=X49=SAMPLE75=2017010134=426752=2017010104035702685531860=201701010403570268553185799=10000100268=1279=0269=148=17360055=6SH783=99041270=10270.0271=3346=11023=110=029
1128=99=18135=X49=SAMPLE75=2017010134=50852=2017010108260960475386460=201701010826096047538645799=10000100268=1279=1269=148=17359555=6SZ683=354521270=10223.0271=6346=21023=1010=125
1128=99=18235=X49=SAMPLE75=2017010134=113352=2017010100541693609352160=201701010054169360935215799=10000100268=1279=1269=148=17359555=6SZ683=354522270=10223.0271=36346=31023=1010=192
1128=99=18135=X49=SAMPLE75=2017010134=292552=2017010102304081020448260=201701010230408102044825799=10000100268=1279=1269=148=17359555=6SZ683=354523270=10223.0271=6346=21023=1010=141
1128=99=18235=X49=SAMPLE75=2017010134=486852=2017010111303204022450660=201701011130320402245065799=10000100268=1279=1269=148=17359555=6SZ683=354524270=10223.0271=36346=31023=1010=192
1128=99=18035=X49=SAMPLE75=2017010134=324152=2017010113085346056421760=201701011308534605642175799=10000100268=1279=1269=048=17359555=6SZ683=354525270=10207.0271=8346=41023=510=092
1128=99=18135=X49=SAMPLE75=2017010134=350052=2017010107384403625547360=201701010738440362554735799=10000100268=1279=1269=148=17359555=6SZ683=354526270=10223.0271=6346=21023=1010=148
1128=99=18235=X49=SAMPLE75=2017010134=93952=2017010101445496430056360=201701010144549643005635799=10000100268=1279=1269=148=17359555=6SZ683=354527270=10223.0271=36346=31023=1010=200
1128=99=18135=X49=SAMPLE75=2017010134=66252=2017010113153719332370360=201701011315371933237035799=10000100268=1279=1269=148=17359555=6SZ683=354528270=10223.0271=6346=21023=1010=135
1128=99=18235=X49=SAMPLE75=2017010134=284352=2017010100473596330125660=201701010047359633012565799=10000100268=1279=1269=148=17359555=6SZ683=354529270=10223.0271=36346=31023=1010=183
1128=99=18135=X49=SAMPLE75=2017010134=180452=2017010109243993198507260=201701010924399319850725799=10000100268=1279=1269=148=17359555=6SZ683=354530270=10223.0271=6346=21023=1010=128
1128=99=18235=X49=SAMPLE75=2017010134=212552=2017010102582333531801360=201701010258233353180135799=10000100268=1279=1269=148=17359555=6SZ683=354531270=10223.0271=36346=31023=1010=165
1128=99=18035=X49=SAMPLE75=2017010134=322552=2017010108164597578450660=201701010816459757845065799=10000100268=1279=1269=148=17359555=6SZ683=354532270=10216.0271=9346=31023=410=084
1128=99=18135=X49=SAMPLE75=2017010134=468252=2017010109233238523789560=201701010923323852378955799=10000100268=1279=1269=148=17359555=6SZ683=354533270=10216.0271=39346=41023=410=153
1128=99=18035=X49=SAMPLE75=2017010134=187052=2017010109382873355240560=201701010938287335524055799=10000100268=1279=1269=148=17359555=6SZ683=354534270=10216.0271=9346=31023=410=096
1128=99=18135=X49=SAMPLE75=2017010134=80552=2017010104210759541838460=201701010421075954183845799=10000100268=1279=1269=148=17359555=6SZ683=354535270=10216.0271=39346=41023=410=155
1128=99=18135=X49=SAMPLE75=2017010134=58352=2017010111361217825616360=201701011136121782561635799=10000100268=1279=1269=148=17359555=6SZ683=354536270=10223.0271=6346=21023=1010=143
1128=99=18235=X49=SAMPLE75=2017010134=226052=2017010104344799004650560=201701010434479900465055799=10000100268=1279=1269=148=17359555=6SZ683=354537270=10223.0271=36346=31023=1010=185
1128=99=18035=X49=SAMPLE75=2017010134=302552=2017010101191573201479460=201701010119157320147945799=10000100268=1279=1269=048=17359555=6SZ683=354538270=10207.0271=9346=51023=510=077
1128=99=18135=X49=SAMPLE75=2017010134=439752=2017010108064992549561560=201701010806499254956155799=10000100268=1279=1269=148=17359555=6SZ683=354539270=10223.0271=6346=21023=1010=148
1128=99=18235=X49=SAMPLE75=2017010134=494052=2017010113113010380394460=201701011311301038039445799=10000100268=1279=1269=148=17359555=6SZ683=354540270=10223.0271=36346=31023=1010=196
1128=99=18135=X49=SAMPLE75=2017010134=455352=2017010110233491505665260=201701011023349150566525799=10000100268=1279=1269=148=17359555=6SZ683=354541270=10223.0271=6346=21023=1010=152
1128=99=18235=X49=SAMPLE75=2017010134=105252=2017010101424701945110660=201701010142470194511065799=10000100268=1279=1269=148=17359555=6SZ683=354542270=10223.0271=36346=31023=1010=218
1128=99=18135=X49=SAMPLE75=2017010134=20552=2017010104254362184161360=201701010425436218416135799=10000100268=1279=1269=148=17359555=6SZ683=354543270=10223.0271=6346=21023=1010=156
1128=99=18235=X49=SAMPLE75=2017010134=62852=2017010109361987106660360=201701010936198710666035799=10000100268=1279=1269=148=17359555=6SZ683=354544270=10223.0271=36346=31023=1010=227
1128=99=18135=X49=SAMPLE75=2017010134=318952=2017010113581650296396460=201701011358165029639645799=10000100268=1279=1269=148=17359555=6SZ683=354545270=10223.0271=6346=21023=1010=144
1128=99=18235=X49=SAMPLE75=2017010134=44652=2017010101462901503682760=201701010146290150368275799=10000100268=1279=1269=148=17359555=6SZ683=354546270=10223.0271=36346=31023=1010=185
1128=99=18135=X49=SAMPLE75=2017010134=340852=2017010112525749534622760=201701011252574953462275799=10000100268=1279=1269=148=17359555=6SZ683=354547270=10223.0271=6346=21023=1010=122
1128=99=18235=X49=SAMPLE75=2017010134=469852=2017010108351187707758560=201701010835118770775855799=10000100268=1279=1269=148=17359555=6SZ683=354548270=10223.0271=36346=31023=1010=171
1128=99=18135=X49=SAMPLE75=2017010134=480452=2017010103174150664776560=201701010317415066477655799=10000100268=1279=1269=148=17359555=6SZ683=354549270=10223.0271=6346=21023=1010=118
1128=99=18235=X49=SAMPLE75=2017010134=489352=2017010101071663353925860=201701010107166335392585799=10000100268=1279=1269=148=17359555=6SZ683=354550270=10223.0271=36346=31023=1010=179
1128=99=18135=X49=SAMPLE75=2017010134=450952=2017010111424207185483860=201701011142420718548385799=10000100268=1279=1269=148=17359555=6SZ683=354551270=10223.0271=6346=21023=1010=111
1128=99=18235=X49=SAMPLE75=2017010134=227652=2017010105595618543979360=201701010559561854397935799=10000100268=1279=1269=148=17359555=6SZ683=354552270=10223.0271=36346=31023=1010=207
1128=99=18135=X49=SAMPLE75=2017010134=350352=2017010107550702645917960=201701010755070264591795799=10000100268=1279=1269=148=17359555=6SZ683=354553270=10223.0271=6346=21023=1010=152
1128=99=18235=X49=SAMPLE75=2017010134=37252=2017010105291939165684060=201701010529193916568405799=10000100268=1279=1269=148=17359555=6SZ683=354554270=10223.0271=36346=31023=1010=190
1128=99=18135=X49=SAMPLE75=2017010134=166052=2017010107240292676002160=201701010724029267600215799=10000100268=1279=1269=148=17359555=6SZ683=354555270=10223.0271=6346=21023=1010=112
1128=99=18235=X49=SAMPLE75=2017010134=262052=2017010103481935089239660=201701010348193508923965799=10000100268=1279=1269=148=17359555=6SZ683=354556270=10223.0271=36346=31023=1010=181
1128=99=18135=X49=SAMPLE75=2017010134=199752=2017010107222192035799360=201701010722219203579935799=10000100268=1279=1269=148=17359555=6SZ683=354557270=10223.0271=6346=21023=1010=128
1128=99=18235=X49=SAMPLE75=2017010134=395652=2017010113120429036957460=201701011312042903695745799=10000100268=1279=1269=148=17359555=6SZ683=354558270=10223.0271=36346=31023=1010=182
1128=99=18035=X49=SAMPLE75=2017010134=59052=2017010112164322771404560=201701011216432277140455799=10000100268=1279=1269=048=17359555=6SZ683=354559270=10203.0271=1346=11023=910=087
1128=99=18135=X49=SAMPLE75=2017010134=230652=2017010106540974712081260=201701010654097471208125799=10000100268=1279=1269=048=17359555=6SZ683=354560270=10204.0271=31346=21023=810=114
1128=99=18135=X49=SAMPLE75=2017010134=169952=2017010110201751532747560=201701011020175153274755799=10000100268=1279=1269=148=17359555=6SZ683=354561270=10223.0271=6346=21023=1010=143
1128=99=18235=X49=SAMPLE75=2017010134=168052=2017010114134710036205660=201701011413471003620565799=10000100268=1279=1269=148=17359555=6SZ683=354562270=10223.0271=36346=31023=1010=210
1128=99=18135=X49=SAMPLE75=2017010134=473752=2017010105462569146405160=201701010546256914640515799=10000100268=1279=1269=148=17359555=6SZ683=354563270=10223.0271=6346=21023=1010=141
1128=99=18035=X49=SAMPLE75=2017010134=126152=2017010108375026192737660=201701010837502619273765799=10000100268=1279=1269=048=17359555=6SZ683=354564270=10204.0271=1346=11023=810=097
1128=99=18235=X49=SAMPLE75=2017010134=245252=2017010111462515221168660=201701011146251522116865799=10000100268=1279=1269=148=17359555=6SZ683=354565270=10223.0271=36346=31023=1010=195
1128=99=18135=X49=SAMPLE75=2017010134=29952=2017010101362711454454360=201701010136271145445435799=10000100268=1279=1269=048=17359555=6SZ683=354566270=10204.0271=31346=21023=810=149
1128=99=18135=X49=SAMPLE75=2017010134=250752=2017010107234983530471060=201701010723498353047105799=10000100268=1279=1269=148=17359555=6SZ683=354567270=10223.0271=6346=21023=1010=142
1128=99=18235=X49=SAMPLE75=2017010134=217052=2017010104041955651155860=201701010404195565115585799=10000100268=1279=1269=148=17359555=6SZ683=354568270=10223.0271=36346=31023=1010=201
1128=99=18035=X49=SAMPLE75=2017010134=39452=2017010105543615764201860=201701010554361576420185799=10000100268=1279=1269=048=17359555=6SZ683=354569270=10206.0271=1346=11023=610=099
1128=99=18135=X49=SAMPLE75=2017010134=150952=2017010113563296530405160=201701011356329653040515799=10000100268=1279=1269=148=17359555=6SZ683=354570270=10223.0271=6346=21023=1010=123
1128=99=18235=X49=SAMPLE75=2017010134=87452=2017010100274653371449860=201701010027465337144985799=10000100268=1279=1269=148=17359555=6SZ683=354571270=10223.0271=36346=31023=1010=176
1128=99=18135=X49=SAMPLE75=2017010134=477652=2017010108400181603169360=201701010840018160316935799=10000100268=1279=1269=148=17359555=6SZ683=354572270=10223.0271=6346=21023=1010=100
1128=99=18235=X49=SAMPLE75=2017010134=196952=2017010100030801783950960=201701010003080178395095799=10000100268=1279=1269=148=17359555=6SZ683=354573270=10223.0271=36346=31023=1010=171
1128=99=18035=X49=SAMPLE75=2017010134=165952=2017010112185155292816160=201701011218515529281615799=10000100268=1279=1269=148=17359555=6SZ683=354574270=10213.0271=1346=11023=110=045
1128=99=25335=X49=SAMPLE75=2017010134=292852=2017010102501099356900960=201701010250109935690095799=10000100268=2279=2269=148=17359555=6SZ683=354575270=10213.0271=1346=11023=1279=0269=148=17359555=6SZ683=354576270=10225.0271=18346=61023=1010=220
1128=99=25135=X49=SAMPLE75=2017010134=66052=2017010105481783620519160=201701010548178362051915799=10000100268=2279=2269=148=17360055=6SH783=99042270=10270.0271=3346=11023=1279=0269=148=17360055=6SH783=99043270=10280.0271=53346=11023=1010=057
1128=99=18035=X49=SAMPLE75=2017010134=189152=2017010101142353682358060=201701010114235368235805799=10000100268=1279=1269=148=17359555=6SZ683=354577270=10223.0271=6346=21023=910=079
1128=99=18135=X49=SAMPLE75=2017010134=201152=2017010112430424124797060=201701011243042412479705799=10000100268=1279=1269=148=17359555=6SZ683=354578270=10223.0271=36346=31023=910=148
1128=99=18035=X49=SAMPLE75=2017010134=76652=2017010112281703935050560=201701011228170393505055799=00000100268=1279=0269=048=17359555=6SZ683=354579270=10213.0271=1346=11023=110=080
1128=99=16935=X49=SAMPLE75=2017010134=215252=2017010112030643078254960=201701011203064307825495799=10001000268=1279=0269=N48=17359555=6SZ683=354580270=10213.0286=25510=158
1128=99=17935=X49=SAMPLE75=2017010134=13052=2017010104230646346824260=201701010423064634682425799=00000100268=1279=0269=048=17360055=6SH783=99044270=10265.0271=3346=11023=110=008
1128=99=16835=X49=SAMPLE75=2017010134=439152=2017010108361256713695160=201701010836125671369515799=10001000268=1279=0269=N48=17360055=6SH783=99045270=10265.0286=25510=084
1128=99=17935=X49=SAMPLE75=2017010134=7852=2017010101591690919128160=201701010159169091912815799=10000100268=1279=0269=048=17360055=6SH783=99046270=10264.0271=3346=11023=210=005
1128=99=18035=X49=SAMPLE75=2017010134=340352=2017010100323172502162460=201701010032317250216245799=10000100268=1279=1269=148=17359555=6SZ683=354581270=10223.0271=6346=21023=910=090
1128=99=18135=X49=SAMPLE75=2017010134=197252=2017010113354020794000460=201701011335402079400045799=10000100268=1279=1269=048=17359555=6SZ683=354582270=10205.0271=18346=61023=810=144
1128=99=18135=X49=SAMPLE75=2017010134=89652=2017010110165712460479760=201701011016571246047975799=10000100268=1279=1269=148=17359555=6SZ683=354583270=10223.0271=36346=31023=910=154
1128=99=18035=X49=SAMPLE75=2017010134=114452=2017010107574947394815260=201701010757494739481525799=10000100268=1279=1269=148=17359555=6SZ683=354584270=10223.0271=6346=21023=910=104
1128=99=18135=X49=SAMPLE75=2017010134=476452=2017010100135400568432760=201701010013540056843275799=10000100268=1279=1269=048=17359555=6SZ683=354585270=10205.0271=48346=71023=810=159
1128=99=18035=X49=SAMPLE75=2017010134=457452=2017010106054426879180160=201701010605442687918015799=10000100268=1279=1269=048=17359555=6SZ683=354586270=10204.0271=1346=11023=910=102
1128=99=18135=X49=SAMPLE75=2017010134=480252=2017010111471504090062060=201701011147150409006205799=10000100268=1279=1269=148=17359555=6SZ683=354587270=10223.0271=36346=31023=910=173
1128=99=18135=X49=SAMPLE75=2017010134=68252=2017010110425330928264560=201701011042533092826455799=10000100268=1279=1269=048=17359555=6SZ683=354588270=10205.0271=18346=61023=810=164
1128=99=18235=X49=SAMPLE75=2017010134=203452=2017010107211799705514560=201701010721179970551455799=10000100268=1279=1269=048=17359555=6SZ683=354589270=10203.0271=31346=21023=1010=213
1128=99=18135=X49=SAMPLE75=2017010134=193052=2017010109073253453379160=201701010907325345337915799=10000100268=1279=1269=048=17359555=6SZ683=354590270=10204.0271=31346=21023=910=147
1128=99=18035=X49=SAMPLE75=2017010134=499852=2017010102013077027394860=201701010201307702739485799=10000100268=1279=1269=048=17359555=6SZ683=354591270=10204.0271=1346=11023=910=096
1128=99=18135=X49=SAMPLE75=2017010134=480552=2017010102133002666568260=201701010213300266656825799=10000100268=1279=1269=048=17359555=6SZ683=354592270=10205.0271=48346=71023=810=160
1128=99=18035=X49=SAMPLE75=2017010134=428152=2017010112080150115003760=201701011208015011500375799=10000100268=1279=1269=148=17359555=6SZ683=354593270=10223.0271=6346=21023=910=106
1128=99=18135=X49=SAMPLE75=2017010134=93052=2017010102502555024742360=201701010250255502474235799=10000100268=1279=1269=148=17359555=6SZ683=354594270=10223.0271=36346=31023=910=166
1128=99=18035=X49=SAMPLE75=2017010134=339152=2017010112533612832898660=201701011253361283289865799=10000100268=1279=1269=148=17359555=6SZ683=354595270=10223.0271=6346=21023=910=116
1128=99=18135=X49=SAMPLE75=2017010134=151952=2017010111054026876350860=201701011105402687635085799=10000100268=1279=1269=148=17359555=6SZ683=354596270=10223.0271=36346=31023=910=141
1128=99=20835=X49=SAMPLE75=2017010134=49752=2017010109063916208357360=201701010906391620835735799=00000001268=1279=0269=248=17359555=6SZ683=354597270=10213.0271=1346=25797=237705=237=032=137=032=110=055
1128=99=15635=X49=SAMPLE75=2017010134=242852=2017010101375499175052760=201701010137549917505275799=00000010268=1279=0269=e48=17359555=6SZ683=354598271=1210=066
1128=99=25335=X49=SAMPLE75=2017010134=179352=2017010103321986584861260=201701010332198658486125799=10000100268=2279=2269=048=17359555=6SZ683=354599270=10213.0271=1346=11023=1279=0269=048=17359555=6SZ683=354600270=10202.0271=19346=71023=1010=209
1128=99=17935=X49=SAMPLE75=2017010134=362052=2017010102471031110833360=201701010247103111083335799=10000100268=1279=0269=148=17360055=6SH783=99047270=10269.0271=3346=11023=110=032
1128=99=18035=X49=SAMPLE75=2017010134=299652=2017010103352183512050860=201701010335218351205085799=10000100268=1279=0269=048=17359555=6SZ683=354601270=10212.0271=1346=11023=110=055
1128=99=25135=X49=SAMPLE75=2017010134=230052=2017010102261544300088660=201701010226154430008865799=10000100268=2279=2269=048=17360055=6SH783=99048270=10265.0271=3346=11023=1279=0269=048=17360055=6SH783=99049270=10255.0271=53346=21023=1010=081
1128=99=17935=X49=SAMPLE75=2017010134=73852=2017010105422775410976860=201701010542277541097685799=10000100268=1279=0269=148=17360055=6SH783=99050270=10270.0271=3346=11023=210=001
1128=99=25035=X49=SAMPLE75=2017010134=376152=2017010107371030524752760=201701010737103052475275799=10000100268=2279=2269=048=17360055=6SH783=99051270=10264.0271=3346=11023=1279=0269=048=17360055=6SH783=99052270=10254.0271=3346=11023=1010=011
1128=99=18035=X49=SAMPLE75=2017010134=484952=2017010105550945536792060=201701010555094553679205799=10000100268=1279=1269=048=17359555=6SZ683=354602270=10212.0271=2346=21023=110=070
1128=99=17935=X49=SAMPLE75=2017010134=446752=2017010109330753337100560=201701010933075333710055799=10000100268=1279=0269=048=17360055=6SH783=99053270=10264.0271=3346=11023=110=000
1128=99=25035=X49=SAMPLE75=2017010134=256752=2017010107442695070314660=201701010744269507031465799=10000100268=2279=2269=148=17360055=6SH783=99054270=10269.0271=3346=11023=1279=0269=148=17360055=6SH783=99055270=10279.0271=3346=11023=1010=031
1128=99=25135=X49=SAMPLE75=2017010134=454552=2017010109380208408672260=201701010938020840867225799=10000100268=2279=2269=148=17360055=6SH783=99056270=10270.0271=3346=11023=1279=0269=148=17360055=6SH783=99057270=10280.0271=53346=11023=1010=095
1128=99=18035=X49=SAMPLE75=2017010134=160852=2017010104533823145261960=201701010453382314526195799=10000100268=1279=1269=148=17359555=6SZ683=354603270=10223.0271=6346=21023=910=076
1128=99=18035=X49=SAMPLE75=2017010134=458252=2017010107070674224957460=201701010707067422495745799=10000100268=1279=1269=048=17359555=6SZ683=354604270=10208.0271=4346=31023=510=095
1128=99=18035=X49=SAMPLE75=2017010134=78152=2017010103222727588920960=201701010322272758892095799=10000100268=1279=1269=148=17359555=6SZ683=354605270=10214.0271=6346=61023=110=091
1128=99=17935=X49=SAMPLE75=2017010134=148052=2017010104435346636405560=201701010443534663640555799=10000100268=1279=0269=148=17360055=6SH783=99058270=10270.0271=3346=11023=110=018
1128=99=18135=X49=SAMPLE75=2017010134=46852=2017010110281906991482460=201701011028190699148245799=10000100268=1279=1269=148=17359555=6SZ683=354606270=10223.0271=36346=31023=910=154
1128=99=18035=X49=SAMPLE75=2017010134=145852=2017010103123031659154160=201701010312303165915415799=10000100268=1279=1269=148=17359555=6SZ683=354607270=10223.0271=6346=21023=910=104
1128=99=18135=X49=SAMPLE75=2017010134=5452=2017010101322774697962060=201701010132277469796205799=10000100268=1279=1269=148=17359555=6SZ683=354608270=10223.0271=36346=31023=910=165
1128=99=18035=X49=SAMPLE75=2017010134=202652=2017010110144309702038360=201701011014430970203835799=10000100268=1279=1269=148=17359555=6SZ683=354609270=10223.0271=6346=21023=910=095
1128=99=18135=X49=SAMPLE75=2017010134=467252=2017010109352936102893360=201701010935293610289335799=10000100268=1279=1269=148=17359555=6SZ683=354610270=10223.0271=36346=31023=910=160
1128=99=18035=X49=SAMPLE75=2017010134=449052=2017010114250467755826460=201701011425046775582645799=10000100268=1279=1269=148=17359555=6SZ683=354611270=10223.0271=6346=21023=910=076
1128=99=18135=X49=SAMPLE75=2017010134=165952=2017010111535410628632160=201701011153541062863215799=10000100268=1279=1269=148=17359555=6SZ683=354612270=10223.0271=36346=31023=910=101
1128=99=18035=X49=SAMPLE75=2017010134=307752=2017010100483775331763460=201701010048377533176345799=10000100268=1279=1269=148=17359555=6SZ683=354613270=10223.0271=6346=21023=910=080
1128=99=18135=X49=SAMPLE75=2017010134=105352=2017010114222136971128060=201701011422213697112805799=10000100268=1279=1269=148=17359555=6SZ683=354614270=10223.0271=36346=31023=910=133
1128=99=18035=X49=SAMPLE75=2017010134=121152=2017010108270897508165960=201701010827089750816595799=10000100268=1279=0269=148=17359555=6SZ683=354615270=10213.0271=1346=11023=110=080
1128=99=17935=X49=SAMPLE75=2017010134=30252=2017010114234844113382260=201701011423484411338225799=10000100268=1279=0269=148=17360055=6SH783=99059270=10269.0271=3346=11023=110=037
1128=99=25135=X49=SAMPLE75=2017010134=104752=2017010106520350979142460=201701010652035097914245799=10000100268=2279=1269=148=17359555=6SZ683=354616270=10213.0271=2346=21023=1279=1269=148=17359555=6SZ683=354617270=10214.0271=5346=51023=210=104
1128=99=25035=X49=SAMPLE75=2017010134=45752=2017010106334120493648960=201701010633412049364895799=10000100268=2279=2269=148=17360055=6SH783=99060270=10269.0271=3346=11023=1279=0269=148=17360055=6SH783=99061270=10279.0271=3346=11023=1010=049
1128=99=18035=X49=SAMPLE75=2017010134=438352=2017010103040197024280160=201701010304019702428015799=10000100268=1279=1269=048=17359555=6SZ683=354618270=10212.0271=1346=11023=110=082
1128=99=25335=X49=SAMPLE75=2017010134=348752=2017010104321926484993760=201701010432192648499375799=10000100268=2279=2269=048=17359555=6SZ683=354619270=10212.0271=1346=11023=1279=0269=048=17359555=6SZ683=354620270=10202.0271=19346=71023=1010=224
1128=99=18035=X49=SAMPLE75=2017010134=13252=2017010105461155665410160=201701010546115566541015799=10000100268=1279=1269=148=17359555=6SZ683=354621270=10213.0271=3346=31023=110=078
1128=99=25035=X49=SAMPLE75=2017010134=13052=2017010110104480106193260=201701011010448010619325799=10000100268=2279=2269=048=17360055=6SH783=99062270=10264.0271=3346=11023=1279=0269=048=17360055=6SH783=99063270=10254.0271=3346=11023=1010=024
1128=99=18135=X49=SAMPLE75=2017010134=313752=2017010107570191809725460=201701010757019180972545799=10000100268=1279=1269=148=17359555=6SZ683=354622270=10223.0271=6346=21023=1010=123
1128=99=18135=X49=SAMPLE75=2017010134=340152=2017010102033277567554360=201701010203327756755435799=10000100268=1279=1269=048=17359555=6SZ683=354623270=10204.0271=31346=21023=810=145
1128=99=18035=X49=SAMPLE75=2017010134=412052=2017010109165920737918860=201701010916592073791885799=10000100268=1279=1269=048=17359555=6SZ683=354624270=10203.0271=1346=11023=910=086
1128=99=18235=X49=SAMPLE75=2017010134=6552=2017010109540180261855160=201701010954018026185515799=10000100268=1279=1269=148=17359555=6SZ683=354625270=10223.0271=36346=31023=1010=195
1128=99=18035=X49=SAMPLE75=2017010134=253152=2017010109091251177210360=201701010909125117721035799=10000100268=1279=1269=048=17359555=6SZ683=354626270=10204.0271=1346=11023=810=084
1128=99=18135=X49=SAMPLE75=2017010134=408352=2017010109372541762388460=201701010937254176238845799=10000100268=1279=1269=148=17359555=6SZ683=354627270=10223.0271=6346=21023=1010=142
1128=99=18135=X49=SAMPLE75=2017010134=490452=2017010111070246983397360=201701011107024698339735799=10000100268=1279=1269=048=17359555=6SZ683=354628270=10204.0271=31346=21023=810=162
1128=99=18235=X49=SAMPLE75=2017010134=150752=2017010100500782804974260=201701010050078280497425799=10000100268=1279=1269=148=17359555=6SZ683=354629270=10223.0271=36346=31023=1010=205
1128=99=18135=X49=SAMPLE75=2017010134=86352=2017010100554329551075160=201701010055432955107515799=10000100268=1279=1269=148=17359555=6SZ683=354630270=10223.0271=6346=21023=1010=133
1128=99=18035=X49=SAMPLE75=2017010134=251552=2017010104415519665137460=201701010441551966513745799=10000100268=1279=1269=148=17359555=6SZ683=354631270=10213.0271=2346=21023=110=117
1128=99=18035=X49=SAMPLE75=2017010134=469252=2017010105415271946041660=201701010541527194604165799=10000100268=1279=1269=048=17359555=6SZ683=354632270=10204.0271=1346=11023=810=062
1128=99=18235=X49=SAMPLE75=2017010134=50852=2017010113361375763024160=201701011336137576302415799=10000100268=1279=1269=148=17359555=6SZ683=354633270=10223.0271=36346=31023=1010=168
1128=99=18135=X49=SAMPLE75=2017010134=133752=2017010108031835444417960=201701010803183544441795799=10000100268=1279=1269=048=17359555=6SZ683=354634270=10204.0271=31346=21023=810=138
1128=99=18235=X49=SAMPLE75=2017010134=96252=2017010111584412066935260=201701011158441206693525799=10000100268=1279=1269=048=17359555=6SZ683=354635270=10202.0271=49346=81023=1010=187
1128=99=18135=X49=SAMPLE75=2017010134=319852=2017010108344158225725560=201701010834415822572555799=10000100268=1279=1269=148=17359555=6SZ683=354636270=10223.0271=6346=21023=1010=121
1128=99=18235=X49=SAMPLE75=2017010134=218352=2017010102185946053068260=201701010218594605306825799=10000100268=1279=1269=148=17359555=6SZ683=354637270=10223.0271=36346=31023=1010=221
1128=99=18235=X49=SAMPLE75=2017010134=454952=2017010104001986120680760=201701010400198612068075799=10000100268=1279=1269=048=17359555=6SZ683=354638270=10202.0271=19346=71023=1010=194
1128=99=18135=X49=SAMPLE75=2017010134=241352=2017010102340994985117660=201701010234099498511765799=10000100268=1279=1269=148=17359555=6SZ683=354639270=10223.0271=6346=21023=1010=160
1128=99=18035=X49=SAMPLE75=2017010134=228452=2017010106090261771050860=201701010609026177105085799=10000100268=1279=1269=048=17359555=6SZ683=354640270=10204.0271=1346=11023=810=087
1128=99=18235=X49=SAMPLE75=2017010134=356152=2017010106495514359284460=201701010649551435928445799=10000100268=1279=1269=048=17359555=6SZ683=354641270=10202.0271=49346=81023=1010=200
1128=99=18235=X49=SAMPLE75=2017010134=219852=2017010109073207676608160=201701010907320767660815799=10000100268=1279=1269=148=17359555=6SZ683=354642270=10223.0271=36346=31023=1010=181
1128=99=18135=X49=SAMPLE75=2017010134=94952=2017010102112836738583060=201701010211283673858305799=10000100268=1279=1269=048=17359555=6SZ683=354643270=10204.0271=31346=21023=810=141
1128=99=18135=X49=SAMPLE75=2017010134=361152=2017010108085708020657260=201701010808570802065725799=10000100268=1279=1269=148=17359555=6SZ683=354644270=10223.0271=6346=21023=1010=130
1128=99=18235=X49=SAMPLE75=2017010134=29352=2017010105405013994876660=201701010540501399487665799=10000100268=1279=1269=148=17359555=6SZ683=354645270=10223.0271=36346=31023=1010=198
1128=99=18135=X49=SAMPLE75=2017010134=273252=2017010107363934767017560=201701010736393476701755799=10000100268=1279=1269=148=17359555=6SZ683=354646270=10223.0271=6346=21023=1010=157
1128=99=18235=X49=SAMPLE75=2017010134=339852=2017010109375823095448260=201701010937582309544825799=10000100268=1279=1269=148=17359555=6SZ683=354647270=10223.0271=36346=31023=1010=180
1128=99=18135=X49=SAMPLE75=2017010134=123752=2017010113021243492047260=201701011302124349204725799=10000100268=1279=1269=148=17359555=6SZ683=354648270=10223.0271=6346=21023=1010=158
1128=99=18235=X49=SAMPLE75=2017010134=143552=2017010103472615730275360=201701010347261573027535799=10000100268=1279=1269=148=17359555=6SZ683=354649270=10223.0271=36346=31023=1010=194
1128=99=18135=X49=SAMPLE75=2017010134=336852=2017010101511425501068560=201701010151142550106855799=10000100268=1279=1269=148=17359555=6SZ683=354650270=10223.0271=6346=21023=1010=128
1128=99=18235=X49=SAMPLE75=2017010134=155152=2017010102381964853276660=201701010238196485327665799=10000100268=1279=1269=148=17359555=6SZ683=354651270=10223.0271=36346=31023=1010=208
1128=99=18135=X49=SAMPLE75=2017010134=226652=2017010113312002705521360=201701011331200270552135799=10000100268=1279=1269=148=17359555=6SZ683=354652270=10223.0271=6346=21023=1010=148
1128=99=18235=X49=SAMPLE75=2017010134=175652=2017010100075312518593760=201701010007531251859375799=10000100268=1279=1269=148=17359555=6SZ683=354653270=10223.0271=36346=31023=1010=193
1128=99=18135=X49=SAMPLE75=2017010134=114052=2017010108074620882034960=201701010807462088203495799=10000100268=1279=1269=148=17359555=6SZ683=354654270=10223.0271=6346=21023=1010=157
1128=99=18235=X49=SAMPLE75=2017010134=11152=2017010104493654282442960=201701010449365428244295799=10000100268=1279=1269=048=17359555=6SZ683=354655270=10202.0271=19346=71023=1010=179
1128=99=18235=X49=SAMPLE75=2017010134=493652=2017010105452472094258260=201701010545247209425825799=10000100268=1279=1269=148=17359555=6SZ683=354656270=10223.0271=36346=31023=1010=216
1128=99=18235=X49=SAMPLE75=2017010134=497452=2017010106001852908203260=201701010600185290820325799=10000100268=1279=1269=048=17359555=6SZ683=354657270=10202.0271=49346=81023=1010=215
1128=99=18135=X49=SAMPLE75=2017010134=433252=2017010104562799585296760=201701010456279958529675799=10000100268=1279=1269=148=17359555=6SZ683=354658270=10223.0271=6346=21023=1010=150
1128=99=18235=X49=SAMPLE75=2017010134=303552=2017010107543072294096860=201701010754307229409685799=10000100268=1279=1269=148=17359555=6SZ683=354659270=10223.0271=36346=31023=1010=211
1128=99=18135=X49=SAMPLE75=2017010134=391152=2017010107492720340345560=201701010749272034034555799=10000100268=1279=1269=148=17359555=6SZ683=354660270=10223.0271=6346=21023=1010=131
1128=99=18235=X49=SAMPLE75=2017010134=84152=2017010109075237354124860=201701010907523735412485799=10000100268=1279=1269=148=17359555=6SZ683=354661270=10223.0271=36346=31023=1010=215
1128=99=18135=X49=SAMPLE75=2017010134=327152=2017010109152152375506860=201701010915215237550685799=10000100268=1279=1269=148=17359555=6SZ683=354662270=10223.0271=6346=21023=1010=143
1128=99=18235=X49=SAMPLE75=2017010134=25652=2017010109422617474549360=201701010942261747454935799=10000100268=1279=1269=148=17359555=6SZ683=354663270=10223.0271=36346=31023=1010=205
1128=99=18235=X49=SAMPLE75=2017010134=8552=2017010106212106106182860=201701010621210610618285799=10000100268=1279=1269=048=17359555=6SZ683=354664270=10202.0271=19346=71023=1010=203
1128=99=18135=X49=SAMPLE75=2017010134=20852=2017010104175969606470360=201701010417596960647035799=10000100268=1279=1269=148=17359555=6SZ683=354665270=10223.0271=6346=21023=1010=142
1128=99=18235=X49=SAMPLE75=2017010134=134152=2017010103383181448074060=201701010338318144807405799=10000100268=1279=1269=048=17359555=6SZ683=354666270=10202.0271=49346=81023=1010=192
1128=99=18235=X49=SAMPLE75=2017010134=329652=2017010103091825668076360=201701010309182566807635799=10000100268=1279=1269=148=17359555=6SZ683=354667270=10223.0271=36346=31023=1010=205
1128=99=18235=X49=SAMPLE75=2017010134=262152=2017010110184090026856560=201701011018409002685655799=10000100268=1279=1269=048=17359555=6SZ683=354668270=10202.0271=19346=71023=1010=209
1128=99=18235=X49=SAMPLE75=2017010134=69152=2017010112421421354112360=201701011242142135411235799=10000100268=1279=1269=048=17359555=6SZ683=354669270=10202.0271=49346=81023=1010=238
1128=99=18135=X49=SAMPLE75=2017010134=97952=2017010105241195056117160=201701010524119505611715799=10000100268=1279=1269=148=17359555=6SZ683=354670270=10223.0271=6346=21023=1010=172
1128=99=18235=X49=SAMPLE75=2017010134=64252=2017010114303437026429860=201701011430343702642985799=10000100268=1279=1269=148=17359555=6SZ683=354671270=10223.0271=36346=31023=1010=189
1128=99=18135=X49=SAMPLE75=2017010134=432152=2017010111143760265946960=201701011114376026594695799=10000100268=1279=1269=148=17359555=6SZ683=354672270=10223.0271=6346=21023=1010=161
1128=99=18235=X49=SAMPLE75=2017010134=280152=2017010105252107835977060=201701010525210783597705799=10000100268=1279=1269=148=17359555=6SZ683=354673270=10223.0271=36346=31023=1010=198
1128=99=18235=X49=SAMPLE75=2017010134=491152=2017010111502543945096760=201701011150254394509675799=10000100268=1279=1269=048=17359555=6SZ683=354674270=10202.0271=19346=71023=1010=185
1128=99=18135=X49=SAMPLE75=2017010134=336452=2017010105483452709901460=201701010548345270990145799=10000100268=1279=1269=148=17359555=6SZ683=354675270=10223.0271=6346=21023=1010=143
1128=99=18235=X49=SAMPLE75=2017010134=398752=2017010100111455219646560=201701010011145521964655799=10000100268=1279=1269=048=17359555=6SZ683=354676270=10202.0271=49346=81023=1010=215
1128=99=18235=X49=SAMPLE75=2017010134=305752=2017010101125715003895760=201701010112571500389575799=10000100268=1279=1269=148=17359555=6SZ683=354677270=10223.0271=36346=31023=1010=197
1128=99=18135=X49=SAMPLE75=2017010134=17952=2017010113533266979324660=201701011353326697932465799=10000100268=1279=1269=148=17359555=6SZ683=354678270=10223.0271=6346=21023=1010=178
1128=99=18235=X49=SAMPLE75=2017010134=362052=2017010101392413272854260=201701010139241327285425799=10000100268=1279=1269=048=17359555=6SZ683=354679270=10202.0271=19346=71023=1010=210
1128=99=18235=X49=SAMPLE75=2017010134=171152=2017010102241739283200160=201701010224173928320015799=10000100268=1279=1269=148=17359555=6SZ683=354680270=10223.0271=36346=31023=1010=223
1128=99=18235=X49=SAMPLE75=2017010134=118652=2017010100142699938811160=201701010014269993881115799=10000100268=1279=1269=048=17359555=6SZ683=354681270=10202.0271=49346=81023=1010=229
1128=99=18235=X49=SAMPLE75=2017010134=440952=2017010112164477596958160=201701011216447759695815799=10000100268=1279=1269=048=17359555=6SZ683=354682270=10202.0271=19346=71023=1010=220
1128=99=18135=X49=SAMPLE75=2017010134=297952=2017010107531266770404560=201701010753126677040455799=10000100268=1279=1269=148=17359555=6SZ683=354683270=10223.0271=6346=21023=1010=177
1128=99=18235=X49=SAMPLE75=2017010134=370252=2017010111021509103466860=201701011102150910346685799=10000100268=1279=1269=048=17359555=6SZ683=354684270=10202.0271=49346=81023=1010=224
1128=99=18235=X49=SAMPLE75=2017010134=367052=2017010113154626989074160=201701011315462698907415799=10000100268=1279=1269=148=17359555=6SZ683=354685270=10223.0271=36346=31023=1010=226
1128=99=18135=X49=SAMPLE75=2017010134=351052=2017010111583516371836260=201701011158351637183625799=10000100268=1279=1269=148=17359555=6SZ683=354686270=10223.0271=6346=21023=1010=176
1128=99=18235=X49=SAMPLE75=2017010134=71552=2017010105551638129973360=201701010555163812997335799=10000100268=1279=1269=048=17359555=6SZ683=354687270=10202.0271=19346=71023=1010=206
1128=99=18235=X49=SAMPLE75=2017010134=53052=2017010112015154123769860=201701011201515412376985799=10000100268=1279=1269=148=17359555=6SZ683=354688270=10223.0271=36346=31023=1010=230
1128=99=18235=X49=SAMPLE75=2017010134=159552=2017010104492992815850660=201701010449299281585065799=10000100268=1279=1269=048=17359555=6SZ683=354689270=10202.0271=49346=81023=1010=220
1128=99=18235=X49=SAMPLE75=2017010134=416852=2017010104183765980893660=201701010418376598089365799=10000100268=1279=1269=048=17359555=6SZ683=354690270=10202.0271=19346=71023=1010=181
1128=99=18135=X49=SAMPLE75=2017010134=159052=2017010107323646369548060=201701010732364636954805799=10000100268=1279=1269=148=17359555=6SZ683=354691270=10223.0271=6346=21023=1010=119
1128=99=18235=X49=SAMPLE75=2017010134=42052=2017010104094218966780860=201701010409421896678085799=10000100268=1279=1269=048=17359555=6SZ683=354692270=10202.0271=49346=81023=1010=181
1128=99=18235=X49=SAMPLE75=2017010134=467352=2017010106570914293749260=201701010657091429374925799=10000100268=1279=1269=148=17359555=6SZ683=354693270=10223.0271=36346=31023=1010=171
1128=99=18235=X49=SAMPLE75=2017010134=56952=2017010103191109533047860=201701010319110953304785799=10000100268=1279=1269=048=17359555=6SZ683=354694270=10202.0271=19346=71023=1010=176
1128=99=18135=X49=SAMPLE75=2017010134=230352=2017010111313638586755160=201701011131363858675515799=10000100268=1279=1269=148=17359555=6SZ683=354695270=10223.0271=6346=21023=1010=124
1128=99=18235=X49=SAMPLE75=2017010134=446152=2017010110545163622198860=201701011054516362219885799=10000100268=1279=1269=048=17359555=6SZ683=354696270=10202.0271=49346=81023=1010=190
1128=99=18235=X49=SAMPLE75=2017010134=111552=2017010102340793737984960=201701010234079373798495799=10000100268=1279=1269=148=17359555=6SZ683=354697270=10223.0271=36346=31023=1010=201
1128=99=18235=X49=SAMPLE75=2017010134=69352=2017010107495764466564660=201701010749576446656465799=10000100268=1279=1269=048=17359555=6SZ683=354698270=10202.0271=19346=71023=1010=173
1128=99=18135=X49=SAMPLE75=2017010134=498852=2017010109051558751006360=201701010905155875100635799=10000100268=1279=1269=148=17359555=6SZ683=354699270=10223.0271=6346=21023=1010=130
1128=99=18235=X49=SAMPLE75=2017010134=491852=2017010102175562038113060=201701010217556203811305799=10000100268=1279=1269=048=17359555=6SZ683=354700270=10202.0271=49346=81023=1010=165
1128=99=18235=X49=SAMPLE75=2017010134=66252=2017010111372158810463360=201701011137215881046335799=10000100268=1279=1269=148=17359555=6SZ683=354701270=10223.0271=36346=31023=1010=155
1128=99=18135=X49=SAMPLE75=2017010134=339552=2017010111352917864264760=201701011135291786426475799=10000100268=1279=1269=148=17359555=6SZ683=354702270=10223.0271=6346=21023=1010=131
1128=99=18235=X49=SAMPLE75=2017010134=91252=2017010112411949486899960=201701011241194948689995799=10000100268=1279=1269=148=17359555=6SZ683=354703270=10223.0271=36346=31023=1010=164
1128=99=18235=X49=SAMPLE75=2017010134=325652=2017010106454979802920160=201701010645497980292015799=10000100268=1279=1269=048=17359555=6SZ683=354704270=10202.0271=19346=71023=1010=188
1128=99=18135=X49=SAMPLE75=2017010134=297952=2017010109242211542258960=201701010924221154225895799=10000100268=1279=1269=148=17359555=6SZ683=354705270=10223.0271=6346=21023=1010=162
1128=99=18235=X49=SAMPLE75=2017010134=338052=2017010112370901274115660=201701011237090127411565799=10000100268=1279=1269=048=17359555=6SZ683=354706270=10202.0271=49346=81023=1010=221
1128=99=18235=X49=SAMPLE75=2017010134=321052=2017010112280124225431760=201701011228012422543175799=10000100268=1279=1269=148=17359555=6SZ683=354707270=10223.0271=36346=31023=1010=212
1128=99=18235=X49=SAMPLE75=2017010134=146852=2017010109004619365612460=201701010900461936561245799=10000100268=1279=1269=048=17359555=6SZ683=354708270=10202.0271=19346=71023=1010=200
1128=99=18135=X49=SAMPLE75=2017010134=217552=2017010112040346411845860=201701011204034641184585799=10000100268=1279=1269=148=17359555=6SZ683=354709270=10223.0271=6346=21023=1010=149
1128=99=18235=X49=SAMPLE75=2017010134=101452=2017010101165880050614760=201701010116588005061475799=10000100268=1279=1269=048=17359555=6SZ683=354710270=10202.0271=49346=81023=1010=219
1128=99=18235=X49=SAMPLE75=2017010134=463352=2017010111591957004850660=201701011159195700485065799=10000100268=1279=1269=148=17359555=6SZ683=354711270=10223.0271=36346=31023=1010=220
1128=99=18135=X49=SAMPLE75=2017010134=122252=2017010110453029070898960=201701011045302907089895799=10000100268=1279=1269=148=17359555=6SZ683=354712270=10223.0271=6346=21023=1010=147
1128=99=18235=X49=SAMPLE75=2017010134=85652=2017010112580474732686160=201701011258047473268615799=10000100268=1279=1269=148=17359555=6SZ683=354713270=10223.0271=36346=31023=1010=182
1128=99=18235=X49=SAMPLE75=2017010134=403952=2017010113554392565894760=201701011355439256589475799=10000100268=1279=1269=048=17359555=6SZ683=354714270=10202.0271=19346=71023=1010=196
1128=99=18135=X49=SAMPLE75=2017010134=395252=2017010103344946948568460=201701010334494694856845799=10000100268=1279=1269=148=17359555=6SZ683=354715270=10223.0271=6346=21023=1010=126
1128=99=18235=X49=SAMPLE75=2017010134=377652=2017010103124053078017360=201701010312405307801735799=10000100268=1279=1269=048=17359555=6SZ683=354716270=10202.0271=49346=81023=1010=171
1128=99=18235=X49=SAMPLE75=2017010134=486452=2017010113245102738243060=201701011324510273824305799=10000100268=1279=1269=148=17359555=6SZ683=354717270=10223.0271=36346=31023=1010=169
1128=99=18135=X49=SAMPLE75=2017010134=450052=2017010107303736762117160=201701010730373676211715799=10000100268=1279=1269=148=17359555=6SZ683=354718270=10223.0271=6346=21023=1010=134
1128=99=18235=X49=SAMPLE75=2017010134=408052=2017010102452090083269860=201701010245209008326985799=10000100268=1279=1269=148=17359555=6SZ683=354719270=10223.0271=36346=31023=1010=199
1128=99=18235=X49=SAMPLE75=2017010134=247852=2017010106250449328113360=201701010625044932811335799=10000100268=1279=1269=048=17359555=6SZ683=354720270=10202.0271=19346=71023=1010=183
1128=99=18135=X49=SAMPLE75=2017010134=2052=2017010105430133973341960=201701010543013397334195799=10000100268=1279=1269=148=17359555=6SZ683=354721270=10223.0271=6346=21023=1010=129
1128=99=18235=X49=SAMPLE75=2017010134=427752=2017010102313076123153660=201701010231307612315365799=10000100268=1279=1269=048=17359555=6SZ683=354722270=10202.0271=49346=81023=1010=191
1128=99=18235=X49=SAMPLE75=2017010134=132252=2017010109071896163806960=201701010907189616380695799=10000100268=1279=1269=148=17359555=6SZ683=354723270=10223.0271=36346=31023=1010=196
1128=99=18235=X49=SAMPLE75=2017010134=297052=2017010100203667196906760=201701010020366719690675799=10000100268=1279=1269=048=17359555=6SZ683=354724270=10202.0271=19346=71023=1010=166
1128=99=18135=X49=SAMPLE75=2017010134=471952=2017010100315606679889960=201701010031560667988995799=10000100268=1279=1269=148=17359555=6SZ683=354725270=10223.0271=6346=21023=1010=125
1128=99=18235=X49=SAMPLE75=2017010134=342252=2017010100081912372186960=201701010008191237218695799=10000100268=1279=1269=048=17359555=6SZ683=354726270=10202.0271=49346=81023=1010=181
1128=99=18235=X49=SAMPLE75=2017010134=410252=2017010114101454652111660=201701011410145465211165799=10000100268=1279=1269=148=17359555=6SZ683=354727270=10223.0271=36346=31023=1010=183
1128=99=18135=X49=SAMPLE75=2017010134=282252=2017010104335637197326760=201701010433563719732675799=10000100268=1279=1269=148=17359555=6SZ683=354728270=10223.0271=6346=21023=1010=151
1128=99=18235=X49=SAMPLE75=2017010134=98252=2017010110515273703958660=201701011051527370395865799=10000100268=1279=1269=048=17359555=6SZ683=354729270=10202.0271=19346=71023=1010=188
1128=99=18235=X49=SAMPLE75=2017010134=115552=2017010112475533118497660=201701011247553311849765799=10000100268=1279=1269=148=17359555=6SZ683=354730270=10223.0271=36346=31023=1010=193
1128=99=18235=X49=SAMPLE75=2017010134=240152=2017010110224707778796460=201701011022470777879645799=10000100268=1279=1269=048=17359555=6SZ683=354731270=10202.0271=49346=81023=1010=221
1128=99=18135=X49=SAMPLE75=2017010134=140652=2017010103451812591632960=201701010345181259163295799=10000100268=1279=1269=148=17359555=6SZ683=354732270=10223.0271=6346=21023=1010=138
1128=99=18235=X49=SAMPLE75=2017010134=321052=2017010100512687207238060=201701010051268720723805799=10000100268=1279=1269=048=17359555=6SZ683=354733270=10202.0271=19346=71023=1010=171
1128=99=18235=X49=SAMPLE75=2017010134=330152=2017010102314991594982060=201701010231499159498205799=10000100268=1279=1269=148=17359555=6SZ683=354734270=10223.0271=36346=31023=1010=203
1128=99=18235=X49=SAMPLE75=2017010134=297052=2017010100470146186167660=201701010047014618616765799=10000100268=1279=1269=048=17359555=6SZ683=354735270=10202.0271=49346=81023=1010=205
1128=99=18135=X49=SAMPLE75=2017010134=119652=2017010110353888766183360=201701011035388876618335799=10000100268=1279=1269=148=17359555=6SZ683=354736270=10223.0271=6346=21023=1010=147
1128=99=18235=X49=SAMPLE75=2017010134=311852=2017010114191275584554860=201701011419127558455485799=10000100268=1279=1269=048=17359555=6SZ683=354737270=10202.0271=19346=71023=1010=159
1128=99=18235=X49=SAMPLE75=2017010134=367252=2017010114295526018977260=201701011429552601897725799=10000100268=1279=1269=148=17359555=6SZ683=354738270=10223.0271=36346=31023=1010=205
1128=99=18235=X49=SAMPLE75=2017010134=134252=2017010113244664745393760=201701011324466474539375799=10000100268=1279=1269=048=17359555=6SZ683=354739270=10202.0271=49346=81023=1010=223
1128=99=18135=X49=SAMPLE75=2017010134=221852=2017010108351427470568560=201701010835142747056855799=10000100268=1279=1269=148=17359555=6SZ683=354740270=10223.0271=6346=21023=1010=143
1128=99=18035=X49=SAMPLE75=2017010134=460452=2017010104350717752998860=201701010435071775299885799=10000100268=1279=1269=048=17359555=6SZ683=354741270=10204.0271=1346=11023=810=081
1128=99=18235=X49=SAMPLE75=2017010134=469252=2017010114084989178150460=201701011408498917815045799=10000100268=1279=1269=148=17359555=6SZ683=354742270=10223.0271=36346=31023=1010=198
1128=99=18135=X49=SAMPLE75=2017010134=99352=2017010111014961350236360=201701011101496135023635799=10000100268=1279=1269=048=17359555=6SZ683=354743270=10204.0271=31346=21023=810=139
1128=99=18135=X49=SAMPLE75=2017010134=430952=2017010114132560331877160=201701011413256033187715799=10000100268=1279=1269=148=17359555=6SZ683=354744270=10223.0271=6346=21023=1010=139
1128=99=18235=X49=SAMPLE75=2017010134=308752=2017010104230008650529560=201701010423000865052955799=10000100268=1279=1269=148=17359555=6SZ683=354745270=10223.0271=36346=31023=1010=221
1128=99=18135=X49=SAMPLE75=2017010134=281152=2017010110191156019695360=201701011019115601969535799=10000100268=1279=1269=148=17359555=6SZ683=354746270=10223.0271=6346=21023=1010=154
1128=99=18235=X49=SAMPLE75=2017010134=237852=2017010111022498561282260=201701011102249856128225799=10000100268=1279=1269=048=17359555=6SZ683=354747270=10202.0271=19346=71023=1010=208
1128=99=18235=X49=SAMPLE75=2017010134=37552=2017010111414955518614560=201701011141495551861455799=10000100268=1279=1269=148=17359555=6SZ683=354748270=10223.0271=36346=31023=1010=216
1128=99=18235=X49=SAMPLE75=2017010134=464352=2017010102302944028635760=201701010230294402863575799=10000100268=1279=1269=048=17359555=6SZ683=354749270=10202.0271=49346=81023=1010=200
1128=99=18135=X49=SAMPLE75=2017010134=115952=2017010112243052881663060=201701011224305288166305799=10000100268=1279=1269=148=17359555=6SZ683=354750270=10223.0271=6346=21023=1010=126
1128=99=18235=X49=SAMPLE75=2017010134=426152=2017010112504882807837860=201701011250488280783785799=10000100268=1279=1269=148=17359555=6SZ683=354751270=10223.0271=36346=31023=1010=196
1128=99=18135=X49=SAMPLE75=2017010134=5152=2017010101220082612654060=201701010122008261265405799=10000100268=1279=1269=148=17359555=6SZ683=354752270=10223.0271=6346=21023=1010=153
1128=99=18235=X49=SAMPLE75=2017010134=249552=2017010108423757664945260=201701010842375766494525799=10000100268=1279=1269=148=17359555=6SZ683=354753270=10223.0271=36346=31023=1010=194
1128=99=18135=X49=SAMPLE75=2017010134=366552=2017010111211577911716560=201701011121157791171655799=10000100268=1279=1269=148=17359555=6SZ683=354754270=10223.0271=6346=21023=1010=156
1128=99=18235=X49=SAMPLE75=2017010134=306552=2017010104351604782019560=201701010435160478201955799=10000100268=1279=1269=048=17359555=6SZ683=354755270=10202.0271=19346=71023=1010=199
1128=99=18235=X49=SAMPLE75=2017010134=488752=2017010107054017537030960=201701010705401753703095799=10000100268=1279=1269=148=17359555=6SZ683=354756270=10223.0271=36346=31023=1010=197
1128=99=18235=X49=SAMPLE75=2017010134=230252=2017010106354896857858660=201701010635489685785865799=10000100268=1279=1269=048=17359555=6SZ683=354757270=10202.0271=49346=81023=1010=199
1128=99=18135=X49=SAMPLE75=2017010134=191952=2017010109444507543054060=201701010944450754305405799=10000100268=1279=1269=148=17359555=6SZ683=354758270=10223.0271=6346=21023=1010=147
1128=99=18235=X49=SAMPLE75=2017010134=242752=2017010106252117118135560=201701010625211711813555799=10000100268=1279=1269=048=17359555=6SZ683=354759270=10202.0271=19346=71023=1010=179
1128=99=18235=X49=SAMPLE75=2017010134=329452=2017010108092113968304260=201701010809211396830425799=10000100268=1279=1269=148=17359555=6SZ683=354760270=10223.0271=36346=31023=1010=204
1128=99=18235=X49=SAMPLE75=2017010134=231652=2017010108585486601557660=201701010858548660155765799=10000100268=1279=1269=048=17359555=6SZ683=354761270=10202.0271=49346=81023=1010=195
1128=99=18135=X49=SAMPLE75=2017010134=311252=2017010110103596573904860=201701011010359657390485799=10000100268=1279=1269=048=17359555=6SZ683=354762270=10207.0271=12346=61023=510=145
1128=99=18135=X49=SAMPLE75=2017010134=287652=2017010107405419974399360=201701010740541997439935799=10000100268=1279=1269=148=17359555=6SZ683=354763270=10219.0271=19346=71023=710=160
1128=99=18135=X49=SAMPLE75=2017010134=392052=2017010110430701191050160=201701011043070119105015799=10000100268=1279=1269=148=17359555=6SZ683=354764270=10223.0271=6346=21023=1010=146
1128=99=18235=X49=SAMPLE75=2017010134=11652=2017010101120306826740260=201701010112030682674025799=10000100268=1279=1269=048=17359555=6SZ683=354765270=10202.0271=19346=71023=1010=223
1128=99=18235=X49=SAMPLE75=2017010134=131652=2017010106321234985900260=201701010632123498590025799=10000100268=1279=1269=148=17359555=6SZ683=354766270=10223.0271=36346=31023=1010=201
1128=99=18235=X49=SAMPLE75=2017010134=179352=2017010101500664034737360=201701010150066403473735799=10000100268=1279=1269=048=17359555=6SZ683=354767270=10202.0271=49346=81023=1010=221
1128=99=18235=X49=SAMPLE75=2017010134=319252=2017010111314464333333560=201701011131446433333355799=10000100268=1279=1269=048=17359555=6SZ683=354768270=10202.0271=19346=71023=1010=194
1128=99=18235=X49=SAMPLE75=2017010134=235652=2017010109460846092860760=201701010946084609286075799=10000100268=1279=1269=048=17359555=6SZ683=354769270=10202.0271=49346=81023=1010=173
1128=99=18135=X49=SAMPLE75=2017010134=470752=2017010106020145907931160=201701010602014590793115799=10000100268=1279=1269=148=17359555=6SZ683=354770270=10223.0271=6346=21023=1010=143
1128=99=18235=X49=SAMPLE75=2017010134=42652=2017010111214736523300960=201701011121473652330095799=10000100268=1279=1269=148=17359555=6SZ683=354771270=10223.0271=36346=31023=1010=192
1128=99=18135=X49=SAMPLE75=2017010134=136552=2017010104475689070695160=201701010447568907069515799=10000100268=1279=1269=148=17359555=6SZ683=354772270=10223.0271=6346=21023=1010=132
1128=99=18235=X49=SAMPLE75=2017010134=155252=2017010112353141489079260=201701011235314148907925799=10000100268=1279=1269=148=17359555=6SZ683=354773270=10223.0271=36346=31023=1010=182
1128=99=18135=X49=SAMPLE75=2017010134=344852=2017010100065771871804960=201701010006577187180495799=10000100268=1279=1269=148=17359555=6SZ683=354774270=10223.0271=6346=21023=1010=148
1128=99=18235=X49=SAMPLE75=2017010134=285352=2017010103061446950439760=201701010306144695043975799=10000100268=1279=1269=048=17359555=6SZ683=354775270=10202.0271=19346=71023=1010=200
1128=99=18235=X49=SAMPLE75=2017010134=84552=2017010114203101889121260=201701011420310188912125799=10000100268=1279=1269=148=17359555=6SZ683=354776270=10223.0271=36346=31023=1010=199
1128=99=18235=X49=SAMPLE75=2017010134=100452=2017010104261924424894660=201701010426192442489465799=10000100268=1279=1269=048=17359555=6SZ683=354777270=10202.0271=49346=81023=1010=210
1128=99=18135=X49=SAMPLE75=2017010134=90352=2017010101044324548256160=201701010104432454825615799=10000100268=1279=1269=148=17359555=6SZ683=354778270=10219.0271=27346=81023=710=157
1128=99=18135=X49=SAMPLE75=2017010134=42052=2017010105585147800681560=201701010558514780068155799=10000100268=1279=1269=148=17359555=6SZ683=354779270=10221.0271=18346=51023=910=167
1128=99=18135=X49=SAMPLE75=2017010134=304352=2017010104261048178186760=201701010426104817818675799=10000100268=1279=1269=148=17359555=6SZ683=354780270=10223.0271=6346=21023=1010=165
1128=99=18235=X49=SAMPLE75=2017010134=464852=2017010105203344550433760=201701010520334455043375799=10000100268=1279=1269=148=17359555=6SZ683=354781270=10223.0271=36346=31023=1010=224
1128=99=18135=X49=SAMPLE75=2017010134=215252=2017010105101627511383960=201701010510162751138395799=10000100268=1279=1269=148=17359555=6SZ683=354782270=10223.0271=6346=21023=1010=141
1128=99=18235=X49=SAMPLE75=2017010134=294952=2017010108231882480045560=201701010823188248004555799=10000100268=1279=1269=148=17359555=6SZ683=354783270=10223.0271=36346=31023=1010=201
1128=99=18135=X49=SAMPLE75=2017010134=63052=2017010108042287320194460=201701010804228732019445799=10000100268=1279=1269=148=17359555=6SZ683=354784270=10223.0271=6346=21023=1010=148
1128=99=18235=X49=SAMPLE75=2017010134=390352=2017010112264940842757960=201701011226494084275795799=10000100268=1279=1269=048=17359555=6SZ683=354785270=10202.0271=19346=71023=1010=214
1128=99=18235=X49=SAMPLE75=2017010134=360252=2017010105514341073902460=201701010551434107390245799=10000100268=1279=1269=148=17359555=6SZ683=354786270=10223.0271=36346=31023=1010=199
1128=99=18235=X49=SAMPLE75=2017010134=102752=2017010105310973372668260=201701010531097337266825799=10000100268=1279=1269=048=17359555=6SZ683=354787270=10202.0271=49346=81023=1010=208
1128=99=18135=X49=SAMPLE75=2017010134=335652=2017010104540553124376260=201701010454055312437625799=10000100268=1279=1269=148=17359555=6SZ683=354788270=10223.0271=6346=21023=1010=164
1128=99=18235=X49=SAMPLE75=2017010134=284752=2017010107475261251468960=201701010747526125146895799=10000100268=1279=1269=048=17359555=6SZ683=354789270=10202.0271=19346=71023=1010=225
1128=99=18235=X49=SAMPLE75=2017010134=97052=2017010103441983330470260=201701010344198333047025799=10000100268=1279=1269=148=17359555=6SZ683=354790270=10223.0271=36346=31023=1010=213
1128=99=18235=X49=SAMPLE75=2017010134=375252=2017010112234512929321860=201701011223451292932185799=10000100268=1279=1269=048=17359555=6SZ683=354791270=10202.0271=49346=81023=1010=196
1128=99=18135=X49=SAMPLE75=2017010134=118452=2017010109234134368932560=201701010923413436893255799=10000100268=1279=1269=148=17359555=6SZ683=354792270=10223.0271=6346=21023=1010=152
1128=99=18235=X49=SAMPLE75=2017010134=183352=2017010104455495369082060=201701010445549536908205799=10000100268=1279=1269=048=17359555=6SZ683=354793270=10202.0271=19346=71023=1010=188
1128=99=18235=X49=SAMPLE75=2017010134=442652=2017010112010373606007460=201701011201037360600745799=10000100268=1279=1269=148=17359555=6SZ683=354794270=10223.0271=36346=31023=1010=216
1128=99=18235=X49=SAMPLE75=2017010134=102952=2017010113410910933926060=201701011341091093392605799=10000100268=1279=1269=048=17359555=6SZ683=354795270=10202.0271=49346=81023=1010=211
1128=99=18135=X49=SAMPLE75=2017010134=316452=2017010107383190056651560=201701010738319005665155799=10000100268=1279=1269=148=17359555=6SZ683=354796270=10223.0271=6346=21023=1010=157
1128=99=18235=X49=SAMPLE75=2017010134=87752=2017010110133928140625960=201701011013392814062595799=10000100268=1279=1269=048=17359555=6SZ683=354797270=10202.0271=19346=71023=1010=214
1128=99=18235=X49=SAMPLE75=2017010134=15452=2017010100572110767060760=201701010057211076706075799=10000100268=1279=1269=148=17359555=6SZ683=354798270=10223.0271=36346=31023=1010=202
1128=99=18235=X49=SAMPLE75=2017010134=422252=2017010106591475332825960=201701010659147533282595799=10000100268=1279=1269=048=17359555=6SZ683=354799270=10202.0271=49346=81023=1010=202
1128=99=18135=X49=SAMPLE75=2017010134=491752=2017010108230974063924360=201701010823097406392435799=10000100268=1279=1269=148=17359555=6SZ683=354800270=10223.0271=6346=21023=1010=158
1128=99=18235=X49=SAMPLE75=2017010134=376052=2017010102062519997339460=201701010206251999733945799=10000100268=1279=1269=048=17359555=6SZ683=354801270=10202.0271=19346=71023=1010=194
1128=99=18235=X49=SAMPLE75=2017010134=21352=2017010102420094543172160=201701010242009454317215799=10000100268=1279=1269=148=17359555=6SZ683=354802270=10223.0271=36346=31023=1010=231
1128=99=18235=X49=SAMPLE75=2017010134=276552=2017010108011460608989060=201701010801146060898905799=10000100268=1279=1269=048=17359555=6SZ683=354803270=10202.0271=49346=81023=1010=248
1128=99=18235=X49=SAMPLE75=2017010134=5152=2017010111183293036702860=201701011118329303670285799=10000100268=1279=1269=048=17359555=6SZ683=354804270=10202.0271=19346=71023=1010=212
1128=99=18235=X49=SAMPLE75=2017010134=431152=2017010103540997814959360=201701010354099781495935799=10000100268=1279=1269=048=17359555=6SZ683=354805270=10202.0271=49346=81023=1010=232
1128=99=18235=X49=SAMPLE75=2017010134=372652=2017010104312448781292260=201701010431244878129225799=10000100268=1279=1269=048=17359555=6SZ683=354806270=10202.0271=19346=71023=1010=210
1128=99=18135=X49=SAMPLE75=2017010134=415152=2017010107173192722868460=201701010717319272286845799=10000100268=1279=1269=148=17359555=6SZ683=354807270=10223.0271=6346=21023=1010=134
1128=99=18235=X49=SAMPLE75=2017010134=462852=2017010110024586344974860=201701011002458634497485799=10000100268=1279=1269=048=17359555=6SZ683=354808270=10202.0271=49346=81023=1010=198
1128=99=18235=X49=SAMPLE75=2017010134=490352=2017010106251482449564960=201701010625148244956495799=10000100268=1279=1269=148=17359555=6SZ683=354809270=10223.0271=36346=31023=1010=190
1128=99=17935=X49=SAMPLE75=2017010134=350952=2017010112364772969871260=201701011236477296987125799=10000100268=1279=1269=048=17360055=6SH783=99064270=10260.0271=5346=21023=410=034
1128=99=17935=X49=SAMPLE75=2017010134=181352=2017010101070400848995260=201701010107040084899525799=10000100268=1279=1269=048=17360055=6SH783=99065270=10259.0271=5346=21023=510=058
1128=99=17935=X49=SAMPLE75=2017010134=487252=2017010106481277383146060=201701010648127738314605799=10000100268=1279=1269=148=17360055=6SH783=99066270=10271.0271=5346=21023=210=040
1128=99=17935=X49=SAMPLE75=2017010134=146652=2017010104485826741033860=201701010448582674103385799=10000100268=1279=1269=148=17360055=6SH783=99067270=10272.0271=5346=21023=310=058
1128=99=18235=X49=SAMPLE75=2017010134=317652=2017010104123659900989960=201701010412365990098995799=10000100268=1279=1269=048=17359555=6SZ683=354810270=10202.0271=19346=71023=1010=210
1128=99=18235=X49=SAMPLE75=2017010134=211652=2017010114084061433607660=201701011408406143360765799=10000100268=1279=1269=048=17359555=6SZ683=354811270=10202.0271=49346=81023=1010=234
1128=99=18135=X49=SAMPLE75=2017010134=45152=2017010108420431212535360=201701010842043121253535799=10000100268=1279=1269=148=17359555=6SZ683=354812270=10223.0271=6346=21023=1010=165
1128=99=18235=X49=SAMPLE75=2017010134=349752=2017010109451598842749660=201701010945159884274965799=10000100268=1279=1269=048=17359555=6SZ683=354813270=10202.0271=19346=71023=1010=209
1128=99=18235=X49=SAMPLE75=2017010134=277452=2017010100422558277582860=201701010042255827758285799=10000100268=1279=1269=148=17359555=6SZ683=354814270=10223.0271=36346=31023=1010=217
1128=99=18235=X49=SAMPLE75=2017010134=141452=2017010104202129127257860=201701010420212912725785799=10000100268=1279=1269=048=17359555=6SZ683=354815270=10202.0271=49346=81023=1010=214
1128=99=18135=X49=SAMPLE75=2017010134=65952=2017010101454555519839060=201701010145455551983905799=10000100268=1279=1269=148=17359555=6SZ683=354816270=10223.0271=6346=21023=1010=145
1128=99=18235=X49=SAMPLE75=2017010134=415352=2017010106160207870473960=201701010616020787047395799=10000100268=1279=1269=148=17359555=6SZ683=354817270=10223.0271=36346=31023=1010=195
1128=99=18135=X49=SAMPLE75=2017010134=19452=2017010111253234024616160=201701011125323402461615799=10000100268=1279=1269=148=17359555=6SZ683=354818270=10223.0271=6346=21023=1010=146
1128=99=18235=X49=SAMPLE75=2017010134=276652=2017010107003882807222960=201701010700388280722295799=10000100268=1279=1269=148=17359555=6SZ683=354819270=10223.0271=36346=31023=1010=197
1128=99=18135=X49=SAMPLE75=2017010134=26752=2017010108522069133523860=201701010852206913352385799=10000100268=1279=1269=148=17359555=6SZ683=354820270=10223.0271=6346=21023=1010=150
1128=99=18235=X49=SAMPLE75=2017010134=2152=2017010102232917123353760=201701010223291712335375799=10000100268=1279=1269=148=17359555=6SZ683=354821270=10223.0271=36346=31023=1010=188
1128=99=18135=X49=SAMPLE75=2017010134=347952=2017010109591358617135460=201701010959135861713545799=10000100268=1279=1269=148=17359555=6SZ683=354822270=10223.0271=6346=21023=1010=157
1128=99=18235=X49=SAMPLE75=2017010134=249252=2017010113271852016569060=201701011327185201656905799=10000100268=1279=1269=148=17359555=6SZ683=354823270=10223.0271=36346=31023=1010=206
1128=99=18135=X49=SAMPLE75=2017010134=274252=2017010100200256817350260=201701010020025681735025799=10000100268=1279=1269=148=17359555=6SZ683=354824270=10223.0271=6346=21023=1010=122
1128=99=18235=X49=SAMPLE75=2017010134=154152=2017010114204139102459960=201701011420413910245995799=10000100268=1279=1269=048=17359555=6SZ683=354825270=10202.0271=19346=71023=1010=215
1128=99=18235=X49=SAMPLE75=2017010134=40752=2017010107182604666122360=201701010718260466612235799=10000100268=1279=1269=148=17359555=6SZ683=354826270=10223.0271=36346=31023=1010=189
1128=99=18235=X49=SAMPLE75=2017010134=251152=2017010113174920955166460=201701011317492095516645799=10000100268=1279=1269=048=17359555=6SZ683=354827270=10202.0271=49346=81023=1010=204
1128=99=18135=X49=SAMPLE75=2017010134=112352=2017010104310470120375760=201701010431047012037575799=10000100268=1279=1269=148=17359555=6SZ683=354828270=10223.0271=6346=21023=1010=137
1128=99=18235=X49=SAMPLE75=2017010134=158452=2017010107170234900050960=201701010717023490005095799=10000100268=1279=1269=048=17359555=6SZ683=354829270=10202.0271=19346=71023=1010=221
1128=99=18235=X49=SAMPLE75=2017010134=469952=2017010108394020767277660=201701010839402076727765799=10000100268=1279=1269=148=17359555=6SZ683=354830270=10223.0271=36346=31023=1010=197
1128=99=18235=X49=SAMPLE75=2017010134=102352=2017010111114252230594060=201701011111425223059405799=10000100268=1279=1269=048=17359555=6SZ683=354831270=10202.0271=49346=81023=1010=194
1128=99=18135=X49=SAMPLE75=2017010134=490252=2017010103211352358134660=201701010321135235813465799=10000100268=1279=1269=148=17359555=6SZ683=354832270=10223.0271=6346=21023=1010=142
1128=99=18235=X49=SAMPLE75=2017010134=121552=2017010114051536167768560=201701011405153616776855799=10000100268=1279=1269=048=17359555=6SZ683=354833270=10202.0271=19346=71023=1010=203
1128=99=18235=X49=SAMPLE75=2017010134=170552=2017010112443776011046360=201701011244377601104635799=10000100268=1279=1269=148=17359555=6SZ683=354834270=10223.0271=36346=31023=1010=196
1128=99=18235=X49=SAMPLE75=2017010134=446752=2017010102495236353431960=201701010249523635343195799=10000100268=1279=1269=048=17359555=6SZ683=354835270=10202.0271=49346=81023=1010=222
1128=99=18235=X49=SAMPLE75=2017010134=97252=2017010102424139543557760=201701010242413954355775799=10000100268=1279=1269=048=17359555=6SZ683=354836270=10202.0271=19346=71023=1010=211
1128=99=18135=X49=SAMPLE75=2017010134=346752=2017010106535608029120260=201701010653560802912025799=10000100268=1279=1269=148=17359555=6SZ683=354837270=10223.0271=6346=21023=1010=169
1128=99=18235=X49=SAMPLE75=2017010134=437252=2017010111341825268584460=201701011134182526858445799=10000100268=1279=1269=048=17359555=6SZ683=354838270=10202.0271=49346=81023=1010=221
1128=99=18235=X49=SAMPLE75=2017010134=224252=2017010108392037763511160=201701010839203776351115799=10000100268=1279=1269=148=17359555=6SZ683=354839270=10223.0271=36346=31023=1010=238
1128=99=18135=X49=SAMPLE75=2017010134=163652=2017010114112063523441660=201701011411206352344165799=10000100268=1279=1269=148=17359555=6SZ683=354840270=10223.0271=6346=21023=1010=165
1128=99=18235=X49=SAMPLE75=2017010134=203652=2017010107484391873627460=201701010748439187362745799=10000100268=1279=1269=148=17359555=6SZ683=354841270=10223.0271=36346=31023=1010=238
1128=99=18235=X49=SAMPLE75=2017010134=93152=2017010103244494087606260=201701010324449408760625799=10000100268=1279=1269=048=17359555=6SZ683=354842270=10202.0271=19346=71023=1010=211
1128=99=18135=X49=SAMPLE75=2017010134=61352=2017010103084961271798360=201701010308496127179835799=10000100268=1279=1269=148=17359555=6SZ683=354843270=10223.0271=6346=21023=1010=154
1128=99=18235=X49=SAMPLE75=2017010134=31052=2017010109093412372295560=201701010909341237229555799=10000100268=1279=1269=048=17359555=6SZ683=354844270=10202.0271=49346=81023=1010=199
1128=99=18235=X49=SAMPLE75=2017010134=375352=2017010100423346748460460=201701010042334674846045799=10000100268=1279=1269=148=17359555=6SZ683=354845270=10223.0271=36346=31023=1010=190
1128=99=18235=X49=SAMPLE75=2017010134=240852=2017010107191945815053260=201701010719194581505325799=10000100268=1279=1269=048=17359555=6SZ683=354846270=10202.0271=19346=71023=1010=198
1128=99=18235=X49=SAMPLE75=2017010134=368652=2017010100160358111953060=201701010016035811195305799=10000100268=1279=1269=048=17359555=6SZ683=354847270=10202.0271=49346=81023=1010=228
1128=99=18135=X49=SAMPLE75=2017010134=400652=2017010108114795910576560=201701010811479591057655799=10000100268=1279=1269=148=17359555=6SZ683=354848270=10223.0271=6346=21023=1010=177
1128=99=18235=X49=SAMPLE75=2017010134=267452=2017010113411287054345260=201701011341128705434525799=10000100268=1279=1269=048=17359555=6SZ683=354849270=10202.0271=52346=91023=1010=218
1128=99=18035=X49=SAMPLE75=2017010134=157052=2017010104180687245829660=201701010418068724582965799=10000100268=1279=1269=048=17359555=6SZ683=354850270=10203.0271=4346=21023=910=100
1128=99=18135=X49=SAMPLE75=2017010134=172752=2017010102581592002841560=201701010258159200284155799=10000100268=1279=1269=048=17359555=6SZ683=354851270=10204.0271=34346=31023=810=161
1128=99=18135=X49=SAMPLE75=2017010134=482552=2017010106181129080680860=201701010618112908068085799=10000100268=1279=1269=048=17359555=6SZ683=354852270=10205.0271=51346=81023=710=175
1128=99=18035=X49=SAMPLE75=2017010134=339152=2017010106112825555251060=201701010611282555525105799=10000100268=1279=1269=048=17359555=6SZ683=354853270=10206.0271=4346=21023=610=105
1128=99=18135=X49=SAMPLE75=2017010134=306652=2017010112571037257576660=201701011257103725757665799=10000100268=1279=1269=048=17359555=6SZ683=354854270=10207.0271=15346=71023=510=172
1128=99=18035=X49=SAMPLE75=2017010134=8252=2017010101061952381733660=201701010106195238173365799=10000100268=1279=1269=048=17359555=6SZ683=354855270=10208.0271=7346=41023=410=118
1128=99=18035=X49=SAMPLE75=2017010134=225652=2017010109305686513617860=201701010930568651361785799=10000100268=1279=1269=048=17359555=6SZ683=354856270=10209.0271=4346=21023=310=106
1128=99=18035=X49=SAMPLE75=2017010134=456352=2017010107565524201316860=201701010756552420131685799=10000100268=1279=1269=048=17359555=6SZ683=354857270=10210.0271=4346=21023=210=116
1128=99=18035=X49=SAMPLE75=2017010134=49752=2017010104543750845584960=201701010454375084558495799=10000100268=1279=1269=048=17359555=6SZ683=354858270=10211.0271=5346=31023=110=120
1128=99=18035=X49=SAMPLE75=2017010134=95052=2017010104322985519923060=201701010432298551992305799=10000100268=1279=1269=148=17359555=6SZ683=354859270=10214.0271=8346=61023=210=136
1128=99=18035=X49=SAMPLE75=2017010134=337552=2017010110404166915981560=201701011040416691598155799=10000100268=1279=1269=148=17359555=6SZ683=354860270=10213.0271=1346=11023=110=105
1128=99=18135=X49=SAMPLE75=2017010134=82052=2017010101430165946732860=201701010143016594673285799=10000100268=1279=1269=148=17359555=6SZ683=354861270=10215.0271=20346=71023=310=143
1128=99=18135=X49=SAMPLE75=2017010134=210152=2017010113575331841864060=201701011357533184186405799=10000100268=1279=1269=148=17359555=6SZ683=354862270=10216.0271=42346=51023=410=162
1128=99=18135=X49=SAMPLE75=2017010134=247052=2017010108114976240142560=201701010811497624014255799=10000100268=1279=1269=148=17359555=6SZ683=354863270=10217.0271=33346=21023=510=156
1128=99=18035=X49=SAMPLE75=2017010134=47352=2017010110542337397187060=201701011054233739718705799=10000100268=1279=1269=148=17359555=6SZ683=354864270=10218.0271=4346=21023=610=108
1128=99=18235=X49=SAMPLE75=2017010134=488152=2017010114292020998520060=201701011429202099852005799=10000100268=1279=1269=148=17359555=6SZ683=354865270=10223.0271=36346=31023=1010=217
1128=99=18135=X49=SAMPLE75=2017010134=341052=2017010106412449540739460=201701010641244954073945799=10000100268=1279=1269=148=17359555=6SZ683=354866270=10219.0271=30346=91023=710=192
1128=99=18035=X49=SAMPLE75=2017010134=356652=2017010104220629677438960=201701010422062967743895799=10000100268=1279=1269=148=17359555=6SZ683=354867270=10220.0271=4346=21023=810=106
1128=99=18135=X49=SAMPLE75=2017010134=218352=2017010109031690350853660=201701010903169035085365799=10000100268=1279=1269=148=17359555=6SZ683=354868270=10221.0271=21346=61023=910=160
1128=99=18135=X49=SAMPLE75=2017010134=418952=2017010109424400274147260=201701010942440027414725799=10000100268=1279=0269=148=17359555=6SZ683=354869270=10222.0271=3346=11023=1010=153
1128=99=24935=X49=SAMPLE75=2017010134=36452=2017010103582997321063460=201701010358299732106345799=10000100268=2279=1269=048=17360055=6SH783=99068270=10261.0271=5346=21023=3279=1269=048=17360055=6SH783=99069270=10259.0271=3346=11023=510=044
1128=99=24935=X49=SAMPLE75=2017010134=274452=2017010105432774532867960=201701010543277453286795799=10000100268=2279=1269=048=17360055=6SH783=99070270=10262.0271=5346=21023=2279=1269=048=17360055=6SH783=99071270=10260.0271=3346=11023=410=003
1128=99=18035=X49=SAMPLE75=2017010134=151752=2017010105121902934706660=201701010512190293470665799=10000100268=1279=1269=048=17359555=6SZ683=354870270=10204.0271=4346=21023=810=121
1128=99=18135=X49=SAMPLE75=2017010134=358352=2017010101204969815639560=201701010120496981563955799=10000100268=1279=1269=048=17359555=6SZ683=354871270=10205.0271=21346=71023=710=189
1128=99=18135=X49=SAMPLE75=2017010134=83852=2017010109181647120866560=201701010918164712086655799=10000100268=1279=1269=048=17359555=6SZ683=354872270=10206.0271=34346=31023=610=186
1128=99=18235=X49=SAMPLE75=2017010134=361452=2017010104264230966991560=201701010426423096699155799=10000100268=1279=1269=048=17359555=6SZ683=354873270=10202.0271=22346=81023=1010=197
1128=99=18135=X49=SAMPLE75=2017010134=17252=2017010113014566774938460=201701011301456677493845799=10000100268=1279=1269=048=17359555=6SZ683=354874270=10204.0271=34346=31023=810=155
1128=99=18235=X49=SAMPLE75=2017010134=455952=2017010107201917111849660=201701010720191711184965799=10000100268=1279=1269=048=17359555=6SZ683=354875270=10202.0271=52346=91023=1010=189
1128=99=18035=X49=SAMPLE75=2017010134=48852=2017010100580794963389760=201701010058079496338975799=10000100268=1279=1269=048=17359555=6SZ683=354876270=10206.0271=4346=21023=610=133
1128=99=18235=X49=SAMPLE75=2017010134=343052=2017010105165375637478460=201701010516537563747845799=10000100268=1279=1269=048=17359555=6SZ683=354877270=10202.0271=22346=81023=1010=220
1128=99=18135=X49=SAMPLE75=2017010134=289252=2017010109592217196463660=201701010959221719646365799=10000100268=1279=1269=048=17359555=6SZ683=354878270=10203.0271=34346=31023=910=196
1128=99=18035=X49=SAMPLE75=2017010134=171352=2017010100405082736389360=201701010040508273638935799=10000100268=1279=1269=048=17359555=6SZ683=354879270=10203.0271=4346=21023=910=114
1128=99=18135=X49=SAMPLE75=2017010134=324552=2017010104242128110073460=201701010424212811007345799=10000100268=1279=1269=048=17359555=6SZ683=354880270=10206.0271=34346=31023=610=156
1128=99=18235=X49=SAMPLE75=2017010134=151952=2017010113460306894809160=201701011346030689480915799=10000100268=1279=1269=048=17359555=6SZ683=354881270=10202.0271=52346=91023=1010=220
1128=99=18235=X49=SAMPLE75=2017010134=492052=2017010104052453981361760=201701010405245398136175799=10000100268=1279=1269=048=17359555=6SZ683=354882270=10202.0271=22346=81023=1010=203
1128=99=18235=X49=SAMPLE75=2017010134=261252=2017010107020424483614460=201701010702042448361445799=10000100268=1279=1269=048=17359555=6SZ683=354883270=10202.0271=52346=91023=1010=214
1128=99=18235=X49=SAMPLE75=2017010134=379752=2017010102444443213852160=201701010244444321385215799=10000100268=1279=1269=048=17359555=6SZ683=354884270=10202.0271=22346=81023=1010=241
1128=99=18235=X49=SAMPLE75=2017010134=204552=2017010101505068237376760=201701010150506823737675799=10000100268=1279=1269=048=17359555=6SZ683=354885270=10202.0271=52346=91023=1010=228
1128=99=18235=X49=SAMPLE75=2017010134=397052=2017010109171822202333560=201701010917182220233355799=10000100268=1279=1269=048=17359555=6SZ683=354886270=10202.0271=22346=81023=1010=205
1128=99=18235=X49=SAMPLE75=2017010134=230252=2017010105564748607658760=201701010556474860765875799=10000100268=1279=1269=048=17359555=6SZ683=354887270=10202.0271=52346=91023=1010=220
1128=99=25235=X49=SAMPLE75=2017010134=441452=2017010113343681231172860=201701011334368123117285799=10000100268=2279=1269=148=17359555=6SZ683=354888270=10218.0271=7346=31023=6279=1269=148=17359555=6SZ683=354889270=10219.0271=27346=81023=710=207
1128=99=25235=X49=SAMPLE75=2017010134=89852=2017010101362521023741760=201701010136252102374175799=10000100268=2279=1269=148=17359555=6SZ683=354890270=10218.0271=4346=21023=6279=1269=148=17359555=6SZ683=354891270=10219.0271=30346=91023=710=178
1128=99=18235=X49=SAMPLE75=2017010134=397252=2017010104345291795891860=201701010434529179589185799=10000100268=1279=1269=048=17359555=6SZ683=354892270=10202.0271=22346=81023=1010=180
1128=99=18235=X49=SAMPLE75=2017010134=215452=2017010103442256618093960=201701010344225661809395799=10000100268=1279=1269=048=17359555=6SZ683=354893270=10202.0271=52346=91023=1010=189
1128=99=18235=X49=SAMPLE75=2017010134=407552=2017010112511932850404060=201701011251193285040405799=10000100268=1279=1269=048=17359555=6SZ683=354894270=10202.0271=22346=81023=1010=212
1128=99=18235=X49=SAMPLE75=2017010134=483752=2017010111171326681430660=201701011117132668143065799=10000100268=1279=1269=048=17359555=6SZ683=354895270=10202.0271=52346=91023=1010=188
1128=99=24035=X49=SAMPLE75=2017010134=294852=2017010103475054228347460=201701010347505422834745799=00000001268=1279=0269=248=17359555=6SZ683=354896270=10211.0271=3346=45797=237705=437=032=337=032=137=621180789662432=137=032=110=029
1128=99=15635=X49=SAMPLE75=2017010134=487152=2017010102334290849443060=201701010233429084944305799=00000010268=1279=0269=e48=17359555=6SZ683=354897271=1510=074
1128=99=18035=X49=SAMPLE75=2017010134=77452=2017010113452730907616160=201701011345273090761615799=10000100268=1279=1269=048=17359555=6SZ683=354898270=10211.0271=2346=11023=110=076
1128=99=17935=X49=SAMPLE75=2017010134=107852=2017010109342442154009660=201701010934244215400965799=10000100268=1279=0269=148=17360055=6SH783=99072270=10268.0271=3346=11023=110=019
1128=99=17935=X49=SAMPLE75=2017010134=22252=2017010112580696725848060=201701011258069672584805799=10000100268=1279=0269=148=17360055=6SH783=99073270=10269.0271=3346=11023=210=031
1128=99=25035=X49=SAMPLE75=2017010134=477952=2017010101431943472176260=201701010143194347217625799=10000100268=2279=2269=148=17360055=6SH783=99074270=10268.0271=3346=11023=1279=0269=148=17360055=6SH783=99075270=10278.0271=3346=11023=1010=041
1128=99=25035=X49=SAMPLE75=2017010134=273052=2017010110095620449387360=201701011009562044938735799=10000100268=2279=2269=148=17360055=6SH783=99076270=10269.0271=3346=11023=1279=0269=148=17360055=6SH783=99077270=10279.0271=3346=11023=1010=066
1128=99=18035=X49=SAMPLE75=2017010134=98852=2017010108092233440403560=201701010809223344040355799=10000100268=1279=1269=048=17359555=6SZ683=354899270=10206.0271=4346=21023=610=111
1128=99=18035=X49=SAMPLE75=2017010134=30052=2017010112413064920663260=201701011241306492066325799=10000100268=1279=1269=048=17359555=6SZ683=354900270=10211.0271=3346=21023=110=098
1128=99=18135=X49=SAMPLE75=2017010134=164652=2017010109290683535136060=201701010929068353513605799=10000100268=1279=1269=048=17359555=6SZ683=354901270=10205.0271=51346=81023=710=162
1128=99=18235=X49=SAMPLE75=2017010134=326052=2017010111385228708738860=201701011138522870873885799=10000100268=1279=1269=048=17359555=6SZ683=354902270=10202.0271=22346=81023=1010=172
1128=99=18235=X49=SAMPLE75=2017010134=234752=2017010114104975699031660=201701011410497569903165799=10000100268=1279=1269=048=17359555=6SZ683=354903270=10202.0271=52346=91023=1010=199
1128=99=18035=X49=SAMPLE75=2017010134=221452=2017010106084095443196960=201701010608409544319695799=10000100268=1279=1269=048=17359555=6SZ683=354904270=10204.0271=4346=21023=810=120
1128=99=18135=X49=SAMPLE75=2017010134=412752=2017010104114063074994660=201701010411406307499465799=10000100268=1279=1269=048=17359555=6SZ683=354905270=10204.0271=34346=31023=810=164
1128=99=18035=X49=SAMPLE75=2017010134=148752=2017010112152028872159860=201701011215202887215985799=10000100268=1279=1269=048=17359555=6SZ683=354906270=10204.0271=4346=21023=810=116
1128=99=18135=X49=SAMPLE75=2017010134=69152=2017010106134071868838360=201701010613407186883835799=10000100268=1279=1269=048=17359555=6SZ683=354907270=10205.0271=21346=71023=710=145
1128=99=18135=X49=SAMPLE75=2017010134=339252=2017010113045543372018460=201701011304554337201845799=10000100268=1279=1269=048=17359555=6SZ683=354908270=10206.0271=34346=31023=610=146
1128=99=18135=X49=SAMPLE75=2017010134=184452=2017010114181999862624460=201701011418199986262445799=10000100268=1279=1269=048=17359555=6SZ683=354909270=10204.0271=34346=31023=810=120
1128=99=18035=X49=SAMPLE75=2017010134=95252=2017010106184038063044460=201701010618403806304445799=10000100268=1279=1269=048=17359555=6SZ683=354910270=10204.0271=4346=21023=810=066
1128=99=18135=X49=SAMPLE75=2017010134=80552=2017010111342334850823560=201701011134233485082355799=10000100268=1279=1269=048=17359555=6SZ683=354911270=10204.0271=34346=31023=810=134
1128=99=18235=X49=SAMPLE75=2017010134=326352=2017010100324344560024560=201701010032434456002455799=10000100268=1279=1269=048=17359555=6SZ683=354912270=10202.0271=22346=81023=1010=161
1128=99=18235=X49=SAMPLE75=2017010134=178852=2017010110013069993634260=201701011001306999363425799=10000100268=1279=1269=048=17359555=6SZ683=354913270=10202.0271=52346=91023=1010=187
1128=99=18235=X49=SAMPLE75=2017010134=245752=2017010113312996084929860=201701011331299608492985799=10000100268=1279=1269=048=17359555=6SZ683=354914270=10202.0271=22346=81023=1010=211
1128=99=18235=X49=SAMPLE75=2017010134=293752=2017010111372451517643460=201701011137245151764345799=10000100268=1279=1269=048=17359555=6SZ683=354915270=10202.0271=52346=91023=1010=172
1128=99=18235=X49=SAMPLE75=2017010134=250852=2017010106571343495774460=201701010657134349577445799=10000100268=1279=1269=048=17359555=6SZ683=354916270=10202.0271=22346=81023=1010=175
1128=99=18235=X49=SAMPLE75=2017010134=312952=2017010110390840118374460=201701011039084011837445799=10000100268=1279=1269=048=17359555=6SZ683=354917270=10202.0271=52346=91023=1010=192
1128=99=18135=X49=SAMPLE75=2017010134=244852=2017010110063565457082960=201701011006356545708295799=10000100268=1279=1269=148=17359555=6SZ683=354918270=10219.0271=29346=81023=710=171
1128=99=18235=X49=SAMPLE75=2017010134=416752=2017010104520145728673560=201701010452014572867355799=10000100268=1279=1269=048=17359555=6SZ683=354919270=10202.0271=22346=81023=1010=196
1128=99=18235=X49=SAMPLE75=2017010134=376452=2017010102164207607747860=201701010216420760774785799=10000100268=1279=1269=048=17359555=6SZ683=354920270=10202.0271=52346=91023=1010=206
1128=99=18235=X49=SAMPLE75=2017010134=159352=2017010112364985554208060=201701011236498555420805799=10000100268=1279=1269=148=17359555=6SZ683=354921270=10222.0271=33346=21023=1010=170
1128=99=18235=X49=SAMPLE75=2017010134=472052=2017010112061950185120460=201701011206195018512045799=10000100268=1279=1269=048=17359555=6SZ683=354922270=10202.0271=22346=81023=1010=163
1128=99=18135=X49=SAMPLE75=2017010134=142052=2017010113272779700408160=201701011327277970040815799=10000100268=1279=1269=148=17359555=6SZ683=354923270=10222.0271=3346=11023=1010=138
1128=99=18235=X49=SAMPLE75=2017010134=358052=2017010111125544386097160=201701011112554438609715799=10000100268=1279=1269=048=17359555=6SZ683=354924270=10202.0271=52346=91023=1010=180
1128=99=18235=X49=SAMPLE75=2017010134=340052=2017010113393078358132560=201701011339307835813255799=10000100268=1279=1269=148=17359555=6SZ683=354925270=10222.0271=33346=21023=1010=209
1128=99=18235=X49=SAMPLE75=2017010134=33852=2017010106205737819068160=201701010620573781906815799=10000100268=1279=1269=048=17359555=6SZ683=354926270=10202.0271=22346=81023=1010=194
1128=99=18135=X49=SAMPLE75=2017010134=194852=2017010111531370682975860=201701011153137068297585799=10000100268=1279=1269=148=17359555=6SZ683=354927270=10222.0271=3346=11023=1010=120
1128=99=18235=X49=SAMPLE75=2017010134=378652=2017010110465448919458060=201701011046544891945805799=10000100268=1279=1269=048=17359555=6SZ683=354928270=10202.0271=52346=91023=1010=185
1128=99=18235=X49=SAMPLE75=2017010134=467652=2017010103410852221365260=201701010341085222136525799=10000100268=1279=1269=148=17359555=6SZ683=354929270=10222.0271=33346=21023=1010=176
1128=99=18235=X49=SAMPLE75=2017010134=232252=2017010113170048473191060=201701011317004847319105799=10000100268=1279=1269=048=17359555=6SZ683=354930270=10202.0271=22346=81023=1010=184
1128=99=18235=X49=SAMPLE75=2017010134=310852=2017010102465144695405460=201701010246514469540545799=10000100268=1279=1269=048=17359555=6SZ683=354931270=10202.0271=52346=91023=1010=191
1128=99=18135=X49=SAMPLE75=2017010134=104052=2017010110311662165470660=201701011031166216547065799=10000100268=1279=1269=148=17359555=6SZ683=354932270=10222.0271=3346=11023=1010=128
1128=99=18235=X49=SAMPLE75=2017010134=467752=2017010112444597421891960=201701011244459742189195799=10000100268=1279=1269=048=17359555=6SZ683=354933270=10202.0271=22346=81023=1010=196
1128=99=18235=X49=SAMPLE75=2017010134=100852=2017010110533836287751160=201701011053383628775115799=10000100268=1279=1269=148=17359555=6SZ683=354934270=10222.0271=33346=21023=1010=199
1128=99=18235=X49=SAMPLE75=2017010134=423352=2017010110213343427673360=201701011021334342767335799=10000100268=1279=1269=048=17359555=6SZ683=354935270=10202.0271=52346=91023=1010=203
1128=99=18135=X49=SAMPLE75=2017010134=134452=2017010101520067095743260=201701010152006709574325799=10000100268=1279=1269=148=17359555=6SZ683=354936270=10222.0271=3346=11023=1010=153
1128=99=18235=X49=SAMPLE75=2017010134=25352=2017010104592291123429160=201701010459229112342915799=10000100268=1279=1269=148=17359555=6SZ683=354937270=10222.0271=33346=21023=1010=191
1128=99=18135=X49=SAMPLE75=2017010134=93352=2017010111255781373821060=201701011125578137382105799=10000100268=1279=1269=148=17359555=6SZ683=354938270=10222.0271=3346=11023=1010=126
1128=99=18035=X49=SAMPLE75=2017010134=415552=2017010104082216031021360=201701010408221603102135799=10000100268=1279=1269=048=17359555=6SZ683=354939270=10204.0271=4346=21023=810=091
1128=99=18135=X49=SAMPLE75=2017010134=258352=2017010110505009663474460=201701011050500966347445799=10000100268=1279=1269=048=17359555=6SZ683=354940270=10205.0271=51346=81023=710=133
1128=99=18235=X49=SAMPLE75=2017010134=652=2017010105554769070805960=201701010555476907080595799=10000100268=1279=1269=148=17359555=6SZ683=354941270=10222.0271=33346=21023=1010=182
1128=99=18135=X49=SAMPLE75=2017010134=121952=2017010105434877164647160=201701010543487716464715799=10000100268=1279=1269=148=17359555=6SZ683=354942270=10222.0271=3346=11023=1010=117
1128=99=18135=X49=SAMPLE75=2017010134=265452=2017010103522281573159860=201701010352228157315985799=10000100268=1279=1269=048=17359555=6SZ683=354943270=10205.0271=21346=71023=710=140
1128=99=18235=X49=SAMPLE75=2017010134=246152=2017010109412900029436460=201701010941290002943645799=10000100268=1279=1269=148=17359555=6SZ683=354944270=10222.0271=33346=21023=1010=195
1128=99=18135=X49=SAMPLE75=2017010134=470152=2017010103104069559512760=201701010310406955951275799=10000100268=1279=1269=048=17359555=6SZ683=354945270=10204.0271=34346=31023=810=143
1128=99=18135=X49=SAMPLE75=2017010134=108352=2017010108221451429020460=201701010822145142902045799=10000100268=1279=1269=148=17359555=6SZ683=354946270=10222.0271=3346=11023=1010=136
1128=99=18235=X49=SAMPLE75=2017010134=397752=2017010108134161121762260=201701010813416112176225799=10000100268=1279=1269=148=17359555=6SZ683=354947270=10222.0271=33346=21023=1010=196
1128=99=18135=X49=SAMPLE75=2017010134=317852=2017010108464513650935460=201701010846451365093545799=10000100268=1279=1269=148=17359555=6SZ683=354948270=10222.0271=3346=11023=1010=150
1128=99=18235=X49=SAMPLE75=2017010134=217452=2017010104585219064429760=201701010458521906442975799=10000100268=1279=1269=148=17359555=6SZ683=354949270=10222.0271=33346=21023=1010=204
1128=99=18135=X49=SAMPLE75=2017010134=186352=2017010109552395249411260=201701010955239524941125799=10000100268=1279=1269=148=17359555=6SZ683=354950270=10222.0271=3346=11023=1010=131
1128=99=18235=X49=SAMPLE75=2017010134=292252=2017010113492744413295460=201701011349274441329545799=10000100268=1279=1269=048=17359555=6SZ683=354951270=10202.0271=22346=81023=1010=183
1128=99=18235=X49=SAMPLE75=2017010134=342852=2017010114041296242294060=201701011404129624229405799=10000100268=1279=1269=148=17359555=6SZ683=354952270=10222.0271=33346=21023=1010=201
1128=99=18235=X49=SAMPLE75=2017010134=2752=2017010108162012510058760=201701010816201251005875799=10000100268=1279=1269=048=17359555=6SZ683=354953270=10202.0271=52346=91023=1010=207
1128=99=18135=X49=SAMPLE75=2017010134=366952=2017010100484060152310460=201701010048406015231045799=10000100268=1279=1269=148=17359555=6SZ683=354954270=10222.0271=3346=11023=1010=149
1128=99=18235=X49=SAMPLE75=2017010134=155552=2017010111134185690553860=201701011113418569055385799=10000100268=1279=1269=148=17359555=6SZ683=354955270=10222.0271=33346=21023=1010=186
1128=99=18135=X49=SAMPLE75=2017010134=268152=2017010113395045825349560=201701011339504582534955799=10000100268=1279=1269=148=17359555=6SZ683=354956270=10222.0271=3346=11023=1010=140
1128=99=18235=X49=SAMPLE75=2017010134=72652=2017010112094988817826760=201701011209498881782675799=10000100268=1279=1269=148=17359555=6SZ683=354957270=10222.0271=33346=21023=1010=191
1128=99=18135=X49=SAMPLE75=2017010134=114352=2017010110261056654676360=201701011026105665467635799=10000100268=1279=1269=148=17359555=6SZ683=354958270=10222.0271=3346=11023=1010=160
1128=99=18235=X49=SAMPLE75=2017010134=14252=2017010102022852614749660=201701010202285261474965799=10000100268=1279=1269=148=17359555=6SZ683=354959270=10222.0271=33346=21023=1010=190
1128=99=18135=X49=SAMPLE75=2017010134=246152=2017010113054766869434860=201701011305476686943485799=10000100268=1279=1269=148=17359555=6SZ683=354960270=10222.0271=3346=11023=1010=164
1128=99=18235=X49=SAMPLE75=2017010134=202552=2017010101484249236186960=201701010148424923618695799=10000100268=1279=1269=148=17359555=6SZ683=354961270=10222.0271=33346=21023=1010=191
1128=99=18135=X49=SAMPLE75=2017010134=452852=2017010108371457884753060=201701010837145788475305799=10000100268=1279=1269=148=17359555=6SZ683=354962270=10222.0271=3346=11023=1010=142
1128=99=18235=X49=SAMPLE75=2017010134=31052=2017010100512895367208860=201701010051289536720885799=10000100268=1279=1269=148=17359555=6SZ683=354963270=10222.0271=33346=21023=1010=210
1128=99=18135=X49=SAMPLE75=2017010134=239352=2017010108412623177561860=201701010841262317756185799=10000100268=1279=1269=148=17359555=6SZ683=354964270=10222.0271=3346=11023=1010=137
1128=99=18235=X49=SAMPLE75=2017010134=380152=2017010111263361224559960=201701011126336122455995799=10000100268=1279=1269=148=17359555=6SZ683=354965270=10222.0271=33346=21023=1010=184
