1128=99=18135=X49=SAMPLE75=2016101134=353252=2007110123240282860166460=200711012324028286016645799=10000100268=1279=1269=148=17359555=6SZ683=355954270=10220.0271=34346=31023=710=165
1128=99=18035=X49=SAMPLE75=2016101134=374252=2011082923062113529472060=201108292306211352947205799=10000100268=1279=1269=048=17359555=6SZ683=355955270=10210.0271=6346=41023=410=080
1128=99=18035=X49=SAMPLE75=2016101134=252852=2007061702305019559440060=200706170230501955944005799=10000100268=1279=1269=148=17359555=6SZ683=355956270=10220.0271=4346=21023=710=096
1128=99=18135=X49=SAMPLE75=2016101134=30252=2015070107561352799072060=201507010756135279907205799=10000100268=1279=1269=048=17359555=6SZ683=355957270=10207.0271=12346=61023=710=132
1128=99=18135=X49=SAMPLE75=2016101134=271752=2014100416260882299443260=201410041626088229944325799=10000100268=1279=1269=148=17359555=6SZ683=355958270=10220.0271=34346=31023=710=139
1128=99=18135=X49=SAMPLE75=2016101134=333052=2002123008191116035963260=200212300819111603596325799=10000100268=1279=1269=048=17359555=6SZ683=355959270=10207.0271=42346=71023=710=125
1128=99=18135=X49=SAMPLE75=2016101134=33952=2007061209174789922726460=200706120917478992272645799=10000100268=1279=1269=048=17359555=6SZ683=355960270=10207.0271=12346=61023=710=151
1128=99=18035=X49=SAMPLE75=2016101134=89952=2005021221513925146787260=200502122151392514678725799=10000100268=1279=1269=148=17359555=6SZ683=355961270=10220.0271=4346=21023=710=094
1128=99=18135=X49=SAMPLE75=2016101134=111552=2006112221350637840726460=200611222135063784072645799=10000100268=1279=1269=048=17359555=6SZ683=355962270=10207.0271=42346=71023=710=177
1128=99=18135=X49=SAMPLE75=2016101134=93452=2002102421092864574396860=200210242109286457439685799=10000100268=1279=1269=148=17359555=6SZ683=355963270=10220.0271=34346=31023=710=143
1128=99=18035=X49=SAMPLE75=2016101134=233352=2010100807023589488300860=201010080702358948830085799=10000100268=1279=1269=148=17359555=6SZ683=355964270=10220.0271=4346=21023=710=102
1128=99=18135=X49=SAMPLE75=2016101134=221052=2013040601353551920723260=201304060135355192072325799=10000100268=1279=1269=048=17359555=6SZ683=355965270=10207.0271=12346=61023=710=166
1128=99=18135=X49=SAMPLE75=2016101134=27652=2009022315025754833574460=200902231502575483357445799=10000100268=1279=1269=148=17359555=6SZ683=355966270=10220.0271=34346=31023=710=139
1128=99=18135=X49=SAMPLE75=2016101134=499952=2007121816191462633308860=200712181619146263330885799=10000100268=1279=1269=048=17359555=6SZ683=355967270=10207.0271=42346=71023=710=144
1128=99=18035=X49=SAMPLE75=2016101134=57852=2012020816395533763008060=201202081639553376300805799=10000100268=1279=1269=148=17359555=6SZ683=355968270=10220.0271=4346=21023=710=099
1128=99=18135=X49=SAMPLE75=2016101134=153452=2008123003424097119372860=200812300342409711937285799=10000100268=1279=1269=148=17359555=6SZ683=355969270=10220.0271=34346=31023=710=135
1128=99=18035=X49=SAMPLE75=2016101134=1752=2000082505211394856944460=200008250521139485694445799=10000100268=1279=1269=148=17359555=6SZ683=355970270=10220.0271=4346=21023=710=105
1128=99=18135=X49=SAMPLE75=2016101134=61752=2007021302372608294547260=200702130237260829454725799=10000100268=1279=1269=148=17359555=6SZ683=355971270=10220.0271=34346=31023=710=155
1128=99=18135=X49=SAMPLE75=2016101134=117952=2003022211024674814947260=200302221102467481494725799=10000100268=1279=1269=048=17359555=6SZ683=355972270=10207.0271=12346=61023=710=122
1128=99=18035=X49=SAMPLE75=2016101134=445152=2014040913202706446592060=201404091320270644659205799=10000100268=1279=1269=148=17359555=6SZ683=355973270=10220.0271=4346=21023=710=066
1128=99=18135=X49=SAMPLE75=2016101134=189652=2010031011191699782086460=201003101119169978208645799=10000100268=1279=1269=048=17359555=6SZ683=355974270=10207.0271=42346=71023=710=152
1128=99=18135=X49=SAMPLE75=2016101134=434452=2012121907030095364057660=201212190703009536405765799=10000100268=1279=1269=148=17359555=6SZ683=355975270=10220.0271=34346=31023=710=134
1128=99=18135=X49=SAMPLE75=2016101134=227952=2004042418493793335516860=200404241849379333551685799=10000100268=1279=1269=048=17359555=6SZ683=355976270=10207.0271=12346=61023=710=144
1128=99=18135=X49=SAMPLE75=2016101134=14852=2000042821071172593320060=200004282107117259332005799=10000100268=1279=1269=048=17359555=6SZ683=355977270=10207.0271=42346=71023=710=175
1128=99=18035=X49=SAMPLE75=2016101134=306252=2007071105371906191110460=200707110537190619111045799=10000100268=1279=1269=148=17359555=6SZ683=355978270=10222.0271=4346=21023=910=099
1128=99=18035=X49=SAMPLE75=2016101134=89252=2006022202245404692796860=200602220224540469279685799=10000100268=1279=1269=148=17359555=6SZ683=355979270=10220.0271=4346=21023=710=080
1128=99=18135=X49=SAMPLE75=2016101134=319952=2013052707523162609862460=201305270752316260986245799=10000100268=1279=1269=148=17359555=6SZ683=355980270=10220.0271=34346=31023=710=129
1128=99=18035=X49=SAMPLE75=2016101134=291452=2000020317081019935875460=200002031708101993587545799=10000100268=1279=1269=148=17359555=6SZ683=355981270=10220.0271=4346=21023=710=073
1128=99=18135=X49=SAMPLE75=2016101134=159252=2005072216472390926678460=200507221647239092667845799=10000100268=1279=1269=148=17359555=6SZ683=355982270=10220.0271=34346=31023=710=153
1128=99=18035=X49=SAMPLE75=2016101134=87752=2008082213042828251801660=200808221304282825180165799=10000100268=1279=1269=148=17359555=6SZ683=355983270=10220.0271=4346=21023=710=081
1128=99=18135=X49=SAMPLE75=2016101134=375252=2005111820092871857174460=200511182009287185717445799=10000100268=1279=1269=048=17359555=6SZ683=355984270=10207.0271=12346=61023=710=147
1128=99=18135=X49=SAMPLE75=2016101134=177652=2001061218385519775820060=200106121838551977582005799=10000100268=1279=1269=048=17359555=6SZ683=355985270=10207.0271=42346=71023=710=132
1128=99=18135=X49=SAMPLE75=2016101134=22452=2002100502523051520944060=200210050252305152094405799=10000100268=1279=1269=148=17359555=6SZ683=355986270=10220.0271=34346=31023=710=145
1128=99=18135=X49=SAMPLE75=2016101134=271752=2005061309070141857267260=200506130907014185726725799=10000100268=1279=1269=048=17359555=6SZ683=355987270=10207.0271=12346=61023=710=156
1128=99=18035=X49=SAMPLE75=2016101134=23652=2014071201411499911238460=201407120141149991123845799=10000100268=1279=1269=148=17359555=6SZ683=355988270=10220.0271=4346=21023=710=107
1128=99=18135=X49=SAMPLE75=2016101134=120052=2010011812560515795155260=201001181256051579515525799=10000100268=1279=1269=048=17359555=6SZ683=355989270=10207.0271=42346=71023=710=182
1128=99=18135=X49=SAMPLE75=2016101134=393352=2001120806500643222904060=200112080650064322290405799=10000100268=1279=1269=148=17359555=6SZ683=355990270=10220.0271=34346=31023=710=158
1128=99=32135=X49=SAMPLE75=2016101134=320752=2014013120444530526035260=201401312044453052603525799=00000001268=2279=0269=248=17359555=6SZ683=355991270=10213.0271=1346=25797=2279=0269=248=17359555=6SZ683=355992270=10212.0271=4346=35797=237705=537=032=137=032=137=032=437=621180790715732=137=032=310=002
1128=99=15635=X49=SAMPLE75=2016101134=327952=2016051018071231422764860=201605101807123142276485799=00000010268=1279=0269=e48=17359555=6SZ683=355993271=2910=095
1128=99=39535=X49=SAMPLE75=2016101134=429052=2011101623163754260422460=201110162316375426042245799=10000100268=4279=2269=048=17359555=6SZ683=355994270=10213.0271=1346=11023=1279=2269=048=17359555=6SZ683=355995270=10212.0271=4346=21023=1279=0269=048=17359555=6SZ683=355996270=10203.0271=4346=21023=9279=0269=048=17359555=6SZ683=355997270=10202.0271=52346=91023=1010=105
1128=99=17935=X49=SAMPLE75=2016101134=106652=2011010705071939501664060=201101070507193950166405799=10000100268=1279=0269=148=17360055=6SH783=99105270=10269.0271=3346=11023=110=026
1128=99=25135=X49=SAMPLE75=2016101134=259852=2007043008550302058604860=200704300855030205860485799=10000100268=2279=2269=048=17360055=6SH783=99106270=10265.0271=3346=11023=1279=0269=048=17360055=6SH783=99107270=10255.0271=53346=21023=1010=082
1128=99=17935=X49=SAMPLE75=2016101134=355552=2005071404051469906835260=200507140405146990683525799=10000100268=1279=0269=148=17360055=6SH783=99108270=10270.0271=3346=11023=210=007
1128=99=17935=X49=SAMPLE75=2016101134=190852=2012042020190857251724860=201204202019085725172485799=10000100268=1279=1269=048=17360055=6SH783=99109270=10264.0271=2346=11023=110=039
1128=99=32035=X49=SAMPLE75=2016101134=67852=2005110209234126373731260=200511020923412637373125799=10000100268=3279=2269=048=17360055=6SH783=99110270=10264.0271=2346=11023=1279=1269=048=17360055=6SH783=99111270=10261.0271=5346=21023=3279=0269=048=17360055=6SH783=99112270=10254.0271=3346=11023=1010=208
1128=99=18035=X49=SAMPLE75=2016101134=381452=2000101807100218876963660=200010180710021887696365799=10000100268=1279=1269=048=17359555=6SZ683=355998270=10211.0271=4346=31023=110=088
1128=99=18135=X49=SAMPLE75=2016101134=69552=2015082522431332600544060=201508252243133260054405799=10000100268=1279=1269=048=17359555=6SZ683=355999270=10207.0271=12346=61023=510=157
1128=99=25035=X49=SAMPLE75=2016101134=14952=2009111700332974984288060=200911170033297498428805799=10000100268=2279=2269=148=17360055=6SH783=99113270=10269.0271=3346=11023=1279=0269=148=17360055=6SH783=99114270=10279.0271=3346=11023=1010=042
1128=99=25135=X49=SAMPLE75=2016101134=285852=2005100605585040235555260=200510060558504023555525799=10000100268=2279=2269=148=17360055=6SH783=99115270=10270.0271=3346=11023=1279=0269=148=17360055=6SH783=99116270=10280.0271=53346=11023=1010=069
1128=99=18035=X49=SAMPLE75=2016101134=200352=2008051118242803651497660=200805111824280365149765799=10000100268=1279=1269=148=17359555=6SZ683=356000270=10220.0271=4346=21023=710=102
1128=99=18135=X49=SAMPLE75=2016101134=266052=2014090720530756011961660=201409072053075601196165799=10000100268=1279=1269=048=17359555=6SZ683=356001270=10206.0271=34346=31023=610=149
1128=99=18135=X49=SAMPLE75=2016101134=459952=2011061112143374691174460=201106111214337469117445799=10000100268=1279=1269=148=17359555=6SZ683=356002270=10220.0271=34346=31023=710=138
1128=99=18035=X49=SAMPLE75=2016101134=419452=2008062114251019589164860=200806211425101958916485799=10000100268=1279=1269=148=17359555=6SZ683=356003270=10220.0271=4346=21023=710=056
1128=99=18135=X49=SAMPLE75=2016101134=159152=2003101922251179381091260=200310192225117938109125799=10000100268=1279=1269=148=17359555=6SZ683=356004270=10220.0271=34346=31023=710=143
1128=99=18235=X49=SAMPLE75=2016101134=443552=2016111219441925453766460=201611121944192545376645799=10000100268=1279=1269=048=17359555=6SZ683=356005270=10202.0271=22346=81023=1010=164
1128=99=18235=X49=SAMPLE75=2016101134=131652=2016101119480731960627260=201610111948073196062725799=10000100268=1279=1269=048=17359555=6SZ683=356006270=10202.0271=52346=91023=1010=171
1128=99=18035=X49=SAMPLE75=2016101134=496052=2014092120244815982131260=201409212024481598213125799=10000100268=1279=1269=148=17359555=6SZ683=356007270=10220.0271=4346=21023=710=077
1128=99=18035=X49=SAMPLE75=2016101134=253852=2000031017404585672805260=200003101740458567280525799=10000100268=1279=1269=048=17359555=6SZ683=356008270=10206.0271=4346=21023=610=072
1128=99=18135=X49=SAMPLE75=2016101134=111952=2007061916160475526188860=200706191616047552618885799=10000100268=1279=1269=148=17359555=6SZ683=356009270=10220.0271=34346=31023=710=136
1128=99=18135=X49=SAMPLE75=2016101134=174952=2003082116473490249966460=200308211647349024996645799=10000100268=1279=1269=048=17359555=6SZ683=356010270=10206.0271=34346=31023=610=135
1128=99=18135=X49=SAMPLE75=2016101134=280652=2010040612021500074220860=201004061202150007422085799=10000100268=1279=1269=148=17359555=6SZ683=356011270=10215.0271=18346=61023=210=137
1128=99=18035=X49=SAMPLE75=2016101134=192852=2009102303453430909241660=200910230345343090924165799=10000100268=1279=1269=048=17359555=6SZ683=356012270=10206.0271=4346=21023=610=076
1128=99=18135=X49=SAMPLE75=2016101134=116452=2011083022160853416012860=201108302216085341601285799=10000100268=1279=1269=148=17359555=6SZ683=356013270=10219.0271=51346=81023=610=188
1128=99=18035=X49=SAMPLE75=2016101134=261952=2008072323154154495270460=200807232315415449527045799=10000100268=1279=1269=148=17359555=6SZ683=356014270=10220.0271=4346=21023=710=090
1128=99=18135=X49=SAMPLE75=2016101134=172552=2001042505553021534977660=200104250555302153497765799=10000100268=1279=1269=148=17359555=6SZ683=356015270=10219.0271=21346=71023=610=141
1128=99=18135=X49=SAMPLE75=2016101134=435352=2013020308512728915328060=201302030851272891532805799=10000100268=1279=1269=048=17359555=6SZ683=356016270=10206.0271=34346=31023=610=131
1128=99=18135=X49=SAMPLE75=2016101134=264552=2016021205250934091916860=201602120525093409191685799=10000100268=1279=1269=148=17359555=6SZ683=356017270=10220.0271=34346=31023=710=113
1128=99=18035=X49=SAMPLE75=2016101134=270252=2007010501205120831366460=200701050120512083136645799=10000100268=1279=1269=048=17359555=6SZ683=356018270=10206.0271=4346=21023=610=048
1128=99=18135=X49=SAMPLE75=2016101134=65652=2006010819214238238281660=200601081921423823828165799=10000100268=1279=1269=048=17359555=6SZ683=356019270=10206.0271=34346=31023=610=154
1128=99=18035=X49=SAMPLE75=2016101134=202452=2000051512091178502557460=200005151209117850255745799=10000100268=1279=1269=148=17359555=6SZ683=356020270=10220.0271=4346=21023=710=082
1128=99=18135=X49=SAMPLE75=2016101134=447852=2008060205493749589740860=200806020549374958974085799=10000100268=1279=1269=148=17359555=6SZ683=356021270=10220.0271=34346=31023=710=146
1128=99=18035=X49=SAMPLE75=2016101134=460652=2011102002282749186438460=201110200228274918643845799=10000100268=1279=1269=148=17359555=6SZ683=356022270=10220.0271=4346=21023=710=059
1128=99=18135=X49=SAMPLE75=2016101134=9552=2000032207591839100049560=200003220759183910004955799=10000100268=1279=1269=048=17359555=6SZ683=356023270=10208.0271=10346=51023=410=128
1128=99=18235=X49=SAMPLE75=2016101134=121652=2011092600324302366592060=201109260032430236659205799=10000100268=1279=1269=048=17359555=6SZ683=356024270=10202.0271=22346=81023=1010=162
1128=99=18135=X49=SAMPLE75=2016101134=226752=2009030909475008162009660=200903090947500816200965799=10000100268=1279=1269=048=17359555=6SZ683=356025270=10205.0271=51346=81023=710=153
1128=99=18135=X49=SAMPLE75=2016101134=5552=2008051903564200767449660=200805190356420076744965799=10000100268=1279=1269=148=17359555=6SZ683=356026270=10220.0271=34346=31023=710=128
1128=99=18135=X49=SAMPLE75=2016101134=35852=2001081707275858588451260=200108170727585858845125799=10000100268=1279=1269=048=17359555=6SZ683=356027270=10205.0271=21346=71023=710=130
1128=99=18135=X49=SAMPLE75=2016101134=442652=2008100503423002053446460=200810050342300205344645799=10000100268=1279=1269=048=17359555=6SZ683=356028270=10208.0271=40346=61023=410=130
1128=99=18035=X49=SAMPLE75=2016101134=6652=2007061305495832637475260=200706130549583263747525799=10000100268=1279=1269=148=17359555=6SZ683=356029270=10220.0271=4346=21023=710=071
1128=99=18235=X49=SAMPLE75=2016101134=286452=2014111708370054410566460=201411170837005441056645799=10000100268=1279=1269=048=17359555=6SZ683=356030270=10202.0271=52346=91023=1010=187
1128=99=18135=X49=SAMPLE75=2016101134=215452=2015112403525176581766460=201511240352517658176645799=10000100268=1279=1269=148=17359555=6SZ683=356031270=10220.0271=34346=31023=710=144
1128=99=18035=X49=SAMPLE75=2016101134=160752=2014031618093776746323260=201403161809377674632325799=10000100268=1279=1269=148=17359555=6SZ683=356032270=10220.0271=4346=21023=710=076
1128=99=18135=X49=SAMPLE75=2016101134=400352=2000020418345546028552360=200002041834554602855235799=10000100268=1279=1269=148=17359555=6SZ683=356033270=10220.0271=34346=31023=710=159
1128=99=18035=X49=SAMPLE75=2016101134=417052=2015030811205130688742460=201503081120513068874245799=10000100268=1279=1269=148=17359555=6SZ683=356034270=10220.0271=4346=21023=710=077
1128=99=18035=X49=SAMPLE75=2016101134=137052=2004012419500240883038460=200401241950024088303845799=10000100268=1279=1269=048=17359555=6SZ683=356035270=10206.0271=4346=21023=610=072
1128=99=18135=X49=SAMPLE75=2016101134=163452=2013021904495784366662460=201302190449578436666245799=10000100268=1279=1269=148=17359555=6SZ683=356036270=10220.0271=34346=31023=710=125
1128=99=18135=X49=SAMPLE75=2016101134=342252=2015072412593197912268860=201507241259319791226885799=10000100268=1279=1269=048=17359555=6SZ683=356037270=10206.0271=34346=31023=610=136
1128=99=18135=X49=SAMPLE75=2016101134=311852=2000012922102373644269860=200001292210237364426985799=10000100268=1279=1269=048=17359555=6SZ683=356038270=10208.0271=10346=51023=410=159
1128=99=18235=X49=SAMPLE75=2016101134=362952=2007070416131020789686460=200707041613102078968645799=10000100268=1279=1269=048=17359555=6SZ683=356039270=10202.0271=22346=81023=1010=216
1128=99=18135=X49=SAMPLE75=2016101134=218552=2014071006292217070380860=201407100629221707038085799=10000100268=1279=1269=048=17359555=6SZ683=356040270=10205.0271=51346=81023=710=158
1128=99=18035=X49=SAMPLE75=2016101134=136152=2000110418511974362203660=200011041851197436220365799=10000100268=1279=1269=148=17359555=6SZ683=356041270=10220.0271=4346=21023=710=107
1128=99=18135=X49=SAMPLE75=2016101134=494352=2011071001080151145561660=201107100108015114556165799=10000100268=1279=1269=048=17359555=6SZ683=356042270=10205.0271=21346=71023=710=145
1128=99=18135=X49=SAMPLE75=2016101134=302552=2013080814531152913568060=201308081453115291356805799=10000100268=1279=1269=048=17359555=6SZ683=356043270=10208.0271=40346=61023=410=142
1128=99=18135=X49=SAMPLE75=2016101134=252452=2008070515242407906339260=200807051524240790633925799=10000100268=1279=1269=148=17359555=6SZ683=356044270=10220.0271=34346=31023=710=132
1128=99=18035=X49=SAMPLE75=2016101134=6752=2009041314034277941024060=200904131403427794102405799=10000100268=1279=1269=148=17359555=6SZ683=356045270=10220.0271=4346=21023=710=078
1128=99=18235=X49=SAMPLE75=2016101134=479852=2008021715192798520297660=200802171519279852029765799=10000100268=1279=1269=048=17359555=6SZ683=356046270=10202.0271=52346=91023=1010=198
1128=99=18135=X49=SAMPLE75=2016101134=82552=2006053104075688625702460=200605310407568862570245799=10000100268=1279=1269=148=17359555=6SZ683=356047270=10220.0271=34346=31023=710=154
1128=99=18035=X49=SAMPLE75=2016101134=83052=2006062300155119091737660=200606230015511909173765799=10000100268=1279=1269=148=17359555=6SZ683=356048270=10220.0271=4346=21023=710=102
1128=99=18135=X49=SAMPLE75=2016101134=466952=2012081917201016218003260=201208191720101621800325799=10000100268=1279=1269=148=17359555=6SZ683=356049270=10220.0271=34346=31023=710=162
1128=99=18235=X49=SAMPLE75=2016101134=272052=2007050401225382379043260=200705040122538237904325799=10000100268=1279=1269=048=17359555=6SZ683=356050270=10202.0271=22346=81023=1010=163
1128=99=18235=X49=SAMPLE75=2016101134=370752=2006032522412220432598460=200603252241222043259845799=10000100268=1279=1269=048=17359555=6SZ683=356051270=10202.0271=52346=91023=1010=178
1128=99=18235=X49=SAMPLE75=2016101134=170252=2017031404015140689977660=201703140401514068997765799=10000100268=1279=1269=048=17359555=6SZ683=356052270=10202.0271=22346=81023=1010=166
1128=99=18235=X49=SAMPLE75=2016101134=43152=2001081401312194144733660=200108140131219414473365799=10000100268=1279=1269=048=17359555=6SZ683=356053270=10202.0271=52346=91023=1010=168
1128=99=18035=X49=SAMPLE75=2016101134=372452=2004081716005168693654460=200408171600516869365445799=10000100268=1279=1269=148=17359555=6SZ683=356054270=10220.0271=4346=21023=710=122
1128=99=18135=X49=SAMPLE75=2016101134=367252=2000101202010563593149260=200010120201056359314925799=10000100268=1279=1269=148=17359555=6SZ683=356055270=10220.0271=34346=31023=710=159
1128=99=18035=X49=SAMPLE75=2016101134=199852=2003090417583728071908860=200309041758372807190885799=10000100268=1279=1269=148=17359555=6SZ683=356056270=10220.0271=4346=21023=710=097
1128=99=18135=X49=SAMPLE75=2016101134=205452=2011030521305159971968060=201103052130515997196805799=10000100268=1279=1269=148=17359555=6SZ683=356057270=10220.0271=34346=31023=710=126
1128=99=18035=X49=SAMPLE75=2016101134=331452=2012052014090674626156860=201205201409067462615685799=10000100268=1279=0269=048=17359555=6SZ683=356058270=10212.0271=1346=11023=110=066
1128=99=17935=X49=SAMPLE75=2016101134=365252=2004030423104080375740860=200403042310408037574085799=10000100268=1279=0269=048=17360055=6SH783=99117270=10265.0271=3346=11023=110=008
1128=99=17935=X49=SAMPLE75=2016101134=211952=2009061508333183660915260=200906150833318366091525799=10000100268=1279=0269=048=17360055=6SH783=99118270=10264.0271=3346=11023=210=027
1128=99=18035=X49=SAMPLE75=2016101134=247652=2013021511232175897587260=201302151123217589758725799=10000100268=1279=1269=048=17359555=6SZ683=356059270=10212.0271=2346=21023=110=086
1128=99=25135=X49=SAMPLE75=2016101134=449252=2016082523014878804832060=201608252301487880483205799=10000100268=2279=2269=048=17360055=6SH783=99119270=10265.0271=3346=11023=1279=0269=048=17360055=6SH783=99120270=10255.0271=53346=21023=1010=073
1128=99=24935=X49=SAMPLE75=2016101134=223152=2007031812310405959382460=200703181231040595938245799=10000100268=2279=1269=048=17360055=6SH783=99121270=10262.0271=5346=21023=3279=1269=048=17360055=6SH783=99122270=10261.0271=3346=11023=410=227
1128=99=18135=X49=SAMPLE75=2016101134=381652=2003062222393543384851260=200306222239354338485125799=10000100268=1279=1269=048=17359555=6SZ683=356060270=10208.0271=10346=51023=510=125
1128=99=18135=X49=SAMPLE75=2016101134=237052=2009092221243613747872060=200909222124361374787205799=10000100268=1279=1269=048=17359555=6SZ683=356061270=10205.0271=51346=81023=810=137
1128=99=18035=X49=SAMPLE75=2016101134=423552=2012092708125817742240060=201209270812581774224005799=10000100268=1279=1269=148=17359555=6SZ683=356062270=10220.0271=4346=21023=710=070
1128=99=18135=X49=SAMPLE75=2016101134=93652=2008073119184502125088060=200807311918450212508805799=10000100268=1279=1269=048=17359555=6SZ683=356063270=10205.0271=21346=71023=810=128
1128=99=18135=X49=SAMPLE75=2016101134=293552=2016041506400039598508860=201604150640003959850885799=10000100268=1279=1269=048=17359555=6SZ683=356064270=10208.0271=40346=61023=510=151
1128=99=18135=X49=SAMPLE75=2016101134=296552=2007021914532237952688060=200702191453223795268805799=10000100268=1279=1269=148=17359555=6SZ683=356065270=10220.0271=34346=31023=710=133
1128=99=18035=X49=SAMPLE75=2016101134=29052=2002111720572697748860860=200211172057269774886085799=10000100268=1279=1269=048=17359555=6SZ683=356066270=10206.0271=4346=21023=710=086
1128=99=18135=X49=SAMPLE75=2016101134=264052=2007042006134397084646460=200704200613439708464645799=10000100268=1279=1269=048=17359555=6SZ683=356067270=10206.0271=34346=31023=710=166
1128=99=18135=X49=SAMPLE75=2016101134=118252=2010032912584004332403260=201003291258400433240325799=10000100268=1279=1269=048=17359555=6SZ683=356068270=10208.0271=10346=51023=510=145
1128=99=18135=X49=SAMPLE75=2016101134=391652=2006122220482561724432060=200612222048256172443205799=10000100268=1279=1269=048=17359555=6SZ683=356069270=10205.0271=51346=81023=810=154
1128=99=18035=X49=SAMPLE75=2016101134=82952=2016052512460505835520060=201605251246050583552005799=10000100268=1279=1269=148=17359555=6SZ683=356070270=10220.0271=4346=21023=710=098
1128=99=18135=X49=SAMPLE75=2016101134=469552=2015030301052815784467260=201503030105281578446725799=10000100268=1279=1269=048=17359555=6SZ683=356071270=10205.0271=21346=71023=810=114
1128=99=18135=X49=SAMPLE75=2016101134=314752=2003120120060406702505660=200312012006040670250565799=10000100268=1279=1269=048=17359555=6SZ683=356072270=10208.0271=40346=61023=510=144
1128=99=18135=X49=SAMPLE75=2016101134=224552=2007041505114856876550460=200704150511485687655045799=10000100268=1279=1269=148=17359555=6SZ683=356073270=10220.0271=34346=31023=710=154
1128=99=18035=X49=SAMPLE75=2016101134=356852=2006032020380272782524860=200603202038027278252485799=10000100268=1279=1269=048=17359555=6SZ683=356074270=10206.0271=4346=21023=710=092
1128=99=18035=X49=SAMPLE75=2016101134=194652=2002061616011701988748860=200206161601170198874885799=10000100268=1279=1269=148=17359555=6SZ683=356075270=10220.0271=4346=21023=710=110
1128=99=18135=X49=SAMPLE75=2016101134=398452=2008021515425722418928060=200802151542572241892805799=10000100268=1279=1269=048=17359555=6SZ683=356076270=10206.0271=34346=31023=710=166
1128=99=18135=X49=SAMPLE75=2016101134=186852=2017012000043596179910460=201701200004359617991045799=10000100268=1279=1269=148=17359555=6SZ683=356077270=10220.0271=34346=31023=710=130
1128=99=18035=X49=SAMPLE75=2016101134=434952=2005101714142049859078460=200510171414204985907845799=10000100268=1279=1269=048=17359555=6SZ683=356078270=10206.0271=4346=21023=710=105
1128=99=18035=X49=SAMPLE75=2016101134=386652=2016092115012188805062460=201609211501218880506245799=10000100268=1279=1269=148=17359555=6SZ683=356079270=10220.0271=4346=21023=710=103
1128=99=18135=X49=SAMPLE75=2016101134=303752=2005100815504269721824060=200510081550426972182405799=10000100268=1279=1269=148=17359555=6SZ683=356080270=10220.0271=34346=31023=710=172
1128=99=18135=X49=SAMPLE75=2016101134=114752=2003060815200304560137660=200306081520030456013765799=10000100268=1279=1269=048=17359555=6SZ683=356081270=10206.0271=34346=31023=710=150
1128=99=18035=X49=SAMPLE75=2016101134=49552=2000061103541279303787060=200006110354127930378705799=10000100268=1279=1269=148=17359555=6SZ683=356082270=10220.0271=4346=21023=710=072
1128=99=18035=X49=SAMPLE75=2016101134=149052=2015031501500738062764860=201503150150073806276485799=10000100268=1279=1269=048=17359555=6SZ683=356083270=10206.0271=4346=21023=710=084
1128=99=18135=X49=SAMPLE75=2016101134=223552=2015011900015793343347260=201501190001579334334725799=10000100268=1279=1269=148=17359555=6SZ683=356084270=10220.0271=34346=31023=710=153
1128=99=18135=X49=SAMPLE75=2016101134=312752=2008061409572020934956860=200806140957202093495685799=10000100268=1279=1269=048=17359555=6SZ683=356085270=10206.0271=34346=31023=710=168
1128=99=18035=X49=SAMPLE75=2016101134=497152=2003042204272572647923260=200304220427257264792325799=10000100268=1279=1269=148=17359555=6SZ683=356086270=10220.0271=4346=21023=710=075
1128=99=18135=X49=SAMPLE75=2016101134=221552=2011122019082097451110460=201112201908209745111045799=10000100268=1279=1269=148=17359555=6SZ683=356087270=10220.0271=34346=31023=710=173
1128=99=18035=X49=SAMPLE75=2016101134=307452=2010072722483510138771260=201007272248351013877125799=10000100268=1279=1269=048=17359555=6SZ683=356088270=10212.0271=5346=31023=110=105
1128=99=18035=X49=SAMPLE75=2016101134=196352=2010051014215967087507260=201005101421596708750725799=10000100268=1279=1269=048=17359555=6SZ683=356089270=10206.0271=4346=21023=710=112
1128=99=18135=X49=SAMPLE75=2016101134=79052=2010061413432777432608060=201006141343277743260805799=10000100268=1279=1269=048=17359555=6SZ683=356090270=10206.0271=34346=31023=710=188
1128=99=18135=X49=SAMPLE75=2016101134=88652=2003122114141727404136060=200312211414172740413605799=10000100268=1279=1269=048=17359555=6SZ683=356091270=10207.0271=42346=71023=610=145
1128=99=18035=X49=SAMPLE75=2016101134=257352=2000020502011896079616560=200002050201189607961655799=10000100268=1279=1269=048=17359555=6SZ683=356092270=10206.0271=4346=21023=710=101
1128=99=18135=X49=SAMPLE75=2016101134=58552=2016042505155515942598460=201604250515551594259845799=10000100268=1279=1269=048=17359555=6SZ683=356093270=10207.0271=12346=61023=610=173
1128=99=18135=X49=SAMPLE75=2016101134=45452=2011091822020716709958460=201109182202071670995845799=10000100268=1279=1269=048=17359555=6SZ683=356094270=10207.0271=42346=71023=610=160
1128=99=18135=X49=SAMPLE75=2016101134=480452=2011071217083873526784060=201107121708387352678405799=10000100268=1279=1269=148=17359555=6SZ683=356095270=10219.0271=51346=81023=610=146
1128=99=18035=X49=SAMPLE75=2016101134=86952=2016072905455839007584060=201607290545583900758405799=10000100268=1279=1269=148=17359555=6SZ683=356096270=10220.0271=4346=21023=710=106
1128=99=18135=X49=SAMPLE75=2016101134=456652=2005081303491003281782460=200508130349100328178245799=10000100268=1279=1269=148=17359555=6SZ683=356097270=10219.0271=21346=71023=610=176
1128=99=18135=X49=SAMPLE75=2016101134=214852=2014101408175532361708860=201410140817553236170885799=10000100268=1279=1269=148=17359555=6SZ683=356098270=10220.0271=34346=31023=710=177
1128=99=18135=X49=SAMPLE75=2016101134=419252=2003052207102214703803260=200305220710221470380325799=10000100268=1279=1269=048=17359555=6SZ683=356099270=10207.0271=12346=61023=610=188
1128=99=18135=X49=SAMPLE75=2016101134=3752=2007072719580482514403260=200707271958048251440325799=10000100268=1279=1269=048=17359555=6SZ683=356100270=10207.0271=42346=71023=610=116
1128=99=18035=X49=SAMPLE75=2016101134=428852=2000111007575493818813260=200011100757549381881325799=10000100268=1279=1269=148=17359555=6SZ683=356101270=10220.0271=4346=21023=710=076
1128=99=18135=X49=SAMPLE75=2016101134=122352=2006032609581994909168060=200603260958199490916805799=10000100268=1279=1269=148=17359555=6SZ683=356102270=10220.0271=34346=31023=710=138
1128=99=18135=X49=SAMPLE75=2016101134=72852=2010120411093576755961660=201012041109357675596165799=10000100268=1279=1269=048=17359555=6SZ683=356103270=10207.0271=12346=61023=610=137
1128=99=18135=X49=SAMPLE75=2016101134=444752=2011062105304755533568060=201106210530475553356805799=10000100268=1279=1269=048=17359555=6SZ683=356104270=10207.0271=42346=71023=610=150
1128=99=18035=X49=SAMPLE75=2016101134=174952=2010122220044194063424060=201012222004419406342405799=10000100268=1279=1269=148=17359555=6SZ683=356105270=10220.0271=4346=21023=710=086
1128=99=18135=X49=SAMPLE75=2016101134=107552=2004070515274403020011260=200407051527440302001125799=10000100268=1279=1269=148=17359555=6SZ683=356106270=10220.0271=34346=31023=710=156
1128=99=18035=X49=SAMPLE75=2016101134=234152=2004101407210540011315260=200410140721054001131525799=10000100268=1279=1269=148=17359555=6SZ683=356107270=10214.0271=3346=31023=110=055
1128=99=18035=X49=SAMPLE75=2016101134=328352=2004030318390564418752060=200403031839056441875205799=10000100268=1279=1269=148=17359555=6SZ683=356108270=10220.0271=4346=21023=710=083
1128=99=18035=X49=SAMPLE75=2016101134=403552=2016092620390983557440060=201609262039098355744005799=10000100268=1279=1269=048=17359555=6SZ683=356109270=10212.0271=6346=41023=110=063
1128=99=17935=X49=SAMPLE75=2016101134=353252=2015010503180052199468860=201501050318005219946885799=10000100268=1279=0269=048=17360055=6SH783=99123270=10265.0271=3346=11023=110=255
1128=99=24935=X49=SAMPLE75=2016101134=140852=2007020216205077119734460=200702021620507711973445799=10000100268=2279=1269=048=17360055=6SH783=99124270=10264.0271=5346=21023=2279=1269=048=17360055=6SH783=99125270=10262.0271=3346=11023=410=228
1128=99=18135=X49=SAMPLE75=2016101134=81452=2008051614462082340838460=200805161446208234083845799=10000100268=1279=1269=148=17359555=6SZ683=356110270=10220.0271=34346=31023=710=114
1128=99=18135=X49=SAMPLE75=2016101134=24952=2004120706011149550588860=200412070601114955058885799=10000100268=1279=1269=048=17359555=6SZ683=356111270=10207.0271=12346=61023=610=107
1128=99=18135=X49=SAMPLE75=2016101134=228252=2001040223571445124232060=200104022357144512423205799=10000100268=1279=1269=048=17359555=6SZ683=356112270=10207.0271=42346=71023=610=154
1128=99=18035=X49=SAMPLE75=2016101134=9252=2007052310553901022880060=200705231055390102288005799=10000100268=1279=1269=148=17359555=6SZ683=356113270=10220.0271=4346=21023=710=084
1128=99=18135=X49=SAMPLE75=2016101134=452152=2012102613014946037164860=201210261301494603716485799=10000100268=1279=1269=148=17359555=6SZ683=356114270=10219.0271=51346=81023=610=111
1128=99=18135=X49=SAMPLE75=2016101134=138352=2000041815361899083142060=200004181536189908314205799=10000100268=1279=1269=048=17359555=6SZ683=356115270=10207.0271=12346=61023=610=108
1128=99=18135=X49=SAMPLE75=2016101134=293352=2014092303154240409798460=201409230315424040979845799=10000100268=1279=1269=048=17359555=6SZ683=356116270=10207.0271=42346=71023=610=130
1128=99=18135=X49=SAMPLE75=2016101134=32852=2003030309522301244843260=200303030952230124484325799=10000100268=1279=1269=048=17359555=6SZ683=356117270=10207.0271=12346=61023=610=135
1128=99=18135=X49=SAMPLE75=2016101134=332252=2016062301542944167776060=201606230154294416777605799=10000100268=1279=1269=148=17359555=6SZ683=356118270=10219.0271=21346=71023=610=144
1128=99=18135=X49=SAMPLE75=2016101134=470652=2016032523563092356064060=201603252356309235606405799=10000100268=1279=1269=048=17359555=6SZ683=356119270=10207.0271=42346=71023=610=139
1128=99=18135=X49=SAMPLE75=2016101134=163652=2002052306572175744832060=200205230657217574483205799=10000100268=1279=1269=148=17359555=6SZ683=356120270=10220.0271=34346=31023=710=100
1128=99=18135=X49=SAMPLE75=2016101134=309752=2015070519195200277619260=201507051919520027761925799=10000100268=1279=1269=048=17359555=6SZ683=356121270=10207.0271=12346=61023=610=118
1128=99=18135=X49=SAMPLE75=2016101134=54452=2000122214243912807116460=200012221424391280711645799=10000100268=1279=1269=048=17359555=6SZ683=356122270=10207.0271=42346=71023=610=118
1128=99=18135=X49=SAMPLE75=2016101134=118152=2000011413453058264921160=200001141345305826492115799=10000100268=1279=1269=048=17359555=6SZ683=356123270=10207.0271=43346=81023=610=136
1128=99=18035=X49=SAMPLE75=2016101134=290852=2000011402582721280678760=200001140258272128067875799=10000100268=1279=1269=148=17359555=6SZ683=356124270=10220.0271=4346=21023=710=093
1128=99=18135=X49=SAMPLE75=2016101134=53152=2000060903160531437667660=200006090316053143766765799=10000100268=1279=1269=148=17359555=6SZ683=356125270=10219.0271=51346=81023=610=168
1128=99=18135=X49=SAMPLE75=2016101134=327552=2015092010123787108595260=201509201012378710859525799=10000100268=1279=1269=048=17359555=6SZ683=356126270=10207.0271=13346=71023=610=141
1128=99=18135=X49=SAMPLE75=2016101134=148952=2002071916432924964707260=200207191643292496470725799=10000100268=1279=1269=048=17359555=6SZ683=356127270=10207.0271=43346=81023=610=128
1128=99=18135=X49=SAMPLE75=2016101134=487352=2010050904001947074534460=201005090400194707453445799=10000100268=1279=1269=048=17359555=6SZ683=356128270=10207.0271=13346=71023=610=141
1128=99=18135=X49=SAMPLE75=2016101134=463652=2007011613343321351657660=200701161334332135165765799=10000100268=1279=1269=148=17359555=6SZ683=356129270=10219.0271=21346=71023=610=154
1128=99=18135=X49=SAMPLE75=2016101134=14952=2014011912074753677580860=201401191207475367758085799=10000100268=1279=1269=148=17359555=6SZ683=356130270=10219.0271=51346=81023=610=166
1128=99=18135=X49=SAMPLE75=2016101134=74252=2011030511045262480582460=201103051104526248058245799=10000100268=1279=1269=048=17359555=6SZ683=356131270=10207.0271=43346=81023=610=142
1128=99=18135=X49=SAMPLE75=2016101134=203052=2012011111574308161363260=201201111157430816136325799=10000100268=1279=1269=148=17359555=6SZ683=356132270=10219.0271=21346=71023=610=109
1128=99=18135=X49=SAMPLE75=2016101134=134652=2011072907474934079955260=201107290747493407995525799=10000100268=1279=1269=148=17359555=6SZ683=356133270=10219.0271=51346=81023=610=154
1128=99=18135=X49=SAMPLE75=2016101134=108152=2001092613213480221652060=200109261321348022165205799=10000100268=1279=1269=148=17359555=6SZ683=356134270=10219.0271=21346=71023=610=158
1128=99=18135=X49=SAMPLE75=2016101134=215952=2012011112312906984288060=201201111231290698428805799=10000100268=1279=1269=148=17359555=6SZ683=356135270=10219.0271=51346=81023=610=160
1128=99=18135=X49=SAMPLE75=2016101134=293552=2013112322281893770899260=201311232228189377089925799=10000100268=1279=1269=148=17359555=6SZ683=356136270=10215.0271=15346=51023=210=140
1128=99=18135=X49=SAMPLE75=2016101134=153052=2015101417405247589593660=201510141740524758959365799=10000100268=1279=1269=148=17359555=6SZ683=356137270=10215.0271=12346=41023=210=148
1128=99=18135=X49=SAMPLE75=2016101134=413252=2009121208122321080755260=200912120812232108075525799=10000100268=1279=1269=148=17359555=6SZ683=356138270=10219.0271=21346=71023=610=161
1128=99=18035=X49=SAMPLE75=2016101134=429452=2011021604150367822329660=201102160415036782232965799=10000100268=1279=1269=148=17359555=6SZ683=356139270=10215.0271=9346=31023=210=099
1128=99=18035=X49=SAMPLE75=2016101134=400552=2012011612365661527417660=201201161236566152741765799=10000100268=1279=1269=148=17359555=6SZ683=356140270=10215.0271=6346=21023=210=106
1128=99=18035=X49=SAMPLE75=2016101134=351852=2009050823251688720172860=200905082325168872017285799=10000100268=1279=1269=148=17359555=6SZ683=356141270=10215.0271=3346=11023=210=075
1128=99=25235=X49=SAMPLE75=2016101134=245652=2007120410120815866819260=200712041012081586681925799=10000100268=2279=1269=048=17359555=6SZ683=356142270=10212.0271=7346=51023=1279=1269=048=17359555=6SZ683=356143270=10208.0271=39346=51023=510=196
1128=99=18135=X49=SAMPLE75=2016101134=34852=2009031202212145937536060=200903120221214593753605799=10000100268=1279=1269=148=17359555=6SZ683=356144270=10219.0271=51346=81023=610=166
1128=99=18135=X49=SAMPLE75=2016101134=486952=2012071609050603106150460=201207160905060310615045799=10000100268=1279=1269=148=17359555=6SZ683=356145270=10219.0271=21346=71023=610=138
1128=99=18135=X49=SAMPLE75=2016101134=194152=2013121519311839624921660=201312151931183962492165799=10000100268=1279=1269=048=17359555=6SZ683=356146270=10207.0271=13346=71023=610=149
1128=99=18135=X49=SAMPLE75=2016101134=7952=2013112604532687445779260=201311260453268744577925799=10000100268=1279=1269=148=17359555=6SZ683=356147270=10220.0271=34346=31023=710=151
1128=99=18135=X49=SAMPLE75=2016101134=433252=2000030305193587658650660=200003030519358765865065799=10000100268=1279=1269=048=17359555=6SZ683=356148270=10207.0271=43346=81023=610=158
1128=99=18035=X49=SAMPLE75=2016101134=412052=2016070602544929973427260=201607060254492997342725799=10000100268=1279=1269=148=17359555=6SZ683=356149270=10220.0271=4346=21023=710=104
1128=99=18135=X49=SAMPLE75=2016101134=208552=2008080317314778858432060=200808031731477885843205799=10000100268=1279=1269=148=17359555=6SZ683=356150270=10220.0271=34346=31023=710=171
1128=99=18135=X49=SAMPLE75=2016101134=307452=2012110120063796639334460=201211012006379663933445799=10000100268=1279=1269=048=17359555=6SZ683=356151270=10207.0271=13346=71023=610=152
1128=99=18135=X49=SAMPLE75=2016101134=166852=2000040416310024237661660=200004041631002423766165799=10000100268=1279=1269=048=17359555=6SZ683=356152270=10207.0271=43346=81023=610=169
1128=99=18035=X49=SAMPLE75=2016101134=450452=2003080621373559725232060=200308062137355972523205799=10000100268=1279=1269=148=17359555=6SZ683=356153270=10220.0271=4346=21023=710=074
1128=99=18135=X49=SAMPLE75=2016101134=189652=2010010413185686294860860=201001041318568629486085799=10000100268=1279=1269=148=17359555=6SZ683=356154270=10220.0271=34346=31023=710=131
1128=99=18035=X49=SAMPLE75=2016101134=377152=2012121210102078460742460=201212121010207846074245799=10000100268=1279=1269=148=17359555=6SZ683=356155270=10220.0271=4346=21023=710=109
1128=99=18135=X49=SAMPLE75=2016101134=254852=2002052406471075726208060=200205240647107572620805799=10000100268=1279=1269=148=17359555=6SZ683=356156270=10220.0271=34346=31023=710=119
1128=99=18135=X49=SAMPLE75=2016101134=431452=2015050907113601773728060=201505090711360177372805799=10000100268=1279=1269=048=17359555=6SZ683=356157270=10207.0271=13346=71023=610=124
1128=99=18135=X49=SAMPLE75=2016101134=346952=2007052710301337315884860=200705271030133731588485799=10000100268=1279=1269=048=17359555=6SZ683=356158270=10207.0271=43346=81023=610=134
1128=99=18035=X49=SAMPLE75=2016101134=452452=2011041002371234534937660=201104100237123453493765799=10000100268=1279=1269=148=17359555=6SZ683=356159270=10220.0271=4346=21023=710=094
1128=99=18135=X49=SAMPLE75=2016101134=200852=2012030502202298965792060=201203050220229896579205799=10000100268=1279=1269=048=17359555=6SZ683=356160270=10207.0271=13346=71023=610=148
1128=99=18135=X49=SAMPLE75=2016101134=454252=2004070520315663533006460=200407052031566353300645799=10000100268=1279=1269=148=17359555=6SZ683=356161270=10220.0271=34346=31023=710=153
1128=99=18135=X49=SAMPLE75=2016101134=45952=2004070908505795943203260=200407090850579594320325799=10000100268=1279=1269=048=17359555=6SZ683=356162270=10207.0271=43346=81023=610=142
1128=99=18135=X49=SAMPLE75=2016101134=377252=2001030215401305444021660=200103021540130544402165799=10000100268=1279=1269=048=17359555=6SZ683=356163270=10207.0271=13346=71023=610=142
1128=99=18035=X49=SAMPLE75=2016101134=345252=2016052402542833701862460=201605240254283370186245799=10000100268=1279=1269=148=17359555=6SZ683=356164270=10220.0271=4346=21023=710=087
1128=99=18135=X49=SAMPLE75=2016101134=180852=2002111301523218125697660=200211130152321812569765799=10000100268=1279=1269=048=17359555=6SZ683=356165270=10207.0271=43346=81023=610=157
1128=99=18135=X49=SAMPLE75=2016101134=58852=2016082419142884478483260=201608241914288447848325799=10000100268=1279=1269=148=17359555=6SZ683=356166270=10220.0271=34346=31023=710=161
1128=99=18035=X49=SAMPLE75=2016101134=468352=2000040718132691671121760=200004071813269167112175799=10000100268=1279=1269=148=17359555=6SZ683=356167270=10220.0271=4346=21023=710=093
1128=99=18135=X49=SAMPLE75=2016101134=17052=2000121017330105722600460=200012101733010572260045799=10000100268=1279=1269=148=17359555=6SZ683=356168270=10220.0271=34346=31023=710=177
1128=99=18035=X49=SAMPLE75=2016101134=73852=2016031211525724603436860=201603121152572460343685799=10000100268=1279=1269=048=17359555=6SZ683=356169270=10209.0271=7346=31023=410=119
1128=99=18135=X49=SAMPLE75=2016101134=269252=2005031322005472085996860=200503132200547208599685799=10000100268=1279=1269=048=17359555=6SZ683=356170270=10209.0271=10346=41023=410=186
1128=99=18035=X49=SAMPLE75=2016101134=274152=2012012314320155128800060=201201231432015512880005799=10000100268=1279=1269=148=17359555=6SZ683=356171270=10220.0271=4346=21023=710=093
1128=99=18135=X49=SAMPLE75=2016101134=283552=2000051320085683337706460=200005132008568333770645799=10000100268=1279=1269=148=17359555=6SZ683=356172270=10220.0271=34346=31023=710=141
1128=99=18135=X49=SAMPLE75=2016101134=350352=2002122319040328650670460=200212231904032865067045799=10000100268=1279=1269=048=17359555=6SZ683=356173270=10207.0271=13346=71023=610=132
1128=99=18135=X49=SAMPLE75=2016101134=420952=2013112223375239087008060=201311222337523908700805799=10000100268=1279=1269=048=17359555=6SZ683=356174270=10207.0271=43346=81023=610=142
1128=99=18035=X49=SAMPLE75=2016101134=316452=2012042423024796649644860=201204242302479664964485799=10000100268=1279=1269=148=17359555=6SZ683=356175270=10220.0271=4346=21023=710=077
1128=99=18135=X49=SAMPLE75=2016101134=174752=2011042101320269322873660=201104210132026932287365799=10000100268=1279=1269=048=17359555=6SZ683=356176270=10207.0271=13346=71023=610=125
1128=99=18135=X49=SAMPLE75=2016101134=60952=2014021809005636424832060=201402180900563642483205799=10000100268=1279=1269=148=17359555=6SZ683=356177270=10220.0271=34346=31023=710=159
1128=99=18135=X49=SAMPLE75=2016101134=257952=2016102020070016126496060=201610202007001612649605799=10000100268=1279=1269=048=17359555=6SZ683=356178270=10207.0271=43346=81023=610=145
1128=99=18135=X49=SAMPLE75=2016101134=354852=2009100705401565033971260=200910070540156503397125799=10000100268=1279=1269=048=17359555=6SZ683=356179270=10207.0271=13346=71023=610=155
1128=99=18135=X49=SAMPLE75=2016101134=476252=2012040914504740645849660=201204091450474064584965799=10000100268=1279=1269=048=17359555=6SZ683=356180270=10207.0271=43346=81023=610=153
1128=99=18035=X49=SAMPLE75=2016101134=113652=2006022110020913265737660=200602211002091326573765799=10000100268=1279=1269=148=17359555=6SZ683=356181270=10220.0271=4346=21023=710=106
1128=99=18135=X49=SAMPLE75=2016101134=15652=2007021116494653821078460=200702111649465382107845799=10000100268=1279=1269=148=17359555=6SZ683=356182270=10220.0271=34346=31023=710=177
1128=99=18135=X49=SAMPLE75=2016101134=17652=2009032921504825036320060=200903292150482503632005799=10000100268=1279=1269=148=17359555=6SZ683=356183270=10216.0271=13346=51023=310=145
1128=99=18035=X49=SAMPLE75=2016101134=285852=2014042502580422381088060=201404250258042238108805799=10000100268=1279=1269=148=17359555=6SZ683=356184270=10215.0271=4346=21023=210=083
1128=99=18035=X49=SAMPLE75=2016101134=157952=2011031123112632223161660=201103112311263222316165799=10000100268=1279=1269=148=17359555=6SZ683=356185270=10220.0271=4346=21023=710=108
1128=99=18135=X49=SAMPLE75=2016101134=236952=2014012316385810466617660=201401231638581046661765799=10000100268=1279=1269=148=17359555=6SZ683=356186270=10220.0271=34346=31023=710=148
1128=99=18035=X49=SAMPLE75=2016101134=23252=2015060910445216114457660=201506091044521611445765799=10000100268=1279=1269=148=17359555=6SZ683=356187270=10220.0271=4346=21023=710=084
1128=99=18135=X49=SAMPLE75=2016101134=121152=2013092103140200504659260=201309210314020050465925799=10000100268=1279=1269=148=17359555=6SZ683=356188270=10220.0271=34346=31023=710=167
1128=99=18035=X49=SAMPLE75=2016101134=2652=2010010100565930051891260=201001010056593005189125799=10000100268=1279=1269=148=17359555=6SZ683=356189270=10220.0271=4346=21023=710=112
1128=99=18135=X49=SAMPLE75=2016101134=165752=2014082915035253463200060=201408291503525346320005799=10000100268=1279=1269=148=17359555=6SZ683=356190270=10220.0271=34346=31023=710=146
1128=99=18135=X49=SAMPLE75=2016101134=149452=2007052907311182021561660=200705290731118202156165799=10000100268=1279=1269=048=17359555=6SZ683=356191270=10207.0271=13346=71023=610=151
1128=99=18035=X49=SAMPLE75=2016101134=132952=2002102519031608557260860=200210251903160855726085799=10000100268=1279=1269=148=17359555=6SZ683=356192270=10220.0271=4346=21023=710=101
1128=99=18135=X49=SAMPLE75=2016101134=186652=2015040410271403843936060=201504041027140384393605799=10000100268=1279=1269=048=17359555=6SZ683=356193270=10207.0271=43346=81023=610=179
1128=99=18135=X49=SAMPLE75=2016101134=41752=2005032303011083523523260=200503230301108352352325799=10000100268=1279=1269=148=17359555=6SZ683=356194270=10220.0271=34346=31023=710=164
1128=99=18035=X49=SAMPLE75=2016101134=172852=2004081522015183198995260=200408152201518319899525799=10000100268=1279=1269=148=17359555=6SZ683=356195270=10220.0271=4346=21023=710=106
1128=99=18135=X49=SAMPLE75=2016101134=426452=2001120910125843814397660=200112091012584381439765799=10000100268=1279=1269=048=17359555=6SZ683=356196270=10207.0271=13346=71023=610=174
1128=99=18135=X49=SAMPLE75=2016101134=112152=2012111302284061605990460=201211130228406160599045799=10000100268=1279=1269=148=17359555=6SZ683=356197270=10220.0271=34346=31023=710=195
1128=99=18135=X49=SAMPLE75=2016101134=202552=2010030517223021268268860=201003051722302126826885799=10000100268=1279=1269=048=17359555=6SZ683=356198270=10207.0271=43346=81023=610=205
1128=99=18135=X49=SAMPLE75=2016101134=312652=2000051516101070331448660=200005151610107033144865799=10000100268=1279=1269=048=17359555=6SZ683=356199270=10207.0271=13346=71023=610=171
1128=99=18135=X49=SAMPLE75=2016101134=409852=2000062118361610312361460=200006211836161031236145799=10000100268=1279=1269=048=17359555=6SZ683=356200270=10207.0271=43346=81023=610=154
1128=99=18135=X49=SAMPLE75=2016101134=466752=2012120701560552832486460=201212070156055283248645799=10000100268=1279=1269=048=17359555=6SZ683=356201270=10207.0271=13346=71023=610=135
1128=99=18135=X49=SAMPLE75=2016101134=317252=2009122721393215199609660=200912272139321519960965799=10000100268=1279=1269=048=17359555=6SZ683=356202270=10207.0271=43346=81023=610=134
1128=99=18035=X49=SAMPLE75=2016101134=1552=2003082419575761775011260=200308241957576177501125799=10000100268=1279=1269=148=17359555=6SZ683=356203270=10220.0271=4346=21023=710=091
1128=99=18135=X49=SAMPLE75=2016101134=169452=2011062001032461844364860=201106200103246184436485799=10000100268=1279=1269=048=17359555=6SZ683=356204270=10207.0271=13346=71023=610=125
1128=99=18135=X49=SAMPLE75=2016101134=343752=2003112018192109269635260=200311201819210926963525799=10000100268=1279=1269=148=17359555=6SZ683=356205270=10220.0271=34346=31023=710=145
1128=99=18135=X49=SAMPLE75=2016101134=247452=2007101103221050673459260=200710110322105067345925799=10000100268=1279=1269=048=17359555=6SZ683=356206270=10207.0271=43346=81023=610=146
1128=99=18135=X49=SAMPLE75=2016101134=952=2000070106205894112500460=200007010620589411250045799=10000100268=1279=1269=048=17359555=6SZ683=356207270=10207.0271=13346=71023=610=156
1128=99=18035=X49=SAMPLE75=2016101134=462252=2010053107494272523180860=201005310749427252318085799=10000100268=1279=1269=148=17359555=6SZ683=356208270=10220.0271=4346=21023=710=092
1128=99=18135=X49=SAMPLE75=2016101134=437752=2000050702274973446183260=200005070227497344618325799=10000100268=1279=1269=048=17359555=6SZ683=356209270=10207.0271=43346=81023=610=146
1128=99=18135=X49=SAMPLE75=2016101134=295252=2004051205215842818609660=200405120521584281860965799=10000100268=1279=1269=148=17359555=6SZ683=356210270=10220.0271=34346=31023=710=140
1128=99=18135=X49=SAMPLE75=2016101134=424652=2008042219112153813161660=200804221911215381316165799=10000100268=1279=1269=048=17359555=6SZ683=356211270=10207.0271=13346=71023=610=126
1128=99=18135=X49=SAMPLE75=2016101134=353852=2010060406572818132544060=201006040657281813254405799=10000100268=1279=1269=048=17359555=6SZ683=356212270=10207.0271=43346=81023=610=172
1128=99=18035=X49=SAMPLE75=2016101134=34352=2016120101412869644819260=201612010141286964481925799=10000100268=1279=1269=148=17359555=6SZ683=356213270=10220.0271=4346=21023=710=092
1128=99=18135=X49=SAMPLE75=2016101134=273052=2010112623315384595251260=201011262331538459525125799=10000100268=1279=1269=148=17359555=6SZ683=356214270=10220.0271=34346=31023=710=172
1128=99=18035=X49=SAMPLE75=2016101134=353152=2010110314162616423648060=201011031416261642364805799=10000100268=1279=1269=148=17359555=6SZ683=356215270=10220.0271=4346=21023=710=129
1128=99=18135=X49=SAMPLE75=2016101134=382052=2009031712174209203475260=200903171217420920347525799=10000100268=1279=1269=148=17359555=6SZ683=356216270=10220.0271=34346=31023=710=148
1128=99=18035=X49=SAMPLE75=2016101134=8552=2006072815051471541123260=200607281505147154112325799=10000100268=1279=1269=148=17359555=6SZ683=356217270=10220.0271=4346=21023=710=098
1128=99=18135=X49=SAMPLE75=2016101134=401152=2008093006101825153686460=200809300610182515368645799=10000100268=1279=1269=048=17359555=6SZ683=356218270=10207.0271=13346=71023=610=146
1128=99=18135=X49=SAMPLE75=2016101134=143952=2008111709075129617017660=200811170907512961701765799=10000100268=1279=1269=148=17359555=6SZ683=356219270=10220.0271=34346=31023=710=156
1128=99=18135=X49=SAMPLE75=2016101134=197052=2014101701302584951366460=201410170130258495136645799=10000100268=1279=1269=048=17359555=6SZ683=356220270=10207.0271=43346=81023=610=164
1128=99=18035=X49=SAMPLE75=2016101134=319152=2013072405271250978188860=201307240527125097818885799=10000100268=1279=1269=148=17359555=6SZ683=356221270=10220.0271=4346=21023=710=106
1128=99=18135=X49=SAMPLE75=2016101134=439752=2006091720462877415481660=200609172046287741548165799=10000100268=1279=1269=148=17359555=6SZ683=356222270=10220.0271=34346=31023=710=178
1128=99=25235=X49=SAMPLE75=2016101134=144152=2008092421582433952172860=200809242158243395217285799=10000100268=2279=1269=048=17359555=6SZ683=356223270=10210.0271=5346=31023=3279=1269=048=17359555=6SZ683=356224270=10209.0271=11346=51023=410=173
1128=99=18035=X49=SAMPLE75=2016101134=298552=2016100504083251937587260=201610050408325193758725799=10000100268=1279=1269=148=17359555=6SZ683=356225270=10220.0271=4346=21023=710=085
1128=99=18135=X49=SAMPLE75=2016101134=369652=2012021602462223029625660=201202160246222302962565799=10000100268=1279=1269=048=17359555=6SZ683=356226270=10207.0271=13346=71023=610=150
1128=99=18135=X49=SAMPLE75=2016101134=299652=2012071313191164410931260=201207131319116441093125799=10000100268=1279=1269=148=17359555=6SZ683=356227270=10220.0271=34346=31023=710=145
1128=99=18035=X49=SAMPLE75=2016101134=496752=2008102515053632259161660=200810251505363225916165799=10000100268=1279=1269=148=17359555=6SZ683=356228270=10220.0271=4346=21023=710=105
1128=99=18135=X49=SAMPLE75=2016101134=206352=2001050205335574636187260=200105020533557463618725799=10000100268=1279=1269=048=17359555=6SZ683=356229270=10207.0271=43346=81023=610=147
1128=99=18135=X49=SAMPLE75=2016101134=46352=2004081311302170435827260=200408131130217043582725799=10000100268=1279=1269=148=17359555=6SZ683=356230270=10220.0271=34346=31023=710=135
1128=99=18035=X49=SAMPLE75=2016101134=32352=2014100311452598876908860=201410031145259887690885799=10000100268=1279=1269=148=17359555=6SZ683=356231270=10220.0271=4346=21023=710=058
1128=99=18135=X49=SAMPLE75=2016101134=91552=2012022710544525645638460=201202271054452564563845799=10000100268=1279=1269=148=17359555=6SZ683=356232270=10220.0271=34346=31023=710=129
1128=99=18035=X49=SAMPLE75=2016101134=396952=2016061603133106470246460=201606160313310647024645799=10000100268=1279=1269=148=17359555=6SZ683=356233270=10220.0271=4346=21023=710=072
1128=99=18135=X49=SAMPLE75=2016101134=308652=2015112523395049020428860=201511252339504902042885799=10000100268=1279=1269=148=17359555=6SZ683=356234270=10220.0271=34346=31023=710=146
1128=99=18035=X49=SAMPLE75=2016101134=20852=2004020716382607671430460=200402071638260767143045799=10000100268=1279=1269=148=17359555=6SZ683=356235270=10220.0271=4346=21023=710=082
1128=99=18135=X49=SAMPLE75=2016101134=43152=2007080813064770920422460=200708081306477092042245799=10000100268=1279=1269=148=17359555=6SZ683=356236270=10221.0271=42346=51023=810=153
1128=99=18135=X49=SAMPLE75=2016101134=332152=2014062500335393980153660=201406250033539398015365799=10000100268=1279=1269=148=17359555=6SZ683=356237270=10221.0271=12346=41023=810=126
1128=99=18135=X49=SAMPLE75=2016101134=114652=2003021314543338187483260=200302131454333818748325799=10000100268=1279=1269=048=17359555=6SZ683=356238270=10207.0271=13346=71023=610=141
1128=99=18135=X49=SAMPLE75=2016101134=436852=2016072003340402705740860=201607200334040270574085799=10000100268=1279=1269=148=17359555=6SZ683=356239270=10220.0271=34346=31023=710=130
1128=99=18135=X49=SAMPLE75=2016101134=30752=2014051719115138324422460=201405171911513832442245799=10000100268=1279=1269=048=17359555=6SZ683=356240270=10207.0271=43346=81023=610=125
1128=99=18135=X49=SAMPLE75=2016101134=380652=2012010123314114394112060=201201012331411439411205799=10000100268=1279=1269=048=17359555=6SZ683=356241270=10207.0271=13346=71023=610=144
1128=99=18035=X49=SAMPLE75=2016101134=360952=2009110807514734225222460=200911080751473422522245799=10000100268=1279=1269=148=17359555=6SZ683=356242270=10220.0271=4346=21023=710=081
1128=99=18135=X49=SAMPLE75=2016101134=197752=2015060517212875151046460=201506051721287515104645799=10000100268=1279=1269=048=17359555=6SZ683=356243270=10207.0271=43346=81023=610=152
1128=99=18135=X49=SAMPLE75=2016101134=133552=2009091806330668494796860=200909180633066849479685799=10000100268=1279=1269=148=17359555=6SZ683=356244270=10221.0271=42346=51023=810=126
1128=99=18135=X49=SAMPLE75=2016101134=92752=2004041911224740559289660=200404191122474055928965799=10000100268=1279=1269=048=17359555=6SZ683=356245270=10207.0271=13346=71023=610=132
1128=99=18135=X49=SAMPLE75=2016101134=233152=2000100417581089397524060=200010041758108939752405799=10000100268=1279=1269=148=17359555=6SZ683=356246270=10221.0271=12346=41023=810=120
1128=99=18135=X49=SAMPLE75=2016101134=158052=2004042411550777661176060=200404241155077766117605799=10000100268=1279=1269=148=17359555=6SZ683=356247270=10220.0271=34346=31023=710=128
1128=99=18135=X49=SAMPLE75=2016101134=115252=2010062710542254572614460=201006271054225457261445799=10000100268=1279=1269=048=17359555=6SZ683=356248270=10207.0271=43346=81023=610=137
1128=99=18135=X49=SAMPLE75=2016101134=339052=2009092403424735418233660=200909240342473541823365799=10000100268=1279=1269=048=17359555=6SZ683=356249270=10207.0271=13346=71023=610=145
1128=99=18035=X49=SAMPLE75=2016101134=489152=2011090807394253605299260=201109080739425360529925799=10000100268=1279=1269=148=17359555=6SZ683=356250270=10220.0271=4346=21023=710=078
1128=99=18135=X49=SAMPLE75=2016101134=95752=2006110305035790636326460=200611030503579063632645799=10000100268=1279=1269=048=17359555=6SZ683=356251270=10207.0271=43346=81023=610=128
1128=99=18135=X49=SAMPLE75=2016101134=110552=2004042415511654551075260=200404241551165455107525799=10000100268=1279=1269=148=17359555=6SZ683=356252270=10220.0271=34346=31023=710=120
1128=99=18035=X49=SAMPLE75=2016101134=445852=2008030502303420686640060=200803050230342068664005799=10000100268=1279=1269=148=17359555=6SZ683=356253270=10220.0271=4346=21023=710=055
1128=99=18135=X49=SAMPLE75=2016101134=311652=2003063009224480258603260=200306300922448025860325799=10000100268=1279=1269=148=17359555=6SZ683=356254270=10220.0271=34346=31023=710=158
1128=99=18135=X49=SAMPLE75=2016101134=489452=2017031113051503293984060=201703111305150329398405799=10000100268=1279=1269=048=17359555=6SZ683=356255270=10207.0271=13346=71023=610=148
1128=99=18035=X49=SAMPLE75=2016101134=340252=2003060514111831466715260=200306051411183146671525799=10000100268=1279=1269=148=17359555=6SZ683=356256270=10220.0271=4346=21023=710=110
1128=99=18135=X49=SAMPLE75=2016101134=70452=2004011001124322396825660=200401100112432239682565799=10000100268=1279=1269=048=17359555=6SZ683=356257270=10207.0271=43346=81023=610=158
1128=99=18135=X49=SAMPLE75=2016101134=291852=2006040116325435887129660=200604011632543588712965799=10000100268=1279=1269=148=17359555=6SZ683=356258270=10220.0271=34346=31023=710=176
1128=99=18135=X49=SAMPLE75=2016101134=33952=2000082904574588817020460=200008290457458881702045799=10000100268=1279=1269=048=17359555=6SZ683=356259270=10207.0271=13346=71023=610=137
1128=99=18035=X49=SAMPLE75=2016101134=215152=2013021008543113209894460=201302100854311320989445799=10000100268=1279=1269=148=17359555=6SZ683=356260270=10220.0271=4346=21023=710=051
1128=99=18135=X49=SAMPLE75=2016101134=255452=2015123023220819597824060=201512302322081959782405799=10000100268=1279=1269=048=17359555=6SZ683=356261270=10207.0271=43346=81023=610=139
1128=99=18135=X49=SAMPLE75=2016101134=85152=2009012520362172427670460=200901252036217242767045799=10000100268=1279=1269=148=17359555=6SZ683=356262270=10220.0271=34346=31023=710=129
1128=99=18135=X49=SAMPLE75=2016101134=7152=2009081714294275679763260=200908171429427567976325799=10000100268=1279=1269=048=17359555=6SZ683=356263270=10207.0271=13346=71023=610=147
1128=99=18035=X49=SAMPLE75=2016101134=261752=2016111111030177636902460=201611111103017763690245799=10000100268=1279=1269=148=17359555=6SZ683=356264270=10220.0271=4346=21023=710=110
1128=99=18135=X49=SAMPLE75=2016101134=406052=2008092413412154120380860=200809241341215412038085799=10000100268=1279=1269=048=17359555=6SZ683=356265270=10207.0271=43346=81023=610=161
1128=99=18135=X49=SAMPLE75=2016101134=70752=2017020622561656133651260=201702062256165613365125799=10000100268=1279=1269=148=17359555=6SZ683=356266270=10220.0271=34346=31023=710=131
1128=99=18135=X49=SAMPLE75=2016101134=78052=2003060723321087179878460=200306072332108717987845799=10000100268=1279=1269=048=17359555=6SZ683=356267270=10207.0271=13346=71023=610=139
1128=99=18135=X49=SAMPLE75=2016101134=480252=2004011301461700890457660=200401130146170089045765799=10000100268=1279=1269=048=17359555=6SZ683=356268270=10207.0271=43346=81023=610=150
1128=99=18035=X49=SAMPLE75=2016101134=415152=2016112815453265295449660=201611281545326529544965799=10000100268=1279=1269=148=17359555=6SZ683=356269270=10220.0271=4346=21023=710=093
1128=99=18135=X49=SAMPLE75=2016101134=115252=2005053115132031928579260=200505311513203192857925799=10000100268=1279=1269=048=17359555=6SZ683=356270270=10207.0271=13346=71023=610=127
1128=99=18135=X49=SAMPLE75=2016101134=341652=2015051115015589476326460=201505111501558947632645799=10000100268=1279=1269=148=17359555=6SZ683=356271270=10220.0271=34346=31023=710=142
1128=99=18135=X49=SAMPLE75=2016101134=446052=2016040414543771510681660=201604041454377151068165799=10000100268=1279=1269=048=17359555=6SZ683=356272270=10207.0271=43346=81023=610=142
1128=99=18135=X49=SAMPLE75=2016101134=452352=2001052905290335651878460=200105290529033565187845799=10000100268=1279=1269=048=17359555=6SZ683=356273270=10207.0271=13346=71023=610=139
1128=99=18035=X49=SAMPLE75=2016101134=137452=2013072520252444850137660=201307252025244485013765799=10000100268=1279=1269=148=17359555=6SZ683=356274270=10220.0271=4346=21023=710=100
1128=99=18135=X49=SAMPLE75=2016101134=274552=2010110208063092312710460=201011020806309231271045799=10000100268=1279=1269=048=17359555=6SZ683=356275270=10207.0271=43346=81023=610=152
1128=99=18135=X49=SAMPLE75=2016101134=476752=2010080721102346018323260=201008072110234601832325799=10000100268=1279=1269=148=17359555=6SZ683=356276270=10220.0271=34346=31023=710=124
1128=99=18135=X49=SAMPLE75=2016101134=195852=2006092204461470167680060=200609220446147016768005799=10000100268=1279=1269=048=17359555=6SZ683=356277270=10207.0271=13346=71023=610=144
1128=99=18035=X49=SAMPLE75=2016101134=426752=2010101100241359814297660=201010110024135981429765799=10000100268=1279=1269=148=17359555=6SZ683=356278270=10220.0271=4346=21023=710=092
1128=99=18135=X49=SAMPLE75=2016101134=292852=2003020300293387561990460=200302030029338756199045799=10000100268=1279=1269=048=17359555=6SZ683=356279270=10207.0271=43346=81023=610=161
1128=99=18135=X49=SAMPLE75=2016101134=172852=2011032302000763507987260=201103230200076350798725799=10000100268=1279=1269=148=17359555=6SZ683=356280270=10220.0271=34346=31023=710=139
1128=99=18035=X49=SAMPLE75=2016101134=106652=2002101820595227395046460=200210182059522739504645799=10000100268=1279=1269=148=17359555=6SZ683=356281270=10220.0271=4346=21023=710=105
1128=99=18135=X49=SAMPLE75=2016101134=428052=2013091419185215578073660=201309141918521557807365799=10000100268=1279=1269=148=17359555=6SZ683=356282270=10220.0271=34346=31023=710=172
1128=99=18135=X49=SAMPLE75=2016101134=319952=2007091511044406526019260=200709151104440652601925799=10000100268=1279=1269=048=17359555=6SZ683=356283270=10207.0271=13346=71023=610=139
1128=99=18035=X49=SAMPLE75=2016101134=287052=2006041719031421458348860=200604171903142145834885799=10000100268=1279=1269=148=17359555=6SZ683=356284270=10220.0271=4346=21023=710=124
1128=99=18135=X49=SAMPLE75=2016101134=415252=2004033016534358580662460=200403301653435858066245799=10000100268=1279=1269=048=17359555=6SZ683=356285270=10207.0271=43346=81023=610=179
1128=99=18135=X49=SAMPLE75=2016101134=185052=2015041618413613843040060=201504161841361384304005799=10000100268=1279=1269=148=17359555=6SZ683=356286270=10220.0271=34346=31023=710=180
1128=99=18035=X49=SAMPLE75=2016101134=33252=2005012615485796730016060=200501261548579673001605799=10000100268=1279=1269=148=17359555=6SZ683=356287270=10220.0271=4346=21023=710=098
1128=99=18135=X49=SAMPLE75=2016101134=348252=2012022817012112453177660=201202281701211245317765799=10000100268=1279=1269=148=17359555=6SZ683=356288270=10220.0271=34346=31023=710=164
1128=99=18035=X49=SAMPLE75=2016101134=452152=2016062723412557208576060=201606272341255720857605799=10000100268=1279=1269=148=17359555=6SZ683=356289270=10220.0271=4346=21023=710=095
1128=99=18135=X49=SAMPLE75=2016101134=151152=2004052002513298541803260=200405200251329854180325799=10000100268=1279=1269=048=17359555=6SZ683=356290270=10207.0271=13346=71023=610=154
1128=99=18135=X49=SAMPLE75=2016101134=22552=2014032811333080141049660=201403281133308014104965799=10000100268=1279=1269=148=17359555=6SZ683=356291270=10220.0271=34346=31023=710=140
1128=99=18135=X49=SAMPLE75=2016101134=322552=2004021017571399073675260=200402101757139907367525799=10000100268=1279=1269=048=17359555=6SZ683=356292270=10207.0271=43346=81023=610=158
1128=99=18035=X49=SAMPLE75=2016101134=459152=2002121816324347273788860=200212181632434727378885799=10000100268=1279=1269=148=17359555=6SZ683=356293270=10220.0271=4346=21023=710=086
1128=99=18135=X49=SAMPLE75=2016101134=105952=2013121917035290747814460=201312191703529074781445799=10000100268=1279=1269=148=17359555=6SZ683=356294270=10220.0271=34346=31023=710=163
1128=99=18035=X49=SAMPLE75=2016101134=332452=2003073106550012927484860=200307310655001292748485799=10000100268=1279=1269=148=17359555=6SZ683=356295270=10220.0271=4346=21023=710=079
1128=99=18135=X49=SAMPLE75=2016101134=425752=2003030915372171592987260=200303091537217159298725799=10000100268=1279=1269=048=17359555=6SZ683=356296270=10207.0271=13346=71023=610=145
1128=99=18135=X49=SAMPLE75=2016101134=143152=2006020705385448964009660=200602070538544896400965799=10000100268=1279=1269=148=17359555=6SZ683=356297270=10220.0271=34346=31023=710=150
1128=99=18135=X49=SAMPLE75=2016101134=399152=2008081716290143956355260=200808171629014395635525799=10000100268=1279=1269=048=17359555=6SZ683=356298270=10207.0271=43346=81023=610=163
1128=99=18135=X49=SAMPLE75=2016101134=60852=2005082309502634864617660=200508230950263486461765799=10000100268=1279=1269=048=17359555=6SZ683=356299270=10207.0271=13346=71023=610=153
1128=99=18035=X49=SAMPLE75=2016101134=104052=2006060204251969628512060=200606020425196962851205799=10000100268=1279=1269=148=17359555=6SZ683=356300270=10220.0271=4346=21023=710=088
1128=99=18135=X49=SAMPLE75=2016101134=253752=2011071319111919591667260=201107131911191959166725799=10000100268=1279=1269=048=17359555=6SZ683=356301270=10207.0271=43346=81023=610=150
1128=99=18135=X49=SAMPLE75=2016101134=338352=2001011114303188017004060=200101111430318801700405799=10000100268=1279=1269=148=17359555=6SZ683=356302270=10220.0271=34346=31023=710=164
1128=99=18135=X49=SAMPLE75=2016101134=202752=2014120910085281641555260=201412091008528164155525799=10000100268=1279=1269=048=17359555=6SZ683=356303270=10207.0271=13346=71023=610=164
1128=99=18035=X49=SAMPLE75=2016101134=76852=2011091910024258016179260=201109191002425801617925799=10000100268=1279=1269=148=17359555=6SZ683=356304270=10220.0271=4346=21023=710=094
1128=99=18135=X49=SAMPLE75=2016101134=261752=2000091703381277512226860=200009170338127751222685799=10000100268=1279=1269=048=17359555=6SZ683=356305270=10207.0271=43346=81023=610=164
1128=99=18135=X49=SAMPLE75=2016101134=292852=2000062900475096322887860=200006290047509632288785799=10000100268=1279=1269=148=17359555=6SZ683=356306270=10220.0271=34346=31023=710=144
1128=99=18135=X49=SAMPLE75=2016101134=118852=2010012118085149940000060=201001211808514994000005799=10000100268=1279=1269=048=17359555=6SZ683=356307270=10207.0271=13346=71023=610=144
1128=99=18035=X49=SAMPLE75=2016101134=417652=2003081411143782512436860=200308141114378251243685799=10000100268=1279=1269=148=17359555=6SZ683=356308270=10220.0271=4346=21023=710=093
1128=99=18135=X49=SAMPLE75=2016101134=350552=2014122001254659236153660=201412200125465923615365799=10000100268=1279=1269=048=17359555=6SZ683=356309270=10207.0271=43346=81023=610=166
1128=99=18135=X49=SAMPLE75=2016101134=381652=2007041807473106020774460=200704180747310602077445799=10000100268=1279=1269=148=17359555=6SZ683=356310270=10220.0271=34346=31023=710=146
1128=99=18035=X49=SAMPLE75=2016101134=52452=2015080302454041596294460=201508030245404159629445799=10000100268=1279=1269=148=17359555=6SZ683=356311270=10220.0271=4346=21023=710=118
1128=99=18135=X49=SAMPLE75=2016101134=331952=2014070400120168585139260=201407040012016858513925799=10000100268=1279=1269=048=17359555=6SZ683=356312270=10207.0271=13346=71023=610=158
1128=99=18135=X49=SAMPLE75=2016101134=3152=2003080217414773592830460=200308021741477359283045799=10000100268=1279=1269=148=17359555=6SZ683=356313270=10220.0271=34346=31023=710=174
1128=99=18135=X49=SAMPLE75=2016101134=358352=2011120201383609059027260=201112020138360905902725799=10000100268=1279=1269=048=17359555=6SZ683=356314270=10207.0271=43346=81023=610=177
1128=99=18035=X49=SAMPLE75=2016101134=392052=2011052601154460082592060=201105260115446008259205799=10000100268=1279=1269=148=17359555=6SZ683=356315270=10220.0271=4346=21023=710=092
1128=99=18135=X49=SAMPLE75=2016101134=247852=2007122715313731407292860=200712271531373140729285799=10000100268=1279=1269=048=17359555=6SZ683=356316270=10207.0271=13346=71023=610=155
1128=99=18135=X49=SAMPLE75=2016101134=147652=2006062716103142734620860=200606271610314273462085799=10000100268=1279=1269=148=17359555=6SZ683=356317270=10220.0271=34346=31023=710=136
1128=99=18135=X49=SAMPLE75=2016101134=480152=2001082419504642104971260=200108241950464210497125799=10000100268=1279=1269=048=17359555=6SZ683=356318270=10207.0271=43346=81023=610=151
1128=99=18035=X49=SAMPLE75=2016101134=273252=2004020516513645700120060=200402051651364570012005799=10000100268=1279=1269=148=17359555=6SZ683=356319270=10220.0271=4346=21023=710=114
1128=99=18135=X49=SAMPLE75=2016101134=439452=2000092217292518184012060=200009221729251818401205799=10000100268=1279=1269=048=17359555=6SZ683=356320270=10207.0271=13346=71023=610=150
1128=99=18135=X49=SAMPLE75=2016101134=260452=2012061901033079314880060=201206190103307931488005799=10000100268=1279=1269=148=17359555=6SZ683=356321270=10220.0271=34346=31023=710=143
1128=99=18135=X49=SAMPLE75=2016101134=358852=2008081815530879213804860=200808181553087921380485799=10000100268=1279=1269=048=17359555=6SZ683=356322270=10207.0271=43346=81023=610=151
1128=99=18035=X49=SAMPLE75=2016101134=78952=2014120901045891990003260=201412090104589199000325799=10000100268=1279=1269=148=17359555=6SZ683=356323270=10220.0271=4346=21023=710=110
1128=99=18135=X49=SAMPLE75=2016101134=101452=2000072713083898651235660=200007271308389865123565799=10000100268=1279=1269=048=17359555=6SZ683=356324270=10207.0271=13346=71023=610=161
1128=99=18135=X49=SAMPLE75=2016101134=369452=2015112723525779152352060=201511272352577915235205799=10000100268=1279=1269=148=17359555=6SZ683=356325270=10220.0271=34346=31023=710=160
1128=99=18135=X49=SAMPLE75=2016101134=452052=2006122510405963811286460=200612251040596381128645799=10000100268=1279=1269=048=17359555=6SZ683=356326270=10207.0271=43346=81023=610=181
1128=99=18035=X49=SAMPLE75=2016101134=128452=2012070221062010286073660=201207022106201028607365799=10000100268=1279=1269=148=17359555=6SZ683=356327270=10220.0271=4346=21023=710=077
1128=99=18135=X49=SAMPLE75=2016101134=435252=2005041809191028762710460=200504180919102876271045799=10000100268=1279=1269=048=17359555=6SZ683=356328270=10207.0271=13346=71023=610=150
1128=99=18135=X49=SAMPLE75=2016101134=366252=2011112418293926338707260=201111241829392633870725799=10000100268=1279=1269=148=17359555=6SZ683=356329270=10220.0271=34346=31023=710=171
1128=99=18135=X49=SAMPLE75=2016101134=452852=2002082705211963397713660=200208270521196339771365799=10000100268=1279=1269=048=17359555=6SZ683=356330270=10207.0271=43346=81023=610=145
1128=99=18135=X49=SAMPLE75=2016101134=204252=2005120204155319951136060=200512020415531995113605799=10000100268=1279=1269=048=17359555=6SZ683=356331270=10207.0271=13346=71023=610=162
1128=99=18135=X49=SAMPLE75=2016101134=20252=2004052821244589889206460=200405282124458988920645799=10000100268=1279=1269=048=17359555=6SZ683=356332270=10207.0271=43346=81023=610=143
1128=99=18035=X49=SAMPLE75=2016101134=451152=2012092504533564617715260=201209250453356461771525799=10000100268=1279=0269=148=17359555=6SZ683=356333270=10213.0271=2346=11023=110=104
1128=99=17935=X49=SAMPLE75=2016101134=353152=2016051701563146603769660=201605170156314660376965799=10000100268=1279=0269=148=17360055=6SH783=99126270=10269.0271=3346=11023=110=048
1128=99=17935=X49=SAMPLE75=2016101134=429752=2002091513041507981320060=200209151304150798132005799=10000100268=1279=0269=148=17360055=6SH783=99127270=10270.0271=3346=11023=210=057
1128=99=20835=X49=SAMPLE75=2016101134=426252=2001061802494109303036060=200106180249410930303605799=00000001268=1279=0269=248=17359555=6SZ683=356334270=10213.0271=2346=25797=137705=237=032=237=032=210=083
1128=99=15635=X49=SAMPLE75=2016101134=35052=2016061601080349388166460=201606160108034938816645799=00000010268=1279=0269=e48=17359555=6SZ683=356335271=3110=083
1128=99=25235=X49=SAMPLE75=2016101134=496452=2011042913330405663328060=201104291333040566332805799=10000100268=2279=2269=148=17359555=6SZ683=356336270=10213.0271=2346=11023=1279=0269=148=17359555=6SZ683=356337270=10223.0271=9346=31023=1010=186
1128=99=17935=X49=SAMPLE75=2016101134=326552=2002071105331110720395260=200207110533111072039525799=10000100268=1279=0269=048=17360055=6SH783=99128270=10266.0271=3346=11023=110=007
1128=99=25035=X49=SAMPLE75=2016101134=493652=2002011316040069317706460=200201131604006931770645799=10000100268=2279=2269=148=17360055=6SH783=99129270=10269.0271=3346=11023=1279=0269=148=17360055=6SH783=99130270=10279.0271=3346=11023=1010=040
1128=99=25135=X49=SAMPLE75=2016101134=488352=2010101814392465554073660=201010181439246555407365799=10000100268=2279=2269=148=17360055=6SH783=99131270=10270.0271=3346=11023=1279=0269=148=17360055=6SH783=99132270=10280.0271=53346=11023=1010=078
1128=99=25135=X49=SAMPLE75=2016101134=218952=2000070510563690050219860=200007051056369005021985799=10000100268=2279=0269=148=17359555=6SZ683=356338270=10213.0271=1346=11023=1279=1269=148=17359555=6SZ683=356339270=10214.0271=2346=21023=210=126
1128=99=25035=X49=SAMPLE75=2016101134=199552=2005093007135967335945660=200509300713596733594565799=10000100268=2279=2269=048=17360055=6SH783=99133270=10266.0271=3346=11023=1279=0269=048=17360055=6SH783=99134270=10256.0271=3346=11023=1010=016
1128=99=18035=X49=SAMPLE75=2016101134=27352=2004040811524813451249660=200404081152481345124965799=10000100268=1279=1269=148=17359555=6SZ683=356340270=10220.0271=4346=21023=810=107
1128=99=17935=X49=SAMPLE75=2016101134=376952=2001020602511895843544460=200102060251189584354445799=10000100268=1279=0269=148=17360055=6SH783=99135270=10270.0271=3346=11023=110=032
1128=99=18135=X49=SAMPLE75=2016101134=361552=2017010816044459135660860=201701081604445913566085799=10000100268=1279=1269=148=17359555=6SZ683=356341270=10220.0271=34346=31023=810=120
1128=99=18035=X49=SAMPLE75=2016101134=106452=2014082012555433660339260=201408201255543366033925799=10000100268=1279=1269=148=17359555=6SZ683=356342270=10220.0271=4346=21023=810=085
1128=99=18135=X49=SAMPLE75=2016101134=322852=2008062003104313659164860=200806200310431365916485799=10000100268=1279=1269=148=17359555=6SZ683=356343270=10220.0271=34346=31023=810=165
1128=99=18035=X49=SAMPLE75=2016101134=200652=2000111515223057072966060=200011151522305707296605799=10000100268=1279=1269=148=17359555=6SZ683=356344270=10220.0271=4346=21023=810=119
1128=99=18135=X49=SAMPLE75=2016101134=120752=2012021700224424876774460=201202170022442487677445799=10000100268=1279=1269=148=17359555=6SZ683=356345270=10220.0271=34346=31023=810=149
1128=99=18035=X49=SAMPLE75=2016101134=324752=2014100422380984838374460=201410042238098483837445799=10000100268=1279=1269=148=17359555=6SZ683=356346270=10220.0271=4346=21023=810=099
1128=99=18135=X49=SAMPLE75=2016101134=133952=2002072913275464909921660=200207291327546490992165799=10000100268=1279=1269=148=17359555=6SZ683=356347270=10220.0271=34346=31023=810=154
1128=99=18035=X49=SAMPLE75=2016101134=450452=2006122820220136065622460=200612282022013606562245799=10000100268=1279=1269=148=17359555=6SZ683=356348270=10220.0271=4346=21023=810=122
1128=99=18135=X49=SAMPLE75=2016101134=460452=2016100604232574733190460=201610060423257473319045799=10000100268=1279=1269=048=17359555=6SZ683=356349270=10207.0271=13346=71023=610=198
1128=99=18135=X49=SAMPLE75=2016101134=297752=2007052012102811266889660=200705201210281126688965799=10000100268=1279=1269=148=17359555=6SZ683=356350270=10220.0271=34346=31023=810=165
1128=99=18135=X49=SAMPLE75=2016101134=299552=2008010515473947572566460=200801051547394757256645799=10000100268=1279=1269=048=17359555=6SZ683=356351270=10207.0271=43346=81023=610=161
1128=99=18035=X49=SAMPLE75=2016101134=324552=2012020705145551534617660=201202070514555153461765799=10000100268=1279=1269=148=17359555=6SZ683=356352270=10220.0271=4346=21023=810=093
1128=99=18135=X49=SAMPLE75=2016101134=213952=2006042322365994684633660=200604232236599468463365799=10000100268=1279=1269=148=17359555=6SZ683=356353270=10220.0271=34346=31023=810=142
1128=99=18035=X49=SAMPLE75=2016101134=439652=2014082715275426845977660=201408271527542684597765799=10000100268=1279=1269=148=17359555=6SZ683=356354270=10220.0271=4346=21023=810=077
1128=99=18135=X49=SAMPLE75=2016101134=207252=2009121510223454893593660=200912151022345489359365799=10000100268=1279=1269=048=17359555=6SZ683=356355270=10207.0271=13346=71023=610=139
1128=99=18135=X49=SAMPLE75=2016101134=37352=2005031710514875622851260=200503171051487562285125799=10000100268=1279=1269=148=17359555=6SZ683=356356270=10220.0271=34346=31023=810=152
1128=99=18135=X49=SAMPLE75=2016101134=188252=2016020414044804070374460=201602041404480407037445799=10000100268=1279=1269=048=17359555=6SZ683=356357270=10207.0271=43346=81023=610=151
1128=99=18135=X49=SAMPLE75=2016101134=70552=2004101323563884611257660=200410132356388461125765799=10000100268=1279=1269=048=17359555=6SZ683=356358270=10207.0271=13346=71023=610=145
1128=99=18035=X49=SAMPLE75=2016101134=301952=2011043000550143267104060=201104300055014326710405799=10000100268=1279=1269=148=17359555=6SZ683=356359270=10220.0271=4346=21023=810=082
1128=99=18135=X49=SAMPLE75=2016101134=41852=2001040519000960862032060=200104051900096086203205799=10000100268=1279=1269=048=17359555=6SZ683=356360270=10207.0271=43346=81023=610=185
1128=99=18135=X49=SAMPLE75=2016101134=40152=2002042619020480264968060=200204261902048026496805799=10000100268=1279=1269=148=17359555=6SZ683=356361270=10220.0271=34346=31023=810=141
1128=99=18135=X49=SAMPLE75=2016101134=115752=2008062312035623680873660=200806231203562368087365799=10000100268=1279=1269=048=17359555=6SZ683=356362270=10207.0271=13346=71023=610=144
1128=99=18135=X49=SAMPLE75=2016101134=191552=2000061613152551223750860=200006161315255122375085799=10000100268=1279=1269=048=17359555=6SZ683=356363270=10207.0271=43346=81023=610=155
1128=99=18135=X49=SAMPLE75=2016101134=56252=2003051714295782255505660=200305171429578225550565799=10000100268=1279=1269=048=17359555=6SZ683=356364270=10207.0271=13346=71023=610=127
1128=99=18035=X49=SAMPLE75=2016101134=22552=2011012001252579022227260=201101200125257902222725799=10000100268=1279=1269=148=17359555=6SZ683=356365270=10220.0271=4346=21023=810=079
1128=99=18135=X49=SAMPLE75=2016101134=130752=2008100212210509763430460=200810021221050976343045799=10000100268=1279=1269=048=17359555=6SZ683=356366270=10207.0271=43346=81023=610=161
1128=99=18135=X49=SAMPLE75=2016101134=358752=2010031617362371406771260=201003161736237140677125799=10000100268=1279=1269=148=17359555=6SZ683=356367270=10220.0271=34346=31023=810=158
1128=99=18135=X49=SAMPLE75=2016101134=101852=2012070412205248061875260=201207041220524806187525799=10000100268=1279=1269=048=17359555=6SZ683=356368270=10207.0271=13346=71023=610=139
1128=99=18035=X49=SAMPLE75=2016101134=132752=2010032323123801876832060=201003232312380187683205799=10000100268=1279=1269=148=17359555=6SZ683=356369270=10220.0271=4346=21023=810=087
1128=99=18135=X49=SAMPLE75=2016101134=245852=2012022222284658025433660=201202222228465802543365799=10000100268=1279=1269=048=17359555=6SZ683=356370270=10207.0271=43346=81023=610=141
1128=99=18135=X49=SAMPLE75=2016101134=242352=2016072507025276554035260=201607250702527655403525799=10000100268=1279=1269=148=17359555=6SZ683=356371270=10220.0271=34346=31023=810=137
1128=99=18035=X49=SAMPLE75=2016101134=53952=2017022107501855870304060=201702210750185587030405799=10000100268=1279=1269=148=17359555=6SZ683=356372270=10220.0271=4346=21023=810=080
1128=99=18135=X49=SAMPLE75=2016101134=352252=2001120604033552180288860=200112060403355218028885799=10000100268=1279=1269=148=17359555=6SZ683=356373270=10220.0271=34346=31023=810=164
1128=99=20835=X49=SAMPLE75=2016101134=400352=2006122220210738295478460=200612222021073829547845799=00000001268=1279=0269=248=17359555=6SZ683=356374270=10213.0271=1346=25797=137705=237=032=137=032=110=050
1128=99=15635=X49=SAMPLE75=2016101134=68752=2005122914270431639619260=200512291427043163961925799=00000010268=1279=0269=e48=17359555=6SZ683=356375271=3210=069
1128=99=25235=X49=SAMPLE75=2016101134=202852=2004051318580377056457660=200405131858037705645765799=10000100268=2279=2269=148=17359555=6SZ683=356376270=10213.0271=1346=11023=1279=0269=148=17359555=6SZ683=356377270=10223.0271=9346=31023=1010=174
1128=99=17935=X49=SAMPLE75=2016101134=246052=2001062901195490307355260=200106290119549030735525799=10000100268=1279=0269=048=17360055=6SH783=99136270=10266.0271=3346=11023=110=010
1128=99=25135=X49=SAMPLE75=2016101134=361952=2003061004101228592873660=200306100410122859287365799=10000100268=2279=2269=148=17360055=6SH783=99137270=10270.0271=3346=11023=1279=0269=148=17360055=6SH783=99138270=10280.0271=53346=11023=1010=070
1128=99=25235=X49=SAMPLE75=2016101134=451052=2004120308004120301264060=200412030800412030126405799=10000100268=2279=1269=048=17359555=6SZ683=356378270=10210.0271=6346=41023=3279=1269=048=17359555=6SZ683=356379270=10209.0271=10346=41023=410=185
1128=99=18035=X49=SAMPLE75=2016101134=210852=2003053120485266143508860=200305312048526614350885799=10000100268=1279=1269=148=17359555=6SZ683=356380270=10214.0271=3346=31023=110=084
1128=99=18035=X49=SAMPLE75=2016101134=105152=2003030718240240907804860=200303071824024090780485799=10000100268=1279=1269=148=17359555=6SZ683=356381270=10220.0271=4346=21023=710=077
1128=99=25035=X49=SAMPLE75=2016101134=352952=2013071023464675188544060=201307102346467518854405799=10000100268=2279=2269=048=17360055=6SH783=99139270=10266.0271=3346=11023=1279=0269=048=17360055=6SH783=99140270=10256.0271=3346=11023=1010=038
1128=99=18135=X49=SAMPLE75=2016101134=491752=2007051003153777711212860=200705100315377771121285799=10000100268=1279=1269=148=17359555=6SZ683=356382270=10220.0271=34346=31023=710=128
1128=99=18035=X49=SAMPLE75=2016101134=168652=2008081605461406496035260=200808160546140649603525799=10000100268=1279=1269=148=17359555=6SZ683=356383270=10220.0271=4346=21023=710=059
1128=99=18135=X49=SAMPLE75=2016101134=335152=2005082301282644777894460=200508230128264477789445799=10000100268=1279=1269=148=17359555=6SZ683=356384270=10220.0271=34346=31023=710=136
1128=99=18035=X49=SAMPLE75=2016101134=37652=2013082107491726908710460=201308210749172690871045799=10000100268=1279=1269=148=17359555=6SZ683=356385270=10220.0271=4346=21023=710=092
1128=99=18135=X49=SAMPLE75=2016101134=127552=2001111701523304288739260=200111170152330428873925799=10000100268=1279=1269=148=17359555=6SZ683=356386270=10220.0271=34346=31023=710=150
1128=99=18035=X49=SAMPLE75=2016101134=473452=2010042821254574478272060=201004282125457447827205799=10000100268=1279=1269=148=17359555=6SZ683=356387270=10220.0271=4346=21023=710=114
1128=99=18135=X49=SAMPLE75=2016101134=385152=2006030119564286934406460=200603011956428693440645799=10000100268=1279=1269=048=17359555=6SZ683=356388270=10207.0271=13346=71023=610=172
1128=99=18135=X49=SAMPLE75=2016101134=451352=2008091613123098012524860=200809161312309801252485799=10000100268=1279=1269=148=17359555=6SZ683=356389270=10220.0271=34346=31023=710=160
1128=99=18135=X49=SAMPLE75=2016101134=45552=2012020301462058139507260=201202030146205813950725799=10000100268=1279=1269=048=17359555=6SZ683=356390270=10207.0271=43346=81023=610=157
1128=99=18035=X49=SAMPLE75=2016101134=57852=2005041715490565898816060=200504171549056589881605799=10000100268=1279=0269=048=17359555=6SZ683=356391270=10213.0271=1346=11023=110=071
1128=99=17935=X49=SAMPLE75=2016101134=366152=2001111023154171773555260=200111102315417177355525799=10000100268=1279=0269=048=17360055=6SH783=99141270=10266.0271=3346=11023=110=040
1128=99=18135=X49=SAMPLE75=2016101134=274152=2011093008052032815276860=201109300805203281527685799=10000100268=1279=1269=048=17359555=6SZ683=356392270=10207.0271=13346=71023=710=160
1128=99=18035=X49=SAMPLE75=2016101134=337552=2016060317440211105376060=201606031744021110537605799=10000100268=1279=1269=048=17359555=6SZ683=356393270=10208.0271=9346=41023=610=105
1128=99=18135=X49=SAMPLE75=2016101134=101552=2013051503500524161587260=201305150350052416158725799=10000100268=1279=1269=048=17359555=6SZ683=356394270=10209.0271=40346=51023=510=157
1128=99=25035=X49=SAMPLE75=2016101134=238552=2011122817365333563724860=201112281736533356372485799=10000100268=2279=2269=048=17360055=6SH783=99142270=10266.0271=3346=11023=1279=0269=048=17360055=6SH783=99143270=10256.0271=3346=11023=1010=012
1128=99=18135=X49=SAMPLE75=2016101134=387052=2007040900093317133353660=200704090009331713335365799=10000100268=1279=1269=048=17359555=6SZ683=356395270=10207.0271=43346=81023=710=166
1128=99=18135=X49=SAMPLE75=2016101134=248352=2008022221575993364080060=200802222157599336408005799=10000100268=1279=1269=048=17359555=6SZ683=356396270=10207.0271=13346=71023=710=165
1128=99=18135=X49=SAMPLE75=2016101134=399152=2016092507474171372595260=201609250747417137259525799=10000100268=1279=1269=048=17359555=6SZ683=356397270=10207.0271=43346=81023=710=182
1128=99=18035=X49=SAMPLE75=2016101134=108252=2001062815035582168912060=200106281503558216891205799=10000100268=1279=1269=148=17359555=6SZ683=356398270=10214.0271=2346=21023=110=126
1128=99=18035=X49=SAMPLE75=2016101134=279652=2013051923171877092691260=201305192317187709269125799=10000100268=1279=1269=148=17359555=6SZ683=356399270=10220.0271=4346=21023=710=104
1128=99=18135=X49=SAMPLE75=2016101134=433252=2013081521181805602867260=201308152118180560286725799=10000100268=1279=1269=048=17359555=6SZ683=356400270=10207.0271=13346=71023=710=159
1128=99=18135=X49=SAMPLE75=2016101134=161652=2008111617534005500764860=200811161753400550076485799=10000100268=1279=1269=148=17359555=6SZ683=356401270=10220.0271=34346=31023=710=138
1128=99=18035=X49=SAMPLE75=2016101134=431752=2007110113275165801494460=200711011327516580149445799=10000100268=1279=1269=148=17359555=6SZ683=356402270=10220.0271=4346=21023=710=097
1128=99=18135=X49=SAMPLE75=2016101134=345552=2010101222251002496211260=201010122225100249621125799=10000100268=1279=1269=048=17359555=6SZ683=356403270=10207.0271=43346=81023=710=169
1128=99=18135=X49=SAMPLE75=2016101134=34152=2012111301502926221670460=201211130150292622167045799=10000100268=1279=1269=148=17359555=6SZ683=356404270=10220.0271=34346=31023=710=151
1128=99=18035=X49=SAMPLE75=2016101134=351952=2014070611430956561696060=201407061143095656169605799=10000100268=1279=1269=148=17359555=6SZ683=356405270=10220.0271=4346=21023=710=071
1128=99=18135=X49=SAMPLE75=2016101134=198652=2011072108103295029190460=201107210810329502919045799=10000100268=1279=1269=148=17359555=6SZ683=356406270=10220.0271=34346=31023=710=147
1128=99=18135=X49=SAMPLE75=2016101134=224152=2003081306435766142932860=200308130643576614293285799=10000100268=1279=1269=048=17359555=6SZ683=356407270=10207.0271=13346=71023=710=177
1128=99=18035=X49=SAMPLE75=2016101134=3552=2004122606101412244192060=200412260610141224419205799=10000100268=1279=1269=148=17359555=6SZ683=356408270=10220.0271=4346=21023=710=097
1128=99=18135=X49=SAMPLE75=2016101134=225052=2008111406541742817900860=200811140654174281790085799=10000100268=1279=1269=048=17359555=6SZ683=356409270=10207.0271=43346=81023=710=160
1128=99=18135=X49=SAMPLE75=2016101134=26252=2003040702214369454532860=200304070221436945453285799=10000100268=1279=1269=148=17359555=6SZ683=356410270=10220.0271=34346=31023=710=135
1128=99=18035=X49=SAMPLE75=2016101134=496252=2015021602134270010976060=201502160213427001097605799=10000100268=1279=1269=148=17359555=6SZ683=356411270=10220.0271=4346=21023=710=085
1128=99=18135=X49=SAMPLE75=2016101134=273852=2004091310384449265164860=200409131038444926516485799=10000100268=1279=1269=148=17359555=6SZ683=356412270=10220.0271=34346=31023=710=174
1128=99=18035=X49=SAMPLE75=2016101134=338652=2002091307213287203112060=200209130721328720311205799=10000100268=1279=1269=148=17359555=6SZ683=356413270=10220.0271=4346=21023=710=095
1128=99=18135=X49=SAMPLE75=2016101134=392452=2010092020163502606560060=201009202016350260656005799=10000100268=1279=1269=148=17359555=6SZ683=356414270=10220.0271=34346=31023=710=147
1128=99=18035=X49=SAMPLE75=2016101134=51952=2016080816445008417945660=201608081644500841794565799=10000100268=1279=1269=148=17359555=6SZ683=356415270=10220.0271=4346=21023=710=107
1128=99=18135=X49=SAMPLE75=2016101134=477752=2008083107061251269744060=200808310706125126974405799=10000100268=1279=1269=048=17359555=6SZ683=356416270=10207.0271=13346=71023=710=155
1128=99=18135=X49=SAMPLE75=2016101134=283152=2000112412285432725572060=200011241228543272557205799=10000100268=1279=1269=148=17359555=6SZ683=356417270=10220.0271=34346=31023=710=161
1128=99=18135=X49=SAMPLE75=2016101134=176952=2007070810375580123571260=200707081037558012357125799=10000100268=1279=1269=048=17359555=6SZ683=356418270=10207.0271=43346=81023=710=168
1128=99=18135=X49=SAMPLE75=2016101134=352352=2015093021054897054214460=201509302105489705421445799=10000100268=1279=1269=048=17359555=6SZ683=356419270=10207.0271=13346=71023=710=144
1128=99=18135=X49=SAMPLE75=2016101134=45452=2011011722325785055411260=201101172232578505541125799=10000100268=1279=1269=048=17359555=6SZ683=356420270=10207.0271=43346=81023=710=171
1128=99=18135=X49=SAMPLE75=2016101134=279252=2000062112342989982921660=200006211234298998292165799=10000100268=1279=1269=048=17359555=6SZ683=356421270=10207.0271=13346=71023=710=152
1128=99=18035=X49=SAMPLE75=2016101134=41952=2015101012021095087596860=201510101202109508759685799=10000100268=1279=1269=148=17359555=6SZ683=356422270=10220.0271=4346=21023=710=089
1128=99=18135=X49=SAMPLE75=2016101134=495852=2010061818265554049401660=201006181826555404940165799=10000100268=1279=1269=048=17359555=6SZ683=356423270=10207.0271=43346=81023=710=176
1128=99=18135=X49=SAMPLE75=2016101134=13952=2008022609482109612380860=200802260948210961238085799=10000100268=1279=1269=148=17359555=6SZ683=356424270=10220.0271=34346=31023=710=164
1128=99=18035=X49=SAMPLE75=2016101134=187252=2000010618430971366333760=200001061843097136633375799=10000100268=1279=1269=148=17359555=6SZ683=356425270=10220.0271=4346=21023=710=090
1128=99=18135=X49=SAMPLE75=2016101134=170952=2010020211035349516435260=201002021103534951643525799=10000100268=1279=1269=048=17359555=6SZ683=356426270=10207.0271=13346=71023=710=157
1128=99=18135=X49=SAMPLE75=2016101134=343352=2002010413454944893810460=200201041345494489381045799=10000100268=1279=1269=148=17359555=6SZ683=356427270=10220.0271=34346=31023=710=164
1128=99=18135=X49=SAMPLE75=2016101134=378752=2001120221120470286343260=200112022112047028634325799=10000100268=1279=1269=048=17359555=6SZ683=356428270=10207.0271=43346=81023=710=145
1128=99=18135=X49=SAMPLE75=2016101134=355652=2014110900254425601638460=201411090025442560163845799=10000100268=1279=1269=048=17359555=6SZ683=356429270=10207.0271=13346=71023=710=174
1128=99=18035=X49=SAMPLE75=2016101134=21252=2004112109505067836342460=200411210950506783634245799=10000100268=1279=1269=148=17359555=6SZ683=356430270=10220.0271=4346=21023=710=101
1128=99=18135=X49=SAMPLE75=2016101134=30652=2016111109293222714892860=201611110929322271489285799=10000100268=1279=1269=048=17359555=6SZ683=356431270=10207.0271=43346=81023=710=182
1128=99=18135=X49=SAMPLE75=2016101134=14052=2014010504043685734502460=201401050404368573450245799=10000100268=1279=1269=148=17359555=6SZ683=356432270=10220.0271=34346=31023=710=154
1128=99=18135=X49=SAMPLE75=2016101134=25452=2015101223263211396076860=201510122326321139607685799=10000100268=1279=1269=048=17359555=6SZ683=356433270=10207.0271=13346=71023=710=157
1128=99=18035=X49=SAMPLE75=2016101134=7252=2011033101515700946048060=201103310151570094604805799=10000100268=1279=1269=148=17359555=6SZ683=356434270=10220.0271=4346=21023=710=093
1128=99=18135=X49=SAMPLE75=2016101134=155052=2011011013143488280000060=201101101314348828000005799=10000100268=1279=1269=048=17359555=6SZ683=356435270=10207.0271=43346=81023=710=182
1128=99=18135=X49=SAMPLE75=2016101134=213552=2002121817371010818035260=200212181737101081803525799=10000100268=1279=1269=148=17359555=6SZ683=356436270=10220.0271=34346=31023=710=156
1128=99=18135=X49=SAMPLE75=2016101134=98452=2001040605015214918316060=200104060501521491831605799=10000100268=1279=1269=048=17359555=6SZ683=356437270=10207.0271=13346=71023=710=172
1128=99=18035=X49=SAMPLE75=2016101134=105552=2006062309333874943721660=200606230933387494372165799=10000100268=1279=1269=148=17359555=6SZ683=356438270=10220.0271=4346=21023=710=102
1128=99=18135=X49=SAMPLE75=2016101134=74352=2010082210392022509427260=201008221039202250942725799=10000100268=1279=1269=048=17359555=6SZ683=356439270=10207.0271=43346=81023=710=182
1128=99=18135=X49=SAMPLE75=2016101134=463452=2001090512483630993121660=200109051248363099312165799=10000100268=1279=1269=148=17359555=6SZ683=356440270=10220.0271=34346=31023=710=161
1128=99=18135=X49=SAMPLE75=2016101134=124052=2008111822395996962038460=200811182239599696203845799=10000100268=1279=1269=048=17359555=6SZ683=356441270=10207.0271=13346=71023=710=170
1128=99=18035=X49=SAMPLE75=2016101134=165452=2009081808365844092646460=200908180836584409264645799=10000100268=1279=1269=148=17359555=6SZ683=356442270=10220.0271=4346=21023=710=105
1128=99=18135=X49=SAMPLE75=2016101134=88952=2003060615242635424916860=200306061524263542491685799=10000100268=1279=1269=048=17359555=6SZ683=356443270=10207.0271=43346=81023=710=158
1128=99=18135=X49=SAMPLE75=2016101134=326452=2013062812461249483897660=201306281246124948389765799=10000100268=1279=1269=148=17359555=6SZ683=356444270=10220.0271=34346=31023=710=144
1128=99=18035=X49=SAMPLE75=2016101134=421652=2004031523510943093011260=200403152351094309301125799=10000100268=1279=1269=148=17359555=6SZ683=356445270=10220.0271=4346=21023=710=083
1128=99=18135=X49=SAMPLE75=2016101134=316052=2008081801030589469264060=200808180103058946926405799=10000100268=1279=1269=148=17359555=6SZ683=356446270=10220.0271=34346=31023=710=155
1128=99=18135=X49=SAMPLE75=2016101134=338252=2013053021212552260704060=201305302121255226070405799=10000100268=1279=1269=048=17359555=6SZ683=356447270=10207.0271=13346=71023=710=174
1128=99=18035=X49=SAMPLE75=2016101134=22552=2016102019101132439424060=201610201910113243942405799=10000100268=1279=1269=148=17359555=6SZ683=356448270=10220.0271=4346=21023=710=124
1128=99=18135=X49=SAMPLE75=2016101134=188852=2005110500150221220438460=200511050015022122043845799=10000100268=1279=1269=048=17359555=6SZ683=356449270=10207.0271=43346=81023=710=182
1128=99=18135=X49=SAMPLE75=2016101134=221052=2009030411083984270246460=200903041108398427024645799=10000100268=1279=1269=148=17359555=6SZ683=356450270=10220.0271=34346=31023=710=170
1128=99=18035=X49=SAMPLE75=2016101134=266352=2014112009415936075436860=201411200941593607543685799=10000100268=1279=1269=148=17359555=6SZ683=356451270=10220.0271=4346=21023=710=118
1128=99=18135=X49=SAMPLE75=2016101134=375952=2007010718261896517206460=200701071826189651720645799=10000100268=1279=1269=048=17359555=6SZ683=356452270=10207.0271=13346=71023=710=153
1128=99=18135=X49=SAMPLE75=2016101134=217652=2005042602081631120832060=200504260208163112083205799=10000100268=1279=1269=148=17359555=6SZ683=356453270=10220.0271=34346=31023=710=164
1128=99=18135=X49=SAMPLE75=2016101134=451152=2002011811542870944556060=200201181154287094455605799=10000100268=1279=1269=048=17359555=6SZ683=356454270=10207.0271=43346=81023=710=163
1128=99=33135=X49=SAMPLE75=2016101134=140352=2000101217341345622708460=200010121734134562270845799=00000001268=2279=0269=248=17359555=6SZ683=356455270=10213.0271=1346=25797=2279=0269=248=17359555=6SZ683=356456270=10212.0271=4346=45797=237705=637=032=137=032=137=032=437=032=137=621180791228032=137=032=210=186
1128=99=15635=X49=SAMPLE75=2016101134=250752=2006091506415804517017660=200609150641580451701765799=00000010268=1279=0269=e48=17359555=6SZ683=356457271=3710=125
1128=99=32335=X49=SAMPLE75=2016101134=272052=2008100422050164921984060=200810042205016492198405799=10000100268=3279=2269=048=17359555=6SZ683=356458270=10213.0271=1346=11023=1279=1269=048=17359555=6SZ683=356459270=10212.0271=3346=31023=1279=0269=048=17359555=6SZ683=356460270=10203.0271=4346=21023=1010=251
1128=99=17935=X49=SAMPLE75=2016101134=470752=2003012607320897408635260=200301260732089740863525799=10000100268=1279=0269=148=17360055=6SH783=99144270=10269.0271=3346=11023=110=042
1128=99=18035=X49=SAMPLE75=2016101134=78252=2014040218313257567987260=201404021831325756798725799=10000100268=1279=1269=048=17359555=6SZ683=356461270=10212.0271=2346=21023=110=095
1128=99=18035=X49=SAMPLE75=2016101134=88952=2002061907093304589502460=200206190709330458950245799=10000100268=1279=1269=148=17359555=6SZ683=356462270=10214.0271=3346=31023=110=113
1128=99=25135=X49=SAMPLE75=2016101134=89052=2013020900054357229843260=201302090005435722984325799=10000100268=2279=2269=048=17360055=6SH783=99145270=10265.0271=3346=11023=1279=0269=048=17360055=6SH783=99146270=10255.0271=53346=21023=1010=086
1128=99=17935=X49=SAMPLE75=2016101134=294652=2014071306111421164384060=201407130611142116438405799=10000100268=1279=0269=148=17360055=6SH783=99147270=10270.0271=3346=11023=210=036
1128=99=18035=X49=SAMPLE75=2016101134=333752=2007121114455088065811260=200712111445508806581125799=10000100268=1279=1269=048=17359555=6SZ683=356463270=10211.0271=3346=21023=210=086
1128=99=18035=X49=SAMPLE75=2016101134=349852=2002021117322563387541660=200202111732256338754165799=10000100268=1279=1269=048=17359555=6SZ683=356464270=10212.0271=3346=31023=110=081
1128=99=24935=X49=SAMPLE75=2016101134=442452=2015032706212456405740860=201503270621245640574085799=10000100268=2279=1269=048=17360055=6SH783=99148270=10264.0271=3346=11023=1279=1269=048=17360055=6SH783=99149270=10261.0271=5346=21023=410=013
1128=99=24935=X49=SAMPLE75=2016101134=384152=2010101912531669026323260=201010191253166902632325799=10000100268=2279=1269=048=17360055=6SH783=99150270=10262.0271=5346=21023=3279=1269=048=17360055=6SH783=99151270=10261.0271=3346=11023=410=007
1128=99=18135=X49=SAMPLE75=2016101134=111552=2002082915404925653420860=200208291540492565342085799=10000100268=1279=1269=048=17359555=6SZ683=356465270=10207.0271=13346=71023=610=179
1128=99=18035=X49=SAMPLE75=2016101134=15552=2002030322284732043301660=200203032228473204330165799=10000100268=1279=1269=148=17359555=6SZ683=356466270=10220.0271=4346=21023=710=126
1128=99=25035=X49=SAMPLE75=2016101134=114452=2013062704044565508684860=201306270404456550868485799=10000100268=2279=2269=148=17360055=6SH783=99152270=10269.0271=3346=11023=1279=0269=148=17360055=6SH783=99153270=10279.0271=3346=11023=1010=066
1128=99=25135=X49=SAMPLE75=2016101134=198252=2014112320360682636128060=201411232036068263612805799=10000100268=2279=2269=148=17360055=6SH783=99154270=10270.0271=3346=11023=1279=0269=148=17360055=6SH783=99155270=10280.0271=53346=11023=1010=108
1128=99=18135=X49=SAMPLE75=2016101134=5852=2017022409100640127385660=201702240910064012738565799=10000100268=1279=1269=048=17359555=6SZ683=356467270=10209.0271=10346=41023=410=146
1128=99=18035=X49=SAMPLE75=2016101134=325052=2003091902260655381699260=200309190226065538169925799=10000100268=1279=1269=048=17359555=6SZ683=356468270=10212.0271=4346=41023=110=111
1128=99=18135=X49=SAMPLE75=2016101134=393852=2010013021413610313715260=201001302141361031371525799=10000100268=1279=1269=048=17359555=6SZ683=356469270=10206.0271=34346=31023=710=195
1128=99=18135=X49=SAMPLE75=2016101134=374952=2008031711582619800368060=200803171158261980036805799=10000100268=1279=1269=148=17359555=6SZ683=356470270=10220.0271=34346=31023=710=171
1128=99=18135=X49=SAMPLE75=2016101134=204952=2006011606073029338764860=200601160607302933876485799=10000100268=1279=1269=048=17359555=6SZ683=356471270=10208.0271=39346=51023=510=211
1128=99=18035=X49=SAMPLE75=2016101134=276652=2003020916543444239785660=200302091654344423978565799=10000100268=1279=1269=048=17359555=6SZ683=356472270=10206.0271=4346=21023=710=118
1128=99=18135=X49=SAMPLE75=2016101134=268552=2010051401593507240774460=201005140159350724077445799=10000100268=1279=1269=048=17359555=6SZ683=356473270=10206.0271=34346=31023=710=150
1128=99=18035=X49=SAMPLE75=2016101134=287152=2012061422414915135750460=201206142241491513575045799=10000100268=1279=1269=048=17359555=6SZ683=356474270=10206.0271=4346=21023=710=133
1128=99=18135=X49=SAMPLE75=2016101134=141652=2008041817494078245203260=200804181749407824520325799=10000100268=1279=1269=048=17359555=6SZ683=356475270=10206.0271=34346=31023=710=182
1128=99=18035=X49=SAMPLE75=2016101134=341752=2007032419252802149977660=200703241925280214997765799=10000100268=1279=1269=048=17359555=6SZ683=356476270=10212.0271=5346=51023=110=094
1128=99=18035=X49=SAMPLE75=2016101134=381052=2011121112114156108608060=201112111211415610860805799=10000100268=1279=1269=048=17359555=6SZ683=356477270=10206.0271=4346=21023=710=135
1128=99=18135=X49=SAMPLE75=2016101134=104352=2013061116031848974348860=201306111603184897434885799=10000100268=1279=1269=048=17359555=6SZ683=356478270=10205.0271=51346=81023=810=179
1128=99=18135=X49=SAMPLE75=2016101134=332452=2001050323523465839535260=200105032352346583953525799=10000100268=1279=1269=048=17359555=6SZ683=356479270=10206.0271=34346=31023=710=176
1128=99=18135=X49=SAMPLE75=2016101134=415352=2011080320460085730265660=201108032046008573026565799=10000100268=1279=1269=048=17359555=6SZ683=356480270=10205.0271=21346=71023=810=165
1128=99=18035=X49=SAMPLE75=2016101134=84852=2016042708121978043078460=201604270812197804307845799=10000100268=1279=1269=148=17359555=6SZ683=356481270=10220.0271=4346=21023=710=102
1128=99=18135=X49=SAMPLE75=2016101134=60152=2014061600000954681171260=201406160000095468117125799=10000100268=1279=1269=148=17359555=6SZ683=356482270=10219.0271=51346=81023=610=153
1128=99=18035=X49=SAMPLE75=2016101134=40152=2002111703244482242483260=200211170324448224248325799=10000100268=1279=1269=048=17359555=6SZ683=356483270=10206.0271=4346=21023=710=114
1128=99=18035=X49=SAMPLE75=2016101134=388752=2013082605240100762380860=201308260524010076238085799=10000100268=1279=1269=048=17359555=6SZ683=356484270=10212.0271=4346=41023=110=105
1128=99=18035=X49=SAMPLE75=2016101134=304152=2013120513364248263840060=201312051336424826384005799=10000100268=1279=1269=048=17359555=6SZ683=356485270=10212.0271=3346=31023=110=118
1128=99=18135=X49=SAMPLE75=2016101134=361052=2011020119010872691673660=201102011901087269167365799=10000100268=1279=1269=148=17359555=6SZ683=356486270=10219.0271=21346=71023=610=150
1128=99=18135=X49=SAMPLE75=2016101134=1552=2016042407135820606144060=201604240713582060614405799=10000100268=1279=1269=048=17359555=6SZ683=356487270=10206.0271=34346=31023=710=167
1128=99=18135=X49=SAMPLE75=2016101134=144052=2005121306510082998176060=200512130651008299817605799=10000100268=1279=1269=148=17359555=6SZ683=356488270=10219.0271=51346=81023=610=179
1128=99=18035=X49=SAMPLE75=2016101134=172552=2002062420110911489808060=200206242011091148980805799=10000100268=1279=1269=048=17359555=6SZ683=356489270=10206.0271=4346=21023=710=092
1128=99=18035=X49=SAMPLE75=2016101134=494552=2012082423275742251648060=201208242327574225164805799=10000100268=1279=1269=048=17359555=6SZ683=356490270=10212.0271=4346=41023=110=119
1128=99=18035=X49=SAMPLE75=2016101134=212852=2005022823134048332643260=200502282313404833264325799=10000100268=1279=1269=048=17359555=6SZ683=356491270=10212.0271=3346=31023=110=099
1128=99=18135=X49=SAMPLE75=2016101134=150252=2009101304192377051904060=200910130419237705190405799=10000100268=1279=1269=148=17359555=6SZ683=356492270=10219.0271=21346=71023=610=155
1128=99=18035=X49=SAMPLE75=2016101134=428752=2009040906561666628563260=200904090656166662856325799=10000100268=1279=1269=048=17359555=6SZ683=356493270=10212.0271=4346=41023=110=119
1128=99=18135=X49=SAMPLE75=2016101134=57252=2009100914283428713612860=200910091428342871361285799=10000100268=1279=1269=048=17359555=6SZ683=356494270=10206.0271=34346=31023=710=154
1128=99=18135=X49=SAMPLE75=2016101134=108352=2010020100443805410438460=201002010044380541043845799=10000100268=1279=1269=148=17359555=6SZ683=356495270=10219.0271=51346=81023=610=174
1128=99=18035=X49=SAMPLE75=2016101134=354652=2011110504553164726259260=201111050455316472625925799=10000100268=1279=1269=048=17359555=6SZ683=356496270=10206.0271=4346=21023=710=112
1128=99=18135=X49=SAMPLE75=2016101134=263552=2001051211502359774930460=200105121150235977493045799=10000100268=1279=1269=148=17359555=6SZ683=356497270=10219.0271=21346=71023=610=180
1128=99=18135=X49=SAMPLE75=2016101134=238852=2003050619532890857401660=200305061953289085740165799=10000100268=1279=1269=048=17359555=6SZ683=356498270=10206.0271=34346=31023=710=188
1128=99=18135=X49=SAMPLE75=2016101134=305652=2006110404593888066230460=200611040459388806623045799=10000100268=1279=1269=148=17359555=6SZ683=356499270=10219.0271=51346=81023=610=162
1128=99=18035=X49=SAMPLE75=2016101134=82052=2011100510561351078816060=201110051056135107881605799=10000100268=1279=1269=048=17359555=6SZ683=356500270=10206.0271=4346=21023=710=071
1128=99=18135=X49=SAMPLE75=2016101134=396352=2014051205424342862361660=201405120542434286236165799=10000100268=1279=1269=048=17359555=6SZ683=356501270=10206.0271=34346=31023=710=137
1128=99=18035=X49=SAMPLE75=2016101134=37052=2016092904395110736057660=201609290439511073605765799=10000100268=1279=1269=048=17359555=6SZ683=356502270=10206.0271=4346=21023=710=108
1128=99=18135=X49=SAMPLE75=2016101134=253652=2014013009420447234809660=201401300942044723480965799=10000100268=1279=1269=148=17359555=6SZ683=356503270=10219.0271=21346=71023=610=168
1128=99=18035=X49=SAMPLE75=2016101134=150352=2014072622184127840806460=201407262218412784080645799=10000100268=1279=1269=048=17359555=6SZ683=356504270=10212.0271=3346=31023=110=101
1128=99=18135=X49=SAMPLE75=2016101134=472552=2016060213464846809740860=201606021346484680974085799=10000100268=1279=1269=048=17359555=6SZ683=356505270=10206.0271=34346=31023=710=169
1128=99=18135=X49=SAMPLE75=2016101134=400752=2015010414282089604256060=201501041428208960425605799=10000100268=1279=1269=148=17359555=6SZ683=356506270=10219.0271=51346=81023=610=152
1128=99=18035=X49=SAMPLE75=2016101134=76052=2001032421210415540823260=200103242121041554082325799=10000100268=1279=1269=048=17359555=6SZ683=356507270=10206.0271=4346=21023=710=120
1128=99=18135=X49=SAMPLE75=2016101134=256652=2003032908562159576404860=200303290856215957640485799=10000100268=1279=1269=048=17359555=6SZ683=356508270=10206.0271=34346=31023=710=155
1128=99=18035=X49=SAMPLE75=2016101134=13952=2015061001113476545811260=201506100111347654581125799=10000100268=1279=1269=048=17359555=6SZ683=356509270=10206.0271=4346=21023=710=122
1128=99=18135=X49=SAMPLE75=2016101134=220952=2008121707561212828454460=200812170756121282845445799=10000100268=1279=1269=048=17359555=6SZ683=356510270=10206.0271=34346=31023=710=141
1128=99=18035=X49=SAMPLE75=2016101134=112852=2016011614093781329158460=201601161409378132915845799=10000100268=1279=1269=048=17359555=6SZ683=356511270=10206.0271=4346=21023=710=112
1128=99=18135=X49=SAMPLE75=2016101134=452952=2009062823345075341580860=200906282334507534158085799=10000100268=1279=1269=048=17359555=6SZ683=356512270=10207.0271=43346=81023=610=170
1128=99=18135=X49=SAMPLE75=2016101134=269852=2005021009502815392217660=200502100950281539221765799=10000100268=1279=1269=048=17359555=6SZ683=356513270=10207.0271=13346=71023=610=178
1128=99=18135=X49=SAMPLE75=2016101134=91352=2000082408461765098468460=200008240846176509846845799=10000100268=1279=1269=048=17359555=6SZ683=356514270=10207.0271=43346=81023=610=171
1128=99=18135=X49=SAMPLE75=2016101134=133952=2007062301441439528000060=200706230144143952800005799=10000100268=1279=1269=048=17359555=6SZ683=356515270=10207.0271=13346=71023=610=175
1128=99=18135=X49=SAMPLE75=2016101134=228652=2001112419334066794488860=200111241933406679448885799=10000100268=1279=1269=148=17359555=6SZ683=356516270=10219.0271=21346=71023=610=161
1128=99=18135=X49=SAMPLE75=2016101134=470252=2003052207201420549905660=200305220720142054990565799=10000100268=1279=1269=048=17359555=6SZ683=356517270=10206.0271=34346=31023=710=151
1128=99=18135=X49=SAMPLE75=2016101134=396652=2016050303015598144838460=201605030301559814483845799=10000100268=1279=1269=148=17359555=6SZ683=356518270=10220.0271=34346=31023=710=149
1128=99=18035=X49=SAMPLE75=2016101134=406952=2009091822120774512569660=200909182212077451256965799=10000100268=1279=1269=048=17359555=6SZ683=356519270=10212.0271=4346=41023=110=098
1128=99=18035=X49=SAMPLE75=2016101134=198252=2004041512322889102940860=200404151232288910294085799=10000100268=1279=1269=048=17359555=6SZ683=356520270=10206.0271=4346=21023=710=108
1128=99=18135=X49=SAMPLE75=2016101134=122852=2009082020135487817939260=200908202013548781793925799=10000100268=1279=1269=048=17359555=6SZ683=356521270=10206.0271=34346=31023=710=152
1128=99=18035=X49=SAMPLE75=2016101134=351552=2004011503202402639254460=200401150320240263925445799=10000100268=1279=1269=048=17359555=6SZ683=356522270=10206.0271=4346=21023=710=084
1128=99=18135=X49=SAMPLE75=2016101134=88352=2007071012193188606387260=200707101219318860638725799=10000100268=1279=1269=048=17359555=6SZ683=356523270=10206.0271=34346=31023=710=133
1128=99=18235=X49=SAMPLE75=2016101134=427252=2015010503405946759411260=201501050340594675941125799=10000100268=1279=1269=148=17359555=6SZ683=356524270=10223.0271=17346=41023=1010=199
1128=99=18135=X49=SAMPLE75=2016101134=32752=2008110908493476755177660=200811090849347675517765799=10000100268=1279=1269=148=17359555=6SZ683=356525270=10223.0271=9346=31023=1010=170
1128=99=18035=X49=SAMPLE75=2016101134=55352=2008011301532401281385660=200801130153240128138565799=10000100268=1279=1269=048=17359555=6SZ683=356526270=10212.0271=3346=31023=110=096
1128=99=18035=X49=SAMPLE75=2016101134=80452=2007011119423455552409660=200701111942345555240965799=10000100268=1279=1269=048=17359555=6SZ683=356527270=10206.0271=4346=21023=710=113
1128=99=18135=X49=SAMPLE75=2016101134=30552=2014120500531022281689660=201412050053102228168965799=10000100268=1279=1269=048=17359555=6SZ683=356528270=10206.0271=34346=31023=710=146
1128=99=18035=X49=SAMPLE75=2016101134=335652=2015062805304460151014460=201506280530446015101445799=10000100268=1279=1269=048=17359555=6SZ683=356529270=10206.0271=4346=21023=710=110
1128=99=18135=X49=SAMPLE75=2016101134=83752=2004121303401683191888060=200412130340168319188805799=10000100268=1279=1269=048=17359555=6SZ683=356530270=10206.0271=34346=31023=710=149
1128=99=18035=X49=SAMPLE75=2016101134=393652=2002063003023592855950460=200206300302359285595045799=10000100268=1279=1269=048=17359555=6SZ683=356531270=10212.0271=4346=41023=110=132
1128=99=18035=X49=SAMPLE75=2016101134=416752=2010101817481223997612860=201010181748122399761285799=10000100268=1279=1269=048=17359555=6SZ683=356532270=10206.0271=4346=21023=710=110
1128=99=18135=X49=SAMPLE75=2016101134=101052=2000072611371192062083260=200007261137119206208325799=10000100268=1279=1269=048=17359555=6SZ683=356533270=10206.0271=34346=31023=710=154
1128=99=18035=X49=SAMPLE75=2016101134=39352=2005060200532106599987260=200506020053210659998725799=10000100268=1279=1269=048=17359555=6SZ683=356534270=10206.0271=4346=21023=710=138
1128=99=18135=X49=SAMPLE75=2016101134=261052=2014051105253480150739260=201405110525348015073925799=10000100268=1279=1269=048=17359555=6SZ683=356535270=10206.0271=34346=31023=710=166
1128=99=18035=X49=SAMPLE75=2016101134=291652=2004100817395061559859260=200410081739506155985925799=10000100268=1279=1269=048=17359555=6SZ683=356536270=10206.0271=4346=21023=710=117
1128=99=18135=X49=SAMPLE75=2016101134=49952=2003020510044120497864060=200302051004412049786405799=10000100268=1279=1269=048=17359555=6SZ683=356537270=10206.0271=34346=31023=710=167
1128=99=18035=X49=SAMPLE75=2016101134=435252=2009040717174037207974460=200904071717403720797445799=10000100268=1279=1269=148=17359555=6SZ683=356538270=10220.0271=4346=21023=710=117
1128=99=18135=X49=SAMPLE75=2016101134=131152=2004041813312738225822460=200404181331273822582245799=10000100268=1279=1269=148=17359555=6SZ683=356539270=10219.0271=51346=81023=610=181
1128=99=18035=X49=SAMPLE75=2016101134=293452=2005082007454524239276860=200508200745452423927685799=10000100268=1279=1269=148=17359555=6SZ683=356540270=10218.0271=4346=21023=510=110
1128=99=18135=X49=SAMPLE75=2016101134=238752=2005121104340027222688060=200512110434002722268805799=10000100268=1279=1269=148=17359555=6SZ683=356541270=10217.0271=34346=31023=410=187
1128=99=18135=X49=SAMPLE75=2016101134=434152=2013082116595055130137660=201308211659505513013765799=10000100268=1279=1269=148=17359555=6SZ683=356542270=10219.0271=21346=71023=610=173
1128=99=18135=X49=SAMPLE75=2016101134=310252=2014022406520929112601660=201402240652092911260165799=10000100268=1279=1269=148=17359555=6SZ683=356543270=10219.0271=51346=81023=610=165
1128=99=18035=X49=SAMPLE75=2016101134=322452=2001110118070937908420060=200111011807093790842005799=10000100268=1279=1269=148=17359555=6SZ683=356544270=10217.0271=4346=21023=410=098
1128=99=18135=X49=SAMPLE75=2016101134=81752=2013010416590968000185660=201301041659096800018565799=10000100268=1279=1269=148=17359555=6SZ683=356545270=10220.0271=34346=31023=710=160
1128=99=18035=X49=SAMPLE75=2016101134=176552=2015060913072506349235260=201506091307250634923525799=10000100268=1279=1269=148=17359555=6SZ683=356546270=10220.0271=4346=21023=710=095
1128=99=18135=X49=SAMPLE75=2016101134=344652=2013082006564682500518460=201308200656468250051845799=10000100268=1279=1269=148=17359555=6SZ683=356547270=10218.0271=34346=31023=510=171
1128=99=18035=X49=SAMPLE75=2016101134=273352=2014041412523771231251260=201404141252377123125125799=10000100268=1279=1269=048=17359555=6SZ683=356548270=10206.0271=4346=21023=710=096
1128=99=18135=X49=SAMPLE75=2016101134=161052=2004091004432825651414460=200409100443282565141445799=10000100268=1279=1269=148=17359555=6SZ683=356549270=10219.0271=21346=71023=610=156
1128=99=18135=X49=SAMPLE75=2016101134=79852=2005022302093623609376060=200502230209362360937605799=10000100268=1279=1269=048=17359555=6SZ683=356550270=10206.0271=34346=31023=710=131
1128=99=18135=X49=SAMPLE75=2016101134=434752=2004120822055662438355260=200412082205566243835525799=10000100268=1279=1269=148=17359555=6SZ683=356551270=10220.0271=34346=31023=710=126
1128=99=18035=X49=SAMPLE75=2016101134=143452=2009033022182674123302460=200903302218267412330245799=10000100268=1279=1269=048=17359555=6SZ683=356552270=10212.0271=5346=51023=110=081
1128=99=18035=X49=SAMPLE75=2016101134=80052=2001102910051514901386460=200110291005151490138645799=10000100268=1279=1269=048=17359555=6SZ683=356553270=10206.0271=4346=21023=710=095
1128=99=18135=X49=SAMPLE75=2016101134=402952=2006052818120931690912060=200605281812093169091205799=10000100268=1279=1269=048=17359555=6SZ683=356554270=10206.0271=34346=31023=710=145
1128=99=18035=X49=SAMPLE75=2016101134=413452=2000101005500742229702860=200010100550074222970285799=10000100268=1279=1269=048=17359555=6SZ683=356555270=10206.0271=4346=21023=710=083
1128=99=18135=X49=SAMPLE75=2016101134=13952=2016042022474273756428860=201604202247427375642885799=10000100268=1279=1269=048=17359555=6SZ683=356556270=10207.0271=43346=81023=610=159
1128=99=18135=X49=SAMPLE75=2016101134=151452=2007050412274955067398460=200705041227495506739845799=10000100268=1279=1269=048=17359555=6SZ683=356557270=10207.0271=13346=71023=610=167
1128=99=18135=X49=SAMPLE75=2016101134=135852=2007070817214725357158460=200707081721472535715845799=10000100268=1279=1269=048=17359555=6SZ683=356558270=10207.0271=43346=81023=610=182
1128=99=18135=X49=SAMPLE75=2016101134=243152=2015010801072200918291260=201501080107220091829125799=10000100268=1279=1269=048=17359555=6SZ683=356559270=10207.0271=13346=71023=610=136
1128=99=18135=X49=SAMPLE75=2016101134=228652=2009072902041817004652860=200907290204181700465285799=10000100268=1279=1269=048=17359555=6SZ683=356560270=10207.0271=43346=81023=610=147
1128=99=18135=X49=SAMPLE75=2016101134=277252=2009083104440197638444860=200908310444019763844485799=10000100268=1279=1269=048=17359555=6SZ683=356561270=10207.0271=13346=71023=610=160
1128=99=18135=X49=SAMPLE75=2016101134=382152=2012071821030446647417660=201207182103044664741765799=10000100268=1279=1269=048=17359555=6SZ683=356562270=10207.0271=43346=81023=610=149
1128=99=18135=X49=SAMPLE75=2016101134=310752=2016030209181493199641660=201603020918149319964165799=10000100268=1279=1269=048=17359555=6SZ683=356563270=10207.0271=13346=71023=610=168
1128=99=18135=X49=SAMPLE75=2016101134=292152=2001050407214516875768860=200105040721451687576885799=10000100268=1279=1269=048=17359555=6SZ683=356564270=10207.0271=43346=81023=610=191
1128=99=18135=X49=SAMPLE75=2016101134=433652=2013102315580055730675260=201310231558005573067525799=10000100268=1279=1269=048=17359555=6SZ683=356565270=10207.0271=13346=71023=610=101
1128=99=18035=X49=SAMPLE75=2016101134=260552=2002021800265932643689660=200202180026593264368965799=10000100268=1279=1269=048=17359555=6SZ683=356566270=10208.0271=9346=41023=510=095
1128=99=18035=X49=SAMPLE75=2016101134=394652=2003060923153125736020860=200306092315312573602085799=10000100268=1279=1269=148=17359555=6SZ683=356567270=10218.0271=4346=21023=510=079
1128=99=18035=X49=SAMPLE75=2016101134=385652=2003012603233985086124860=200301260323398508612485799=10000100268=1279=1269=148=17359555=6SZ683=356568270=10220.0271=4346=21023=710=058
1128=99=18235=X49=SAMPLE75=2016101134=20552=2014010418250976526988860=201401041825097652698885799=10000100268=1279=1269=148=17359555=6SZ683=356569270=10223.0271=17346=41023=1010=183
1128=99=18035=X49=SAMPLE75=2016101134=167852=2004073019470020407446460=200407301947002040744645799=10000100268=1279=1269=048=17359555=6SZ683=356570270=10211.0271=4346=31023=210=070
1128=99=18035=X49=SAMPLE75=2016101134=253652=2005042410244556786121660=200504241024455678612165799=10000100268=1279=1269=148=17359555=6SZ683=356571270=10218.0271=5346=31023=510=083
1128=99=18135=X49=SAMPLE75=2016101134=325152=2001063016533220080008860=200106301653322008000885799=10000100268=1279=1269=148=17359555=6SZ683=356572270=10223.0271=9346=31023=1010=140
1128=99=18035=X49=SAMPLE75=2016101134=256652=2008060617115657756832060=200806061711565775683205799=10000100268=1279=0269=148=17359555=6SZ683=356573270=10213.0271=1346=11023=110=117
1128=99=17935=X49=SAMPLE75=2016101134=327852=2006032115531099788131260=200603211553109978813125799=10000100268=1279=0269=148=17360055=6SH783=99156270=10269.0271=3346=11023=110=075
1128=99=17935=X49=SAMPLE75=2016101134=207452=2000120616512531423991260=200012061651253142399125799=10000100268=1279=0269=148=17360055=6SH783=99157270=10270.0271=3346=11023=210=043
1128=99=25135=X49=SAMPLE75=2016101134=156752=2011011609222151658483260=201101160922215165848325799=10000100268=2279=1269=148=17359555=6SZ683=356574270=10213.0271=2346=21023=1279=1269=148=17359555=6SZ683=356575270=10214.0271=2346=21023=210=125
1128=99=25035=X49=SAMPLE75=2016101134=375152=2012080422252037995948860=201208042225203799594885799=10000100268=2279=2269=148=17360055=6SH783=99158270=10269.0271=3346=11023=1279=0269=148=17360055=6SH783=99159270=10279.0271=3346=11023=1010=062
1128=99=18035=X49=SAMPLE75=2016101134=427052=2012032406571686021075260=201203240657168602107525799=10000100268=1279=1269=148=17359555=6SZ683=356576270=10213.0271=1346=11023=110=113
1128=99=18035=X49=SAMPLE75=2016101134=368152=2007041717574725537302460=200704171757472553730245799=10000100268=1279=1269=048=17359555=6SZ683=356577270=10212.0271=4346=41023=110=102
1128=99=18035=X49=SAMPLE75=2016101134=114752=2011062023323868760339260=201106202332386876033925799=10000100268=1279=1269=148=17359555=6SZ683=356578270=10213.0271=2346=21023=110=126
1128=99=18035=X49=SAMPLE75=2016101134=258352=2015030102192140869350460=201503010219214086935045799=10000100268=1279=1269=148=17359555=6SZ683=356579270=10213.0271=1346=11023=110=111
1128=99=18035=X49=SAMPLE75=2016101134=428352=2006100412454309231510460=200610041245430923151045799=10000100268=1279=1269=048=17359555=6SZ683=356580270=10212.0271=5346=51023=110=125
1128=99=18135=X49=SAMPLE75=2016101134=460052=2008052714543310243628860=200805271454331024362885799=10000100268=1279=1269=148=17359555=6SZ683=356581270=10218.0271=13346=41023=610=216
1128=99=18135=X49=SAMPLE75=2016101134=187652=2014072805192821028070460=201407280519282102807045799=10000100268=1279=1269=148=17359555=6SZ683=356582270=10220.0271=12346=31023=810=176
1128=99=18035=X49=SAMPLE75=2016101134=327352=2000071419503437021885660=200007141950343702188565799=10000100268=1279=1269=148=17360055=6SH783=99160270=10277.0271=11346=21023=810=113
1128=99=18135=X49=SAMPLE75=2016101134=152352=2012022708233844436454460=201202270823384443645445799=10000100268=1279=1269=148=17360055=6SH783=99161270=10279.0271=11346=21023=1010=142
1128=99=20835=X49=SAMPLE75=2016101134=355152=2010102804552518894976060=201010280455251889497605799=00000001268=1279=0269=248=17359555=6SZ683=356583270=10213.0271=1346=25797=137705=237=032=137=032=110=075
1128=99=15635=X49=SAMPLE75=2016101134=312052=2007091611015265424604860=200709161101526542460485799=00000010268=1279=0269=e48=17359555=6SZ683=356584271=3810=124
1128=99=25235=X49=SAMPLE75=2016101134=210952=2011031820073257729638460=201103182007325772963845799=10000100268=2279=2269=148=17359555=6SZ683=356585270=10213.0271=1346=11023=1279=0269=148=17359555=6SZ683=356586270=10223.0271=9346=31023=1010=225
1128=99=17935=X49=SAMPLE75=2016101134=386752=2010011507310555557593660=201001150731055555759365799=10000100268=1279=0269=048=17360055=6SH783=99162270=10266.0271=3346=11023=110=058
1128=99=25135=X49=SAMPLE75=2016101134=347652=2009110401233971848486460=200911040123397184848645799=10000100268=2279=2269=148=17360055=6SH783=99163270=10270.0271=3346=11023=1279=0269=148=17360055=6SH783=99164270=10280.0271=53346=11023=1010=110
1128=99=17935=X49=SAMPLE75=2016101134=73252=2008062317315291509248060=200806231731529150924805799=10000100268=1279=0269=048=17360055=6SH783=99165270=10265.0271=3346=11023=210=053
1128=99=25135=X49=SAMPLE75=2016101134=265752=2000092205390180439802060=200009220539018043980205799=10000100268=2279=1269=048=17359555=6SZ683=356587270=10211.0271=5346=41023=2279=1269=048=17359555=6SZ683=356588270=10210.0271=5346=31023=310=157
1128=99=18035=X49=SAMPLE75=2016101134=278352=2003112714514972044814460=200311271451497204481445799=10000100268=1279=1269=148=17359555=6SZ683=356589270=10214.0271=3346=31023=110=123
1128=99=25035=X49=SAMPLE75=2016101134=491652=2000052512172176276018060=200005251217217627601805799=10000100268=2279=2269=048=17360055=6SH783=99166270=10266.0271=3346=11023=1279=0269=048=17360055=6SH783=99167270=10256.0271=3346=11023=1010=040
1128=99=18035=X49=SAMPLE75=2016101134=358252=2002012918504528719907260=200201291850452871990725799=10000100268=1279=1269=048=17359555=6SZ683=356590270=10212.0271=6346=61023=110=071
1128=99=18035=X49=SAMPLE75=2016101134=432752=2004080200062008638611260=200408020006200863861125799=10000100268=1279=1269=048=17359555=6SZ683=356591270=10211.0271=4346=31023=210=088
1128=99=24935=X49=SAMPLE75=2016101134=457252=2000062701463570032592860=200006270146357003259285799=10000100268=2279=1269=048=17360055=6SH783=99168270=10264.0271=5346=21023=2279=1269=048=17360055=6SH783=99169270=10262.0271=3346=11023=410=240
1128=99=18135=X49=SAMPLE75=2016101134=161852=2001070410004566593567260=200107041000456659356725799=10000100268=1279=1269=048=17359555=6SZ683=356592270=10207.0271=21346=81023=610=157
1128=99=18135=X49=SAMPLE75=2016101134=83152=2005070514471927380934460=200507051447192738093445799=10000100268=1279=1269=048=17359555=6SZ683=356593270=10205.0271=29346=81023=810=172
1128=99=18035=X49=SAMPLE75=2016101134=96552=2013101913384733816166460=201310191338473381616645799=10000100268=1279=1269=048=17360055=6SH783=99170270=10257.0271=11346=21023=910=069
1128=99=18035=X49=SAMPLE75=2016101134=354552=2009101721262448809875260=200910172126244880987525799=10000100268=1279=1269=048=17359555=6SZ683=356594270=10212.0271=5346=51023=110=093
1128=99=25135=X49=SAMPLE75=2016101134=175752=2012111610325088917356860=201211161032508891735685799=10000100268=2279=2269=048=17360055=6SH783=99171270=10265.0271=3346=11023=1279=0269=048=17360055=6SH783=99172270=10255.0271=61346=31023=1010=073
1128=99=18035=X49=SAMPLE75=2016101134=496352=2013103002462635194432060=201310300246263519443205799=10000100268=1279=1269=048=17359555=6SZ683=356595270=10211.0271=5346=41023=210=099
1128=99=25235=X49=SAMPLE75=2016101134=288152=2014030811423416897056060=201403081142341689705605799=10000100268=2279=1269=048=17359555=6SZ683=356596270=10208.0271=6346=31023=5279=1269=048=17359555=6SZ683=356597270=10207.0271=24346=91023=610=214
1128=99=25135=X49=SAMPLE75=2016101134=69752=2010101805463981321632060=201010180546398132163205799=10000100268=2279=1269=048=17359555=6SZ683=356598270=10211.0271=4346=31023=2279=1269=048=17359555=6SZ683=356599270=10210.0271=6346=41023=310=140
1128=99=18135=X49=SAMPLE75=2016101134=471852=2001010407260750275541260=200101040726075027554125799=10000100268=1279=1269=148=17359555=6SZ683=356600270=10222.0271=11346=31023=910=145
1128=99=18235=X49=SAMPLE75=2016101134=236652=2011052806344957057862460=201105280634495705786245799=10000100268=1279=1269=148=17359555=6SZ683=356601270=10223.0271=16346=41023=1010=201
1128=99=18035=X49=SAMPLE75=2016101134=30752=2002040409132516239465660=200204040913251623946565799=10000100268=1279=1269=148=17359555=6SZ683=356602270=10222.0271=4346=21023=910=088
1128=99=18135=X49=SAMPLE75=2016101134=252=2000040622094072279640860=200004062209407227964085799=10000100268=1279=1269=148=17359555=6SZ683=356603270=10223.0271=9346=31023=1010=138
1128=99=18035=X49=SAMPLE75=2016101134=149252=2009010602262093301315260=200901060226209330131525799=10000100268=1279=0269=148=17359555=6SZ683=356604270=10213.0271=1346=11023=110=086
1128=99=17935=X49=SAMPLE75=2016101134=37852=2008043001112105625075260=200804300111210562507525799=10000100268=1279=0269=148=17360055=6SH783=99173270=10269.0271=3346=11023=110=050
1128=99=17935=X49=SAMPLE75=2016101134=372352=2009081215143289594380860=200908121514328959438085799=10000100268=1279=0269=148=17360055=6SH783=99174270=10270.0271=3346=11023=210=017
1128=99=18035=X49=SAMPLE75=2016101134=141652=2013101215290588983680060=201310121529058898368005799=10000100268=1279=1269=048=17359555=6SZ683=356605270=10212.0271=4346=41023=110=089
1128=99=18035=X49=SAMPLE75=2016101134=184352=2016013109140778022342460=201601310914077802234245799=10000100268=1279=1269=148=17359555=6SZ683=356606270=10213.0271=2346=21023=110=112
1128=99=18035=X49=SAMPLE75=2016101134=163652=2004071118465413378134460=200407111846541337813445799=10000100268=1279=1269=048=17359555=6SZ683=356607270=10212.0271=3346=31023=110=098
1128=99=18035=X49=SAMPLE75=2016101134=95152=2005080422101236916921660=200508042210123691692165799=10000100268=1279=1269=048=17359555=6SZ683=356608270=10212.0271=2346=21023=110=111
1128=99=25135=X49=SAMPLE75=2016101134=104752=2004060216195445679828860=200406021619544567982885799=10000100268=2279=1269=148=17359555=6SZ683=356609270=10213.0271=3346=31023=1279=1269=148=17359555=6SZ683=356610270=10214.0271=2346=21023=210=133
1128=99=25135=X49=SAMPLE75=2016101134=315252=2006041713040136996582460=200604171304013699658245799=10000100268=2279=2269=148=17360055=6SH783=99175270=10269.0271=3346=11023=1279=0269=148=17360055=6SH783=99176270=10279.0271=11346=21023=1010=127
1128=99=18035=X49=SAMPLE75=2016101134=72352=2015020904253080882016060=201502090425308088201605799=10000100268=1279=1269=148=17359555=6SZ683=356611270=10213.0271=2346=21023=110=037
1128=99=18035=X49=SAMPLE75=2016101134=433652=2007031103404725082182460=200703110340472508218245799=10000100268=1279=1269=148=17359555=6SZ683=356612270=10214.0271=5346=31023=210=112
1128=99=25135=X49=SAMPLE75=2016101134=361652=2010101609153599405766460=201010160915359940576645799=10000100268=2279=1269=048=17359555=6SZ683=356613270=10212.0271=1346=11023=1279=1269=048=17359555=6SZ683=356614270=10208.0271=7346=41023=510=141
1128=99=24935=X49=SAMPLE75=2016101134=120352=2002021213120993174600060=200202121312099317460005799=10000100268=2279=1269=048=17360055=6SH783=99177270=10264.0271=3346=11023=1279=1269=048=17360055=6SH783=99178270=10261.0271=5346=21023=410=240
1128=99=23035=X49=SAMPLE75=2016101134=495652=2000062520471625911924060=200006252047162591192405799=00000001268=1279=0269=248=17359555=6SZ683=356615270=10213.0271=2346=35797=137705=337=032=237=621180791993932=137=032=110=129
1128=99=15635=X49=SAMPLE75=2016101134=366352=2009092613091949900454460=200909261309194990045445799=00000010268=1279=0269=e48=17359555=6SZ683=356616271=4010=114
1128=99=25235=X49=SAMPLE75=2016101134=53552=2016052211314088447641660=201605221131408844764165799=10000100268=2279=2269=148=17359555=6SZ683=356617270=10213.0271=2346=21023=1279=0269=148=17359555=6SZ683=356618270=10223.0271=9346=31023=1010=220
1128=99=17935=X49=SAMPLE75=2016101134=106352=2000061308491750481906060=200006130849175048190605799=10000100268=1279=0269=048=17360055=6SH783=99179270=10266.0271=3346=11023=110=063
1128=99=18035=X49=SAMPLE75=2016101134=10452=2005102409441273816889660=200510240944127381688965799=10000100268=1279=1269=048=17359555=6SZ683=356619270=10212.0271=2346=21023=110=117
1128=99=25135=X49=SAMPLE75=2016101134=353052=2011052921183270424908860=201105292118327042490885799=10000100268=2279=2269=148=17360055=6SH783=99180270=10270.0271=3346=11023=1279=0269=148=17360055=6SH783=99181270=10280.0271=53346=11023=1010=109
1128=99=17935=X49=SAMPLE75=2016101134=199852=2009062608322164541574460=200906260832216454157445799=10000100268=1279=0269=048=17360055=6SH783=99182270=10265.0271=3346=11023=210=071
1128=99=24935=X49=SAMPLE75=2016101134=25052=2011051312102310488499260=201105131210231048849925799=10000100268=2279=1269=048=17360055=6SH783=99183270=10262.0271=5346=21023=5279=1269=048=17360055=6SH783=99184270=10261.0271=3346=11023=610=023
1128=99=18035=X49=SAMPLE75=2016101134=63652=2016101613332484575168060=201610161333248457516805799=10000100268=1279=1269=148=17359555=6SZ683=356620270=10214.0271=2346=21023=110=117
1128=99=25135=X49=SAMPLE75=2016101134=409652=2015092119231623910521660=201509211923162391052165799=10000100268=2279=1269=048=17359555=6SZ683=356621270=10212.0271=3346=31023=1279=1269=048=17359555=6SZ683=356622270=10208.0271=6346=31023=510=171
1128=99=18035=X49=SAMPLE75=2016101134=413752=2014042708210675396179260=201404270821067539617925799=10000100268=1279=0269=048=17359555=6SZ683=356623270=10213.0271=1346=11023=110=130
1128=99=18035=X49=SAMPLE75=2016101134=271352=2015102516002569349081660=201510251600256934908165799=10000100268=1279=1269=148=17359555=6SZ683=356624270=10214.0271=1346=11023=110=117
1128=99=25335=X49=SAMPLE75=2016101134=23952=2000090720074230975309660=200009072007423097530965799=10000100268=2279=2269=148=17359555=6SZ683=356625270=10214.0271=1346=11023=1279=0269=148=17359555=6SZ683=356626270=10225.0271=18346=61023=1010=009
1128=99=24935=X49=SAMPLE75=2016101134=200752=2016062722464025618790460=201606272246402561879045799=10000100268=2279=1269=148=17360055=6SH783=99185270=10271.0271=3346=11023=1279=1269=148=17360055=6SH783=99186270=10274.0271=5346=21023=410=040
1128=99=25035=X49=SAMPLE75=2016101134=188752=2016090405231044909152060=201609040523104490915205799=10000100268=2279=2269=148=17360055=6SH783=99187270=10271.0271=3346=11023=1279=0269=148=17360055=6SH783=99188270=10281.0271=3346=11023=1010=065
1128=99=18035=X49=SAMPLE75=2016101134=291652=2005121816265550314848060=200512181626555031484805799=10000100268=1279=0269=148=17359555=6SZ683=356627270=10214.0271=1346=11023=110=117
1128=99=25135=X49=SAMPLE75=2016101134=136952=2004090723023755741104060=200409072302375574110405799=10000100268=2279=1269=048=17359555=6SZ683=356628270=10211.0271=5346=41023=3279=1269=048=17359555=6SZ683=356629270=10210.0271=5346=31023=410=175
1128=99=17935=X49=SAMPLE75=2016101134=298652=2016111010105245193881660=201611101010524519388165799=10000100268=1279=0269=148=17360055=6SH783=99189270=10271.0271=3346=11023=110=056
1128=99=18035=X49=SAMPLE75=2016101134=152852=2009041323412633929376060=200904132341263392937605799=10000100268=1279=1269=148=17359555=6SZ683=356630270=10214.0271=2346=21023=110=136
1128=99=24935=X49=SAMPLE75=2016101134=95052=2002120416345480412601660=200212041634548041260165799=10000100268=2279=1269=148=17360055=6SH783=99190270=10273.0271=5346=21023=3279=1269=148=17360055=6SH783=99191270=10274.0271=3346=11023=410=042
1128=99=25235=X49=SAMPLE75=2016101134=403352=2003032420050314210387260=200303242005031421038725799=10000100268=2279=2269=048=17359555=6SZ683=356631270=10213.0271=1346=11023=1279=0269=048=17359555=6SZ683=356632270=10203.0271=4346=21023=1010=175
1128=99=18035=X49=SAMPLE75=2016101134=460552=2004072713174369310822460=200407271317436931082245799=10000100268=1279=1269=148=17359555=6SZ683=356633270=10214.0271=3346=31023=110=093
1128=99=25035=X49=SAMPLE75=2016101134=31052=2009091503462109383398460=200909150346210938339845799=10000100268=2279=2269=048=17360055=6SH783=99192270=10266.0271=3346=11023=1279=0269=048=17360055=6SH783=99193270=10256.0271=3346=11023=1010=032
1128=99=25135=X49=SAMPLE75=2016101134=32352=2016053111073651364595260=201605311107365136459525799=10000100268=2279=2269=048=17360055=6SH783=99194270=10265.0271=3346=11023=1279=0269=048=17360055=6SH783=99195270=10255.0271=61346=31023=1010=111
1128=99=18035=X49=SAMPLE75=2016101134=125652=2014102520314745407808060=201410252031474540780805799=10000100268=1279=1269=048=17359555=6SZ683=356634270=10212.0271=4346=41023=110=075
1128=99=18035=X49=SAMPLE75=2016101134=255952=2015020821364225602566460=201502082136422560256645799=10000100268=1279=1269=148=17359555=6SZ683=356635270=10214.0271=4346=41023=110=108
1128=99=18035=X49=SAMPLE75=2016101134=99852=2014021919105945820940860=201402191910594582094085799=10000100268=1279=1269=048=17359555=6SZ683=356636270=10212.0271=5346=51023=110=084
1128=99=18035=X49=SAMPLE75=2016101134=72752=2001062321150781156002460=200106232115078115600245799=10000100268=1279=1269=048=17359555=6SZ683=356637270=10211.0271=4346=31023=210=064
1128=99=18035=X49=SAMPLE75=2016101134=35452=2014041115153684527744060=201404111515368452774405799=10000100268=1279=1269=048=17359555=6SZ683=356638270=10212.0271=8346=61023=110=064
1128=99=17935=X49=SAMPLE75=2016101134=311752=2014062908174902067001660=201406290817490206700165799=10000100268=1279=0269=048=17360055=6SH783=99196270=10265.0271=3346=11023=110=247
1128=99=24935=X49=SAMPLE75=2016101134=452052=2009091310394812549196860=200909131039481254919685799=10000100268=2279=1269=048=17360055=6SH783=99197270=10264.0271=5346=21023=2279=1269=048=17360055=6SH783=99198270=10262.0271=3346=11023=410=232
1128=99=18035=X49=SAMPLE75=2016101134=191952=2017022303482658883340860=201702230348265888334085799=10000100268=1279=0269=048=17359555=6SZ683=356639270=10213.0271=1346=11023=110=045
1128=99=17935=X49=SAMPLE75=2016101134=113752=2004060620535544706956860=200406062053554470695685799=10000100268=1279=0269=048=17360055=6SH783=99199270=10266.0271=3346=11023=110=004
1128=99=25035=X49=SAMPLE75=2016101134=362452=2002112505254996842828860=200211250525499684282885799=10000100268=2279=2269=048=17360055=6SH783=99200270=10266.0271=3346=11023=1279=0269=048=17360055=6SH783=99201270=10256.0271=3346=11023=1010=009
1128=99=25235=X49=SAMPLE75=2016101134=376152=2011122310462847605459260=201112231046284760545925799=10000100268=2279=2269=048=17359555=6SZ683=356640270=10213.0271=1346=11023=1279=0269=048=17359555=6SZ683=356641270=10203.0271=4346=21023=1010=155
1128=99=25335=X49=SAMPLE75=2016101134=382152=2005040312322521646620860=200504031232252164662085799=10000100268=2279=1269=048=17359555=6SZ683=356642270=10209.0271=18346=51023=4279=1269=048=17359555=6SZ683=356643270=10205.0271=21346=71023=810=237
1128=99=18035=X49=SAMPLE75=2016101134=464252=2002082113584448109142460=200208211358444810914245799=10000100268=1279=1269=048=17360055=6SH783=99202270=10259.0271=11346=21023=710=060
1128=99=18035=X49=SAMPLE75=2016101134=323852=2015020311412218300332860=201502031141221830033285799=10000100268=1279=1269=148=17359555=6SZ683=356644270=10214.0271=3346=31023=110=097
1128=99=25035=X49=SAMPLE75=2016101134=77952=2013111401245179041536060=201311140124517904153605799=10000100268=2279=1269=048=17360055=6SH783=99203270=10261.0271=11346=21023=5279=1269=048=17360055=6SH783=99204270=10257.0271=3346=11023=910=011
1128=99=18135=X49=SAMPLE75=2016101134=122452=2013040104124079807123260=201304010412407980712325799=10000100268=1279=1269=048=17359555=6SZ683=356645270=10209.0271=10346=41023=410=144
1128=99=18135=X49=SAMPLE75=2016101134=192052=2010012505013262067763260=201001250501326206776325799=10000100268=1279=1269=048=17359555=6SZ683=356646270=10207.0271=16346=81023=610=143
1128=99=17935=X49=SAMPLE75=2016101134=384352=2002081306551191813588860=200208130655119181358885799=10000100268=1279=1269=048=17360055=6SH783=99205270=10261.0271=3346=11023=510=254
1128=99=17935=X49=SAMPLE75=2016101134=413152=2013121720535070833235260=201312172053507083323525799=10000100268=1279=1269=048=17360055=6SH783=99206270=10259.0271=3346=11023=710=006
1128=99=18035=X49=SAMPLE75=2016101134=129752=2007071320294525051440060=200707132029452505144005799=10000100268=1279=0269=148=17359555=6SZ683=356647270=10213.0271=1346=11023=110=064
1128=99=17935=X49=SAMPLE75=2016101134=414252=2002102018440461932476860=200210201844046193247685799=10000100268=1279=0269=148=17360055=6SH783=99207270=10269.0271=3346=11023=110=027
1128=99=17935=X49=SAMPLE75=2016101134=102752=2005120603365995121497660=200512060336599512149765799=10000100268=1279=0269=148=17360055=6SH783=99208270=10270.0271=3346=11023=210=001
1128=99=18035=X49=SAMPLE75=2016101134=257852=2007012806014751830761660=200701280601475183076165799=10000100268=1279=1269=048=17359555=6SZ683=356648270=10212.0271=7346=51023=110=087
1128=99=25135=X49=SAMPLE75=2016101134=97752=2000032611535204089067960=200003261153520408906795799=10000100268=2279=2269=148=17360055=6SH783=99209270=10269.0271=3346=11023=1279=0269=148=17360055=6SH783=99210270=10279.0271=11346=21023=1010=082
1128=99=18035=X49=SAMPLE75=2016101134=38752=2012021023231359125676860=201202102323135912567685799=10000100268=1279=1269=048=17359555=6SZ683=356649270=10212.0271=6346=41023=110=097
1128=99=25235=X49=SAMPLE75=2016101134=183852=2001041216294819160022460=200104121629481916002245799=10000100268=2279=2269=148=17359555=6SZ683=356650270=10213.0271=1346=11023=1279=0269=148=17359555=6SZ683=356651270=10223.0271=9346=31023=1010=164
1128=99=18035=X49=SAMPLE75=2016101134=340252=2014010214133930788691260=201401021413393078869125799=10000100268=1279=1269=048=17359555=6SZ683=356652270=10212.0271=7346=51023=110=080
1128=99=25135=X49=SAMPLE75=2016101134=152052=2007062211365492615161660=200706221136549261516165799=10000100268=2279=2269=148=17360055=6SH783=99211270=10270.0271=3346=11023=1279=0269=148=17360055=6SH783=99212270=10280.0271=53346=11023=1010=079
1128=99=18035=X49=SAMPLE75=2016101134=290952=2006110722153170854985660=200611072215317085498565799=10000100268=1279=1269=148=17359555=6SZ683=356653270=10215.0271=3346=11023=210=097
1128=99=18035=X49=SAMPLE75=2016101134=388552=2012031820235162586771260=201203182023516258677125799=10000100268=1279=1269=148=17359555=6SZ683=356654270=10214.0271=4346=41023=110=087
1128=99=18035=X49=SAMPLE75=2016101134=293552=2011021715553869512230460=201102171555386951223045799=10000100268=1279=1269=148=17359555=6SZ683=356655270=10214.0271=3346=31023=110=099
1128=99=18035=X49=SAMPLE75=2016101134=374252=2000080318001532073885260=200008031800153207388525799=10000100268=1279=0269=048=17359555=6SZ683=356656270=10213.0271=1346=11023=110=066
1128=99=17935=X49=SAMPLE75=2016101134=207352=2006111614224641082288060=200611161422464108228805799=10000100268=1279=0269=048=17360055=6SH783=99213270=10266.0271=3346=11023=110=007
1128=99=25035=X49=SAMPLE75=2016101134=37052=2008082212453980686985660=200808221245398068698565799=10000100268=2279=2269=048=17360055=6SH783=99214270=10266.0271=3346=11023=1279=0269=048=17360055=6SH783=99215270=10256.0271=3346=11023=1010=006
1128=99=18035=X49=SAMPLE75=2016101134=2252=2004122812024295264633660=200412281202429526463365799=10000100268=1279=1269=048=17359555=6SZ683=356657270=10211.0271=5346=41023=310=081
1128=99=18035=X49=SAMPLE75=2016101134=259052=2014031415321998683987260=201403141532199868398725799=10000100268=1279=1269=148=17359555=6SZ683=356658270=10215.0271=4346=21023=210=120
1128=99=18035=X49=SAMPLE75=2016101134=350152=2012070522494253832115260=201207052249425383211525799=10000100268=1279=1269=148=17359555=6SZ683=356659270=10215.0271=3346=11023=210=115
1128=99=18035=X49=SAMPLE75=2016101134=168752=2012111020305143220460860=201211102030514322046085799=10000100268=1279=1269=148=17359555=6SZ683=356660270=10214.0271=4346=41023=110=114
1128=99=18035=X49=SAMPLE75=2016101134=93852=2002032112112604363009660=200203211211260436300965799=10000100268=1279=1269=148=17359555=6SZ683=356661270=10214.0271=3346=31023=110=095
1128=99=18035=X49=SAMPLE75=2016101134=419952=2003022815363261043980860=200302281536326104398085799=10000100268=1279=1269=148=17359555=6SZ683=356662270=10215.0271=4346=21023=210=086
1128=99=18035=X49=SAMPLE75=2016101134=161452=2007051320281224308364860=200705132028122430836485799=10000100268=1279=1269=148=17359555=6SZ683=356663270=10215.0271=3346=11023=210=126
1128=99=18035=X49=SAMPLE75=2016101134=363352=2012090915441577725753660=201209091544157772575365799=10000100268=1279=1269=148=17359555=6SZ683=356664270=10214.0271=4346=41023=110=131
1128=99=18035=X49=SAMPLE75=2016101134=24552=2010062008533398951692860=201006200853339895169285799=10000100268=1279=1269=148=17359555=6SZ683=356665270=10214.0271=3346=31023=110=099
1128=99=25235=X49=SAMPLE75=2016101134=84152=2013010521461812488121660=201301052146181248812165799=10000100268=2279=1269=148=17359555=6SZ683=356666270=10218.0271=5346=31023=5279=1269=148=17359555=6SZ683=356667270=10222.0271=12346=31023=910=210
1128=99=18035=X49=SAMPLE75=2016101134=173552=2010032021204407283488060=201003202120440728348805799=10000100268=1279=1269=148=17359555=6SZ683=356668270=10215.0271=4346=21023=210=093
1128=99=20835=X49=SAMPLE75=2016101134=296852=2006081112405426462940860=200608111240542646294085799=00000001268=1279=0269=248=17359555=6SZ683=356669270=10213.0271=1346=25797=237705=237=032=137=032=110=072
1128=99=15635=X49=SAMPLE75=2016101134=61852=2007122522300448732832060=200712252230044873283205799=00000010268=1279=0269=e48=17359555=6SZ683=356670271=4110=088
1128=99=32435=X49=SAMPLE75=2016101134=175252=2000122216221538340486060=200012221622153834048605799=10000100268=3279=2269=048=17359555=6SZ683=356671270=10213.0271=1346=11023=1279=0269=048=17359555=6SZ683=356672270=10203.0271=4346=21023=10279=0269=148=17359555=6SZ683=356673270=10213.0271=13346=11023=110=015
1128=99=17935=X49=SAMPLE75=2016101134=310052=2009061813221072285382460=200906181322107228538245799=10000100268=1279=0269=148=17360055=6SH783=99216270=10269.0271=3346=11023=110=035
1128=99=18035=X49=SAMPLE75=2016101134=119352=2007031505505291747734460=200703150550529174773445799=10000100268=1279=1269=048=17359555=6SZ683=356674270=10212.0271=6346=41023=110=108
1128=99=18135=X49=SAMPLE75=2016101134=235352=2006032808500124054048060=200603280850012405404805799=10000100268=1279=1269=148=17359555=6SZ683=356675270=10213.0271=14346=21023=110=169
1128=99=18035=X49=SAMPLE75=2016101134=353452=2014123111292289335878460=201412311129228933587845799=10000100268=1279=1269=048=17359555=6SZ683=356676270=10212.0271=5346=31023=110=112
1128=99=17935=X49=SAMPLE75=2016101134=393652=2000091407370078200088060=200009140737007820008805799=10000100268=1279=0269=148=17360055=6SH783=99217270=10270.0271=3346=11023=210=040
1128=99=24935=X49=SAMPLE75=2016101134=274352=2012052302171342488230460=201205230217134248823045799=10000100268=2279=1269=148=17360055=6SH783=99218270=10270.0271=5346=21023=2279=1269=148=17360055=6SH783=99219270=10272.0271=3346=11023=410=251
1128=99=24935=X49=SAMPLE75=2016101134=213852=2000020510231835680536460=200002051023183568053645799=10000100268=2279=1269=148=17360055=6SH783=99220270=10271.0271=5346=21023=3279=1269=148=17360055=6SH783=99221270=10273.0271=3346=11023=510=006
1128=99=25135=X49=SAMPLE75=2016101134=296752=2013021905040023821132860=201302190504002382113285799=10000100268=2279=2269=048=17360055=6SH783=99222270=10265.0271=3346=11023=1279=0269=048=17360055=6SH783=99223270=10255.0271=53346=21023=1010=084
1128=99=18035=X49=SAMPLE75=2016101134=15952=2008040904545792527798460=200804090454579252779845799=10000100268=1279=1269=048=17359555=6SZ683=356677270=10212.0271=2346=21023=110=107
1128=99=25135=X49=SAMPLE75=2016101134=474952=2008110818051967079094460=200811081805196707909445799=10000100268=2279=1269=048=17359555=6SZ683=356678270=10212.0271=1346=11023=1279=1269=048=17359555=6SZ683=356679270=10208.0271=7346=41023=510=167
1128=99=18035=X49=SAMPLE75=2016101134=374452=2001030600510068066486460=200103060051006806648645799=10000100268=1279=1269=048=17359555=6SZ683=356680270=10211.0271=4346=31023=210=113
1128=99=24935=X49=SAMPLE75=2016101134=190652=2012051409091219690707260=201205140909121969070725799=10000100268=2279=1269=048=17360055=6SH783=99224270=10264.0271=3346=11023=1279=1269=048=17360055=6SH783=99225270=10261.0271=5346=21023=410=254
1128=99=25335=X49=SAMPLE75=2016101134=68752=2015032007225280269939260=201503200722528026993925799=10000100268=2279=1269=148=17359555=6SZ683=356681270=10218.0271=13346=41023=6279=1269=148=17359555=6SZ683=356682270=10222.0271=4346=21023=1010=008
1128=99=18035=X49=SAMPLE75=2016101134=496852=2012051210581170537792060=201205121058117053779205799=10000100268=1279=1269=148=17359555=6SZ683=356683270=10214.0271=6346=41023=210=126
1128=99=18035=X49=SAMPLE75=2016101134=142052=2008071511454397590304060=200807151145439759030405799=10000100268=1279=1269=148=17359555=6SZ683=356684270=10215.0271=3346=11023=310=093
1128=99=18035=X49=SAMPLE75=2016101134=424652=2004100705405354735420860=200410070540535473542085799=10000100268=1279=1269=148=17359555=6SZ683=356685270=10214.0271=7346=51023=210=118
1128=99=18035=X49=SAMPLE75=2016101134=454052=2016092401042602979475260=201609240104260297947525799=10000100268=1279=1269=048=17359555=6SZ683=356686270=10210.0271=6346=41023=310=096
1128=99=25335=X49=SAMPLE75=2016101134=311752=2014061217533516186336060=201406121753351618633605799=10000100268=2279=1269=048=17359555=6SZ683=356687270=10208.0271=10346=51023=5279=1269=048=17359555=6SZ683=356688270=10207.0271=13346=71023=610=251
1128=99=18035=X49=SAMPLE75=2016101134=231752=2005030808110778291081660=200503080811077829108165799=10000100268=1279=1269=048=17359555=6SZ683=356689270=10210.0271=5346=31023=310=099
1128=99=25335=X49=SAMPLE75=2016101134=334052=2015071821452735201152060=201507182145273520115205799=10000100268=2279=1269=148=17359555=6SZ683=356690270=10219.0271=18346=61023=7279=1269=148=17359555=6SZ683=356691270=10220.0271=15346=41023=810=027
1128=99=25135=X49=SAMPLE75=2016101134=336952=2006100700274358607324860=200610070027435860732485799=10000100268=2279=1269=048=17359555=6SZ683=356692270=10212.0271=2346=21023=1279=1269=048=17359555=6SZ683=356693270=10211.0271=3346=21023=210=131
1128=99=25135=X49=SAMPLE75=2016101134=408552=2011071116422218493228860=201107111642221849322885799=10000100268=2279=1269=148=17359555=6SZ683=356694270=10214.0271=6346=41023=2279=1269=148=17359555=6SZ683=356695270=10215.0271=4346=21023=310=171
1128=99=25135=X49=SAMPLE75=2016101134=341252=2006062409022323190044860=200606240902232319004485799=10000100268=2279=1269=048=17359555=6SZ683=356696270=10206.0271=5346=31023=7279=1269=048=17359555=6SZ683=356697270=10204.0271=3346=11023=910=170
1128=99=25235=X49=SAMPLE75=2016101134=291552=2002050501560515957840060=200205050156051595784005799=10000100268=2279=1269=048=17359555=6SZ683=356698270=10209.0271=13346=51023=4279=1269=048=17359555=6SZ683=356699270=10208.0271=7346=41023=510=224
1128=99=25335=X49=SAMPLE75=2016101134=118652=2003091122262095076812860=200309112226209507681285799=10000100268=2279=1269=048=17359555=6SZ683=356700270=10209.0271=10346=41023=4279=1269=048=17359555=6SZ683=356701270=10208.0271=10346=51023=510=001
1128=99=25235=X49=SAMPLE75=2016101134=405352=2002110421211964038558460=200211042121196403855845799=10000100268=2279=1269=048=17359555=6SZ683=356702270=10209.0271=13346=51023=4279=1269=048=17359555=6SZ683=356703270=10208.0271=7346=41023=510=213
1128=99=25335=X49=SAMPLE75=2016101134=154752=2015122720101446594726460=201512272010144659472645799=10000100268=2279=1269=048=17359555=6SZ683=356704270=10209.0271=10346=41023=4279=1269=048=17359555=6SZ683=356705270=10208.0271=10346=51023=510=252
1128=99=18135=X49=SAMPLE75=2016101134=70552=2001051218233431835548060=200105121823343183554805799=10000100268=1279=1269=048=17359555=6SZ683=356706270=10205.0271=22346=81023=810=167
1128=99=18135=X49=SAMPLE75=2016101134=379852=2005092904054873929520060=200509290405487392952005799=10000100268=1279=1269=048=17359555=6SZ683=356707270=10203.0271=5346=31023=1010=121
1128=99=25335=X49=SAMPLE75=2016101134=247952=2009041303362568109452860=200904130336256810945285799=10000100268=2279=1269=148=17359555=6SZ683=356708270=10219.0271=21346=71023=7279=1269=148=17359555=6SZ683=356709270=10220.0271=12346=31023=810=239
1128=99=25135=X49=SAMPLE75=2016101134=132652=2015120805254482645472060=201512080525448264547205799=10000100268=2279=1269=048=17359555=6SZ683=356710270=10212.0271=1346=11023=1279=1269=048=17359555=6SZ683=356711270=10211.0271=4346=31023=210=111
1128=99=25135=X49=SAMPLE75=2016101134=70452=2016080500372714596268860=201608050037271459626885799=10000100268=2279=1269=148=17359555=6SZ683=356712270=10214.0271=7346=51023=2279=1269=148=17359555=6SZ683=356713270=10215.0271=3346=11023=310=117
1128=99=18035=X49=SAMPLE75=2016101134=283652=2010080107540605804192060=201008010754060580419205799=10000100268=1279=1269=048=17359555=6SZ683=356714270=10210.0271=6346=41023=310=069
1128=99=18135=X49=SAMPLE75=2016101134=331252=2015092901425620090784060=201509290142562009078405799=10000100268=1279=1269=148=17359555=6SZ683=356715270=10216.0271=14346=61023=410=138
1128=99=25235=X49=SAMPLE75=2016101134=482552=2015020802183876513708860=201502080218387651370885799=10000100268=2279=1269=048=17359555=6SZ683=356716270=10209.0271=13346=51023=4279=1269=048=17359555=6SZ683=356717270=10208.0271=7346=41023=510=167
1128=99=25335=X49=SAMPLE75=2016101134=222352=2007091216062098399488060=200709121606209839948805799=10000100268=2279=1269=148=17359555=6SZ683=356718270=10219.0271=18346=61023=7279=1269=148=17359555=6SZ683=356719270=10220.0271=15346=41023=810=002
1128=99=25135=X49=SAMPLE75=2016101134=269852=2014042500545775473286460=201404250054577547328645799=10000100268=2279=1269=148=17359555=6SZ683=356720270=10214.0271=6346=41023=2279=1269=148=17359555=6SZ683=356721270=10215.0271=4346=21023=310=118
1128=99=25135=X49=SAMPLE75=2016101134=311652=2011050103225535071200060=201105010322553507120005799=10000100268=2279=1269=048=17359555=6SZ683=356722270=10212.0271=2346=21023=1279=1269=048=17359555=6SZ683=356723270=10211.0271=3346=21023=210=116
1128=99=18135=X49=SAMPLE75=2016101134=113052=2008020809093688997385660=200802080909368899738565799=10000100268=1279=1269=048=17359555=6SZ683=356724270=10209.0271=14346=61023=410=145
1128=99=18035=X49=SAMPLE75=2016101134=433852=2000032515090343360808060=200003251509034336080805799=10000100268=1279=1269=148=17359555=6SZ683=356725270=10217.0271=5346=31023=510=093
1128=99=25335=X49=SAMPLE75=2016101134=58352=2004122300592839945555260=200412230059283994555525799=10000100268=2279=1269=048=17359555=6SZ683=356726270=10209.0271=11346=51023=4279=1269=048=17359555=6SZ683=356727270=10208.0271=10346=51023=510=225
1128=99=25335=X49=SAMPLE75=2016101134=90052=2004010712535595625304060=200401071253559562530405799=10000100268=2279=1269=148=17359555=6SZ683=356728270=10219.0271=21346=71023=7279=1269=148=17359555=6SZ683=356729270=10220.0271=12346=31023=810=243
1128=99=25135=X49=SAMPLE75=2016101134=327952=2007092622593025713219260=200709262259302571321925799=10000100268=2279=1269=148=17359555=6SZ683=356730270=10214.0271=7346=51023=2279=1269=148=17359555=6SZ683=356731270=10215.0271=3346=11023=310=118
1128=99=25135=X49=SAMPLE75=2016101134=56852=2017010917563016872428860=201701091756301687242885799=10000100268=2279=1269=048=17359555=6SZ683=356732270=10212.0271=1346=11023=1279=1269=048=17359555=6SZ683=356733270=10211.0271=4346=31023=210=112
1128=99=18135=X49=SAMPLE75=2016101134=473652=2002012715593143313314460=200201271559314331331445799=10000100268=1279=1269=048=17359555=6SZ683=356734270=10208.0271=11346=61023=510=127
1128=99=18135=X49=SAMPLE75=2016101134=277052=2015071408470056472985660=201507140847005647298565799=10000100268=1279=1269=148=17359555=6SZ683=356735270=10218.0271=14346=51023=610=140
1128=99=17835=X49=SAMPLE75=2016101134=187652=2015060219034520349715260=201506021903452034971525799=00000100268=1279=0269=048=17364055=6SH883=1592270=10440.0271=5346=11023=110=214
1128=99=16735=X49=SAMPLE75=2016101134=316752=2007042005213580207043260=200704200521358020704325799=10001000268=1279=0269=N48=17364055=6SH883=1593270=10440.0286=25510=032
1128=99=25335=X49=SAMPLE75=2016101134=26752=2011070222081073671737660=201107022208107367173765799=10000100268=2279=1269=148=17359555=6SZ683=356736270=10219.0271=18346=61023=7279=1269=148=17359555=6SZ683=356737270=10220.0271=15346=41023=810=023
1128=99=25135=X49=SAMPLE75=2016101134=420752=2001122515510152530119260=200112251551015253011925799=10000100268=2279=1269=048=17359555=6SZ683=356738270=10212.0271=2346=21023=1279=1269=048=17359555=6SZ683=356739270=10211.0271=3346=21023=210=148
1128=99=25135=X49=SAMPLE75=2016101134=108652=2013081216140615710873660=201308121614061571087365799=10000100268=2279=1269=148=17359555=6SZ683=356740270=10214.0271=6346=41023=2279=1269=148=17359555=6SZ683=356741270=10215.0271=4346=21023=310=143
1128=99=18135=X49=SAMPLE75=2016101134=303652=2008111512280989302611260=200811151228098930261125799=10000100268=1279=1269=048=17359555=6SZ683=356742270=10207.0271=14346=81023=610=165
1128=99=18135=X49=SAMPLE75=2016101134=183052=2009060312261720737260860=200906031226172073726085799=10000100268=1279=1269=148=17359555=6SZ683=356743270=10219.0271=19346=71023=710=171
1128=99=25335=X49=SAMPLE75=2016101134=434852=2000123107134833226645660=200012310713483322664565799=10000100268=2279=1269=148=17359555=6SZ683=356744270=10219.0271=22346=81023=7279=1269=148=17359555=6SZ683=356745270=10220.0271=12346=31023=810=245
1128=99=25135=X49=SAMPLE75=2016101134=401052=2009060517221400663078460=200906051722140066307845799=10000100268=2279=1269=048=17359555=6SZ683=356746270=10212.0271=1346=11023=1279=1269=048=17359555=6SZ683=356747270=10211.0271=4346=31023=210=140
1128=99=25135=X49=SAMPLE75=2016101134=303752=2001040904185613906871260=200104090418561390687125799=10000100268=2279=1269=148=17359555=6SZ683=356748270=10214.0271=7346=51023=2279=1269=148=17359555=6SZ683=356749270=10215.0271=3346=11023=310=163
1128=99=18035=X49=SAMPLE75=2016101134=47252=2003081219211186635576060=200308121921118663557605799=10000100268=1279=1269=048=17359555=6SZ683=356750270=10206.0271=6346=41023=710=096
1128=99=18135=X49=SAMPLE75=2016101134=436452=2001103119535312586029660=200110311953531258602965799=10000100268=1279=1269=148=17359555=6SZ683=356751270=10220.0271=13346=41023=810=129
1128=99=17835=X49=SAMPLE75=2016101134=274452=2004120400265068056809660=200412040026506805680965799=00000100268=1279=0269=148=17364055=6SH883=1594270=10576.0271=5346=11023=110=247
1128=99=16735=X49=SAMPLE75=2016101134=272152=2000020215530546899981460=200002021553054689998145799=10001000268=1279=0269=O48=17364055=6SH883=1595270=10576.0286=25510=065
1128=99=17835=X49=SAMPLE75=2016101134=441552=2012011118543484957696060=201201111854348495769605799=00000100268=1279=0269=048=17362555=6SZ783=1729270=10383.0271=5346=11023=110=012
1128=99=16735=X49=SAMPLE75=2016101134=295852=2012070614320891294316860=201207061432089129431685799=10001000268=1279=0269=N48=17362555=6SZ783=1730270=10383.0286=25510=077
1128=99=17835=X49=SAMPLE75=2016101134=298252=2006072501273249668540860=200607250127324966854085799=00000100268=1279=0269=148=17362555=6SZ783=1731270=10513.0271=5346=11023=110=015
1128=99=16735=X49=SAMPLE75=2016101134=143352=2000032913470184798295960=200003291347018479829595799=10001000268=1279=0269=O48=17362555=6SZ783=1732270=10513.0286=25510=089
1128=99=25235=X49=SAMPLE75=2016101134=45252=2014060410131556883436860=201406041013155688343685799=10000100268=2279=1269=048=17359555=6SZ683=356752270=10208.0271=8346=51023=5279=1269=048=17359555=6SZ683=356753270=10207.0271=17346=91023=610=249
1128=99=25335=X49=SAMPLE75=2016101134=236052=2000122616434868255236060=200012261643486825523605799=10000100268=2279=1269=048=17359555=6SZ683=356754270=10208.0271=11346=61023=5279=1269=048=17359555=6SZ683=356755270=10207.0271=14346=81023=610=018
1128=99=25235=X49=SAMPLE75=2016101134=306052=2003101105483976460684860=200310110548397646068485799=10000100268=2279=1269=048=17359555=6SZ683=356756270=10208.0271=8346=51023=5279=1269=048=17359555=6SZ683=356757270=10207.0271=17346=91023=610=194
1128=99=25335=X49=SAMPLE75=2016101134=391652=2010102508285380220000060=201010250828538022000005799=10000100268=2279=1269=048=17359555=6SZ683=356758270=10208.0271=11346=61023=5279=1269=048=17359555=6SZ683=356759270=10207.0271=14346=81023=610=006
1128=99=25235=X49=SAMPLE75=2016101134=461152=2000011206264609753897860=200001120626460975389785799=10000100268=2279=1269=048=17359555=6SZ683=356760270=10208.0271=8346=51023=5279=1269=048=17359555=6SZ683=356761270=10207.0271=17346=91023=610=207
1128=99=25335=X49=SAMPLE75=2016101134=297052=2004052112325262347827260=200405211232526234782725799=10000100268=2279=1269=048=17359555=6SZ683=356762270=10208.0271=11346=61023=5279=1269=048=17359555=6SZ683=356763270=10207.0271=14346=81023=610=008
1128=99=25235=X49=SAMPLE75=2016101134=258052=2010010122281840729459260=201001012228184072945925799=10000100268=2279=1269=048=17359555=6SZ683=356764270=10208.0271=8346=51023=5279=1269=048=17359555=6SZ683=356765270=10207.0271=17346=91023=610=209
1128=99=25335=X49=SAMPLE75=2016101134=144852=2013030320321549560396860=201303032032154956039685799=10000100268=2279=1269=048=17359555=6SZ683=356766270=10208.0271=11346=61023=5279=1269=048=17359555=6SZ683=356767270=10207.0271=14346=81023=610=010
1128=99=25235=X49=SAMPLE75=2016101134=752=2013011521242702899520060=201301152124270289952005799=10000100268=2279=1269=048=17359555=6SZ683=356768270=10208.0271=8346=51023=5279=1269=048=17359555=6SZ683=356769270=10207.0271=17346=91023=610=253
1128=99=25335=X49=SAMPLE75=2016101134=348352=2004091005392488758240060=200409100539248875824005799=10000100268=2279=1269=048=17359555=6SZ683=356770270=10208.0271=11346=61023=5279=1269=048=17359555=6SZ683=356771270=10207.0271=14346=81023=610=018
1128=99=17835=X49=SAMPLE75=2016101134=92252=2012072601213110092966460=201207260121311009296645799=10000100268=1279=0269=048=17360355=6SM783=7541270=10281.0271=6346=11023=410=254
1128=99=17835=X49=SAMPLE75=2016101134=349352=2008073009171498637337660=200807300917149863733765799=10000100268=1279=0269=148=17360355=6SM783=7542270=10372.0271=6346=11023=410=012
1128=99=25335=X49=SAMPLE75=2016101134=348452=2003100609444375560220860=200310060944437556022085799=10000100268=2279=1269=148=17359555=6SZ683=356772270=10219.0271=19346=71023=7279=1269=148=17359555=6SZ683=356773270=10220.0271=16346=51023=810=051
1128=99=25135=X49=SAMPLE75=2016101134=27952=2015100716170157911884860=201510071617015791188485799=10000100268=2279=1269=048=17359555=6SZ683=356774270=10212.0271=2346=21023=1279=1269=048=17359555=6SZ683=356775270=10211.0271=3346=21023=210=168
1128=99=25135=X49=SAMPLE75=2016101134=99252=2007052801400329980000060=200705280140032998000005799=10000100268=2279=1269=148=17359555=6SZ683=356776270=10214.0271=6346=41023=2279=1269=148=17359555=6SZ683=356777270=10215.0271=4346=21023=310=178
1128=99=18135=X49=SAMPLE75=2016101134=458652=2011102303155115541760060=201110230315511554176005799=10000100268=1279=1269=048=17359555=6SZ683=356778270=10205.0271=23346=91023=810=168
1128=99=25335=X49=SAMPLE75=2016101134=362952=2002031320153242250360860=200203132015324225036085799=10000100268=2279=1269=148=17359555=6SZ683=356779270=10219.0271=22346=81023=7279=1269=148=17359555=6SZ683=356780270=10220.0271=13346=41023=810=039
1128=99=25135=X49=SAMPLE75=2016101134=393652=2016081009053353385414460=201608100905335338541445799=10000100268=2279=1269=048=17359555=6SZ683=356781270=10212.0271=1346=11023=1279=1269=048=17359555=6SZ683=356782270=10211.0271=4346=31023=210=166
1128=99=25135=X49=SAMPLE75=2016101134=347952=2007100716380673608278460=200710071638067360827845799=10000100268=2279=1269=148=17359555=6SZ683=356783270=10214.0271=7346=51023=2279=1269=148=17359555=6SZ683=356784270=10215.0271=3346=11023=310=171
1128=99=18035=X49=SAMPLE75=2016101134=191352=2006122708161720182403260=200612270816172018240325799=10000100268=1279=1269=048=17359555=6SZ683=356785270=10204.0271=4346=21023=910=142
1128=99=25335=X49=SAMPLE75=2016101134=336052=2015091004424318157836860=201509100442431815783685799=10000100268=2279=1269=148=17359555=6SZ683=356786270=10219.0271=19346=71023=7279=1269=148=17359555=6SZ683=356787270=10220.0271=16346=51023=810=037
1128=99=25135=X49=SAMPLE75=2016101134=216552=2001110516470296889579260=200111051647029688957925799=10000100268=2279=1269=148=17359555=6SZ683=356788270=10214.0271=6346=41023=2279=1269=148=17359555=6SZ683=356789270=10215.0271=4346=21023=310=159
1128=99=25135=X49=SAMPLE75=2016101134=294052=2007082807491611541968060=200708280749161154196805799=10000100268=2279=1269=048=17359555=6SZ683=356790270=10212.0271=2346=21023=1279=1269=048=17359555=6SZ683=356791270=10211.0271=3346=21023=210=150
1128=99=18035=X49=SAMPLE75=2016101134=230152=2015101601490368614918460=201510160149036861491845799=10000100268=1279=1269=148=17359555=6SZ683=356792270=10218.0271=6346=41023=610=108
1128=99=17935=X49=SAMPLE75=2016101134=193952=2011011611565871304147260=201101161156587130414725799=10000100268=1279=1269=148=17360055=6SH783=99226270=10277.0271=3346=11023=910=035
1128=99=18035=X49=SAMPLE75=2016101134=327852=2006060820524932415907260=200606082052493241590725799=10000100268=1279=1269=148=17359555=6SZ683=356793270=10220.0271=8346=41023=810=127
1128=99=25235=X49=SAMPLE75=2016101134=460452=2009091320005935581587260=200909132000593558158725799=10000100268=2279=1269=148=17359555=6SZ683=356794270=10219.0271=22346=81023=7279=1269=148=17359555=6SZ683=356795270=10220.0271=5346=31023=810=224
1128=99=25135=X49=SAMPLE75=2016101134=123052=2009060808174894297766460=200906080817489429776645799=10000100268=2279=1269=048=17359555=6SZ683=356796270=10212.0271=1346=11023=1279=1269=048=17359555=6SZ683=356797270=10211.0271=4346=31023=210=141
1128=99=25135=X49=SAMPLE75=2016101134=341152=2010122815283966645926460=201012281528396664592645799=10000100268=2279=1269=148=17359555=6SZ683=356798270=10214.0271=7346=51023=2279=1269=148=17359555=6SZ683=356799270=10215.0271=3346=11023=310=170
1128=99=25235=X49=SAMPLE75=2016101134=253152=2013110703521924783347260=201311070352192478334725799=10000100268=2279=1269=148=17359555=6SZ683=356800270=10219.0271=19346=71023=7279=1269=148=17359555=6SZ683=356801270=10220.0271=8346=41023=810=212
1128=99=25135=X49=SAMPLE75=2016101134=498252=2005091907003449818643260=200509190700344981864325799=10000100268=2279=1269=048=17359555=6SZ683=356802270=10212.0271=2346=21023=1279=1269=048=17359555=6SZ683=356803270=10211.0271=3346=21023=210=113
1128=99=25135=X49=SAMPLE75=2016101134=75852=2002081221222496427948860=200208122122249642794885799=10000100268=2279=1269=148=17359555=6SZ683=356804270=10214.0271=6346=41023=2279=1269=148=17359555=6SZ683=356805270=10215.0271=4346=21023=310=172
1128=99=25235=X49=SAMPLE75=2016101134=391752=2009111818211791276736060=200911181821179127673605799=10000100268=2279=1269=148=17359555=6SZ683=356806270=10219.0271=22346=81023=7279=1269=148=17359555=6SZ683=356807270=10220.0271=5346=31023=810=204
1128=99=25135=X49=SAMPLE75=2016101134=188652=2011022102311158450361660=201102210231115845036165799=10000100268=2279=1269=048=17359555=6SZ683=356808270=10212.0271=1346=11023=1279=1269=048=17359555=6SZ683=356809270=10211.0271=4346=31023=210=151
1128=99=25135=X49=SAMPLE75=2016101134=317552=2000100601542183612284060=200010060154218361228405799=10000100268=2279=1269=148=17359555=6SZ683=356810270=10214.0271=7346=51023=2279=1269=148=17359555=6SZ683=356811270=10215.0271=3346=11023=310=133
1128=99=25235=X49=SAMPLE75=2016101134=461452=2009070411054352421100860=200907041105435242110085799=10000100268=2279=1269=148=17359555=6SZ683=356812270=10219.0271=19346=71023=7279=1269=148=17359555=6SZ683=356813270=10220.0271=8346=41023=810=198
1128=99=25135=X49=SAMPLE75=2016101134=416552=2010041407021706571744060=201004140702170657174405799=10000100268=2279=1269=048=17359555=6SZ683=356814270=10212.0271=2346=21023=1279=1269=048=17359555=6SZ683=356815270=10211.0271=3346=21023=210=117
1128=99=25135=X49=SAMPLE75=2016101134=89652=2013122723294560399532860=201312272329456039953285799=10000100268=2279=1269=148=17359555=6SZ683=356816270=10214.0271=6346=41023=2279=1269=148=17359555=6SZ683=356817270=10215.0271=4346=21023=310=110
1128=99=25235=X49=SAMPLE75=2016101134=453852=2006021613334822308556860=200602161333482230855685799=10000100268=2279=1269=048=17359555=6SZ683=356818270=10209.0271=14346=61023=4279=1269=048=17359555=6SZ683=356819270=10208.0271=8346=51023=510=223
1128=99=25335=X49=SAMPLE75=2016101134=176552=2014012121343081613068860=201401212134308161306885799=10000100268=2279=1269=048=17359555=6SZ683=356820270=10209.0271=11346=51023=4279=1269=048=17359555=6SZ683=356821270=10208.0271=11346=61023=510=222
1128=99=25235=X49=SAMPLE75=2016101134=165252=2007102103433976110070460=200710210343397611007045799=10000100268=2279=1269=148=17359555=6SZ683=356822270=10219.0271=22346=81023=7279=1269=148=17359555=6SZ683=356823270=10220.0271=5346=31023=810=187
1128=99=25135=X49=SAMPLE75=2016101134=102052=2014081408501388298009660=201408140850138829800965799=10000100268=2279=1269=048=17359555=6SZ683=356824270=10212.0271=1346=11023=1279=1269=048=17359555=6SZ683=356825270=10211.0271=4346=31023=210=108
1128=99=25135=X49=SAMPLE75=2016101134=232652=2015080420215222057254460=201508042021522205725445799=10000100268=2279=1269=148=17359555=6SZ683=356826270=10214.0271=7346=51023=2279=1269=148=17359555=6SZ683=356827270=10215.0271=3346=11023=310=160
1128=99=25235=X49=SAMPLE75=2016101134=44952=2012061311141597288844860=201206131114159728884485799=10000100268=2279=1269=148=17359555=6SZ683=356828270=10219.0271=19346=71023=7279=1269=148=17359555=6SZ683=356829270=10220.0271=8346=41023=810=205
1128=99=25135=X49=SAMPLE75=2016101134=351852=2006022815203349398665660=200602281520334939866565799=10000100268=2279=1269=048=17359555=6SZ683=356830270=10212.0271=2346=21023=1279=1269=048=17359555=6SZ683=356831270=10211.0271=3346=21023=210=107
1128=99=25135=X49=SAMPLE75=2016101134=202852=2011053104101966931251260=201105310410196693125125799=10000100268=2279=1269=148=17359555=6SZ683=356832270=10214.0271=6346=41023=2279=1269=148=17359555=6SZ683=356833270=10215.0271=4346=21023=310=122
1128=99=25235=X49=SAMPLE75=2016101134=183952=2016070907570630102438460=201607090757063010243845799=10000100268=2279=1269=048=17359555=6SZ683=356834270=10209.0271=14346=61023=4279=1269=048=17359555=6SZ683=356835270=10208.0271=8346=51023=510=218
1128=99=25335=X49=SAMPLE75=2016101134=448152=2011111522060564482976060=201111152206056448297605799=10000100268=2279=1269=048=17359555=6SZ683=356836270=10209.0271=11346=51023=4279=1269=048=17359555=6SZ683=356837270=10208.0271=11346=61023=510=253
1128=99=25235=X49=SAMPLE75=2016101134=16652=2003073006582176278523260=200307300658217627852325799=10000100268=2279=1269=148=17359555=6SZ683=356838270=10219.0271=22346=81023=7279=1269=148=17359555=6SZ683=356839270=10220.0271=5346=31023=810=253
1128=99=25135=X49=SAMPLE75=2016101134=306352=2017012019205732120403260=201701201920573212040325799=10000100268=2279=1269=048=17359555=6SZ683=356840270=10212.0271=1346=11023=1279=1269=048=17359555=6SZ683=356841270=10211.0271=4346=31023=210=160
1128=99=25135=X49=SAMPLE75=2016101134=6752=2017011618453352507833660=201701161845335250783365799=10000100268=2279=1269=148=17359555=6SZ683=356842270=10214.0271=7346=51023=2279=1269=148=17359555=6SZ683=356843270=10215.0271=3346=11023=310=191
1128=99=25235=X49=SAMPLE75=2016101134=246252=2007101003515804147078460=200710100351580414707845799=10000100268=2279=1269=148=17359555=6SZ683=356844270=10219.0271=19346=71023=7279=1269=148=17359555=6SZ683=356845270=10220.0271=8346=41023=810=238
1128=99=25135=X49=SAMPLE75=2016101134=439652=2011120421091477979206460=201112042109147797920645799=10000100268=2279=1269=148=17359555=6SZ683=356846270=10214.0271=6346=41023=2279=1269=148=17359555=6SZ683=356847270=10215.0271=4346=21023=310=168
1128=99=25135=X49=SAMPLE75=2016101134=478552=2004050508391132732753660=200405050839113273275365799=10000100268=2279=1269=048=17359555=6SZ683=356848270=10212.0271=2346=21023=1279=1269=048=17359555=6SZ683=356849270=10211.0271=3346=21023=210=149
1128=99=18035=X49=SAMPLE75=2016101134=272452=2010061510463061665216060=201006151046306166521605799=10000100268=1279=1269=048=17359555=6SZ683=356850270=10212.0271=3346=31023=110=099
1128=99=24935=X49=SAMPLE75=2016101134=129252=2001032704303097290865660=200103270430309729086565799=10000100268=2279=1269=048=17360055=6SH783=99227270=10262.0271=5346=21023=3279=1269=048=17360055=6SH783=99228270=10261.0271=3346=11023=410=035
1128=99=18035=X49=SAMPLE75=2016101134=428952=2006022213484445606310460=200602221348444560631045799=10000100268=1279=1269=048=17359555=6SZ683=356851270=10212.0271=2346=21023=110=120
1128=99=18035=X49=SAMPLE75=2016101134=373252=2007020502254805662310460=200702050225480566231045799=10000100268=1279=1269=048=17359555=6SZ683=356852270=10208.0271=9346=51023=510=133
1128=99=25235=X49=SAMPLE75=2016101134=480852=2002121507132812025201660=200212150713281202520165799=10000100268=2279=1269=148=17359555=6SZ683=356853270=10219.0271=22346=81023=7279=1269=148=17359555=6SZ683=356854270=10220.0271=5346=31023=810=209
1128=99=25135=X49=SAMPLE75=2016101134=445852=2004041107420607321721660=200404110742060732172165799=10000100268=2279=1269=048=17359555=6SZ683=356855270=10212.0271=1346=11023=1279=1269=048=17359555=6SZ683=356856270=10211.0271=4346=31023=210=129
1128=99=25135=X49=SAMPLE75=2016101134=321652=2012062122062558244819260=201206212206255824481925799=10000100268=2279=1269=148=17359555=6SZ683=356857270=10214.0271=7346=51023=2279=1269=148=17359555=6SZ683=356858270=10215.0271=3346=11023=310=146
1128=99=25235=X49=SAMPLE75=2016101134=1952=2016071306495020857286460=201607130649502085728645799=10000100268=2279=1269=148=17359555=6SZ683=356859270=10219.0271=19346=71023=7279=1269=148=17359555=6SZ683=356860270=10220.0271=8346=41023=810=225
1128=99=25135=X49=SAMPLE75=2016101134=235652=2002011418165014947160060=200201141816501494716005799=10000100268=2279=1269=048=17359555=6SZ683=356861270=10212.0271=2346=21023=1279=1269=048=17359555=6SZ683=356862270=10211.0271=3346=21023=210=135
1128=99=25135=X49=SAMPLE75=2016101134=101952=2011022007545905334208060=201102200754590533420805799=10000100268=2279=1269=148=17359555=6SZ683=356863270=10214.0271=6346=41023=2279=1269=148=17359555=6SZ683=356864270=10215.0271=4346=21023=310=150
1128=99=18135=X49=SAMPLE75=2016101134=70752=2014012117393423755513660=201401211739342375551365799=10000100268=1279=1269=148=17359555=6SZ683=356865270=10216.0271=11346=51023=410=146
1128=99=18035=X49=SAMPLE75=2016101134=376552=2009110222562639387481660=200911022256263938748165799=10000100268=1279=1269=148=17359555=6SZ683=356866270=10216.0271=8346=41023=410=136
1128=99=18035=X49=SAMPLE75=2016101134=384852=2014052118254665078022460=201405211825466507802245799=10000100268=1279=1269=148=17359555=6SZ683=356867270=10216.0271=5346=31023=410=115
1128=99=18035=X49=SAMPLE75=2016101134=443852=2003011116050068609776060=200301111605006860977605799=10000100268=1279=1269=048=17359555=6SZ683=356868270=10209.0271=8346=41023=410=112
1128=99=18035=X49=SAMPLE75=2016101134=435352=2008082002585814539756860=200808200258581453975685799=10000100268=1279=1269=048=17359555=6SZ683=356869270=10209.0271=5346=31023=410=086
1128=99=18135=X49=SAMPLE75=2016101134=160952=2000091315112228205866460=200009131511222820586645799=10000100268=1279=1269=048=17359555=6SZ683=356870270=10207.0271=11346=71023=610=161
1128=99=18135=X49=SAMPLE75=2016101134=195052=2009100215115133631731260=200910021511513363173125799=10000100268=1279=1269=148=17359555=6SZ683=356871270=10219.0271=16346=61023=710=156
1128=99=18135=X49=SAMPLE75=2016101134=397552=2009071713295579776588860=200907171329557977658885799=10000100268=1279=1269=148=17359555=6SZ683=356872270=10219.0271=13346=51023=710=180
1128=99=18135=X49=SAMPLE75=2016101134=195152=2002030509443226422779260=200203050944322642277925799=10000100268=1279=1269=148=17359555=6SZ683=356873270=10219.0271=10346=41023=710=149
1128=99=18035=X49=SAMPLE75=2016101134=164352=2005112001045137038489660=200511200104513703848965799=10000100268=1279=1269=148=17359555=6SZ683=356874270=10219.0271=7346=31023=710=108
1128=99=18035=X49=SAMPLE75=2016101134=381352=2001040206321210975353660=200104020632121097535365799=10000100268=1279=1269=048=17359555=6SZ683=356875270=10207.0271=8346=61023=610=109
1128=99=18035=X49=SAMPLE75=2016101134=201352=2005071904574498105766460=200507190457449810576645799=10000100268=1279=1269=148=17359555=6SZ683=356876270=10219.0271=4346=21023=710=127
1128=99=18135=X49=SAMPLE75=2016101134=73252=2010011005475800948313660=201001100547580094831365799=10000100268=1279=1269=048=17359555=6SZ683=356877270=10205.0271=20346=81023=810=146
1128=99=18135=X49=SAMPLE75=2016101134=307152=2008060708410267321264060=200806070841026732126405799=10000100268=1279=1269=048=17359555=6SZ683=356878270=10205.0271=17346=71023=810=170
1128=99=18135=X49=SAMPLE75=2016101134=314152=2001091323225116665092060=200109132322511666509205799=10000100268=1279=1269=048=17359555=6SZ683=356879270=10205.0271=14346=61023=810=159
1128=99=18135=X49=SAMPLE75=2016101134=141452=2012021101470651681075260=201202110147065168107525799=10000100268=1279=1269=048=17359555=6SZ683=356880270=10205.0271=11346=51023=810=152
1128=99=18035=X49=SAMPLE75=2016101134=363252=2004021606470460212166460=200402160647046021216645799=10000100268=1279=1269=048=17359555=6SZ683=356881270=10205.0271=8346=41023=810=117
1128=99=18035=X49=SAMPLE75=2016101134=404652=2001123005493033734664060=200112300549303373466405799=10000100268=1279=1269=048=17359555=6SZ683=356882270=10205.0271=5346=31023=810=120
1128=99=18035=X49=SAMPLE75=2016101134=228152=2014060509471320952390460=201406050947132095239045799=10000100268=1279=1269=148=17359555=6SZ683=356883270=10221.0271=9346=31023=910=105
1128=99=18035=X49=SAMPLE75=2016101134=406052=2002012320573769992246460=200201232057376999224645799=10000100268=1279=1269=148=17359555=6SZ683=356884270=10221.0271=6346=21023=910=102
1128=99=18035=X49=SAMPLE75=2016101134=146352=2006122023024857602400060=200612202302485760240005799=10000100268=1279=1269=148=17359555=6SZ683=356885270=10221.0271=3346=11023=910=124
1128=99=18035=X49=SAMPLE75=2016101134=264552=2012082212141143472256060=201208221214114347225605799=10000100268=1279=1269=148=17359555=6SZ683=356886270=10218.0271=5346=31023=610=108
1128=99=18035=X49=SAMPLE75=2016101134=441852=2011040123024271571872060=201104012302427157187205799=10000100268=1279=1269=148=17359555=6SZ683=356887270=10218.0271=4346=21023=610=133
1128=99=18035=X49=SAMPLE75=2016101134=458752=2001092401264728091464060=200109240126472809146405799=10000100268=1279=1269=048=17359555=6SZ683=356888270=10204.0271=7346=31023=910=112
1128=99=18035=X49=SAMPLE75=2016101134=268852=2009033020224730951366460=200903302022473095136645799=10000100268=1279=1269=048=17359555=6SZ683=356889270=10212.0271=3346=31023=110=100
1128=99=18035=X49=SAMPLE75=2016101134=157352=2015042201181014014022460=201504220118101401402245799=10000100268=1279=1269=048=17359555=6SZ683=356890270=10205.0271=8346=41023=810=126
1128=99=18135=X49=SAMPLE75=2016101134=391852=2013121107112763457644860=201312110711276345764485799=10000100268=1279=1269=048=17359555=6SZ683=356891270=10205.0271=11346=51023=810=174
1128=99=18035=X49=SAMPLE75=2016101134=62052=2015042215161333358009660=201504221516133335800965799=10000100268=1279=1269=048=17359555=6SZ683=356892270=10204.0271=4346=21023=910=093
1128=99=25135=X49=SAMPLE75=2016101134=93652=2015082423581550869670460=201508242358155086967045799=10000100268=2279=1269=048=17359555=6SZ683=356893270=10209.0271=8346=41023=4279=1269=048=17359555=6SZ683=356894270=10208.0271=6346=41023=510=184
1128=99=25135=X49=SAMPLE75=2016101134=123752=2014032908073565658950460=201403290807356565895045799=10000100268=2279=1269=048=17359555=6SZ683=356895270=10209.0271=5346=31023=4279=1269=048=17359555=6SZ683=356896270=10208.0271=9346=51023=510=164
1128=99=25135=X49=SAMPLE75=2016101134=40952=2011062512481156011360060=201106251248115601136005799=10000100268=2279=1269=048=17359555=6SZ683=356897270=10209.0271=8346=41023=4279=1269=048=17359555=6SZ683=356898270=10208.0271=6346=41023=510=194
1128=99=25135=X49=SAMPLE75=2016101134=456252=2008102001214844093564860=200810200121484409356485799=10000100268=2279=1269=048=17359555=6SZ683=356899270=10209.0271=5346=31023=4279=1269=048=17359555=6SZ683=356900270=10208.0271=9346=51023=510=149
1128=99=25135=X49=SAMPLE75=2016101134=332552=2007052321515070127868860=200705232151507012786885799=10000100268=2279=1269=048=17359555=6SZ683=356901270=10209.0271=8346=41023=4279=1269=048=17359555=6SZ683=356902270=10208.0271=6346=41023=510=153
1128=99=18035=X49=SAMPLE75=2016101134=162752=2000081914035208062558060=200008191403520806255805799=10000100268=1279=1269=148=17359555=6SZ683=356903270=10219.0271=7346=31023=710=111
1128=99=18135=X49=SAMPLE75=2016101134=482152=2001083109380913187146460=200108310938091318714645799=10000100268=1279=1269=148=17359555=6SZ683=356904270=10219.0271=10346=41023=710=118
1128=99=18035=X49=SAMPLE75=2016101134=255252=2000112514232247945400060=200011251423224794540005799=10000100268=1279=1269=148=17359555=6SZ683=356905270=10217.0271=4346=21023=510=127
1128=99=18135=X49=SAMPLE75=2016101134=102752=2011082010051951730092860=201108201005195173009285799=10000100268=1279=1269=148=17359555=6SZ683=356906270=10222.0271=3346=11023=1010=154
1128=99=18035=X49=SAMPLE75=2016101134=202052=2014030902401916379769660=201403090240191637976965799=10000100268=1279=1269=048=17359555=6SZ683=356907270=10207.0271=7346=51023=610=101
1128=99=25135=X49=SAMPLE75=2016101134=68252=2003072803454619444958460=200307280345461944495845799=10000100268=2279=1269=048=17359555=6SZ683=356908270=10209.0271=5346=31023=4279=1269=048=17359555=6SZ683=356909270=10208.0271=9346=51023=510=146
1128=99=25135=X49=SAMPLE75=2016101134=27152=2016061804221389644140860=201606180422138964414085799=10000100268=2279=1269=048=17359555=6SZ683=356910270=10209.0271=8346=41023=4279=1269=048=17359555=6SZ683=356911270=10208.0271=6346=41023=510=147
1128=99=18035=X49=SAMPLE75=2016101134=27452=2010101407080562472396860=201010140708056247239685799=10000100268=1279=1269=048=17359555=6SZ683=356912270=10212.0271=2346=21023=110=070
1128=99=18035=X49=SAMPLE75=2016101134=203052=2006032017103336997507260=200603201710333699750725799=10000100268=1279=1269=148=17359555=6SZ683=356913270=10220.0271=7346=31023=810=099
1128=99=18035=X49=SAMPLE75=2016101134=123052=2005033013053825538921660=200503301305382553892165799=10000100268=1279=1269=148=17359555=6SZ683=356914270=10215.0271=5346=31023=310=088
1128=99=25135=X49=SAMPLE75=2016101134=309452=2000080709580251989268460=200008070958025198926845799=10000100268=2279=1269=048=17359555=6SZ683=356915270=10209.0271=5346=31023=4279=1269=048=17359555=6SZ683=356916270=10208.0271=9346=51023=510=155
1128=99=25135=X49=SAMPLE75=2016101134=377252=2016092115232344704563260=201609211523234470456325799=10000100268=2279=1269=048=17359555=6SZ683=356917270=10209.0271=8346=41023=4279=1269=048=17359555=6SZ683=356918270=10208.0271=6346=41023=510=151
1128=99=25135=X49=SAMPLE75=2016101134=315252=2016012111334727611936060=201601211133472761193605799=10000100268=2279=1269=048=17359555=6SZ683=356919270=10209.0271=5346=31023=4279=1269=048=17359555=6SZ683=356920270=10208.0271=9346=51023=510=175
1128=99=25135=X49=SAMPLE75=2016101134=19552=2005082719063853646873660=200508271906385364687365799=10000100268=2279=1269=048=17359555=6SZ683=356921270=10209.0271=8346=41023=4279=1269=048=17359555=6SZ683=356922270=10208.0271=6346=41023=510=131
1128=99=25135=X49=SAMPLE75=2016101134=486152=2005070807234499483475260=200507080723449948347525799=10000100268=2279=1269=048=17359555=6SZ683=356923270=10209.0271=5346=31023=4279=1269=048=17359555=6SZ683=356924270=10208.0271=9346=51023=510=165
1128=99=25135=X49=SAMPLE75=2016101134=390752=2014060423254946495961660=201406042325494649596165799=10000100268=2279=1269=048=17359555=6SZ683=356925270=10209.0271=8346=41023=4279=1269=048=17359555=6SZ683=356926270=10208.0271=6346=41023=510=171
