1128=99=25135=X49=SAMPLE75=2017010134=185952=2017010112440191118539460=201701011244019111853945799=10000100268=2279=1269=048=17359555=6SZ683=356927270=10209.0271=5346=31023=4279=1269=048=17359555=6SZ683=356928270=10208.0271=9346=51023=510=186
1128=99=25135=X49=SAMPLE75=2017010134=328852=2017010110211954518518360=201701011021195451851835799=10000100268=2279=1269=048=17359555=6SZ683=356929270=10209.0271=8346=41023=4279=1269=048=17359555=6SZ683=356930270=10208.0271=6346=41023=510=168
1128=99=25135=X49=SAMPLE75=2017010134=353152=2017010100590137076032760=201701010059013707603275799=10000100268=2279=1269=048=17359555=6SZ683=356931270=10209.0271=5346=31023=4279=1269=048=17359555=6SZ683=356932270=10208.0271=9346=51023=510=167
1128=99=25135=X49=SAMPLE75=2017010134=277952=2017010112585219432977560=201701011258521943297755799=10000100268=2279=1269=048=17359555=6SZ683=356933270=10209.0271=8346=41023=4279=1269=048=17359555=6SZ683=356934270=10208.0271=6346=41023=510=154
1128=99=25135=X49=SAMPLE75=2017010134=273552=2017010107290801632830060=201701010729080163283005799=10000100268=2279=1269=048=17359555=6SZ683=356935270=10209.0271=5346=31023=4279=1269=048=17359555=6SZ683=356936270=10208.0271=9346=51023=510=166
1128=99=25135=X49=SAMPLE75=2017010134=423752=2017010108045632111345060=201701010804563211134505799=10000100268=2279=1269=048=17359555=6SZ683=356937270=10209.0271=8346=41023=4279=1269=048=17359555=6SZ683=356938270=10208.0271=6346=41023=510=145
1128=99=25135=X49=SAMPLE75=2017010134=187552=2017010113461023616405560=201701011346102361640555799=10000100268=2279=1269=048=17359555=6SZ683=356939270=10209.0271=5346=31023=4279=1269=048=17359555=6SZ683=356940270=10208.0271=9346=51023=510=151
1128=99=25135=X49=SAMPLE75=2017010134=399952=2017010111350110806021060=201701011135011080602105799=10000100268=2279=1269=048=17359555=6SZ683=356941270=10209.0271=8346=41023=4279=1269=048=17359555=6SZ683=356942270=10208.0271=6346=41023=510=146
1128=99=25135=X49=SAMPLE75=2017010134=122052=2017010106552398687446960=201701010655239868744695799=10000100268=2279=1269=048=17359555=6SZ683=356943270=10209.0271=5346=31023=4279=1269=048=17359555=6SZ683=356944270=10208.0271=9346=51023=510=165
1128=99=25135=X49=SAMPLE75=2017010134=53152=2017010104454165043232860=201701010445416504323285799=10000100268=2279=1269=048=17359555=6SZ683=356945270=10209.0271=8346=41023=4279=1269=048=17359555=6SZ683=356946270=10208.0271=6346=41023=510=166
1128=99=25135=X49=SAMPLE75=2017010134=478352=2017010111293273789842760=201701011129327378984275799=10000100268=2279=1269=048=17359555=6SZ683=356947270=10209.0271=5346=31023=4279=1269=048=17359555=6SZ683=356948270=10208.0271=9346=51023=510=187
1128=99=25135=X49=SAMPLE75=2017010134=387552=2017010103314875125124060=201701010331487512512405799=10000100268=2279=1269=048=17359555=6SZ683=356949270=10209.0271=8346=41023=4279=1269=048=17359555=6SZ683=356950270=10208.0271=6346=41023=510=176
1128=99=25135=X49=SAMPLE75=2017010134=98452=2017010112232823400232760=201701011223282340023275799=10000100268=2279=1269=048=17359555=6SZ683=356951270=10209.0271=5346=31023=4279=1269=048=17359555=6SZ683=356952270=10208.0271=9346=51023=510=161
1128=99=25135=X49=SAMPLE75=2017010134=119252=2017010106261154301432260=201701010626115430143225799=10000100268=2279=1269=048=17359555=6SZ683=356953270=10209.0271=8346=41023=4279=1269=048=17359555=6SZ683=356954270=10208.0271=6346=41023=510=184
1128=99=25135=X49=SAMPLE75=2017010134=63152=2017010108091851607460960=201701010809185160746095799=10000100268=2279=1269=148=17359555=6SZ683=356955270=10220.0271=4346=21023=8279=1269=148=17359555=6SZ683=356956270=10221.0271=6346=21023=910=193
1128=99=25135=X49=SAMPLE75=2017010134=167252=2017010111170838623518560=201701011117083862351855799=10000100268=2279=1269=148=17359555=6SZ683=356957270=10220.0271=7346=31023=8279=1269=148=17359555=6SZ683=356958270=10221.0271=3346=11023=910=185
1128=99=25135=X49=SAMPLE75=2017010134=203752=2017010109572546293160760=201701010957254629316075799=10000100268=2279=1269=048=17359555=6SZ683=356959270=10209.0271=5346=31023=4279=1269=048=17359555=6SZ683=356960270=10208.0271=9346=51023=510=187
1128=99=25135=X49=SAMPLE75=2017010134=434552=2017010103332233937897960=201701010333223393789795799=10000100268=2279=1269=048=17359555=6SZ683=356961270=10209.0271=8346=41023=4279=1269=048=17359555=6SZ683=356962270=10208.0271=6346=41023=510=169
1128=99=25135=X49=SAMPLE75=2017010134=93152=2017010106152060864927560=201701010615206086492755799=10000100268=2279=1269=048=17359555=6SZ683=356963270=10209.0271=5346=31023=4279=1269=048=17359555=6SZ683=356964270=10208.0271=9346=51023=510=176
1128=99=25135=X49=SAMPLE75=2017010134=269552=2017010112204262062028160=201701011220426206202815799=10000100268=2279=1269=048=17359555=6SZ683=356965270=10209.0271=8346=41023=4279=1269=048=17359555=6SZ683=356966270=10208.0271=6346=41023=510=163
1128=99=25135=X49=SAMPLE75=2017010134=165252=2017010112010623927686860=201701011201062392768685799=10000100268=2279=1269=048=17359555=6SZ683=356967270=10209.0271=5346=31023=4279=1269=048=17359555=6SZ683=356968270=10208.0271=9346=51023=510=191
1128=99=25135=X49=SAMPLE75=2017010134=144952=2017010106414644391998860=201701010641464439199885799=10000100268=2279=1269=048=17359555=6SZ683=356969270=10209.0271=8346=41023=4279=1269=048=17359555=6SZ683=356970270=10208.0271=6346=41023=510=199
1128=99=25135=X49=SAMPLE75=2017010134=59452=2017010103290847907892860=201701010329084790789285799=10000100268=2279=1269=148=17359555=6SZ683=356971270=10220.0271=4346=21023=8279=1269=148=17359555=6SZ683=356972270=10221.0271=6346=21023=910=130
1128=99=25135=X49=SAMPLE75=2017010134=398252=2017010105332230316367360=201701010533223031636735799=10000100268=2279=1269=148=17359555=6SZ683=356973270=10220.0271=7346=31023=8279=1269=148=17359555=6SZ683=356974270=10221.0271=3346=11023=910=136
1128=99=25135=X49=SAMPLE75=2017010134=15952=2017010113174605989735160=201701011317460598973515799=10000100268=2279=1269=048=17359555=6SZ683=356975270=10209.0271=5346=31023=4279=1269=048=17359555=6SZ683=356976270=10208.0271=9346=51023=510=155
1128=99=25135=X49=SAMPLE75=2017010134=394952=2017010114034578316361160=201701011403457831636115799=10000100268=2279=1269=048=17359555=6SZ683=356977270=10209.0271=8346=41023=4279=1269=048=17359555=6SZ683=356978270=10208.0271=6346=41023=510=162
1128=99=25135=X49=SAMPLE75=2017010134=456852=2017010106045981046516360=201701010604598104651635799=10000100268=2279=1269=048=17359555=6SZ683=356979270=10209.0271=5346=31023=4279=1269=048=17359555=6SZ683=356980270=10208.0271=9346=51023=510=147
1128=99=25135=X49=SAMPLE75=2017010134=89252=2017010109502839869836560=201701010950283986983655799=10000100268=2279=1269=048=17359555=6SZ683=356981270=10209.0271=8346=41023=4279=1269=048=17359555=6SZ683=356982270=10208.0271=6346=41023=510=159
1128=99=25135=X49=SAMPLE75=2017010134=204152=2017010103440718724745360=201701010344071872474535799=10000100268=2279=1269=048=17359555=6SZ683=356983270=10209.0271=5346=31023=4279=1269=048=17359555=6SZ683=356984270=10208.0271=9346=51023=510=149
1128=99=25135=X49=SAMPLE75=2017010134=456652=2017010111381058065107060=201701011138105806510705799=10000100268=2279=1269=048=17359555=6SZ683=356985270=10209.0271=8346=41023=4279=1269=048=17359555=6SZ683=356986270=10208.0271=6346=41023=510=175
1128=99=25135=X49=SAMPLE75=2017010134=69652=2017010104310195465411760=201701010431019546541175799=10000100268=2279=1269=048=17359555=6SZ683=356987270=10209.0271=5346=31023=4279=1269=048=17359555=6SZ683=356988270=10208.0271=9346=51023=510=185
1128=99=25135=X49=SAMPLE75=2017010134=197052=2017010110325397070746060=201701011032539707074605799=10000100268=2279=1269=048=17359555=6SZ683=356989270=10209.0271=8346=41023=4279=1269=048=17359555=6SZ683=356990270=10208.0271=6346=41023=510=154
1128=99=25135=X49=SAMPLE75=2017010134=188552=2017010105232069765187460=201701010523206976518745799=10000100268=2279=1269=148=17359555=6SZ683=356991270=10220.0271=4346=21023=8279=1269=148=17359555=6SZ683=356992270=10221.0271=6346=21023=910=141
1128=99=25135=X49=SAMPLE75=2017010134=68552=2017010104021892598259460=201701010402189259825945799=10000100268=2279=1269=148=17359555=6SZ683=356993270=10220.0271=7346=31023=8279=1269=148=17359555=6SZ683=356994270=10221.0271=3346=11023=910=136
1128=99=25135=X49=SAMPLE75=2017010134=124852=2017010107262445613098560=201701010726244561309855799=10000100268=2279=1269=148=17359555=6SZ683=356995270=10220.0271=4346=21023=8279=1269=148=17359555=6SZ683=356996270=10221.0271=6346=21023=910=174
1128=99=25135=X49=SAMPLE75=2017010134=91152=2017010108272220416891660=201701010827222041689165799=10000100268=2279=1269=148=17359555=6SZ683=356997270=10220.0271=7346=31023=8279=1269=148=17359555=6SZ683=356998270=10221.0271=3346=11023=910=175
1128=99=25135=X49=SAMPLE75=2017010134=208652=2017010107552849092597660=201701010755284909259765799=10000100268=2279=1269=148=17359555=6SZ683=356999270=10220.0271=4346=21023=8279=1269=148=17359555=6SZ683=357000270=10221.0271=6346=21023=910=139
1128=99=25135=X49=SAMPLE75=2017010134=331752=2017010102285728549823760=201701010228572854982375799=10000100268=2279=1269=148=17359555=6SZ683=357001270=10220.0271=7346=31023=8279=1269=148=17359555=6SZ683=357002270=10221.0271=3346=11023=910=140
1128=99=25135=X49=SAMPLE75=2017010134=74452=2017010101050100078875260=201701010105010007887525799=10000100268=2279=1269=048=17359555=6SZ683=357003270=10209.0271=5346=31023=4279=1269=048=17359555=6SZ683=357004270=10208.0271=9346=51023=510=129
1128=99=25135=X49=SAMPLE75=2017010134=54252=2017010107074790819295460=201701010707479081929545799=10000100268=2279=1269=048=17359555=6SZ683=357005270=10209.0271=8346=41023=4279=1269=048=17359555=6SZ683=357006270=10208.0271=6346=41023=510=145
1128=99=18035=X49=SAMPLE75=2017010134=119152=2017010108381815667131360=201701010838181566713135799=10000100268=1279=1269=048=17359555=6SZ683=357007270=10212.0271=3346=31023=110=090
1128=99=25135=X49=SAMPLE75=2017010134=128752=2017010108280404730536160=201701010828040473053615799=10000100268=2279=1269=148=17359555=6SZ683=357008270=10220.0271=4346=21023=8279=1269=148=17359555=6SZ683=357009270=10221.0271=6346=21023=910=166
1128=99=25135=X49=SAMPLE75=2017010134=177752=2017010106184328871502060=201701010618432887150205799=10000100268=2279=1269=148=17359555=6SZ683=357010270=10220.0271=7346=31023=8279=1269=148=17359555=6SZ683=357011270=10221.0271=3346=11023=910=104
1128=99=25135=X49=SAMPLE75=2017010134=156252=2017010107454785447317860=201701010745478544731785799=10000100268=2279=1269=148=17359555=6SZ683=357012270=10220.0271=4346=21023=8279=1269=148=17359555=6SZ683=357013270=10221.0271=6346=21023=910=143
1128=99=25135=X49=SAMPLE75=2017010134=260752=2017010112160634696600160=201701011216063469660015799=10000100268=2279=1269=148=17359555=6SZ683=357014270=10220.0271=7346=31023=8279=1269=148=17359555=6SZ683=357015270=10221.0271=3346=11023=910=147
1128=99=18035=X49=SAMPLE75=2017010134=259852=2017010100213161753085560=201701010021316175308555799=10000100268=1279=1269=048=17359555=6SZ683=357016270=10211.0271=4346=31023=210=099
1128=99=18035=X49=SAMPLE75=2017010134=141152=2017010113210829151297660=201701011321082915129765799=10000100268=1279=1269=048=17359555=6SZ683=357017270=10210.0271=5346=31023=310=094
1128=99=25135=X49=SAMPLE75=2017010134=212752=2017010100340503333382360=201701010034050333338235799=10000100268=2279=1269=148=17359555=6SZ683=357018270=10220.0271=4346=21023=8279=1269=148=17359555=6SZ683=357019270=10221.0271=6346=21023=910=132
1128=99=18035=X49=SAMPLE75=2017010134=141652=2017010114255159651024660=201701011425515965102465799=10000100268=1279=1269=048=17359555=6SZ683=357020270=10212.0271=4346=41023=110=095
1128=99=18135=X49=SAMPLE75=2017010134=425552=2017010111290773220613060=201701011129077322061305799=10000100268=1279=1269=148=17359555=6SZ683=357021270=10213.0271=13346=11023=110=152
1128=99=25135=X49=SAMPLE75=2017010134=3452=2017010110112623301004260=201701011011262330100425799=10000100268=2279=1269=148=17359555=6SZ683=357022270=10215.0271=4346=21023=3279=1269=148=17359555=6SZ683=357023270=10216.0271=6346=41023=410=136
1128=99=18135=X49=SAMPLE75=2017010134=252352=2017010113433417332857560=201701011343341733285755799=10000100268=1279=1269=148=17359555=6SZ683=357024270=10213.0271=14346=21023=110=153
1128=99=18235=X49=SAMPLE75=2017010134=114752=2017010105311607928196660=201701010531160792819665799=10000100268=1279=1269=048=17359555=6SZ683=357025270=10203.0271=12346=41023=1010=199
1128=99=18135=X49=SAMPLE75=2017010134=18352=2017010105324425363080460=201701010532442536308045799=10000100268=1279=1269=048=17359555=6SZ683=357026270=10203.0271=5346=31023=1010=129
1128=99=18035=X49=SAMPLE75=2017010134=42452=2017010103013840323538060=201701010301384032353805799=10000100268=1279=1269=048=17359555=6SZ683=357027270=10212.0271=3346=31023=110=082
1128=99=18035=X49=SAMPLE75=2017010134=221252=2017010106131088105183060=201701010613108810518305799=10000100268=1279=1269=048=17359555=6SZ683=357028270=10212.0271=2346=21023=110=128
1128=99=18235=X49=SAMPLE75=2017010134=472952=2017010101570136538941660=201701010157013653894165799=10000100268=1279=1269=048=17359555=6SZ683=357029270=10203.0271=12346=41023=1010=181
1128=99=25135=X49=SAMPLE75=2017010134=352052=2017010107292361268142860=201701010729236126814285799=10000100268=2279=1269=148=17359555=6SZ683=357030270=10215.0271=5346=31023=3279=1269=148=17359555=6SZ683=357031270=10216.0271=5346=31023=410=122
1128=99=18135=X49=SAMPLE75=2017010134=21052=2017010113025156518146860=201701011302515651814685799=10000100268=1279=1269=048=17359555=6SZ683=357032270=10203.0271=5346=31023=1010=144
1128=99=25135=X49=SAMPLE75=2017010134=245752=2017010102094212824801560=201701010209421282480155799=10000100268=2279=1269=148=17359555=6SZ683=357033270=10215.0271=4346=21023=3279=1269=148=17359555=6SZ683=357034270=10216.0271=6346=41023=410=134
1128=99=18035=X49=SAMPLE75=2017010134=89952=2017010110305606939345460=201701011030560693934545799=10000100268=1279=1269=048=17359555=6SZ683=357035270=10212.0271=3346=31023=110=094
1128=99=18035=X49=SAMPLE75=2017010134=232452=2017010110034383873500960=201701011003438387350095799=10000100268=1279=1269=048=17359555=6SZ683=357036270=10212.0271=4346=41023=110=101
1128=99=23335=X49=SAMPLE75=2017010134=26852=2017010112541960177150160=201701011254196017715015799=00000001268=1279=0269=248=17359555=6SZ683=357037270=10213.0271=14346=35797=137705=337=032=1437=032=1337=621180793659332=110=004
1128=99=15635=X49=SAMPLE75=2017010134=493852=2017010111390359477650860=201701011139035947765085799=00000010268=1279=0269=e48=17359555=6SZ683=357038271=5510=080
1128=99=25335=X49=SAMPLE75=2017010134=482052=2017010107502450092103060=201701010750245009210305799=10000100268=2279=2269=148=17359555=6SZ683=357039270=10213.0271=14346=21023=1279=0269=148=17359555=6SZ683=357040270=10223.0271=3346=11023=1010=214
1128=99=18035=X49=SAMPLE75=2017010134=272952=2017010105452064695548460=201701010545206469554845799=10000100268=1279=1269=048=17359555=6SZ683=357041270=10212.0271=5346=51023=110=089
1128=99=17935=X49=SAMPLE75=2017010134=404952=2017010103133740019101960=201701010313374001910195799=10000100268=1279=0269=048=17360055=6SH783=99229270=10266.0271=3346=11023=110=036
1128=99=25035=X49=SAMPLE75=2017010134=181652=2017010113030686420242960=201701011303068642024295799=10000100268=2279=2269=148=17360055=6SH783=99230270=10269.0271=3346=11023=1279=0269=148=17360055=6SH783=99231270=10279.0271=3346=11023=1010=044
1128=99=18035=X49=SAMPLE75=2017010134=279052=2017010112185544838186860=201701011218554483818685799=10000100268=1279=1269=048=17359555=6SZ683=357042270=10212.0271=6346=61023=110=093
1128=99=18035=X49=SAMPLE75=2017010134=438652=2017010107150360753207660=201701010715036075320765799=10000100268=1279=1269=148=17359555=6SZ683=357043270=10214.0271=7346=51023=110=095
1128=99=18035=X49=SAMPLE75=2017010134=486252=2017010111385404993041560=201701011138540499304155799=10000100268=1279=1269=048=17359555=6SZ683=357044270=10212.0271=7346=71023=110=105
1128=99=18035=X49=SAMPLE75=2017010134=430552=2017010108240247832388660=201701010824024783238865799=10000100268=1279=1269=048=17359555=6SZ683=357045270=10212.0271=8346=81023=110=088
1128=99=18035=X49=SAMPLE75=2017010134=337252=2017010100070422647304460=201701010007042264730445799=10000100268=1279=1269=148=17359555=6SZ683=357046270=10214.0271=8346=61023=110=085
1128=99=18035=X49=SAMPLE75=2017010134=192252=2017010114333714150824260=201701011433371415082425799=10000100268=1279=1269=148=17359555=6SZ683=357047270=10214.0271=9346=71023=110=094
1128=99=18035=X49=SAMPLE75=2017010134=288952=2017010102415142669900860=201701010241514266990085799=10000100268=1279=1269=048=17359555=6SZ683=357048270=10211.0271=5346=41023=210=097
1128=99=18035=X49=SAMPLE75=2017010134=411252=2017010108281920812803060=201701010828192081280305799=10000100268=1279=1269=148=17359555=6SZ683=357049270=10215.0271=5346=31023=210=100
1128=99=18035=X49=SAMPLE75=2017010134=67752=2017010105110968212542060=201701010511096821254205799=10000100268=1279=1269=048=17359555=6SZ683=357050270=10211.0271=6346=51023=210=086
1128=99=18035=X49=SAMPLE75=2017010134=239752=2017010100280360767111860=201701010028036076711185799=10000100268=1279=1269=148=17359555=6SZ683=357051270=10215.0271=6346=41023=210=103
1128=99=18035=X49=SAMPLE75=2017010134=69452=2017010105035353969250560=201701010503535396925055799=10000100268=1279=1269=048=17359555=6SZ683=357052270=10212.0271=9346=91023=110=091
1128=99=18135=X49=SAMPLE75=2017010134=418252=2017010105424387465569260=201701010542438746556925799=10000100268=1279=1269=148=17359555=6SZ683=357053270=10214.0271=10346=81023=110=121
1128=99=18035=X49=SAMPLE75=2017010134=81452=2017010100151895526025460=201701010015189552602545799=10000100268=1279=1269=048=17359555=6SZ683=357054270=10211.0271=7346=61023=210=084
1128=99=18035=X49=SAMPLE75=2017010134=318752=2017010101005788854971360=201701010100578885497135799=10000100268=1279=1269=148=17359555=6SZ683=357055270=10215.0271=7346=51023=210=091
1128=99=17935=X49=SAMPLE75=2017010134=414252=2017010110395440348847660=201701011039544034884765799=10000100268=1279=0269=048=17360055=6SH783=99232270=10265.0271=3346=11023=210=024
1128=99=18235=X49=SAMPLE75=2017010134=92152=2017010100094173606988560=201701010009417360698855799=10000100268=1279=1269=048=17359555=6SZ683=357056270=10212.0271=10346=101023=110=159
1128=99=24935=X49=SAMPLE75=2017010134=494752=2017010110282636386525760=201701011028263638652575799=10000100268=2279=1269=048=17360055=6SH783=99233270=10264.0271=5346=21023=3279=1269=048=17360055=6SH783=99234270=10262.0271=3346=11023=510=003
1128=99=25335=X49=SAMPLE75=2017010134=364652=2017010103062566113561260=201701010306256611356125799=10000100268=2279=1269=048=17359555=6SZ683=357057270=10212.0271=11346=111023=1279=1269=048=17359555=6SZ683=357058270=10208.0271=5346=31023=510=235
1128=99=18035=X49=SAMPLE75=2017010134=16352=2017010108155479412234860=201701010815547941223485799=10000100268=1279=1269=148=17359555=6SZ683=357059270=10214.0271=7346=71023=110=086
1128=99=18035=X49=SAMPLE75=2017010134=31452=2017010111333078174535660=201701011133307817453565799=10000100268=1279=1269=048=17359555=6SZ683=357060270=10210.0271=6346=41023=310=081
1128=99=18035=X49=SAMPLE75=2017010134=343852=2017010102071514128914560=201701010207151412891455799=10000100268=1279=1269=148=17359555=6SZ683=357061270=10216.0271=7346=51023=310=095
1128=99=18035=X49=SAMPLE75=2017010134=370252=2017010101304688128328660=201701010130468812832865799=10000100268=1279=1269=048=17359555=6SZ683=357062270=10210.0271=7346=51023=310=086
1128=99=18035=X49=SAMPLE75=2017010134=346652=2017010106383683219913160=201701010638368321991315799=10000100268=1279=1269=148=17359555=6SZ683=357063270=10216.0271=8346=61023=310=079
1128=99=18035=X49=SAMPLE75=2017010134=332652=2017010111073329702071660=201701011107332970207165799=10000100268=1279=1269=048=17359555=6SZ683=357064270=10210.0271=8346=61023=310=090
1128=99=18035=X49=SAMPLE75=2017010134=27452=2017010111364028857538060=201701011136402885753805799=10000100268=1279=1269=148=17359555=6SZ683=357065270=10216.0271=9346=71023=310=106
1128=99=18035=X49=SAMPLE75=2017010134=296752=2017010113032858642254360=201701011303285864225435799=10000100268=1279=1269=048=17359555=6SZ683=357066270=10209.0271=9346=51023=410=104
1128=99=18035=X49=SAMPLE75=2017010134=148152=2017010106000057889520260=201701010600005788952025799=10000100268=1279=1269=148=17359555=6SZ683=357067270=10217.0271=5346=31023=410=099
1128=99=18135=X49=SAMPLE75=2017010134=60452=2017010108433566281225660=201701010843356628122565799=10000100268=1279=1269=048=17359555=6SZ683=357068270=10209.0271=10346=61023=410=159
1128=99=18035=X49=SAMPLE75=2017010134=163852=2017010110481762228873860=201701011048176222887385799=10000100268=1279=1269=148=17359555=6SZ683=357069270=10217.0271=6346=41023=410=097
1128=99=18135=X49=SAMPLE75=2017010134=139552=2017010106222967025874760=201701010622296702587475799=10000100268=1279=1269=048=17359555=6SZ683=357070270=10209.0271=11346=71023=410=126
1128=99=18035=X49=SAMPLE75=2017010134=470752=2017010113124053903084360=201701011312405390308435799=10000100268=1279=1269=148=17359555=6SZ683=357071270=10217.0271=7346=51023=410=093
1128=99=25035=X49=SAMPLE75=2017010134=97852=2017010109085702809686260=201701010908570280968625799=10000100268=2279=2269=048=17360055=6SH783=99235270=10266.0271=3346=11023=1279=0269=048=17360055=6SH783=99236270=10256.0271=3346=11023=1010=023
1128=99=18035=X49=SAMPLE75=2017010134=78452=2017010105212931011448660=201701010521293101144865799=10000100268=1279=1269=048=17359555=6SZ683=357072270=10208.0271=6346=41023=510=095
1128=99=18035=X49=SAMPLE75=2017010134=50552=2017010113305799568681560=201701011330579956868155799=10000100268=1279=1269=148=17359555=6SZ683=357073270=10218.0271=5346=31023=510=090
1128=99=18035=X49=SAMPLE75=2017010134=180252=2017010102582212004402860=201701010258221200440285799=10000100268=1279=1269=048=17359555=6SZ683=357074270=10208.0271=7346=51023=510=078
1128=99=18035=X49=SAMPLE75=2017010134=181552=2017010101444339674662260=201701010144433967466225799=10000100268=1279=1269=148=17359555=6SZ683=357075270=10218.0271=6346=41023=510=098
1128=99=18035=X49=SAMPLE75=2017010134=116252=2017010100160420592870360=201701010016042059287035799=10000100268=1279=1269=048=17359555=6SZ683=357076270=10208.0271=8346=61023=510=086
1128=99=18035=X49=SAMPLE75=2017010134=232552=2017010106130204614716660=201701010613020461471665799=10000100268=1279=1269=148=17359555=6SZ683=357077270=10218.0271=7346=51023=510=093
1128=99=18035=X49=SAMPLE75=2017010134=416052=2017010105554937403172860=201701010555493740317285799=10000100268=1279=0269=048=17359555=6SZ683=357078270=10213.0271=1346=11023=110=075
1128=99=17935=X49=SAMPLE75=2017010134=489552=2017010109355992235567160=201701010935599223556715799=10000100268=1279=0269=048=17360055=6SH783=99237270=10266.0271=3346=11023=110=005
1128=99=24735=X49=SAMPLE75=2017010134=24252=2017010110542857464622860=201701011054285746462285799=10000100268=2279=0269=048=17360355=6SM783=7543270=10282.0271=6346=11023=4279=2269=048=17360355=6SM783=7544270=10281.0271=6346=11023=510=150
1128=99=18035=X49=SAMPLE75=2017010134=115652=2017010106033889315860160=201701010603388931586015799=10000100268=1279=1269=148=17359555=6SZ683=357079270=10214.0271=6346=61023=110=103
1128=99=18035=X49=SAMPLE75=2017010134=1352=2017010102540346739360460=201701010254034673936045799=10000100268=1279=1269=148=17359555=6SZ683=357080270=10214.0271=5346=51023=110=090
1128=99=18035=X49=SAMPLE75=2017010134=345652=2017010110024373244025960=201701011002437324402595799=10000100268=1279=1269=048=17359555=6SZ683=357081270=10213.0271=2346=21023=110=066
1128=99=18135=X49=SAMPLE75=2017010134=460252=2017010102351649527962460=201701010235164952796245799=10000100268=1279=1269=048=17359555=6SZ683=357082270=10204.0271=3346=11023=1010=109
1128=99=18035=X49=SAMPLE75=2017010134=196852=2017010113370104229939160=201701011337010422993915799=10000100268=1279=1269=048=17359555=6SZ683=357083270=10211.0271=8346=71023=310=105
1128=99=18035=X49=SAMPLE75=2017010134=383652=2017010100152685520118260=201701010015268552011825799=10000100268=1279=1269=048=17359555=6SZ683=357084270=10213.0271=3346=31023=110=090
1128=99=18035=X49=SAMPLE75=2017010134=420352=2017010110261498435439060=201701011026149843543905799=10000100268=1279=1269=048=17359555=6SZ683=357085270=10213.0271=4346=41023=110=095
1128=99=18035=X49=SAMPLE75=2017010134=316452=2017010101213594683997560=201701010121359468399755799=10000100268=1279=1269=148=17359555=6SZ683=357086270=10214.0271=4346=41023=110=086
1128=99=17935=X49=SAMPLE75=2017010134=50952=2017010104213926797790360=201701010421392679779035799=10000100268=1279=1269=148=17360055=6SH783=99238270=10270.0271=2346=11023=110=016
1128=99=18035=X49=SAMPLE75=2017010134=85352=2017010112512981294256260=201701011251298129425625799=10000100268=1279=1269=048=17359555=6SZ683=357087270=10213.0271=5346=51023=110=086
1128=99=32135=X49=SAMPLE75=2017010134=217252=2017010113292907077711260=201701011329290707771125799=10000100268=3279=2269=148=17360055=6SH783=99239270=10270.0271=2346=11023=1279=1269=148=17360055=6SH783=99240270=10273.0271=5346=21023=3279=0269=148=17360055=6SH783=99241270=10280.0271=53346=11023=1010=049
1128=99=25035=X49=SAMPLE75=2017010134=49952=2017010102205744465617360=201701010220574446561735799=10000100268=2279=2269=048=17360055=6SH783=99242270=10266.0271=3346=11023=1279=0269=048=17360055=6SH783=99243270=10256.0271=3346=11023=1010=026
1128=99=18135=X49=SAMPLE75=2017010134=155752=2017010108455373489164660=201701010845537348916465799=10000100268=1279=1269=148=17359555=6SZ683=357088270=10219.0271=11346=51023=610=149
1128=99=25335=X49=SAMPLE75=2017010134=46752=2017010100454578189762160=201701010045457818976215799=10000100268=2279=1269=048=17359555=6SZ683=357089270=10213.0271=6346=61023=1279=1269=048=17359555=6SZ683=357090270=10212.0271=10346=101023=210=228
1128=99=17935=X49=SAMPLE75=2017010134=267452=2017010110264696572763560=201701011026469657276355799=10000100268=1279=0269=048=17360055=6SH783=99244270=10266.0271=3346=11023=110=035
1128=99=24935=X49=SAMPLE75=2017010134=73452=2017010103394487597108560=201701010339448759710855799=10000100268=2279=1269=048=17360055=6SH783=99245270=10265.0271=5346=21023=2279=1269=048=17360055=6SH783=99246270=10263.0271=3346=11023=410=005
1128=99=18035=X49=SAMPLE75=2017010134=193952=2017010107304355990088660=201701010730435599008865799=10000100268=1279=1269=148=17359555=6SZ683=357091270=10214.0271=3346=31023=110=057
1128=99=18035=X49=SAMPLE75=2017010134=6052=2017010109464642413466460=201701010946464241346645799=10000100268=1279=1269=148=17359555=6SZ683=357092270=10214.0271=2346=21023=110=084
1128=99=18035=X49=SAMPLE75=2017010134=96252=2017010113193127454566860=201701011319312745456685799=10000100268=1279=1269=148=17359555=6SZ683=357093270=10214.0271=1346=11023=110=079
1128=99=18135=X49=SAMPLE75=2017010134=399852=2017010112132093864202160=201701011213209386420215799=10000100268=1279=1269=148=17359555=6SZ683=357094270=10219.0271=12346=61023=610=135
1128=99=22035=X49=SAMPLE75=2017010134=90052=2017010108573096842505060=201701010857309684250505799=00000001268=1279=0269=248=17359555=6SZ683=357095270=10214.0271=1346=25797=137705=237=032=137=621180793707432=110=194
1128=99=15635=X49=SAMPLE75=2017010134=431752=2017010103101057699682360=201701010310105769968235799=00000010268=1279=0269=e48=17359555=6SZ683=357096271=5610=104
1128=99=25235=X49=SAMPLE75=2017010134=94552=2017010106424047266817860=201701010642404726681785799=10000100268=2279=2269=148=17359555=6SZ683=357097270=10214.0271=1346=11023=1279=0269=148=17359555=6SZ683=357098270=10224.0271=1346=11023=1010=196
1128=99=17935=X49=SAMPLE75=2017010134=104352=2017010110100311973338060=201701011010031197333805799=00000100268=1279=0269=048=17360055=6SH783=99247270=10267.0271=3346=11023=110=019
1128=99=16835=X49=SAMPLE75=2017010134=197552=2017010105530126816816160=201701010553012681681615799=10001000268=1279=0269=N48=17360055=6SH783=99248270=10267.0286=25510=095
1128=99=18135=X49=SAMPLE75=2017010134=325652=2017010108555271462744460=201701010855527146274445799=10000100268=1279=1269=148=17359555=6SZ683=357099270=10219.0271=13346=71023=510=145
1128=99=18035=X49=SAMPLE75=2017010134=251852=2017010112091727039304360=201701011209172703930435799=10000100268=1279=1269=148=17359555=6SZ683=357100270=10215.0271=8346=61023=110=083
1128=99=18035=X49=SAMPLE75=2017010134=333352=2017010110400621244383260=201701011040062124438325799=10000100268=1279=1269=048=17359555=6SZ683=357101270=10213.0271=7346=71023=110=108
1128=99=18035=X49=SAMPLE75=2017010134=59352=2017010112122232831818660=201701011212223283181865799=10000100268=1279=1269=148=17359555=6SZ683=357102270=10215.0271=9346=71023=110=089
1128=99=25035=X49=SAMPLE75=2017010134=485152=2017010113053847098700060=201701011305384709870005799=10000100268=2279=2269=048=17360055=6SH783=99249270=10267.0271=3346=11023=1279=0269=048=17360055=6SH783=99250270=10257.0271=3346=11023=1010=040
1128=99=18135=X49=SAMPLE75=2017010134=155352=2017010101183792658915360=201701010118379265891535799=10000100268=1279=1269=148=17359555=6SZ683=357103270=10215.0271=10346=81023=110=126
1128=99=18035=X49=SAMPLE75=2017010134=375052=2017010112433353359687360=201701011243335335968735799=10000100268=1279=1269=148=17359555=6SZ683=357104270=10215.0271=9346=71023=110=101
1128=99=18135=X49=SAMPLE75=2017010134=213252=2017010100481157611130860=201701010048115761113085799=10000100268=1279=1269=148=17359555=6SZ683=357105270=10223.0271=10346=21023=910=156
1128=99=18135=X49=SAMPLE75=2017010134=453552=2017010100084305270051960=201701010008430527005195799=10000100268=1279=1269=148=17359555=6SZ683=357106270=10224.0271=8346=21023=1010=133
1128=99=18035=X49=SAMPLE75=2017010134=321352=2017010111424932694640260=201701011142493269464025799=10000100268=1279=1269=148=17359555=6SZ683=357107270=10215.0271=8346=61023=110=086
1128=99=18035=X49=SAMPLE75=2017010134=5452=2017010105065370493291560=201701010506537049329155799=10000100268=1279=1269=148=17359555=6SZ683=357108270=10216.0271=8346=61023=210=101
1128=99=18035=X49=SAMPLE75=2017010134=162752=2017010106580612560879160=201701010658061256087915799=10000100268=1279=1269=148=17359555=6SZ683=357109270=10220.0271=5346=31023=610=089
1128=99=18235=X49=SAMPLE75=2017010134=78052=2017010100531065516586960=201701010053106551658695799=10000100268=1279=1269=048=17359555=6SZ683=357110270=10212.0271=13346=111023=210=177
1128=99=18035=X49=SAMPLE75=2017010134=325252=2017010104081959860884760=201701010408195986088475799=10000100268=1279=1269=048=17359555=6SZ683=357111270=10211.0271=7346=61023=310=095
1128=99=18035=X49=SAMPLE75=2017010134=249152=2017010110350830631295260=201701011035083063129525799=10000100268=1279=1269=048=17359555=6SZ683=357112270=10213.0271=8346=81023=110=090
1128=99=18035=X49=SAMPLE75=2017010134=25552=2017010107152709395820960=201701010715270939582095799=10000100268=1279=1269=148=17359555=6SZ683=357113270=10221.0271=7346=31023=710=083
1128=99=18035=X49=SAMPLE75=2017010134=365752=2017010107541216955771860=201701010754121695577185799=00000100268=1279=0269=048=17359555=6SZ683=357114270=10214.0271=1346=11023=110=109
1128=99=16935=X49=SAMPLE75=2017010134=423552=2017010114230312135498060=201701011423031213549805799=10001000268=1279=0269=N48=17359555=6SZ683=357115270=10214.0286=25510=196
1128=99=17935=X49=SAMPLE75=2017010134=386752=2017010107165755531130560=201701010716575553113055799=10000100268=1279=0269=048=17360055=6SH783=99251270=10267.0271=3346=11023=110=025
1128=99=24735=X49=SAMPLE75=2017010134=397252=2017010111465595307689860=201701011146559530768985799=10000100268=2279=0269=048=17360355=6SM783=7545270=10283.0271=6346=11023=4279=2269=048=17360355=6SM783=7546270=10282.0271=6346=11023=510=158
1128=99=18035=X49=SAMPLE75=2017010134=124952=2017010103374753103146960=201701010337475310314695799=10000100268=1279=1269=148=17359555=6SZ683=357116270=10215.0271=7346=51023=110=109
1128=99=18035=X49=SAMPLE75=2017010134=296352=2017010111304464957001060=201701011130446495700105799=10000100268=1279=1269=048=17359555=6SZ683=357117270=10214.0271=2346=21023=110=087
1128=99=18035=X49=SAMPLE75=2017010134=341052=2017010111101258694480160=201701011110125869448015799=10000100268=1279=1269=048=17359555=6SZ683=357118270=10214.0271=3346=31023=110=110
1128=99=18035=X49=SAMPLE75=2017010134=58852=2017010114303771987232860=201701011430377198723285799=10000100268=1279=1269=048=17359555=6SZ683=357119270=10214.0271=4346=41023=110=093
1128=99=18235=X49=SAMPLE75=2017010134=126152=2017010104340046115253960=201701010434004611525395799=10000100268=1279=1269=048=17359555=6SZ683=357120270=10205.0271=10346=41023=1010=173
1128=99=18235=X49=SAMPLE75=2017010134=497052=2017010105273535949734060=201701010527353594973405799=10000100268=1279=1269=048=17359555=6SZ683=357121270=10212.0271=14346=121023=310=157
1128=99=18035=X49=SAMPLE75=2017010134=174152=2017010105382018883872360=201701010538201888387235799=10000100268=1279=1269=048=17359555=6SZ683=357122270=10214.0271=5346=51023=110=086
1128=99=25035=X49=SAMPLE75=2017010134=429552=2017010108125958547956260=201701010812595854795625799=10000100268=2279=2269=048=17360055=6SH783=99252270=10267.0271=3346=11023=1279=0269=048=17360055=6SH783=99253270=10257.0271=3346=11023=1010=031
1128=99=18035=X49=SAMPLE75=2017010134=26852=2017010113030356707536760=201701011303035670753675799=10000100268=1279=1269=148=17359555=6SZ683=357123270=10215.0271=6346=41023=110=087
1128=99=18035=X49=SAMPLE75=2017010134=263552=2017010110131211245982960=201701011013121124598295799=10000100268=1279=1269=148=17359555=6SZ683=357124270=10220.0271=6346=41023=610=092
1128=99=18035=X49=SAMPLE75=2017010134=237952=2017010105495811731146360=201701010549581173114635799=10000100268=1279=1269=148=17359555=6SZ683=357125270=10215.0271=5346=31023=110=074
1128=99=17935=X49=SAMPLE75=2017010134=478652=2017010105032706245190960=201701010503270624519095799=10000100268=1279=1269=148=17360055=6SH783=99254270=10271.0271=2346=11023=110=020
1128=99=32035=X49=SAMPLE75=2017010134=370652=2017010108050608301225460=201701010805060830122545799=10000100268=3279=2269=148=17360055=6SH783=99255270=10271.0271=2346=11023=1279=1269=148=17360055=6SH783=99256270=10274.0271=5346=21023=3279=0269=148=17360055=6SH783=99257270=10281.0271=3346=11023=1010=246
1128=99=18035=X49=SAMPLE75=2017010134=40852=2017010108454932961205960=201701010845493296120595799=10000100268=1279=1269=148=17359555=6SZ683=357126270=10220.0271=7346=51023=610=092
1128=99=20835=X49=SAMPLE75=2017010134=210252=2017010107480881639401060=201701010748088163940105799=00000001268=1279=0269=248=17359555=6SZ683=357127270=10214.0271=1346=25797=237705=237=032=137=032=110=056
1128=99=15635=X49=SAMPLE75=2017010134=387452=2017010113095180443107060=201701011309518044310705799=00000010268=1279=0269=e48=17359555=6SZ683=357128271=5710=089
1128=99=18035=X49=SAMPLE75=2017010134=460252=2017010108350119344575860=201701010835011934457585799=10000100268=1279=1269=048=17359555=6SZ683=357129270=10214.0271=4346=41023=110=093
1128=99=18035=X49=SAMPLE75=2017010134=123752=2017010100421352146850560=201701010042135214685055799=10000100268=1279=1269=148=17359555=6SZ683=357130270=10215.0271=6346=41023=110=083
1128=99=17935=X49=SAMPLE75=2017010134=432852=2017010107170036311494060=201701010717003631149405799=10000100268=1279=0269=148=17360055=6SH783=99258270=10271.0271=3346=11023=110=024
1128=99=24935=X49=SAMPLE75=2017010134=261652=2017010101444512030359460=201701010144451203035945799=10000100268=2279=1269=148=17360055=6SH783=99259270=10272.0271=5346=21023=2279=1269=148=17360055=6SH783=99260270=10274.0271=3346=11023=410=009
1128=99=18035=X49=SAMPLE75=2017010134=171352=2017010112242275813281160=201701011224227581328115799=10000100268=1279=1269=148=17359555=6SZ683=357131270=10215.0271=3346=31023=110=092
1128=99=25035=X49=SAMPLE75=2017010134=40852=2017010103555083414657360=201701010355508341465735799=10000100268=2279=2269=148=17360055=6SH783=99261270=10271.0271=3346=11023=1279=0269=148=17360055=6SH783=99262270=10281.0271=3346=11023=1010=027
1128=99=18035=X49=SAMPLE75=2017010134=136252=2017010102460533088775760=201701010246053308877575799=10000100268=1279=1269=148=17359555=6SZ683=357132270=10215.0271=4346=41023=110=095
1128=99=18035=X49=SAMPLE75=2017010134=132052=2017010106175159054733360=201701010617515905473335799=10000100268=1279=1269=048=17359555=6SZ683=357133270=10214.0271=3346=31023=110=088
1128=99=18035=X49=SAMPLE75=2017010134=63052=2017010107431827708361060=201701010743182770836105799=10000100268=1279=1269=048=17359555=6SZ683=357134270=10214.0271=2346=21023=110=111
1128=99=24235=X49=SAMPLE75=2017010134=343552=2017010103134476376256860=201701010313447637625685799=00000001268=1279=0269=248=17359555=6SZ683=357135270=10214.0271=2346=35797=237705=337=032=237=621180793728532=137=621180793728632=110=221
1128=99=15635=X49=SAMPLE75=2017010134=129952=2017010108423162020026560=201701010842316202002655799=00000010268=1279=0269=e48=17359555=6SZ683=357136271=5910=100
1128=99=25235=X49=SAMPLE75=2017010134=427152=2017010107341100384788460=201701010734110038478845799=10000100268=2279=2269=048=17359555=6SZ683=357137270=10214.0271=2346=21023=1279=0269=048=17359555=6SZ683=357138270=10204.0271=3346=11023=1010=184
1128=99=18035=X49=SAMPLE75=2017010134=164552=2017010110224641556214560=201701011022464155621455799=10000100268=1279=0269=048=17359555=6SZ683=357139270=10214.0271=1346=11023=110=107
1128=99=17935=X49=SAMPLE75=2017010134=372352=2017010112115971884580560=201701011211597188458055799=10000100268=1279=0269=148=17360055=6SH783=99263270=10270.0271=3346=11023=110=043
1128=99=18035=X49=SAMPLE75=2017010134=415452=2017010108272933282472160=201701010827293328247215799=10000100268=1279=1269=148=17359555=6SZ683=357140270=10215.0271=5346=51023=110=110
1128=99=17935=X49=SAMPLE75=2017010134=271352=2017010109181564858840260=201701010918156485884025799=10000100268=1279=0269=148=17360055=6SH783=99264270=10271.0271=3346=11023=210=034
1128=99=25135=X49=SAMPLE75=2017010134=111852=2017010109485646589119260=201701010948564658911925799=10000100268=2279=2269=148=17360055=6SH783=99265270=10270.0271=3346=11023=1279=0269=148=17360055=6SH783=99266270=10280.0271=53346=11023=1010=100
1128=99=22035=X49=SAMPLE75=2017010134=487952=2017010103395399887800160=201701010339539988780015799=00000001268=1279=0269=248=17359555=6SZ683=357141270=10214.0271=1346=25797=237705=237=032=137=621180793730132=110=187
1128=99=15635=X49=SAMPLE75=2017010134=129652=2017010101305431297191460=201701010130543129719145799=00000010268=1279=0269=e48=17359555=6SZ683=357142271=6010=111
1128=99=25235=X49=SAMPLE75=2017010134=245752=2017010105233690317273560=201701010523369031727355799=10000100268=2279=2269=048=17359555=6SZ683=357143270=10214.0271=1346=11023=1279=0269=048=17359555=6SZ683=357144270=10204.0271=3346=11023=1010=198
1128=99=25035=X49=SAMPLE75=2017010134=282352=2017010101024575758213560=201701010102457575821355799=10000100268=2279=2269=148=17360055=6SH783=99267270=10271.0271=3346=11023=1279=0269=148=17360055=6SH783=99268270=10281.0271=3346=11023=1010=046
1128=99=18035=X49=SAMPLE75=2017010134=445352=2017010112521115021112660=201701011252111502111265799=10000100268=1279=1269=148=17359555=6SZ683=357145270=10223.0271=3346=11023=910=131
1128=99=18135=X49=SAMPLE75=2017010134=278952=2017010106522389734595460=201701010652238973459545799=10000100268=1279=1269=148=17359555=6SZ683=357146270=10224.0271=1346=11023=1010=181
1128=99=18135=X49=SAMPLE75=2017010134=153252=2017010109224732538882160=201701010922473253888215799=10000100268=1279=1269=148=17359555=6SZ683=357147270=10223.0271=10346=21023=910=138
1128=99=18135=X49=SAMPLE75=2017010134=98052=2017010105193956194578660=201701010519395619457865799=10000100268=1279=1269=148=17359555=6SZ683=357148270=10224.0271=8346=21023=1010=154
1128=99=18235=X49=SAMPLE75=2017010134=475552=2017010113531334201993060=201701011353133420199305799=10000100268=1279=1269=048=17359555=6SZ683=357149270=10212.0271=13346=111023=210=206
1128=99=18135=X49=SAMPLE75=2017010134=440852=2017010107164515980630460=201701010716451598063045799=10000100268=1279=1269=048=17359555=6SZ683=357150270=10205.0271=11346=51023=910=166
1128=99=18235=X49=SAMPLE75=2017010134=263452=2017010103311362613228660=201701010331136261322865799=10000100268=1279=1269=048=17359555=6SZ683=357151270=10212.0271=12346=101023=210=196
1128=99=18035=X49=SAMPLE75=2017010134=145752=2017010108235350954800760=201701010823535095480075799=10000100268=1279=1269=148=17359555=6SZ683=357152270=10216.0271=9346=71023=210=105
1128=99=18135=X49=SAMPLE75=2017010134=211052=2017010100471239102436660=201701010047123910243665799=10000100268=1279=1269=048=17359555=6SZ683=357153270=10213.0271=11346=91023=110=156
1128=99=18135=X49=SAMPLE75=2017010134=29152=2017010113251260133989460=201701011325126013398945799=10000100268=1279=1269=048=17359555=6SZ683=357154270=10212.0271=11346=91023=210=135
1128=99=18135=X49=SAMPLE75=2017010134=411452=2017010112484298489238960=201701011248429848923895799=10000100268=1279=1269=048=17359555=6SZ683=357155270=10212.0271=10346=81023=210=150
1128=99=18035=X49=SAMPLE75=2017010134=490552=2017010100333709370624060=201701010033370937062405799=10000100268=1279=1269=048=17359555=6SZ683=357156270=10207.0271=6346=41023=710=092
1128=99=18035=X49=SAMPLE75=2017010134=349452=2017010100092866314064760=201701010009286631406475799=10000100268=1279=1269=048=17359555=6SZ683=357157270=10206.0271=5346=31023=810=108
1128=99=18035=X49=SAMPLE75=2017010134=487352=2017010108044895419297760=201701010804489541929775799=10000100268=1279=1269=148=17359555=6SZ683=357158270=10215.0271=4346=41023=110=121
1128=99=18035=X49=SAMPLE75=2017010134=40052=2017010105113609738138060=201701010511360973813805799=10000100268=1279=0269=048=17359555=6SZ683=357159270=10214.0271=1346=11023=110=109
1128=99=25235=X49=SAMPLE75=2017010134=459752=2017010106253976773405960=201701010625397677340595799=10000100268=2279=1269=048=17359555=6SZ683=357160270=10210.0271=11346=71023=5279=1269=048=17359555=6SZ683=357161270=10209.0271=8346=61023=610=215
1128=99=17935=X49=SAMPLE75=2017010134=62052=2017010113261613454348060=201701011326161345434805799=10000100268=1279=0269=048=17360055=6SH783=99269270=10267.0271=3346=11023=110=062
1128=99=18035=X49=SAMPLE75=2017010134=63252=2017010108542175338752160=201701010854217533875215799=10000100268=1279=1269=148=17359555=6SZ683=357162270=10215.0271=3346=31023=110=106
1128=99=18035=X49=SAMPLE75=2017010134=91052=2017010107242630319908960=201701010724263031990895799=10000100268=1279=1269=048=17359555=6SZ683=357163270=10214.0271=2346=21023=110=112
1128=99=18035=X49=SAMPLE75=2017010134=27252=2017010114093062409146360=201701011409306240914635799=10000100268=1279=1269=048=17359555=6SZ683=357164270=10214.0271=3346=31023=110=129
1128=99=18035=X49=SAMPLE75=2017010134=357252=2017010112294488193571060=201701011229448819357105799=10000100268=1279=1269=048=17359555=6SZ683=357165270=10214.0271=4346=41023=110=111
1128=99=18035=X49=SAMPLE75=2017010134=225952=2017010102205605785689860=201701010220560578568985799=10000100268=1279=1269=148=17359555=6SZ683=357166270=10215.0271=4346=41023=110=120
1128=99=18235=X49=SAMPLE75=2017010134=72352=2017010109125764580220560=201701010912576458022055799=10000100268=1279=1269=048=17359555=6SZ683=357167270=10205.0271=10346=41023=1010=222
1128=99=18135=X49=SAMPLE75=2017010134=292152=2017010100104032621760260=201701010010403262176025799=10000100268=1279=1269=048=17359555=6SZ683=357168270=10212.0271=11346=91023=310=182
1128=99=18035=X49=SAMPLE75=2017010134=247852=2017010101225958545184160=201701010122595854518415799=10000100268=1279=1269=048=17359555=6SZ683=357169270=10214.0271=5346=51023=110=146
1128=99=18035=X49=SAMPLE75=2017010134=487452=2017010113220443725337460=201701011322044372533745799=10000100268=1279=1269=148=17359555=6SZ683=357170270=10215.0271=3346=31023=110=105
1128=99=18035=X49=SAMPLE75=2017010134=358852=2017010104362312884941060=201701010436231288494105799=10000100268=1279=1269=148=17359555=6SZ683=357171270=10215.0271=2346=21023=110=106
1128=99=18035=X49=SAMPLE75=2017010134=138752=2017010111163774143464360=201701011116377414346435799=10000100268=1279=1269=148=17359555=6SZ683=357172270=10215.0271=1346=11023=110=135
1128=99=25035=X49=SAMPLE75=2017010134=97952=2017010112412937038107260=201701011241293703810725799=10000100268=2279=2269=048=17360055=6SH783=99270270=10267.0271=3346=11023=1279=0269=048=17360055=6SH783=99271270=10257.0271=3346=11023=1010=072
1128=99=25335=X49=SAMPLE75=2017010134=9252=2017010110175177971661260=201701011017517797166125799=10000100268=2279=2269=148=17359555=6SZ683=357173270=10215.0271=1346=11023=1279=0269=148=17359555=6SZ683=357174270=10225.0271=15346=21023=1010=012
1128=99=18035=X49=SAMPLE75=2017010134=453652=2017010112082625698447360=201701011208262569844735799=10000100268=1279=1269=148=17359555=6SZ683=357175270=10220.0271=8346=61023=510=109
1128=99=18035=X49=SAMPLE75=2017010134=454852=2017010108012878132174860=201701010801287813217485799=10000100268=1279=1269=048=17359555=6SZ683=357176270=10214.0271=6346=61023=110=117
1128=99=18135=X49=SAMPLE75=2017010134=217552=2017010110311811761703960=201701011031181176170395799=10000100268=1279=1269=148=17359555=6SZ683=357177270=10216.0271=10346=81023=110=176
1128=99=18035=X49=SAMPLE75=2017010134=151552=2017010105133857231628360=201701010513385723162835799=00000100268=1279=0269=048=17359555=6SZ683=357178270=10215.0271=1346=11023=110=125
1128=99=16935=X49=SAMPLE75=2017010134=191452=2017010101023883898543060=201701010102388389854305799=10001000268=1279=0269=N48=17359555=6SZ683=357179270=10215.0286=25510=212
1128=99=17935=X49=SAMPLE75=2017010134=229752=2017010107232938668723460=201701010723293866872345799=10000100268=1279=1269=148=17360055=6SH783=99272270=10280.0271=3346=11023=910=076
1128=99=18135=X49=SAMPLE75=2017010134=64152=2017010113483411975633660=201701011348341197563365799=10000100268=1279=1269=148=17359555=6SZ683=357180270=10216.0271=11346=91023=110=166
1128=99=18035=X49=SAMPLE75=2017010134=163052=2017010112332601270435460=201701011233260127043545799=10000100268=1279=1269=148=17359555=6SZ683=357181270=10217.0271=6346=41023=210=128
1128=99=18035=X49=SAMPLE75=2017010134=2152=2017010107293001796275260=201701010729300179627525799=10000100268=1279=1269=148=17359555=6SZ683=357182270=10222.0271=4346=21023=710=127
1128=99=25235=X49=SAMPLE75=2017010134=280952=2017010106354527259784560=201701010635452725978455799=10000100268=2279=1269=048=17359555=6SZ683=357183270=10214.0271=7346=71023=2279=1269=048=17359555=6SZ683=357184270=10213.0271=10346=81023=310=220
1128=99=25235=X49=SAMPLE75=2017010134=482752=2017010114085306685491960=201701011408530668549195799=10000100268=2279=1269=148=17359555=6SZ683=357185270=10216.0271=10346=81023=1279=1269=148=17359555=6SZ683=357186270=10217.0271=7346=51023=210=223
1128=99=25135=X49=SAMPLE75=2017010134=275352=2017010105310351298653960=201701010531035129865395799=10000100268=2279=1269=148=17359555=6SZ683=357187270=10221.0271=4346=21023=6279=1269=148=17359555=6SZ683=357188270=10222.0271=7346=31023=710=156
1128=99=18035=X49=SAMPLE75=2017010134=82752=2017010106421053128109460=201701010642105312810945799=10000100268=1279=1269=048=17359555=6SZ683=357189270=10214.0271=8346=81023=210=123
1128=99=17935=X49=SAMPLE75=2017010134=134352=2017010103305142451582760=201701010330514245158275799=10000100268=1279=0269=048=17360055=6SH783=99273270=10267.0271=3346=11023=110=042
1128=99=24935=X49=SAMPLE75=2017010134=240252=2017010113063893818627660=201701011306389381862765799=10000100268=2279=1269=048=17360055=6SH783=99274270=10266.0271=5346=21023=2279=1269=048=17360055=6SH783=99275270=10264.0271=3346=11023=410=006
1128=99=24735=X49=SAMPLE75=2017010134=337452=2017010102021234766270060=201701010202123476627005799=10000100268=2279=0269=048=17360355=6SM783=7547270=10284.0271=6346=11023=4279=2269=048=17360355=6SM783=7548270=10283.0271=6346=11023=510=189
1128=99=17935=X49=SAMPLE75=2017010134=362552=2017010108553544847100060=201701010855354484710005799=00000100268=1279=0269=048=17360355=6SM783=7549270=10308.0271=15346=11023=110=049
1128=99=16735=X49=SAMPLE75=2017010134=130152=2017010103060242207659860=201701010306024220765985799=10001000268=1279=0269=N48=17360355=6SM783=7550270=10308.0286=25510=064
1128=99=17935=X49=SAMPLE75=2017010134=37152=2017010101220545241218360=201701010122054524121835799=10000100268=1279=1269=048=17360355=6SM783=7551270=10304.0271=12346=21023=210=042
1128=99=17935=X49=SAMPLE75=2017010134=130852=2017010104483234219757560=201701010448323421975755799=10000100268=1279=2269=048=17360355=6SM783=7552270=10299.0271=10346=11023=310=059
1128=99=22035=X49=SAMPLE75=2017010134=362252=2017010101011021445540460=201701010101102144554045799=00000001268=1279=0269=248=17359555=6SZ683=357190270=10215.0271=1346=25797=237705=237=032=137=621180793857732=110=200
1128=99=15635=X49=SAMPLE75=2017010134=11052=2017010103115113092456860=201701010311511309245685799=00000010268=1279=0269=e48=17359555=6SZ683=357191271=6110=102
1128=99=25335=X49=SAMPLE75=2017010134=267752=2017010112560402265425960=201701011256040226542595799=00000100268=2279=2269=048=17359555=6SZ683=357192270=10215.0271=1346=11023=1279=0269=048=17359555=6SZ683=357193270=10205.0271=10346=41023=1010=243
1128=99=16935=X49=SAMPLE75=2017010134=5352=2017010104245909154561660=201701010424590915456165799=10001000268=1279=0269=748=17359555=6SZ683=357194270=10215.0286=25510=169
1128=99=18035=X49=SAMPLE75=2017010134=421352=2017010113194803197461360=201701011319480319746135799=10000100268=1279=1269=148=17359555=6SZ683=357195270=10216.0271=9346=71023=110=130
1128=99=25135=X49=SAMPLE75=2017010134=162752=2017010110005217654730160=201701011000521765473015799=10000100268=2279=0269=048=17359555=6SZ683=357196270=10215.0271=1346=11023=1279=1269=048=17359555=6SZ683=357197270=10214.0271=7346=71023=210=175
1128=99=25235=X49=SAMPLE75=2017010134=466452=2017010109290683516774560=201701010929068351677455799=10000100268=2279=1269=148=17359555=6SZ683=357198270=10220.0271=7346=51023=5279=1269=148=17359555=6SZ683=357199270=10223.0271=11346=31023=810=245
1128=99=24835=X49=SAMPLE75=2017010134=37752=2017010103110243610015560=201701010311024361001555799=00000100268=2279=0269=048=17360355=6SM783=7553270=10309.0271=2346=11023=1279=1269=048=17360355=6SM783=7554270=10304.0271=10346=11023=310=200
1128=99=16735=X49=SAMPLE75=2017010134=268952=2017010113464585121026860=201701011346458512102685799=10001000268=1279=0269=N48=17360355=6SM783=7555270=10309.0286=25510=061
1128=99=20835=X49=SAMPLE75=2017010134=61052=2017010108102904924796760=201701010810290492479675799=00000001268=1279=0269=248=17359555=6SZ683=357200270=10215.0271=1346=25797=237705=237=032=137=032=110=085
1128=99=15635=X49=SAMPLE75=2017010134=362752=2017010102185678711355760=201701010218567871135575799=00000010268=1279=0269=e48=17359555=6SZ683=357201271=6210=090
1128=99=25335=X49=SAMPLE75=2017010134=361052=2017010104490942476999060=201701010449094247699905799=10000100268=2279=2269=048=17359555=6SZ683=357202270=10215.0271=1346=11023=1279=0269=048=17359555=6SZ683=357203270=10205.0271=10346=41023=1010=223
1128=99=24935=X49=SAMPLE75=2017010134=83152=2017010101002733224553160=201701010100273322455315799=10000100268=2279=1269=048=17360355=6SM783=7556270=10309.0271=17346=21023=1279=2269=048=17360355=6SM783=7557270=10308.0271=15346=11023=210=029
1128=99=18035=X49=SAMPLE75=2017010134=462052=2017010108470038432506660=201701010847003843250665799=10000100268=1279=1269=148=17359555=6SZ683=357204270=10216.0271=8346=61023=110=138
1128=99=18035=X49=SAMPLE75=2017010134=116452=2017010103261615875952960=201701010326161587595295799=10000100268=1279=1269=148=17359555=6SZ683=357205270=10223.0271=4346=21023=810=133
1128=99=18135=X49=SAMPLE75=2017010134=404552=2017010101171918941165560=201701010117191894116555799=10000100268=1279=1269=148=17359555=6SZ683=357206270=10225.0271=8346=11023=1010=187
1128=99=18035=X49=SAMPLE75=2017010134=357352=2017010106040596947599860=201701010604059694759985799=10000100268=1279=1269=148=17359555=6SZ683=357207270=10224.0271=1346=11023=910=124
1128=99=18035=X49=SAMPLE75=2017010134=442752=2017010106232235132405260=201701010623223513240525799=10000100268=1279=1269=148=17359555=6SZ683=357208270=10216.0271=9346=71023=110=141
1128=99=18135=X49=SAMPLE75=2017010134=142552=2017010114141834399621660=201701011414183439962165799=10000100268=1279=1269=148=17359555=6SZ683=357209270=10223.0271=11346=31023=810=160
1128=99=18035=X49=SAMPLE75=2017010134=317152=2017010103490511103990560=201701010349051110399055799=10000100268=1279=1269=148=17359555=6SZ683=357210270=10224.0271=8346=21023=910=104
1128=99=18235=X49=SAMPLE75=2017010134=454952=2017010110092932901077460=201701011009293290107745799=10000100268=1279=1269=148=17359555=6SZ683=357211270=10225.0271=15346=21023=1010=204
1128=99=25135=X49=SAMPLE75=2017010134=345152=2017010101515894341017660=201701010151589434101765799=10000100268=2279=1269=148=17359555=6SZ683=357212270=10221.0271=7346=31023=6279=1269=148=17359555=6SZ683=357213270=10222.0271=4346=21023=710=144
1128=99=25235=X49=SAMPLE75=2017010134=123852=2017010100174878115080360=201701010017487811508035799=10000100268=2279=1269=048=17359555=6SZ683=357214270=10214.0271=6346=61023=1279=1269=048=17359555=6SZ683=357215270=10213.0271=11346=91023=210=197
1128=99=25235=X49=SAMPLE75=2017010134=488252=2017010112144460032928260=201701011214446003292825799=10000100268=2279=1269=148=17359555=6SZ683=357216270=10216.0271=10346=81023=1279=1269=148=17359555=6SZ683=357217270=10217.0271=6346=41023=210=230
1128=99=18035=X49=SAMPLE75=2017010134=150452=2017010106464091710557360=201701010646409171055735799=10000100268=1279=1269=148=17359555=6SZ683=357218270=10223.0271=4346=21023=810=125
1128=99=18035=X49=SAMPLE75=2017010134=298352=2017010112593930137681860=201701011259393013768185799=10000100268=1279=1269=148=17359555=6SZ683=357219270=10224.0271=1346=11023=910=108
1128=99=18135=X49=SAMPLE75=2017010134=416952=2017010111433136168619360=201701011143313616861935799=10000100268=1279=1269=148=17359555=6SZ683=357220270=10225.0271=8346=11023=1010=175
1128=99=18035=X49=SAMPLE75=2017010134=121752=2017010108512945178965260=201701010851294517896525799=10000100268=1279=1269=048=17359555=6SZ683=357221270=10214.0271=9346=71023=110=130
1128=99=18035=X49=SAMPLE75=2017010134=343852=2017010114202629587469260=201701011420262958746925799=10000100268=1279=1269=148=17359555=6SZ683=357222270=10217.0271=7346=51023=210=144
1128=99=25135=X49=SAMPLE75=2017010134=368052=2017010102092917447220460=201701010209291744722045799=10000100268=2279=1269=148=17359555=6SZ683=357223270=10221.0271=4346=21023=6279=1269=148=17359555=6SZ683=357224270=10222.0271=7346=31023=710=138
1128=99=25135=X49=SAMPLE75=2017010134=2652=2017010114060632845118060=201701011406063284511805799=10000100268=2279=1269=148=17359555=6SZ683=357225270=10216.0271=9346=71023=1279=1269=148=17359555=6SZ683=357226270=10217.0271=8346=61023=210=156
1128=99=25335=X49=SAMPLE75=2017010134=385352=2017010107365444969110660=201701010736544496911065799=10000100268=2279=1269=048=17359555=6SZ683=357227270=10214.0271=10346=81023=1279=1269=048=17359555=6SZ683=357228270=10213.0271=10346=81023=210=230
1128=99=18035=X49=SAMPLE75=2017010134=77052=2017010103492794128464860=201701010349279412846485799=10000100268=1279=1269=148=17359555=6SZ683=357229270=10216.0271=8346=61023=110=085
1128=99=25135=X49=SAMPLE75=2017010134=18552=2017010106303267071585560=201701010630326707158555799=10000100268=2279=1269=148=17359555=6SZ683=357230270=10221.0271=7346=31023=6279=1269=148=17359555=6SZ683=357231270=10222.0271=4346=21023=710=124
1128=99=25235=X49=SAMPLE75=2017010134=84852=2017010112083684593839860=201701011208368459383985799=10000100268=2279=1269=048=17359555=6SZ683=357232270=10214.0271=9346=71023=1279=1269=048=17359555=6SZ683=357233270=10213.0271=11346=91023=210=188
1128=99=25135=X49=SAMPLE75=2017010134=154152=2017010112215371041869960=201701011221537104186995799=10000100268=2279=1269=148=17359555=6SZ683=357234270=10216.0271=9346=71023=1279=1269=148=17359555=6SZ683=357235270=10217.0271=7346=51023=210=154
1128=99=18135=X49=SAMPLE75=2017010134=285952=2017010102063196894306560=201701010206319689430655799=10000100268=1279=1269=148=17359555=6SZ683=357236270=10216.0271=10346=81023=110=123
1128=99=25235=X49=SAMPLE75=2017010134=9852=2017010104550727132854460=201701010455072713285445799=10000100268=2279=1269=048=17359555=6SZ683=357237270=10210.0271=8346=61023=5279=1269=048=17359555=6SZ683=357238270=10209.0271=11346=71023=610=205
1128=99=18135=X49=SAMPLE75=2017010134=95452=2017010100532890292859760=201701010053289029285975799=10000100268=1279=1269=148=17359555=6SZ683=357239270=10223.0271=11346=31023=810=148
1128=99=18035=X49=SAMPLE75=2017010134=478252=2017010108062166258415160=201701010806216625841515799=10000100268=1279=1269=148=17359555=6SZ683=357240270=10224.0271=8346=21023=910=097
1128=99=18235=X49=SAMPLE75=2017010134=495352=2017010111471396763582360=201701011147139676358235799=10000100268=1279=1269=148=17359555=6SZ683=357241270=10225.0271=15346=21023=1010=183
1128=99=18135=X49=SAMPLE75=2017010134=329652=2017010111384510576122860=201701011138451057612285799=10000100268=1279=1269=148=17359555=6SZ683=357242270=10225.0271=8346=11023=1010=175
1128=99=18035=X49=SAMPLE75=2017010134=352952=2017010105521301381249960=201701010552130138124995799=10000100268=1279=1269=148=17359555=6SZ683=357243270=10224.0271=1346=11023=910=115
1128=99=18035=X49=SAMPLE75=2017010134=185952=2017010111085257875802460=201701011108525787580245799=10000100268=1279=1269=148=17359555=6SZ683=357244270=10223.0271=4346=21023=810=127
1128=99=18135=X49=SAMPLE75=2017010134=19052=2017010108243192070165460=201701010824319207016545799=10000100268=1279=1269=148=17359555=6SZ683=357245270=10223.0271=11346=31023=810=153
1128=99=18035=X49=SAMPLE75=2017010134=208152=2017010107410676953477760=201701010741067695347775799=10000100268=1279=1269=148=17359555=6SZ683=357246270=10224.0271=8346=21023=910=110
1128=99=18235=X49=SAMPLE75=2017010134=75952=2017010102020026504711160=201701010202002650471115799=10000100268=1279=1269=148=17359555=6SZ683=357247270=10225.0271=15346=21023=1010=192
1128=99=18035=X49=SAMPLE75=2017010134=313752=2017010107211724272726360=201701010721172427272635799=10000100268=1279=1269=148=17359555=6SZ683=357248270=10223.0271=4346=21023=810=136
1128=99=18135=X49=SAMPLE75=2017010134=23752=2017010103430453992161460=201701010343045399216145799=10000100268=1279=1269=148=17359555=6SZ683=357249270=10225.0271=8346=11023=1010=170
1128=99=18035=X49=SAMPLE75=2017010134=97952=2017010104405292965820260=201701010440529296582025799=10000100268=1279=1269=148=17359555=6SZ683=357250270=10224.0271=1346=11023=910=110
1128=99=25235=X49=SAMPLE75=2017010134=380452=2017010103272751838981060=201701010327275183898105799=10000100268=2279=1269=048=17359555=6SZ683=357251270=10210.0271=11346=71023=5279=1269=048=17359555=6SZ683=357252270=10209.0271=8346=61023=610=179
1128=99=18235=X49=SAMPLE75=2017010134=264152=2017010112322116011321960=201701011232211601132195799=10000100268=1279=1269=048=17359555=6SZ683=357253270=10212.0271=19346=101023=310=177
1128=99=18135=X49=SAMPLE75=2017010134=112552=2017010102252139448998060=201701010225213944899805799=10000100268=1279=1269=148=17359555=6SZ683=357254270=10218.0271=15346=61023=310=152
1128=99=25135=X49=SAMPLE75=2017010134=189752=2017010106110319407299160=201701010611031940729915799=10000100268=2279=1269=148=17359555=6SZ683=357255270=10216.0271=9346=71023=1279=1269=148=17359555=6SZ683=357256270=10220.0271=8346=61023=510=149
1128=99=18235=X49=SAMPLE75=2017010134=366352=2017010106054322299205760=201701010605432229920575799=10000100268=1279=1269=048=17359555=6SZ683=357257270=10213.0271=19346=101023=210=193
1128=99=18135=X49=SAMPLE75=2017010134=10052=2017010113234572221401760=201701011323457222140175799=10000100268=1279=1269=148=17359555=6SZ683=357258270=10217.0271=15346=61023=210=141
1128=99=18135=X49=SAMPLE75=2017010134=487852=2017010100481496534473060=201701010048149653447305799=10000100268=1279=1269=048=17359555=6SZ683=357259270=10211.0271=15346=71023=410=162
1128=99=18135=X49=SAMPLE75=2017010134=56352=2017010103033786476547360=201701010303378647654735799=10000100268=1279=1269=048=17359555=6SZ683=357260270=10210.0271=19346=81023=510=156
1128=99=18135=X49=SAMPLE75=2017010134=99052=2017010112593670485091860=201701011259367048509185799=10000100268=1279=1269=048=17359555=6SZ683=357261270=10209.0271=16346=71023=610=136
1128=99=18135=X49=SAMPLE75=2017010134=140652=2017010109370854840846260=201701010937085484084625799=10000100268=1279=1269=048=17359555=6SZ683=357262270=10208.0271=16346=71023=710=139
1128=99=18135=X49=SAMPLE75=2017010134=4252=2017010105295894061068260=201701010529589406106825799=10000100268=1279=1269=148=17359555=6SZ683=357263270=10219.0271=21346=81023=410=166
1128=99=18135=X49=SAMPLE75=2017010134=239352=2017010111542988241918160=201701011154298824191815799=10000100268=1279=1269=148=17359555=6SZ683=357264270=10220.0271=16346=71023=510=156
1128=99=18135=X49=SAMPLE75=2017010134=305052=2017010105123439422196060=201701010512343942219605799=10000100268=1279=1269=148=17359555=6SZ683=357265270=10221.0271=15346=41023=610=151
1128=99=18135=X49=SAMPLE75=2017010134=450152=2017010108532539444109260=201701010853253944410925799=10000100268=1279=1269=148=17359555=6SZ683=357266270=10222.0271=12346=31023=710=138
1128=99=25335=X49=SAMPLE75=2017010134=126452=2017010104362515584889460=201701010436251558488945799=10000100268=2279=1269=148=17359555=6SZ683=357267270=10216.0271=10346=81023=1279=1269=148=17359555=6SZ683=357268270=10220.0271=15346=61023=510=236
1128=99=18135=X49=SAMPLE75=2017010134=145552=2017010110260069993111860=201701011026006999311185799=10000100268=1279=1269=148=17359555=6SZ683=357269270=10223.0271=11346=31023=810=158
1128=99=18035=X49=SAMPLE75=2017010134=441352=2017010101301119637359060=201701010130111963735905799=10000100268=1279=1269=148=17359555=6SZ683=357270270=10224.0271=8346=21023=910=108
1128=99=18235=X49=SAMPLE75=2017010134=230452=2017010107574374748672460=201701010757437474867245799=10000100268=1279=1269=148=17359555=6SZ683=357271270=10225.0271=15346=21023=1010=197
1128=99=18135=X49=SAMPLE75=2017010134=378152=2017010106395407156728460=201701010639540715672845799=10000100268=1279=1269=148=17359555=6SZ683=357272270=10224.0271=28346=31023=910=151
1128=99=18135=X49=SAMPLE75=2017010134=182152=2017010112044573673476860=201701011204457367347685799=10000100268=1279=1269=148=17359555=6SZ683=357273270=10221.0271=22346=51023=610=126
1128=99=18135=X49=SAMPLE75=2017010134=169852=2017010101112903014279660=201701010111290301427965799=10000100268=1279=1269=148=17359555=6SZ683=357274270=10222.0271=19346=41023=710=144
1128=99=18135=X49=SAMPLE75=2017010134=217652=2017010114214742840673060=201701011421474284067305799=10000100268=1279=1269=048=17359555=6SZ683=357275270=10209.0271=23346=81023=610=176
1128=99=18135=X49=SAMPLE75=2017010134=351352=2017010104332103739842860=201701010433210373984285799=10000100268=1279=1269=048=17359555=6SZ683=357276270=10208.0271=23346=81023=710=168
1128=99=18135=X49=SAMPLE75=2017010134=275852=2017010104425019435960260=201701010442501943596025799=10000100268=1279=1269=048=17359555=6SZ683=357277270=10207.0271=13346=51023=810=175
1128=99=18135=X49=SAMPLE75=2017010134=20552=2017010106333945219926660=201701010633394521992665799=10000100268=1279=1269=048=17359555=6SZ683=357278270=10206.0271=12346=41023=910=190
1128=99=18235=X49=SAMPLE75=2017010134=201352=2017010107255414671569760=201701010725541467156975799=10000100268=1279=1269=048=17359555=6SZ683=357279270=10205.0271=17346=51023=1010=229
1128=99=18135=X49=SAMPLE75=2017010134=412652=2017010101444576343854360=201701010144457634385435799=10000100268=1279=1269=048=17359555=6SZ683=357280270=10206.0271=32346=51023=910=172
1128=99=18135=X49=SAMPLE75=2017010134=222552=2017010103031097719342260=201701010303109771934225799=10000100268=1279=1269=148=17359555=6SZ683=357281270=10220.0271=22346=71023=510=177
1128=99=18135=X49=SAMPLE75=2017010134=432152=2017010105170475654486760=201701010517047565448675799=10000100268=1279=1269=048=17359555=6SZ683=357282270=10210.0271=26346=91023=510=165
1128=99=18035=X49=SAMPLE75=2017010134=439052=2017010110293295198325960=201701011029329519832595799=10000100268=1279=1269=148=17359555=6SZ683=357283270=10216.0271=9346=71023=110=137
1128=99=25335=X49=SAMPLE75=2017010134=162052=2017010105062004887521960=201701010506200488752195799=10000100268=2279=1269=148=17359555=6SZ683=357284270=10220.0271=30346=81023=5279=1269=148=17359555=6SZ683=357285270=10225.0271=7346=11023=1010=250
1128=99=18035=X49=SAMPLE75=2017010134=389052=2017010106580671780924160=201701010658067178092415799=10000100268=1279=1269=148=17360055=6SH783=99276270=10279.0271=11346=21023=810=079
1128=99=18135=X49=SAMPLE75=2017010134=37852=2017010114061562237412360=201701011406156223741235799=10000100268=1279=1269=148=17360055=6SH783=99277270=10281.0271=11346=21023=1010=133
1128=99=18135=X49=SAMPLE75=2017010134=112752=2017010104005368870069560=201701010400536887006955799=10000100268=1279=1269=148=17359555=6SZ683=357286270=10222.0271=27346=51023=710=166
1128=99=18035=X49=SAMPLE75=2017010134=320752=2017010107530774057162360=201701010753077405716235799=10000100268=1279=1269=048=17360055=6SH783=99278270=10261.0271=11346=21023=710=049
1128=99=18235=X49=SAMPLE75=2017010134=28952=2017010103583495724195060=201701010358349572419505799=10000100268=1279=1269=048=17359555=6SZ683=357287270=10210.0271=34346=101023=510=209
1128=99=18035=X49=SAMPLE75=2017010134=220552=2017010103395287126808160=201701010339528712680815799=10000100268=1279=1269=048=17360055=6SH783=99279270=10259.0271=11346=21023=910=058
1128=99=18135=X49=SAMPLE75=2017010134=461752=2017010108311344821049260=201701010831134482104925799=10000100268=1279=1269=048=17359555=6SZ683=357288270=10208.0271=31346=91023=710=168
1128=99=18135=X49=SAMPLE75=2017010134=240252=2017010107544840697649660=201701010754484069764965799=10000100268=1279=1269=048=17359555=6SZ683=357289270=10214.0271=17346=81023=110=177
1128=99=18135=X49=SAMPLE75=2017010134=287652=2017010103175712577331960=201701010317571257733195799=10000100268=1279=1269=148=17359555=6SZ683=357290270=10220.0271=23346=71023=510=135
1128=99=18135=X49=SAMPLE75=2017010134=499352=2017010112034682681392160=201701011203468268139215799=10000100268=1279=1269=048=17359555=6SZ683=357291270=10210.0271=27346=91023=510=144
1128=99=18135=X49=SAMPLE75=2017010134=427152=2017010109545560833105060=201701010954556083310505799=10000100268=1279=1269=148=17359555=6SZ683=357292270=10220.0271=30346=81023=510=178
1128=99=18235=X49=SAMPLE75=2017010134=181752=2017010111092176330420760=201701011109217633042075799=10000100268=1279=1269=048=17359555=6SZ683=357293270=10210.0271=34346=101023=510=232
1128=99=18135=X49=SAMPLE75=2017010134=4652=2017010110442076668888360=201701011044207666888835799=10000100268=1279=1269=048=17359555=6SZ683=357294270=10207.0271=21346=61023=810=180
1128=99=18135=X49=SAMPLE75=2017010134=303352=2017010110125393476347060=201701011012539347634705799=10000100268=1279=1269=148=17359555=6SZ683=357295270=10223.0271=19346=41023=810=190
1128=99=18135=X49=SAMPLE75=2017010134=493952=2017010111165489885877060=201701011116548988587705799=10000100268=1279=1269=048=17359555=6SZ683=357296270=10206.0271=40346=61023=910=185
1128=99=18135=X49=SAMPLE75=2017010134=249052=2017010112515345355761160=201701011251534535576115799=10000100268=1279=1269=148=17359555=6SZ683=357297270=10224.0271=36346=41023=910=167
1128=99=18235=X49=SAMPLE75=2017010134=375652=2017010101512184741737560=201701010151218474173755799=10000100268=1279=1269=048=17359555=6SZ683=357298270=10205.0271=25346=61023=1010=219
1128=99=18235=X49=SAMPLE75=2017010134=129952=2017010111043209035360660=201701011104320903536065799=10000100268=1279=1269=148=17359555=6SZ683=357299270=10225.0271=15346=21023=1010=231
1128=99=18135=X49=SAMPLE75=2017010134=288352=2017010110375759759046060=201701011037575975904605799=10000100268=1279=1269=048=17359555=6SZ683=357300270=10213.0271=18346=91023=210=134
1128=99=18135=X49=SAMPLE75=2017010134=251052=2017010107495212891755660=201701010749521289175565799=10000100268=1279=1269=048=17359555=6SZ683=357301270=10214.0271=18346=91023=110=146
1128=99=18135=X49=SAMPLE75=2017010134=242352=2017010111153254191942760=201701011115325419194275799=10000100268=1279=1269=148=17359555=6SZ683=357302270=10216.0271=10346=81023=110=180
1128=99=25335=X49=SAMPLE75=2017010134=381652=2017010109071405548940160=201701010907140554894015799=10000100268=2279=1269=048=17359555=6SZ683=357303270=10210.0271=31346=91023=5279=1269=048=17359555=6SZ683=357304270=10209.0271=26346=91023=610=019
1128=99=18035=X49=SAMPLE75=2017010134=458452=2017010113542852075875660=201701011354285207587565799=10000100268=1279=1269=148=17359555=6SZ683=357305270=10216.0271=9346=71023=110=116
1128=99=18135=X49=SAMPLE75=2017010134=236052=2017010100134174470528860=201701010013417447052885799=10000100268=1279=1269=048=17359555=6SZ683=357306270=10214.0271=17346=81023=110=130
1128=99=25435=X49=SAMPLE75=2017010134=326852=2017010113572271025917960=201701011357227102591795799=10000100268=2279=1269=048=17359555=6SZ683=357307270=10210.0271=34346=101023=5279=1269=048=17359555=6SZ683=357308270=10209.0271=23346=81023=610=079
1128=99=18135=X49=SAMPLE75=2017010134=294952=2017010106045930963094060=201701010604593096309405799=10000100268=1279=1269=048=17359555=6SZ683=357309270=10214.0271=18346=91023=110=168
1128=99=25335=X49=SAMPLE75=2017010134=428652=2017010114285977034433660=201701011428597703443365799=10000100268=2279=1269=048=17359555=6SZ683=357310270=10210.0271=31346=91023=5279=1269=048=17359555=6SZ683=357311270=10209.0271=26346=91023=610=002
1128=99=25435=X49=SAMPLE75=2017010134=203952=2017010106020963272531460=201701010602096327253145799=10000100268=2279=1269=048=17359555=6SZ683=357312270=10210.0271=34346=101023=5279=1269=048=17359555=6SZ683=357313270=10209.0271=23346=81023=610=000
1128=99=25335=X49=SAMPLE75=2017010134=13852=2017010109324755456251260=201701010932475545625125799=10000100268=2279=1269=048=17359555=6SZ683=357314270=10210.0271=31346=91023=5279=1269=048=17359555=6SZ683=357315270=10209.0271=26346=91023=610=009
1128=99=25435=X49=SAMPLE75=2017010134=271252=2017010100131749136369760=201701010013174913636975799=10000100268=2279=1269=048=17359555=6SZ683=357316270=10210.0271=34346=101023=5279=1269=048=17359555=6SZ683=357317270=10209.0271=23346=81023=610=059
1128=99=18035=X49=SAMPLE75=2017010134=163252=2017010108354719250261460=201701010835471925026145799=10000100268=1279=1269=148=17359555=6SZ683=357318270=10216.0271=8346=61023=110=125
1128=99=18035=X49=SAMPLE75=2017010134=72652=2017010100354124838289460=201701010035412483828945799=10000100268=1279=1269=148=17359555=6SZ683=357319270=10216.0271=7346=51023=110=104
1128=99=18135=X49=SAMPLE75=2017010134=14952=2017010107265584575359960=201701010726558457535995799=10000100268=1279=1269=148=17359555=6SZ683=357320270=10221.0271=23346=61023=610=147
1128=99=18135=X49=SAMPLE75=2017010134=383752=2017010108452109239782660=201701010845210923978265799=10000100268=1279=1269=148=17359555=6SZ683=357321270=10221.0271=24346=71023=610=160
1128=99=18035=X49=SAMPLE75=2017010134=178352=2017010110274650861479860=201701011027465086147985799=10000100268=1279=1269=148=17359555=6SZ683=357322270=10216.0271=6346=41023=110=093
1128=99=18135=X49=SAMPLE75=2017010134=71352=2017010109085719946612760=201701010908571994661275799=10000100268=1279=1269=148=17359555=6SZ683=357323270=10221.0271=25346=81023=610=171
1128=99=18035=X49=SAMPLE75=2017010134=129752=2017010110222361593085160=201701011022236159308515799=10000100268=1279=1269=148=17359555=6SZ683=357324270=10216.0271=7346=51023=110=127
1128=99=18035=X49=SAMPLE75=2017010134=444452=2017010100390764618765060=201701010039076461876505799=10000100268=1279=1269=148=17359555=6SZ683=357325270=10216.0271=8346=61023=110=135
1128=99=18035=X49=SAMPLE75=2017010134=303052=2017010106565856228542760=201701010656585622854275799=10000100268=1279=1269=148=17359555=6SZ683=357326270=10216.0271=9346=71023=110=126
1128=99=25335=X49=SAMPLE75=2017010134=335452=2017010107384078738417160=201701010738407873841715799=10000100268=2279=1269=048=17359555=6SZ683=357327270=10210.0271=31346=91023=5279=1269=048=17359555=6SZ683=357328270=10209.0271=26346=91023=610=013
1128=99=17935=X49=SAMPLE75=2017010134=384452=2017010104412573166778960=201701010441257316677895799=10000100268=1279=1269=048=17360055=6SH783=99280270=10261.0271=3346=11023=710=031
1128=99=18135=X49=SAMPLE75=2017010134=253752=2017010108020694105757460=201701010802069410575745799=10000100268=1279=1269=048=17359555=6SZ683=357329270=10214.0271=17346=81023=110=152
1128=99=25435=X49=SAMPLE75=2017010134=287352=2017010110022029078538760=201701011002202907853875799=10000100268=2279=1269=048=17359555=6SZ683=357330270=10210.0271=34346=101023=5279=1269=048=17359555=6SZ683=357331270=10209.0271=23346=81023=610=044
1128=99=25335=X49=SAMPLE75=2017010134=492252=2017010101181747619269760=201701010118174761926975799=10000100268=2279=1269=048=17359555=6SZ683=357332270=10210.0271=31346=91023=5279=1269=048=17359555=6SZ683=357333270=10209.0271=26346=91023=610=021
1128=99=18035=X49=SAMPLE75=2017010134=134852=2017010110565867967946160=201701011056586796794615799=10000100268=1279=1269=048=17359555=6SZ683=357334270=10214.0271=9346=71023=110=095
1128=99=18135=X49=SAMPLE75=2017010134=418452=2017010103223412185403060=201701010322341218540305799=10000100268=1279=1269=148=17359555=6SZ683=357335270=10216.0271=10346=81023=110=150
1128=99=25435=X49=SAMPLE75=2017010134=487052=2017010109351917831554760=201701010935191783155475799=10000100268=2279=1269=048=17359555=6SZ683=357336270=10210.0271=34346=101023=5279=1269=048=17359555=6SZ683=357337270=10209.0271=23346=81023=610=073
1128=99=25335=X49=SAMPLE75=2017010134=84552=2017010109063333980148860=201701010906333398014885799=10000100268=2279=1269=048=17359555=6SZ683=357338270=10210.0271=31346=91023=5279=1269=048=17359555=6SZ683=357339270=10209.0271=26346=91023=610=043
1128=99=25435=X49=SAMPLE75=2017010134=169052=2017010102023271080555660=201701010202327108055565799=10000100268=2279=1269=048=17359555=6SZ683=357340270=10210.0271=34346=101023=5279=1269=048=17359555=6SZ683=357341270=10209.0271=23346=81023=610=046
1128=99=18035=X49=SAMPLE75=2017010134=46052=2017010111175475169787760=201701011117547516978775799=10000100268=1279=1269=148=17359555=6SZ683=357342270=10216.0271=9346=71023=110=103
1128=99=25335=X49=SAMPLE75=2017010134=427252=2017010107241292907508760=201701010724129290750875799=10000100268=2279=1269=148=17359555=6SZ683=357343270=10221.0271=22346=71023=6279=1269=148=17359555=6SZ683=357344270=10222.0271=30346=61023=710=013
1128=99=25335=X49=SAMPLE75=2017010134=384052=2017010113504103611860160=201701011350410361186015799=10000100268=2279=1269=048=17359555=6SZ683=357345270=10214.0271=10346=81023=1279=1269=048=17359555=6SZ683=357346270=10213.0271=17346=81023=210=016
1128=99=25235=X49=SAMPLE75=2017010134=464652=2017010101473750087286160=201701010147375008728615799=10000100268=2279=1269=148=17359555=6SZ683=357347270=10216.0271=8346=61023=1279=1269=148=17359555=6SZ683=357348270=10217.0271=16346=71023=210=238
1128=99=25335=X49=SAMPLE75=2017010134=87652=2017010102561771207688660=201701010256177120768865799=10000100268=2279=1269=148=17359555=6SZ683=357349270=10221.0271=25346=81023=6279=1269=148=17359555=6SZ683=357350270=10222.0271=27346=51023=710=253
1128=99=25235=X49=SAMPLE75=2017010134=88052=2017010107144689186098460=201701010714468918609845799=10000100268=2279=1269=148=17359555=6SZ683=357351270=10216.0271=9346=71023=1279=1269=148=17359555=6SZ683=357352270=10217.0271=15346=61023=210=206
1128=99=25235=X49=SAMPLE75=2017010134=33552=2017010111593772828353860=201701011159377282835385799=10000100268=2279=1269=048=17359555=6SZ683=357353270=10214.0271=9346=71023=1279=1269=048=17359555=6SZ683=357354270=10213.0271=18346=91023=210=215
1128=99=25335=X49=SAMPLE75=2017010134=57452=2017010114292095717384760=201701011429209571738475799=10000100268=2279=1269=148=17359555=6SZ683=357355270=10221.0271=22346=71023=6279=1269=148=17359555=6SZ683=357356270=10222.0271=30346=61023=710=252
1128=99=25235=X49=SAMPLE75=2017010134=400552=2017010102102295435645260=201701010210229543564525799=10000100268=2279=1269=148=17359555=6SZ683=357357270=10216.0271=8346=61023=1279=1269=148=17359555=6SZ683=357358270=10217.0271=16346=71023=210=239
1128=99=25335=X49=SAMPLE75=2017010134=497652=2017010104431831651324960=201701010443183165132495799=10000100268=2279=1269=048=17359555=6SZ683=357359270=10214.0271=10346=81023=1279=1269=048=17359555=6SZ683=357360270=10213.0271=17346=81023=210=008
1128=99=25335=X49=SAMPLE75=2017010134=454852=2017010108513983835258160=201701010851398383525815799=10000100268=2279=1269=148=17359555=6SZ683=357361270=10221.0271=25346=81023=6279=1269=148=17359555=6SZ683=357362270=10222.0271=27346=51023=710=254
1128=99=25235=X49=SAMPLE75=2017010134=300352=2017010104065534017996760=201701010406553401799675799=10000100268=2279=1269=148=17359555=6SZ683=357363270=10216.0271=9346=71023=1279=1269=148=17359555=6SZ683=357364270=10217.0271=15346=61023=210=221
1128=99=25235=X49=SAMPLE75=2017010134=11252=2017010108441878664679360=201701010844187866467935799=10000100268=2279=1269=048=17359555=6SZ683=357365270=10214.0271=9346=71023=1279=1269=048=17359555=6SZ683=357366270=10213.0271=18346=91023=210=210
1128=99=18235=X49=SAMPLE75=2017010134=78152=2017010105274451774657060=201701010527445177465705799=10000100268=1279=1269=048=17359555=6SZ683=357367270=10213.0271=19346=101023=210=227
1128=99=18035=X49=SAMPLE75=2017010134=456852=2017010100425334297254760=201701010042533429725475799=10000100268=1279=1269=048=17359555=6SZ683=357368270=10214.0271=8346=61023=110=092
1128=99=18135=X49=SAMPLE75=2017010134=281052=2017010106145833647863260=201701010614583364786325799=10000100268=1279=1269=148=17359555=6SZ683=357369270=10216.0271=10346=81023=110=158
1128=99=18035=X49=SAMPLE75=2017010134=341652=2017010100543766118341560=201701010054376611834155799=10000100268=1279=1269=048=17359555=6SZ683=357370270=10214.0271=9346=71023=110=110
1128=99=18035=X49=SAMPLE75=2017010134=51452=2017010101573351786342860=201701010157335178634285799=10000100268=1279=1269=148=17359555=6SZ683=357371270=10216.0271=9346=71023=110=107
1128=99=18035=X49=SAMPLE75=2017010134=124452=2017010108165391667567760=201701010816539166756775799=10000100268=1279=1269=048=17359555=6SZ683=357372270=10214.0271=8346=61023=110=120
1128=99=18035=X49=SAMPLE75=2017010134=160352=2017010102415922963452660=201701010241592296345265799=10000100268=1279=1269=048=17359555=6SZ683=357373270=10214.0271=9346=71023=110=132
1128=99=25335=X49=SAMPLE75=2017010134=343652=2017010108494266072126360=201701010849426607212635799=10000100268=2279=1269=048=17359555=6SZ683=357374270=10210.0271=31346=91023=5279=1269=048=17359555=6SZ683=357375270=10209.0271=26346=91023=610=026
1128=99=25435=X49=SAMPLE75=2017010134=246352=2017010108100743731812760=201701010810074373181275799=10000100268=2279=1269=048=17359555=6SZ683=357376270=10210.0271=34346=101023=5279=1269=048=17359555=6SZ683=357377270=10209.0271=23346=81023=610=087
1128=99=25335=X49=SAMPLE75=2017010134=82252=2017010105290000886411760=201701010529000088641175799=10000100268=2279=1269=048=17359555=6SZ683=357378270=10210.0271=31346=91023=5279=1269=048=17359555=6SZ683=357379270=10209.0271=26346=91023=610=019
1128=99=18135=X49=SAMPLE75=2017010134=135952=2017010107433614328885260=201701010743361432888525799=10000100268=1279=1269=148=17359555=6SZ683=357380270=10216.0271=17346=81023=110=181
1128=99=18035=X49=SAMPLE75=2017010134=302952=2017010106415913299353660=201701010641591329935365799=10000100268=1279=1269=048=17359555=6SZ683=357381270=10214.0271=8346=61023=110=126
1128=99=18035=X49=SAMPLE75=2017010134=377352=2017010112353948354336160=201701011235394835433615799=10000100268=1279=0269=148=17359555=6SZ683=357382270=10215.0271=1346=11023=110=132
1128=99=17935=X49=SAMPLE75=2017010134=186052=2017010114330834140280960=201701011433083414028095799=10000100268=1279=0269=148=17360055=6SH783=99281270=10271.0271=3346=11023=110=047
1128=99=18035=X49=SAMPLE75=2017010134=201052=2017010103531332003012460=201701010353133200301245799=10000100268=1279=1269=048=17359555=6SZ683=357383270=10214.0271=5346=51023=110=114
1128=99=25135=X49=SAMPLE75=2017010134=168452=2017010114172969850595860=201701011417296985059585799=10000100268=2279=2269=048=17360055=6SH783=99282270=10267.0271=3346=11023=1279=0269=048=17360055=6SH783=99283270=10257.0271=11346=21023=1010=121
1128=99=25135=X49=SAMPLE75=2017010134=49952=2017010101285348585584060=201701010128534858558405799=10000100268=2279=2269=148=17360055=6SH783=99284270=10271.0271=3346=11023=1279=0269=148=17360055=6SH783=99285270=10281.0271=11346=21023=1010=108
1128=99=25135=X49=SAMPLE75=2017010134=23952=2017010105200699604101560=201701010520069960410155799=10000100268=2279=1269=048=17360055=6SH783=99286270=10261.0271=11346=21023=6279=1269=048=17360055=6SH783=99287270=10257.0271=3346=11023=1010=111
1128=99=18035=X49=SAMPLE75=2017010134=112952=2017010100221776779805760=201701010022177677980575799=10000100268=1279=1269=148=17359555=6SZ683=357384270=10215.0271=2346=21023=110=111
1128=99=18035=X49=SAMPLE75=2017010134=35852=2017010110124049851896260=201701011012404985189625799=10000100268=1279=1269=148=17359555=6SZ683=357385270=10215.0271=3346=31023=110=115
1128=99=18035=X49=SAMPLE75=2017010134=174452=2017010112570068586158360=201701011257006858615835799=10000100268=1279=1269=048=17359555=6SZ683=357386270=10214.0271=4346=41023=110=148
1128=99=18035=X49=SAMPLE75=2017010134=137452=2017010107041230785217460=201701010704123078521745799=10000100268=1279=1269=048=17359555=6SZ683=357387270=10214.0271=3346=31023=110=093
1128=99=18035=X49=SAMPLE75=2017010134=227952=2017010101472544277920560=201701010147254427792055799=10000100268=1279=1269=148=17359555=6SZ683=357388270=10215.0271=4346=41023=110=104
1128=99=18135=X49=SAMPLE75=2017010134=118852=2017010107105605906034560=201701010710560590603455799=10000100268=1279=1269=148=17359555=6SZ683=357389270=10219.0271=28346=91023=510=187
1128=99=18135=X49=SAMPLE75=2017010134=166052=2017010109252670359622160=201701010925267035962215799=10000100268=1279=1269=148=17359555=6SZ683=357390270=10221.0271=45346=91023=710=147
1128=99=18035=X49=SAMPLE75=2017010134=314952=2017010104200016555472760=201701010420001655547275799=10000100268=1279=1269=148=17359555=6SZ683=357391270=10215.0271=5346=51023=110=108
1128=99=18135=X49=SAMPLE75=2017010134=490252=2017010100271564768458060=201701010027156476845805799=10000100268=1279=1269=148=17359555=6SZ683=357392270=10217.0271=14346=51023=310=180
1128=99=18135=X49=SAMPLE75=2017010134=17052=2017010106553486377210160=201701010655348637721015799=10000100268=1279=1269=148=17359555=6SZ683=357393270=10216.0271=18346=91023=210=190
1128=99=18035=X49=SAMPLE75=2017010134=220052=2017010100425067177527160=201701010042506717752715799=10000100268=1279=1269=148=17359555=6SZ683=357394270=10215.0271=4346=41023=110=132
1128=99=18135=X49=SAMPLE75=2017010134=138252=2017010109492479443127960=201701010949247944312795799=10000100268=1279=1269=148=17359555=6SZ683=357395270=10222.0271=26346=41023=810=168
1128=99=18135=X49=SAMPLE75=2017010134=133352=2017010104093567044367260=201701010409356704436725799=10000100268=1279=1269=148=17359555=6SZ683=357396270=10217.0271=15346=61023=310=194
1128=99=18035=X49=SAMPLE75=2017010134=57952=2017010106023759845741760=201701010602375984574175799=10000100268=1279=1269=148=17359555=6SZ683=357397270=10215.0271=5346=51023=110=115
1128=99=18035=X49=SAMPLE75=2017010134=480152=2017010113374421833551860=201701011337442183355185799=10000100268=1279=1269=148=17359555=6SZ683=357398270=10215.0271=6346=61023=110=118
1128=99=17935=X49=SAMPLE75=2017010134=113252=2017010110210022987169760=201701011021002298716975799=10000100268=1279=0269=148=17360055=6SH783=99288270=10271.0271=3346=11023=110=058
1128=99=18035=X49=SAMPLE75=2017010134=71352=2017010109413453367746660=201701010941345336774665799=10000100268=1279=1269=148=17359555=6SZ683=357399270=10215.0271=5346=51023=110=099
1128=99=18035=X49=SAMPLE75=2017010134=242552=2017010102294947692787860=201701010229494769278785799=10000100268=1279=1269=148=17359555=6SZ683=357400270=10215.0271=4346=41023=110=085
1128=99=18035=X49=SAMPLE75=2017010134=97752=2017010104501658615331760=201701010450165861533175799=10000100268=1279=1269=148=17359555=6SZ683=357401270=10215.0271=3346=31023=110=081
1128=99=18035=X49=SAMPLE75=2017010134=183852=2017010110471687994822660=201701011047168799482265799=10000100268=1279=1269=048=17359555=6SZ683=357402270=10214.0271=4346=41023=110=091
1128=99=25135=X49=SAMPLE75=2017010134=232652=2017010102274215610274160=201701010227421561027415799=10000100268=2279=2269=148=17360055=6SH783=99289270=10271.0271=3346=11023=1279=0269=148=17360055=6SH783=99290270=10281.0271=11346=21023=1010=069
1128=99=25235=X49=SAMPLE75=2017010134=8152=2017010110540990518495960=201701011054099051849595799=00000001268=1279=0269=248=17359555=6SZ683=357403270=10215.0271=3346=45797=137705=437=032=337=032=137=621180794231432=137=621180794231632=110=120
1128=99=15635=X49=SAMPLE75=2017010134=429852=2017010103230957456543960=201701010323095745654395799=00000010268=1279=0269=e48=17359555=6SZ683=357404271=6510=090
1128=99=25335=X49=SAMPLE75=2017010134=105852=2017010108454340650682560=201701010845434065068255799=10000100268=2279=2269=148=17359555=6SZ683=357405270=10215.0271=3346=31023=1279=0269=148=17359555=6SZ683=357406270=10225.0271=15346=21023=1010=236
1128=99=17935=X49=SAMPLE75=2017010134=74452=2017010111042050552170660=201701011104205055217065799=00000100268=1279=0269=048=17360055=6SH783=99291270=10268.0271=3346=11023=110=037
1128=99=16835=X49=SAMPLE75=2017010134=72852=2017010105554405777213860=201701010555440577721385799=10001000268=1279=0269=N48=17360055=6SH783=99292270=10268.0286=25510=113
1128=99=18035=X49=SAMPLE75=2017010134=36052=2017010111453108570054960=201701011145310857005495799=10000100268=1279=1269=048=17359555=6SZ683=357407270=10214.0271=5346=51023=110=117
1128=99=17935=X49=SAMPLE75=2017010134=214752=2017010104575354025976660=201701010457535402597665799=10000100268=1279=0269=048=17360055=6SH783=99293270=10267.0271=3346=11023=210=047
1128=99=18035=X49=SAMPLE75=2017010134=158052=2017010101142144414328960=201701010114214441432895799=10000100268=1279=0269=148=17359555=6SZ683=357408270=10215.0271=1346=11023=110=111
1128=99=25435=X49=SAMPLE75=2017010134=436252=2017010106451915624003360=201701010645191562400335799=10000100268=2279=1269=048=17359555=6SZ683=357409270=10210.0271=34346=101023=5279=1269=048=17359555=6SZ683=357410270=10209.0271=23346=81023=610=029
1128=99=25035=X49=SAMPLE75=2017010134=478552=2017010102022318911083360=201701010202231891108335799=10000100268=2279=2269=048=17360055=6SH783=99294270=10268.0271=3346=11023=1279=0269=048=17360055=6SH783=99295270=10258.0271=3346=11023=1010=077
1128=99=25035=X49=SAMPLE75=2017010134=7452=2017010111053558859121760=201701011105355885912175799=10000100268=2279=2269=048=17360055=6SH783=99296270=10267.0271=3346=11023=1279=0269=048=17360055=6SH783=99297270=10257.0271=3346=11023=1010=049
1128=99=25335=X49=SAMPLE75=2017010134=402852=2017010112414898077826260=201701011241489807782625799=10000100268=2279=2269=148=17359555=6SZ683=357411270=10215.0271=1346=11023=1279=0269=148=17359555=6SZ683=357412270=10225.0271=15346=21023=1010=240
1128=99=18035=X49=SAMPLE75=2017010134=252252=2017010101090768607789960=201701010109076860778995799=10000100268=1279=1269=048=17359555=6SZ683=357413270=10214.0271=6346=61023=110=114
1128=99=17935=X49=SAMPLE75=2017010134=72652=2017010101535770834536760=201701010153577083453675799=10000100268=1279=0269=048=17360055=6SH783=99298270=10267.0271=3346=11023=110=063
1128=99=25335=X49=SAMPLE75=2017010134=231052=2017010106012835564364660=201701010601283556436465799=10000100268=2279=1269=148=17359555=6SZ683=357414270=10220.0271=22346=71023=5279=1269=148=17359555=6SZ683=357415270=10224.0271=44346=51023=910=022
1128=99=25335=X49=SAMPLE75=2017010134=158852=2017010105243868022169060=201701010524386802216905799=10000100268=2279=1269=148=17359555=6SZ683=357416270=10220.0271=30346=81023=5279=1269=148=17359555=6SZ683=357417270=10224.0271=36346=41023=910=026
1128=99=18035=X49=SAMPLE75=2017010134=147452=2017010108241397002069960=201701010824139700206995799=10000100268=1279=1269=048=17359555=6SZ683=357418270=10214.0271=5346=51023=110=096
1128=99=25035=X49=SAMPLE75=2017010134=280852=2017010100244193841519860=201701010024419384151985799=10000100268=2279=2269=048=17360055=6SH783=99299270=10267.0271=3346=11023=1279=0269=048=17360055=6SH783=99300270=10257.0271=3346=11023=1010=043
1128=99=25335=X49=SAMPLE75=2017010134=312452=2017010103583394669780360=201701010358339466978035799=10000100268=2279=1269=048=17359555=6SZ683=357419270=10210.0271=31346=91023=5279=1269=048=17359555=6SZ683=357420270=10209.0271=26346=91023=610=235
1128=99=18035=X49=SAMPLE75=2017010134=9852=2017010105370557789132360=201701010537055778913235799=10000100268=1279=1269=048=17359555=6SZ683=357421270=10214.0271=4346=41023=110=113
1128=99=18035=X49=SAMPLE75=2017010134=342452=2017010111461558524450260=201701011146155852445025799=10000100268=1279=1269=048=17359555=6SZ683=357422270=10214.0271=3346=31023=110=115
1128=99=18035=X49=SAMPLE75=2017010134=82052=2017010102544941866850060=201701010254494186685005799=10000100268=1279=0269=148=17359555=6SZ683=357423270=10215.0271=1346=11023=110=114
1128=99=17935=X49=SAMPLE75=2017010134=433652=2017010112532235246003260=201701011253223524600325799=10000100268=1279=0269=148=17360055=6SH783=99301270=10271.0271=3346=11023=110=015
1128=99=18035=X49=SAMPLE75=2017010134=289152=2017010104444518021492560=201701010444451802149255799=10000100268=1279=1269=048=17359555=6SZ683=357424270=10214.0271=2346=21023=110=093
1128=99=18035=X49=SAMPLE75=2017010134=345252=2017010105003867606375260=201701010500386760637525799=10000100268=1279=1269=148=17359555=6SZ683=357425270=10215.0271=2346=21023=110=096
1128=99=18035=X49=SAMPLE75=2017010134=414452=2017010104535871195360060=201701010453587119536005799=10000100268=1279=1269=048=17359555=6SZ683=357426270=10214.0271=3346=31023=110=085
1128=99=18035=X49=SAMPLE75=2017010134=275252=2017010101575166724444760=201701010157516672444475799=10000100268=1279=1269=048=17359555=6SZ683=357427270=10214.0271=4346=41023=110=104
1128=99=18035=X49=SAMPLE75=2017010134=48752=2017010111521195620347860=201701011152119562034785799=10000100268=1279=1269=148=17359555=6SZ683=357428270=10215.0271=3346=31023=110=090
1128=99=18035=X49=SAMPLE75=2017010134=99652=2017010109015119201288960=201701010901511920128895799=10000100268=1279=1269=048=17359555=6SZ683=357429270=10214.0271=3346=31023=110=101
1128=99=18035=X49=SAMPLE75=2017010134=99352=2017010104311848208539960=201701010431184820853995799=10000100268=1279=1269=148=17359555=6SZ683=357430270=10215.0271=4346=41023=110=095
1128=99=18035=X49=SAMPLE75=2017010134=456852=2017010106574690127538460=201701010657469012753845799=10000100268=1279=1269=148=17359555=6SZ683=357431270=10215.0271=5346=51023=110=115
1128=99=18035=X49=SAMPLE75=2017010134=240652=2017010100022630101435060=201701010002263010143505799=10000100268=1279=1269=048=17359555=6SZ683=357432270=10214.0271=2346=21023=110=079
1128=99=18135=X49=SAMPLE75=2017010134=68452=2017010100503276967217360=201701010050327696721735799=10000100268=1279=1269=148=17359555=6SZ683=357433270=10216.0271=17346=81023=210=158
1128=99=25235=X49=SAMPLE75=2017010134=254752=2017010101365869083306560=201701010136586908330655799=10000100268=2279=1269=148=17359555=6SZ683=357434270=10215.0271=6346=61023=1279=1269=148=17359555=6SZ683=357435270=10216.0271=16346=71023=210=206
1128=99=23035=X49=SAMPLE75=2017010134=407552=2017010107152162314060160=201701010715216231406015799=00000001268=1279=0269=248=17359555=6SZ683=357436270=10214.0271=2346=35797=237705=337=032=237=032=137=621180794292232=110=105
1128=99=15635=X49=SAMPLE75=2017010134=266752=2017010107090427863077560=201701010709042786307755799=00000010268=1279=0269=e48=17359555=6SZ683=357437271=6710=102
1128=99=25335=X49=SAMPLE75=2017010134=142852=2017010106424176484361860=201701010642417648436185799=10000100268=2279=2269=048=17359555=6SZ683=357438270=10214.0271=2346=21023=1279=0269=048=17359555=6SZ683=357439270=10204.0271=18346=31023=1010=248
1128=99=17935=X49=SAMPLE75=2017010134=200852=2017010107074749990432360=201701010707474999043235799=10000100268=1279=0269=148=17360055=6SH783=99302270=10270.0271=3346=11023=110=014
1128=99=25335=X49=SAMPLE75=2017010134=148452=2017010113540176241112460=201701011354017624111245799=10000100268=2279=1269=148=17359555=6SZ683=357440270=10220.0271=33346=91023=6279=1269=148=17359555=6SZ683=357441270=10221.0271=42346=81023=710=251
1128=99=25435=X49=SAMPLE75=2017010134=330552=2017010113054610871726460=201701011305461087172645799=10000100268=2279=1269=048=17359555=6SZ683=357442270=10213.0271=18346=91023=1279=1269=048=17359555=6SZ683=357443270=10212.0271=20346=111023=210=041
1128=99=25335=X49=SAMPLE75=2017010134=355752=2017010100125684249318960=201701010012568424931895799=10000100268=2279=1269=148=17359555=6SZ683=357444270=10221.0271=43346=91023=7279=1269=148=17359555=6SZ683=357445270=10223.0271=18346=31023=910=014
1128=99=18135=X49=SAMPLE75=2017010134=56052=2017010106561183875480660=201701010656118387548065799=10000100268=1279=1269=048=17359555=6SZ683=357446270=10213.0271=17346=81023=110=172
1128=99=25035=X49=SAMPLE75=2017010134=238952=2017010101500391792087060=201701010150039179208705799=10000100268=2279=2269=148=17360055=6SH783=99303270=10270.0271=3346=11023=1279=0269=148=17360055=6SH783=99304270=10280.0271=3346=11023=1010=009
1128=99=18135=X49=SAMPLE75=2017010134=299652=2017010102560673948966160=201701010256067394896615799=10000100268=1279=1269=048=17359555=6SZ683=357447270=10213.0271=18346=91023=110=158
1128=99=18135=X49=SAMPLE75=2017010134=246652=2017010105415245742993260=201701010541524574299325799=10000100268=1279=1269=048=17359555=6SZ683=357448270=10213.0271=17346=81023=110=163
1128=99=18135=X49=SAMPLE75=2017010134=40152=2017010110130601069762960=201701011013060106976295799=10000100268=1279=1269=048=17359555=6SZ683=357449270=10213.0271=18346=91023=110=173
1128=99=18135=X49=SAMPLE75=2017010134=189452=2017010111034428530144460=201701011103442853014445799=10000100268=1279=1269=048=17359555=6SZ683=357450270=10213.0271=17346=81023=110=151
1128=99=18135=X49=SAMPLE75=2017010134=333552=2017010103271558680614160=201701010327155868061415799=10000100268=1279=1269=048=17359555=6SZ683=357451270=10213.0271=18346=91023=110=170
1128=99=18135=X49=SAMPLE75=2017010134=35852=2017010100403938639948560=201701010040393863994855799=10000100268=1279=1269=048=17359555=6SZ683=357452270=10210.0271=24346=81023=410=166
1128=99=18135=X49=SAMPLE75=2017010134=36552=2017010110281576085626660=201701011028157608562665799=10000100268=1279=1269=048=17359555=6SZ683=357453270=10210.0271=31346=91023=410=164
1128=99=18135=X49=SAMPLE75=2017010134=198452=2017010113070626928430760=201701011307062692843075799=10000100268=1279=1269=048=17359555=6SZ683=357454270=10210.0271=24346=81023=410=166
1128=99=18135=X49=SAMPLE75=2017010134=377152=2017010111093026100147660=201701011109302610014765799=10000100268=1279=1269=048=17359555=6SZ683=357455270=10210.0271=31346=91023=410=145
1128=99=18235=X49=SAMPLE75=2017010134=258352=2017010104174312438368860=201701010417431243836885799=10000100268=1279=1269=048=17359555=6SZ683=357456270=10212.0271=19346=101023=210=208
1128=99=18135=X49=SAMPLE75=2017010134=3352=2017010102270790069886960=201701010227079006988695799=10000100268=1279=1269=048=17359555=6SZ683=357457270=10205.0271=26346=71023=910=150
1128=99=18135=X49=SAMPLE75=2017010134=431352=2017010113385544591686760=201701011338554459168675799=10000100268=1279=1269=048=17359555=6SZ683=357458270=10210.0271=24346=81023=410=160
1128=99=18135=X49=SAMPLE75=2017010134=281852=2017010107461745717702260=201701010746174571770225799=10000100268=1279=1269=048=17359555=6SZ683=357459270=10210.0271=31346=91023=410=151
1128=99=18135=X49=SAMPLE75=2017010134=420052=2017010112120763259551960=201701011212076325955195799=10000100268=1279=1269=048=17359555=6SZ683=357460270=10210.0271=24346=81023=410=183
1128=99=18135=X49=SAMPLE75=2017010134=490552=2017010111005477061707260=201701011100547706170725799=10000100268=1279=1269=048=17359555=6SZ683=357461270=10210.0271=31346=91023=410=156
1128=99=18135=X49=SAMPLE75=2017010134=250752=2017010102293861160075260=201701010229386116007525799=10000100268=1279=1269=048=17359555=6SZ683=357462270=10210.0271=24346=81023=410=165
1128=99=18035=X49=SAMPLE75=2017010134=482252=2017010107015389555809660=201701010701538955580965799=10000100268=1279=1269=148=17359555=6SZ683=357463270=10215.0271=5346=51023=110=125
1128=99=25135=X49=SAMPLE75=2017010134=230652=2017010114160403255221560=201701011416040325522155799=10000100268=2279=2269=148=17360055=6SH783=99305270=10271.0271=3346=11023=1279=0269=148=17360055=6SH783=99306270=10281.0271=11346=21023=1010=092
1128=99=18035=X49=SAMPLE75=2017010134=12152=2017010102593108549960460=201701010259310854996045799=10000100268=1279=1269=148=17359555=6SZ683=357464270=10215.0271=8346=61023=110=116
1128=99=18035=X49=SAMPLE75=2017010134=118552=2017010113355770332495860=201701011335577033249585799=10000100268=1279=1269=148=17359555=6SZ683=357465270=10215.0271=9346=71023=110=131
1128=99=17935=X49=SAMPLE75=2017010134=390452=2017010111103721611313060=201701011110372161131305799=10000100268=1279=0269=148=17360055=6SH783=99307270=10271.0271=3346=11023=110=046
1128=99=25435=X49=SAMPLE75=2017010134=164852=2017010103522967208284960=201701010352296720828495799=10000100268=2279=1269=048=17359555=6SZ683=357466270=10213.0271=19346=101023=1279=1269=048=17359555=6SZ683=357467270=10212.0271=18346=91023=210=075
1128=99=25435=X49=SAMPLE75=2017010134=133652=2017010112485193791378360=201701011248519379137835799=10000100268=2279=1269=148=17359555=6SZ683=357468270=10220.0271=30346=81023=6279=1269=148=17359555=6SZ683=357469270=10221.0271=46346=101023=710=048
1128=99=18135=X49=SAMPLE75=2017010134=149752=2017010104595788873580860=201701010459578887358085799=10000100268=1279=1269=048=17359555=6SZ683=357470270=10210.0271=31346=91023=410=158
1128=99=18135=X49=SAMPLE75=2017010134=203552=2017010105590964576808460=201701010559096457680845799=10000100268=1279=1269=048=17359555=6SZ683=357471270=10210.0271=24346=81023=410=179
1128=99=18135=X49=SAMPLE75=2017010134=461552=2017010104114787542667760=201701010411478754266775799=10000100268=1279=1269=048=17359555=6SZ683=357472270=10210.0271=31346=91023=410=148
1128=99=25335=X49=SAMPLE75=2017010134=129752=2017010112151460500947660=201701011215146050094765799=10000100268=2279=1269=148=17359555=6SZ683=357473270=10220.0271=33346=91023=6279=1269=148=17359555=6SZ683=357474270=10221.0271=43346=91023=710=017
1128=99=25435=X49=SAMPLE75=2017010134=418652=2017010112413725710368260=201701011241372571036825799=10000100268=2279=1269=048=17359555=6SZ683=357475270=10213.0271=18346=91023=1279=1269=048=17359555=6SZ683=357476270=10212.0271=19346=101023=210=065
1128=99=18135=X49=SAMPLE75=2017010134=160952=2017010103121166557165460=201701010312116655716545799=10000100268=1279=1269=048=17359555=6SZ683=357477270=10210.0271=24346=81023=410=151
1128=99=18135=X49=SAMPLE75=2017010134=72152=2017010109504507251376460=201701010950450725137645799=10000100268=1279=1269=148=17359555=6SZ683=357478270=10216.0271=17346=81023=210=204
1128=99=18135=X49=SAMPLE75=2017010134=435052=2017010110541510397442260=201701011054151039744225799=10000100268=1279=1269=048=17359555=6SZ683=357479270=10213.0271=17346=81023=110=168
1128=99=18035=X49=SAMPLE75=2017010134=370352=2017010104243073976398460=201701010424307397639845799=10000100268=1279=1269=048=17359555=6SZ683=357480270=10213.0271=9346=71023=110=104
1128=99=18035=X49=SAMPLE75=2017010134=381952=2017010113085414689372760=201701011308541468937275799=10000100268=1279=1269=048=17359555=6SZ683=357481270=10213.0271=6346=61023=110=095
1128=99=25335=X49=SAMPLE75=2017010134=196252=2017010102195899228749060=201701010219589922874905799=10000100268=2279=1269=048=17359555=6SZ683=357482270=10210.0271=16346=71023=4279=1269=048=17359555=6SZ683=357483270=10206.0271=48346=71023=810=028
1128=99=25135=X49=SAMPLE75=2017010134=74152=2017010107430497476646260=201701010743049747664625799=10000100268=2279=1269=048=17360055=6SH783=99308270=10261.0271=3346=11023=6279=1269=048=17360055=6SH783=99309270=10257.0271=11346=21023=1010=107
1128=99=18135=X49=SAMPLE75=2017010134=467952=2017010110444832752067960=201701011044483275206795799=10000100268=1279=1269=148=17359555=6SZ683=357484270=10218.0271=22346=71023=410=177
1128=99=18035=X49=SAMPLE75=2017010134=423352=2017010114030500737381560=201701011403050073738155799=10000100268=1279=1269=148=17360055=6SH783=99310270=10277.0271=11346=21023=710=096
1128=99=18135=X49=SAMPLE75=2017010134=338452=2017010106433477295713460=201701010643347729571345799=10000100268=1279=1269=148=17359555=6SZ683=357485270=10218.0271=15346=61023=410=192
1128=99=18135=X49=SAMPLE75=2017010134=7752=2017010112243213098505060=201701011224321309850505799=10000100268=1279=1269=148=17359555=6SZ683=357486270=10218.0271=22346=71023=410=191
1128=99=18235=X49=SAMPLE75=2017010134=198852=2017010106062089552648360=201701010606208955264835799=10000100268=1279=1269=048=17359555=6SZ683=357487270=10212.0271=20346=111023=210=163
1128=99=18035=X49=SAMPLE75=2017010134=486852=2017010111411524149851660=201701011141152414985165799=10000100268=1279=0269=048=17359555=6SZ683=357488270=10214.0271=1346=11023=110=085
1128=99=17935=X49=SAMPLE75=2017010134=284752=2017010110271532427235660=201701011027153242723565799=10000100268=1279=0269=048=17360055=6SH783=99311270=10267.0271=3346=11023=110=044
1128=99=18035=X49=SAMPLE75=2017010134=88352=2017010100024142653219760=201701010002414265321975799=10000100268=1279=1269=048=17359555=6SZ683=357489270=10214.0271=2346=21023=110=100
1128=99=18235=X49=SAMPLE75=2017010134=194252=2017010103282639905759760=201701010328263990575975799=10000100268=1279=1269=048=17359555=6SZ683=357490270=10205.0271=25346=61023=1010=203
1128=99=20835=X49=SAMPLE75=2017010134=422252=2017010112153411099859860=201701011215341109985985799=00000001268=1279=0269=248=17359555=6SZ683=357491270=10214.0271=1346=25797=237705=237=032=137=032=110=070
1128=99=15635=X49=SAMPLE75=2017010134=440552=2017010109542988564468160=201701010954298856446815799=00000010268=1279=0269=e48=17359555=6SZ683=357492271=6810=093
1128=99=18035=X49=SAMPLE75=2017010134=89152=2017010106570382026125060=201701010657038202612505799=10000100268=1279=1269=048=17359555=6SZ683=357493270=10214.0271=1346=11023=110=089
1128=99=18235=X49=SAMPLE75=2017010134=236952=2017010100560861191648360=201701010056086119164835799=10000100268=1279=1269=048=17359555=6SZ683=357494270=10212.0271=21346=121023=310=198
1128=99=20835=X49=SAMPLE75=2017010134=471852=2017010102401650184749060=201701010240165018474905799=00000001268=1279=0269=248=17359555=6SZ683=357495270=10214.0271=1346=25797=237705=237=032=137=032=110=061
1128=99=15635=X49=SAMPLE75=2017010134=272852=2017010107235920405414160=201701010723592040541415799=00000010268=1279=0269=e48=17359555=6SZ683=357496271=6910=104
1128=99=25335=X49=SAMPLE75=2017010134=432352=2017010101394571079309160=201701010139457107930915799=10000100268=2279=2269=048=17359555=6SZ683=357497270=10214.0271=1346=11023=1279=0269=048=17359555=6SZ683=357498270=10204.0271=18346=31023=1010=251
1128=99=17935=X49=SAMPLE75=2017010134=18352=2017010112302016288069060=201701011230201628806905799=10000100268=1279=0269=148=17360055=6SH783=99312270=10270.0271=3346=11023=110=021
1128=99=25135=X49=SAMPLE75=2017010134=177052=2017010110250674900141760=201701011025067490014175799=10000100268=2279=2269=048=17360055=6SH783=99313270=10267.0271=3346=11023=1279=0269=048=17360055=6SH783=99314270=10257.0271=11346=21023=1010=059
1128=99=25035=X49=SAMPLE75=2017010134=281352=2017010112155739938567860=201701011215573993856785799=10000100268=2279=2269=148=17360055=6SH783=99315270=10270.0271=3346=11023=1279=0269=148=17360055=6SH783=99316270=10280.0271=3346=11023=1010=035
1128=99=18135=X49=SAMPLE75=2017010134=275652=2017010109061648943507960=201701010906164894350795799=10000100268=1279=1269=048=17359555=6SZ683=357499270=10213.0271=14346=71023=110=176
1128=99=18135=X49=SAMPLE75=2017010134=69152=2017010113101242286386060=201701011310124228638605799=10000100268=1279=1269=148=17359555=6SZ683=357500270=10218.0271=15346=61023=410=132
1128=99=18035=X49=SAMPLE75=2017010134=96052=2017010107595704582190660=201701010759570458219065799=10000100268=1279=1269=048=17359555=6SZ683=357501270=10213.0271=6346=61023=110=090
1128=99=18135=X49=SAMPLE75=2017010134=431152=2017010109542122331696460=201701010954212233169645799=10000100268=1279=1269=148=17359555=6SZ683=357502270=10218.0271=22346=71023=410=149
1128=99=18135=X49=SAMPLE75=2017010134=167252=2017010106194671224048360=201701010619467122404835799=10000100268=1279=1269=148=17359555=6SZ683=357503270=10218.0271=15346=61023=410=135
1128=99=18235=X49=SAMPLE75=2017010134=211352=2017010107390412516137460=201701010739041251613745799=10000100268=1279=1269=048=17359555=6SZ683=357504270=10212.0271=20346=111023=210=184
1128=99=18135=X49=SAMPLE75=2017010134=183052=2017010104043363938823860=201701010404336393882385799=10000100268=1279=1269=048=17359555=6SZ683=357505270=10205.0271=26346=71023=910=171
1128=99=18135=X49=SAMPLE75=2017010134=399452=2017010108582690530207360=201701010858269053020735799=10000100268=1279=1269=148=17359555=6SZ683=357506270=10218.0271=22346=71023=410=176
1128=99=18135=X49=SAMPLE75=2017010134=189352=2017010102093334380991860=201701010209333438099185799=10000100268=1279=1269=148=17359555=6SZ683=357507270=10218.0271=15346=61023=410=160
1128=99=18135=X49=SAMPLE75=2017010134=344052=2017010108471224843830860=201701010847122484383085799=10000100268=1279=1269=148=17359555=6SZ683=357508270=10215.0271=10346=81023=110=176
1128=99=25335=X49=SAMPLE75=2017010134=110052=2017010114265987224835360=201701011426598722483535799=10000100268=2279=1269=048=17359555=6SZ683=357509270=10213.0271=7346=71023=1279=1269=048=17359555=6SZ683=357510270=10212.0271=19346=101023=210=005
1128=99=25235=X49=SAMPLE75=2017010134=174852=2017010106094010097235860=201701010609401009723585799=10000100268=2279=1269=148=17359555=6SZ683=357511270=10215.0271=9346=71023=1279=1269=148=17359555=6SZ683=357512270=10216.0271=18346=91023=210=207
1128=99=18035=X49=SAMPLE75=2017010134=314852=2017010108320255488419760=201701010832025548841975799=10000100268=1279=1269=148=17359555=6SZ683=357513270=10215.0271=8346=61023=110=109
1128=99=18035=X49=SAMPLE75=2017010134=101252=2017010113510374170599760=201701011351037417059975799=10000100268=1279=0269=048=17359555=6SZ683=357514270=10214.0271=1346=11023=110=105
1128=99=17935=X49=SAMPLE75=2017010134=165652=2017010105341671084200660=201701010534167108420065799=10000100268=1279=0269=048=17360055=6SH783=99317270=10267.0271=3346=11023=110=043
1128=99=18035=X49=SAMPLE75=2017010134=240852=2017010111301408884711760=201701011130140888471175799=10000100268=1279=1269=148=17359555=6SZ683=357515270=10215.0271=7346=51023=110=087
1128=99=18235=X49=SAMPLE75=2017010134=45752=2017010113271467699955360=201701011327146769995535799=10000100268=1279=1269=048=17359555=6SZ683=357516270=10205.0271=25346=61023=1010=179
1128=99=18235=X49=SAMPLE75=2017010134=160552=2017010108475318751739660=201701010847531875173965799=10000100268=1279=1269=048=17359555=6SZ683=357517270=10212.0271=20346=111023=310=180
1128=99=18035=X49=SAMPLE75=2017010134=220752=2017010107583822953676660=201701010758382295367665799=10000100268=1279=1269=048=17359555=6SZ683=357518270=10214.0271=2346=21023=110=093
1128=99=25435=X49=SAMPLE75=2017010134=183252=2017010107463349519246960=201701010746334951924695799=10000100268=2279=1269=148=17359555=6SZ683=357519270=10220.0271=30346=81023=6279=1269=148=17359555=6SZ683=357520270=10221.0271=46346=101023=710=026
1128=99=18035=X49=SAMPLE75=2017010134=6352=2017010114333506509975660=201701011433350650997565799=10000100268=1279=1269=048=17359555=6SZ683=357521270=10214.0271=3346=31023=110=100
1128=99=18035=X49=SAMPLE75=2017010134=145152=2017010105590927020347560=201701010559092702034755799=10000100268=1279=1269=148=17359555=6SZ683=357522270=10215.0271=4346=41023=110=098
1128=99=18035=X49=SAMPLE75=2017010134=377252=2017010113363901817546060=201701011336390181754605799=10000100268=1279=1269=048=17359555=6SZ683=357523270=10214.0271=4346=41023=110=104
1128=99=25035=X49=SAMPLE75=2017010134=5452=2017010108471547310830460=201701010847154731083045799=10000100268=2279=2269=148=17360055=6SH783=99318270=10271.0271=3346=11023=1279=0269=148=17360055=6SH783=99319270=10281.0271=3346=11023=1010=053
1128=99=18035=X49=SAMPLE75=2017010134=263852=2017010101303881845265360=201701010130388184526535799=10000100268=1279=1269=148=17359555=6SZ683=357524270=10215.0271=3346=31023=110=114
1128=99=25135=X49=SAMPLE75=2017010134=483452=2017010110025598389537360=201701011002559838953735799=10000100268=2279=2269=048=17360055=6SH783=99320270=10267.0271=3346=11023=1279=0269=048=17360055=6SH783=99321270=10257.0271=11346=21023=1010=079
1128=99=18135=X49=SAMPLE75=2017010134=64152=2017010104153401191059160=201701010415340119105915799=10000100268=1279=1269=048=17359555=6SZ683=357525270=10213.0271=15346=81023=210=157
1128=99=18035=X49=SAMPLE75=2017010134=37852=2017010103503057820317260=201701010350305782031725799=10000100268=1279=1269=148=17359555=6SZ683=357526270=10215.0271=2346=21023=110=099
1128=99=18035=X49=SAMPLE75=2017010134=264752=2017010104262347612632360=201701010426234761263235799=10000100268=1279=1269=048=17359555=6SZ683=357527270=10214.0271=5346=51023=110=093
1128=99=24235=X49=SAMPLE75=2017010134=27952=2017010114284971438176360=201701011428497143817635799=00000001268=1279=0269=248=17359555=6SZ683=357528270=10215.0271=2346=35797=137705=337=032=237=621180794292532=137=621180794334132=110=225
1128=99=15635=X49=SAMPLE75=2017010134=362652=2017010112112231242069860=201701011211223124206985799=00000010268=1279=0269=e48=17359555=6SZ683=357529271=7110=105
1128=99=25335=X49=SAMPLE75=2017010134=55652=2017010101393153953077560=201701010139315395307755799=10000100268=2279=2269=148=17359555=6SZ683=357530270=10215.0271=2346=21023=1279=0269=148=17359555=6SZ683=357531270=10225.0271=15346=21023=1010=242
1128=99=17935=X49=SAMPLE75=2017010134=497252=2017010101404840332377360=201701010140484033237735799=10000100268=1279=0269=048=17360055=6SH783=99322270=10268.0271=3346=11023=110=055
1128=99=17935=X49=SAMPLE75=2017010134=267152=2017010107484437751734860=201701010748443775173485799=10000100268=1279=0269=048=17360055=6SH783=99323270=10267.0271=3346=11023=210=076
1128=99=18035=X49=SAMPLE75=2017010134=131352=2017010103185462220588260=201701010318546222058825799=10000100268=1279=0269=148=17359555=6SZ683=357532270=10215.0271=1346=11023=110=113
1128=99=25035=X49=SAMPLE75=2017010134=458252=2017010106480042859980560=201701010648004285998055799=10000100268=2279=2269=048=17360055=6SH783=99324270=10268.0271=3346=11023=1279=0269=048=17360055=6SH783=99325270=10258.0271=3346=11023=1010=048
1128=99=25135=X49=SAMPLE75=2017010134=113452=2017010109585593879913460=201701010958559387991345799=10000100268=2279=2269=048=17360055=6SH783=99326270=10267.0271=3346=11023=1279=0269=048=17360055=6SH783=99327270=10257.0271=11346=21023=1010=106
1128=99=25335=X49=SAMPLE75=2017010134=335152=2017010106150517880555260=201701010615051788055525799=10000100268=2279=2269=148=17359555=6SZ683=357533270=10215.0271=1346=11023=1279=0269=148=17359555=6SZ683=357534270=10225.0271=15346=21023=1010=242
1128=99=18035=X49=SAMPLE75=2017010134=207952=2017010109111880985965360=201701010911188098596535799=10000100268=1279=1269=048=17359555=6SZ683=357535270=10214.0271=6346=61023=110=118
1128=99=17935=X49=SAMPLE75=2017010134=346352=2017010101144809782149660=201701010114480978214965799=10000100268=1279=0269=048=17360055=6SH783=99328270=10267.0271=3346=11023=110=042
1128=99=25135=X49=SAMPLE75=2017010134=365552=2017010101015266505012060=201701010101526650501205799=10000100268=2279=1269=148=17360055=6SH783=99329270=10277.0271=3346=11023=6279=1269=148=17360055=6SH783=99330270=10281.0271=11346=21023=1010=104
1128=99=18135=X49=SAMPLE75=2017010134=170852=2017010106473275022760560=201701010647327502276055799=10000100268=1279=1269=048=17359555=6SZ683=357536270=10210.0271=23346=81023=510=158
1128=99=18135=X49=SAMPLE75=2017010134=388852=2017010103500749661802760=201701010350074966180275799=10000100268=1279=1269=048=17359555=6SZ683=357537270=10210.0271=16346=71023=510=162
1128=99=18135=X49=SAMPLE75=2017010134=144852=2017010108395796982504360=201701010839579698250435799=10000100268=1279=1269=148=17359555=6SZ683=357538270=10219.0271=21346=81023=410=159
1128=99=18135=X49=SAMPLE75=2017010134=329052=2017010101494997460891360=201701010149499746089135799=10000100268=1279=1269=148=17359555=6SZ683=357539270=10219.0271=28346=91023=410=169
1128=99=18035=X49=SAMPLE75=2017010134=448752=2017010111112772891354460=201701011111277289135445799=10000100268=1279=1269=048=17360055=6SH783=99331270=10261.0271=11346=21023=710=083
1128=99=25335=X49=SAMPLE75=2017010134=354152=2017010112174922268116460=201701011217492226811645799=10000100268=2279=1269=048=17359555=6SZ683=357540270=10210.0271=24346=81023=5279=1269=048=17359555=6SZ683=357541270=10206.0271=40346=61023=910=006
1128=99=18135=X49=SAMPLE75=2017010134=392652=2017010111580272803598260=201701011158027280359825799=10000100268=1279=1269=148=17359555=6SZ683=357542270=10216.0271=10346=81023=110=165
1128=99=18035=X49=SAMPLE75=2017010134=477152=2017010100103151354640560=201701010010315135464055799=10000100268=1279=1269=148=17359555=6SZ683=357543270=10216.0271=9346=71023=110=135
1128=99=18135=X49=SAMPLE75=2017010134=6652=2017010101313918225861960=201701010131391822586195799=10000100268=1279=1269=048=17359555=6SZ683=357544270=10210.0271=31346=91023=510=147
1128=99=18035=X49=SAMPLE75=2017010134=469052=2017010105485136218350460=201701010548513621835045799=10000100268=1279=1269=048=17359555=6SZ683=357545270=10214.0271=5346=51023=110=103
1128=99=18135=X49=SAMPLE75=2017010134=378252=2017010100363816789782960=201701010036381678978295799=10000100268=1279=1269=148=17359555=6SZ683=357546270=10216.0271=10346=81023=110=161
1128=99=25035=X49=SAMPLE75=2017010134=298452=2017010111174387196952260=201701011117438719695225799=10000100268=2279=2269=048=17360055=6SH783=99332270=10267.0271=3346=11023=1279=0269=048=17360055=6SH783=99333270=10257.0271=3346=11023=1010=041
1128=99=18035=X49=SAMPLE75=2017010134=89152=2017010106470782423479460=201701010647078242347945799=10000100268=1279=1269=048=17359555=6SZ683=357547270=10214.0271=6346=61023=110=124
1128=99=18035=X49=SAMPLE75=2017010134=61852=2017010103241792832416760=201701010324179283241675799=10000100268=1279=1269=148=17359555=6SZ683=357548270=10216.0271=9346=71023=110=137
1128=99=17935=X49=SAMPLE75=2017010134=16652=2017010103512873846910760=201701010351287384691075799=10000100268=1279=0269=048=17360055=6SH783=99334270=10267.0271=3346=11023=110=060
1128=99=18135=X49=SAMPLE75=2017010134=97752=2017010101292659598312260=201701010129265959831225799=10000100268=1279=1269=148=17359555=6SZ683=357549270=10219.0271=21346=81023=410=194
1128=99=18135=X49=SAMPLE75=2017010134=455052=2017010105084875066695560=201701010508487506669555799=10000100268=1279=1269=148=17359555=6SZ683=357550270=10217.0271=14346=51023=210=172
1128=99=18135=X49=SAMPLE75=2017010134=101752=2017010111421001707899860=201701011142100170789985799=10000100268=1279=1269=148=17359555=6SZ683=357551270=10222.0271=27346=51023=710=182
1128=99=18135=X49=SAMPLE75=2017010134=369552=2017010109323548436575160=201701010932354843657515799=10000100268=1279=1269=148=17359555=6SZ683=357552270=10219.0271=28346=91023=410=176
1128=99=18135=X49=SAMPLE75=2017010134=421152=2017010112061638803941760=201701011206163880394175799=10000100268=1279=1269=048=17359555=6SZ683=357553270=10210.0271=24346=81023=510=171
1128=99=18135=X49=SAMPLE75=2017010134=226352=2017010113021321807289460=201701011302132180728945799=10000100268=1279=1269=148=17359555=6SZ683=357554270=10219.0271=21346=81023=410=190
1128=99=18135=X49=SAMPLE75=2017010134=357952=2017010110244192656712760=201701011024419265671275799=10000100268=1279=1269=148=17359555=6SZ683=357555270=10219.0271=28346=91023=410=180
1128=99=18135=X49=SAMPLE75=2017010134=212752=2017010113450629357857760=201701011345062935785775799=10000100268=1279=1269=148=17359555=6SZ683=357556270=10219.0271=21346=81023=410=176
1128=99=18135=X49=SAMPLE75=2017010134=259652=2017010106495353501814560=201701010649535350181455799=10000100268=1279=1269=148=17359555=6SZ683=357557270=10219.0271=28346=91023=410=162
1128=99=18135=X49=SAMPLE75=2017010134=444152=2017010103402107823800560=201701010340210782380055799=10000100268=1279=1269=148=17359555=6SZ683=357558270=10219.0271=21346=81023=410=191
1128=99=18135=X49=SAMPLE75=2017010134=182552=2017010114291760250609160=201701011429176025060915799=10000100268=1279=1269=048=17359555=6SZ683=357559270=10213.0271=18346=91023=210=196
1128=99=18135=X49=SAMPLE75=2017010134=78952=2017010104191047816909860=201701010419104781690985799=10000100268=1279=1269=148=17359555=6SZ683=357560270=10216.0271=17346=81023=110=204
1128=99=18035=X49=SAMPLE75=2017010134=200552=2017010114280032793107460=201701011428003279310745799=10000100268=1279=0269=148=17359555=6SZ683=357561270=10215.0271=1346=11023=110=122
1128=99=17935=X49=SAMPLE75=2017010134=153652=2017010109295879011396760=201701010929587901139675799=10000100268=1279=0269=148=17360055=6SH783=99335270=10271.0271=3346=11023=110=031
1128=99=20835=X49=SAMPLE75=2017010134=445852=2017010102080414708319860=201701010208041470831985799=00000001268=1279=0269=248=17359555=6SZ683=357562270=10215.0271=1346=25797=137705=237=032=137=032=110=069
1128=99=15635=X49=SAMPLE75=2017010134=157352=2017010106285837975195060=201701010628583797519505799=00000010268=1279=0269=e48=17359555=6SZ683=357563271=7210=101
1128=99=25335=X49=SAMPLE75=2017010134=144052=2017010101314512641616860=201701010131451264161685799=10000100268=2279=2269=148=17359555=6SZ683=357564270=10215.0271=1346=11023=1279=0269=148=17359555=6SZ683=357565270=10225.0271=15346=21023=1010=251
1128=99=18035=X49=SAMPLE75=2017010134=283652=2017010114315648115288760=201701011431564811528875799=10000100268=1279=1269=048=17359555=6SZ683=357566270=10214.0271=5346=51023=110=112
1128=99=18035=X49=SAMPLE75=2017010134=206952=2017010102482547636050960=201701010248254763605095799=10000100268=1279=0269=148=17359555=6SZ683=357567270=10215.0271=1346=11023=110=107
1128=99=17935=X49=SAMPLE75=2017010134=236252=2017010105414707519125960=201701010541470751912595799=10000100268=1279=0269=048=17360055=6SH783=99336270=10268.0271=3346=11023=110=054
1128=99=25135=X49=SAMPLE75=2017010134=343252=2017010112292452738798760=201701011229245273879875799=10000100268=2279=2269=148=17360055=6SH783=99337270=10271.0271=3346=11023=1279=0269=148=17360055=6SH783=99338270=10281.0271=11346=21023=1010=109
1128=99=25035=X49=SAMPLE75=2017010134=374952=2017010102333067628233360=201701010233306762823335799=10000100268=2279=2269=048=17360055=6SH783=99339270=10268.0271=3346=11023=1279=0269=048=17360055=6SH783=99340270=10258.0271=3346=11023=1010=050
1128=99=25035=X49=SAMPLE75=2017010134=98652=2017010105233037276967860=201701010523303727696785799=10000100268=2279=2269=048=17360055=6SH783=99341270=10267.0271=3346=11023=1279=0269=048=17360055=6SH783=99342270=10257.0271=3346=11023=1010=052
1128=99=25335=X49=SAMPLE75=2017010134=59852=2017010101350657450777160=201701010135065745077715799=10000100268=2279=2269=148=17359555=6SZ683=357568270=10215.0271=1346=11023=1279=0269=148=17359555=6SZ683=357569270=10225.0271=15346=21023=1010=011
1128=99=18135=X49=SAMPLE75=2017010134=368052=2017010111434060936319760=201701011143406093631975799=10000100268=1279=1269=148=17359555=6SZ683=357570270=10219.0271=28346=91023=410=167
1128=99=18135=X49=SAMPLE75=2017010134=451052=2017010102550833673803360=201701010255083367380335799=10000100268=1279=1269=148=17359555=6SZ683=357571270=10219.0271=21346=81023=410=175
1128=99=18135=X49=SAMPLE75=2017010134=456352=2017010107420575110086760=201701010742057511008675799=10000100268=1279=1269=148=17359555=6SZ683=357572270=10216.0271=18346=91023=110=186
1128=99=18235=X49=SAMPLE75=2017010134=68752=2017010114285225436578460=201701011428522543657845799=10000100268=1279=1269=048=17359555=6SZ683=357573270=10212.0271=19346=101023=310=235
1128=99=18235=X49=SAMPLE75=2017010134=286252=2017010104184444125443260=201701010418444412544325799=10000100268=1279=1269=048=17359555=6SZ683=357574270=10213.0271=19346=101023=210=243
1128=99=18035=X49=SAMPLE75=2017010134=414852=2017010106512493846839260=201701010651249384683925799=10000100268=1279=0269=148=17359555=6SZ683=357575270=10215.0271=1346=11023=110=087
1128=99=17935=X49=SAMPLE75=2017010134=34752=2017010112590331981903160=201701011259033198190315799=10000100268=1279=0269=148=17360055=6SH783=99343270=10271.0271=3346=11023=110=030
1128=99=20835=X49=SAMPLE75=2017010134=259952=2017010103085870467190460=201701010308587046719045799=00000001268=1279=0269=248=17359555=6SZ683=357576270=10215.0271=1346=25797=137705=237=032=137=032=110=066
1128=99=15635=X49=SAMPLE75=2017010134=293352=2017010101303869635562860=201701010130386963556285799=00000010268=1279=0269=e48=17359555=6SZ683=357577271=7310=087
1128=99=25335=X49=SAMPLE75=2017010134=104252=2017010106332734929167860=201701010633273492916785799=10000100268=2279=2269=148=17359555=6SZ683=357578270=10215.0271=1346=11023=1279=0269=148=17359555=6SZ683=357579270=10225.0271=15346=21023=1010=241
1128=99=18035=X49=SAMPLE75=2017010134=113852=2017010107024922345715560=201701010702492234571555799=10000100268=1279=0269=148=17359555=6SZ683=357580270=10215.0271=1346=11023=110=109
1128=99=17935=X49=SAMPLE75=2017010134=470652=2017010113384750146799760=201701011338475014679975799=10000100268=1279=0269=048=17360055=6SH783=99344270=10268.0271=3346=11023=110=037
1128=99=25135=X49=SAMPLE75=2017010134=38752=2017010112011463638122560=201701011201146363812255799=10000100268=2279=2269=148=17360055=6SH783=99345270=10271.0271=3346=11023=1279=0269=148=17360055=6SH783=99346270=10281.0271=11346=21023=1010=079
1128=99=17935=X49=SAMPLE75=2017010134=126052=2017010112051604971655960=201701011205160497165595799=10000100268=1279=0269=048=17360055=6SH783=99347270=10267.0271=3346=11023=210=035
1128=99=25035=X49=SAMPLE75=2017010134=183552=2017010103465408537996860=201701010346540853799685799=10000100268=2279=2269=048=17360055=6SH783=99348270=10268.0271=3346=11023=1279=0269=048=17360055=6SH783=99349270=10258.0271=3346=11023=1010=020
1128=99=25335=X49=SAMPLE75=2017010134=314252=2017010109511226890314060=201701010951122689031405799=10000100268=2279=2269=148=17359555=6SZ683=357581270=10215.0271=1346=11023=1279=0269=148=17359555=6SZ683=357582270=10225.0271=15346=21023=1010=225
1128=99=25035=X49=SAMPLE75=2017010134=498652=2017010107551533299896160=201701010755153329989615799=10000100268=2279=2269=048=17360055=6SH783=99350270=10267.0271=3346=11023=1279=0269=048=17360055=6SH783=99351270=10257.0271=3346=11023=1010=015
1128=99=18035=X49=SAMPLE75=2017010134=357852=2017010112263020828032760=201701011226302082803275799=10000100268=1279=1269=048=17359555=6SZ683=357583270=10214.0271=6346=61023=110=092
1128=99=17935=X49=SAMPLE75=2017010134=141652=2017010108365013795474160=201701010836501379547415799=10000100268=1279=0269=048=17360055=6SH783=99352270=10267.0271=3346=11023=110=019
1128=99=18135=X49=SAMPLE75=2017010134=74152=2017010107222502948367760=201701010722250294836775799=10000100268=1279=1269=148=17359555=6SZ683=357584270=10219.0271=28346=91023=410=173
1128=99=18135=X49=SAMPLE75=2017010134=426052=2017010102113026621989360=201701010211302662198935799=10000100268=1279=1269=148=17359555=6SZ683=357585270=10219.0271=21346=81023=410=175
1128=99=25335=X49=SAMPLE75=2017010134=65652=2017010108220862408153760=201701010822086240815375799=10000100268=2279=1269=048=17359555=6SZ683=357586270=10210.0271=27346=91023=5279=1269=048=17359555=6SZ683=357587270=10209.0271=23346=81023=610=020
1128=99=18135=X49=SAMPLE75=2017010134=64252=2017010103310950875879160=201701010331095087587915799=10000100268=1279=1269=148=17359555=6SZ683=357588270=10219.0271=28346=91023=410=176
1128=99=18235=X49=SAMPLE75=2017010134=9152=2017010110524015682391060=201701011052401568239105799=10000100268=1279=1269=048=17359555=6SZ683=357589270=10210.0271=34346=101023=510=194
1128=99=18035=X49=SAMPLE75=2017010134=73352=2017010111392825790348960=201701011139282579034895799=10000100268=1279=0269=148=17359555=6SZ683=357590270=10215.0271=1346=11023=110=097
1128=99=17935=X49=SAMPLE75=2017010134=478152=2017010105035228514520560=201701010503522851452055799=10000100268=1279=0269=148=17360055=6SH783=99353270=10271.0271=3346=11023=110=022
1128=99=20835=X49=SAMPLE75=2017010134=250352=2017010113075940186925260=201701011307594018692525799=00000001268=1279=0269=248=17359555=6SZ683=357591270=10215.0271=1346=25797=137705=237=032=137=032=110=083
1128=99=15635=X49=SAMPLE75=2017010134=30952=2017010112542701865378760=201701011254270186537875799=00000010268=1279=0269=e48=17359555=6SZ683=357592271=7410=127
1128=99=25335=X49=SAMPLE75=2017010134=65952=2017010103461469862449760=201701010346146986244975799=10000100268=2279=2269=148=17359555=6SZ683=357593270=10215.0271=1346=11023=1279=0269=148=17359555=6SZ683=357594270=10225.0271=15346=21023=1010=021
1128=99=18035=X49=SAMPLE75=2017010134=196352=2017010107034394781390460=201701010703439478139045799=10000100268=1279=0269=148=17359555=6SZ683=357595270=10215.0271=1346=11023=110=095
1128=99=18035=X49=SAMPLE75=2017010134=91552=2017010102534243861740060=201701010253424386174005799=10000100268=1279=1269=148=17359555=6SZ683=357596270=10215.0271=2346=21023=110=110
1128=99=17935=X49=SAMPLE75=2017010134=356352=2017010110304954543144360=201701011030495454314435799=10000100268=1279=0269=048=17360055=6SH783=99354270=10268.0271=3346=11023=110=029
1128=99=25135=X49=SAMPLE75=2017010134=453252=2017010111432233796648060=201701011143223379664805799=10000100268=2279=2269=148=17360055=6SH783=99355270=10271.0271=3346=11023=1279=0269=148=17360055=6SH783=99356270=10281.0271=11346=21023=1010=072
1128=99=18035=X49=SAMPLE75=2017010134=83952=2017010100514364442384060=201701010051436444238405799=10000100268=1279=1269=148=17359555=6SZ683=357597270=10215.0271=1346=11023=110=102
1128=99=25035=X49=SAMPLE75=2017010134=436652=2017010101480963057399160=201701010148096305739915799=10000100268=2279=2269=048=17360055=6SH783=99357270=10268.0271=3346=11023=1279=0269=048=17360055=6SH783=99358270=10258.0271=3346=11023=1010=053
1128=99=22035=X49=SAMPLE75=2017010134=240552=2017010108453530202739560=201701010845353020273955799=00000001268=1279=0269=248=17359555=6SZ683=357598270=10215.0271=1346=25797=137705=237=032=137=621180794538532=110=177
1128=99=15635=X49=SAMPLE75=2017010134=378752=2017010106065287146709360=201701010606528714670935799=00000010268=1279=0269=e48=17359555=6SZ683=357599271=7510=100
1128=99=25335=X49=SAMPLE75=2017010134=117852=2017010107415075560334560=201701010741507556033455799=10000100268=2279=2269=148=17359555=6SZ683=357600270=10215.0271=1346=11023=1279=0269=148=17359555=6SZ683=357601270=10225.0271=15346=21023=1010=220
1128=99=18135=X49=SAMPLE75=2017010134=456152=2017010102432996589869160=201701010243299658986915799=10000100268=1279=1269=148=17359555=6SZ683=357602270=10219.0271=21346=81023=410=140
1128=99=18135=X49=SAMPLE75=2017010134=84052=2017010104042500865082960=201701010404250086508295799=10000100268=1279=1269=148=17359555=6SZ683=357603270=10219.0271=28346=91023=410=149
1128=99=18035=X49=SAMPLE75=2017010134=299052=2017010111451716149125460=201701011145171614912545799=10000100268=1279=1269=048=17359555=6SZ683=357604270=10214.0271=7346=71023=110=099
1128=99=18135=X49=SAMPLE75=2017010134=141252=2017010106234789242044560=201701010623478924204455799=10000100268=1279=1269=148=17359555=6SZ683=357605270=10219.0271=21346=81023=410=165
1128=99=18135=X49=SAMPLE75=2017010134=166752=2017010100200725219660460=201701010020072521966045799=10000100268=1279=1269=148=17359555=6SZ683=357606270=10219.0271=28346=91023=410=162
1128=99=18135=X49=SAMPLE75=2017010134=366352=2017010108190215251715460=201701010819021525171545799=10000100268=1279=1269=148=17359555=6SZ683=357607270=10217.0271=15346=61023=210=136
1128=99=25335=X49=SAMPLE75=2017010134=3252=2017010107420919055117760=201701010742091905511775799=10000100268=2279=1269=048=17359555=6SZ683=357608270=10210.0271=31346=91023=5279=1269=048=17359555=6SZ683=357609270=10209.0271=26346=91023=610=041
1128=99=18135=X49=SAMPLE75=2017010134=277752=2017010108412825185513460=201701010841282518551345799=10000100268=1279=1269=048=17359555=6SZ683=357610270=10210.0271=24346=81023=510=153
1128=99=18135=X49=SAMPLE75=2017010134=401252=2017010106503197326937260=201701010650319732693725799=10000100268=1279=1269=048=17359555=6SZ683=357611270=10210.0271=31346=91023=510=185
1128=99=25435=X49=SAMPLE75=2017010134=140252=2017010111032655406942760=201701011103265540694275799=10000100268=2279=1269=048=17359555=6SZ683=357612270=10210.0271=34346=101023=5279=1269=048=17359555=6SZ683=357613270=10209.0271=23346=81023=610=040
1128=99=18135=X49=SAMPLE75=2017010134=256952=2017010113250117696129460=201701011325011769612945799=10000100268=1279=1269=048=17359555=6SZ683=357614270=10210.0271=27346=91023=510=161
1128=99=18235=X49=SAMPLE75=2017010134=438952=2017010110573423305958360=201701011057342330595835799=10000100268=1279=1269=048=17359555=6SZ683=357615270=10210.0271=34346=101023=510=203
1128=99=18135=X49=SAMPLE75=2017010134=116752=2017010108063867670262560=201701010806386767026255799=10000100268=1279=1269=148=17359555=6SZ683=357616270=10216.0271=17346=81023=110=202
1128=99=25335=X49=SAMPLE75=2017010134=272452=2017010106585213087127360=201701010658521308712735799=10000100268=2279=1269=048=17359555=6SZ683=357617270=10210.0271=31346=91023=5279=1269=048=17359555=6SZ683=357618270=10209.0271=26346=91023=610=017
1128=99=18135=X49=SAMPLE75=2017010134=218852=2017010109063797836501160=201701010906379783650115799=10000100268=1279=1269=148=17359555=6SZ683=357619270=10219.0271=21346=81023=410=168
1128=99=18135=X49=SAMPLE75=2017010134=352152=2017010102380290336866960=201701010238029033686695799=10000100268=1279=1269=148=17359555=6SZ683=357620270=10219.0271=28346=91023=410=157
1128=99=18135=X49=SAMPLE75=2017010134=342752=2017010114272061324058560=201701011427206132405855799=10000100268=1279=1269=148=17359555=6SZ683=357621270=10219.0271=21346=81023=410=182
1128=99=18135=X49=SAMPLE75=2017010134=256352=2017010109455066335922960=201701010945506633592295799=10000100268=1279=1269=148=17359555=6SZ683=357622270=10217.0271=16346=71023=210=183
1128=99=18135=X49=SAMPLE75=2017010134=407052=2017010106365097356990260=201701010636509735699025799=10000100268=1279=1269=148=17359555=6SZ683=357623270=10219.0271=28346=91023=410=168
1128=99=18135=X49=SAMPLE75=2017010134=7552=2017010114120669633416060=201701011412066963341605799=10000100268=1279=1269=148=17359555=6SZ683=357624270=10219.0271=25346=81023=410=128
1128=99=18135=X49=SAMPLE75=2017010134=359152=2017010102384397142357560=201701010238439714235755799=10000100268=1279=1269=148=17359555=6SZ683=357625270=10219.0271=22346=71023=410=144
1128=99=18235=X49=SAMPLE75=2017010134=124452=2017010103015061184111960=201701010301506118411195799=10000100268=1279=1269=048=17359555=6SZ683=357626270=10205.0271=22346=51023=1010=199
1128=99=18235=X49=SAMPLE75=2017010134=170552=2017010107022822927408460=201701010702282292740845799=10000100268=1279=1269=048=17359555=6SZ683=357627270=10205.0271=19346=41023=1010=210
1128=99=25435=X49=SAMPLE75=2017010134=128352=2017010112380823478660560=201701011238082347866055799=10000100268=2279=1269=048=17359555=6SZ683=357628270=10210.0271=34346=101023=5279=1269=048=17359555=6SZ683=357629270=10209.0271=23346=81023=610=066
1128=99=25335=X49=SAMPLE75=2017010134=351652=2017010110262961504443560=201701011026296150444355799=10000100268=2279=1269=048=17359555=6SZ683=357630270=10210.0271=31346=91023=5279=1269=048=17359555=6SZ683=357631270=10209.0271=26346=91023=610=249
1128=99=25435=X49=SAMPLE75=2017010134=11752=2017010113184953494697760=201701011318495349469775799=10000100268=2279=1269=048=17359555=6SZ683=357632270=10210.0271=34346=101023=5279=1269=048=17359555=6SZ683=357633270=10209.0271=23346=81023=610=051
1128=99=25335=X49=SAMPLE75=2017010134=317052=2017010113520425716241960=201701011352042571624195799=10000100268=2279=1269=048=17359555=6SZ683=357634270=10210.0271=31346=91023=5279=1269=048=17359555=6SZ683=357635270=10209.0271=26346=91023=610=014
1128=99=18135=X49=SAMPLE75=2017010134=61652=2017010101401687973798360=201701010140168797379835799=10000100268=1279=1269=148=17359555=6SZ683=357636270=10219.0271=15346=61023=410=162
1128=99=18135=X49=SAMPLE75=2017010134=117752=2017010109120942526757760=201701010912094252675775799=10000100268=1279=1269=148=17359555=6SZ683=357637270=10219.0271=22346=71023=410=179
1128=99=18035=X49=SAMPLE75=2017010134=310252=2017010112510545054653360=201701011251054505465335799=10000100268=1279=1269=048=17359555=6SZ683=357638270=10214.0271=6346=61023=110=103
1128=99=18035=X49=SAMPLE75=2017010134=39552=2017010102102891468753960=201701010210289146875395799=10000100268=1279=1269=048=17359555=6SZ683=357639270=10214.0271=7346=71023=110=098
1128=99=25435=X49=SAMPLE75=2017010134=98252=2017010107433721245605860=201701010743372124560585799=10000100268=2279=1269=048=17359555=6SZ683=357640270=10210.0271=34346=101023=5279=1269=048=17359555=6SZ683=357641270=10209.0271=23346=81023=610=028
1128=99=25335=X49=SAMPLE75=2017010134=226152=2017010102002951116882460=201701010200295111688245799=10000100268=2279=1269=048=17359555=6SZ683=357642270=10210.0271=31346=91023=5279=1269=048=17359555=6SZ683=357643270=10209.0271=26346=91023=610=018
1128=99=18035=X49=SAMPLE75=2017010134=26252=2017010109253801328916760=201701010925380132891675799=10000100268=1279=1269=048=17359555=6SZ683=357644270=10214.0271=6346=61023=110=083
1128=99=18035=X49=SAMPLE75=2017010134=361952=2017010102554682777963460=201701010255468277796345799=10000100268=1279=1269=048=17359555=6SZ683=357645270=10214.0271=7346=71023=110=116
1128=99=25435=X49=SAMPLE75=2017010134=44052=2017010102554428233865860=201701010255442823386585799=10000100268=2279=1269=048=17359555=6SZ683=357646270=10210.0271=34346=101023=5279=1269=048=17359555=6SZ683=357647270=10209.0271=23346=81023=610=055
1128=99=25335=X49=SAMPLE75=2017010134=481952=2017010108421946374100660=201701010842194637410065799=10000100268=2279=1269=048=17359555=6SZ683=357648270=10210.0271=31346=91023=5279=1269=048=17359555=6SZ683=357649270=10209.0271=26346=91023=610=007
1128=99=25435=X49=SAMPLE75=2017010134=12152=2017010107032099160749860=201701010703209916074985799=10000100268=2279=1269=048=17359555=6SZ683=357650270=10210.0271=34346=101023=5279=1269=048=17359555=6SZ683=357651270=10209.0271=23346=81023=610=041
1128=99=25335=X49=SAMPLE75=2017010134=20152=2017010107085287419108460=201701010708528741910845799=10000100268=2279=1269=048=17359555=6SZ683=357652270=10210.0271=31346=91023=5279=1269=048=17359555=6SZ683=357653270=10209.0271=26346=91023=610=027
1128=99=25435=X49=SAMPLE75=2017010134=360152=2017010110053870652943160=201701011005387065294315799=10000100268=2279=1269=048=17359555=6SZ683=357654270=10210.0271=34346=101023=5279=1269=048=17359555=6SZ683=357655270=10209.0271=23346=81023=610=060
1128=99=25335=X49=SAMPLE75=2017010134=115052=2017010100291669715757760=201701010029166971575775799=10000100268=2279=1269=048=17359555=6SZ683=357656270=10210.0271=31346=91023=5279=1269=048=17359555=6SZ683=357657270=10209.0271=26346=91023=610=012
1128=99=18135=X49=SAMPLE75=2017010134=114352=2017010110075715007431960=201701011007571500743195799=10000100268=1279=1269=148=17359555=6SZ683=357658270=10219.0271=15346=61023=410=139
1128=99=18135=X49=SAMPLE75=2017010134=418552=2017010113401688326278960=201701011340168832627895799=10000100268=1279=1269=148=17359555=6SZ683=357659270=10219.0271=22346=71023=410=158
1128=99=25435=X49=SAMPLE75=2017010134=39352=2017010106300160973549760=201701010630016097354975799=10000100268=2279=1269=048=17359555=6SZ683=357660270=10210.0271=34346=101023=5279=1269=048=17359555=6SZ683=357661270=10209.0271=23346=81023=610=050
1128=99=25235=X49=SAMPLE75=2017010134=121452=2017010111322437605678360=201701011132243760567835799=10000100268=2279=1269=048=17359555=6SZ683=357662270=10214.0271=8346=81023=1279=1269=048=17359555=6SZ683=357663270=10213.0271=18346=91023=210=226
1128=99=25335=X49=SAMPLE75=2017010134=78552=2017010104502631708044360=201701010450263170804435799=10000100268=2279=1269=148=17359555=6SZ683=357664270=10216.0271=16346=71023=1279=1269=148=17359555=6SZ683=357665270=10217.0271=17346=81023=210=034
1128=99=25335=X49=SAMPLE75=2017010134=176552=2017010102413240531618160=201701010241324053161815799=10000100268=2279=1269=148=17359555=6SZ683=357666270=10221.0271=43346=91023=6279=1269=148=17359555=6SZ683=357667270=10222.0271=30346=61023=710=030
1128=99=25435=X49=SAMPLE75=2017010134=164452=2017010107483075993221760=201701010748307599322175799=10000100268=2279=1269=148=17359555=6SZ683=357668270=10221.0271=46346=101023=6279=1269=148=17359555=6SZ683=357669270=10222.0271=27346=51023=710=075
1128=99=25335=X49=SAMPLE75=2017010134=392552=2017010105060899320789060=201701010506089932078905799=10000100268=2279=1269=048=17359555=6SZ683=357670270=10214.0271=7346=71023=1279=1269=048=17359555=6SZ683=357671270=10213.0271=19346=101023=210=242
1128=99=25335=X49=SAMPLE75=2017010134=228052=2017010113094397645597560=201701011309439764559755799=10000100268=2279=1269=148=17359555=6SZ683=357672270=10216.0271=17346=81023=1279=1269=148=17359555=6SZ683=357673270=10217.0271=16346=71023=210=251
1128=99=25335=X49=SAMPLE75=2017010134=373852=2017010114144585971632060=201701011414458597163205799=10000100268=2279=1269=148=17359555=6SZ683=357674270=10221.0271=43346=91023=6279=1269=148=17359555=6SZ683=357675270=10222.0271=30346=61023=710=008
1128=99=25335=X49=SAMPLE75=2017010134=277852=2017010105453284493028760=201701010545328449302875799=10000100268=2279=1269=148=17359555=6SZ683=357676270=10216.0271=16346=71023=1279=1269=148=17359555=6SZ683=357677270=10217.0271=17346=81023=210=029
1128=99=25235=X49=SAMPLE75=2017010134=416752=2017010108254164234072660=201701010825416423407265799=10000100268=2279=1269=048=17359555=6SZ683=357678270=10214.0271=8346=81023=1279=1269=048=17359555=6SZ683=357679270=10213.0271=18346=91023=210=245
1128=99=25435=X49=SAMPLE75=2017010134=145452=2017010113352090855739160=201701011335209085573915799=10000100268=2279=1269=148=17359555=6SZ683=357680270=10221.0271=46346=101023=6279=1269=148=17359555=6SZ683=357681270=10222.0271=27346=51023=710=075
1128=99=25335=X49=SAMPLE75=2017010134=478352=2017010110224641936834860=201701011022464193683485799=10000100268=2279=1269=048=17359555=6SZ683=357682270=10214.0271=7346=71023=1279=1269=048=17359555=6SZ683=357683270=10213.0271=19346=101023=210=013
1128=99=25335=X49=SAMPLE75=2017010134=112552=2017010103115405056492960=201701010311540505649295799=10000100268=2279=1269=148=17359555=6SZ683=357684270=10216.0271=17346=81023=1279=1269=148=17359555=6SZ683=357685270=10217.0271=16346=71023=210=043
1128=99=25335=X49=SAMPLE75=2017010134=463352=2017010100504670164758860=201701010050467016475885799=10000100268=2279=1269=148=17359555=6SZ683=357686270=10221.0271=43346=91023=6279=1269=148=17359555=6SZ683=357687270=10222.0271=30346=61023=710=047
1128=99=25235=X49=SAMPLE75=2017010134=354652=2017010109165637646499560=201701010916563764649955799=10000100268=2279=1269=048=17359555=6SZ683=357688270=10214.0271=8346=81023=1279=1269=048=17359555=6SZ683=357689270=10213.0271=18346=91023=210=247
1128=99=25335=X49=SAMPLE75=2017010134=177652=2017010106454451328411260=201701010645445132841125799=10000100268=2279=1269=148=17359555=6SZ683=357690270=10216.0271=16346=71023=1279=1269=148=17359555=6SZ683=357691270=10217.0271=17346=81023=210=023
1128=99=25335=X49=SAMPLE75=2017010134=96652=2017010101115296854312760=201701010111529685431275799=10000100268=2279=1269=048=17359555=6SZ683=357692270=10214.0271=7346=71023=1279=1269=048=17359555=6SZ683=357693270=10213.0271=19346=101023=210=022
1128=99=25335=X49=SAMPLE75=2017010134=29552=2017010105252575813920160=201701010525257581392015799=10000100268=2279=1269=148=17359555=6SZ683=357694270=10216.0271=17346=81023=1279=1269=148=17359555=6SZ683=357695270=10217.0271=16346=71023=210=041
1128=99=25435=X49=SAMPLE75=2017010134=203552=2017010105231442602289460=201701010523144260228945799=10000100268=2279=1269=148=17359555=6SZ683=357696270=10221.0271=46346=101023=6279=1269=148=17359555=6SZ683=357697270=10222.0271=27346=51023=710=108
1128=99=18135=X49=SAMPLE75=2017010134=420252=2017010109240459816433560=201701010924045981643355799=10000100268=1279=1269=148=17359555=6SZ683=357698270=10219.0271=15346=61023=410=191
1128=99=18135=X49=SAMPLE75=2017010134=363152=2017010109254790039774760=201701010925479003977475799=10000100268=1279=1269=148=17359555=6SZ683=357699270=10219.0271=22346=71023=410=173
1128=99=18135=X49=SAMPLE75=2017010134=240752=2017010107501430613664660=201701010750143061366465799=10000100268=1279=1269=148=17359555=6SZ683=357700270=10219.0271=15346=61023=410=159
1128=99=18135=X49=SAMPLE75=2017010134=69752=2017010110131978341317260=201701011013197834131725799=10000100268=1279=1269=148=17359555=6SZ683=357701270=10219.0271=22346=71023=410=165
1128=99=18135=X49=SAMPLE75=2017010134=323152=2017010113470573307971060=201701011347057330797105799=10000100268=1279=1269=148=17359555=6SZ683=357702270=10219.0271=15346=61023=410=158
1128=99=18135=X49=SAMPLE75=2017010134=344152=2017010104290917904692660=201701010429091790469265799=10000100268=1279=1269=148=17359555=6SZ683=357703270=10219.0271=22346=71023=410=168
1128=99=18135=X49=SAMPLE75=2017010134=70552=2017010105085584776953760=201701010508558477695375799=10000100268=1279=1269=148=17359555=6SZ683=357704270=10219.0271=15346=61023=410=198
1128=99=22035=X49=SAMPLE75=2017010134=210752=2017010110042011990090660=201701011004201199009065799=00000001268=1279=0269=248=17359555=6SZ683=357705270=10214.0271=1346=25797=237705=237=032=137=621180794447232=110=198
1128=99=15635=X49=SAMPLE75=2017010134=304052=2017010102202384117229660=201701010220238411722965799=00000010268=1279=0269=e48=17359555=6SZ683=357706271=7610=113
1128=99=18035=X49=SAMPLE75=2017010134=207152=2017010110494959557682060=201701011049495955768205799=10000100268=1279=1269=048=17359555=6SZ683=357707270=10214.0271=6346=61023=110=120
1128=99=17935=X49=SAMPLE75=2017010134=99252=2017010108542092431414760=201701010854209243141475799=10000100268=1279=0269=148=17360055=6SH783=99359270=10271.0271=3346=11023=110=054
1128=99=25135=X49=SAMPLE75=2017010134=375652=2017010112112055466705960=201701011211205546670595799=10000100268=2279=2269=148=17360055=6SH783=99360270=10271.0271=3346=11023=1279=0269=148=17360055=6SH783=99361270=10281.0271=11346=21023=1010=083
1128=99=18035=X49=SAMPLE75=2017010134=295752=2017010110481476042952860=201701011048147604295285799=10000100268=1279=1269=048=17359555=6SZ683=357708270=10214.0271=7346=71023=110=117
1128=99=18135=X49=SAMPLE75=2017010134=496852=2017010113410417319251160=201701011341041731925115799=10000100268=1279=1269=148=17359555=6SZ683=357709270=10219.0271=22346=71023=410=177
1128=99=18135=X49=SAMPLE75=2017010134=155652=2017010100090443674298960=201701010009044367429895799=10000100268=1279=1269=148=17359555=6SZ683=357710270=10219.0271=15346=61023=410=181
1128=99=18135=X49=SAMPLE75=2017010134=177952=2017010101105565515716060=201701010110556551571605799=10000100268=1279=1269=148=17359555=6SZ683=357711270=10219.0271=22346=71023=410=174
1128=99=18135=X49=SAMPLE75=2017010134=74852=2017010100285485864600560=201701010028548586460055799=10000100268=1279=1269=148=17359555=6SZ683=357712270=10219.0271=15346=61023=410=179
1128=99=25335=X49=SAMPLE75=2017010134=450552=2017010100552748419233060=201701010055274841923305799=10000100268=2279=1269=048=17359555=6SZ683=357713270=10210.0271=31346=91023=5279=1269=048=17359555=6SZ683=357714270=10209.0271=26346=91023=610=011
1128=99=18135=X49=SAMPLE75=2017010134=285352=2017010109455683742371860=201701010945568374237185799=10000100268=1279=1269=148=17359555=6SZ683=357715270=10219.0271=22346=71023=410=145
1128=99=18135=X49=SAMPLE75=2017010134=432452=2017010104254795846895960=201701010425479584689595799=10000100268=1279=1269=148=17359555=6SZ683=357716270=10219.0271=15346=61023=410=162
1128=99=18135=X49=SAMPLE75=2017010134=462152=2017010101254571551246960=201701010125457155124695799=10000100268=1279=1269=148=17359555=6SZ683=357717270=10219.0271=22346=71023=410=147
1128=99=18135=X49=SAMPLE75=2017010134=290752=2017010100303716049221260=201701010030371604922125799=10000100268=1279=1269=148=17359555=6SZ683=357718270=10219.0271=15346=61023=410=161
1128=99=18135=X49=SAMPLE75=2017010134=328452=2017010110303464156753560=201701011030346415675355799=10000100268=1279=1269=148=17359555=6SZ683=357719270=10219.0271=22346=71023=410=165
1128=99=25435=X49=SAMPLE75=2017010134=478952=2017010110432049016775960=201701011043204901677595799=10000100268=2279=1269=048=17359555=6SZ683=357720270=10210.0271=34346=101023=5279=1269=048=17359555=6SZ683=357721270=10209.0271=23346=81023=610=013
1128=99=18135=X49=SAMPLE75=2017010134=307352=2017010110294906657375860=201701011029490665737585799=10000100268=1279=1269=148=17359555=6SZ683=357722270=10219.0271=15346=61023=410=153
1128=99=25335=X49=SAMPLE75=2017010134=94652=2017010109592010870976360=201701010959201087097635799=10000100268=2279=1269=048=17359555=6SZ683=357723270=10210.0271=31346=91023=5279=1269=048=17359555=6SZ683=357724270=10209.0271=26346=91023=610=029
1128=99=18035=X49=SAMPLE75=2017010134=374952=2017010104525366823563760=201701010452536682356375799=10000100268=1279=1269=048=17359555=6SZ683=357725270=10214.0271=6346=61023=110=110
1128=99=18035=X49=SAMPLE75=2017010134=223652=2017010101350962446507860=201701010135096244650785799=10000100268=1279=1269=048=17359555=6SZ683=357726270=10214.0271=7346=71023=110=102
1128=99=18035=X49=SAMPLE75=2017010134=2852=2017010103200415668109660=201701010320041566810965799=10000100268=1279=1269=048=17359555=6SZ683=357727270=10214.0271=6346=61023=110=099
1128=99=18035=X49=SAMPLE75=2017010134=31252=2017010101493238174496460=201701010149323817449645799=10000100268=1279=1269=048=17359555=6SZ683=357728270=10214.0271=7346=71023=110=111
1128=99=18035=X49=SAMPLE75=2017010134=489952=2017010102490809812916860=201701010249080981291685799=10000100268=1279=1269=048=17359555=6SZ683=357729270=10214.0271=6346=61023=110=099
1128=99=25335=X49=SAMPLE75=2017010134=254752=2017010105002948282152660=201701010500294828215265799=10000100268=2279=1269=148=17359555=6SZ683=357730270=10220.0271=33346=91023=5279=1269=148=17359555=6SZ683=357731270=10221.0271=43346=91023=610=040
1128=99=25435=X49=SAMPLE75=2017010134=332452=2017010107072868298489160=201701010707286829848915799=10000100268=2279=1269=048=17359555=6SZ683=357732270=10213.0271=18346=91023=2279=1269=048=17359555=6SZ683=357733270=10212.0271=20346=111023=310=055
1128=99=18035=X49=SAMPLE75=2017010134=339352=2017010108221799001134960=201701010822179900113495799=10000100268=1279=1269=048=17359555=6SZ683=357734270=10214.0271=7346=71023=110=098
1128=99=25535=X49=SAMPLE75=2017010134=490552=2017010101301935638433860=201701010130193563843385799=10000100268=2279=1269=048=17359555=6SZ683=357735270=10213.0271=19346=101023=2279=1269=048=17359555=6SZ683=357736270=10212.0271=19346=101023=310=092
1128=99=25435=X49=SAMPLE75=2017010134=6152=2017010102522990463093760=201701010252299046309375799=10000100268=2279=1269=148=17359555=6SZ683=357737270=10220.0271=30346=81023=5279=1269=148=17359555=6SZ683=357738270=10221.0271=46346=101023=610=041
1128=99=18135=X49=SAMPLE75=2017010134=74352=2017010105212898755483060=201701010521289875548305799=10000100268=1279=1269=048=17359555=6SZ683=357739270=10214.0271=10346=81023=110=176
1128=99=18135=X49=SAMPLE75=2017010134=337452=2017010108572975015994760=201701010857297501599475799=10000100268=1279=1269=148=17359555=6SZ683=357740270=10219.0271=22346=71023=410=141
1128=99=18135=X49=SAMPLE75=2017010134=85252=2017010111525852085314860=201701011152585208531485799=10000100268=1279=1269=048=17359555=6SZ683=357741270=10213.0271=18346=91023=210=181
1128=99=18135=X49=SAMPLE75=2017010134=157452=2017010106250420561621860=201701010625042056162185799=10000100268=1279=1269=048=17359555=6SZ683=357742270=10214.0271=11346=91023=110=174
1128=99=18135=X49=SAMPLE75=2017010134=452252=2017010100024180750739260=201701010002418075073925799=10000100268=1279=1269=048=17359555=6SZ683=357743270=10214.0271=10346=81023=110=155
1128=99=18135=X49=SAMPLE75=2017010134=298552=2017010110202815632990360=201701011020281563299035799=10000100268=1279=1269=148=17359555=6SZ683=357744270=10219.0271=15346=61023=410=162
1128=99=18135=X49=SAMPLE75=2017010134=253952=2017010102241376952834660=201701010224137695283465799=10000100268=1279=1269=148=17359555=6SZ683=357745270=10219.0271=22346=71023=410=178
1128=99=18135=X49=SAMPLE75=2017010134=144252=2017010102091747639796060=201701010209174763979605799=10000100268=1279=1269=148=17359555=6SZ683=357746270=10219.0271=15346=61023=410=185
1128=99=18135=X49=SAMPLE75=2017010134=343552=2017010113544013183755960=201701011354401318375595799=10000100268=1279=1269=148=17359555=6SZ683=357747270=10217.0271=15346=61023=210=174
1128=99=18235=X49=SAMPLE75=2017010134=81952=2017010105054417590460060=201701010505441759046005799=10000100268=1279=1269=048=17359555=6SZ683=357748270=10213.0271=19346=101023=210=234
1128=99=18135=X49=SAMPLE75=2017010134=390152=2017010103452705469155560=201701010345270546915555799=10000100268=1279=1269=148=17359555=6SZ683=357749270=10218.0271=16346=71023=310=187
1128=99=18135=X49=SAMPLE75=2017010134=84552=2017010113021436307131860=201701011302143630713185799=10000100268=1279=1269=148=17359555=6SZ683=357750270=10219.0271=22346=71023=410=165
1128=99=18135=X49=SAMPLE75=2017010134=302252=2017010110134104165804860=201701011013410416580485799=10000100268=1279=1269=148=17359555=6SZ683=357751270=10216.0271=18346=91023=110=186
1128=99=18135=X49=SAMPLE75=2017010134=393252=2017010111014965661397160=201701011101496566139715799=10000100268=1279=1269=148=17359555=6SZ683=357752270=10217.0271=14346=51023=210=149
1128=99=18135=X49=SAMPLE75=2017010134=89352=2017010112571303455731060=201701011257130345573105799=10000100268=1279=1269=048=17359555=6SZ683=357753270=10207.0271=22346=71023=810=168
1128=99=18135=X49=SAMPLE75=2017010134=29952=2017010114045664545407560=201701011404566454540755799=10000100268=1279=1269=148=17359555=6SZ683=357754270=10219.0271=15346=61023=410=163
1128=99=18135=X49=SAMPLE75=2017010134=438452=2017010102442535579366060=201701010244253557936605799=10000100268=1279=1269=148=17359555=6SZ683=357755270=10219.0271=22346=71023=410=196
1128=99=18135=X49=SAMPLE75=2017010134=487452=2017010110520547658478460=201701011052054765847845799=10000100268=1279=1269=148=17359555=6SZ683=357756270=10216.0271=17346=81023=110=170
1128=99=18135=X49=SAMPLE75=2017010134=291052=2017010109263585455385160=201701010926358545538515799=10000100268=1279=1269=148=17359555=6SZ683=357757270=10219.0271=15346=61023=410=190
1128=99=18135=X49=SAMPLE75=2017010134=448552=2017010104552820663341860=201701010455282066334185799=10000100268=1279=1269=048=17359555=6SZ683=357758270=10214.0271=18346=91023=110=185
1128=99=18235=X49=SAMPLE75=2017010134=487152=2017010111463515517507860=201701011146351551750785799=10000100268=1279=1269=048=17359555=6SZ683=357759270=10214.0271=19346=101023=110=201
1128=99=18135=X49=SAMPLE75=2017010134=316152=2017010101075461536882260=201701010107546153688225799=10000100268=1279=1269=048=17359555=6SZ683=357760270=10213.0271=18346=91023=210=176
1128=99=18135=X49=SAMPLE75=2017010134=66452=2017010112472668475804960=201701011247266847580495799=10000100268=1279=1269=148=17359555=6SZ683=357761270=10219.0271=22346=71023=410=178
1128=99=18135=X49=SAMPLE75=2017010134=145652=2017010103264357001439260=201701010326435700143925799=10000100268=1279=1269=148=17359555=6SZ683=357762270=10219.0271=15346=61023=410=144
1128=99=18135=X49=SAMPLE75=2017010134=496652=2017010108071404861327660=201701010807140486132765799=10000100268=1279=1269=148=17359555=6SZ683=357763270=10217.0271=15346=61023=210=135
1128=99=18035=X49=SAMPLE75=2017010134=161152=2017010101074443578867960=201701010107444357886795799=10000100268=1279=0269=048=17359555=6SZ683=357764270=10215.0271=3346=11023=110=125
1128=99=18035=X49=SAMPLE75=2017010134=298252=2017010102451345415961560=201701010245134541596155799=10000100268=1279=1269=148=17359555=6SZ683=357765270=10216.0271=9346=71023=110=144
1128=99=17935=X49=SAMPLE75=2017010134=317152=2017010107171180685257760=201701010717118068525775799=10000100268=1279=0269=048=17360055=6SH783=99362270=10268.0271=3346=11023=110=052
1128=99=18035=X49=SAMPLE75=2017010134=204452=2017010107484096402818860=201701010748409640281885799=10000100268=1279=1269=048=17359555=6SZ683=357766270=10215.0271=4346=21023=110=117
1128=99=18235=X49=SAMPLE75=2017010134=385052=2017010107090514167320760=201701010709051416732075799=10000100268=1279=1269=048=17359555=6SZ683=357767270=10206.0271=39346=51023=1010=234
1128=99=18235=X49=SAMPLE75=2017010134=492352=2017010109150851124821260=201701010915085112482125799=10000100268=1279=1269=048=17359555=6SZ683=357768270=10213.0271=19346=101023=310=214
1128=99=18135=X49=SAMPLE75=2017010134=481852=2017010111102754584696960=201701011110275458469695799=10000100268=1279=1269=048=17359555=6SZ683=357769270=10208.0271=30346=81023=810=193
1128=99=18135=X49=SAMPLE75=2017010134=335752=2017010108220374253144160=201701010822037425314415799=10000100268=1279=1269=048=17359555=6SZ683=357770270=10214.0271=18346=91023=210=198
1128=99=25235=X49=SAMPLE75=2017010134=411052=2017010109544252950509360=201701010954425295050935799=10000100268=2279=1269=148=17359555=6SZ683=357771270=10216.0271=8346=61023=1279=1269=148=17359555=6SZ683=357772270=10220.0271=31346=91023=510=224
1128=99=18035=X49=SAMPLE75=2017010134=148452=2017010100552613114042060=201701010055261311404205799=10000100268=1279=1269=048=17359555=6SZ683=357773270=10215.0271=5346=31023=110=104
1128=99=25035=X49=SAMPLE75=2017010134=461552=2017010107543392192732260=201701010754339219273225799=10000100268=2279=2269=048=17360055=6SH783=99363270=10268.0271=3346=11023=1279=0269=048=17360055=6SH783=99364270=10258.0271=3346=11023=1010=071
1128=99=18135=X49=SAMPLE75=2017010134=482752=2017010100554617247400160=201701010055461724740015799=10000100268=1279=1269=048=17359555=6SZ683=357774270=10211.0271=22346=81023=510=177
1128=99=18135=X49=SAMPLE75=2017010134=291252=2017010100225266945706260=201701010022526694570625799=10000100268=1279=1269=148=17359555=6SZ683=357775270=10216.0271=16346=71023=110=175
1128=99=18035=X49=SAMPLE75=2017010134=250952=2017010114173412949191760=201701011417341294919175799=10000100268=1279=1269=048=17359555=6SZ683=357776270=10215.0271=4346=21023=110=110
1128=99=25335=X49=SAMPLE75=2017010134=269152=2017010109215641580658660=201701010921564158065865799=10000100268=2279=1269=148=17359555=6SZ683=357777270=10216.0271=17346=81023=1279=1269=148=17359555=6SZ683=357778270=10220.0271=30346=81023=510=013
1128=99=18135=X49=SAMPLE75=2017010134=135552=2017010103331571558553660=201701010333157155855365799=10000100268=1279=1269=048=17359555=6SZ683=357779270=10211.0271=15346=71023=510=186
1128=99=18135=X49=SAMPLE75=2017010134=356252=2017010105192518485155060=201701010519251848515505799=10000100268=1279=1269=048=17359555=6SZ683=357780270=10211.0271=22346=81023=510=160
1128=99=18035=X49=SAMPLE75=2017010134=445852=2017010112560110408487560=201701011256011040848755799=10000100268=1279=1269=148=17359555=6SZ683=357781270=10216.0271=9346=71023=110=116
1128=99=18035=X49=SAMPLE75=2017010134=279452=2017010111355244408792760=201701011135524440879275799=10000100268=1279=1269=048=17359555=6SZ683=357782270=10215.0271=5346=31023=110=122
1128=99=25235=X49=SAMPLE75=2017010134=109752=2017010110412608153398460=201701011041260815339845799=10000100268=2279=1269=148=17359555=6SZ683=357783270=10216.0271=8346=61023=1279=1269=148=17359555=6SZ683=357784270=10220.0271=31346=91023=510=220
1128=99=18035=X49=SAMPLE75=2017010134=375352=2017010104570004727857060=201701010457000472785705799=10000100268=1279=1269=048=17359555=6SZ683=357785270=10215.0271=6346=41023=110=108
1128=99=18035=X49=SAMPLE75=2017010134=71452=2017010104195008565902560=201701010419500856590255799=10000100268=1279=1269=048=17359555=6SZ683=357786270=10215.0271=7346=51023=110=112
1128=99=17935=X49=SAMPLE75=2017010134=119452=2017010101274065068458160=201701010127406506845815799=10000100268=1279=0269=048=17360055=6SH783=99365270=10268.0271=3346=11023=110=044
1128=99=24935=X49=SAMPLE75=2017010134=478452=2017010107535729089365460=201701010753572908936545799=10000100268=2279=1269=048=17360055=6SH783=99366270=10267.0271=5346=21023=2279=1269=048=17360055=6SH783=99367270=10265.0271=3346=11023=410=030
1128=99=18135=X49=SAMPLE75=2017010134=247152=2017010102535555830994060=201701010253555583099405799=10000100268=1279=1269=048=17359555=6SZ683=357787270=10208.0271=29346=71023=810=191
1128=99=18035=X49=SAMPLE75=2017010134=459852=2017010111595684733602860=201701011159568473360285799=10000100268=1279=1269=048=17359555=6SZ683=357788270=10215.0271=8346=61023=110=131
1128=99=18135=X49=SAMPLE75=2017010134=357752=2017010106341868107220360=201701010634186810722035799=10000100268=1279=1269=048=17359555=6SZ683=357789270=10208.0271=28346=61023=810=184
1128=99=18035=X49=SAMPLE75=2017010134=116052=2017010108150029715392960=201701010815002971539295799=10000100268=1279=1269=148=17359555=6SZ683=357790270=10216.0271=5346=51023=110=128
1128=99=18035=X49=SAMPLE75=2017010134=486052=2017010107351979474983560=201701010735197947498355799=10000100268=1279=1269=148=17359555=6SZ683=357791270=10216.0271=4346=41023=110=118
1128=99=17935=X49=SAMPLE75=2017010134=43352=2017010101460130950936660=201701010146013095093665799=10000100268=1279=1269=148=17360055=6SH783=99368270=10272.0271=2346=11023=110=036
1128=99=32035=X49=SAMPLE75=2017010134=441052=2017010113055698470088760=201701011305569847008875799=10000100268=3279=2269=148=17360055=6SH783=99369270=10272.0271=2346=11023=1279=1269=148=17360055=6SH783=99370270=10275.0271=5346=21023=3279=0269=148=17360055=6SH783=99371270=10282.0271=3346=11023=1010=015
1128=99=18035=X49=SAMPLE75=2017010134=43952=2017010106324842442177560=201701010632484244217755799=10000100268=1279=1269=148=17359555=6SZ683=357792270=10216.0271=3346=31023=110=124
1128=99=18035=X49=SAMPLE75=2017010134=21952=2017010103485563961139460=201701010348556396113945799=10000100268=1279=1269=148=17359555=6SZ683=357793270=10216.0271=2346=21023=110=110
1128=99=18135=X49=SAMPLE75=2017010134=456052=2017010109393745974663660=201701010939374597466365799=10000100268=1279=1269=048=17359555=6SZ683=357794270=10211.0271=15346=71023=510=159
1128=99=18135=X49=SAMPLE75=2017010134=324252=2017010108323207859934560=201701010832320785993455799=10000100268=1279=1269=048=17359555=6SZ683=357795270=10211.0271=22346=81023=510=150
1128=99=18035=X49=SAMPLE75=2017010134=179652=2017010101483770505568460=201701010148377050556845799=10000100268=1279=1269=148=17359555=6SZ683=357796270=10216.0271=3346=31023=110=135
1128=99=18035=X49=SAMPLE75=2017010134=412552=2017010112504301093019860=201701011250430109301985799=10000100268=1279=1269=048=17359555=6SZ683=357797270=10215.0271=7346=51023=110=168
1128=99=18035=X49=SAMPLE75=2017010134=83452=2017010110021708723868860=201701011002170872386885799=10000100268=1279=1269=148=17359555=6SZ683=357798270=10216.0271=4346=41023=110=153
1128=99=18035=X49=SAMPLE75=2017010134=202352=2017010113382183719417060=201701011338218371941705799=10000100268=1279=1269=048=17359555=6SZ683=357799270=10215.0271=6346=41023=110=119
1128=99=18035=X49=SAMPLE75=2017010134=294752=2017010105183254315061760=201701010518325431506175799=10000100268=1279=1269=048=17359555=6SZ683=357800270=10215.0271=5346=31023=110=094
1128=99=25035=X49=SAMPLE75=2017010134=40152=2017010111542262124938560=201701011154226212493855799=10000100268=2279=2269=048=17360055=6SH783=99372270=10268.0271=3346=11023=1279=0269=048=17360055=6SH783=99373270=10258.0271=3346=11023=1010=059
1128=99=23235=X49=SAMPLE75=2017010134=132652=2017010113420956569779660=201701011342095656977965799=00000001268=1279=0269=248=17359555=6SZ683=357801270=10216.0271=1346=25797=137705=237=621180795450032=137=621180794100832=110=016
1128=99=15635=X49=SAMPLE75=2017010134=475852=2017010109372099768492460=201701010937209976849245799=00000010268=1279=0269=e48=17359555=6SZ683=357802271=7710=086
1128=99=18035=X49=SAMPLE75=2017010134=46952=2017010107524131917980860=201701010752413191798085799=00000100268=1279=1269=148=17359555=6SZ683=357803270=10216.0271=3346=31023=110=088
1128=99=16935=X49=SAMPLE75=2017010134=271852=2017010104434632499678060=201701010443463249967805799=10001000268=1279=0269=748=17359555=6SZ683=357804270=10216.0286=25510=146
1128=99=18035=X49=SAMPLE75=2017010134=321252=2017010111050664157513260=201701011105066415751325799=10000100268=1279=1269=148=17359555=6SZ683=357805270=10216.0271=2346=21023=110=083
1128=99=18035=X49=SAMPLE75=2017010134=218052=2017010108415064700655560=201701010841506470065555799=10000100268=1279=1269=048=17359555=6SZ683=357806270=10215.0271=6346=41023=110=112
1128=99=18035=X49=SAMPLE75=2017010134=87852=2017010110381482431740160=201701011038148243174015799=10000100268=1279=1269=048=17359555=6SZ683=357807270=10215.0271=7346=51023=110=118
1128=99=18035=X49=SAMPLE75=2017010134=236152=2017010100311571343838760=201701010031157134383875799=10000100268=1279=1269=148=17359555=6SZ683=357808270=10216.0271=3346=31023=110=105
1128=99=18035=X49=SAMPLE75=2017010134=24952=2017010101150832192158560=201701010115083219215855799=10000100268=1279=1269=048=17359555=6SZ683=357809270=10215.0271=8346=61023=110=112
1128=99=17935=X49=SAMPLE75=2017010134=103452=2017010103192287263778060=201701010319228726377805799=10000100268=1279=0269=048=17360055=6SH783=99374270=10268.0271=3346=11023=110=040
1128=99=18035=X49=SAMPLE75=2017010134=18452=2017010101481159687405960=201701010148115968740595799=10000100268=1279=1269=148=17359555=6SZ683=357810270=10216.0271=2346=21023=110=101
1128=99=18035=X49=SAMPLE75=2017010134=191652=2017010105061084819908160=201701010506108481990815799=10000100268=1279=1269=148=17359555=6SZ683=357811270=10216.0271=1346=11023=110=103
1128=99=20835=X49=SAMPLE75=2017010134=26652=2017010101102718215973960=201701010110271821597395799=00000001268=1279=0269=248=17359555=6SZ683=357812270=10216.0271=1346=25797=137705=237=032=137=032=110=084
1128=99=15635=X49=SAMPLE75=2017010134=152552=2017010112582052429431560=201701011258205242943155799=00000010268=1279=0269=e48=17359555=6SZ683=357813271=7810=122
1128=99=25335=X49=SAMPLE75=2017010134=318252=2017010112412480906212160=201701011241248090621215799=10000100268=2279=2269=148=17359555=6SZ683=357814270=10216.0271=1346=11023=1279=0269=148=17359555=6SZ683=357815270=10226.0271=15346=21023=1010=010
1128=99=17935=X49=SAMPLE75=2017010134=224252=2017010108370507842030660=201701010837050784203065799=00000100268=1279=0269=048=17360055=6SH783=99375270=10269.0271=3346=11023=110=041
1128=99=16835=X49=SAMPLE75=2017010134=449752=2017010105350592096835960=201701010535059209683595799=10001000268=1279=0269=N48=17360055=6SH783=99376270=10269.0286=25510=117
1128=99=18035=X49=SAMPLE75=2017010134=195352=2017010110454451502645460=201701011045445150264545799=10000100268=1279=1269=048=17359555=6SZ683=357816270=10215.0271=9346=71023=110=132
1128=99=18135=X49=SAMPLE75=2017010134=61452=2017010114085547751444660=201701011408554775144465799=10000100268=1279=1269=048=17359555=6SZ683=357817270=10215.0271=10346=81023=110=177
1128=99=18135=X49=SAMPLE75=2017010134=186552=2017010102242801162803860=201701010224280116280385799=10000100268=1279=1269=048=17359555=6SZ683=357818270=10209.0271=25346=81023=710=180
1128=99=18135=X49=SAMPLE75=2017010134=152852=2017010105461823692684460=201701010546182369268445799=10000100268=1279=1269=148=17359555=6SZ683=357819270=10217.0271=16346=71023=110=181
1128=99=25135=X49=SAMPLE75=2017010134=183752=2017010112011414626817560=201701011201141462681755799=10000100268=2279=2269=048=17360055=6SH783=99377270=10269.0271=3346=11023=1279=0269=048=17360055=6SH783=99378270=10259.0271=11346=21023=1010=131
1128=99=25335=X49=SAMPLE75=2017010134=449452=2017010114183043592662960=201701011418304359266295799=10000100268=2279=1269=148=17359555=6SZ683=357820270=10220.0271=23346=81023=4279=1269=148=17359555=6SZ683=357821270=10224.0271=44346=51023=810=008
1128=99=17935=X49=SAMPLE75=2017010134=323452=2017010101430727265076560=201701010143072726507655799=10000100268=1279=1269=148=17360055=6SH783=99379270=10279.0271=3346=11023=710=067
1128=99=18135=X49=SAMPLE75=2017010134=299252=2017010107014293294875560=201701010701429329487555799=10000100268=1279=1269=148=17359555=6SZ683=357822270=10220.0271=16346=71023=410=165
1128=99=18035=X49=SAMPLE75=2017010134=243552=2017010107545013140365260=201701010754501314036525799=10000100268=1279=0269=148=17359555=6SZ683=357823270=10216.0271=1346=11023=110=097
1128=99=17935=X49=SAMPLE75=2017010134=225252=2017010114331299828164360=201701011433129982816435799=10000100268=1279=0269=148=17360055=6SH783=99380270=10272.0271=3346=11023=110=043
1128=99=25235=X49=SAMPLE75=2017010134=298652=2017010100500975671824460=201701010050097567182445799=10000100268=2279=1269=148=17359555=6SZ683=357824270=10216.0271=2346=21023=1279=1269=148=17359555=6SZ683=357825270=10217.0271=15346=61023=210=220
1128=99=18035=X49=SAMPLE75=2017010134=317752=2017010109390395052909260=201701010939039505290925799=10000100268=1279=1269=048=17359555=6SZ683=357826270=10215.0271=9346=71023=110=115
1128=99=18035=X49=SAMPLE75=2017010134=409052=2017010102532081529279060=201701010253208152927905799=10000100268=1279=1269=048=17359555=6SZ683=357827270=10215.0271=8346=61023=110=132
1128=99=25335=X49=SAMPLE75=2017010134=217052=2017010104384909454137160=201701010438490945413715799=10000100268=2279=1269=148=17359555=6SZ683=357828270=10220.0271=19346=81023=5279=1269=148=17359555=6SZ683=357829270=10221.0271=43346=91023=610=046
1128=99=25035=X49=SAMPLE75=2017010134=84852=2017010104394810194827360=201701010439481019482735799=10000100268=2279=2269=148=17360055=6SH783=99381270=10272.0271=3346=11023=1279=0269=148=17360055=6SH783=99382270=10282.0271=3346=11023=1010=063
1128=99=18135=X49=SAMPLE75=2017010134=227452=2017010110281441243769860=201701011028144124376985799=10000100268=1279=1269=148=17359555=6SZ683=357830270=10220.0271=26346=91023=510=171
1128=99=18035=X49=SAMPLE75=2017010134=299852=2017010100063634760639060=201701010006363476063905799=10000100268=1279=1269=148=17359555=6SZ683=357831270=10216.0271=3346=31023=110=124
1128=99=18035=X49=SAMPLE75=2017010134=240152=2017010100180522135308260=201701010018052213530825799=10000100268=1279=1269=148=17359555=6SZ683=357832270=10216.0271=2346=21023=110=111
1128=99=18035=X49=SAMPLE75=2017010134=357952=2017010101143675620874960=201701010114367562087495799=10000100268=1279=1269=148=17359555=6SZ683=357833270=10216.0271=1346=11023=110=115
1128=99=18035=X49=SAMPLE75=2017010134=77752=2017010113283769492820960=201701011328376949282095799=10000100268=1279=1269=148=17359555=6SZ683=357834270=10216.0271=2346=21023=110=082
1128=99=18135=X49=SAMPLE75=2017010134=386752=2017010105512257061455560=201701010551225706145555799=10000100268=1279=1269=148=17359555=6SZ683=357835270=10220.0271=19346=81023=510=147
1128=99=25435=X49=SAMPLE75=2017010134=384552=2017010104410665351315760=201701010441066535131575799=10000100268=2279=1269=148=17359555=6SZ683=357836270=10220.0271=16346=71023=5279=1269=148=17359555=6SZ683=357837270=10221.0271=46346=101023=610=052
1128=99=25335=X49=SAMPLE75=2017010134=173452=2017010106490168930013560=201701010649016893001355799=10000100268=2279=1269=148=17359555=6SZ683=357838270=10220.0271=19346=81023=5279=1269=148=17359555=6SZ683=357839270=10221.0271=43346=91023=610=243
1128=99=18135=X49=SAMPLE75=2017010134=259652=2017010113332859544832460=201701011333285954483245799=10000100268=1279=1269=148=17359555=6SZ683=357840270=10220.0271=26346=91023=510=145
1128=99=25435=X49=SAMPLE75=2017010134=252952=2017010100524998688876660=201701010052499868887665799=10000100268=2279=1269=148=17359555=6SZ683=357841270=10220.0271=34346=101023=5279=1269=148=17359555=6SZ683=357842270=10224.0271=36346=41023=910=051
1128=99=18035=X49=SAMPLE75=2017010134=73052=2017010102344903052980560=201701010234490305298055799=10000100268=1279=1269=148=17359555=6SZ683=357843270=10216.0271=1346=11023=110=118
1128=99=20835=X49=SAMPLE75=2017010134=372852=2017010103400042222321860=201701010340004222232185799=00000001268=1279=0269=248=17359555=6SZ683=357844270=10216.0271=1346=25797=137705=237=032=137=032=110=064
1128=99=15635=X49=SAMPLE75=2017010134=478952=2017010107055544243512960=201701010705554424351295799=00000010268=1279=0269=e48=17359555=6SZ683=357845271=7910=105
1128=99=25335=X49=SAMPLE75=2017010134=403552=2017010112444894725011160=201701011244489472501115799=10000100268=2279=2269=148=17359555=6SZ683=357846270=10216.0271=1346=11023=1279=0269=148=17359555=6SZ683=357847270=10226.0271=15346=21023=1010=253
1128=99=17935=X49=SAMPLE75=2017010134=248252=2017010108551074170958160=201701010855107417095815799=10000100268=1279=0269=048=17360055=6SH783=99383270=10269.0271=3346=11023=110=047
1128=99=18035=X49=SAMPLE75=2017010134=105952=2017010105001130143099660=201701010500113014309965799=10000100268=1279=1269=048=17359555=6SZ683=357848270=10215.0271=9346=71023=110=126
1128=99=18035=X49=SAMPLE75=2017010134=28852=2017010106234981304695460=201701010623498130469545799=10000100268=1279=1269=148=17359555=6SZ683=357849270=10217.0271=7346=51023=110=135
1128=99=18135=X49=SAMPLE75=2017010134=420752=2017010108140173092384760=201701010814017309238475799=10000100268=1279=1269=048=17359555=6SZ683=357850270=10215.0271=10346=81023=110=159
1128=99=18035=X49=SAMPLE75=2017010134=271552=2017010103083225179888760=201701010308322517988875799=10000100268=1279=1269=148=17359555=6SZ683=357851270=10217.0271=8346=61023=110=109
1128=99=25435=X49=SAMPLE75=2017010134=21152=2017010104134836488530360=201701010413483648853035799=10000100268=2279=1269=048=17359555=6SZ683=357852270=10214.0271=19346=101023=2279=1269=048=17359555=6SZ683=357853270=10213.0271=18346=91023=310=053
1128=99=18035=X49=SAMPLE75=2017010134=106252=2017010101272452955383860=201701010127245295538385799=10000100268=1279=1269=148=17359555=6SZ683=357854270=10217.0271=9346=71023=110=132
1128=99=25135=X49=SAMPLE75=2017010134=364752=2017010104530166693775360=201701010453016669377535799=10000100268=2279=2269=048=17360055=6SH783=99384270=10269.0271=3346=11023=1279=0269=048=17360055=6SH783=99385270=10259.0271=11346=21023=1010=125
1128=99=18135=X49=SAMPLE75=2017010134=13152=2017010111125543438330560=201701011112554343833055799=10000100268=1279=1269=148=17359555=6SZ683=357855270=10217.0271=10346=81023=110=163
1128=99=18135=X49=SAMPLE75=2017010134=78052=2017010113252477847482760=201701011325247784748275799=10000100268=1279=1269=148=17359555=6SZ683=357856270=10220.0271=27346=91023=410=157
1128=99=25335=X49=SAMPLE75=2017010134=211452=2017010103085773106752060=201701010308577310675205799=10000100268=2279=1269=148=17359555=6SZ683=357857270=10220.0271=19346=81023=4279=1269=148=17359555=6SZ683=357858270=10224.0271=44346=51023=810=238
1128=99=18035=X49=SAMPLE75=2017010134=275852=2017010101254196380156060=201701010125419638015605799=10000100268=1279=1269=148=17359555=6SZ683=357859270=10217.0271=9346=71023=110=124
1128=99=18135=X49=SAMPLE75=2017010134=270252=2017010114280302414219260=201701011428030241421925799=10000100268=1279=1269=148=17359555=6SZ683=357860270=10217.0271=17346=81023=110=160
1128=99=18135=X49=SAMPLE75=2017010134=257652=2017010113022988767054860=201701011302298876705485799=10000100268=1279=1269=048=17359555=6SZ683=357861270=10207.0271=21346=61023=910=167
1128=99=18135=X49=SAMPLE75=2017010134=398752=2017010100212013638848460=201701010021201363884845799=10000100268=1279=1269=148=17359555=6SZ683=357862270=10218.0271=15346=61023=210=153
1128=99=18135=X49=SAMPLE75=2017010134=139752=2017010102264667006108660=201701010226466700610865799=10000100268=1279=1269=148=17359555=6SZ683=357863270=10223.0271=19346=41023=710=169
1128=99=18135=X49=SAMPLE75=2017010134=209352=2017010100333997721575660=201701010033399772157565799=10000100268=1279=1269=148=17359555=6SZ683=357864270=10218.0271=16346=71023=210=167
1128=99=18035=X49=SAMPLE75=2017010134=211952=2017010108435000608208160=201701010843500060820815799=10000100268=1279=1269=148=17359555=6SZ683=357865270=10217.0271=9346=71023=110=109
1128=99=18035=X49=SAMPLE75=2017010134=176052=2017010113335622423628260=201701011333562242362825799=10000100268=1279=1269=148=17359555=6SZ683=357866270=10217.0271=8346=61023=110=121
1128=99=25435=X49=SAMPLE75=2017010134=366852=2017010107233634990818160=201701010723363499081815799=10000100268=2279=1269=148=17359555=6SZ683=357867270=10220.0271=16346=71023=4279=1269=148=17359555=6SZ683=357868270=10221.0271=46346=101023=510=071
1128=99=18035=X49=SAMPLE75=2017010134=119552=2017010101481768090267060=201701010148176809026705799=00000100268=1279=0269=048=17359555=6SZ683=357869270=10216.0271=1346=11023=110=119
1128=99=16935=X49=SAMPLE75=2017010134=475452=2017010105561344845435560=201701010556134484543555799=10001000268=1279=0269=N48=17359555=6SZ683=357870270=10216.0286=25510=197
1128=99=17935=X49=SAMPLE75=2017010134=131352=2017010103524014804222860=201701010352401480422285799=10000100268=1279=0269=048=17360055=6SH783=99386270=10269.0271=3346=11023=110=040
1128=99=24735=X49=SAMPLE75=2017010134=225052=2017010110572268469848060=201701011057226846984805799=10000100268=2279=0269=048=17360355=6SM783=7558270=10285.0271=6346=11023=4279=2269=048=17360355=6SM783=7559270=10284.0271=6346=11023=510=208
1128=99=18235=X49=SAMPLE75=2017010134=286452=2017010107230208905503460=201701010723020890550345799=10000100268=1279=1269=048=17359555=6SZ683=357871270=10207.0271=20346=51023=1010=209
1128=99=18235=X49=SAMPLE75=2017010134=85852=2017010100523573587602060=201701010052357358760205799=10000100268=1279=1269=048=17359555=6SZ683=357872270=10214.0271=20346=111023=310=223
1128=99=18035=X49=SAMPLE75=2017010134=381352=2017010108233923506005960=201701010823392350600595799=10000100268=1279=1269=048=17359555=6SZ683=357873270=10215.0271=9346=71023=210=136
1128=99=18035=X49=SAMPLE75=2017010134=404752=2017010110551422987386960=201701011055142298738695799=10000100268=1279=1269=048=17359555=6SZ683=357874270=10216.0271=2346=21023=110=128
1128=99=25135=X49=SAMPLE75=2017010134=203352=2017010108131371440619960=201701010813137144061995799=10000100268=2279=2269=048=17360055=6SH783=99387270=10269.0271=3346=11023=1279=0269=048=17360055=6SH783=99388270=10259.0271=11346=21023=1010=134
1128=99=18135=X49=SAMPLE75=2017010134=50252=2017010100515110748633560=201701010051511074863355799=10000100268=1279=1269=048=17359555=6SZ683=357875270=10215.0271=17346=81023=210=167
1128=99=25235=X49=SAMPLE75=2017010134=429852=2017010100545786532865460=201701010054578653286545799=10000100268=2279=1269=048=17359555=6SZ683=357876270=10216.0271=3346=31023=1279=1269=048=17359555=6SZ683=357877270=10212.0271=18346=91023=510=251
1128=99=18035=X49=SAMPLE75=2017010134=334652=2017010113413981587577360=201701011341398158757735799=10000100268=1279=1269=048=17359555=6SZ683=357878270=10216.0271=4346=41023=110=140
1128=99=18135=X49=SAMPLE75=2017010134=485952=2017010104592379115732160=201701010459237911573215799=10000100268=1279=1269=048=17359555=6SZ683=357879270=10209.0271=24346=71023=810=210
1128=99=18035=X49=SAMPLE75=2017010134=156852=2017010104384402024024860=201701010438440202402485799=10000100268=1279=1269=148=17359555=6SZ683=357880270=10217.0271=7346=51023=110=101
1128=99=18035=X49=SAMPLE75=2017010134=416052=2017010109293455924770560=201701010929345592477055799=10000100268=1279=1269=048=17359555=6SZ683=357881270=10216.0271=5346=51023=110=123
1128=99=18135=X49=SAMPLE75=2017010134=271052=2017010106223636088521260=201701010622363608852125799=10000100268=1279=1269=048=17359555=6SZ683=357882270=10209.0271=23346=61023=810=194
1128=99=18135=X49=SAMPLE75=2017010134=349952=2017010112355353191881760=201701011235535319188175799=10000100268=1279=1269=048=17359555=6SZ683=357883270=10209.0271=43346=71023=810=182
1128=99=25135=X49=SAMPLE75=2017010134=219452=2017010105070942023564360=201701010507094202356435799=10000100268=2279=1269=048=17360055=6SH783=99389270=10263.0271=11346=21023=6279=1269=048=17360055=6SH783=99390270=10259.0271=3346=11023=1010=116
1128=99=25435=X49=SAMPLE75=2017010134=49452=2017010114172591097725260=201701011417259109772525799=10000100268=2279=1269=048=17359555=6SZ683=357884270=10212.0271=26346=101023=5279=1269=048=17359555=6SZ683=357885270=10208.0271=20346=51023=910=061
1128=99=18035=X49=SAMPLE75=2017010134=105152=2017010100442218783611260=201701010044221878361125799=10000100268=1279=1269=048=17359555=6SZ683=357886270=10216.0271=4346=41023=110=134
1128=99=18035=X49=SAMPLE75=2017010134=361452=2017010103242660944316260=201701010324266094431625799=10000100268=1279=1269=048=17359555=6SZ683=357887270=10216.0271=3346=31023=110=099
1128=99=18035=X49=SAMPLE75=2017010134=13452=2017010101564216111718660=201701010156421611171865799=10000100268=1279=1269=048=17359555=6SZ683=357888270=10216.0271=4346=41023=110=112
1128=99=18035=X49=SAMPLE75=2017010134=201552=2017010104471809421948360=201701010447180942194835799=10000100268=1279=1269=048=17359555=6SZ683=357889270=10216.0271=5346=51023=110=105
1128=99=18035=X49=SAMPLE75=2017010134=355952=2017010105334293468721260=201701010533429346872125799=10000100268=1279=1269=048=17359555=6SZ683=357890270=10216.0271=6346=61023=110=115
1128=99=18135=X49=SAMPLE75=2017010134=30652=2017010108363655097481260=201701010836365509748125799=10000100268=1279=1269=048=17359555=6SZ683=357891270=10209.0271=42346=61023=810=166
1128=99=17935=X49=SAMPLE75=2017010134=127852=2017010106565108775829060=201701010656510877582905799=10000100268=1279=0269=048=17360055=6SH783=99391270=10269.0271=3346=11023=110=030
1128=99=24935=X49=SAMPLE75=2017010134=496352=2017010102503572287331160=201701010250357228733115799=10000100268=2279=1269=048=17360055=6SH783=99392270=10268.0271=5346=21023=2279=1269=048=17360055=6SH783=99393270=10266.0271=3346=11023=410=002
1128=99=18035=X49=SAMPLE75=2017010134=338152=2017010105383414607337260=201701010538341460733725799=10000100268=1279=1269=048=17359555=6SZ683=357892270=10216.0271=7346=71023=110=114
1128=99=18035=X49=SAMPLE75=2017010134=199252=2017010101555517264239160=201701010155551726423915799=10000100268=1279=1269=148=17359555=6SZ683=357893270=10217.0271=6346=41023=110=100
1128=99=18135=X49=SAMPLE75=2017010134=254352=2017010103083439537253360=201701010308343953725335799=10000100268=1279=1269=148=17359555=6SZ683=357894270=10222.0271=28346=61023=610=173
1128=99=18035=X49=SAMPLE75=2017010134=164452=2017010110353428181021560=201701011035342818102155799=10000100268=1279=1269=148=17359555=6SZ683=357895270=10217.0271=5346=31023=110=107
1128=99=17935=X49=SAMPLE75=2017010134=4252=2017010107194277120424460=201701010719427712042445799=10000100268=1279=1269=148=17360055=6SH783=99394270=10273.0271=2346=11023=110=040
1128=99=18135=X49=SAMPLE75=2017010134=466352=2017010100094552339978060=201701010009455233997805799=10000100268=1279=1269=148=17359555=6SZ683=357896270=10222.0271=29346=71023=610=189
1128=99=32135=X49=SAMPLE75=2017010134=284752=2017010102462922383493260=201701010246292238349325799=10000100268=3279=2269=148=17360055=6SH783=99395270=10273.0271=2346=11023=1279=1269=148=17360055=6SH783=99396270=10276.0271=5346=21023=3279=0269=148=17360055=6SH783=99397270=10283.0271=61346=31023=1010=091
1128=99=18035=X49=SAMPLE75=2017010134=261352=2017010103444101810655360=201701010344410181065535799=10000100268=1279=1269=148=17359555=6SZ683=357897270=10217.0271=2346=21023=110=120
1128=99=18035=X49=SAMPLE75=2017010134=326752=2017010113442334641514360=201701011344233464151435799=10000100268=1279=1269=148=17359555=6SZ683=357898270=10217.0271=1346=11023=110=134
1128=99=18135=X49=SAMPLE75=2017010134=107352=2017010112474771795493060=201701011247477179549305799=10000100268=1279=1269=148=17359555=6SZ683=357899270=10222.0271=30346=81023=610=171
1128=99=18035=X49=SAMPLE75=2017010134=385052=2017010111223172768542060=201701011122317276854205799=10000100268=1279=1269=048=17359555=6SZ683=357900270=10216.0271=8346=81023=110=122
1128=99=18135=X49=SAMPLE75=2017010134=75352=2017010111591913216934960=201701011159191321693495799=10000100268=1279=1269=048=17359555=6SZ683=357901270=10210.0271=30346=81023=710=168
