1128=99=25135=X49=SAMPLE75=2016101134=185952=2015011708120464035116860=201501170812046403511685799=10000100268=2279=1269=048=17359555=6SZ683=356927270=10209.0271=5346=31023=4279=1269=048=17359555=6SZ683=356928270=10208.0271=9346=51023=510=186
1128=99=25135=X49=SAMPLE75=2016101134=328852=2012032622045951414995260=201203262204595141499525799=10000100268=2279=1269=048=17359555=6SZ683=356929270=10209.0271=8346=41023=4279=1269=048=17359555=6SZ683=356930270=10208.0271=6346=41023=510=168
1128=99=25135=X49=SAMPLE75=2016101134=353152=2001022812360964174033660=200102281236096417403365799=10000100268=2279=1269=048=17359555=6SZ683=356931270=10209.0271=5346=31023=4279=1269=048=17359555=6SZ683=356932270=10208.0271=9346=51023=510=167
1128=99=25135=X49=SAMPLE75=2016101134=277952=2015050401335580022220860=201505040133558002222085799=10000100268=2279=1269=048=17359555=6SZ683=356933270=10209.0271=8346=41023=4279=1269=048=17359555=6SZ683=356934270=10208.0271=6346=41023=510=154
1128=99=25135=X49=SAMPLE75=2016101134=273552=2008110410023851895804860=200811041002385189580485799=10000100268=2279=1269=048=17359555=6SZ683=356935270=10209.0271=5346=31023=4279=1269=048=17359555=6SZ683=356936270=10208.0271=9346=51023=510=166
1128=99=25135=X49=SAMPLE75=2016101134=423752=2009071922455314917280060=200907192245531491728005799=10000100268=2279=1269=048=17359555=6SZ683=356937270=10209.0271=8346=41023=4279=1269=048=17359555=6SZ683=356938270=10208.0271=6346=41023=510=145
1128=99=25135=X49=SAMPLE75=2016101134=187552=2016040806402960740691260=201604080640296074069125799=10000100268=2279=1269=048=17359555=6SZ683=356939270=10209.0271=5346=31023=4279=1269=048=17359555=6SZ683=356940270=10208.0271=9346=51023=510=151
1128=99=25135=X49=SAMPLE75=2016101134=399952=2013090723010397904025660=201309072301039790402565799=10000100268=2279=1269=048=17359555=6SZ683=356941270=10209.0271=8346=41023=4279=1269=048=17359555=6SZ683=356942270=10208.0271=6346=41023=510=146
1128=99=25135=X49=SAMPLE75=2016101134=122052=2008030618515747960566460=200803061851574796056645799=10000100268=2279=1269=048=17359555=6SZ683=356943270=10209.0271=5346=31023=4279=1269=048=17359555=6SZ683=356944270=10208.0271=9346=51023=510=165
1128=99=25135=X49=SAMPLE75=2016101134=53152=2005081620543768561545660=200508162054376856154565799=10000100268=2279=1269=048=17359555=6SZ683=356945270=10209.0271=8346=41023=4279=1269=048=17359555=6SZ683=356946270=10208.0271=6346=41023=510=166
1128=99=25135=X49=SAMPLE75=2016101134=478352=2013073014172135390009660=201307301417213539000965799=10000100268=2279=1269=048=17359555=6SZ683=356947270=10209.0271=5346=31023=4279=1269=048=17359555=6SZ683=356948270=10208.0271=9346=51023=510=187
1128=99=25135=X49=SAMPLE75=2016101134=387552=2004030311213832446526460=200403031121383244652645799=10000100268=2279=1269=048=17359555=6SZ683=356949270=10209.0271=8346=41023=4279=1269=048=17359555=6SZ683=356950270=10208.0271=6346=41023=510=176
1128=99=25135=X49=SAMPLE75=2016101134=98452=2014082210530067736761660=201408221053006773676165799=10000100268=2279=1269=048=17359555=6SZ683=356951270=10209.0271=5346=31023=4279=1269=048=17359555=6SZ683=356952270=10208.0271=9346=51023=510=161
1128=99=25135=X49=SAMPLE75=2016101134=119252=2007080917024449540332860=200708091702444954033285799=10000100268=2279=1269=048=17359555=6SZ683=356953270=10209.0271=8346=41023=4279=1269=048=17359555=6SZ683=356954270=10208.0271=6346=41023=510=184
1128=99=25135=X49=SAMPLE75=2016101134=63152=2009082009061809500902460=200908200906180950090245799=10000100268=2279=1269=148=17359555=6SZ683=356955270=10220.0271=4346=21023=8279=1269=148=17359555=6SZ683=356956270=10221.0271=6346=21023=910=193
1128=99=25135=X49=SAMPLE75=2016101134=167252=2013050208462122068896060=201305020846212206889605799=10000100268=2279=1269=148=17359555=6SZ683=356957270=10220.0271=7346=31023=8279=1269=148=17359555=6SZ683=356958270=10221.0271=3346=11023=910=185
1128=99=25135=X49=SAMPLE75=2016101134=203752=2011100700114404974137660=201110070011440497413765799=10000100268=2279=1269=048=17359555=6SZ683=356959270=10209.0271=5346=31023=4279=1269=048=17359555=6SZ683=356960270=10208.0271=9346=51023=510=187
1128=99=25135=X49=SAMPLE75=2016101134=434552=2004031416365628058868860=200403141636562805886885799=10000100268=2279=1269=048=17359555=6SZ683=356961270=10209.0271=8346=41023=4279=1269=048=17359555=6SZ683=356962270=10208.0271=6346=41023=510=169
1128=99=25135=X49=SAMPLE75=2016101134=93152=2007052316173411411603260=200705231617341141160325799=10000100268=2279=1269=048=17359555=6SZ683=356963270=10209.0271=5346=31023=4279=1269=048=17359555=6SZ683=356964270=10208.0271=9346=51023=510=176
1128=99=25135=X49=SAMPLE75=2016101134=269552=2014080214243440453740860=201408021424344045374085799=10000100268=2279=1269=048=17359555=6SZ683=356965270=10209.0271=8346=41023=4279=1269=048=17359555=6SZ683=356966270=10208.0271=6346=41023=510=163
1128=99=25135=X49=SAMPLE75=2016101134=165252=2014031413560292298937660=201403141356029229893765799=10000100268=2279=1269=048=17359555=6SZ683=356967270=10209.0271=5346=31023=4279=1269=048=17359555=6SZ683=356968270=10208.0271=9346=51023=510=191
1128=99=25135=X49=SAMPLE75=2016101134=144952=2007112918463388712563260=200711291846338871256325799=10000100268=2279=1269=048=17359555=6SZ683=356969270=10209.0271=8346=41023=4279=1269=048=17359555=6SZ683=356970270=10208.0271=6346=41023=510=199
1128=99=25135=X49=SAMPLE75=2016101134=59452=2004021306151360254849660=200402130615136025484965799=10000100268=2279=1269=148=17359555=6SZ683=356971270=10220.0271=4346=21023=8279=1269=148=17359555=6SZ683=356972270=10221.0271=6346=21023=910=130
1128=99=25135=X49=SAMPLE75=2016101134=398252=2006072519041790012790460=200607251904179001279045799=10000100268=2279=1269=148=17359555=6SZ683=356973270=10220.0271=7346=31023=8279=1269=148=17359555=6SZ683=356974270=10221.0271=3346=11023=910=136
1128=99=25135=X49=SAMPLE75=2016101134=15952=2015091623431265176825660=201509162343126517682565799=10000100268=2279=1269=048=17359555=6SZ683=356975270=10209.0271=5346=31023=4279=1269=048=17359555=6SZ683=356976270=10208.0271=9346=51023=510=155
1128=99=25135=X49=SAMPLE75=2016101134=394952=2016081219301935252006460=201608121930193525200645799=10000100268=2279=1269=048=17359555=6SZ683=356977270=10209.0271=8346=41023=4279=1269=048=17359555=6SZ683=356978270=10208.0271=6346=41023=510=162
1128=99=25135=X49=SAMPLE75=2016101134=456852=2007031006143221260902460=200703100614322126090245799=10000100268=2279=1269=048=17359555=6SZ683=356979270=10209.0271=5346=31023=4279=1269=048=17359555=6SZ683=356980270=10208.0271=9346=51023=510=147
1128=99=25135=X49=SAMPLE75=2016101134=89252=2011081800173034260038460=201108180017303426003845799=10000100268=2279=1269=048=17359555=6SZ683=356981270=10209.0271=8346=41023=4279=1269=048=17359555=6SZ683=356982270=10208.0271=6346=41023=510=159
1128=99=25135=X49=SAMPLE75=2016101134=204152=2004053023512536910835260=200405302351253691083525799=10000100268=2279=1269=048=17359555=6SZ683=356983270=10209.0271=5346=31023=4279=1269=048=17359555=6SZ683=356984270=10208.0271=9346=51023=510=149
1128=99=25135=X49=SAMPLE75=2016101134=456652=2013093016075860843628860=201309301607586084362885799=10000100268=2279=1269=048=17359555=6SZ683=356985270=10209.0271=8346=41023=4279=1269=048=17359555=6SZ683=356986270=10208.0271=6346=41023=510=175
1128=99=25135=X49=SAMPLE75=2016101134=69652=2005050310001970686179260=200505031000197068617925799=10000100268=2279=1269=048=17359555=6SZ683=356987270=10209.0271=5346=31023=4279=1269=048=17359555=6SZ683=356988270=10208.0271=9346=51023=510=185
1128=99=25135=X49=SAMPLE75=2016101134=197052=2012061803573148264697660=201206180357314826469765799=10000100268=2279=1269=048=17359555=6SZ683=356989270=10209.0271=8346=41023=4279=1269=048=17359555=6SZ683=356990270=10208.0271=6346=41023=510=154
1128=99=25135=X49=SAMPLE75=2016101134=188552=2006051416141976376364860=200605141614197637636485799=10000100268=2279=1269=148=17359555=6SZ683=356991270=10220.0271=4346=21023=8279=1269=148=17359555=6SZ683=356992270=10221.0271=6346=21023=910=141
1128=99=25135=X49=SAMPLE75=2016101134=68552=2004100820484869313913660=200410082048486931391365799=10000100268=2279=1269=148=17359555=6SZ683=356993270=10220.0271=7346=31023=8279=1269=148=17359555=6SZ683=356994270=10221.0271=3346=11023=910=136
1128=99=25135=X49=SAMPLE75=2016101134=124852=2008101519283418640233660=200810151928341864023365799=10000100268=2279=1269=148=17359555=6SZ683=356995270=10220.0271=4346=21023=8279=1269=148=17359555=6SZ683=356996270=10221.0271=6346=21023=910=174
1128=99=25135=X49=SAMPLE75=2016101134=91152=2009122806535490663737660=200912280653549066373765799=10000100268=2279=1269=148=17359555=6SZ683=356997270=10220.0271=7346=31023=8279=1269=148=17359555=6SZ683=356998270=10221.0271=3346=11023=910=175
1128=99=25135=X49=SAMPLE75=2016101134=208652=2009051221061066591001660=200905122106106659100165799=10000100268=2279=1269=148=17359555=6SZ683=356999270=10220.0271=4346=21023=8279=1269=148=17359555=6SZ683=357000270=10221.0271=6346=21023=910=139
1128=99=25135=X49=SAMPLE75=2016101134=331752=2002120708460896614326460=200212070846089661432645799=10000100268=2279=1269=148=17359555=6SZ683=357001270=10220.0271=7346=31023=8279=1269=148=17359555=6SZ683=357002270=10221.0271=3346=11023=910=140
1128=99=25135=X49=SAMPLE75=2016101134=74452=2001041215155769416986460=200104121515576941698645799=10000100268=2279=1269=048=17359555=6SZ683=357003270=10209.0271=5346=31023=4279=1269=048=17359555=6SZ683=357004270=10208.0271=9346=51023=510=129
1128=99=25135=X49=SAMPLE75=2016101134=54252=2008060323083361240163260=200806032308336124016325799=10000100268=2279=1269=048=17359555=6SZ683=357005270=10209.0271=8346=41023=4279=1269=048=17359555=6SZ683=357006270=10208.0271=6346=41023=510=145
1128=99=18035=X49=SAMPLE75=2016101134=119152=2010031622051766889280060=201003162205176688928005799=10000100268=1279=1269=048=17359555=6SZ683=357007270=10212.0271=3346=31023=110=090
1128=99=25135=X49=SAMPLE75=2016101134=128752=2010010207165482812025660=201001020716548281202565799=10000100268=2279=1269=148=17359555=6SZ683=357008270=10220.0271=4346=21023=8279=1269=148=17359555=6SZ683=357009270=10221.0271=6346=21023=910=166
1128=99=25135=X49=SAMPLE75=2016101134=177752=2007061623242460291062460=200706162324246029106245799=10000100268=2279=1269=148=17359555=6SZ683=357010270=10220.0271=7346=31023=8279=1269=148=17359555=6SZ683=357011270=10221.0271=3346=11023=910=104
1128=99=25135=X49=SAMPLE75=2016101134=156252=2009030406355504872768060=200903040635550487276805799=10000100268=2279=1269=148=17359555=6SZ683=357012270=10220.0271=4346=21023=8279=1269=148=17359555=6SZ683=357013270=10221.0271=6346=21023=910=143
1128=99=25135=X49=SAMPLE75=2016101134=260752=2014063011334319220307260=201406301133431922030725799=10000100268=2279=1269=148=17359555=6SZ683=357014270=10220.0271=7346=31023=8279=1269=148=17359555=6SZ683=357015270=10221.0271=3346=11023=910=147
1128=99=18035=X49=SAMPLE75=2016101134=259852=2000060320004444312544060=200006032000444431254405799=10000100268=1279=1269=048=17359555=6SZ683=357016270=10211.0271=4346=31023=210=099
1128=99=18035=X49=SAMPLE75=2016101134=141152=2015101105323493611430460=201510110532349361143045799=10000100268=1279=1269=048=17359555=6SZ683=357017270=10210.0271=5346=31023=310=094
1128=99=25135=X49=SAMPLE75=2016101134=212752=2000090203362286338844460=200009020336228633884445799=10000100268=2279=1269=148=17359555=6SZ683=357018270=10220.0271=4346=21023=8279=1269=148=17359555=6SZ683=357019270=10221.0271=6346=21023=910=132
1128=99=18035=X49=SAMPLE75=2016101134=141652=2017011817535156240422460=201701181753515624042245799=10000100268=1279=1269=048=17359555=6SZ683=357020270=10212.0271=4346=41023=110=095
1128=99=18135=X49=SAMPLE75=2016101134=425552=2013072714203965830995260=201307271420396583099525799=10000100268=1279=1269=148=17359555=6SZ683=357021270=10213.0271=13346=11023=110=152
1128=99=25135=X49=SAMPLE75=2016101134=3452=2012011519062709490457660=201201151906270949045765799=10000100268=2279=1269=148=17359555=6SZ683=357022270=10215.0271=4346=21023=3279=1269=148=17359555=6SZ683=357023270=10216.0271=6346=41023=410=136
1128=99=18135=X49=SAMPLE75=2016101134=252352=2016032013402834900921660=201603201340283490092165799=10000100268=1279=1269=148=17359555=6SZ683=357024270=10213.0271=14346=21023=110=153
1128=99=18235=X49=SAMPLE75=2016101134=114752=2006071015551800825590460=200607101555180082559045799=10000100268=1279=1269=048=17359555=6SZ683=357025270=10203.0271=12346=41023=1010=199
1128=99=18135=X49=SAMPLE75=2016101134=18352=2006072105360432360089660=200607210536043236008965799=10000100268=1279=1269=048=17359555=6SZ683=357026270=10203.0271=5346=31023=1010=129
1128=99=18035=X49=SAMPLE75=2016101134=42452=2003073010565352100121660=200307301056535210012165799=10000100268=1279=1269=048=17359555=6SZ683=357027270=10212.0271=3346=31023=110=082
1128=99=18035=X49=SAMPLE75=2016101134=221252=2007050803034368544035260=200705080303436854403525799=10000100268=1279=1269=048=17359555=6SZ683=357028270=10212.0271=2346=21023=110=128
1128=99=18235=X49=SAMPLE75=2016101134=472952=2002042116372702745505660=200204211637270274550565799=10000100268=1279=1269=048=17359555=6SZ683=357029270=10203.0271=12346=41023=1010=181
1128=99=25135=X49=SAMPLE75=2016101134=352052=2008110606544508929708860=200811060654450892970885799=10000100268=2279=1269=148=17359555=6SZ683=357030270=10215.0271=5346=31023=3279=1269=148=17359555=6SZ683=357031270=10216.0271=5346=31023=410=122
1128=99=18135=X49=SAMPLE75=2016101134=21052=2015060118141011491564860=201506011814101149156485799=10000100268=1279=1269=048=17359555=6SZ683=357032270=10203.0271=5346=31023=1010=144
1128=99=25135=X49=SAMPLE75=2016101134=245752=2002072121212080514697660=200207212121208051469765799=10000100268=2279=1269=148=17359555=6SZ683=357033270=10215.0271=4346=21023=3279=1269=148=17359555=6SZ683=357034270=10216.0271=6346=41023=410=134
1128=99=18035=X49=SAMPLE75=2016101134=89952=2012060400450793762656060=201206040045079376265605799=10000100268=1279=1269=048=17359555=6SZ683=357035270=10212.0271=3346=31023=110=094
1128=99=18035=X49=SAMPLE75=2016101134=232452=2011112108471790397433660=201111210847179039743365799=10000100268=1279=1269=048=17359555=6SZ683=357036270=10212.0271=4346=41023=110=101
1128=99=23335=X49=SAMPLE75=2016101134=26852=2015040109182072758124860=201504010918207275812485799=00000001268=1279=0269=248=17359555=6SZ683=357037270=10213.0271=14346=35797=137705=337=032=1437=032=1337=621180793659332=110=004
1128=99=15635=X49=SAMPLE75=2016101134=493852=2013100700391187437190460=201310070039118743719045799=00000010268=1279=0269=e48=17359555=6SZ683=357038271=5510=080
1128=99=25335=X49=SAMPLE75=2016101134=482052=2009040610305646137644860=200904061030564613764485799=10000100268=2279=2269=148=17359555=6SZ683=357039270=10213.0271=14346=21023=1279=0269=148=17359555=6SZ683=357040270=10223.0271=3346=11023=1010=214
1128=99=18035=X49=SAMPLE75=2016101134=272952=2006101921454037010678460=200610192145403701067845799=10000100268=1279=1269=048=17359555=6SZ683=357041270=10212.0271=5346=51023=110=089
1128=99=17935=X49=SAMPLE75=2016101134=404952=2003102415310550925688060=200310241531055092568805799=10000100268=1279=0269=048=17360055=6SH783=99229270=10266.0271=3346=11023=110=036
1128=99=25035=X49=SAMPLE75=2016101134=181652=2015060314150400964000060=201506031415040096400005799=10000100268=2279=2269=148=17360055=6SH783=99230270=10269.0271=3346=11023=1279=0269=148=17360055=6SH783=99231270=10279.0271=3346=11023=1010=044
1128=99=18035=X49=SAMPLE75=2016101134=279052=2014072018040793595712060=201407201804079359571205799=10000100268=1279=1269=048=17359555=6SZ683=357042270=10212.0271=6346=61023=110=093
1128=99=18035=X49=SAMPLE75=2016101134=438652=2008072604392921218627260=200807260439292121862725799=10000100268=1279=1269=148=17359555=6SZ683=357043270=10214.0271=7346=51023=110=095
1128=99=18035=X49=SAMPLE75=2016101134=486252=2013100521113161630585660=201310052111316163058565799=10000100268=1279=1269=048=17359555=6SZ683=357044270=10212.0271=7346=71023=110=105
1128=99=18035=X49=SAMPLE75=2016101134=430552=2009120408165209925305660=200912040816520992530565799=10000100268=1279=1269=048=17359555=6SZ683=357045270=10212.0271=8346=81023=110=088
1128=99=18035=X49=SAMPLE75=2016101134=337252=2000022020303230931864360=200002202030323093186435799=10000100268=1279=1269=148=17359555=6SZ683=357046270=10214.0271=8346=61023=110=085
1128=99=18035=X49=SAMPLE75=2016101134=192252=2017031513164428415123260=201703151316442841512325799=10000100268=1279=1269=148=17359555=6SZ683=357047270=10214.0271=9346=71023=110=094
1128=99=18035=X49=SAMPLE75=2016101134=288952=2003031003592415277512060=200303100359241527751205799=10000100268=1279=1269=048=17359555=6SZ683=357048270=10211.0271=5346=41023=210=097
1128=99=18035=X49=SAMPLE75=2016101134=411252=2010010402535390632448060=201001040253539063244805799=10000100268=1279=1269=148=17359555=6SZ683=357049270=10215.0271=5346=31023=210=100
1128=99=18035=X49=SAMPLE75=2016101134=67752=2006021601052246533846460=200602160105224653384645799=10000100268=1279=1269=048=17359555=6SZ683=357050270=10211.0271=6346=51023=210=086
1128=99=18035=X49=SAMPLE75=2016101134=239752=2000072019463579709208260=200007201946357970920825799=10000100268=1279=1269=148=17359555=6SZ683=357051270=10215.0271=6346=41023=210=103
1128=99=18035=X49=SAMPLE75=2016101134=69452=2005122518175302470000060=200512251817530247000005799=10000100268=1279=1269=048=17359555=6SZ683=357052270=10212.0271=9346=91023=110=091
1128=99=18135=X49=SAMPLE75=2016101134=418252=2006100102432421151638460=200610010243242115163845799=10000100268=1279=1269=148=17359555=6SZ683=357053270=10214.0271=10346=81023=110=121
1128=99=18035=X49=SAMPLE75=2016101134=81452=2000042003511677740534060=200004200351167774053405799=10000100268=1279=1269=048=17359555=6SZ683=357054270=10211.0271=7346=61023=210=084
1128=99=18035=X49=SAMPLE75=2016101134=318752=2001031411493525971288060=200103141149352597128805799=10000100268=1279=1269=148=17359555=6SZ683=357055270=10215.0271=7346=51023=210=091
1128=99=17935=X49=SAMPLE75=2016101134=414252=2012080713330025446380860=201208071333002544638085799=10000100268=1279=0269=048=17360055=6SH783=99232270=10265.0271=3346=11023=210=024
1128=99=18235=X49=SAMPLE75=2016101134=92152=2000031017400325120838060=200003101740032512083805799=10000100268=1279=1269=048=17359555=6SZ683=357056270=10212.0271=10346=101023=110=159
1128=99=24935=X49=SAMPLE75=2016101134=494752=2012051702024096575404860=201205170202409657540485799=10000100268=2279=1269=048=17360055=6SH783=99233270=10264.0271=5346=21023=3279=1269=048=17360055=6SH783=99234270=10262.0271=3346=11023=510=003
1128=99=25335=X49=SAMPLE75=2016101134=364652=2003090221234210561942460=200309022123421056194245799=10000100268=2279=1269=048=17359555=6SZ683=357057270=10212.0271=11346=111023=1279=1269=048=17359555=6SZ683=357058270=10208.0271=5346=31023=510=235
1128=99=18035=X49=SAMPLE75=2016101134=16352=2009100621120785901619260=200910062112078590161925799=10000100268=1279=1269=148=17359555=6SZ683=357059270=10214.0271=7346=71023=110=086
1128=99=18035=X49=SAMPLE75=2016101134=31452=2013082803082865951180860=201308280308286595118085799=10000100268=1279=1269=048=17359555=6SZ683=357060270=10210.0271=6346=41023=310=081
1128=99=18035=X49=SAMPLE75=2016101134=343852=2002070406281449970209660=200207040628144997020965799=10000100268=1279=1269=148=17359555=6SZ683=357061270=10216.0271=7346=51023=310=095
1128=99=18035=X49=SAMPLE75=2016101134=370252=2001101422475335730612860=200110142247533573061285799=10000100268=1279=1269=048=17359555=6SZ683=357062270=10210.0271=7346=51023=310=086
1128=99=18035=X49=SAMPLE75=2016101134=346652=2007110701152231768944060=200711070115223176894405799=10000100268=1279=1269=148=17359555=6SZ683=357063270=10216.0271=8346=61023=310=079
1128=99=18035=X49=SAMPLE75=2016101134=332652=2013022210132278080416060=201302221013227808041605799=10000100268=1279=1269=048=17359555=6SZ683=357064270=10210.0271=8346=61023=310=090
1128=99=18035=X49=SAMPLE75=2016101134=27452=2013091920212284602579260=201309192021228460257925799=10000100268=1279=1269=148=17359555=6SZ683=357065270=10216.0271=9346=71023=310=106
1128=99=18035=X49=SAMPLE75=2016101134=296752=2015060604444048381856060=201506060444404838185605799=10000100268=1279=1269=048=17359555=6SZ683=357066270=10209.0271=9346=51023=410=104
1128=99=18035=X49=SAMPLE75=2016101134=148152=2007020209203838509308860=200702020920383850930885799=10000100268=1279=1269=148=17359555=6SZ683=357067270=10217.0271=5346=31023=410=099
1128=99=18135=X49=SAMPLE75=2016101134=60452=2010042323332812490976060=201004232333281249097605799=10000100268=1279=1269=048=17359555=6SZ683=357068270=10209.0271=10346=61023=410=159
1128=99=18035=X49=SAMPLE75=2016101134=163852=2012100621191526471340860=201210062119152647134085799=10000100268=1279=1269=148=17359555=6SZ683=357069270=10217.0271=6346=41023=410=097
1128=99=18135=X49=SAMPLE75=2016101134=139552=2007071402423469237264060=200707140242346923726405799=10000100268=1279=1269=048=17359555=6SZ683=357070270=10209.0271=11346=71023=410=126
1128=99=18035=X49=SAMPLE75=2016101134=470752=2015081108432683833523260=201508110843268383352325799=10000100268=1279=1269=148=17359555=6SZ683=357071270=10217.0271=7346=51023=410=093
1128=99=25035=X49=SAMPLE75=2016101134=97852=2010102308333329542732860=201010230833332954273285799=10000100268=2279=2269=048=17360055=6SH783=99235270=10266.0271=3346=11023=1279=0269=048=17360055=6SH783=99236270=10256.0271=3346=11023=1010=023
1128=99=18035=X49=SAMPLE75=2016101134=78452=2006050107462042409190460=200605010746204240919045799=10000100268=1279=1269=048=17359555=6SZ683=357072270=10208.0271=6346=41023=510=095
1128=99=18035=X49=SAMPLE75=2016101134=50552=2015122022075159846438460=201512202207515984643845799=10000100268=1279=1269=148=17359555=6SZ683=357073270=10218.0271=5346=31023=510=090
1128=99=18035=X49=SAMPLE75=2016101134=180252=2003070622141076018499260=200307062214107601849925799=10000100268=1279=1269=048=17359555=6SZ683=357074270=10208.0271=7346=51023=510=078
1128=99=18035=X49=SAMPLE75=2016101134=181552=2002012305281757507018460=200201230528175750701845799=10000100268=1279=1269=148=17359555=6SZ683=357075270=10218.0271=6346=41023=510=098
1128=99=18035=X49=SAMPLE75=2016101134=116252=2000042514023048748384660=200004251402304874838465799=10000100268=1279=1269=048=17359555=6SZ683=357076270=10208.0271=8346=61023=510=086
1128=99=18035=X49=SAMPLE75=2016101134=232552=2007050701383198084172860=200705070138319808417285799=10000100268=1279=1269=148=17359555=6SZ683=357077270=10218.0271=7346=51023=510=093
1128=99=18035=X49=SAMPLE75=2016101134=416052=2007010306371794352992060=200701030637179435299205799=10000100268=1279=0269=048=17359555=6SZ683=357078270=10213.0271=1346=11023=110=075
1128=99=17935=X49=SAMPLE75=2016101134=489552=2011050521394155442739260=201105052139415544273925799=10000100268=1279=0269=048=17360055=6SH783=99237270=10266.0271=3346=11023=110=005
1128=99=24735=X49=SAMPLE75=2016101134=24252=2012112008333004159232060=201211200833300415923205799=10000100268=2279=0269=048=17360355=6SM783=7543270=10282.0271=6346=11023=4279=2269=048=17360355=6SM783=7544270=10281.0271=6346=11023=510=150
1128=99=18035=X49=SAMPLE75=2016101134=115652=2007022813261849159158460=200702281326184915915845799=10000100268=1279=1269=148=17359555=6SZ683=357079270=10214.0271=6346=61023=110=103
1128=99=18035=X49=SAMPLE75=2016101134=1352=2003060522051244639558460=200306052205124463955845799=10000100268=1279=1269=148=17359555=6SZ683=357080270=10214.0271=5346=51023=110=090
1128=99=18035=X49=SAMPLE75=2016101134=345652=2011111403513036104774460=201111140351303610477445799=10000100268=1279=1269=048=17359555=6SZ683=357081270=10213.0271=2346=21023=110=066
1128=99=18135=X49=SAMPLE75=2016101134=460252=2003012119454699386940860=200301211945469938694085799=10000100268=1279=1269=048=17359555=6SZ683=357082270=10204.0271=3346=11023=1010=109
1128=99=18035=X49=SAMPLE75=2016101134=196852=2016020210372370847820860=201602021037237084782085799=10000100268=1279=1269=048=17359555=6SZ683=357083270=10211.0271=8346=71023=310=105
1128=99=18035=X49=SAMPLE75=2016101134=383652=2000042102345850666330660=200004210234585066633065799=10000100268=1279=1269=048=17359555=6SZ683=357084270=10213.0271=3346=31023=110=090
1128=99=18035=X49=SAMPLE75=2016101134=420352=2012050108034032423078460=201205010803403242307845799=10000100268=1279=1269=048=17359555=6SZ683=357085270=10213.0271=4346=41023=110=095
1128=99=18035=X49=SAMPLE75=2016101134=316452=2001080921445048565595260=200108092144504856559525799=10000100268=1279=1269=148=17359555=6SZ683=357086270=10214.0271=4346=41023=110=086
1128=99=17935=X49=SAMPLE75=2016101134=50952=2005022423082838621865660=200502242308283862186565799=10000100268=1279=1269=148=17360055=6SH783=99238270=10270.0271=2346=11023=110=016
1128=99=18035=X49=SAMPLE75=2016101134=85352=2015031200485628951283260=201503120048562895128325799=10000100268=1279=1269=048=17359555=6SZ683=357087270=10213.0271=5346=51023=110=086
1128=99=32135=X49=SAMPLE75=2016101134=217252=2015121006172675320640060=201512100617267532064005799=10000100268=3279=2269=148=17360055=6SH783=99239270=10270.0271=2346=11023=1279=1269=148=17360055=6SH783=99240270=10273.0271=5346=21023=3279=0269=148=17360055=6SH783=99241270=10280.0271=53346=11023=1010=049
1128=99=25035=X49=SAMPLE75=2016101134=49952=2002101020151907675446460=200210102015190767544645799=10000100268=2279=2269=048=17360055=6SH783=99242270=10266.0271=3346=11023=1279=0269=048=17360055=6SH783=99243270=10256.0271=3346=11023=1010=026
1128=99=18135=X49=SAMPLE75=2016101134=155752=2010051012473475713996860=201005101247347571399685799=10000100268=1279=1269=148=17359555=6SZ683=357088270=10219.0271=11346=51023=610=149
1128=99=25335=X49=SAMPLE75=2016101134=46752=2000112503403082541079260=200011250340308254107925799=10000100268=2279=1269=048=17359555=6SZ683=357089270=10213.0271=6346=61023=1279=1269=048=17359555=6SZ683=357090270=10212.0271=10346=101023=210=228
1128=99=17935=X49=SAMPLE75=2016101134=267452=2012050504041858205318460=201205050404185820531845799=10000100268=1279=0269=048=17360055=6SH783=99244270=10266.0271=3346=11023=110=035
1128=99=24935=X49=SAMPLE75=2016101134=73452=2004042913104672758035260=200404291310467275803525799=10000100268=2279=1269=048=17360055=6SH783=99245270=10265.0271=5346=21023=2279=1269=048=17360055=6SH783=99246270=10263.0271=3346=11023=410=005
1128=99=18035=X49=SAMPLE75=2016101134=193952=2008111520551069395766460=200811152055106939576645799=10000100268=1279=1269=148=17359555=6SZ683=357091270=10214.0271=3346=31023=110=057
1128=99=18035=X49=SAMPLE75=2016101134=6052=2011072209393754448006460=201107220939375444800645799=10000100268=1279=1269=148=17359555=6SZ683=357092270=10214.0271=2346=21023=110=084
1128=99=18035=X49=SAMPLE75=2016101134=96252=2015092914250171824537660=201509291425017182453765799=10000100268=1279=1269=148=17359555=6SZ683=357093270=10214.0271=1346=11023=110=079
1128=99=18135=X49=SAMPLE75=2016101134=399852=2014061015402255803667260=201406101540225580366725799=10000100268=1279=1269=148=17359555=6SZ683=357094270=10219.0271=12346=61023=610=135
1128=99=22035=X49=SAMPLE75=2016101134=90052=2010080202445599611385660=201008020244559961138565799=00000001268=1279=0269=248=17359555=6SZ683=357095270=10214.0271=1346=25797=137705=237=032=137=621180793707432=110=194
1128=99=15635=X49=SAMPLE75=2016101134=431752=2003092920285580488692860=200309292028558048869285799=00000010268=1279=0269=e48=17359555=6SZ683=357096271=5610=104
1128=99=25235=X49=SAMPLE75=2016101134=94552=2007120606124942124390460=200712060612494212439045799=10000100268=2279=2269=148=17359555=6SZ683=357097270=10214.0271=1346=11023=1279=0269=148=17359555=6SZ683=357098270=10224.0271=1346=11023=1010=196
1128=99=17935=X49=SAMPLE75=2016101134=104352=2012010519590313913369660=201201051959031391336965799=00000100268=1279=0269=048=17360055=6SH783=99247270=10267.0271=3346=11023=110=019
1128=99=16835=X49=SAMPLE75=2016101134=197552=2006121402583533469468860=200612140258353346946885799=10001000268=1279=0269=N48=17360055=6SH783=99248270=10267.0286=25510=095
1128=99=18135=X49=SAMPLE75=2016101134=325652=2010072108041307017619260=201007210804130701761925799=10000100268=1279=1269=148=17359555=6SZ683=357099270=10219.0271=13346=71023=510=145
1128=99=18035=X49=SAMPLE75=2016101134=251852=2014051210380062801702460=201405121038006280170245799=10000100268=1279=1269=148=17359555=6SZ683=357100270=10215.0271=8346=61023=110=083
1128=99=18035=X49=SAMPLE75=2016101134=333352=2012080823311749895616060=201208082331174989561605799=10000100268=1279=1269=048=17359555=6SZ683=357101270=10213.0271=7346=71023=110=108
1128=99=18035=X49=SAMPLE75=2016101134=59352=2014060315025682662227260=201406031502568266222725799=10000100268=1279=1269=148=17359555=6SZ683=357102270=10215.0271=9346=71023=110=089
1128=99=25035=X49=SAMPLE75=2016101134=485152=2015062118251956762528060=201506211825195676252805799=10000100268=2279=2269=048=17360055=6SH783=99249270=10267.0271=3346=11023=1279=0269=048=17360055=6SH783=99250270=10257.0271=3346=11023=1010=040
1128=99=18135=X49=SAMPLE75=2016101134=155352=2001071913344434794896860=200107191334443479489685799=10000100268=1279=1269=148=17359555=6SZ683=357103270=10215.0271=10346=81023=110=126
1128=99=18035=X49=SAMPLE75=2016101134=375052=2015011322325215422176060=201501132232521542217605799=10000100268=1279=1269=148=17359555=6SZ683=357104270=10215.0271=9346=71023=110=101
1128=99=18135=X49=SAMPLE75=2016101134=213252=2000121215074195341940460=200012121507419534194045799=10000100268=1279=1269=148=17359555=6SZ683=357105270=10223.0271=10346=21023=910=156
1128=99=18135=X49=SAMPLE75=2016101134=453552=2000030316500300494904760=200003031650030049490475799=10000100268=1279=1269=148=17359555=6SZ683=357106270=10224.0271=8346=21023=1010=133
1128=99=18035=X49=SAMPLE75=2016101134=321352=2013110302050468499814460=201311030205046849981445799=10000100268=1279=1269=148=17359555=6SZ683=357107270=10215.0271=8346=61023=110=086
1128=99=18035=X49=SAMPLE75=2016101134=5452=2006011608380816557936060=200601160838081655793605799=10000100268=1279=1269=148=17359555=6SZ683=357108270=10216.0271=8346=61023=210=101
1128=99=18035=X49=SAMPLE75=2016101134=162752=2008032605201375838992060=200803260520137583899205799=10000100268=1279=1269=148=17359555=6SZ683=357109270=10220.0271=5346=31023=610=089
1128=99=18235=X49=SAMPLE75=2016101134=78052=2001011711350723001272060=200101171135072300127205799=10000100268=1279=1269=048=17359555=6SZ683=357110270=10212.0271=13346=111023=210=177
1128=99=18035=X49=SAMPLE75=2016101134=325252=2004112102282663471798460=200411210228266347179845799=10000100268=1279=1269=048=17359555=6SZ683=357111270=10211.0271=7346=61023=310=095
1128=99=18035=X49=SAMPLE75=2016101134=249152=2012070406261803752326460=201207040626180375232645799=10000100268=1279=1269=048=17359555=6SZ683=357112270=10213.0271=8346=81023=110=090
1128=99=18035=X49=SAMPLE75=2016101134=25552=2008072900133333633584060=200807290013333363358405799=10000100268=1279=1269=148=17359555=6SZ683=357113270=10221.0271=7346=31023=710=083
1128=99=18035=X49=SAMPLE75=2016101134=365752=2009050317311091622720060=200905031731109162272005799=00000100268=1279=0269=048=17359555=6SZ683=357114270=10214.0271=1346=11023=110=109
1128=99=16935=X49=SAMPLE75=2016101134=423552=2016122913105812447769660=201612291310581244776965799=10001000268=1279=0269=N48=17359555=6SZ683=357115270=10214.0286=25510=196
1128=99=17935=X49=SAMPLE75=2016101134=386752=2008080820290645614988860=200808082029064561498885799=10000100268=1279=0269=048=17360055=6SH783=99251270=10267.0271=3346=11023=110=025
1128=99=24735=X49=SAMPLE75=2016101134=397252=2013120215375829236281660=201312021537582923628165799=10000100268=2279=0269=048=17360355=6SM783=7545270=10283.0271=6346=11023=4279=2269=048=17360355=6SM783=7546270=10282.0271=6346=11023=510=158
1128=99=18035=X49=SAMPLE75=2016101134=124952=2004041511343026336862460=200404151134302633686245799=10000100268=1279=1269=148=17359555=6SZ683=357116270=10215.0271=7346=51023=110=109
1128=99=18035=X49=SAMPLE75=2016101134=296352=2013080805101597749574460=201308080510159774957445799=10000100268=1279=1269=048=17359555=6SZ683=357117270=10214.0271=2346=21023=110=087
1128=99=18035=X49=SAMPLE75=2016101134=341052=2013031312295890121388860=201303131229589012138885799=10000100268=1279=1269=048=17359555=6SZ683=357118270=10214.0271=3346=31023=110=110
1128=99=18035=X49=SAMPLE75=2016101134=58852=2017022201042034008672060=201702220104203400867205799=10000100268=1279=1269=048=17359555=6SZ683=357119270=10214.0271=4346=41023=110=093
1128=99=18235=X49=SAMPLE75=2016101134=126152=2005052419340966423497660=200505241934096642349765799=10000100268=1279=1269=048=17359555=6SZ683=357120270=10205.0271=10346=41023=1010=173
1128=99=18235=X49=SAMPLE75=2016101134=497052=2006061404540996741776060=200606140454099674177605799=10000100268=1279=1269=048=17359555=6SZ683=357121270=10212.0271=14346=121023=310=157
1128=99=18035=X49=SAMPLE75=2016101134=174152=2006083012052751942256060=200608301205275194225605799=10000100268=1279=1269=048=17359555=6SZ683=357122270=10214.0271=5346=51023=110=086
1128=99=25035=X49=SAMPLE75=2016101134=429552=2009091521071096877644860=200909152107109687764485799=10000100268=2279=2269=048=17360055=6SH783=99252270=10267.0271=3346=11023=1279=0269=048=17360055=6SH783=99253270=10257.0271=3346=11023=1010=031
1128=99=18035=X49=SAMPLE75=2016101134=26852=2015060304453049030675260=201506030445304903067525799=10000100268=1279=1269=148=17359555=6SZ683=357123270=10215.0271=6346=41023=110=087
1128=99=18035=X49=SAMPLE75=2016101134=263552=2012012811430755489740860=201201281143075548974085799=10000100268=1279=1269=148=17359555=6SZ683=357124270=10220.0271=6346=41023=610=092
1128=99=18035=X49=SAMPLE75=2016101134=237952=2006112204024724287033660=200611220402472428703365799=10000100268=1279=1269=148=17359555=6SZ683=357125270=10215.0271=5346=31023=110=074
1128=99=17935=X49=SAMPLE75=2016101134=478652=2005122214071223143241660=200512221407122314324165799=10000100268=1279=1269=148=17360055=6SH783=99254270=10271.0271=2346=11023=110=020
1128=99=32035=X49=SAMPLE75=2016101134=370652=2009072102503283090899260=200907210250328309089925799=10000100268=3279=2269=148=17360055=6SH783=99255270=10271.0271=2346=11023=1279=1269=148=17360055=6SH783=99256270=10274.0271=5346=21023=3279=0269=148=17360055=6SH783=99257270=10281.0271=3346=11023=1010=246
1128=99=18035=X49=SAMPLE75=2016101134=40852=2010051000070014851136060=201005100007001485113605799=10000100268=1279=1269=148=17359555=6SZ683=357126270=10220.0271=7346=51023=610=092
1128=99=20835=X49=SAMPLE75=2016101134=210252=2009032104083791048044860=200903210408379104804485799=00000001268=1279=0269=248=17359555=6SZ683=357127270=10214.0271=1346=25797=237705=237=032=137=032=110=056
1128=99=15635=X49=SAMPLE75=2016101134=387452=2015072203155694579532860=201507220315569457953285799=00000010268=1279=0269=e48=17359555=6SZ683=357128271=5710=089
1128=99=18035=X49=SAMPLE75=2016101134=460252=2010022107245233400908860=201002210724523340090885799=10000100268=1279=1269=048=17359555=6SZ683=357129270=10214.0271=4346=41023=110=093
1128=99=18035=X49=SAMPLE75=2016101134=123752=2000103016594952207865660=200010301659495220786565799=10000100268=1279=1269=148=17359555=6SZ683=357130270=10215.0271=6346=41023=110=083
1128=99=17935=X49=SAMPLE75=2016101134=432852=2008080904334460187356860=200808090433446018735685799=10000100268=1279=0269=148=17360055=6SH783=99258270=10271.0271=3346=11023=110=024
1128=99=24935=X49=SAMPLE75=2016101134=261652=2002012310254649953275260=200201231025464995327525799=10000100268=2279=1269=148=17360055=6SH783=99259270=10272.0271=5346=21023=2279=1269=148=17360055=6SH783=99260270=10274.0271=3346=11023=410=009
1128=99=18035=X49=SAMPLE75=2016101134=171352=2014082823442056623737660=201408282344205662373765799=10000100268=1279=1269=148=17359555=6SZ683=357131270=10215.0271=3346=31023=110=092
1128=99=25035=X49=SAMPLE75=2016101134=40852=2004082308154159891929660=200408230815415989192965799=10000100268=2279=2269=148=17360055=6SH783=99261270=10271.0271=3346=11023=1279=0269=148=17360055=6SH783=99262270=10281.0271=3346=11023=1010=027
1128=99=18035=X49=SAMPLE75=2016101134=136252=2003040914283526693998460=200304091428352669399845799=10000100268=1279=1269=148=17359555=6SZ683=357132270=10215.0271=4346=41023=110=095
1128=99=18035=X49=SAMPLE75=2016101134=132052=2007061018395523358614460=200706101839552335861445799=10000100268=1279=1269=048=17359555=6SZ683=357133270=10214.0271=3346=31023=110=088
1128=99=18035=X49=SAMPLE75=2016101134=63052=2009021408151937623219260=200902140815193762321925799=10000100268=1279=1269=048=17359555=6SZ683=357134270=10214.0271=2346=21023=110=111
1128=99=24235=X49=SAMPLE75=2016101134=343552=2003102512420484278049660=200310251242048427804965799=00000001268=1279=0269=248=17359555=6SZ683=357135270=10214.0271=2346=35797=237705=337=032=237=621180793728532=137=621180793728632=110=221
1128=99=15635=X49=SAMPLE75=2016101134=129952=2010041607180606903526460=201004160718060690352645799=00000010268=1279=0269=e48=17359555=6SZ683=357136271=5910=100
1128=99=25235=X49=SAMPLE75=2016101134=427152=2008121017441718760336060=200812101744171876033605799=10000100268=2279=2269=048=17359555=6SZ683=357137270=10214.0271=2346=21023=1279=0269=048=17359555=6SZ683=357138270=10204.0271=3346=11023=1010=184
1128=99=18035=X49=SAMPLE75=2016101134=164552=2012040608000098005491260=201204060800009800549125799=10000100268=1279=0269=048=17359555=6SZ683=357139270=10214.0271=1346=11023=110=107
1128=99=17935=X49=SAMPLE75=2016101134=372352=2014053121595294893888060=201405312159529489388805799=10000100268=1279=0269=148=17360055=6SH783=99263270=10270.0271=3346=11023=110=043
1128=99=18035=X49=SAMPLE75=2016101134=415452=2009122903240308057292860=200912290324030805729285799=10000100268=1279=1269=148=17359555=6SZ683=357140270=10215.0271=5346=51023=110=110
1128=99=17935=X49=SAMPLE75=2016101134=271352=2010122907430596053497660=201012290743059605349765799=10000100268=1279=0269=148=17360055=6SH783=99264270=10271.0271=3346=11023=210=034
1128=99=25135=X49=SAMPLE75=2016101134=111852=2011080623472462516096060=201108062347246251609605799=10000100268=2279=2269=148=17360055=6SH783=99265270=10270.0271=3346=11023=1279=0269=148=17360055=6SH783=99266270=10280.0271=53346=11023=1010=100
1128=99=22035=X49=SAMPLE75=2016101134=487952=2004043015253059889736060=200404301525305988973605799=00000001268=1279=0269=248=17359555=6SZ683=357141270=10214.0271=1346=25797=237705=237=032=137=621180793730132=110=187
1128=99=15635=X49=SAMPLE75=2016101134=129652=2001101520104245004961660=200110152010424500496165799=00000010268=1279=0269=e48=17359555=6SZ683=357142271=6010=111
1128=99=25235=X49=SAMPLE75=2016101134=245752=2006051614512782178652860=200605161451278217865285799=10000100268=2279=2269=048=17359555=6SZ683=357143270=10214.0271=1346=11023=1279=0269=048=17359555=6SZ683=357144270=10204.0271=3346=11023=1010=198
1128=99=25035=X49=SAMPLE75=2016101134=282352=2001032710100274283028060=200103271010027428302805799=10000100268=2279=2269=148=17360055=6SH783=99267270=10271.0271=3346=11023=1279=0269=148=17360055=6SH783=99268270=10281.0271=3346=11023=1010=046
1128=99=18035=X49=SAMPLE75=2016101134=445352=2015031623441888392608060=201503162344188839260805799=10000100268=1279=1269=148=17359555=6SZ683=357145270=10223.0271=3346=11023=910=131
1128=99=18135=X49=SAMPLE75=2016101134=278952=2008021404441344287139260=200802140444134428713925799=10000100268=1279=1269=148=17359555=6SZ683=357146270=10224.0271=1346=11023=1010=181
1128=99=18135=X49=SAMPLE75=2016101134=153252=2011013021201690632147260=201101302120169063214725799=10000100268=1279=1269=148=17359555=6SZ683=357147270=10223.0271=10346=21023=910=138
1128=99=18135=X49=SAMPLE75=2016101134=98052=2006041804011791738201660=200604180401179173820165799=10000100268=1279=1269=148=17359555=6SZ683=357148270=10224.0271=8346=21023=1010=154
1128=99=18235=X49=SAMPLE75=2016101134=475552=2016052823564095321568060=201605282356409532156805799=10000100268=1279=1269=048=17359555=6SZ683=357149270=10212.0271=13346=111023=210=206
1128=99=18135=X49=SAMPLE75=2016101134=440852=2008080708491620397475260=200808070849162039747525799=10000100268=1279=1269=048=17359555=6SZ683=357150270=10205.0271=11346=51023=910=166
1128=99=18235=X49=SAMPLE75=2016101134=263452=2004022806180407453603260=200402280618040745360325799=10000100268=1279=1269=048=17359555=6SZ683=357151270=10212.0271=12346=101023=210=196
1128=99=18035=X49=SAMPLE75=2016101134=145752=2009120306281882941024060=200912030628188294102405799=10000100268=1279=1269=148=17359555=6SZ683=357152270=10216.0271=9346=71023=210=105
1128=99=18135=X49=SAMPLE75=2016101134=211052=2000120512510455764502060=200012051251045576450205799=10000100268=1279=1269=048=17359555=6SZ683=357153270=10213.0271=11346=91023=110=156
1128=99=18135=X49=SAMPLE75=2016101134=29152=2015110912245925257516860=201511091224592525751685799=10000100268=1279=1269=048=17359555=6SZ683=357154270=10212.0271=11346=91023=210=135
1128=99=18135=X49=SAMPLE75=2016101134=411452=2015022000503020515072060=201502200050302051507205799=10000100268=1279=1269=048=17359555=6SZ683=357155270=10212.0271=10346=81023=210=150
1128=99=18035=X49=SAMPLE75=2016101134=490552=2000082919132259627672060=200008291913225962767205799=10000100268=1279=1269=048=17359555=6SZ683=357156270=10207.0271=6346=41023=710=092
1128=99=18035=X49=SAMPLE75=2016101134=349452=2000030904032288973572760=200003090403228897357275799=10000100268=1279=1269=048=17359555=6SZ683=357157270=10206.0271=5346=31023=810=108
1128=99=18035=X49=SAMPLE75=2016101134=487352=2009071901333859543776060=200907190133385954377605799=10000100268=1279=1269=148=17359555=6SZ683=357158270=10215.0271=4346=41023=110=121
1128=99=18035=X49=SAMPLE75=2016101134=40052=2006021905045939388678460=200602190504593938867845799=10000100268=1279=0269=048=17359555=6SZ683=357159270=10214.0271=1346=11023=110=109
1128=99=25235=X49=SAMPLE75=2016101134=459752=2007080521371352062662460=200708052137135206266245799=10000100268=2279=1269=048=17359555=6SZ683=357160270=10210.0271=11346=71023=5279=1269=048=17359555=6SZ683=357161270=10209.0271=8346=61023=610=215
1128=99=17935=X49=SAMPLE75=2016101134=62052=2015111703120858178048060=201511170312085817804805799=10000100268=1279=0269=048=17360055=6SH783=99269270=10267.0271=3346=11023=110=062
1128=99=18035=X49=SAMPLE75=2016101134=63252=2010071010220899691609660=201007101022089969160965799=10000100268=1279=1269=148=17359555=6SZ683=357162270=10215.0271=3346=31023=110=106
1128=99=18035=X49=SAMPLE75=2016101134=91052=2008100115322526587910460=200810011532252658791045799=10000100268=1279=1269=048=17359555=6SZ683=357163270=10214.0271=2346=21023=110=112
1128=99=18035=X49=SAMPLE75=2016101134=27252=2016092303362024863091260=201609230336202486309125799=10000100268=1279=1269=048=17359555=6SZ683=357164270=10214.0271=3346=31023=110=129
1128=99=18035=X49=SAMPLE75=2016101134=357252=2014100614293774448915260=201410061429377444891525799=10000100268=1279=1269=048=17359555=6SZ683=357165270=10214.0271=4346=41023=110=111
1128=99=18035=X49=SAMPLE75=2016101134=225952=2002101016155131262067260=200210101615513126206725799=10000100268=1279=1269=148=17359555=6SZ683=357166270=10215.0271=4346=41023=110=120
1128=99=18235=X49=SAMPLE75=2016101134=72352=2010112104485729567315260=201011210448572956731525799=10000100268=1279=1269=048=17359555=6SZ683=357167270=10205.0271=10346=41023=1010=222
1128=99=18135=X49=SAMPLE75=2016101134=292152=2000031718135734453549160=200003171813573445354915799=10000100268=1279=1269=048=17359555=6SZ683=357168270=10212.0271=11346=91023=310=182
1128=99=18035=X49=SAMPLE75=2016101134=247852=2001081922223625303660060=200108192222362530366005799=10000100268=1279=1269=048=17359555=6SZ683=357169270=10214.0271=5346=51023=110=146
1128=99=18035=X49=SAMPLE75=2016101134=487452=2015101723034720143699260=201510172303472014369925799=10000100268=1279=1269=148=17359555=6SZ683=357170270=10215.0271=3346=31023=110=105
1128=99=18035=X49=SAMPLE75=2016101134=358852=2005061022013342787241660=200506102201334278724165799=10000100268=1279=1269=148=17359555=6SZ683=357171270=10215.0271=2346=21023=110=106
1128=99=18035=X49=SAMPLE75=2016101134=138752=2013042816353763949696060=201304281635376394969605799=10000100268=1279=1269=148=17359555=6SZ683=357172270=10215.0271=1346=11023=110=135
1128=99=25035=X49=SAMPLE75=2016101134=97952=2014123001191931351276860=201412300119193135127685799=10000100268=2279=2269=048=17360055=6SH783=99270270=10267.0271=3346=11023=1279=0269=048=17360055=6SH783=99271270=10257.0271=3346=11023=1010=072
1128=99=25335=X49=SAMPLE75=2016101134=9252=2012030200192769726470460=201203020019276972647045799=10000100268=2279=2269=148=17359555=6SZ683=357173270=10215.0271=1346=11023=1279=0269=148=17359555=6SZ683=357174270=10225.0271=15346=21023=1010=012
1128=99=18035=X49=SAMPLE75=2016101134=453652=2014050607513987876915260=201405060751398787691525799=10000100268=1279=1269=148=17359555=6SZ683=357175270=10220.0271=8346=61023=510=109
1128=99=18035=X49=SAMPLE75=2016101134=454852=2009062501392945477004860=200906250139294547700485799=10000100268=1279=1269=048=17359555=6SZ683=357176270=10214.0271=6346=61023=110=117
1128=99=18135=X49=SAMPLE75=2016101134=217552=2012060616103371093683260=201206061610337109368325799=10000100268=1279=1269=148=17359555=6SZ683=357177270=10216.0271=10346=81023=110=176
1128=99=18035=X49=SAMPLE75=2016101134=151552=2006030521264453804390460=200603052126445380439045799=00000100268=1279=0269=048=17359555=6SZ683=357178270=10215.0271=1346=11023=110=125
1128=99=16935=X49=SAMPLE75=2016101134=191452=2001032614154420476993660=200103261415442047699365799=10001000268=1279=0269=N48=17359555=6SZ683=357179270=10215.0286=25510=212
1128=99=17935=X49=SAMPLE75=2016101134=229752=2008092419472263249184060=200809241947226324918405799=10000100268=1279=1269=148=17360055=6SH783=99272270=10280.0271=3346=11023=910=076
1128=99=18135=X49=SAMPLE75=2016101134=64152=2016042512364959689216060=201604251236495968921605799=10000100268=1279=1269=148=17359555=6SZ683=357180270=10216.0271=11346=91023=110=166
1128=99=18035=X49=SAMPLE75=2016101134=163052=2014110202412677106041660=201411020241267710604165799=10000100268=1279=1269=148=17359555=6SZ683=357181270=10217.0271=6346=41023=210=128
1128=99=18035=X49=SAMPLE75=2016101134=2152=2008110701200096299884860=200811070120009629988485799=10000100268=1279=1269=148=17359555=6SZ683=357182270=10222.0271=4346=21023=710=127
1128=99=25235=X49=SAMPLE75=2016101134=280952=2007101711401336302918460=200710171140133630291845799=10000100268=2279=1269=048=17359555=6SZ683=357183270=10214.0271=7346=71023=2279=1269=048=17359555=6SZ683=357184270=10213.0271=10346=81023=310=220
1128=99=25235=X49=SAMPLE75=2016101134=482752=2016091815330369188940860=201609181533036918894085799=10000100268=2279=1269=148=17359555=6SZ683=357185270=10216.0271=10346=81023=1279=1269=148=17359555=6SZ683=357186270=10217.0271=7346=51023=210=223
1128=99=25135=X49=SAMPLE75=2016101134=275352=2006070903454577266035260=200607090345457726603525799=10000100268=2279=1269=148=17359555=6SZ683=357187270=10221.0271=4346=21023=6279=1269=148=17359555=6SZ683=357188270=10222.0271=7346=31023=710=156
1128=99=18035=X49=SAMPLE75=2016101134=82752=2007120216040455338614460=200712021604045533861445799=10000100268=1279=1269=048=17359555=6SZ683=357189270=10214.0271=8346=81023=210=123
1128=99=17935=X49=SAMPLE75=2016101134=134352=2004022514253321548168060=200402251425332154816805799=10000100268=1279=0269=048=17360055=6SH783=99273270=10267.0271=3346=11023=110=042
1128=99=24935=X49=SAMPLE75=2016101134=240252=2015062900225015234432060=201506290022501523443205799=10000100268=2279=1269=048=17360055=6SH783=99274270=10266.0271=5346=21023=2279=1269=048=17360055=6SH783=99275270=10264.0271=3346=11023=410=006
1128=99=24735=X49=SAMPLE75=2016101134=337452=2002052823193024020675260=200205282319302402067525799=10000100268=2279=0269=048=17360355=6SM783=7547270=10284.0271=6346=11023=4279=2269=048=17360355=6SM783=7548270=10283.0271=6346=11023=510=189
1128=99=17935=X49=SAMPLE75=2016101134=362552=2010071906232439823833660=201007190623243982383365799=00000100268=1279=0269=048=17360355=6SM783=7549270=10308.0271=15346=11023=110=049
1128=99=16735=X49=SAMPLE75=2016101134=130152=2003083102315928684038460=200308310231592868403845799=10001000268=1279=0269=N48=17360355=6SM783=7550270=10308.0286=25510=064
1128=99=17935=X49=SAMPLE75=2016101134=37152=2001081310380460071301660=200108131038046007130165799=10000100268=1279=1269=048=17360355=6SM783=7551270=10304.0271=12346=21023=210=042
1128=99=17935=X49=SAMPLE75=2016101134=130852=2005090607591737412716860=200509060759173741271685799=10000100268=1279=2269=048=17360355=6SM783=7552270=10299.0271=10346=11023=310=059
1128=99=22035=X49=SAMPLE75=2016101134=362252=2001031523171489276552060=200103152317148927655205799=00000001268=1279=0269=248=17359555=6SZ683=357190270=10215.0271=1346=25797=237705=237=032=137=621180793857732=110=200
1128=99=15635=X49=SAMPLE75=2016101134=11052=2003101121463385911569660=200310112146338591156965799=00000010268=1279=0269=e48=17359555=6SZ683=357191271=6110=102
1128=99=25335=X49=SAMPLE75=2016101134=267752=2015041321425081922726460=201504132142508192272645799=00000100268=2279=2269=048=17359555=6SZ683=357192270=10215.0271=1346=11023=1279=0269=048=17359555=6SZ683=357193270=10205.0271=10346=41023=1010=243
1128=99=16935=X49=SAMPLE75=2016101134=5352=2005032022020579421529660=200503202202057942152965799=10001000268=1279=0269=748=17359555=6SZ683=357194270=10215.0286=25510=169
1128=99=18035=X49=SAMPLE75=2016101134=421352=2015100114371200188288060=201510011437120018828805799=10000100268=1279=1269=148=17359555=6SZ683=357195270=10216.0271=9346=71023=110=130
1128=99=25135=X49=SAMPLE75=2016101134=162752=2011103118540800254022460=201110311854080025402245799=10000100268=2279=0269=048=17359555=6SZ683=357196270=10215.0271=1346=11023=1279=1269=048=17359555=6SZ683=357197270=10214.0271=7346=71023=210=175
1128=99=25235=X49=SAMPLE75=2016101134=466452=2011031709113567636128060=201103170911356763612805799=10000100268=2279=1269=148=17359555=6SZ683=357198270=10220.0271=7346=51023=5279=1269=148=17359555=6SZ683=357199270=10223.0271=11346=31023=810=245
1128=99=24835=X49=SAMPLE75=2016101134=37752=2003100601404758593960060=200310060140475859396005799=00000100268=2279=0269=048=17360355=6SM783=7553270=10309.0271=2346=11023=1279=1269=048=17360355=6SM783=7554270=10304.0271=10346=11023=310=200
1128=99=16735=X49=SAMPLE75=2016101134=268952=2016041213071582386988860=201604121307158238698885799=10001000268=1279=0269=N48=17360355=6SM783=7555270=10309.0286=25510=061
1128=99=20835=X49=SAMPLE75=2016101134=61052=2009082820011054540684860=200908282001105454068485799=00000001268=1279=0269=248=17359555=6SZ683=357200270=10215.0271=1346=25797=237705=237=032=137=032=110=085
1128=99=15635=X49=SAMPLE75=2016101134=362752=2002092609070913699323260=200209260907091369932325799=00000010268=1279=0269=e48=17359555=6SZ683=357201271=6210=090
1128=99=25335=X49=SAMPLE75=2016101134=361052=2005091018403074862684860=200509101840307486268485799=10000100268=2279=2269=048=17359555=6SZ683=357202270=10215.0271=1346=11023=1279=0269=048=17359555=6SZ683=357203270=10205.0271=10346=41023=1010=223
1128=99=24935=X49=SAMPLE75=2016101134=83152=2001031019545163265534460=200103101954516326553445799=10000100268=2279=1269=048=17360355=6SM783=7556270=10309.0271=17346=21023=1279=2269=048=17360355=6SM783=7557270=10308.0271=15346=11023=210=029
1128=99=18035=X49=SAMPLE75=2016101134=462052=2010051812321832581388860=201005181232183258138885799=10000100268=1279=1269=148=17359555=6SZ683=357204270=10216.0271=8346=61023=110=138
1128=99=18035=X49=SAMPLE75=2016101134=116452=2004012314284750454611260=200401231428475045461125799=10000100268=1279=1269=148=17359555=6SZ683=357205270=10223.0271=4346=21023=810=133
1128=99=18135=X49=SAMPLE75=2016101134=404552=2001071003025840321909660=200107100302584032190965799=10000100268=1279=1269=148=17359555=6SZ683=357206270=10225.0271=8346=11023=1010=187
1128=99=18035=X49=SAMPLE75=2016101134=357352=2007030319195763462700860=200703031919576346270085799=10000100268=1279=1269=148=17359555=6SZ683=357207270=10224.0271=1346=11023=910=124
1128=99=18035=X49=SAMPLE75=2016101134=442752=2007072010160677509014460=200707201016067750901445799=10000100268=1279=1269=148=17359555=6SZ683=357208270=10216.0271=9346=71023=110=141
1128=99=18135=X49=SAMPLE75=2016101134=142552=2016102715224169589427260=201610271522416958942725799=10000100268=1279=1269=148=17359555=6SZ683=357209270=10223.0271=11346=31023=810=160
1128=99=18035=X49=SAMPLE75=2016101134=317152=2004070516590766998958460=200407051659076699895845799=10000100268=1279=1269=148=17359555=6SZ683=357210270=10224.0271=8346=21023=910=104
1128=99=18235=X49=SAMPLE75=2016101134=454952=2012010118453721663961660=201201011845372166396165799=10000100268=1279=1269=148=17359555=6SZ683=357211270=10225.0271=15346=21023=1010=204
1128=99=25135=X49=SAMPLE75=2016101134=345152=2002031610325031246785660=200203161032503124678565799=10000100268=2279=1269=148=17359555=6SZ683=357212270=10221.0271=7346=31023=6279=1269=148=17359555=6SZ683=357213270=10222.0271=4346=21023=710=144
1128=99=25235=X49=SAMPLE75=2016101134=123852=2000050802542437521529060=200005080254243752152905799=10000100268=2279=1269=048=17359555=6SZ683=357214270=10214.0271=6346=61023=1279=1269=048=17359555=6SZ683=357215270=10213.0271=11346=91023=210=197
1128=99=25235=X49=SAMPLE75=2016101134=488252=2014062016213693229126460=201406201621369322912645799=10000100268=2279=1269=148=17359555=6SZ683=357216270=10216.0271=10346=81023=1279=1269=148=17359555=6SZ683=357217270=10217.0271=6346=41023=210=230
1128=99=18035=X49=SAMPLE75=2016101134=150452=2008010401582157536064060=200801040158215753606405799=10000100268=1279=1269=148=17359555=6SZ683=357218270=10223.0271=4346=21023=810=125
1128=99=18035=X49=SAMPLE75=2016101134=298352=2015050917042645178713660=201505091704264517871365799=10000100268=1279=1269=148=17359555=6SZ683=357219270=10224.0271=1346=11023=910=108
1128=99=18135=X49=SAMPLE75=2016101134=416952=2013110803004131536358460=201311080300413153635845799=10000100268=1279=1269=148=17359555=6SZ683=357220270=10225.0271=8346=11023=1010=175
1128=99=18035=X49=SAMPLE75=2016101134=121752=2010061918390265260492860=201006191839026526049285799=10000100268=1279=1269=048=17359555=6SZ683=357221270=10214.0271=9346=71023=110=130
1128=99=18035=X49=SAMPLE75=2016101134=343852=2016121017585901523897660=201612101758590152389765799=10000100268=1279=1269=148=17359555=6SZ683=357222270=10217.0271=7346=51023=210=144
1128=99=25135=X49=SAMPLE75=2016101134=368052=2002072008050589865512060=200207200805058986551205799=10000100268=2279=1269=148=17359555=6SZ683=357223270=10221.0271=4346=21023=6279=1269=148=17359555=6SZ683=357224270=10222.0271=7346=31023=710=138
1128=99=25135=X49=SAMPLE75=2016101134=2652=2016082915501607217017660=201608291550160721701765799=10000100268=2279=1269=148=17359555=6SZ683=357225270=10216.0271=9346=71023=1279=1269=148=17359555=6SZ683=357226270=10217.0271=8346=61023=210=156
1128=99=25335=X49=SAMPLE75=2016101134=385352=2008123007581768672307260=200812300758176867230725799=10000100268=2279=1269=048=17359555=6SZ683=357227270=10214.0271=10346=81023=1279=1269=048=17359555=6SZ683=357228270=10213.0271=10346=81023=210=230
1128=99=18035=X49=SAMPLE75=2016101134=77052=2004070810400583904526460=200407081040058390452645799=10000100268=1279=1269=148=17359555=6SZ683=357229270=10216.0271=8346=61023=110=085
1128=99=25135=X49=SAMPLE75=2016101134=18552=2007091000182257952022460=200709100018225795202245799=10000100268=2279=1269=148=17359555=6SZ683=357230270=10221.0271=7346=31023=6279=1269=148=17359555=6SZ683=357231270=10222.0271=4346=21023=710=124
1128=99=25235=X49=SAMPLE75=2016101134=84852=2014050714191938215430460=201405071419193821543045799=10000100268=2279=1269=048=17359555=6SZ683=357232270=10214.0271=9346=71023=1279=1269=048=17359555=6SZ683=357233270=10213.0271=11346=91023=210=188
1128=99=25135=X49=SAMPLE75=2016101134=154152=2014081102550663031084860=201408110255066303108485799=10000100268=2279=1269=148=17359555=6SZ683=357234270=10216.0271=9346=71023=1279=1269=148=17359555=6SZ683=357235270=10217.0271=7346=51023=210=154
1128=99=18135=X49=SAMPLE75=2016101134=285952=2002062902153849157489660=200206290215384915748965799=10000100268=1279=1269=148=17359555=6SZ683=357236270=10216.0271=10346=81023=110=123
1128=99=25235=X49=SAMPLE75=2016101134=9852=2005102316122469688752060=200510231612246968875205799=10000100268=2279=1269=048=17359555=6SZ683=357237270=10210.0271=8346=61023=5279=1269=048=17359555=6SZ683=357238270=10209.0271=11346=71023=610=205
1128=99=18135=X49=SAMPLE75=2016101134=95452=2001011916050202734264060=200101191605020273426405799=10000100268=1279=1269=148=17359555=6SZ683=357239270=10223.0271=11346=31023=810=148
1128=99=18035=X49=SAMPLE75=2016101134=478252=2009073004165284203808060=200907300416528420380805799=10000100268=1279=1269=148=17359555=6SZ683=357240270=10224.0271=8346=21023=910=097
1128=99=18235=X49=SAMPLE75=2016101134=495352=2013120419270964305875260=201312041927096430587525799=10000100268=1279=1269=148=17359555=6SZ683=357241270=10225.0271=15346=21023=1010=183
1128=99=18135=X49=SAMPLE75=2016101134=329652=2013100419264515856275260=201310041926451585627525799=10000100268=1279=1269=148=17359555=6SZ683=357242270=10225.0271=8346=11023=1010=175
1128=99=18035=X49=SAMPLE75=2016101134=352952=2006120808083385080425660=200612080808338508042565799=10000100268=1279=1269=148=17359555=6SZ683=357243270=10224.0271=1346=11023=910=115
1128=99=18035=X49=SAMPLE75=2016101134=185952=2013030322182298563545660=201303032218229856354565799=10000100268=1279=1269=148=17359555=6SZ683=357244270=10223.0271=4346=21023=810=127
1128=99=18135=X49=SAMPLE75=2016101134=19052=2009120720583921447724860=200912072058392144772485799=10000100268=1279=1269=148=17359555=6SZ683=357245270=10223.0271=11346=31023=810=153
1128=99=18035=X49=SAMPLE75=2016101134=208152=2009012913540240523500860=200901291354024052350085799=10000100268=1279=1269=148=17359555=6SZ683=357246270=10224.0271=8346=21023=910=110
1128=99=18235=X49=SAMPLE75=2016101134=75952=2002052712334510866304060=200205271233451086630405799=10000100268=1279=1269=148=17359555=6SZ683=357247270=10225.0271=15346=21023=1010=192
1128=99=18035=X49=SAMPLE75=2016101134=313752=2008090823362148370220860=200809082336214837022085799=10000100268=1279=1269=148=17359555=6SZ683=357248270=10223.0271=4346=21023=810=136
1128=99=18135=X49=SAMPLE75=2016101134=23752=2004052311364984205392060=200405231136498420539205799=10000100268=1279=1269=148=17359555=6SZ683=357249270=10225.0271=8346=11023=1010=170
1128=99=18035=X49=SAMPLE75=2016101134=97952=2005071306144879458390460=200507130614487945839045799=10000100268=1279=1269=148=17359555=6SZ683=357250270=10224.0271=1346=11023=910=110
1128=99=25235=X49=SAMPLE75=2016101134=380452=2004020103465658922054460=200402010346565892205445799=10000100268=2279=1269=048=17359555=6SZ683=357251270=10210.0271=11346=71023=5279=1269=048=17359555=6SZ683=357252270=10209.0271=8346=61023=610=179
1128=99=18235=X49=SAMPLE75=2016101134=264152=2014102508061402683219260=201410250806140268321925799=10000100268=1279=1269=048=17359555=6SZ683=357253270=10212.0271=19346=101023=310=177
1128=99=18135=X49=SAMPLE75=2016101134=112552=2002111111383293348388860=200211111138329334838885799=10000100268=1279=1269=148=17359555=6SZ683=357254270=10218.0271=15346=61023=310=152
1128=99=25135=X49=SAMPLE75=2016101134=189752=2007042219414449826617660=200704221941444982661765799=10000100268=2279=1269=148=17359555=6SZ683=357255270=10216.0271=9346=71023=1279=1269=148=17359555=6SZ683=357256270=10220.0271=8346=61023=510=149
1128=99=18235=X49=SAMPLE75=2016101134=366352=2007031511075470793478460=200703151107547079347845799=10000100268=1279=1269=048=17359555=6SZ683=357257270=10213.0271=19346=101023=210=193
1128=99=18135=X49=SAMPLE75=2016101134=10052=2015103002272216131072060=201510300227221613107205799=10000100268=1279=1269=148=17359555=6SZ683=357258270=10217.0271=15346=61023=210=141
1128=99=18135=X49=SAMPLE75=2016101134=487852=2000121300524268874022060=200012130052426887402205799=10000100268=1279=1269=048=17359555=6SZ683=357259270=10211.0271=15346=71023=410=162
1128=99=18135=X49=SAMPLE75=2016101134=56352=2003081318381518586553660=200308131838151858655365799=10000100268=1279=1269=048=17359555=6SZ683=357260270=10210.0271=19346=81023=510=156
1128=99=18135=X49=SAMPLE75=2016101134=99052=2015050909360486951129660=201505090936048695112965799=10000100268=1279=1269=048=17359555=6SZ683=357261270=10209.0271=16346=71023=610=136
1128=99=18135=X49=SAMPLE75=2016101134=140652=2011051403052374894195260=201105140305237489419525799=10000100268=1279=1269=048=17359555=6SZ683=357262270=10208.0271=16346=71023=710=139
1128=99=18135=X49=SAMPLE75=2016101134=4252=2006070109590400284374460=200607010959040028437445799=10000100268=1279=1269=148=17359555=6SZ683=357263270=10219.0271=21346=81023=410=166
1128=99=18135=X49=SAMPLE75=2016101134=239352=2014012601351578952806460=201401260135157895280645799=10000100268=1279=1269=148=17359555=6SZ683=357264270=10220.0271=16346=71023=510=156
1128=99=18135=X49=SAMPLE75=2016101134=305052=2006022604480584561296060=200602260448058456129605799=10000100268=1279=1269=148=17359555=6SZ683=357265270=10221.0271=15346=41023=610=151
1128=99=18135=X49=SAMPLE75=2016101134=450152=2010070316130661905849660=201007031613066190584965799=10000100268=1279=1269=148=17359555=6SZ683=357266270=10222.0271=12346=31023=710=138
1128=99=25335=X49=SAMPLE75=2016101134=126452=2005061103511950547744060=200506110351195054774405799=10000100268=2279=1269=148=17359555=6SZ683=357267270=10216.0271=10346=81023=1279=1269=148=17359555=6SZ683=357268270=10220.0271=15346=61023=510=236
1128=99=18135=X49=SAMPLE75=2016101134=145552=2012042914571279575392060=201204291457127957539205799=10000100268=1279=1269=148=17359555=6SZ683=357269270=10223.0271=11346=31023=810=158
1128=99=18035=X49=SAMPLE75=2016101134=441352=2001101016074825728180060=200110101607482572818005799=10000100268=1279=1269=148=17359555=6SZ683=357270270=10224.0271=8346=21023=910=108
1128=99=18235=X49=SAMPLE75=2016101134=230452=2009052902133753371040060=200905290213375337104005799=10000100268=1279=1269=148=17359555=6SZ683=357271270=10225.0271=15346=21023=1010=197
1128=99=18135=X49=SAMPLE75=2016101134=378152=2007111607280308877619260=200711160728030887761925799=10000100268=1279=1269=148=17359555=6SZ683=357272270=10224.0271=28346=31023=910=151
1128=99=18135=X49=SAMPLE75=2016101134=182152=2014040921244867514086460=201404092124486751408645799=10000100268=1279=1269=148=17359555=6SZ683=357273270=10221.0271=22346=51023=610=126
1128=99=18135=X49=SAMPLE75=2016101134=169852=2001052903375991188188860=200105290337599118818885799=10000100268=1279=1269=148=17359555=6SZ683=357274270=10222.0271=19346=41023=710=144
1128=99=18135=X49=SAMPLE75=2016101134=217652=2016122011235901101004860=201612201123590110100485799=10000100268=1279=1269=048=17359555=6SZ683=357275270=10209.0271=23346=81023=610=176
1128=99=18135=X49=SAMPLE75=2016101134=351352=2005052002083272800601660=200505200208327280060165799=10000100268=1279=1269=048=17359555=6SZ683=357276270=10208.0271=23346=81023=710=168
1128=99=18135=X49=SAMPLE75=2016101134=275852=2005072707370970500758460=200507270737097050075845799=10000100268=1279=1269=048=17359555=6SZ683=357277270=10207.0271=13346=51023=810=175
1128=99=18135=X49=SAMPLE75=2016101134=20552=2007100209404504785596860=200710020940450478559685799=10000100268=1279=1269=048=17359555=6SZ683=357278270=10206.0271=12346=41023=910=190
1128=99=18235=X49=SAMPLE75=2016101134=201352=2008101204154910952492860=200810120415491095249285799=10000100268=1279=1269=048=17359555=6SZ683=357279270=10205.0271=17346=51023=1010=229
1128=99=18135=X49=SAMPLE75=2016101134=412652=2002012312164261391389660=200201231216426139138965799=10000100268=1279=1269=048=17359555=6SZ683=357280270=10206.0271=32346=51023=910=172
1128=99=18135=X49=SAMPLE75=2016101134=222552=2003081013165189049584060=200308101316518904958405799=10000100268=1279=1269=148=17359555=6SZ683=357281270=10220.0271=22346=71023=510=177
1128=99=18135=X49=SAMPLE75=2016101134=432152=2006033014382202443283260=200603301438220244328325799=10000100268=1279=1269=048=17359555=6SZ683=357282270=10210.0271=26346=91023=510=165
1128=99=18035=X49=SAMPLE75=2016101134=439052=2012052501362345145619260=201205250136234514561925799=10000100268=1279=1269=148=17359555=6SZ683=357283270=10216.0271=9346=71023=110=137
1128=99=25335=X49=SAMPLE75=2016101134=162052=2006011207480494679504060=200601120748049467950405799=10000100268=2279=1269=148=17359555=6SZ683=357284270=10220.0271=30346=81023=5279=1269=148=17359555=6SZ683=357285270=10225.0271=7346=11023=1010=250
1128=99=18035=X49=SAMPLE75=2016101134=389052=2008032607020269970892860=200803260702026997089285799=10000100268=1279=1269=148=17360055=6SH783=99276270=10279.0271=11346=21023=810=079
1128=99=18135=X49=SAMPLE75=2016101134=37852=2016083018342106857625660=201608301834210685762565799=10000100268=1279=1269=148=17360055=6SH783=99277270=10281.0271=11346=21023=1010=133
1128=99=18135=X49=SAMPLE75=2016101134=112752=2004092815343890322128060=200409281534389032212805799=10000100268=1279=1269=148=17359555=6SZ683=357286270=10222.0271=27346=51023=710=166
1128=99=18035=X49=SAMPLE75=2016101134=320752=2009042600085430746739260=200904260008543074673925799=10000100268=1279=1269=048=17360055=6SH783=99278270=10261.0271=11346=21023=710=049
1128=99=18235=X49=SAMPLE75=2016101134=28952=2004091200263840150681660=200409120026384015068165799=10000100268=1279=1269=048=17359555=6SZ683=357287270=10210.0271=34346=101023=510=209
1128=99=18035=X49=SAMPLE75=2016101134=220552=2004043012104143820161660=200404301210414382016165799=10000100268=1279=1269=048=17360055=6SH783=99279270=10259.0271=11346=21023=910=058
1128=99=18135=X49=SAMPLE75=2016101134=461752=2010012500104435143788860=201001250010443514378885799=10000100268=1279=1269=048=17359555=6SZ683=357288270=10208.0271=31346=91023=710=168
1128=99=18135=X49=SAMPLE75=2016101134=240252=2009050801460370467590460=200905080146037046759045799=10000100268=1279=1269=048=17359555=6SZ683=357289270=10214.0271=17346=81023=110=177
1128=99=18135=X49=SAMPLE75=2016101134=287652=2003112418445878069468860=200311241844587806946885799=10000100268=1279=1269=148=17359555=6SZ683=357290270=10220.0271=23346=71023=510=135
1128=99=18135=X49=SAMPLE75=2016101134=499352=2014040219553714517939260=201404021955371451793925799=10000100268=1279=1269=048=17359555=6SZ683=357291270=10210.0271=27346=91023=510=144
1128=99=18135=X49=SAMPLE75=2016101134=427152=2011091901023437169612860=201109190102343716961285799=10000100268=1279=1269=148=17359555=6SZ683=357292270=10220.0271=30346=81023=510=178
1128=99=18235=X49=SAMPLE75=2016101134=181752=2013030710160474587526460=201303071016047458752645799=10000100268=1279=1269=048=17359555=6SZ683=357293270=10210.0271=34346=101023=510=232
1128=99=18135=X49=SAMPLE75=2016101134=4652=2012090811520468123897660=201209081152046812389765799=10000100268=1279=1269=048=17359555=6SZ683=357294270=10207.0271=21346=61023=810=180
1128=99=18135=X49=SAMPLE75=2016101134=303352=2012012607244090161715260=201201260724409016171525799=10000100268=1279=1269=148=17359555=6SZ683=357295270=10223.0271=19346=41023=810=190
1128=99=18135=X49=SAMPLE75=2016101134=493952=2013043017565522481856060=201304301756552248185605799=10000100268=1279=1269=048=17359555=6SZ683=357296270=10206.0271=40346=61023=910=185
1128=99=18135=X49=SAMPLE75=2016101134=249052=2015031420485255858547260=201503142048525585854725799=10000100268=1279=1269=148=17359555=6SZ683=357297270=10224.0271=36346=41023=910=167
1128=99=18235=X49=SAMPLE75=2016101134=375652=2002031123491394971226460=200203112349139497122645799=10000100268=1279=1269=048=17359555=6SZ683=357298270=10205.0271=25346=61023=1010=219
1128=99=18235=X49=SAMPLE75=2016101134=129952=2013013116522010653632060=201301311652201065363205799=10000100268=1279=1269=148=17359555=6SZ683=357299270=10225.0271=15346=21023=1010=231
1128=99=18135=X49=SAMPLE75=2016101134=288352=2012072413285445827923260=201207241328544582792325799=10000100268=1279=1269=048=17359555=6SZ683=357300270=10213.0271=18346=91023=210=134
1128=99=18135=X49=SAMPLE75=2016101134=251052=2009040213220754469350460=200904021322075446935045799=10000100268=1279=1269=048=17359555=6SZ683=357301270=10214.0271=18346=91023=110=146
1128=99=18135=X49=SAMPLE75=2016101134=242352=2013042021002021767270460=201304202100202176727045799=10000100268=1279=1269=148=17359555=6SZ683=357302270=10216.0271=10346=81023=110=180
1128=99=25335=X49=SAMPLE75=2016101134=381652=2010101100173296788083260=201010110017329678808325799=10000100268=2279=1269=048=17359555=6SZ683=357303270=10210.0271=31346=91023=5279=1269=048=17359555=6SZ683=357304270=10209.0271=26346=91023=610=019
1128=99=18035=X49=SAMPLE75=2016101134=458452=2016060700132711464582460=201606070013271146458245799=10000100268=1279=1269=148=17359555=6SZ683=357305270=10216.0271=9346=71023=110=116
1128=99=18135=X49=SAMPLE75=2016101134=236052=2000040812103865821323960=200004081210386582132395799=10000100268=1279=1269=048=17359555=6SZ683=357306270=10214.0271=17346=81023=110=130
1128=99=25435=X49=SAMPLE75=2016101134=326852=2016062721221574371596860=201606272122157437159685799=10000100268=2279=1269=048=17359555=6SZ683=357307270=10210.0271=34346=101023=5279=1269=048=17359555=6SZ683=357308270=10209.0271=23346=81023=610=079
1128=99=18135=X49=SAMPLE75=2016101134=294952=2007031004472560917580860=200703100447256091758085799=10000100268=1279=1269=048=17359555=6SZ683=357309270=10214.0271=18346=91023=110=168
1128=99=25335=X49=SAMPLE75=2016101134=428652=2017021007151449442976060=201702100715144944297605799=10000100268=2279=1269=048=17359555=6SZ683=357310270=10210.0271=31346=91023=5279=1269=048=17359555=6SZ683=357311270=10209.0271=26346=91023=610=002
1128=99=25435=X49=SAMPLE75=2016101134=203952=2007021720373440980105660=200702172037344098010565799=10000100268=2279=1269=048=17359555=6SZ683=357312270=10210.0271=34346=101023=5279=1269=048=17359555=6SZ683=357313270=10209.0271=23346=81023=610=000
1128=99=25335=X49=SAMPLE75=2016101134=13852=2011041220120832056172860=201104122012083205617285799=10000100268=2279=1269=048=17359555=6SZ683=357314270=10210.0271=31346=91023=5279=1269=048=17359555=6SZ683=357315270=10209.0271=26346=91023=610=009
1128=99=25435=X49=SAMPLE75=2016101134=271252=2000040514240001876048060=200004051424000187604805799=10000100268=2279=1269=048=17359555=6SZ683=357316270=10210.0271=34346=101023=5279=1269=048=17359555=6SZ683=357317270=10209.0271=23346=81023=610=059
1128=99=18035=X49=SAMPLE75=2016101134=163252=2010022619444604169568060=201002261944460416956805799=10000100268=1279=1269=148=17359555=6SZ683=357318270=10216.0271=8346=61023=110=125
1128=99=18035=X49=SAMPLE75=2016101134=72652=2000091316250544770206860=200009131625054477020685799=10000100268=1279=1269=148=17359555=6SZ683=357319270=10216.0271=7346=51023=110=104
1128=99=18135=X49=SAMPLE75=2016101134=14952=2008101913461764099708860=200810191346176409970885799=10000100268=1279=1269=148=17359555=6SZ683=357320270=10221.0271=23346=61023=610=147
1128=99=18135=X49=SAMPLE75=2016101134=383752=2010050614520649984448060=201005061452064998444805799=10000100268=1279=1269=148=17359555=6SZ683=357321270=10221.0271=24346=71023=610=160
1128=99=18035=X49=SAMPLE75=2016101134=178352=2012051207215236947993660=201205120721523694799365799=10000100268=1279=1269=148=17359555=6SZ683=357322270=10216.0271=6346=41023=110=093
1128=99=18135=X49=SAMPLE75=2016101134=71352=2010102309022117367961660=201010230902211736796165799=10000100268=1279=1269=148=17359555=6SZ683=357323270=10221.0271=25346=81023=610=171
1128=99=18035=X49=SAMPLE75=2016101134=129752=2012040314234259672697660=201204031423425967269765799=10000100268=1279=1269=148=17359555=6SZ683=357324270=10216.0271=7346=51023=110=127
1128=99=18035=X49=SAMPLE75=2016101134=444452=2000100810134488278993260=200010081013448827899325799=10000100268=1279=1269=148=17359555=6SZ683=357325270=10216.0271=8346=61023=110=135
1128=99=18035=X49=SAMPLE75=2016101134=303052=2008031802565177970604860=200803180256517797060485799=10000100268=1279=1269=148=17359555=6SZ683=357326270=10216.0271=9346=71023=110=126
1128=99=25335=X49=SAMPLE75=2016101134=335452=2009011201541330765372860=200901120154133076537285799=10000100268=2279=1269=048=17359555=6SZ683=357327270=10210.0271=31346=91023=5279=1269=048=17359555=6SZ683=357328270=10209.0271=26346=91023=610=013
1128=99=17935=X49=SAMPLE75=2016101134=384452=2005071704370166412486460=200507170437016641248645799=10000100268=1279=1269=048=17360055=6SH783=99280270=10261.0271=3346=11023=710=031
1128=99=18135=X49=SAMPLE75=2016101134=253752=2009062915261786453030460=200906291526178645303045799=10000100268=1279=1269=048=17359555=6SZ683=357329270=10214.0271=17346=81023=110=152
1128=99=25435=X49=SAMPLE75=2016101134=287352=2011111108240802665036860=201111110824080266503685799=10000100268=2279=1269=048=17359555=6SZ683=357330270=10210.0271=34346=101023=5279=1269=048=17359555=6SZ683=357331270=10209.0271=23346=81023=610=044
1128=99=25335=X49=SAMPLE75=2016101134=492252=2001071702442801140144860=200107170244280114014485799=10000100268=2279=1269=048=17359555=6SZ683=357332270=10210.0271=31346=91023=5279=1269=048=17359555=6SZ683=357333270=10209.0271=26346=91023=610=021
1128=99=18035=X49=SAMPLE75=2016101134=134852=2012120808235352218688060=201212080823535221868805799=10000100268=1279=1269=048=17359555=6SZ683=357334270=10214.0271=9346=71023=110=095
1128=99=18135=X49=SAMPLE75=2016101134=418452=2003122723402181310932860=200312272340218131093285799=10000100268=1279=1269=148=17359555=6SZ683=357335270=10216.0271=10346=81023=110=150
1128=99=25435=X49=SAMPLE75=2016101134=487052=2011050100253427587296060=201105010025342758729605799=10000100268=2279=1269=048=17359555=6SZ683=357336270=10210.0271=34346=101023=5279=1269=048=17359555=6SZ683=357337270=10209.0271=23346=81023=610=073
1128=99=25335=X49=SAMPLE75=2016101134=84552=2010100603090438240601660=201010060309043824060165799=10000100268=2279=1269=048=17359555=6SZ683=357338270=10210.0271=31346=91023=5279=1269=048=17359555=6SZ683=357339270=10209.0271=26346=91023=610=043
1128=99=25435=X49=SAMPLE75=2016101134=169052=2002053109543150119497660=200205310954315011949765799=10000100268=2279=1269=048=17359555=6SZ683=357340270=10210.0271=34346=101023=5279=1269=048=17359555=6SZ683=357341270=10209.0271=23346=81023=610=046
1128=99=18035=X49=SAMPLE75=2016101134=46052=2013050722083969238624060=201305072208396923862405799=10000100268=1279=1269=148=17359555=6SZ683=357342270=10216.0271=9346=71023=110=103
1128=99=25335=X49=SAMPLE75=2016101134=427252=2008093001032155904998460=200809300103215590499845799=10000100268=2279=1269=148=17359555=6SZ683=357343270=10221.0271=22346=71023=6279=1269=148=17359555=6SZ683=357344270=10222.0271=30346=61023=710=013
1128=99=25335=X49=SAMPLE75=2016101134=384052=2016051017443705199526460=201605101744370519952645799=10000100268=2279=1269=048=17359555=6SZ683=357345270=10214.0271=10346=81023=1279=1269=048=17359555=6SZ683=357346270=10213.0271=17346=81023=210=016
1128=99=25235=X49=SAMPLE75=2016101134=464652=2002021302221300018555260=200202130222130001855525799=10000100268=2279=1269=148=17359555=6SZ683=357347270=10216.0271=8346=61023=1279=1269=148=17359555=6SZ683=357348270=10217.0271=16346=71023=210=238
1128=99=25335=X49=SAMPLE75=2016101134=87652=2003062200182660336985660=200306220018266033698565799=10000100268=2279=1269=148=17359555=6SZ683=357349270=10221.0271=25346=81023=6279=1269=148=17359555=6SZ683=357350270=10222.0271=27346=51023=710=253
1128=99=25235=X49=SAMPLE75=2016101134=88052=2008072404331596448576060=200807240433159644857605799=10000100268=2279=1269=148=17359555=6SZ683=357351270=10216.0271=9346=71023=1279=1269=148=17359555=6SZ683=357352270=10217.0271=15346=61023=210=206
1128=99=25235=X49=SAMPLE75=2016101134=33552=2014030323154291149478460=201403032315429114947845799=10000100268=2279=1269=048=17359555=6SZ683=357353270=10214.0271=9346=71023=1279=1269=048=17359555=6SZ683=357354270=10213.0271=18346=91023=210=215
1128=99=25335=X49=SAMPLE75=2016101134=57452=2017021220122311157715260=201702122012231115771525799=10000100268=2279=1269=148=17359555=6SZ683=357355270=10221.0271=22346=71023=6279=1269=148=17359555=6SZ683=357356270=10222.0271=30346=61023=710=252
1128=99=25235=X49=SAMPLE75=2016101134=400552=2002072618483433728315260=200207261848343372831525799=10000100268=2279=1269=148=17359555=6SZ683=357357270=10216.0271=8346=61023=1279=1269=148=17359555=6SZ683=357358270=10217.0271=16346=71023=210=239
1128=99=25335=X49=SAMPLE75=2016101134=497652=2005073016313234029017660=200507301631323402901765799=10000100268=2279=1269=048=17359555=6SZ683=357359270=10214.0271=10346=81023=1279=1269=048=17359555=6SZ683=357360270=10213.0271=17346=81023=210=008
1128=99=25335=X49=SAMPLE75=2016101134=454852=2010062100313879528499260=201006210031387952849925799=10000100268=2279=1269=148=17359555=6SZ683=357361270=10221.0271=25346=81023=6279=1269=148=17359555=6SZ683=357362270=10222.0271=27346=51023=710=254
1128=99=25235=X49=SAMPLE75=2016101134=300352=2004111100031904873043260=200411110003190487304325799=10000100268=2279=1269=148=17359555=6SZ683=357363270=10216.0271=9346=71023=1279=1269=148=17359555=6SZ683=357364270=10217.0271=15346=61023=210=221
1128=99=25235=X49=SAMPLE75=2016101134=11252=2010042903364318302169660=201004290336431830216965799=10000100268=2279=1269=048=17359555=6SZ683=357365270=10214.0271=9346=71023=1279=1269=048=17359555=6SZ683=357366270=10213.0271=18346=91023=210=210
1128=99=18235=X49=SAMPLE75=2016101134=78152=2006061507143961766556860=200606150714396176655685799=10000100268=1279=1269=048=17359555=6SZ683=357367270=10213.0271=19346=101023=210=227
1128=99=18035=X49=SAMPLE75=2016101134=456852=2000110411334888049873260=200011041133488804987325799=10000100268=1279=1269=048=17359555=6SZ683=357368270=10214.0271=8346=61023=110=092
1128=99=18135=X49=SAMPLE75=2016101134=281052=2007052100120813688608060=200705210012081368860805799=10000100268=1279=1269=148=17359555=6SZ683=357369270=10216.0271=10346=81023=110=158
1128=99=18035=X49=SAMPLE75=2016101134=341652=2001012721540844022783660=200101272154084402278365799=10000100268=1279=1269=048=17359555=6SZ683=357370270=10214.0271=9346=71023=110=110
1128=99=18035=X49=SAMPLE75=2016101134=51452=2002042513072615764867260=200204251307261576486725799=10000100268=1279=1269=148=17359555=6SZ683=357371270=10216.0271=9346=71023=110=107
1128=99=18035=X49=SAMPLE75=2016101134=124452=2009101323170637255219260=200910132317063725521925799=10000100268=1279=1269=048=17359555=6SZ683=357372270=10214.0271=8346=61023=110=120
1128=99=18035=X49=SAMPLE75=2016101134=160352=2003031102260422925520060=200303110226042292552005799=10000100268=1279=1269=048=17359555=6SZ683=357373270=10214.0271=9346=71023=110=132
1128=99=25335=X49=SAMPLE75=2016101134=343652=2010060623241564135046460=201006062324156413504645799=10000100268=2279=1269=048=17359555=6SZ683=357374270=10210.0271=31346=91023=5279=1269=048=17359555=6SZ683=357375270=10209.0271=26346=91023=610=026
1128=99=25435=X49=SAMPLE75=2016101134=246352=2009082605500612338988860=200908260550061233898885799=10000100268=2279=1269=048=17359555=6SZ683=357376270=10210.0271=34346=101023=5279=1269=048=17359555=6SZ683=357377270=10209.0271=23346=81023=610=087
1128=99=25335=X49=SAMPLE75=2016101134=82252=2006062408260111247897660=200606240826011124789765799=10000100268=2279=1269=048=17359555=6SZ683=357378270=10210.0271=31346=91023=5279=1269=048=17359555=6SZ683=357379270=10209.0271=26346=91023=610=019
1128=99=18135=X49=SAMPLE75=2016101134=135952=2009021611385097620076860=200902161138509762007685799=10000100268=1279=1269=148=17359555=6SZ683=357380270=10216.0271=17346=81023=110=181
1128=99=18035=X49=SAMPLE75=2016101134=302952=2007120107160718298809660=200712010716071829880965799=10000100268=1279=1269=048=17359555=6SZ683=357381270=10214.0271=8346=61023=110=126
1128=99=18035=X49=SAMPLE75=2016101134=377352=2014111802403829481100860=201411180240382948110085799=10000100268=1279=0269=148=17359555=6SZ683=357382270=10215.0271=1346=11023=110=132
1128=99=17935=X49=SAMPLE75=2016101134=186052=2017031202233890313152060=201703120223389031315205799=10000100268=1279=0269=148=17360055=6SH783=99281270=10271.0271=3346=11023=110=047
1128=99=18035=X49=SAMPLE75=2016101134=201052=2004080411050643385363260=200408041105064338536325799=10000100268=1279=1269=048=17359555=6SZ683=357383270=10214.0271=5346=51023=110=114
1128=99=25135=X49=SAMPLE75=2016101134=168452=2016111913535289485203260=201611191353528948520325799=10000100268=2279=2269=048=17360055=6SH783=99282270=10267.0271=3346=11023=1279=0269=048=17360055=6SH783=99283270=10257.0271=11346=21023=1010=121
1128=99=25135=X49=SAMPLE75=2016101134=49952=2001100108331593747004860=200110010833159374700485799=10000100268=2279=2269=148=17360055=6SH783=99284270=10271.0271=3346=11023=1279=0269=148=17360055=6SH783=99285270=10281.0271=11346=21023=1010=108
1128=99=25135=X49=SAMPLE75=2016101134=23952=2006042110563820302896060=200604211056382030289605799=10000100268=2279=1269=048=17360055=6SH783=99286270=10261.0271=11346=21023=6279=1269=048=17360055=6SH783=99287270=10257.0271=3346=11023=1010=111
1128=99=18035=X49=SAMPLE75=2016101134=112952=2000060908471302126586660=200006090847130212658665799=10000100268=1279=1269=148=17359555=6SZ683=357384270=10215.0271=2346=21023=110=111
1128=99=18035=X49=SAMPLE75=2016101134=35852=2012012416450341678137660=201201241645034167813765799=10000100268=1279=1269=148=17359555=6SZ683=357385270=10215.0271=3346=31023=110=115
1128=99=18035=X49=SAMPLE75=2016101134=174452=2015042016432484152979260=201504201643248415297925799=10000100268=1279=1269=048=17359555=6SZ683=357386270=10214.0271=4346=41023=110=148
1128=99=18035=X49=SAMPLE75=2016101134=137452=2008050902502848483308860=200805090250284848330885799=10000100268=1279=1269=048=17359555=6SZ683=357387270=10214.0271=3346=31023=110=093
1128=99=18035=X49=SAMPLE75=2016101134=227952=2002021115404274482572060=200202111540427448257205799=10000100268=1279=1269=148=17359555=6SZ683=357388270=10215.0271=4346=41023=110=104
1128=99=18135=X49=SAMPLE75=2016101134=118852=2008062612263173015046460=200806261226317301504645799=10000100268=1279=1269=148=17359555=6SZ683=357389270=10219.0271=28346=91023=510=187
1128=99=18135=X49=SAMPLE75=2016101134=166052=2011021823514067117536060=201102182351406711753605799=10000100268=1279=1269=148=17359555=6SZ683=357390270=10221.0271=45346=91023=710=147
1128=99=18035=X49=SAMPLE75=2016101134=314952=2005021302005137092985660=200502130200513709298565799=10000100268=1279=1269=148=17359555=6SZ683=357391270=10215.0271=5346=51023=110=108
1128=99=18135=X49=SAMPLE75=2016101134=490252=2000071501473775770440460=200007150147377577044045799=10000100268=1279=1269=148=17359555=6SZ683=357392270=10217.0271=14346=51023=310=180
1128=99=18135=X49=SAMPLE75=2016101134=17052=2008030802083552320348860=200803080208355232034885799=10000100268=1279=1269=148=17359555=6SZ683=357393270=10216.0271=18346=91023=210=190
1128=99=18035=X49=SAMPLE75=2016101134=220052=2000110403524216296868860=200011040352421629686885799=10000100268=1279=1269=148=17359555=6SZ683=357394270=10215.0271=4346=41023=110=132
1128=99=18135=X49=SAMPLE75=2016101134=138252=2011081009164632678220860=201108100916463267822085799=10000100268=1279=1269=148=17359555=6SZ683=357395270=10222.0271=26346=41023=810=168
1128=99=18135=X49=SAMPLE75=2016101134=133352=2004113005194151653465660=200411300519415165346565799=10000100268=1279=1269=148=17359555=6SZ683=357396270=10217.0271=15346=61023=310=194
1128=99=18035=X49=SAMPLE75=2016101134=57952=2007022105045499045238460=200702210504549904523845799=10000100268=1279=1269=148=17359555=6SZ683=357397270=10215.0271=5346=51023=110=115
1128=99=18035=X49=SAMPLE75=2016101134=480152=2016020714490700496819260=201602071449070049681925799=10000100268=1279=1269=148=17359555=6SZ683=357398270=10215.0271=6346=61023=110=118
1128=99=17935=X49=SAMPLE75=2016101134=113252=2012032414291730194553660=201203241429173019455365799=10000100268=1279=0269=148=17360055=6SH783=99288270=10271.0271=3346=11023=110=058
1128=99=18035=X49=SAMPLE75=2016101134=71352=2011061500194409129164860=201106150019440912916485799=10000100268=1279=1269=148=17359555=6SZ683=357399270=10215.0271=5346=51023=110=099
1128=99=18035=X49=SAMPLE75=2016101134=242552=2002121314551108443307260=200212131455110844330725799=10000100268=1279=1269=148=17359555=6SZ683=357400270=10215.0271=4346=41023=110=085
1128=99=18035=X49=SAMPLE75=2016101134=97752=2005091819534348032256060=200509181953434803225605799=10000100268=1279=1269=148=17359555=6SZ683=357401270=10215.0271=3346=31023=110=081
1128=99=18035=X49=SAMPLE75=2016101134=183852=2012092914323957827225660=201209291432395782722565799=10000100268=1279=1269=048=17359555=6SZ683=357402270=10214.0271=4346=41023=110=091
1128=99=25135=X49=SAMPLE75=2016101134=232652=2002112808365377429240060=200211280836537742924005799=10000100268=2279=2269=148=17360055=6SH783=99289270=10271.0271=3346=11023=1279=0269=148=17360055=6SH783=99290270=10281.0271=11346=21023=1010=069
1128=99=25235=X49=SAMPLE75=2016101134=8152=2012111802493628223052860=201211180249362822305285799=00000001268=1279=0269=248=17359555=6SZ683=357403270=10215.0271=3346=45797=137705=437=032=337=032=137=621180794231432=137=621180794231632=110=120
1128=99=15635=X49=SAMPLE75=2016101134=429852=2004010105401140519982460=200401010540114051998245799=00000010268=1279=0269=e48=17359555=6SZ683=357404271=6510=090
1128=99=25335=X49=SAMPLE75=2016101134=105852=2010050907034733773222460=201005090703473377322245799=10000100268=2279=2269=148=17359555=6SZ683=357405270=10215.0271=3346=31023=1279=0269=148=17359555=6SZ683=357406270=10225.0271=15346=21023=1010=236
1128=99=17935=X49=SAMPLE75=2016101134=74452=2013013007321295849664060=201301300732129584966405799=00000100268=1279=0269=048=17360055=6SH783=99291270=10268.0271=3346=11023=110=037
1128=99=16835=X49=SAMPLE75=2016101134=72852=2007010215185776918515260=200701021518577691851525799=10001000268=1279=0269=N48=17360055=6SH783=99292270=10268.0286=25510=113
1128=99=18035=X49=SAMPLE75=2016101134=36052=2013112211265802074572860=201311221126580207457285799=10000100268=1279=1269=048=17359555=6SZ683=357407270=10214.0271=5346=51023=110=117
1128=99=17935=X49=SAMPLE75=2016101134=214752=2005111214334327137840060=200511121433432713784005799=10000100268=1279=0269=048=17360055=6SH783=99293270=10267.0271=3346=11023=210=047
1128=99=18035=X49=SAMPLE75=2016101134=158052=2001061819401674059840860=200106181940167405984085799=10000100268=1279=0269=148=17359555=6SZ683=357408270=10215.0271=1346=11023=110=111
1128=99=25435=X49=SAMPLE75=2016101134=436252=2007122506441887360627260=200712250644188736062725799=10000100268=2279=1269=048=17359555=6SZ683=357409270=10210.0271=34346=101023=5279=1269=048=17359555=6SZ683=357410270=10209.0271=23346=81023=610=029
1128=99=25035=X49=SAMPLE75=2016101134=478552=2002053006305006328964860=200205300630500632896485799=10000100268=2279=2269=048=17360055=6SH783=99294270=10268.0271=3346=11023=1279=0269=048=17360055=6SH783=99295270=10258.0271=3346=11023=1010=077
1128=99=25035=X49=SAMPLE75=2016101134=7452=2013020807330762885568060=201302080733076288556805799=10000100268=2279=2269=048=17360055=6SH783=99296270=10267.0271=3346=11023=1279=0269=048=17360055=6SH783=99297270=10257.0271=3346=11023=1010=049
1128=99=25335=X49=SAMPLE75=2016101134=402852=2015010109433441041945660=201501010943344104194565799=10000100268=2279=2269=148=17359555=6SZ683=357411270=10215.0271=1346=11023=1279=0269=148=17359555=6SZ683=357412270=10225.0271=15346=21023=1010=240
1128=99=18035=X49=SAMPLE75=2016101134=252252=2001051204585713900105660=200105120458571390010565799=10000100268=1279=1269=048=17359555=6SZ683=357413270=10214.0271=6346=61023=110=114
1128=99=17935=X49=SAMPLE75=2016101134=72652=2002033016140514788862460=200203301614051478886245799=10000100268=1279=0269=048=17360055=6SH783=99298270=10267.0271=3346=11023=110=063
1128=99=25335=X49=SAMPLE75=2016101134=231052=2007021221520526514521660=200702122152052651452165799=10000100268=2279=1269=148=17359555=6SZ683=357414270=10220.0271=22346=71023=5279=1269=148=17359555=6SZ683=357415270=10224.0271=44346=51023=910=022
1128=99=25335=X49=SAMPLE75=2016101134=158852=2006052400350285584112060=200605240035028558411205799=10000100268=2279=1269=148=17359555=6SZ683=357416270=10220.0271=30346=81023=5279=1269=148=17359555=6SZ683=357417270=10224.0271=36346=41023=910=026
1128=99=18035=X49=SAMPLE75=2016101134=147452=2009120517193282080736060=200912051719328208073605799=10000100268=1279=1269=048=17359555=6SZ683=357418270=10214.0271=5346=51023=110=096
1128=99=25035=X49=SAMPLE75=2016101134=280852=2000062615340787849559860=200006261534078784955985799=10000100268=2279=2269=048=17360055=6SH783=99299270=10267.0271=3346=11023=1279=0269=048=17360055=6SH783=99300270=10257.0271=3346=11023=1010=043
1128=99=25335=X49=SAMPLE75=2016101134=312452=2004091121320255797289660=200409112132025579728965799=10000100268=2279=1269=048=17359555=6SZ683=357419270=10210.0271=31346=91023=5279=1269=048=17359555=6SZ683=357420270=10209.0271=26346=91023=610=235
1128=99=18035=X49=SAMPLE75=2016101134=9852=2006082113252902886284860=200608211325290288628485799=10000100268=1279=1269=048=17359555=6SZ683=357421270=10214.0271=4346=41023=110=113
1128=99=18035=X49=SAMPLE75=2016101134=342452=2013112719282839661497660=201311271928283966149765799=10000100268=1279=1269=048=17359555=6SZ683=357422270=10214.0271=3346=31023=110=115
1128=99=18035=X49=SAMPLE75=2016101134=82052=2003061110170307652296060=200306111017030765229605799=10000100268=1279=0269=148=17359555=6SZ683=357423270=10215.0271=1346=11023=110=114
1128=99=17935=X49=SAMPLE75=2016101134=433652=2015032512341461490931260=201503251234146149093125799=10000100268=1279=0269=148=17360055=6SH783=99301270=10271.0271=3346=11023=110=015
1128=99=18035=X49=SAMPLE75=2016101134=289152=2005081002255751874368060=200508100225575187436805799=10000100268=1279=1269=048=17359555=6SZ683=357424270=10214.0271=2346=21023=110=093
1128=99=18035=X49=SAMPLE75=2016101134=345252=2005120209393880070076860=200512020939388007007685799=10000100268=1279=1269=148=17359555=6SZ683=357425270=10215.0271=2346=21023=110=096
1128=99=18035=X49=SAMPLE75=2016101134=414452=2005101510571931867219260=200510151057193186721925799=10000100268=1279=1269=048=17359555=6SZ683=357426270=10214.0271=3346=31023=110=085
1128=99=18035=X49=SAMPLE75=2016101134=275252=2002042717202195562379260=200204271720219556237925799=10000100268=1279=1269=048=17359555=6SZ683=357427270=10214.0271=4346=41023=110=104
1128=99=18035=X49=SAMPLE75=2016101134=48752=2014010912453988296787260=201401091245398829678725799=10000100268=1279=1269=148=17359555=6SZ683=357428270=10215.0271=3346=31023=110=090
1128=99=18035=X49=SAMPLE75=2016101134=99652=2010090207240601351014460=201009020724060135101445799=10000100268=1279=1269=048=17359555=6SZ683=357429270=10214.0271=3346=31023=110=101
1128=99=18035=X49=SAMPLE75=2016101134=99352=2005050509324039974000060=200505050932403997400005799=10000100268=1279=1269=148=17359555=6SZ683=357430270=10215.0271=4346=41023=110=095
1128=99=18035=X49=SAMPLE75=2016101134=456852=2008032322005868191091260=200803232200586819109125799=10000100268=1279=1269=148=17359555=6SZ683=357431270=10215.0271=5346=51023=110=115
1128=99=18035=X49=SAMPLE75=2016101134=240652=2000011812544023896774060=200001181254402389677405799=10000100268=1279=1269=048=17359555=6SZ683=357432270=10214.0271=2346=21023=110=079
1128=99=18135=X49=SAMPLE75=2016101134=68452=2000122913203779427872060=200012291320377942787205799=10000100268=1279=1269=148=17359555=6SZ683=357433270=10216.0271=17346=81023=210=158
1128=99=25235=X49=SAMPLE75=2016101134=254752=2001112812295696940584060=200111281229569694058405799=10000100268=2279=1269=148=17359555=6SZ683=357434270=10215.0271=6346=61023=1279=1269=148=17359555=6SZ683=357435270=10216.0271=16346=71023=210=206
1128=99=23035=X49=SAMPLE75=2016101134=407552=2008072808282539401913660=200807280828253940191365799=00000001268=1279=0269=248=17359555=6SZ683=357436270=10214.0271=2346=35797=237705=337=032=237=032=137=621180794292232=110=105
1128=99=15635=X49=SAMPLE75=2016101134=266752=2008061302504334647558460=200806130250433464755845799=00000010268=1279=0269=e48=17359555=6SZ683=357437271=6710=102
1128=99=25335=X49=SAMPLE75=2016101134=142852=2007120609550845558972860=200712060955084555897285799=10000100268=2279=2269=048=17359555=6SZ683=357438270=10214.0271=2346=21023=1279=0269=048=17359555=6SZ683=357439270=10204.0271=18346=31023=1010=248
1128=99=17935=X49=SAMPLE75=2016101134=200852=2008060321570446501225660=200806032157044650122565799=10000100268=1279=0269=148=17360055=6SH783=99302270=10270.0271=3346=11023=110=014
1128=99=25335=X49=SAMPLE75=2016101134=148452=2016060319134981024185660=201606031913498102418565799=10000100268=2279=1269=148=17359555=6SZ683=357440270=10220.0271=33346=91023=6279=1269=148=17359555=6SZ683=357441270=10221.0271=42346=81023=710=251
1128=99=25435=X49=SAMPLE75=2016101134=330552=2015062216222006783520060=201506221622200678352005799=10000100268=2279=1269=048=17359555=6SZ683=357442270=10213.0271=18346=91023=1279=1269=048=17359555=6SZ683=357443270=10212.0271=20346=111023=210=041
1128=99=25335=X49=SAMPLE75=2016101134=355752=2000040302593341961301160=200004030259334196130115799=10000100268=2279=1269=148=17359555=6SZ683=357444270=10221.0271=43346=91023=7279=1269=148=17359555=6SZ683=357445270=10223.0271=18346=31023=910=014
1128=99=18135=X49=SAMPLE75=2016101134=56052=2008031212310812540499260=200803121231081254049925799=10000100268=1279=1269=048=17359555=6SZ683=357446270=10213.0271=17346=81023=110=172
1128=99=25035=X49=SAMPLE75=2016101134=238952=2002030215365163833301660=200203021536516383330165799=10000100268=2279=2269=148=17360055=6SH783=99303270=10270.0271=3346=11023=1279=0269=148=17360055=6SH783=99304270=10280.0271=3346=11023=1010=009
1128=99=18135=X49=SAMPLE75=2016101134=299652=2003062016441492519163260=200306201644149251916325799=10000100268=1279=1269=048=17359555=6SZ683=357447270=10213.0271=18346=91023=110=158
1128=99=18135=X49=SAMPLE75=2016101134=246652=2006092422465712105587260=200609242246571210558725799=10000100268=1279=1269=048=17359555=6SZ683=357448270=10213.0271=17346=81023=110=163
1128=99=18135=X49=SAMPLE75=2016101134=40152=2012012718084666450451260=201201271808466645045125799=10000100268=1279=1269=048=17359555=6SZ683=357449270=10213.0271=18346=91023=110=173
1128=99=18135=X49=SAMPLE75=2016101134=189452=2013012523194012788217660=201301252319401278821765799=10000100268=1279=1269=048=17359555=6SZ683=357450270=10213.0271=17346=81023=110=151
1128=99=18135=X49=SAMPLE75=2016101134=333552=2004013017270524300481660=200401301727052430048165799=10000100268=1279=1269=048=17359555=6SZ683=357451270=10213.0271=18346=91023=110=170
1128=99=18135=X49=SAMPLE75=2016101134=35852=2000101910100221299077660=200010191010022129907765799=10000100268=1279=1269=048=17359555=6SZ683=357452270=10210.0271=24346=81023=410=166
1128=99=18135=X49=SAMPLE75=2016101134=36552=2012051519310088098592060=201205151931008809859205799=10000100268=1279=1269=048=17359555=6SZ683=357453270=10210.0271=31346=91023=410=164
1128=99=18135=X49=SAMPLE75=2016101134=198452=2015070206594243795577660=201507020659424379557765799=10000100268=1279=1269=048=17359555=6SZ683=357454270=10210.0271=24346=81023=410=166
1128=99=18135=X49=SAMPLE75=2016101134=377152=2013030810422548211776060=201303081042254821177605799=10000100268=1279=1269=048=17359555=6SZ683=357455270=10210.0271=31346=91023=410=145
1128=99=18235=X49=SAMPLE75=2016101134=258352=2005012715443212047670460=200501271544321204767045799=10000100268=1279=1269=048=17359555=6SZ683=357456270=10212.0271=19346=101023=210=208
1128=99=18135=X49=SAMPLE75=2016101134=3352=2002112406033829982462460=200211240603382998246245799=10000100268=1279=1269=048=17359555=6SZ683=357457270=10205.0271=26346=71023=910=150
1128=99=18135=X49=SAMPLE75=2016101134=431352=2016021603441386763724860=201602160344138676372485799=10000100268=1279=1269=048=17359555=6SZ683=357458270=10210.0271=24346=81023=410=160
1128=99=18135=X49=SAMPLE75=2016101134=281852=2009030719445066944025660=200903071944506694402565799=10000100268=1279=1269=048=17359555=6SZ683=357459270=10210.0271=31346=91023=410=151
1128=99=18135=X49=SAMPLE75=2016101134=420052=2014060120444510450400060=201406012044451045040005799=10000100268=1279=1269=048=17359555=6SZ683=357460270=10210.0271=24346=81023=410=183
1128=99=18135=X49=SAMPLE75=2016101134=490552=2013010515374724339078460=201301051537472433907845799=10000100268=1279=1269=048=17359555=6SZ683=357461270=10210.0271=31346=91023=410=156
1128=99=18135=X49=SAMPLE75=2016101134=250752=2002121207393271973096060=200212120739327197309605799=10000100268=1279=1269=048=17359555=6SZ683=357462270=10210.0271=24346=81023=410=165
1128=99=18035=X49=SAMPLE75=2016101134=482252=2008042212372304366963260=200804221237230436696325799=10000100268=1279=1269=148=17359555=6SZ683=357463270=10215.0271=5346=51023=110=125
1128=99=25135=X49=SAMPLE75=2016101134=230652=2016110907254274573856060=201611090725427457385605799=10000100268=2279=2269=148=17360055=6SH783=99305270=10271.0271=3346=11023=1279=0269=148=17360055=6SH783=99306270=10281.0271=11346=21023=1010=092
1128=99=18035=X49=SAMPLE75=2016101134=12152=2003071504384228170502460=200307150438422817050245799=10000100268=1279=1269=148=17359555=6SZ683=357464270=10215.0271=8346=61023=110=116
1128=99=18035=X49=SAMPLE75=2016101134=118552=2016012520220242077875260=201601252022024207787525799=10000100268=1279=1269=148=17359555=6SZ683=357465270=10215.0271=9346=71023=110=131
1128=99=17935=X49=SAMPLE75=2016101134=390452=2013031611201563438041660=201303161120156343804165799=10000100268=1279=0269=148=17360055=6SH783=99307270=10271.0271=3346=11023=110=046
1128=99=25435=X49=SAMPLE75=2016101134=164852=2004073005302559919436860=200407300530255991943685799=10000100268=2279=1269=048=17359555=6SZ683=357466270=10213.0271=19346=101023=1279=1269=048=17359555=6SZ683=357467270=10212.0271=18346=91023=210=075
1128=99=25435=X49=SAMPLE75=2016101134=133652=2015022102344494104096060=201502210234449410409605799=10000100268=2279=1269=148=17359555=6SZ683=357468270=10220.0271=30346=81023=6279=1269=148=17359555=6SZ683=357469270=10221.0271=46346=101023=710=048
1128=99=18135=X49=SAMPLE75=2016101134=149752=2005112712184884887513660=200511271218488488751365799=10000100268=1279=1269=048=17359555=6SZ683=357470270=10210.0271=31346=91023=410=158
1128=99=18135=X49=SAMPLE75=2016101134=203552=2007012706474209152492860=200701270647420915249285799=10000100268=1279=1269=048=17359555=6SZ683=357471270=10210.0271=24346=81023=410=179
1128=99=18135=X49=SAMPLE75=2016101134=461552=2004121601405874418937660=200412160140587441893765799=10000100268=1279=1269=048=17359555=6SZ683=357472270=10210.0271=31346=91023=410=148
1128=99=25335=X49=SAMPLE75=2016101134=129752=2014062406400716224608060=201406240640071622460805799=10000100268=2279=1269=148=17359555=6SZ683=357473270=10220.0271=33346=91023=6279=1269=148=17359555=6SZ683=357474270=10221.0271=43346=91023=710=017
1128=99=25435=X49=SAMPLE75=2016101134=418652=2014123023593383579558460=201412302359338357955845799=10000100268=2279=1269=048=17359555=6SZ683=357475270=10213.0271=18346=91023=1279=1269=048=17359555=6SZ683=357476270=10212.0271=19346=101023=210=065
1128=99=18135=X49=SAMPLE75=2016101134=160952=2003101408510054380724860=200310140851005438072485799=10000100268=1279=1269=048=17359555=6SZ683=357477270=10210.0271=24346=81023=410=151
1128=99=18135=X49=SAMPLE75=2016101134=72152=2011082000141240692025660=201108200014124069202565799=10000100268=1279=1269=148=17359555=6SZ683=357478270=10216.0271=17346=81023=210=204
1128=99=18135=X49=SAMPLE75=2016101134=435052=2012111817464536730406460=201211181746453673040645799=10000100268=1279=1269=048=17359555=6SZ683=357479270=10213.0271=17346=81023=110=168
1128=99=18035=X49=SAMPLE75=2016101134=370352=2005031712273587041654460=200503171227358704165445799=10000100268=1279=1269=048=17359555=6SZ683=357480270=10213.0271=9346=71023=110=104
1128=99=18035=X49=SAMPLE75=2016101134=381952=2015071505213437454528060=201507150521343745452805799=10000100268=1279=1269=048=17359555=6SZ683=357481270=10213.0271=6346=61023=110=095
1128=99=25335=X49=SAMPLE75=2016101134=196252=2002100320045375802622460=200210032004537580262245799=10000100268=2279=1269=048=17359555=6SZ683=357482270=10210.0271=16346=71023=4279=1269=048=17359555=6SZ683=357483270=10206.0271=48346=71023=810=028
1128=99=25135=X49=SAMPLE75=2016101134=74152=2009021217581352268582460=200902121758135226858245799=10000100268=2279=1269=048=17360055=6SH783=99308270=10261.0271=3346=11023=6279=1269=048=17360055=6SH783=99309270=10257.0271=11346=21023=1010=107
1128=99=18135=X49=SAMPLE75=2016101134=467952=2012091119090324418854460=201209111909032441885445799=10000100268=1279=1269=148=17359555=6SZ683=357484270=10218.0271=22346=71023=410=177
1128=99=18035=X49=SAMPLE75=2016101134=423352=2016080722091727572614460=201608072209172757261445799=10000100268=1279=1269=148=17360055=6SH783=99310270=10277.0271=11346=21023=710=096
1128=99=18135=X49=SAMPLE75=2016101134=338452=2007121218252230073715260=200712121825223007371525799=10000100268=1279=1269=148=17359555=6SZ683=357485270=10218.0271=15346=61023=410=192
1128=99=18135=X49=SAMPLE75=2016101134=7752=2014083002405527932928060=201408300240552793292805799=10000100268=1279=1269=148=17359555=6SZ683=357486270=10218.0271=22346=71023=410=191
1128=99=18235=X49=SAMPLE75=2016101134=198852=2007031923303363482515260=200703192330336348251525799=10000100268=1279=1269=048=17359555=6SZ683=357487270=10212.0271=20346=111023=210=163
1128=99=18035=X49=SAMPLE75=2016101134=486852=2013102219222988913676860=201310221922298891367685799=10000100268=1279=0269=048=17359555=6SZ683=357488270=10214.0271=1346=11023=110=085
1128=99=17935=X49=SAMPLE75=2016101134=284752=2012050813381513862284860=201205081338151386228485799=10000100268=1279=0269=048=17360055=6SH783=99311270=10267.0271=3346=11023=110=044
1128=99=18035=X49=SAMPLE75=2016101134=88352=2000012008253937977429860=200001200825393797742985799=10000100268=1279=1269=048=17359555=6SZ683=357489270=10214.0271=2346=21023=110=100
1128=99=18235=X49=SAMPLE75=2016101134=194252=2004020805104472147699260=200402080510447214769925799=10000100268=1279=1269=048=17359555=6SZ683=357490270=10205.0271=25346=61023=1010=203
1128=99=20835=X49=SAMPLE75=2016101134=422252=2014062614471162389574460=201406261447116238957445799=00000001268=1279=0269=248=17359555=6SZ683=357491270=10214.0271=1346=25797=237705=237=032=137=032=110=070
1128=99=15635=X49=SAMPLE75=2016101134=440552=2011091523014121400953660=201109152301412140095365799=00000010268=1279=0269=e48=17359555=6SZ683=357492271=6810=093
1128=99=18035=X49=SAMPLE75=2016101134=89152=2008031818040847209398460=200803181804084720939845799=10000100268=1279=1269=048=17359555=6SZ683=357493270=10214.0271=1346=11023=110=089
1128=99=18235=X49=SAMPLE75=2016101134=236952=2001020719340811101250060=200102071934081110125005799=10000100268=1279=1269=048=17359555=6SZ683=357494270=10212.0271=21346=121023=310=198
1128=99=20835=X49=SAMPLE75=2016101134=471852=2003022618525731415203260=200302261852573141520325799=00000001268=1279=0269=248=17359555=6SZ683=357495270=10214.0271=1346=25797=237705=237=032=137=032=110=061
1128=99=15635=X49=SAMPLE75=2016101134=272852=2008092809334611804416060=200809280933461180441605799=00000010268=1279=0269=e48=17359555=6SZ683=357496271=6910=104
1128=99=25335=X49=SAMPLE75=2016101134=432352=2001121813010709501357660=200112181301070950135765799=10000100268=2279=2269=048=17359555=6SZ683=357497270=10214.0271=1346=11023=1279=0269=048=17359555=6SZ683=357498270=10204.0271=18346=31023=1010=251
1128=99=17935=X49=SAMPLE75=2016101134=18352=2014101019583506539635260=201410101958350653963525799=10000100268=1279=0269=148=17360055=6SH783=99312270=10270.0271=3346=11023=110=021
1128=99=25135=X49=SAMPLE75=2016101134=177052=2012042303432318474611260=201204230343231847461125799=10000100268=2279=2269=048=17360055=6SH783=99313270=10267.0271=3346=11023=1279=0269=048=17360055=6SH783=99314270=10257.0271=11346=21023=1010=059
1128=99=25035=X49=SAMPLE75=2016101134=281352=2014062909471370285388860=201406290947137028538885799=10000100268=2279=2269=148=17360055=6SH783=99315270=10270.0271=3346=11023=1279=0269=148=17360055=6SH783=99316270=10280.0271=3346=11023=1010=035
1128=99=18135=X49=SAMPLE75=2016101134=275652=2010100402395232343001660=201010040239523234300165799=10000100268=1279=1269=048=17359555=6SZ683=357499270=10213.0271=14346=71023=110=176
1128=99=18135=X49=SAMPLE75=2016101134=69152=2015072414333418380608060=201507241433341838060805799=10000100268=1279=1269=148=17359555=6SZ683=357500270=10218.0271=15346=61023=410=132
1128=99=18035=X49=SAMPLE75=2016101134=96052=2009061401431073845350460=200906140143107384535045799=10000100268=1279=1269=048=17359555=6SZ683=357501270=10213.0271=6346=61023=110=090
1128=99=18135=X49=SAMPLE75=2016101134=431152=2011091422062072283321660=201109142206207228332165799=10000100268=1279=1269=148=17359555=6SZ683=357502270=10218.0271=22346=71023=410=149
1128=99=18135=X49=SAMPLE75=2016101134=167252=2007062413513857289452860=200706241351385728945285799=10000100268=1279=1269=148=17359555=6SZ683=357503270=10218.0271=15346=61023=410=135
1128=99=18235=X49=SAMPLE75=2016101134=211352=2009011421022352231587260=200901142102235223158725799=10000100268=1279=1269=048=17359555=6SZ683=357504270=10212.0271=20346=111023=210=184
1128=99=18135=X49=SAMPLE75=2016101134=183052=2004102500223273233580860=200410250022327323358085799=10000100268=1279=1269=048=17359555=6SZ683=357505270=10205.0271=26346=71023=910=171
1128=99=18135=X49=SAMPLE75=2016101134=399452=2010080819393804742003260=201008081939380474200325799=10000100268=1279=1269=148=17359555=6SZ683=357506270=10218.0271=22346=71023=410=176
1128=99=18135=X49=SAMPLE75=2016101134=189352=2002072020043759011177660=200207202004375901117765799=10000100268=1279=1269=148=17359555=6SZ683=357507270=10218.0271=15346=61023=410=160
1128=99=18135=X49=SAMPLE75=2016101134=344052=2010051922392934731820860=201005192239293473182085799=10000100268=1279=1269=148=17359555=6SZ683=357508270=10215.0271=10346=81023=110=176
1128=99=25335=X49=SAMPLE75=2016101134=110052=2017012622172278732588860=201701262217227873258885799=10000100268=2279=1269=048=17359555=6SZ683=357509270=10213.0271=7346=71023=1279=1269=048=17359555=6SZ683=357510270=10212.0271=19346=101023=210=005
1128=99=25235=X49=SAMPLE75=2016101134=174852=2007041220373650508819260=200704122037365050881925799=10000100268=2279=1269=148=17359555=6SZ683=357511270=10215.0271=9346=71023=1279=1269=148=17359555=6SZ683=357512270=10216.0271=18346=91023=210=207
1128=99=18035=X49=SAMPLE75=2016101134=314852=2010013021270036021683260=201001302127003602168325799=10000100268=1279=1269=148=17359555=6SZ683=357513270=10215.0271=8346=61023=110=109
1128=99=18035=X49=SAMPLE75=2016101134=101252=2016051311031990605548860=201605131103199060554885799=10000100268=1279=0269=048=17359555=6SZ683=357514270=10214.0271=1346=11023=110=105
1128=99=17935=X49=SAMPLE75=2016101134=165652=2006080107351574980188860=200608010735157498018885799=10000100268=1279=0269=048=17360055=6SH783=99317270=10267.0271=3346=11023=110=043
1128=99=18035=X49=SAMPLE75=2016101134=240852=2013080413132175935782460=201308041313217593578245799=10000100268=1279=1269=148=17359555=6SZ683=357515270=10215.0271=7346=51023=110=087
1128=99=18235=X49=SAMPLE75=2016101134=45752=2015112403361972960441660=201511240336197296044165799=10000100268=1279=1269=048=17359555=6SZ683=357516270=10205.0271=25346=61023=1010=179
1128=99=18235=X49=SAMPLE75=2016101134=160552=2010052420262534743232060=201005242026253474323205799=10000100268=1279=1269=048=17359555=6SZ683=357517270=10212.0271=20346=111023=310=180
1128=99=18035=X49=SAMPLE75=2016101134=220752=2009060414574605422240060=200906041457460542224005799=10000100268=1279=1269=048=17359555=6SZ683=357518270=10214.0271=2346=21023=110=093
1128=99=25435=X49=SAMPLE75=2016101134=183252=2009030917531135850540860=200903091753113585054085799=10000100268=2279=1269=148=17359555=6SZ683=357519270=10220.0271=30346=81023=6279=1269=148=17359555=6SZ683=357520270=10221.0271=46346=101023=710=026
1128=99=18035=X49=SAMPLE75=2016101134=6352=2017031507160181218272060=201703150716018121827205799=10000100268=1279=1269=048=17359555=6SZ683=357521270=10214.0271=3346=31023=110=100
1128=99=18035=X49=SAMPLE75=2016101134=145152=2007012705424612629209660=200701270542461262920965799=10000100268=1279=1269=148=17359555=6SZ683=357522270=10215.0271=4346=41023=110=098
1128=99=18035=X49=SAMPLE75=2016101134=377252=2016013019133618251052860=201601301913361825105285799=10000100268=1279=1269=048=17359555=6SZ683=357523270=10214.0271=4346=41023=110=104
1128=99=25035=X49=SAMPLE75=2016101134=5452=2010052007560572402732860=201005200756057240273285799=10000100268=2279=2269=148=17360055=6SH783=99318270=10271.0271=3346=11023=1279=0269=148=17360055=6SH783=99319270=10281.0271=3346=11023=1010=053
1128=99=18035=X49=SAMPLE75=2016101134=263852=2001101323355055781100060=200110132335505578110005799=10000100268=1279=1269=148=17359555=6SZ683=357524270=10215.0271=3346=31023=110=114
1128=99=25135=X49=SAMPLE75=2016101134=483452=2011111515045434576307260=201111151504543457630725799=10000100268=2279=2269=048=17360055=6SH783=99320270=10267.0271=3346=11023=1279=0269=048=17360055=6SH783=99321270=10257.0271=11346=21023=1010=079
1128=99=18135=X49=SAMPLE75=2016101134=64152=2005011204165233422518460=200501120416523342251845799=10000100268=1279=1269=048=17359555=6SZ683=357525270=10213.0271=15346=81023=210=157
1128=99=18035=X49=SAMPLE75=2016101134=37852=2004071522521256557931260=200407152252125655793125799=10000100268=1279=1269=148=17359555=6SZ683=357526270=10215.0271=2346=21023=110=099
1128=99=18035=X49=SAMPLE75=2016101134=264752=2005033100481310030291260=200503310048131003029125799=10000100268=1279=1269=048=17359555=6SZ683=357527270=10214.0271=5346=51023=110=093
1128=99=24235=X49=SAMPLE75=2016101134=27952=2017020902182272501644860=201702090218227250164485799=00000001268=1279=0269=248=17359555=6SZ683=357528270=10215.0271=2346=35797=137705=337=032=237=621180794292532=137=621180794334132=110=225
1128=99=15635=X49=SAMPLE75=2016101134=362652=2014052710211407537452860=201405271021140753745285799=00000010268=1279=0269=e48=17359555=6SZ683=357529271=7110=105
1128=99=25335=X49=SAMPLE75=2016101134=55652=2001121620145022526419260=200112162014502252641925799=10000100268=2279=2269=148=17359555=6SZ683=357530270=10215.0271=2346=21023=1279=0269=148=17359555=6SZ683=357531270=10225.0271=15346=21023=1010=242
1128=99=17935=X49=SAMPLE75=2016101134=497252=2001122601230979528856060=200112260123097952885605799=10000100268=1279=0269=048=17360055=6SH783=99322270=10268.0271=3346=11023=110=055
1128=99=17935=X49=SAMPLE75=2016101134=267152=2009032510261366425113660=200903251026136642511365799=10000100268=1279=0269=048=17360055=6SH783=99323270=10267.0271=3346=11023=210=076
1128=99=18035=X49=SAMPLE75=2016101134=131352=2003120116095024937652860=200312011609502493765285799=10000100268=1279=0269=148=17359555=6SZ683=357532270=10215.0271=1346=11023=110=113
1128=99=25035=X49=SAMPLE75=2016101134=458252=2008011314430441784854460=200801131443044178485445799=10000100268=2279=2269=048=17360055=6SH783=99324270=10268.0271=3346=11023=1279=0269=048=17360055=6SH783=99325270=10258.0271=3346=11023=1010=048
1128=99=25135=X49=SAMPLE75=2016101134=113452=2011101720275852101337660=201110172027585210133765799=10000100268=2279=2269=048=17360055=6SH783=99326270=10267.0271=3346=11023=1279=0269=048=17360055=6SH783=99327270=10257.0271=11346=21023=1010=106
1128=99=25335=X49=SAMPLE75=2016101134=335152=2007052119525451172000060=200705211952545117200005799=10000100268=2279=2269=148=17359555=6SZ683=357533270=10215.0271=1346=11023=1279=0269=148=17359555=6SZ683=357534270=10225.0271=15346=21023=1010=242
1128=99=18035=X49=SAMPLE75=2016101134=207952=2010110908264174545075260=201011090826417454507525799=10000100268=1279=1269=048=17359555=6SZ683=357535270=10214.0271=6346=61023=110=118
1128=99=17935=X49=SAMPLE75=2016101134=346352=2001062200211302263812060=200106220021130226381205799=10000100268=1279=0269=048=17360055=6SH783=99328270=10267.0271=3346=11023=110=042
1128=99=25135=X49=SAMPLE75=2016101134=365552=2001032101250087766528860=200103210125008776652885799=10000100268=2279=1269=148=17360055=6SH783=99329270=10277.0271=3346=11023=6279=1269=148=17360055=6SH783=99330270=10281.0271=11346=21023=1010=104
1128=99=18135=X49=SAMPLE75=2016101134=170852=2008011007051094671833660=200801100705109467183365799=10000100268=1279=1269=048=17359555=6SZ683=357536270=10210.0271=23346=81023=510=158
1128=99=18135=X49=SAMPLE75=2016101134=388852=2004071304274899489008060=200407130427489948900805799=10000100268=1279=1269=048=17359555=6SZ683=357537270=10210.0271=16346=71023=510=162
1128=99=18135=X49=SAMPLE75=2016101134=144852=2010032821133932510144060=201003282113393251014405799=10000100268=1279=1269=148=17359555=6SZ683=357538270=10219.0271=21346=81023=410=159
1128=99=18135=X49=SAMPLE75=2016101134=329052=2002022823295325925972860=200202282329532592597285799=10000100268=1279=1269=148=17359555=6SZ683=357539270=10219.0271=28346=91023=410=169
1128=99=18035=X49=SAMPLE75=2016101134=448752=2013032212393281436896060=201303221239328143689605799=10000100268=1279=1269=048=17360055=6SH783=99331270=10261.0271=11346=21023=710=083
1128=99=25335=X49=SAMPLE75=2016101134=354152=2014071219300688201843260=201407121930068820184325799=10000100268=2279=1269=048=17359555=6SZ683=357540270=10210.0271=24346=81023=5279=1269=048=17359555=6SZ683=357541270=10206.0271=40346=61023=910=006
1128=99=18135=X49=SAMPLE75=2016101134=392652=2014022013555275952211260=201402201355527595221125799=10000100268=1279=1269=148=17359555=6SZ683=357542270=10216.0271=10346=81023=110=165
1128=99=18035=X49=SAMPLE75=2016101134=477152=2000031616524079319693860=200003161652407931969385799=10000100268=1279=1269=148=17359555=6SZ683=357543270=10216.0271=9346=71023=110=135
1128=99=18135=X49=SAMPLE75=2016101134=6652=2001102105155445350812860=200110210515544535081285799=10000100268=1279=1269=048=17359555=6SZ683=357544270=10210.0271=31346=91023=510=147
1128=99=18035=X49=SAMPLE75=2016101134=469052=2006111403583802631555260=200611140358380263155525799=10000100268=1279=1269=048=17359555=6SZ683=357545270=10214.0271=5346=51023=110=103
1128=99=18135=X49=SAMPLE75=2016101134=378252=2000092012103399903759660=200009201210339990375965799=10000100268=1279=1269=148=17359555=6SZ683=357546270=10216.0271=10346=81023=110=161
1128=99=25035=X49=SAMPLE75=2016101134=298452=2013050614494916297676860=201305061449491629767685799=10000100268=2279=2269=048=17360055=6SH783=99332270=10267.0271=3346=11023=1279=0269=048=17360055=6SH783=99333270=10257.0271=3346=11023=1010=041
1128=99=18035=X49=SAMPLE75=2016101134=89152=2008010707222391948457660=200801070722239194845765799=10000100268=1279=1269=048=17359555=6SZ683=357547270=10214.0271=6346=61023=110=124
1128=99=18035=X49=SAMPLE75=2016101134=61852=2004010910191994605425660=200401091019199460542565799=10000100268=1279=1269=148=17359555=6SZ683=357548270=10216.0271=9346=71023=110=137
1128=99=17935=X49=SAMPLE75=2016101134=16652=2004072222115239289744060=200407222211523928974405799=10000100268=1279=0269=048=17360055=6SH783=99334270=10267.0271=3346=11023=110=060
1128=99=18135=X49=SAMPLE75=2016101134=97752=2001100507484146083237660=200110050748414608323765799=10000100268=1279=1269=148=17359555=6SZ683=357549270=10219.0271=21346=81023=410=194
1128=99=18135=X49=SAMPLE75=2016101134=455052=2006013003364411931907260=200601300336441193190725799=10000100268=1279=1269=148=17359555=6SZ683=357550270=10217.0271=14346=51023=210=172
1128=99=18135=X49=SAMPLE75=2016101134=101752=2013102908573894582067260=201310290857389458206725799=10000100268=1279=1269=148=17359555=6SZ683=357551270=10222.0271=27346=51023=710=182
1128=99=18135=X49=SAMPLE75=2016101134=369552=2011041109274954231462460=201104110927495423146245799=10000100268=1279=1269=148=17359555=6SZ683=357552270=10219.0271=28346=91023=410=176
1128=99=18135=X49=SAMPLE75=2016101134=421152=2014042018120325879622460=201404201812032587962245799=10000100268=1279=1269=048=17359555=6SZ683=357553270=10210.0271=24346=81023=510=171
1128=99=18135=X49=SAMPLE75=2016101134=226352=2015052803522164542304060=201505280352216454230405799=10000100268=1279=1269=148=17359555=6SZ683=357554270=10219.0271=21346=81023=410=190
1128=99=18135=X49=SAMPLE75=2016101134=357952=2012042004181700517171260=201204200418170051717125799=10000100268=1279=1269=148=17359555=6SZ683=357555270=10219.0271=28346=91023=410=180
1128=99=18135=X49=SAMPLE75=2016101134=212752=2016033114395697685401660=201603311439569768540165799=10000100268=1279=1269=148=17359555=6SZ683=357556270=10219.0271=21346=81023=410=176
1128=99=18135=X49=SAMPLE75=2016101134=259652=2008012704073503224409660=200801270407350322440965799=10000100268=1279=1269=148=17359555=6SZ683=357557270=10219.0271=28346=91023=410=162
1128=99=18135=X49=SAMPLE75=2016101134=444152=2004050321192971839411260=200405032119297183941125799=10000100268=1279=1269=148=17359555=6SZ683=357558270=10219.0271=21346=81023=410=191
1128=99=18135=X49=SAMPLE75=2016101134=182552=2017021210321720910521660=201702121032172091052165799=10000100268=1279=1269=048=17359555=6SZ683=357559270=10213.0271=18346=91023=210=196
1128=99=18135=X49=SAMPLE75=2016101134=78952=2005020703032991849273660=200502070303299184927365799=10000100268=1279=1269=148=17359555=6SZ683=357560270=10216.0271=17346=81023=110=204
1128=99=18035=X49=SAMPLE75=2016101134=200552=2017020304130249503724860=201702030413024950372485799=10000100268=1279=0269=148=17359555=6SZ683=357561270=10215.0271=1346=11023=110=122
1128=99=17935=X49=SAMPLE75=2016101134=153652=2011032314390200900262460=201103231439020090026245799=10000100268=1279=0269=148=17360055=6SH783=99335270=10271.0271=3346=11023=110=031
1128=99=20835=X49=SAMPLE75=2016101134=445852=2002071003271975014803260=200207100327197501480325799=00000001268=1279=0269=248=17359555=6SZ683=357562270=10215.0271=1346=25797=137705=237=032=137=032=110=069
1128=99=15635=X49=SAMPLE75=2016101134=157352=2007082917010338229520060=200708291701033822952005799=00000010268=1279=0269=e48=17359555=6SZ683=357563271=7210=101
1128=99=25335=X49=SAMPLE75=2016101134=144052=2001102122215908241799260=200110212221590824179925799=10000100268=2279=2269=148=17359555=6SZ683=357564270=10215.0271=1346=11023=1279=0269=148=17359555=6SZ683=357565270=10225.0271=15346=21023=1010=251
1128=99=18035=X49=SAMPLE75=2016101134=283652=2017030311380539067302460=201703031138053906730245799=10000100268=1279=1269=048=17359555=6SZ683=357566270=10214.0271=5346=51023=110=112
1128=99=18035=X49=SAMPLE75=2016101134=206952=2003042609401752661128060=200304260940175266112805799=10000100268=1279=0269=148=17359555=6SZ683=357567270=10215.0271=1346=11023=110=107
1128=99=17935=X49=SAMPLE75=2016101134=236252=2006092407173724991523260=200609240717372499152325799=10000100268=1279=0269=048=17360055=6SH783=99336270=10268.0271=3346=11023=110=054
1128=99=25135=X49=SAMPLE75=2016101134=343252=2014100403542296515110460=201410040354229651511045799=10000100268=2279=2269=148=17360055=6SH783=99337270=10271.0271=3346=11023=1279=0269=148=17360055=6SH783=99338270=10281.0271=11346=21023=1010=109
1128=99=25035=X49=SAMPLE75=2016101134=374952=2003010903184506686985660=200301090318450668698565799=10000100268=2279=2269=048=17360055=6SH783=99339270=10268.0271=3346=11023=1279=0269=048=17360055=6SH783=99340270=10258.0271=3346=11023=1010=050
1128=99=25035=X49=SAMPLE75=2016101134=98652=2006051520032616658384060=200605152003261665838405799=10000100268=2279=2269=048=17360055=6SH783=99341270=10267.0271=3346=11023=1279=0269=048=17360055=6SH783=99342270=10257.0271=3346=11023=1010=052
1128=99=25335=X49=SAMPLE75=2016101134=59852=2001111501561248283216060=200111150156124828321605799=10000100268=2279=2269=148=17359555=6SZ683=357568270=10215.0271=1346=11023=1279=0269=148=17359555=6SZ683=357569270=10225.0271=15346=21023=1010=011
1128=99=18135=X49=SAMPLE75=2016101134=368052=2013110905354293558393660=201311090535429355839365799=10000100268=1279=1269=148=17359555=6SZ683=357570270=10219.0271=28346=91023=410=167
1128=99=18135=X49=SAMPLE75=2016101134=451052=2003061316423351786856060=200306131642335178685605799=10000100268=1279=1269=148=17359555=6SZ683=357571270=10219.0271=21346=81023=410=175
1128=99=18135=X49=SAMPLE75=2016101134=456352=2009020515344170145100860=200902051534417014510085799=10000100268=1279=1269=148=17359555=6SZ683=357572270=10216.0271=18346=91023=110=186
1128=99=18235=X49=SAMPLE75=2016101134=68752=2017020909363417414419260=201702090936341741441925799=10000100268=1279=1269=048=17359555=6SZ683=357573270=10212.0271=19346=101023=310=235
1128=99=18235=X49=SAMPLE75=2016101134=286252=2005020400085679551852860=200502040008567955185285799=10000100268=1279=1269=048=17359555=6SZ683=357574270=10213.0271=19346=101023=210=243
1128=99=18035=X49=SAMPLE75=2016101134=414852=2008020703054285869276860=200802070305428586927685799=10000100268=1279=0269=148=17359555=6SZ683=357575270=10215.0271=1346=11023=110=087
1128=99=17935=X49=SAMPLE75=2016101134=34752=2015050509314612761241660=201505050931461276124165799=10000100268=1279=0269=148=17360055=6SH783=99343270=10271.0271=3346=11023=110=030
1128=99=20835=X49=SAMPLE75=2016101134=259952=2003092105414380360368060=200309210541438036036805799=00000001268=1279=0269=248=17359555=6SZ683=357576270=10215.0271=1346=25797=137705=237=032=137=032=110=066
1128=99=15635=X49=SAMPLE75=2016101134=293352=2001101323144401511060060=200110132314440151106005799=00000010268=1279=0269=e48=17359555=6SZ683=357577271=7310=087
1128=99=25335=X49=SAMPLE75=2016101134=104252=2007093022505288184969660=200709302250528818496965799=10000100268=2279=2269=148=17359555=6SZ683=357578270=10215.0271=1346=11023=1279=0269=148=17359555=6SZ683=357579270=10225.0271=15346=21023=1010=241
1128=99=18035=X49=SAMPLE75=2016101134=113852=2008042903475126597097660=200804290347512659709765799=10000100268=1279=0269=148=17359555=6SZ683=357580270=10215.0271=1346=11023=110=109
1128=99=17935=X49=SAMPLE75=2016101134=470652=2016021504521427328083260=201602150452142732808325799=10000100268=1279=0269=048=17360055=6SH783=99344270=10268.0271=3346=11023=110=037
1128=99=25135=X49=SAMPLE75=2016101134=38752=2014031514030989915360060=201403151403098991536005799=10000100268=2279=2269=148=17360055=6SH783=99345270=10271.0271=3346=11023=1279=0269=148=17360055=6SH783=99346270=10281.0271=11346=21023=1010=079
1128=99=17935=X49=SAMPLE75=2016101134=126052=2014041312361436658265660=201404131236143665826565799=10000100268=1279=0269=048=17360055=6SH783=99347270=10267.0271=3346=11023=210=035
1128=99=25035=X49=SAMPLE75=2016101134=183552=2004062000005128052624060=200406200000512805262405799=10000100268=2279=2269=048=17360055=6SH783=99348270=10268.0271=3346=11023=1279=0269=048=17360055=6SH783=99349270=10258.0271=3346=11023=1010=020
1128=99=25335=X49=SAMPLE75=2016101134=314252=2011082306282914161779260=201108230628291416177925799=10000100268=2279=2269=148=17359555=6SZ683=357581270=10215.0271=1346=11023=1279=0269=148=17359555=6SZ683=357582270=10225.0271=15346=21023=1010=225
1128=99=25035=X49=SAMPLE75=2016101134=498652=2009051107131783848512060=200905110713178384851205799=10000100268=2279=2269=048=17360055=6SH783=99350270=10267.0271=3346=11023=1279=0269=048=17360055=6SH783=99351270=10257.0271=3346=11023=1010=015
1128=99=18035=X49=SAMPLE75=2016101134=357852=2014091306230624849888060=201409130623062484988805799=10000100268=1279=1269=048=17359555=6SZ683=357583270=10214.0271=6346=61023=110=092
1128=99=17935=X49=SAMPLE75=2016101134=141652=2010030608494304694176060=201003060849430469417605799=10000100268=1279=0269=048=17360055=6SH783=99352270=10267.0271=3346=11023=110=019
1128=99=18135=X49=SAMPLE75=2016101134=74152=2008091702365844111596860=200809170236584411159685799=10000100268=1279=1269=148=17359555=6SZ683=357584270=10219.0271=28346=91023=410=173
1128=99=18135=X49=SAMPLE75=2016101134=426052=2002080320275134625332860=200208032027513462533285799=10000100268=1279=1269=148=17359555=6SZ683=357585270=10219.0271=21346=81023=410=175
1128=99=25335=X49=SAMPLE75=2016101134=65652=2009112016413937066540860=200911201641393706654085799=10000100268=2279=1269=048=17359555=6SZ683=357586270=10210.0271=27346=91023=5279=1269=048=17359555=6SZ683=357587270=10209.0271=23346=81023=610=020
1128=99=18135=X49=SAMPLE75=2016101134=64252=2004022718264911742832060=200402271826491174283205799=10000100268=1279=1269=148=17359555=6SZ683=357588270=10219.0271=28346=91023=410=176
1128=99=18235=X49=SAMPLE75=2016101134=9152=2012110708362350175276860=201211070836235017527685799=10000100268=1279=1269=048=17359555=6SZ683=357589270=10210.0271=34346=101023=510=194
1128=99=18035=X49=SAMPLE75=2016101134=73352=2013100923342343979641660=201310092334234397964165799=10000100268=1279=0269=148=17359555=6SZ683=357590270=10215.0271=1346=11023=110=097
1128=99=17935=X49=SAMPLE75=2016101134=478152=2005122514402364306601660=200512251440236430660165799=10000100268=1279=0269=148=17360055=6SH783=99353270=10271.0271=3346=11023=110=022
1128=99=20835=X49=SAMPLE75=2016101134=250352=2015070815505107140473660=201507081550510714047365799=00000001268=1279=0269=248=17359555=6SZ683=357591270=10215.0271=1346=25797=137705=237=032=137=032=110=083
1128=99=15635=X49=SAMPLE75=2016101134=30952=2015040206361298344390460=201504020636129834439045799=00000010268=1279=0269=e48=17359555=6SZ683=357592271=7410=127
1128=99=25335=X49=SAMPLE75=2016101134=65952=2004061506415069086702460=200406150641506908670245799=10000100268=2279=2269=148=17359555=6SZ683=357593270=10215.0271=1346=11023=1279=0269=148=17359555=6SZ683=357594270=10225.0271=15346=21023=1010=021
1128=99=18035=X49=SAMPLE75=2016101134=196352=2008050517142386824768060=200805051714238682476805799=10000100268=1279=0269=148=17359555=6SZ683=357595270=10215.0271=1346=11023=110=095
1128=99=18035=X49=SAMPLE75=2016101134=91552=2003060309344123447212860=200306030934412344721285799=10000100268=1279=1269=148=17359555=6SZ683=357596270=10215.0271=2346=21023=110=110
1128=99=17935=X49=SAMPLE75=2016101134=356352=2012060305565693377824060=201206030556569337782405799=10000100268=1279=0269=048=17360055=6SH783=99354270=10268.0271=3346=11023=110=029
1128=99=25135=X49=SAMPLE75=2016101134=453252=2013110701013364218310460=201311070101336421831045799=10000100268=2279=2269=148=17360055=6SH783=99355270=10271.0271=3346=11023=1279=0269=148=17360055=6SH783=99356270=10281.0271=11346=21023=1010=072
1128=99=18035=X49=SAMPLE75=2016101134=83952=2001010701150419830628460=200101070115041983062845799=10000100268=1279=1269=148=17359555=6SZ683=357597270=10215.0271=1346=11023=110=102
1128=99=25035=X49=SAMPLE75=2016101134=436652=2002021622481975775024060=200202162248197577502405799=10000100268=2279=2269=048=17360055=6SH783=99357270=10268.0271=3346=11023=1279=0269=048=17360055=6SH783=99358270=10258.0271=3346=11023=1010=053
1128=99=22035=X49=SAMPLE75=2016101134=240552=2010050807440978344902460=201005080744097834490245799=00000001268=1279=0269=248=17359555=6SZ683=357598270=10215.0271=1346=25797=137705=237=032=137=621180794538532=110=177
1128=99=15635=X49=SAMPLE75=2016101134=378752=2007032319300122142048060=200703231930012214204805799=00000010268=1279=0269=e48=17359555=6SZ683=357599271=7510=100
1128=99=25335=X49=SAMPLE75=2016101134=117852=2009020320260382222233660=200902032026038222223365799=10000100268=2279=2269=148=17359555=6SZ683=357600270=10215.0271=1346=11023=1279=0269=148=17359555=6SZ683=357601270=10225.0271=15346=21023=1010=220
1128=99=18135=X49=SAMPLE75=2016101134=456152=2003032123285133162617660=200303212328513316261765799=10000100268=1279=1269=148=17359555=6SZ683=357602270=10219.0271=21346=81023=410=140
1128=99=18135=X49=SAMPLE75=2016101134=84052=2004102323323248066908860=200410232332324806690885799=10000100268=1279=1269=148=17359555=6SZ683=357603270=10219.0271=28346=91023=410=149
1128=99=18035=X49=SAMPLE75=2016101134=299052=2013112019223072585184060=201311201922307258518405799=10000100268=1279=1269=048=17359555=6SZ683=357604270=10214.0271=7346=71023=110=099
1128=99=18135=X49=SAMPLE75=2016101134=141252=2007072311441349938979260=200707231144134993897925799=10000100268=1279=1269=148=17359555=6SZ683=357605270=10219.0271=21346=81023=410=165
1128=99=18135=X49=SAMPLE75=2016101134=166752=2000052417172503458023460=200005241717250345802345799=10000100268=1279=1269=148=17359555=6SZ683=357606270=10219.0271=28346=91023=410=162
1128=99=18135=X49=SAMPLE75=2016101134=366352=2009102908123815407948860=200910290812381540794885799=10000100268=1279=1269=148=17359555=6SZ683=357607270=10217.0271=15346=61023=210=136
1128=99=25335=X49=SAMPLE75=2016101134=3252=2009020601281863744281660=200902060128186374428165799=10000100268=2279=1269=048=17359555=6SZ683=357608270=10210.0271=31346=91023=5279=1269=048=17359555=6SZ683=357609270=10209.0271=26346=91023=610=041
1128=99=18135=X49=SAMPLE75=2016101134=277752=2010040816580107790451260=201004081658010779045125799=10000100268=1279=1269=048=17359555=6SZ683=357610270=10210.0271=24346=81023=510=153
1128=99=18135=X49=SAMPLE75=2016101134=401252=2008013118424202613587260=200801311842420261358725799=10000100268=1279=1269=048=17359555=6SZ683=357611270=10210.0271=31346=91023=510=185
1128=99=25435=X49=SAMPLE75=2016101134=140252=2013012320181348660550460=201301232018134866055045799=10000100268=2279=1269=048=17359555=6SZ683=357612270=10210.0271=34346=101023=5279=1269=048=17359555=6SZ683=357613270=10209.0271=23346=81023=610=040
1128=99=18135=X49=SAMPLE75=2016101134=256952=2015110803305259875411260=201511080330525987541125799=10000100268=1279=1269=048=17359555=6SZ683=357614270=10210.0271=27346=91023=510=161
1128=99=18235=X49=SAMPLE75=2016101134=438952=2012121214400684594585660=201212121440068459458565799=10000100268=1279=1269=048=17359555=6SZ683=357615270=10210.0271=34346=101023=510=203
1128=99=18135=X49=SAMPLE75=2016101134=116752=2009080105125229839276860=200908010512522983927685799=10000100268=1279=1269=148=17359555=6SZ683=357616270=10216.0271=17346=81023=110=202
1128=99=25335=X49=SAMPLE75=2016101134=272452=2008033117403199648953660=200803311740319964895365799=10000100268=2279=1269=048=17359555=6SZ683=357617270=10210.0271=31346=91023=5279=1269=048=17359555=6SZ683=357618270=10209.0271=26346=91023=610=017
1128=99=18135=X49=SAMPLE75=2016101134=218852=2010100616285495844025660=201010061628549584402565799=10000100268=1279=1269=148=17359555=6SZ683=357619270=10219.0271=21346=81023=410=168
1128=99=18135=X49=SAMPLE75=2016101134=352152=2003021018305343295723260=200302101830534329572325799=10000100268=1279=1269=148=17359555=6SZ683=357620270=10219.0271=28346=91023=410=157
1128=99=18135=X49=SAMPLE75=2016101134=342752=2017012909570699494163260=201701290957069949416325799=10000100268=1279=1269=148=17359555=6SZ683=357621270=10219.0271=21346=81023=410=182
1128=99=18135=X49=SAMPLE75=2016101134=256352=2011071517122373433100860=201107151712237343310085799=10000100268=1279=1269=148=17359555=6SZ683=357622270=10217.0271=16346=71023=210=183
1128=99=18135=X49=SAMPLE75=2016101134=407052=2007102508403969630678460=200710250840396963067845799=10000100268=1279=1269=148=17359555=6SZ683=357623270=10219.0271=28346=91023=410=168
1128=99=18135=X49=SAMPLE75=2016101134=7552=2016101120353600643859260=201610112035360064385925799=10000100268=1279=1269=148=17359555=6SZ683=357624270=10219.0271=25346=81023=410=128
1128=99=18135=X49=SAMPLE75=2016101134=359152=2003021516400639552593660=200302151640063955259365799=10000100268=1279=1269=148=17359555=6SZ683=357625270=10219.0271=22346=71023=410=144
1128=99=18235=X49=SAMPLE75=2016101134=124452=2003073122034469325572860=200307312203446932557285799=10000100268=1279=1269=048=17359555=6SZ683=357626270=10205.0271=22346=51023=1010=199
1128=99=18235=X49=SAMPLE75=2016101134=170552=2008042615234173420329660=200804261523417342032965799=10000100268=1279=1269=048=17359555=6SZ683=357627270=10205.0271=19346=41023=1010=210
1128=99=25435=X49=SAMPLE75=2016101134=128352=2014120522370916910611260=201412052237091691061125799=10000100268=2279=1269=048=17359555=6SZ683=357628270=10210.0271=34346=101023=5279=1269=048=17359555=6SZ683=357629270=10209.0271=23346=81023=610=066
1128=99=25335=X49=SAMPLE75=2016101134=351652=2012050302071959369356860=201205030207195936935685799=10000100268=2279=1269=048=17359555=6SZ683=357630270=10210.0271=31346=91023=5279=1269=048=17359555=6SZ683=357631270=10209.0271=26346=91023=610=249
1128=99=25435=X49=SAMPLE75=2016101134=11752=2015092414172952921683260=201509241417295292168325799=10000100268=2279=1269=048=17359555=6SZ683=357632270=10210.0271=34346=101023=5279=1269=048=17359555=6SZ683=357633270=10209.0271=23346=81023=610=051
1128=99=25335=X49=SAMPLE75=2016101134=317052=2016052017085887824000060=201605201708588782400005799=10000100268=2279=1269=048=17359555=6SZ683=357634270=10210.0271=31346=91023=5279=1269=048=17359555=6SZ683=357635270=10209.0271=26346=91023=610=014
1128=99=18135=X49=SAMPLE75=2016101134=61652=2001122206412748287893660=200112220641274828789365799=10000100268=1279=1269=148=17359555=6SZ683=357636270=10219.0271=15346=61023=410=162
1128=99=18135=X49=SAMPLE75=2016101134=117752=2010111510033964582515260=201011151003396458251525799=10000100268=1279=1269=148=17359555=6SZ683=357637270=10219.0271=22346=71023=410=179
1128=99=18035=X49=SAMPLE75=2016101134=310252=2015030902410606307398460=201503090241060630739845799=10000100268=1279=1269=048=17359555=6SZ683=357638270=10214.0271=6346=61023=110=103
1128=99=18035=X49=SAMPLE75=2016101134=39552=2002072711571447215153660=200207271157144721515365799=10000100268=1279=1269=048=17359555=6SZ683=357639270=10214.0271=7346=71023=110=098
1128=99=25435=X49=SAMPLE75=2016101134=98252=2009021614424196420889660=200902161442419642088965799=10000100268=2279=1269=048=17359555=6SZ683=357640270=10210.0271=34346=101023=5279=1269=048=17359555=6SZ683=357641270=10209.0271=23346=81023=610=028
1128=99=25335=X49=SAMPLE75=2016101134=226152=2002051615272637062147260=200205161527263706214725799=10000100268=2279=1269=048=17359555=6SZ683=357642270=10210.0271=31346=91023=5279=1269=048=17359555=6SZ683=357643270=10209.0271=26346=91023=610=018
1128=99=18035=X49=SAMPLE75=2016101134=26252=2011022008230837977740860=201102200823083797774085799=10000100268=1279=1269=048=17359555=6SZ683=357644270=10214.0271=6346=61023=110=083
1128=99=18035=X49=SAMPLE75=2016101134=361952=2003061807265173185521660=200306180726517318552165799=10000100268=1279=1269=048=17359555=6SZ683=357645270=10214.0271=7346=71023=110=116
1128=99=25435=X49=SAMPLE75=2016101134=44052=2003061800072784163811260=200306180007278416381125799=10000100268=2279=1269=048=17359555=6SZ683=357646270=10210.0271=34346=101023=5279=1269=048=17359555=6SZ683=357647270=10209.0271=23346=81023=610=055
1128=99=25335=X49=SAMPLE75=2016101134=481952=2010041420181161049792060=201004142018116104979205799=10000100268=2279=1269=048=17359555=6SZ683=357648270=10210.0271=31346=91023=5279=1269=048=17359555=6SZ683=357649270=10209.0271=26346=91023=610=007
1128=99=25435=X49=SAMPLE75=2016101134=12152=2008050223113351696710460=200805022311335169671045799=10000100268=2279=1269=048=17359555=6SZ683=357650270=10210.0271=34346=101023=5279=1269=048=17359555=6SZ683=357651270=10209.0271=23346=81023=610=041
1128=99=25335=X49=SAMPLE75=2016101134=20152=2008061118013302871036860=200806111801330287103685799=10000100268=2279=1269=048=17359555=6SZ683=357652270=10210.0271=31346=91023=5279=1269=048=17359555=6SZ683=357653270=10209.0271=26346=91023=610=027
1128=99=25435=X49=SAMPLE75=2016101134=360152=2011120503135078818470460=201112050313507881847045799=10000100268=2279=1269=048=17359555=6SZ683=357654270=10210.0271=34346=101023=5279=1269=048=17359555=6SZ683=357655270=10209.0271=23346=81023=610=060
1128=99=25335=X49=SAMPLE75=2016101134=115052=2000072914031815751376060=200007291403181575137605799=10000100268=2279=1269=048=17359555=6SZ683=357656270=10210.0271=31346=91023=5279=1269=048=17359555=6SZ683=357657270=10209.0271=26346=91023=610=012
1128=99=18135=X49=SAMPLE75=2016101134=114352=2011122117320837796582460=201112211732083779658245799=10000100268=1279=1269=148=17359555=6SZ683=357658270=10219.0271=15346=61023=410=139
1128=99=18135=X49=SAMPLE75=2016101134=418552=2016022522010699895616060=201602252201069989561605799=10000100268=1279=1269=148=17359555=6SZ683=357659270=10219.0271=22346=71023=410=158
1128=99=25435=X49=SAMPLE75=2016101134=39352=2007090606554177932652860=200709060655417793265285799=10000100268=2279=1269=048=17359555=6SZ683=357660270=10210.0271=34346=101023=5279=1269=048=17359555=6SZ683=357661270=10209.0271=23346=81023=610=050
1128=99=25235=X49=SAMPLE75=2016101134=121452=2013082004030814738419260=201308200403081473841925799=10000100268=2279=1269=048=17359555=6SZ683=357662270=10214.0271=8346=81023=1279=1269=048=17359555=6SZ683=357663270=10213.0271=18346=91023=210=226
1128=99=25335=X49=SAMPLE75=2016101134=78552=2005091923530355520582460=200509192353035552058245799=10000100268=2279=1269=148=17359555=6SZ683=357664270=10216.0271=16346=71023=1279=1269=148=17359555=6SZ683=357665270=10217.0271=17346=81023=210=034
1128=99=25335=X49=SAMPLE75=2016101134=176552=2003030721152128657464060=200303072115212865746405799=10000100268=2279=1269=148=17359555=6SZ683=357666270=10221.0271=43346=91023=6279=1269=148=17359555=6SZ683=357667270=10222.0271=30346=61023=710=030
1128=99=25435=X49=SAMPLE75=2016101134=164452=2009032319151153689305660=200903231915115368930565799=10000100268=2279=1269=148=17359555=6SZ683=357668270=10221.0271=46346=101023=6279=1269=148=17359555=6SZ683=357669270=10222.0271=27346=51023=710=075
1128=99=25335=X49=SAMPLE75=2016101134=392552=2006011023590044608585660=200601102359004460858565799=10000100268=2279=1269=048=17359555=6SZ683=357670270=10214.0271=7346=71023=1279=1269=048=17359555=6SZ683=357671270=10213.0271=19346=101023=210=242
1128=99=25335=X49=SAMPLE75=2016101134=228052=2015072104422233024896060=201507210442223302489605799=10000100268=2279=1269=148=17359555=6SZ683=357672270=10216.0271=17346=81023=1279=1269=148=17359555=6SZ683=357673270=10217.0271=16346=71023=210=251
1128=99=25335=X49=SAMPLE75=2016101134=373852=2016103022302550635040060=201610302230255063504005799=10000100268=2279=1269=148=17359555=6SZ683=357674270=10221.0271=43346=91023=6279=1269=148=17359555=6SZ683=357675270=10222.0271=30346=61023=710=008
1128=99=25335=X49=SAMPLE75=2016101134=277852=2006102108500577563385660=200610210850057756338565799=10000100268=2279=1269=148=17359555=6SZ683=357676270=10216.0271=16346=71023=1279=1269=148=17359555=6SZ683=357677270=10217.0271=17346=81023=210=029
1128=99=25235=X49=SAMPLE75=2016101134=416752=2009121605325635049920060=200912160532563504992005799=10000100268=2279=1269=048=17359555=6SZ683=357678270=10214.0271=8346=81023=1279=1269=048=17359555=6SZ683=357679270=10213.0271=18346=91023=210=245
1128=99=25435=X49=SAMPLE75=2016101134=145452=2016012110293165814278460=201601211029316581427845799=10000100268=2279=1269=148=17359555=6SZ683=357680270=10221.0271=46346=101023=6279=1269=148=17359555=6SZ683=357681270=10222.0271=27346=51023=710=075
1128=99=25335=X49=SAMPLE75=2016101134=478352=2012040607585322517049660=201204060758532251704965799=10000100268=2279=1269=048=17359555=6SZ683=357682270=10214.0271=7346=71023=1279=1269=048=17359555=6SZ683=357683270=10213.0271=19346=101023=210=013
1128=99=25335=X49=SAMPLE75=2016101134=112552=2003101206100403211499260=200310120610040321149925799=10000100268=2279=1269=148=17359555=6SZ683=357684270=10216.0271=17346=81023=1279=1269=148=17359555=6SZ683=357685270=10217.0271=16346=71023=210=043
1128=99=25335=X49=SAMPLE75=2016101134=463352=2000123105253101161223260=200012310525310116122325799=10000100268=2279=1269=148=17359555=6SZ683=357686270=10221.0271=43346=91023=6279=1269=148=17359555=6SZ683=357687270=10222.0271=30346=61023=710=047
1128=99=25235=X49=SAMPLE75=2016101134=354652=2010121919372644972390460=201012191937264497239045799=10000100268=2279=1269=048=17359555=6SZ683=357688270=10214.0271=8346=81023=1279=1269=048=17359555=6SZ683=357689270=10213.0271=18346=91023=210=247
1128=99=25335=X49=SAMPLE75=2016101134=177652=2007122807405210381203260=200712280740521038120325799=10000100268=2279=1269=148=17359555=6SZ683=357690270=10216.0271=16346=71023=1279=1269=148=17359555=6SZ683=357691270=10217.0271=17346=81023=210=023
1128=99=25335=X49=SAMPLE75=2016101134=96652=2001060100300713441403260=200106010030071344140325799=10000100268=2279=1269=048=17359555=6SZ683=357692270=10214.0271=7346=71023=1279=1269=048=17359555=6SZ683=357693270=10213.0271=19346=101023=210=022
1128=99=25335=X49=SAMPLE75=2016101134=29552=2006052916011306461699260=200605291601130646169925799=10000100268=2279=1269=148=17359555=6SZ683=357694270=10216.0271=17346=81023=1279=1269=148=17359555=6SZ683=357695270=10217.0271=16346=71023=210=041
1128=99=25435=X49=SAMPLE75=2016101134=203552=2006051322102991163648060=200605132210299116364805799=10000100268=2279=1269=148=17359555=6SZ683=357696270=10221.0271=46346=101023=6279=1269=148=17359555=6SZ683=357697270=10222.0271=27346=51023=710=108
1128=99=18135=X49=SAMPLE75=2016101134=420252=2011020903373582243193660=201102090337358224319365799=10000100268=1279=1269=148=17359555=6SZ683=357698270=10219.0271=15346=61023=410=191
1128=99=18135=X49=SAMPLE75=2016101134=363152=2011022112494542611980860=201102211249454261198085799=10000100268=1279=1269=148=17359555=6SZ683=357699270=10219.0271=22346=71023=410=173
1128=99=18135=X49=SAMPLE75=2016101134=240752=2009040505092512391641660=200904050509251239164165799=10000100268=1279=1269=148=17359555=6SZ683=357700270=10219.0271=15346=61023=410=159
1128=99=18135=X49=SAMPLE75=2016101134=69752=2012012909452551510496060=201201290945255151049605799=10000100268=1279=1269=148=17359555=6SZ683=357701270=10219.0271=22346=71023=410=165
1128=99=18135=X49=SAMPLE75=2016101134=323152=2016041422171008874521660=201604142217100887452165799=10000100268=1279=1269=148=17359555=6SZ683=357702270=10219.0271=15346=61023=410=158
1128=99=18135=X49=SAMPLE75=2016101134=344152=2005041921314964710380860=200504192131496471038085799=10000100268=1279=1269=148=17359555=6SZ683=357703270=10219.0271=22346=71023=410=168
1128=99=18135=X49=SAMPLE75=2016101134=70552=2006013100013698401177660=200601310001369840117765799=10000100268=1279=1269=148=17359555=6SZ683=357704270=10219.0271=15346=61023=410=198
1128=99=22035=X49=SAMPLE75=2016101134=210752=2011112517080065103974460=201111251708006510397445799=00000001268=1279=0269=248=17359555=6SZ683=357705270=10214.0271=1346=25797=237705=237=032=137=621180794447232=110=198
1128=99=15635=X49=SAMPLE75=2016101134=304052=2002100619341051748651260=200210061934105174865125799=00000010268=1279=0269=e48=17359555=6SZ683=357706271=7610=113
1128=99=18035=X49=SAMPLE75=2016101134=207152=2012101721533397722163260=201210172153339772216325799=10000100268=1279=1269=048=17359555=6SZ683=357707270=10214.0271=6346=61023=110=120
1128=99=17935=X49=SAMPLE75=2016101134=99252=2010071007573120165900860=201007100757312016590085799=10000100268=1279=0269=148=17360055=6SH783=99359270=10271.0271=3346=11023=110=054
1128=99=25135=X49=SAMPLE75=2016101134=375652=2014052705170817499801660=201405270517081749980165799=10000100268=2279=2269=148=17360055=6SH783=99360270=10271.0271=3346=11023=1279=0269=148=17360055=6SH783=99361270=10281.0271=11346=21023=1010=083
1128=99=18035=X49=SAMPLE75=2016101134=295752=2012100613025950895705660=201210061302595089570565799=10000100268=1279=1269=048=17359555=6SZ683=357708270=10214.0271=7346=71023=110=117
1128=99=18135=X49=SAMPLE75=2016101134=496852=2016030214041207575072060=201603021404120757507205799=10000100268=1279=1269=148=17359555=6SZ683=357709270=10219.0271=22346=71023=410=177
1128=99=18135=X49=SAMPLE75=2016101134=155652=2000030606212175707505760=200003060621217570750575799=10000100268=1279=1269=148=17359555=6SZ683=357710270=10219.0271=15346=61023=410=181
1128=99=18135=X49=SAMPLE75=2016101134=177952=2001052503363613815698460=200105250336361381569845799=10000100268=1279=1269=148=17359555=6SZ683=357711270=10219.0271=22346=71023=410=174
1128=99=18135=X49=SAMPLE75=2016101134=74852=2000072623133026313726060=200007262313302631372605799=10000100268=1279=1269=148=17359555=6SZ683=357712270=10219.0271=15346=61023=410=179
1128=99=25335=X49=SAMPLE75=2016101134=450552=2001020221143300294042860=200102022114330029404285799=10000100268=2279=1269=048=17359555=6SZ683=357713270=10210.0271=31346=91023=5279=1269=048=17359555=6SZ683=357714270=10209.0271=26346=91023=610=011
1128=99=18135=X49=SAMPLE75=2016101134=285352=2011071610575709545536060=201107161057570954553605799=10000100268=1279=1269=148=17359555=6SZ683=357715270=10219.0271=22346=71023=410=145
1128=99=18135=X49=SAMPLE75=2016101134=432452=2005032618365132373756860=200503261836513237375685799=10000100268=1279=1269=148=17359555=6SZ683=357716270=10219.0271=15346=61023=410=162
1128=99=18135=X49=SAMPLE75=2016101134=462152=2001090820195697641683260=200109082019569764168325799=10000100268=1279=1269=148=17359555=6SZ683=357717270=10219.0271=22346=71023=410=147
1128=99=18135=X49=SAMPLE75=2016101134=290752=2000080805325869145357260=200008080532586914535725799=10000100268=1279=1269=148=17359555=6SZ683=357718270=10219.0271=15346=61023=410=161
1128=99=18135=X49=SAMPLE75=2016101134=328452=2012060111035347581395260=201206011103534758139525799=10000100268=1279=1269=148=17359555=6SZ683=357719270=10219.0271=22346=71023=410=165
1128=99=25435=X49=SAMPLE75=2016101134=478952=2012090106253877432633660=201209010625387743263365799=10000100268=2279=1269=048=17359555=6SZ683=357720270=10210.0271=34346=101023=5279=1269=048=17359555=6SZ683=357721270=10209.0271=23346=81023=610=013
1128=99=18135=X49=SAMPLE75=2016101134=307352=2012052623564022855840060=201205262356402285584005799=10000100268=1279=1269=148=17359555=6SZ683=357722270=10219.0271=15346=61023=410=153
1128=99=25335=X49=SAMPLE75=2016101134=94652=2011102017593826972518460=201110201759382697251845799=10000100268=2279=1269=048=17359555=6SZ683=357723270=10210.0271=31346=91023=5279=1269=048=17359555=6SZ683=357724270=10209.0271=26346=91023=610=029
1128=99=18035=X49=SAMPLE75=2016101134=374952=2005100715485573393116860=200510071548557339311685799=10000100268=1279=1269=048=17359555=6SZ683=357725270=10214.0271=6346=61023=110=110
1128=99=18035=X49=SAMPLE75=2016101134=223652=2001111510423754410761660=200111151042375441076165799=10000100268=1279=1269=048=17359555=6SZ683=357726270=10214.0271=7346=71023=110=102
1128=99=18035=X49=SAMPLE75=2016101134=2852=2003121000124615057508860=200312100012461505750885799=10000100268=1279=1269=048=17359555=6SZ683=357727270=10214.0271=6346=61023=110=099
1128=99=18035=X49=SAMPLE75=2016101134=31252=2002022620525291205204860=200202262052529120520485799=10000100268=1279=1269=048=17359555=6SZ683=357728270=10214.0271=7346=71023=110=111
1128=99=18035=X49=SAMPLE75=2016101134=489952=2003050112173500285062460=200305011217350028506245799=10000100268=1279=1269=048=17359555=6SZ683=357729270=10214.0271=6346=61023=110=099
1128=99=25335=X49=SAMPLE75=2016101134=254752=2005120107121283220428860=200512010712128322042885799=10000100268=2279=1269=148=17359555=6SZ683=357730270=10220.0271=33346=91023=5279=1269=148=17359555=6SZ683=357731270=10221.0271=43346=91023=610=040
1128=99=25435=X49=SAMPLE75=2016101134=332452=2008060115481279922601660=200806011548127992260165799=10000100268=2279=1269=048=17359555=6SZ683=357732270=10213.0271=18346=91023=2279=1269=048=17359555=6SZ683=357733270=10212.0271=20346=111023=310=055
1128=99=18035=X49=SAMPLE75=2016101134=339352=2009112119380522818201660=200911211938052281820165799=10000100268=1279=1269=048=17359555=6SZ683=357734270=10214.0271=7346=71023=110=098
1128=99=25535=X49=SAMPLE75=2016101134=490552=2001101115361061345848060=200110111536106134584805799=10000100268=2279=1269=048=17359555=6SZ683=357735270=10213.0271=19346=101023=2279=1269=048=17359555=6SZ683=357736270=10212.0271=19346=101023=310=092
1128=99=25435=X49=SAMPLE75=2016101134=6152=2003052516534029176800060=200305251653402917680005799=10000100268=2279=1269=148=17359555=6SZ683=357737270=10220.0271=30346=81023=5279=1269=148=17359555=6SZ683=357738270=10221.0271=46346=101023=610=041
1128=99=18135=X49=SAMPLE75=2016101134=74352=2006050106493044893443260=200605010649304489344325799=10000100268=1279=1269=048=17359555=6SZ683=357739270=10214.0271=10346=81023=110=176
1128=99=18135=X49=SAMPLE75=2016101134=337452=2010080123124749054265660=201008012312474905426565799=10000100268=1279=1269=148=17359555=6SZ683=357740270=10219.0271=22346=71023=410=141
1128=99=18135=X49=SAMPLE75=2016101134=85252=2014011502423263685574460=201401150242326368557445799=10000100268=1279=1269=048=17359555=6SZ683=357741270=10213.0271=18346=91023=210=181
1128=99=18135=X49=SAMPLE75=2016101134=157452=2007080115171706581507260=200708011517170658150725799=10000100268=1279=1269=048=17359555=6SZ683=357742270=10214.0271=11346=91023=110=174
1128=99=18135=X49=SAMPLE75=2016101134=452252=2000012009312503127953360=200001200931250312795335799=10000100268=1279=1269=048=17359555=6SZ683=357743270=10214.0271=10346=81023=110=155
1128=99=18135=X49=SAMPLE75=2016101134=298552=2012032018113410914912060=201203201811341091491205799=10000100268=1279=1269=148=17359555=6SZ683=357744270=10219.0271=15346=61023=410=162
1128=99=18135=X49=SAMPLE75=2016101134=253952=2002110309044033762403260=200211030904403376240325799=10000100268=1279=1269=148=17359555=6SZ683=357745270=10219.0271=22346=71023=410=178
1128=99=18135=X49=SAMPLE75=2016101134=144252=2002071822252487860459260=200207182225248786045925799=10000100268=1279=1269=148=17359555=6SZ683=357746270=10219.0271=15346=61023=410=185
1128=99=18135=X49=SAMPLE75=2016101134=343552=2016060809355220651584060=201606080935522065158405799=10000100268=1279=1269=148=17359555=6SZ683=357747270=10217.0271=15346=61023=210=174
1128=99=18235=X49=SAMPLE75=2016101134=81952=2006010800345444501939260=200601080034544450193925799=10000100268=1279=1269=048=17359555=6SZ683=357748270=10213.0271=19346=101023=210=234
1128=99=18135=X49=SAMPLE75=2016101134=390152=2004060913372002418659260=200406091337200241865925799=10000100268=1279=1269=148=17359555=6SZ683=357749270=10218.0271=16346=71023=310=187
1128=99=18135=X49=SAMPLE75=2016101134=84552=2015052807091584721881660=201505280709158472188165799=10000100268=1279=1269=148=17359555=6SZ683=357750270=10219.0271=22346=71023=410=165
1128=99=18135=X49=SAMPLE75=2016101134=302252=2012013122545372852422460=201201312254537285242245799=10000100268=1279=1269=148=17359555=6SZ683=357751270=10216.0271=18346=91023=110=186
1128=99=18135=X49=SAMPLE75=2016101134=393252=2013011205311609015091260=201301120531160901509125799=10000100268=1279=1269=148=17359555=6SZ683=357752270=10217.0271=14346=51023=210=149
1128=99=18135=X49=SAMPLE75=2016101134=89352=2015042204133252832940860=201504220413325283294085799=10000100268=1279=1269=048=17359555=6SZ683=357753270=10207.0271=22346=71023=810=168
1128=99=18135=X49=SAMPLE75=2016101134=29952=2016082107191213511699260=201608210719121351169925799=10000100268=1279=1269=148=17359555=6SZ683=357754270=10219.0271=15346=61023=410=163
1128=99=18135=X49=SAMPLE75=2016101134=438452=2003032814501330546462460=200303281450133054646245799=10000100268=1279=1269=148=17359555=6SZ683=357755270=10219.0271=22346=71023=410=196
1128=99=18135=X49=SAMPLE75=2016101134=487452=2012110304492145103417660=201211030449214510341765799=10000100268=1279=1269=148=17359555=6SZ683=357756270=10216.0271=17346=81023=110=170
1128=99=18135=X49=SAMPLE75=2016101134=291052=2011022706472988633523260=201102270647298863352325799=10000100268=1279=1269=148=17359555=6SZ683=357757270=10219.0271=15346=61023=410=190
1128=99=18135=X49=SAMPLE75=2016101134=448552=2005102604252973483331260=200510260425297348333125799=10000100268=1279=1269=048=17359555=6SZ683=357758270=10214.0271=18346=91023=110=185
1128=99=18235=X49=SAMPLE75=2016101134=487152=2013113003452454177708860=201311300345245417770885799=10000100268=1279=1269=048=17359555=6SZ683=357759270=10214.0271=19346=101023=110=201
1128=99=18135=X49=SAMPLE75=2016101134=316152=2001050310451607569960060=200105031045160756996005799=10000100268=1279=1269=048=17359555=6SZ683=357760270=10213.0271=18346=91023=210=176
1128=99=18135=X49=SAMPLE75=2016101134=66452=2015021021170389639168060=201502102117038963916805799=10000100268=1279=1269=148=17359555=6SZ683=357761270=10219.0271=22346=71023=410=178
1128=99=18135=X49=SAMPLE75=2016101134=145652=2004012621195822503806460=200401262119582250380645799=10000100268=1279=1269=148=17359555=6SZ683=357762270=10219.0271=15346=61023=410=144
1128=99=18135=X49=SAMPLE75=2016101134=496652=2009080510583040789011260=200908051058304078901125799=10000100268=1279=1269=148=17359555=6SZ683=357763270=10217.0271=15346=61023=210=135
1128=99=18035=X49=SAMPLE75=2016101134=161152=2001050205280327162770460=200105020528032716277045799=10000100268=1279=0269=048=17359555=6SZ683=357764270=10215.0271=3346=11023=110=125
1128=99=18035=X49=SAMPLE75=2016101134=298252=2003040309130085210848060=200304030913008521084805799=10000100268=1279=1269=148=17359555=6SZ683=357765270=10216.0271=9346=71023=110=144
1128=99=17935=X49=SAMPLE75=2016101134=317152=2008081013274343626777660=200808101327434362677765799=10000100268=1279=0269=048=17360055=6SH783=99362270=10268.0271=3346=11023=110=052
1128=99=18035=X49=SAMPLE75=2016101134=204452=2009032500362556432960060=200903250036255643296005799=10000100268=1279=1269=048=17359555=6SZ683=357766270=10215.0271=4346=21023=110=117
1128=99=18235=X49=SAMPLE75=2016101134=385052=2008061305185759671011260=200806130518575967101125799=10000100268=1279=1269=048=17359555=6SZ683=357767270=10206.0271=39346=51023=1010=234
1128=99=18235=X49=SAMPLE75=2016101134=492352=2010120621172349473971260=201012062117234947397125799=10000100268=1279=1269=048=17359555=6SZ683=357768270=10213.0271=19346=101023=310=214
1128=99=18135=X49=SAMPLE75=2016101134=481852=2013031507295414554259260=201303150729541455425925799=10000100268=1279=1269=048=17359555=6SZ683=357769270=10208.0271=30346=81023=810=193
1128=99=18135=X49=SAMPLE75=2016101134=335752=2009112002383465189011260=200911200238346518901125799=10000100268=1279=1269=048=17359555=6SZ683=357770270=10214.0271=18346=91023=210=198
1128=99=25235=X49=SAMPLE75=2016101134=411052=2011091711232521402054460=201109171123252140205445799=10000100268=2279=1269=148=17359555=6SZ683=357771270=10216.0271=8346=61023=1279=1269=148=17359555=6SZ683=357772270=10220.0271=31346=91023=510=224
1128=99=18035=X49=SAMPLE75=2016101134=148452=2001020217205809547665660=200102021720580954766565799=10000100268=1279=1269=048=17359555=6SZ683=357773270=10215.0271=5346=31023=110=104
1128=99=25035=X49=SAMPLE75=2016101134=461552=2009050608042687570150460=200905060804268757015045799=10000100268=2279=2269=048=17360055=6SH783=99363270=10268.0271=3346=11023=1279=0269=048=17360055=6SH783=99364270=10258.0271=3346=11023=1010=071
1128=99=18135=X49=SAMPLE75=2016101134=482752=2001020503003167829313660=200102050300316782931365799=10000100268=1279=1269=048=17359555=6SZ683=357774270=10211.0271=22346=81023=510=177
1128=99=18135=X49=SAMPLE75=2016101134=291252=2000061313115634327279660=200006131311563432727965799=10000100268=1279=1269=148=17359555=6SZ683=357775270=10216.0271=16346=71023=110=175
1128=99=18035=X49=SAMPLE75=2016101134=250952=2016112002365720341331260=201611200236572034133125799=10000100268=1279=1269=048=17359555=6SZ683=357776270=10215.0271=4346=21023=110=110
1128=99=25335=X49=SAMPLE75=2016101134=269152=2011012418502191442451260=201101241850219144245125799=10000100268=2279=1269=148=17359555=6SZ683=357777270=10216.0271=17346=81023=1279=1269=148=17359555=6SZ683=357778270=10220.0271=30346=81023=510=013
1128=99=18135=X49=SAMPLE75=2016101134=135552=2004031321323696854467260=200403132132369685446725799=10000100268=1279=1269=048=17359555=6SZ683=357779270=10211.0271=15346=71023=510=186
1128=99=18135=X49=SAMPLE75=2016101134=356252=2006041610382754970243260=200604161038275497024325799=10000100268=1279=1269=048=17359555=6SZ683=357780270=10211.0271=22346=81023=510=160
1128=99=18035=X49=SAMPLE75=2016101134=445852=2015041313164186983443260=201504131316418698344325799=10000100268=1279=1269=148=17359555=6SZ683=357781270=10216.0271=9346=71023=110=116
1128=99=18035=X49=SAMPLE75=2016101134=279452=2013091402394329015321660=201309140239432901532165799=10000100268=1279=1269=048=17359555=6SZ683=357782270=10215.0271=5346=31023=110=122
1128=99=25235=X49=SAMPLE75=2016101134=109752=2012081813160490275571260=201208181316049027557125799=10000100268=2279=1269=148=17359555=6SZ683=357783270=10216.0271=8346=61023=1279=1269=148=17359555=6SZ683=357784270=10220.0271=31346=91023=510=220
1128=99=18035=X49=SAMPLE75=2016101134=375352=2005110604390616635228860=200511060439061663522885799=10000100268=1279=1269=048=17359555=6SZ683=357785270=10215.0271=6346=41023=110=108
1128=99=18035=X49=SAMPLE75=2016101134=71452=2005021121001835235408060=200502112100183523540805799=10000100268=1279=1269=048=17359555=6SZ683=357786270=10215.0271=7346=51023=110=112
1128=99=17935=X49=SAMPLE75=2016101134=119452=2001092215001048527900860=200109221500104852790085799=10000100268=1279=0269=048=17360055=6SH783=99365270=10268.0271=3346=11023=110=044
1128=99=24935=X49=SAMPLE75=2016101134=478452=2009050122410711802342460=200905012241071180234245799=10000100268=2279=1269=048=17360055=6SH783=99366270=10267.0271=5346=21023=2279=1269=048=17360055=6SH783=99367270=10265.0271=3346=11023=410=030
1128=99=18135=X49=SAMPLE75=2016101134=247152=2003060423191632916987260=200306042319163291698725799=10000100268=1279=1269=048=17359555=6SZ683=357787270=10208.0271=29346=71023=810=191
1128=99=18035=X49=SAMPLE75=2016101134=459852=2014030606142458198476860=201403060614245819847685799=10000100268=1279=1269=048=17359555=6SZ683=357788270=10215.0271=8346=61023=110=131
1128=99=18135=X49=SAMPLE75=2016101134=357752=2007100702312646828633660=200710070231264682863365799=10000100268=1279=1269=048=17359555=6SZ683=357789270=10208.0271=28346=61023=810=184
1128=99=18035=X49=SAMPLE75=2016101134=116052=2009093008225074495526460=200909300822507449552645799=10000100268=1279=1269=148=17359555=6SZ683=357790270=10216.0271=5346=51023=110=128
1128=99=18035=X49=SAMPLE75=2016101134=486052=2008121823373052023440060=200812182337305202344005799=10000100268=1279=1269=148=17359555=6SZ683=357791270=10216.0271=4346=41023=110=118
1128=99=17935=X49=SAMPLE75=2016101134=43352=2002020113371735351739260=200202011337173535173925799=10000100268=1279=1269=148=17360055=6SH783=99368270=10272.0271=2346=11023=110=036
1128=99=32035=X49=SAMPLE75=2016101134=441052=2015062323381854270214460=201506232338185427021445799=10000100268=3279=2269=148=17360055=6SH783=99369270=10272.0271=2346=11023=1279=1269=148=17360055=6SH783=99370270=10275.0271=5346=21023=3279=0269=148=17360055=6SH783=99371270=10282.0271=3346=11023=1010=015
1128=99=18035=X49=SAMPLE75=2016101134=43952=2007092606511276606454460=200709260651127660645445799=10000100268=1279=1269=148=17359555=6SZ683=357792270=10216.0271=3346=31023=110=124
1128=99=18035=X49=SAMPLE75=2016101134=21952=2004070413432817427900860=200407041343281742790085799=10000100268=1279=1269=148=17359555=6SZ683=357793270=10216.0271=2346=21023=110=110
1128=99=18135=X49=SAMPLE75=2016101134=456052=2011053123290312856403260=201105312329031285640325799=10000100268=1279=1269=048=17359555=6SZ683=357794270=10211.0271=15346=71023=510=159
1128=99=18135=X49=SAMPLE75=2016101134=324252=2010020310224012276115260=201002031022401227611525799=10000100268=1279=1269=048=17359555=6SZ683=357795270=10211.0271=22346=81023=510=150
1128=99=18035=X49=SAMPLE75=2016101134=179652=2002022007342894952277660=200202200734289495227765799=10000100268=1279=1269=148=17359555=6SZ683=357796270=10216.0271=3346=31023=110=135
1128=99=18035=X49=SAMPLE75=2016101134=412552=2015030610065853211769660=201503061006585321176965799=10000100268=1279=1269=048=17359555=6SZ683=357797270=10215.0271=7346=51023=110=168
1128=99=18035=X49=SAMPLE75=2016101134=83452=2011111023093934928812860=201111102309393492881285799=10000100268=1279=1269=148=17359555=6SZ683=357798270=10216.0271=4346=41023=110=153
1128=99=18035=X49=SAMPLE75=2016101134=202352=2016021203011013924249660=201602120301101392424965799=10000100268=1279=1269=048=17359555=6SZ683=357799270=10215.0271=6346=41023=110=119
1128=99=18035=X49=SAMPLE75=2016101134=294752=2006041003112056484076860=200604100311205648407685799=10000100268=1279=1269=048=17359555=6SZ683=357800270=10215.0271=5346=31023=110=094
1128=99=25035=X49=SAMPLE75=2016101134=40152=2014012504394937045484860=201401250439493704548485799=10000100268=2279=2269=048=17360055=6SH783=99372270=10268.0271=3346=11023=1279=0269=048=17360055=6SH783=99373270=10258.0271=3346=11023=1010=059
1128=99=23235=X49=SAMPLE75=2016101134=132652=2016031010115622093760060=201603101011562209376005799=00000001268=1279=0269=248=17359555=6SZ683=357801270=10216.0271=1346=25797=137705=237=621180795450032=137=621180794100832=110=016
1128=99=15635=X49=SAMPLE75=2016101134=475852=2011051514524623907872060=201105151452462390787205799=00000010268=1279=0269=e48=17359555=6SZ683=357802271=7710=086
1128=99=18035=X49=SAMPLE75=2016101134=46952=2009042220064403154246460=200904222006440315424645799=00000100268=1279=1269=148=17359555=6SZ683=357803270=10216.0271=3346=31023=110=088
1128=99=16935=X49=SAMPLE75=2016101134=271852=2005080301054330504361660=200508030105433050436165799=10001000268=1279=0269=748=17359555=6SZ683=357804270=10216.0286=25510=146
1128=99=18035=X49=SAMPLE75=2016101134=321252=2013020420145157403334460=201302042014515740333445799=10000100268=1279=1269=148=17359555=6SZ683=357805270=10216.0271=2346=21023=110=083
1128=99=18035=X49=SAMPLE75=2016101134=218052=2010041109232520809708860=201004110923252080970885799=10000100268=1279=1269=048=17359555=6SZ683=357806270=10215.0271=6346=41023=110=112
1128=99=18035=X49=SAMPLE75=2016101134=87852=2012072615005530961312060=201207261500553096131205799=10000100268=1279=1269=048=17359555=6SZ683=357807270=10215.0271=7346=51023=110=118
1128=99=18035=X49=SAMPLE75=2016101134=236152=2000081220280130212537660=200008122028013021253765799=10000100268=1279=1269=148=17359555=6SZ683=357808270=10216.0271=3346=31023=110=105
1128=99=18035=X49=SAMPLE75=2016101134=24952=2001062410321327196970460=200106241032132719697045799=10000100268=1279=1269=048=17359555=6SZ683=357809270=10215.0271=8346=61023=110=112
1128=99=17935=X49=SAMPLE75=2016101134=103452=2003120501261050494401660=200312050126105049440165799=10000100268=1279=0269=048=17360055=6SH783=99374270=10268.0271=3346=11023=110=040
1128=99=18035=X49=SAMPLE75=2016101134=18452=2002021704273875868560060=200202170427387586856005799=10000100268=1279=1269=148=17359555=6SZ683=357810270=10216.0271=2346=21023=110=101
1128=99=18035=X49=SAMPLE75=2016101134=191652=2006011105190011460896060=200601110519001146089605799=10000100268=1279=1269=148=17359555=6SZ683=357811270=10216.0271=1346=11023=110=103
1128=99=20835=X49=SAMPLE75=2016101134=26652=2001052117413114987585660=200105211741311498758565799=00000001268=1279=0269=248=17359555=6SZ683=357812270=10216.0271=1346=25797=137705=237=032=137=032=110=084
1128=99=15635=X49=SAMPLE75=2016101134=152552=2015043006232613880102460=201504300623261388010245799=00000010268=1279=0269=e48=17359555=6SZ683=357813271=7810=122
1128=99=25335=X49=SAMPLE75=2016101134=318252=2014122912092321472076860=201412291209232147207685799=10000100268=2279=2269=148=17359555=6SZ683=357814270=10216.0271=1346=11023=1279=0269=148=17359555=6SZ683=357815270=10226.0271=15346=21023=1010=010
1128=99=17935=X49=SAMPLE75=2016101134=224252=2010030803481092098848060=201003080348109209884805799=00000100268=1279=0269=048=17360055=6SH783=99375270=10269.0271=3346=11023=110=041
1128=99=16835=X49=SAMPLE75=2016101134=449752=2006080705092663827174460=200608070509266382717445799=10001000268=1279=0269=N48=17360055=6SH783=99376270=10269.0286=25510=117
1128=99=18035=X49=SAMPLE75=2016101134=195352=2012091812470374366809660=201209181247037436680965799=10000100268=1279=1269=048=17359555=6SZ683=357816270=10215.0271=9346=71023=110=132
1128=99=18135=X49=SAMPLE75=2016101134=61452=2016091822262294047750460=201609182226229404775045799=10000100268=1279=1269=048=17359555=6SZ683=357817270=10215.0271=10346=81023=110=177
1128=99=18135=X49=SAMPLE75=2016101134=186552=2002110502030605785420860=200211050203060578542085799=10000100268=1279=1269=048=17359555=6SZ683=357818270=10209.0271=25346=81023=710=180
1128=99=18135=X49=SAMPLE75=2016101134=152852=2006102619252795803084860=200610261925279580308485799=10000100268=1279=1269=148=17359555=6SZ683=357819270=10217.0271=16346=71023=110=181
1128=99=25135=X49=SAMPLE75=2016101134=183752=2014031512374241546931260=201403151237424154693125799=10000100268=2279=2269=048=17360055=6SH783=99377270=10269.0271=3346=11023=1279=0269=048=17360055=6SH783=99378270=10259.0271=11346=21023=1010=131
1128=99=25335=X49=SAMPLE75=2016101134=449452=2016112620362459539795260=201611262036245953979525799=10000100268=2279=1269=148=17359555=6SZ683=357820270=10220.0271=23346=81023=4279=1269=148=17359555=6SZ683=357821270=10224.0271=44346=51023=810=008
1128=99=17935=X49=SAMPLE75=2016101134=323452=2002011116544842641994460=200201111654484264199445799=10000100268=1279=1269=148=17360055=6SH783=99379270=10279.0271=3346=11023=710=067
1128=99=18135=X49=SAMPLE75=2016101134=299252=2008042105041142217315260=200804210504114221731525799=10000100268=1279=1269=148=17359555=6SZ683=357822270=10220.0271=16346=71023=410=165
1128=99=18035=X49=SAMPLE75=2016101134=243552=2009050806422423938835260=200905080642242393883525799=10000100268=1279=0269=148=17359555=6SZ683=357823270=10216.0271=1346=11023=110=097
1128=99=17935=X49=SAMPLE75=2016101134=225252=2017031215452504002240060=201703121545250400224005799=10000100268=1279=0269=148=17360055=6SH783=99380270=10272.0271=3346=11023=110=043
1128=99=25235=X49=SAMPLE75=2016101134=298652=2000122619075993801090460=200012261907599380109045799=10000100268=2279=1269=148=17359555=6SZ683=357824270=10216.0271=2346=21023=1279=1269=148=17359555=6SZ683=357825270=10217.0271=15346=61023=210=220
1128=99=18035=X49=SAMPLE75=2016101134=317752=2011052723043220058496060=201105272304322005849605799=10000100268=1279=1269=048=17359555=6SZ683=357826270=10215.0271=9346=71023=110=115
1128=99=18035=X49=SAMPLE75=2016101134=409052=2003053119215073937771260=200305311921507393777125799=10000100268=1279=1269=048=17359555=6SZ683=357827270=10215.0271=8346=61023=110=132
1128=99=25335=X49=SAMPLE75=2016101134=217052=2005062809572307954915260=200506280957230795491525799=10000100268=2279=1269=148=17359555=6SZ683=357828270=10220.0271=19346=81023=5279=1269=148=17359555=6SZ683=357829270=10221.0271=43346=91023=610=046
1128=99=25035=X49=SAMPLE75=2016101134=84852=2005070511431894384284860=200507051143189438428485799=10000100268=2279=2269=148=17360055=6SH783=99381270=10272.0271=3346=11023=1279=0269=148=17360055=6SH783=99382270=10282.0271=3346=11023=1010=063
1128=99=18135=X49=SAMPLE75=2016101134=227452=2012051515365854587366460=201205151536585458736645799=10000100268=1279=1269=148=17359555=6SZ683=357830270=10220.0271=26346=91023=510=171
1128=99=18035=X49=SAMPLE75=2016101134=299852=2000021712180139441379660=200002171218013944137965799=10000100268=1279=1269=148=17359555=6SZ683=357831270=10216.0271=3346=31023=110=124
1128=99=18035=X49=SAMPLE75=2016101134=240152=2000051002121663977301060=200005100212166397730105799=10000100268=1279=1269=148=17359555=6SZ683=357832270=10216.0271=2346=21023=110=111
1128=99=18035=X49=SAMPLE75=2016101134=357952=2001062015431782132804860=200106201543178213280485799=10000100268=1279=1269=148=17359555=6SZ683=357833270=10216.0271=1346=11023=110=115
1128=99=18035=X49=SAMPLE75=2016101134=77752=2015120402253730966924860=201512040225373096692485799=10000100268=1279=1269=148=17359555=6SZ683=357834270=10216.0271=2346=21023=110=082
1128=99=18135=X49=SAMPLE75=2016101134=386752=2006120206595386912179260=200612020659538691217925799=10000100268=1279=1269=148=17359555=6SZ683=357835270=10220.0271=19346=81023=510=147
1128=99=25435=X49=SAMPLE75=2016101134=384552=2005071421425852500947260=200507142142585250094725799=10000100268=2279=1269=148=17359555=6SZ683=357836270=10220.0271=16346=71023=5279=1269=148=17359555=6SZ683=357837270=10221.0271=46346=101023=610=052
1128=99=25335=X49=SAMPLE75=2016101134=173452=2008012022571908659728060=200801202257190865972805799=10000100268=2279=1269=148=17359555=6SZ683=357838270=10220.0271=19346=81023=5279=1269=148=17359555=6SZ683=357839270=10221.0271=43346=91023=610=243
1128=99=18135=X49=SAMPLE75=2016101134=259652=2016010723211301809792060=201601072321130180979205799=10000100268=1279=1269=148=17359555=6SZ683=357840270=10220.0271=26346=91023=510=145
1128=99=25435=X49=SAMPLE75=2016101134=252952=2001011500070772936008060=200101150007077293600805799=10000100268=2279=1269=148=17359555=6SZ683=357841270=10220.0271=34346=101023=5279=1269=148=17359555=6SZ683=357842270=10224.0271=36346=41023=910=051
1128=99=18035=X49=SAMPLE75=2016101134=73052=2003011812440882428321660=200301181244088242832165799=10000100268=1279=1269=148=17359555=6SZ683=357843270=10216.0271=1346=11023=110=118
1128=99=20835=X49=SAMPLE75=2016101134=372852=2004050109533032377438460=200405010953303237743845799=00000001268=1279=0269=248=17359555=6SZ683=357844270=10216.0271=1346=25797=137705=237=032=137=032=110=064
1128=99=15635=X49=SAMPLE75=2016101134=478952=2008052111323891563718460=200805211132389156371845799=00000010268=1279=0269=e48=17359555=6SZ683=357845271=7910=105
1128=99=25335=X49=SAMPLE75=2016101134=403552=2015012223275082425446460=201501222327508242544645799=10000100268=2279=2269=148=17359555=6SZ683=357846270=10216.0271=1346=11023=1279=0269=148=17359555=6SZ683=357847270=10226.0271=15346=21023=1010=253
1128=99=17935=X49=SAMPLE75=2016101134=248252=2010071607163940428684860=201007160716394042868485799=10000100268=1279=0269=048=17360055=6SH783=99383270=10269.0271=3346=11023=110=047
1128=99=18035=X49=SAMPLE75=2016101134=105952=2005112902533151128540860=200511290253315112854085799=10000100268=1279=1269=048=17359555=6SZ683=357848270=10215.0271=9346=71023=110=126
1128=99=18035=X49=SAMPLE75=2016101134=28852=2007072317151893231388860=200707231715189323138885799=10000100268=1279=1269=148=17359555=6SZ683=357849270=10217.0271=7346=51023=110=135
1128=99=18135=X49=SAMPLE75=2016101134=420752=2009092307525395553523260=200909230752539555352325799=10000100268=1279=1269=048=17359555=6SZ683=357850270=10215.0271=10346=81023=110=159
1128=99=18035=X49=SAMPLE75=2016101134=271552=2003091801350853168281660=200309180135085316828165799=10000100268=1279=1269=148=17359555=6SZ683=357851270=10217.0271=8346=61023=110=109
1128=99=25435=X49=SAMPLE75=2016101134=21152=2004123012193062198550460=200412301219306219855045799=10000100268=2279=1269=048=17359555=6SZ683=357852270=10214.0271=19346=101023=2279=1269=048=17359555=6SZ683=357853270=10213.0271=18346=91023=310=053
1128=99=18035=X49=SAMPLE75=2016101134=106252=2001092016371745289244860=200109201637174528924485799=10000100268=1279=1269=148=17359555=6SZ683=357854270=10217.0271=9346=71023=110=132
1128=99=25135=X49=SAMPLE75=2016101134=364752=2005100814492811950275260=200510081449281195027525799=10000100268=2279=2269=048=17360055=6SH783=99384270=10269.0271=3346=11023=1279=0269=048=17360055=6SH783=99385270=10259.0271=11346=21023=1010=125
1128=99=18135=X49=SAMPLE75=2016101134=13152=2013040200581683791936060=201304020058168379193605799=10000100268=1279=1269=148=17359555=6SZ683=357855270=10217.0271=10346=81023=110=163
1128=99=18135=X49=SAMPLE75=2016101134=78052=2015111023240329105740860=201511102324032910574085799=10000100268=1279=1269=148=17359555=6SZ683=357856270=10220.0271=27346=91023=410=157
1128=99=25335=X49=SAMPLE75=2016101134=211452=2003092102532395375516860=200309210253239537551685799=10000100268=2279=1269=148=17359555=6SZ683=357857270=10220.0271=19346=81023=4279=1269=148=17359555=6SZ683=357858270=10224.0271=44346=51023=810=238
1128=99=18035=X49=SAMPLE75=2016101134=275852=2001090809321555248696860=200109080932155524869685799=10000100268=1279=1269=148=17359555=6SZ683=357859270=10217.0271=9346=71023=110=124
1128=99=18135=X49=SAMPLE75=2016101134=270252=2017020311570811378790460=201702031157081137879045799=10000100268=1279=1269=148=17359555=6SZ683=357860270=10217.0271=17346=81023=110=160
1128=99=18135=X49=SAMPLE75=2016101134=257652=2015053003483943414598460=201505300348394341459845799=10000100268=1279=1269=048=17359555=6SZ683=357861270=10207.0271=21346=61023=910=167
1128=99=18135=X49=SAMPLE75=2016101134=398752=2000060210584519571980060=200006021058451957198005799=10000100268=1279=1269=148=17359555=6SZ683=357862270=10218.0271=15346=61023=210=153
1128=99=18135=X49=SAMPLE75=2016101134=139752=2002112116582762021035260=200211211658276202103525799=10000100268=1279=1269=148=17359555=6SZ683=357863270=10223.0271=19346=41023=710=169
1128=99=18135=X49=SAMPLE75=2016101134=209352=2000083003310041600194860=200008300331004160019485799=10000100268=1279=1269=148=17359555=6SZ683=357864270=10218.0271=16346=71023=210=167
1128=99=18035=X49=SAMPLE75=2016101134=211952=2010042516471007162080060=201004251647100716208005799=10000100268=1279=1269=148=17359555=6SZ683=357865270=10217.0271=9346=71023=110=109
1128=99=18035=X49=SAMPLE75=2016101134=176052=2016011106502561181632060=201601110650256118163205799=10000100268=1279=1269=148=17359555=6SZ683=357866270=10217.0271=8346=61023=110=121
1128=99=25435=X49=SAMPLE75=2016101134=366852=2008092515474693188752060=200809251547469318875205799=10000100268=2279=1269=148=17359555=6SZ683=357867270=10220.0271=16346=71023=4279=1269=148=17359555=6SZ683=357868270=10221.0271=46346=101023=510=071
1128=99=18035=X49=SAMPLE75=2016101134=119552=2002021721575072080352860=200202172157507208035285799=00000100268=1279=0269=048=17359555=6SZ683=357869270=10216.0271=1346=11023=110=119
1128=99=16935=X49=SAMPLE75=2016101134=475452=2007010603513227481795260=200701060351322748179525799=10001000268=1279=0269=N48=17359555=6SZ683=357870270=10216.0286=25510=197
1128=99=17935=X49=SAMPLE75=2016101134=131352=2004073111381808363932860=200407311138180836393285799=10000100268=1279=0269=048=17360055=6SH783=99386270=10269.0271=3346=11023=110=040
1128=99=24735=X49=SAMPLE75=2016101134=225052=2012121105254825908908860=201212110525482590890885799=10000100268=2279=0269=048=17360355=6SM783=7558270=10285.0271=6346=11023=4279=2269=048=17360355=6SM783=7559270=10284.0271=6346=11023=510=208
1128=99=18235=X49=SAMPLE75=2016101134=286452=2008092113133709374464060=200809211313370937446405799=10000100268=1279=1269=048=17359555=6SZ683=357871270=10207.0271=20346=51023=1010=209
1128=99=18235=X49=SAMPLE75=2016101134=85852=2001011307070554592668860=200101130707055459266885799=10000100268=1279=1269=048=17359555=6SZ683=357872270=10214.0271=20346=111023=310=223
1128=99=18035=X49=SAMPLE75=2016101134=381352=2009120113221962735628860=200912011322196273562885799=10000100268=1279=1269=048=17359555=6SZ683=357873270=10215.0271=9346=71023=210=136
1128=99=18035=X49=SAMPLE75=2016101134=404752=2012112519514540104716860=201211251951454010471685799=10000100268=1279=1269=048=17359555=6SZ683=357874270=10216.0271=2346=21023=110=128
1128=99=25135=X49=SAMPLE75=2016101134=203352=2009091713440954909542460=200909171344095490954245799=10000100268=2279=2269=048=17360055=6SH783=99387270=10269.0271=3346=11023=1279=0269=048=17360055=6SH783=99388270=10259.0271=11346=21023=1010=134
1128=99=18135=X49=SAMPLE75=2016101134=50252=2001010722431694357551260=200101072243169435755125799=10000100268=1279=1269=048=17359555=6SZ683=357875270=10215.0271=17346=81023=210=167
1128=99=25235=X49=SAMPLE75=2016101134=429852=2001013008013932715431260=200101300801393271543125799=10000100268=2279=1269=048=17359555=6SZ683=357876270=10216.0271=3346=31023=1279=1269=048=17359555=6SZ683=357877270=10212.0271=18346=91023=510=251
1128=99=18035=X49=SAMPLE75=2016101134=334652=2016030620360816193036860=201603062036081619303685799=10000100268=1279=1269=048=17359555=6SZ683=357878270=10216.0271=4346=41023=110=140
1128=99=18135=X49=SAMPLE75=2016101134=485952=2005112310121141150684860=200511231012114115068485799=10000100268=1279=1269=048=17359555=6SZ683=357879270=10209.0271=24346=71023=810=210
1128=99=18035=X49=SAMPLE75=2016101134=156852=2005062719212256207273660=200506271921225620727365799=10000100268=1279=1269=148=17359555=6SZ683=357880270=10217.0271=7346=51023=110=101
1128=99=18035=X49=SAMPLE75=2016101134=416052=2011032016551986644684860=201103201655198664468485799=10000100268=1279=1269=048=17359555=6SZ683=357881270=10216.0271=5346=51023=110=123
1128=99=18135=X49=SAMPLE75=2016101134=271052=2007071421555044723926460=200707142155504472392645799=10000100268=1279=1269=048=17359555=6SZ683=357882270=10209.0271=23346=61023=810=194
1128=99=18135=X49=SAMPLE75=2016101134=349952=2014111919033740220915260=201411191903374022091525799=10000100268=1279=1269=048=17359555=6SZ683=357883270=10209.0271=43346=71023=810=182
1128=99=25135=X49=SAMPLE75=2016101134=219452=2006011805493951143920060=200601180549395114392005799=10000100268=2279=1269=048=17360055=6SH783=99389270=10263.0271=11346=21023=6279=1269=048=17360055=6SH783=99390270=10259.0271=3346=11023=1010=116
1128=99=25435=X49=SAMPLE75=2016101134=49452=2016111902574413300364860=201611190257441330036485799=10000100268=2279=1269=048=17359555=6SZ683=357884270=10212.0271=26346=101023=5279=1269=048=17359555=6SZ683=357885270=10208.0271=20346=51023=910=061
1128=99=18035=X49=SAMPLE75=2016101134=105152=2000111503101235705517660=200011150310123570551765799=10000100268=1279=1269=048=17359555=6SZ683=357886270=10216.0271=4346=41023=110=134
1128=99=18035=X49=SAMPLE75=2016101134=361452=2004011011173111550947260=200401101117311155094725799=10000100268=1279=1269=048=17359555=6SZ683=357887270=10216.0271=3346=31023=110=099
1128=99=18035=X49=SAMPLE75=2016101134=13452=2002041909215041539246460=200204190921504153924645799=10000100268=1279=1269=048=17359555=6SZ683=357888270=10216.0271=4346=41023=110=112
1128=99=18035=X49=SAMPLE75=2016101134=201552=2005082810212746320393660=200508281021274632039365799=10000100268=1279=1269=048=17359555=6SZ683=357889270=10216.0271=5346=51023=110=105
1128=99=18035=X49=SAMPLE75=2016101134=355952=2006072806240674874342460=200607280624067487434245799=10000100268=1279=1269=048=17359555=6SZ683=357890270=10216.0271=6346=61023=110=115
1128=99=18135=X49=SAMPLE75=2016101134=30652=2010030417433145066137660=201003041743314506613765799=10000100268=1279=1269=048=17359555=6SZ683=357891270=10209.0271=42346=61023=810=166
1128=99=17935=X49=SAMPLE75=2016101134=127852=2008031705252105746832060=200803170525210574683205799=10000100268=1279=0269=048=17360055=6SH783=99391270=10269.0271=3346=11023=110=030
1128=99=24935=X49=SAMPLE75=2016101134=496352=2003051200231947401238460=200305120023194740123845799=10000100268=2279=1269=048=17360055=6SH783=99392270=10268.0271=5346=21023=2279=1269=048=17360055=6SH783=99393270=10266.0271=3346=11023=410=002
1128=99=18035=X49=SAMPLE75=2016101134=338152=2006090104132279851094460=200609010413227985109445799=10000100268=1279=1269=048=17359555=6SZ683=357892270=10216.0271=7346=71023=110=114
1128=99=18035=X49=SAMPLE75=2016101134=199252=2002041318103758614327260=200204131810375861432725799=10000100268=1279=1269=148=17359555=6SZ683=357893270=10217.0271=6346=41023=110=100
1128=99=18135=X49=SAMPLE75=2016101134=254352=2003091807450729389128060=200309180745072938912805799=10000100268=1279=1269=148=17359555=6SZ683=357894270=10222.0271=28346=61023=610=173
1128=99=18035=X49=SAMPLE75=2016101134=164452=2012070709073342268492860=201207070907334226849285799=10000100268=1279=1269=148=17359555=6SZ683=357895270=10217.0271=5346=31023=110=107
1128=99=17935=X49=SAMPLE75=2016101134=4252=2008082815470325981436860=200808281547032598143685799=10000100268=1279=1269=148=17360055=6SH783=99394270=10273.0271=2346=11023=110=040
1128=99=18135=X49=SAMPLE75=2016101134=466352=2000031104334701471728960=200003110433470147172895799=10000100268=1279=1269=148=17359555=6SZ683=357896270=10222.0271=29346=71023=610=189
1128=99=32135=X49=SAMPLE75=2016101134=284752=2003041211122070466593660=200304121112207046659365799=10000100268=3279=2269=148=17360055=6SH783=99395270=10273.0271=2346=11023=1279=1269=148=17360055=6SH783=99396270=10276.0271=5346=21023=3279=0269=148=17360055=6SH783=99397270=10283.0271=61346=31023=1010=091
1128=99=18035=X49=SAMPLE75=2016101134=261352=2004060401101495242438460=200406040110149524243845799=10000100268=1279=1269=148=17359555=6SZ683=357897270=10217.0271=2346=21023=110=120
1128=99=18035=X49=SAMPLE75=2016101134=326752=2016032611045250962540860=201603261104525096254085799=10000100268=1279=1269=148=17359555=6SZ683=357898270=10217.0271=1346=11023=110=134
1128=99=18135=X49=SAMPLE75=2016101134=107352=2015021309471374834899260=201502130947137483489925799=10000100268=1279=1269=148=17359555=6SZ683=357899270=10222.0271=30346=81023=610=171
1128=99=18035=X49=SAMPLE75=2016101134=385052=2013061002583427921945660=201306100258342792194565799=10000100268=1279=1269=048=17359555=6SZ683=357900270=10216.0271=8346=81023=110=122
1128=99=18135=X49=SAMPLE75=2016101134=75352=2014030117432981444710460=201403011743298144471045799=10000100268=1279=1269=048=17359555=6SZ683=357901270=10210.0271=30346=81023=710=168
