1128=99=18135=X49=SAMPLE75=2017010134=353252=2017010106375446437177160=201701010637544643717715799=10000100268=1279=1269=148=17359555=6SZ683=355954270=10220.0271=34346=31023=710=165
1128=99=18035=X49=SAMPLE75=2017010134=374252=2017010109520807176668360=201701010952080717666835799=10000100268=1279=1269=048=17359555=6SZ683=355955270=10210.0271=6346=41023=410=080
1128=99=18035=X49=SAMPLE75=2017010134=252852=2017010106184435680314060=201701010618443568031405799=10000100268=1279=1269=148=17359555=6SZ683=355956270=10220.0271=4346=21023=710=096
1128=99=18135=X49=SAMPLE75=2017010134=30252=2017010113065821908709560=201701011306582190870955799=10000100268=1279=1269=048=17359555=6SZ683=355957270=10207.0271=12346=61023=710=132
1128=99=18135=X49=SAMPLE75=2017010134=271752=2017010112292884548564360=201701011229288454856435799=10000100268=1279=1269=148=17359555=6SZ683=355958270=10220.0271=34346=31023=710=139
1128=99=18135=X49=SAMPLE75=2017010134=333052=2017010102320898960930760=201701010232089896093075799=10000100268=1279=1269=048=17359555=6SZ683=355959270=10207.0271=42346=71023=710=125
1128=99=18135=X49=SAMPLE75=2017010134=33952=2017010106180500461649960=201701010618050046164995799=10000100268=1279=1269=048=17359555=6SZ683=355960270=10207.0271=12346=61023=710=151
1128=99=18035=X49=SAMPLE75=2017010134=89952=2017010104195871071924260=201701010419587107192425799=10000100268=1279=1269=148=17359555=6SZ683=355961270=10220.0271=4346=21023=710=094
1128=99=18135=X49=SAMPLE75=2017010134=111552=2017010105500420114584860=201701010550042011458485799=10000100268=1279=1269=048=17359555=6SZ683=355962270=10207.0271=42346=71023=710=177
1128=99=18135=X49=SAMPLE75=2017010134=93452=2017010102225454101639760=201701010222545410163975799=10000100268=1279=1269=148=17359555=6SZ683=355963270=10220.0271=34346=31023=710=143
1128=99=18035=X49=SAMPLE75=2017010134=233352=2017010109065135377672160=201701010906513537767215799=10000100268=1279=1269=148=17359555=6SZ683=355964270=10220.0271=4346=21023=710=102
1128=99=18135=X49=SAMPLE75=2017010134=221052=2017010111132897966846960=201701011113289796684695799=10000100268=1279=1269=048=17359555=6SZ683=355965270=10207.0271=12346=61023=710=166
1128=99=18135=X49=SAMPLE75=2017010134=27652=2017010107443569969213860=201701010744356996921385799=10000100268=1279=1269=148=17359555=6SZ683=355966270=10220.0271=34346=31023=710=139
1128=99=18135=X49=SAMPLE75=2017010134=499952=2017010106442407547418960=201701010644240754741895799=10000100268=1279=1269=048=17359555=6SZ683=355967270=10207.0271=42346=71023=710=144
1128=99=18035=X49=SAMPLE75=2017010134=57852=2017010110144557192416660=201701011014455719241665799=10000100268=1279=1269=148=17359555=6SZ683=355968270=10220.0271=4346=21023=710=099
1128=99=18135=X49=SAMPLE75=2017010134=153452=2017010107365295139727060=201701010736529513972705799=10000100268=1279=1269=148=17359555=6SZ683=355969270=10220.0271=34346=31023=710=135
1128=99=18035=X49=SAMPLE75=2017010134=1752=2017010100325890404573260=201701010032589040457325799=10000100268=1279=1269=148=17359555=6SZ683=355970270=10220.0271=4346=21023=710=105
1128=99=18135=X49=SAMPLE75=2017010134=61752=2017010106012999287632860=201701010601299928763285799=10000100268=1279=1269=148=17359555=6SZ683=355971270=10220.0271=34346=31023=710=155
1128=99=18135=X49=SAMPLE75=2017010134=117952=2017010102394040289233860=201701010239404028923385799=10000100268=1279=1269=048=17359555=6SZ683=355972270=10207.0271=12346=61023=710=122
1128=99=18035=X49=SAMPLE75=2017010134=445152=2017010112044290223268560=201701011204429022326855799=10000100268=1279=1269=148=17359555=6SZ683=355973270=10220.0271=4346=21023=710=066
1128=99=18135=X49=SAMPLE75=2017010134=189652=2017010108372434663375560=201701010837243466337555799=10000100268=1279=1269=048=17359555=6SZ683=355974270=10207.0271=42346=71023=710=152
1128=99=18135=X49=SAMPLE75=2017010134=434452=2017010110582994558915760=201701011058299455891575799=10000100268=1279=1269=148=17359555=6SZ683=355975270=10220.0271=34346=31023=710=134
1128=99=18135=X49=SAMPLE75=2017010134=227952=2017010103390512184345160=201701010339051218434515799=10000100268=1279=1269=048=17359555=6SZ683=355976270=10207.0271=12346=61023=710=144
1128=99=18135=X49=SAMPLE75=2017010134=14852=2017010100163169148873460=201701010016316914887345799=10000100268=1279=1269=048=17359555=6SZ683=355977270=10207.0271=42346=71023=710=175
1128=99=18035=X49=SAMPLE75=2017010134=306252=2017010106220564424009860=201701010622056442400985799=10000100268=1279=1269=148=17359555=6SZ683=355978270=10222.0271=4346=21023=910=099
1128=99=18035=X49=SAMPLE75=2017010134=89252=2017010105120018465479660=201701010512001846547965799=10000100268=1279=1269=148=17359555=6SZ683=355979270=10220.0271=4346=21023=710=080
1128=99=18135=X49=SAMPLE75=2017010134=319952=2017010111203660322558160=201701011120366032255815799=10000100268=1279=1269=148=17359555=6SZ683=355980270=10220.0271=34346=31023=710=129
1128=99=18035=X49=SAMPLE75=2017010134=291452=2017010100044124070229160=201701010004412407022915799=10000100268=1279=1269=148=17359555=6SZ683=355981270=10220.0271=4346=21023=710=073
1128=99=18135=X49=SAMPLE75=2017010134=159252=2017010104421166099511860=201701010442116609951185799=10000100268=1279=1269=148=17359555=6SZ683=355982270=10220.0271=34346=31023=710=153
1128=99=18035=X49=SAMPLE75=2017010134=87752=2017010107185175199119760=201701010718517519911975799=10000100268=1279=1269=148=17359555=6SZ683=355983270=10220.0271=4346=21023=710=081
1128=99=18135=X49=SAMPLE75=2017010134=375252=2017010104584552421983760=201701010458455242198375799=10000100268=1279=1269=048=17359555=6SZ683=355984270=10207.0271=12346=61023=710=147
1128=99=18135=X49=SAMPLE75=2017010134=177652=2017010101133103376448860=201701010113310337644885799=10000100268=1279=1269=048=17359555=6SZ683=355985270=10207.0271=42346=71023=710=132
1128=99=18135=X49=SAMPLE75=2017010134=22452=2017010102200968921630460=201701010220096892163045799=10000100268=1279=1269=148=17359555=6SZ683=355986270=10220.0271=34346=31023=710=145
1128=99=18135=X49=SAMPLE75=2017010134=271752=2017010104364365785898460=201701010436436578589845799=10000100268=1279=1269=048=17359555=6SZ683=355987270=10207.0271=12346=61023=710=156
1128=99=18035=X49=SAMPLE75=2017010134=23652=2017010112174299576406560=201701011217429957640655799=10000100268=1279=1269=148=17359555=6SZ683=355988270=10220.0271=4346=21023=710=107
1128=99=18135=X49=SAMPLE75=2017010134=120052=2017010108301946797580160=201701010830194679758015799=10000100268=1279=1269=048=17359555=6SZ683=355989270=10207.0271=42346=71023=710=182
1128=99=18135=X49=SAMPLE75=2017010134=393352=2017010101382013741727560=201701010138201374172755799=10000100268=1279=1269=148=17359555=6SZ683=355990270=10220.0271=34346=31023=710=158
1128=99=32135=X49=SAMPLE75=2017010134=320752=2017010111551822359176360=201701011155182235917635799=00000001268=2279=0269=248=17359555=6SZ683=355991270=10213.0271=1346=25797=2279=0269=248=17359555=6SZ683=355992270=10212.0271=4346=35797=237705=537=032=137=032=137=032=437=621180790715732=137=032=310=002
1128=99=15635=X49=SAMPLE75=2017010134=327952=2017010113504113297557960=201701011350411329755795799=00000010268=1279=0269=e48=17359555=6SZ683=355993271=2910=095
1128=99=39535=X49=SAMPLE75=2017010134=429052=2017010109584854576008960=201701010958485457600895799=10000100268=4279=2269=048=17359555=6SZ683=355994270=10213.0271=1346=11023=1279=2269=048=17359555=6SZ683=355995270=10212.0271=4346=21023=1279=0269=048=17359555=6SZ683=355996270=10203.0271=4346=21023=9279=0269=048=17359555=6SZ683=355997270=10202.0271=52346=91023=1010=105
1128=99=17935=X49=SAMPLE75=2017010134=106652=2017010109192980433306960=201701010919298043330695799=10000100268=1279=0269=148=17360055=6SH783=99105270=10269.0271=3346=11023=110=026
1128=99=25135=X49=SAMPLE75=2017010134=259852=2017010106120616921005560=201701010612061692100555799=10000100268=2279=2269=048=17360055=6SH783=99106270=10265.0271=3346=11023=1279=0269=048=17360055=6SH783=99107270=10255.0271=53346=21023=1010=082
1128=99=17935=X49=SAMPLE75=2017010134=355552=2017010104410051031856160=201701010441005103185615799=10000100268=1279=0269=148=17360055=6SH783=99108270=10270.0271=3346=11023=210=007
1128=99=17935=X49=SAMPLE75=2017010134=190852=2017010110244746314155760=201701011024474631415575799=10000100268=1279=1269=048=17360055=6SH783=99109270=10264.0271=2346=11023=110=039
1128=99=32035=X49=SAMPLE75=2017010134=67852=2017010104562831200815960=201701010456283120081595799=10000100268=3279=2269=048=17360055=6SH783=99110270=10264.0271=2346=11023=1279=1269=048=17360055=6SH783=99111270=10261.0271=5346=21023=3279=0269=048=17360055=6SH783=99112270=10254.0271=3346=11023=1010=208
1128=99=18035=X49=SAMPLE75=2017010134=381452=2017010100402999991292460=201701010040299999129245799=10000100268=1279=1269=048=17359555=6SZ683=355998270=10211.0271=4346=31023=110=088
1128=99=18135=X49=SAMPLE75=2017010134=69552=2017010113144216602823360=201701011314421660282335799=10000100268=1279=1269=048=17359555=6SZ683=355999270=10207.0271=12346=61023=510=157
1128=99=25035=X49=SAMPLE75=2017010134=14952=2017010108213796518822660=201701010821379651882265799=10000100268=2279=2269=148=17360055=6SH783=99113270=10269.0271=3346=11023=1279=0269=148=17360055=6SH783=99114270=10279.0271=3346=11023=1010=042
1128=99=25135=X49=SAMPLE75=2017010134=285852=2017010104524189259993360=201701010452418925999335799=10000100268=2279=2269=148=17360055=6SH783=99115270=10270.0271=3346=11023=1279=0269=148=17360055=6SH783=99116270=10280.0271=53346=11023=1010=069
1128=99=18035=X49=SAMPLE75=2017010134=200352=2017010107043438474201460=201701010704343847420145799=10000100268=1279=1269=148=17359555=6SZ683=356000270=10220.0271=4346=21023=710=102
1128=99=18135=X49=SAMPLE75=2017010134=266052=2017010112254516042529060=201701011225451604252905799=10000100268=1279=1269=048=17359555=6SZ683=356001270=10206.0271=34346=31023=610=149
1128=99=18135=X49=SAMPLE75=2017010134=459952=2017010109410528247262660=201701010941052824726265799=10000100268=1279=1269=148=17359555=6SZ683=356002270=10220.0271=34346=31023=710=138
1128=99=18035=X49=SAMPLE75=2017010134=419452=2017010107101501865278660=201701010710150186527865799=10000100268=1279=1269=148=17359555=6SZ683=356003270=10220.0271=4346=21023=710=056
1128=99=18135=X49=SAMPLE75=2017010134=159152=2017010103125808341956160=201701010312580834195615799=10000100268=1279=1269=148=17359555=6SZ683=356004270=10220.0271=34346=31023=710=143
1128=99=18235=X49=SAMPLE75=2017010134=443552=2017010114163329953443160=201701011416332995344315799=10000100268=1279=1269=048=17359555=6SZ683=356005270=10202.0271=22346=81023=1010=164
1128=99=18235=X49=SAMPLE75=2017010134=131652=2017010114120637904067360=201701011412063790406735799=10000100268=1279=1269=048=17359555=6SZ683=356006270=10202.0271=52346=91023=1010=171
1128=99=18035=X49=SAMPLE75=2017010134=496052=2017010112274178384237760=201701011227417838423775799=10000100268=1279=1269=148=17359555=6SZ683=356007270=10220.0271=4346=21023=710=077
1128=99=18035=X49=SAMPLE75=2017010134=253852=2017010100094173988309760=201701010009417398830975799=10000100268=1279=1269=048=17359555=6SZ683=356008270=10206.0271=4346=21023=610=072
1128=99=18135=X49=SAMPLE75=2017010134=111952=2017010106190582202669260=201701010619058220266925799=10000100268=1279=1269=148=17359555=6SZ683=356009270=10220.0271=34346=31023=710=136
1128=99=18135=X49=SAMPLE75=2017010134=174952=2017010103044395233603060=201701010304439523360305799=10000100268=1279=1269=048=17359555=6SZ683=356010270=10206.0271=34346=31023=610=135
1128=99=18135=X49=SAMPLE75=2017010134=280652=2017010108410982897136760=201701010841098289713675799=10000100268=1279=1269=148=17359555=6SZ683=356011270=10215.0271=18346=61023=210=137
1128=99=18035=X49=SAMPLE75=2017010134=192852=2017010108181052924734160=201701010818105292473415799=10000100268=1279=1269=048=17359555=6SZ683=356012270=10206.0271=4346=21023=610=076
1128=99=18135=X49=SAMPLE75=2017010134=116452=2017010109521612397939860=201701010952161239793985799=10000100268=1279=1269=148=17359555=6SZ683=356013270=10219.0271=51346=81023=610=188
1128=99=18035=X49=SAMPLE75=2017010134=261952=2017010107144503466308860=201701010714450346630885799=10000100268=1279=1269=148=17359555=6SZ683=356014270=10220.0271=4346=21023=710=090
1128=99=18135=X49=SAMPLE75=2017010134=172552=2017010101064619754389460=201701010106461975438945799=10000100268=1279=1269=148=17359555=6SZ683=356015270=10219.0271=21346=71023=610=141
1128=99=18135=X49=SAMPLE75=2017010134=435352=2017010111045430460252060=201701011104543046025205799=10000100268=1279=1269=048=17359555=6SZ683=356016270=10206.0271=34346=31023=610=131
1128=99=18135=X49=SAMPLE75=2017010134=264552=2017010113382262717277260=201701011338226271727725799=10000100268=1279=1269=148=17359555=6SZ683=356017270=10220.0271=34346=31023=710=113
1128=99=18035=X49=SAMPLE75=2017010134=270252=2017010105560421358886960=201701010556042135888695799=10000100268=1279=1269=048=17359555=6SZ683=356018270=10206.0271=4346=21023=610=048
1128=99=18135=X49=SAMPLE75=2017010134=65652=2017010105055068751404960=201701010505506875140495799=10000100268=1279=1269=048=17359555=6SZ683=356019270=10206.0271=34346=31023=610=154
1128=99=18035=X49=SAMPLE75=2017010134=202452=2017010100185038809655860=201701010018503880965585799=10000100268=1279=1269=148=17359555=6SZ683=356020270=10220.0271=4346=21023=710=082
1128=99=18135=X49=SAMPLE75=2017010134=447852=2017010107073353518498260=201701010707335351849825799=10000100268=1279=1269=148=17359555=6SZ683=356021270=10220.0271=34346=31023=710=146
1128=99=18035=X49=SAMPLE75=2017010134=460652=2017010109591468353090760=201701010959146835309075799=10000100268=1279=1269=148=17359555=6SZ683=356022270=10220.0271=4346=21023=710=059
1128=99=18135=X49=SAMPLE75=2017010134=9552=2017010100111847494168760=201701010011184749416875799=10000100268=1279=1269=048=17359555=6SZ683=356023270=10208.0271=10346=51023=410=128
1128=99=18235=X49=SAMPLE75=2017010134=121652=2017010109555380616934560=201701010955538061693455799=10000100268=1279=1269=048=17359555=6SZ683=356024270=10202.0271=22346=81023=1010=162
1128=99=18135=X49=SAMPLE75=2017010134=226752=2017010107463066242911260=201701010746306624291125799=10000100268=1279=1269=048=17359555=6SZ683=356025270=10205.0271=51346=81023=710=153
1128=99=18135=X49=SAMPLE75=2017010134=5552=2017010107053609371003560=201701010705360937100355799=10000100268=1279=1269=148=17359555=6SZ683=356026270=10220.0271=34346=31023=710=128
1128=99=18135=X49=SAMPLE75=2017010134=35852=2017010101223771607017460=201701010122377160701745799=10000100268=1279=1269=048=17359555=6SZ683=356027270=10205.0271=21346=71023=710=130
1128=99=18135=X49=SAMPLE75=2017010134=442652=2017010107245554314265260=201701010724555431426525799=10000100268=1279=1269=048=17359555=6SZ683=356028270=10208.0271=40346=61023=410=130
1128=99=18035=X49=SAMPLE75=2017010134=6652=2017010106181214347195560=201701010618121434719555799=10000100268=1279=1269=148=17359555=6SZ683=356029270=10220.0271=4346=21023=710=071
1128=99=18235=X49=SAMPLE75=2017010134=286452=2017010112353317549208960=201701011235331754920895799=10000100268=1279=1269=048=17359555=6SZ683=356030270=10202.0271=52346=91023=1010=187
1128=99=18135=X49=SAMPLE75=2017010134=215452=2017010113271473650276360=201701011327147365027635799=10000100268=1279=1269=148=17359555=6SZ683=356031270=10220.0271=34346=31023=710=144
1128=99=18035=X49=SAMPLE75=2017010134=160752=2017010112012437194551860=201701011201243719455185799=10000100268=1279=1269=148=17359555=6SZ683=356032270=10220.0271=4346=21023=710=076
1128=99=18135=X49=SAMPLE75=2017010134=400352=2017010100045008523489860=201701010004500852348985799=10000100268=1279=1269=148=17359555=6SZ683=356033270=10220.0271=34346=31023=710=159
1128=99=18035=X49=SAMPLE75=2017010134=417052=2017010112510008169644060=201701011251000816964405799=10000100268=1279=1269=148=17359555=6SZ683=356034270=10220.0271=4346=21023=710=077
1128=99=18035=X49=SAMPLE75=2017010134=137052=2017010103262635435737760=201701010326263543573775799=10000100268=1279=1269=048=17359555=6SZ683=356035270=10206.0271=4346=21023=610=072
1128=99=18135=X49=SAMPLE75=2017010134=163452=2017010111070637731251260=201701011107063773125125799=10000100268=1279=1269=148=17359555=6SZ683=356036270=10220.0271=34346=31023=710=125
1128=99=18135=X49=SAMPLE75=2017010134=342252=2017010113101184312586260=201701011310118431258625799=10000100268=1279=1269=048=17359555=6SZ683=356037270=10206.0271=34346=31023=610=136
1128=99=18135=X49=SAMPLE75=2017010134=311852=2017010100040128173897960=201701010004012817389795799=10000100268=1279=1269=048=17359555=6SZ683=356038270=10208.0271=10346=51023=410=159
1128=99=18235=X49=SAMPLE75=2017010134=362952=2017010106211093483227860=201701010621109348322785799=10000100268=1279=1269=048=17359555=6SZ683=356039270=10202.0271=22346=81023=1010=216
1128=99=18135=X49=SAMPLE75=2017010134=218552=2017010112172798221990560=201701011217279822199055799=10000100268=1279=1269=048=17359555=6SZ683=356040270=10205.0271=51346=81023=710=158
1128=99=18035=X49=SAMPLE75=2017010134=136152=2017010100425587579926260=201701010042558757992625799=10000100268=1279=1269=148=17359555=6SZ683=356041270=10220.0271=4346=21023=710=107
1128=99=18135=X49=SAMPLE75=2017010134=494352=2017010109450333858287160=201701010945033385828715799=10000100268=1279=1269=048=17359555=6SZ683=356042270=10205.0271=21346=71023=710=145
1128=99=18135=X49=SAMPLE75=2017010134=302552=2017010111304800423093960=201701011130480042309395799=10000100268=1279=1269=048=17359555=6SZ683=356043270=10208.0271=40346=61023=410=142
1128=99=18135=X49=SAMPLE75=2017010134=252452=2017010107121214967246060=201701010712121496724605799=10000100268=1279=1269=148=17359555=6SZ683=356044270=10220.0271=34346=31023=710=132
1128=99=18035=X49=SAMPLE75=2017010134=6752=2017010107512411342675060=201701010751241134267505799=10000100268=1279=1269=148=17359555=6SZ683=356045270=10220.0271=4346=21023=710=078
1128=99=18235=X49=SAMPLE75=2017010134=479852=2017010106525258943321460=201701010652525894332145799=10000100268=1279=1269=048=17359555=6SZ683=356046270=10202.0271=52346=91023=1010=198
1128=99=18135=X49=SAMPLE75=2017010134=82552=2017010105253829384301060=201701010525382938430105799=10000100268=1279=1269=148=17359555=6SZ683=356047270=10220.0271=34346=31023=710=154
1128=99=18035=X49=SAMPLE75=2017010134=83052=2017010105284881427556260=201701010528488142755625799=10000100268=1279=1269=148=17359555=6SZ683=356048270=10220.0271=4346=21023=710=102
1128=99=18135=X49=SAMPLE75=2017010134=466952=2017010110413580389563060=201701011041358038956305799=10000100268=1279=1269=148=17359555=6SZ683=356049270=10220.0271=34346=31023=710=162
1128=99=18235=X49=SAMPLE75=2017010134=272052=2017010106123691835806660=201701010612369183580665799=10000100268=1279=1269=048=17359555=6SZ683=356050270=10202.0271=22346=81023=1010=163
1128=99=18235=X49=SAMPLE75=2017010134=370752=2017010105162583300832360=201701010516258330083235799=10000100268=1279=1269=048=17359555=6SZ683=356051270=10202.0271=52346=91023=1010=178
1128=99=18235=X49=SAMPLE75=2017010134=170252=2017010114332555947414360=201701011433255594741435799=10000100268=1279=1269=048=17359555=6SZ683=356052270=10202.0271=22346=81023=1010=166
1128=99=18235=X49=SAMPLE75=2017010134=43152=2017010101221062441656360=201701010122106244165635799=10000100268=1279=1269=048=17359555=6SZ683=356053270=10202.0271=52346=91023=1010=168
1128=99=18035=X49=SAMPLE75=2017010134=372452=2017010103550346947239960=201701010355034694723995799=10000100268=1279=1269=148=17359555=6SZ683=356054270=10220.0271=4346=21023=710=122
1128=99=18135=X49=SAMPLE75=2017010134=367252=2017010100393815854620860=201701010039381585462085799=10000100268=1279=1269=148=17359555=6SZ683=356055270=10220.0271=34346=31023=710=159
1128=99=18035=X49=SAMPLE75=2017010134=199852=2017010103064115148818060=201701010306411514881805799=10000100268=1279=1269=148=17359555=6SZ683=356056270=10220.0271=4346=21023=710=097
1128=99=18135=X49=SAMPLE75=2017010134=205452=2017010109273099452736160=201701010927309945273615799=10000100268=1279=1269=148=17359555=6SZ683=356057270=10220.0271=34346=31023=710=126
1128=99=18035=X49=SAMPLE75=2017010134=331452=2017010110285557940577460=201701011028555794057745799=10000100268=1279=0269=048=17359555=6SZ683=356058270=10212.0271=1346=11023=110=066
1128=99=17935=X49=SAMPLE75=2017010134=365252=2017010103320119499945660=201701010332011949994565799=10000100268=1279=0269=048=17360055=6SH783=99117270=10265.0271=3346=11023=110=008
1128=99=17935=X49=SAMPLE75=2017010134=211952=2017010108000774402050260=201701010800077440205025799=10000100268=1279=0269=048=17360055=6SH783=99118270=10264.0271=3346=11023=210=027
1128=99=18035=X49=SAMPLE75=2017010134=247652=2017010111063528895789960=201701011106352889578995799=10000100268=1279=1269=048=17359555=6SZ683=356059270=10212.0271=2346=21023=110=086
1128=99=25135=X49=SAMPLE75=2017010134=449252=2017010114053543065858760=201701011405354306585875799=10000100268=2279=2269=048=17360055=6SH783=99119270=10265.0271=3346=11023=1279=0269=048=17360055=6SH783=99120270=10255.0271=53346=21023=1010=073
1128=99=24935=X49=SAMPLE75=2017010134=223152=2017010106060871736812260=201701010606087173681225799=10000100268=2279=1269=048=17360055=6SH783=99121270=10262.0271=5346=21023=3279=1269=048=17360055=6SH783=99122270=10261.0271=3346=11023=410=227
1128=99=18135=X49=SAMPLE75=2017010134=381652=2017010102562547455777660=201701010256254745577765799=10000100268=1279=1269=048=17359555=6SZ683=356060270=10208.0271=10346=51023=510=125
1128=99=18135=X49=SAMPLE75=2017010134=237052=2017010108135806445904160=201701010813580644590415799=10000100268=1279=1269=048=17359555=6SZ683=356061270=10205.0271=51346=81023=810=137
1128=99=18035=X49=SAMPLE75=2017010134=423552=2017010110465797054356060=201701011046579705435605799=10000100268=1279=1269=148=17359555=6SZ683=356062270=10220.0271=4346=21023=710=070
1128=99=18135=X49=SAMPLE75=2017010134=93652=2017010107155039840130260=201701010715503984013025799=10000100268=1279=1269=048=17359555=6SZ683=356063270=10205.0271=21346=71023=810=128
1128=99=18135=X49=SAMPLE75=2017010134=293552=2017010113470860521870960=201701011347086052187095799=10000100268=1279=1269=048=17359555=6SZ683=356064270=10208.0271=40346=61023=510=151
1128=99=18135=X49=SAMPLE75=2017010134=296552=2017010106022430905389360=201701010602243090538935799=10000100268=1279=1269=148=17359555=6SZ683=356065270=10220.0271=34346=31023=710=133
1128=99=18035=X49=SAMPLE75=2017010134=29052=2017010102261467873899960=201701010226146787389995799=10000100268=1279=1269=048=17359555=6SZ683=356066270=10206.0271=4346=21023=710=086
1128=99=18135=X49=SAMPLE75=2017010134=264052=2017010106104181606491160=201701010610418160649115799=10000100268=1279=1269=048=17359555=6SZ683=356067270=10206.0271=34346=31023=710=166
1128=99=18135=X49=SAMPLE75=2017010134=118252=2017010108400342113965960=201701010840034211396595799=10000100268=1279=1269=048=17359555=6SZ683=356068270=10208.0271=10346=51023=510=145
1128=99=18135=X49=SAMPLE75=2017010134=391652=2017010105541419060999460=201701010554141906099945799=10000100268=1279=1269=048=17359555=6SZ683=356069270=10205.0271=51346=81023=810=154
1128=99=18035=X49=SAMPLE75=2017010134=82952=2017010113524440424869260=201701011352444042486925799=10000100268=1279=1269=148=17359555=6SZ683=356070270=10220.0271=4346=21023=710=098
1128=99=18135=X49=SAMPLE75=2017010134=469552=2017010112501480796128460=201701011250148079612845799=10000100268=1279=1269=048=17359555=6SZ683=356071270=10205.0271=21346=71023=810=114
1128=99=18135=X49=SAMPLE75=2017010134=314752=2017010103185598191834160=201701010318559819183415799=10000100268=1279=1269=048=17359555=6SZ683=356072270=10208.0271=40346=61023=510=144
1128=99=18135=X49=SAMPLE75=2017010134=224552=2017010106095974763429460=201701010609597476342945799=10000100268=1279=1269=148=17359555=6SZ683=356073270=10220.0271=34346=31023=710=154
1128=99=18035=X49=SAMPLE75=2017010134=356852=2017010105154340908422860=201701010515434090842285799=10000100268=1279=1269=048=17359555=6SZ683=356074270=10206.0271=4346=21023=710=092
1128=99=18035=X49=SAMPLE75=2017010134=194652=2017010102044830206478360=201701010204483020647835799=10000100268=1279=1269=148=17359555=6SZ683=356075270=10220.0271=4346=21023=710=110
1128=99=18135=X49=SAMPLE75=2017010134=398452=2017010106523604202683460=201701010652360420268345799=10000100268=1279=1269=048=17359555=6SZ683=356076270=10206.0271=34346=31023=710=166
1128=99=18135=X49=SAMPLE75=2017010134=186852=2017010114260206224066960=201701011426020622406695799=10000100268=1279=1269=148=17359555=6SZ683=356077270=10220.0271=34346=31023=710=130
1128=99=18035=X49=SAMPLE75=2017010134=434952=2017010104541652529757860=201701010454165252975785799=10000100268=1279=1269=048=17359555=6SZ683=356078270=10206.0271=4346=21023=710=105
1128=99=18035=X49=SAMPLE75=2017010134=386652=2017010114091788075976760=201701011409178807597675799=10000100268=1279=1269=148=17359555=6SZ683=356079270=10220.0271=4346=21023=710=103
1128=99=18135=X49=SAMPLE75=2017010134=303752=2017010104530200599627260=201701010453020059962725799=10000100268=1279=1269=148=17359555=6SZ683=356080270=10220.0271=34346=31023=710=172
1128=99=18135=X49=SAMPLE75=2017010134=114752=2017010102542614104428760=201701010254261410442875799=10000100268=1279=1269=048=17359555=6SZ683=356081270=10206.0271=34346=31023=710=150
1128=99=18035=X49=SAMPLE75=2017010134=49552=2017010100223275346155660=201701010022327534615565799=10000100268=1279=1269=148=17359555=6SZ683=356082270=10220.0271=4346=21023=710=072
1128=99=18035=X49=SAMPLE75=2017010134=149052=2017010112515517037081460=201701011251551703708145799=10000100268=1279=1269=048=17359555=6SZ683=356083270=10206.0271=4346=21023=710=084
1128=99=18135=X49=SAMPLE75=2017010134=223552=2017010112441573632787860=201701011244157363278785799=10000100268=1279=1269=148=17359555=6SZ683=356084270=10220.0271=34346=31023=710=153
1128=99=18135=X49=SAMPLE75=2017010134=312752=2017010107091507453276960=201701010709150745327695799=10000100268=1279=1269=048=17359555=6SZ683=356085270=10206.0271=34346=31023=710=168
1128=99=18035=X49=SAMPLE75=2017010134=497152=2017010102475028854424960=201701010247502885442495799=10000100268=1279=1269=148=17359555=6SZ683=356086270=10220.0271=4346=21023=710=075
1128=99=18135=X49=SAMPLE75=2017010134=221552=2017010110074933642859460=201701011007493364285945799=10000100268=1279=1269=148=17359555=6SZ683=356087270=10220.0271=34346=31023=710=173
1128=99=18035=X49=SAMPLE75=2017010134=307452=2017010108564787342000460=201701010856478734200045799=10000100268=1279=1269=048=17359555=6SZ683=356088270=10212.0271=5346=31023=110=105
1128=99=18035=X49=SAMPLE75=2017010134=196352=2017010108455426627737860=201701010845542662773785799=10000100268=1279=1269=048=17359555=6SZ683=356089270=10206.0271=4346=21023=710=112
1128=99=18135=X49=SAMPLE75=2017010134=79052=2017010108504601149356460=201701010850460114935645799=10000100268=1279=1269=048=17359555=6SZ683=356090270=10206.0271=34346=31023=710=188
1128=99=18135=X49=SAMPLE75=2017010134=88652=2017010103214078325541360=201701010321407832554135799=10000100268=1279=1269=048=17359555=6SZ683=356091270=10207.0271=42346=71023=610=145
1128=99=18035=X49=SAMPLE75=2017010134=257352=2017010100045267120195960=201701010004526712019595799=10000100268=1279=1269=048=17359555=6SZ683=356092270=10206.0271=4346=21023=710=101
1128=99=18135=X49=SAMPLE75=2017010134=58552=2017010113483153835818060=201701011348315383581805799=10000100268=1279=1269=048=17359555=6SZ683=356093270=10207.0271=12346=61023=610=173
1128=99=18135=X49=SAMPLE75=2017010134=45452=2017010109545454141741260=201701010954545414174125799=10000100268=1279=1269=048=17359555=6SZ683=356094270=10207.0271=42346=71023=610=160
1128=99=18135=X49=SAMPLE75=2017010134=480452=2017010109452558841181860=201701010945255884118185799=10000100268=1279=1269=148=17359555=6SZ683=356095270=10219.0271=51346=81023=610=146
1128=99=18035=X49=SAMPLE75=2017010134=86952=2017010114014419823424560=201701011401441982342455799=10000100268=1279=1269=148=17359555=6SZ683=356096270=10220.0271=4346=21023=710=106
1128=99=18135=X49=SAMPLE75=2017010134=456652=2017010104451067675392160=201701010445106767539215799=10000100268=1279=1269=148=17359555=6SZ683=356097270=10219.0271=21346=71023=610=176
1128=99=18135=X49=SAMPLE75=2017010134=214852=2017010112304944012176660=201701011230494401217665799=10000100268=1279=1269=148=17359555=6SZ683=356098270=10220.0271=34346=31023=710=177
1128=99=18135=X49=SAMPLE75=2017010134=419252=2017010102520149116892160=201701010252014911689215799=10000100268=1279=1269=048=17359555=6SZ683=356099270=10207.0271=12346=61023=610=188
1128=99=18135=X49=SAMPLE75=2017010134=3752=2017010106242410345924960=201701010624241034592495799=10000100268=1279=1269=048=17359555=6SZ683=356100270=10207.0271=42346=71023=610=116
1128=99=18035=X49=SAMPLE75=2017010134=428852=2017010100434214237205660=201701010043421423720565799=10000100268=1279=1269=148=17359555=6SZ683=356101270=10220.0271=4346=21023=710=076
1128=99=18135=X49=SAMPLE75=2017010134=122352=2017010105162975520203360=201701010516297552020335799=10000100268=1279=1269=148=17359555=6SZ683=356102270=10220.0271=34346=31023=710=138
1128=99=18135=X49=SAMPLE75=2017010134=72852=2017010109144827851952460=201701010914482785195245799=10000100268=1279=1269=048=17359555=6SZ683=356103270=10207.0271=12346=61023=610=137
1128=99=18135=X49=SAMPLE75=2017010134=444752=2017010109422636483838160=201701010942263648383815799=10000100268=1279=1269=048=17359555=6SZ683=356104270=10207.0271=42346=71023=610=150
1128=99=18035=X49=SAMPLE75=2017010134=174952=2017010109172153360184760=201701010917215336018475799=10000100268=1279=1269=148=17359555=6SZ683=356105270=10220.0271=4346=21023=710=086
1128=99=18135=X49=SAMPLE75=2017010134=107552=2017010103490457391118060=201701010349045739111805799=10000100268=1279=1269=148=17359555=6SZ683=356106270=10220.0271=34346=31023=710=156
1128=99=18035=X49=SAMPLE75=2017010134=234152=2017010104030429221194760=201701010403042922119475799=10000100268=1279=1269=148=17359555=6SZ683=356107270=10214.0271=3346=31023=110=055
1128=99=18035=X49=SAMPLE75=2017010134=328352=2017010103315128008521860=201701010331512800852185799=10000100268=1279=1269=148=17359555=6SZ683=356108270=10220.0271=4346=21023=710=083
1128=99=18035=X49=SAMPLE75=2017010134=403552=2017010114100154816739860=201701011410015481673985799=10000100268=1279=1269=048=17359555=6SZ683=356109270=10212.0271=6346=41023=110=063
1128=99=17935=X49=SAMPLE75=2017010134=353252=2017010112422008523195060=201701011242200852319505799=10000100268=1279=0269=048=17360055=6SH783=99123270=10265.0271=3346=11023=110=255
1128=99=24935=X49=SAMPLE75=2017010134=140852=2017010106000300305132660=201701010600030030513265799=10000100268=2279=1269=048=17360055=6SH783=99124270=10264.0271=5346=21023=2279=1269=048=17360055=6SH783=99125270=10262.0271=3346=11023=410=228
1128=99=18135=X49=SAMPLE75=2017010134=81452=2017010107051483243437460=201701010705148324343745799=10000100268=1279=1269=148=17359555=6SZ683=356110270=10220.0271=34346=31023=710=114
1128=99=18135=X49=SAMPLE75=2017010134=24952=2017010104103429496546160=201701010410342949654615799=10000100268=1279=1269=048=17359555=6SZ683=356111270=10207.0271=12346=61023=610=107
1128=99=18135=X49=SAMPLE75=2017010134=228252=2017010101034059932338460=201701010103405993233845799=10000100268=1279=1269=048=17359555=6SZ683=356112270=10207.0271=42346=71023=610=154
1128=99=18035=X49=SAMPLE75=2017010134=9252=2017010106151873426584960=201701010615187342658495799=10000100268=1279=1269=148=17359555=6SZ683=356113270=10220.0271=4346=21023=710=084
1128=99=18135=X49=SAMPLE75=2017010134=452152=2017010110510156162943660=201701011051015616294365799=10000100268=1279=1269=148=17359555=6SZ683=356114270=10219.0271=51346=81023=610=111
1128=99=18135=X49=SAMPLE75=2017010134=138352=2017010100150635522602460=201701010015063552260245799=10000100268=1279=1269=048=17359555=6SZ683=356115270=10207.0271=12346=61023=610=108
1128=99=18135=X49=SAMPLE75=2017010134=293352=2017010112275250879521460=201701011227525087952145799=10000100268=1279=1269=048=17359555=6SZ683=356116270=10207.0271=42346=71023=610=130
1128=99=18135=X49=SAMPLE75=2017010134=32852=2017010102405507344190460=201701010240550734419045799=10000100268=1279=1269=048=17359555=6SZ683=356117270=10207.0271=12346=61023=610=135
1128=99=18135=X49=SAMPLE75=2017010134=332252=2017010113564254749854560=201701011356425474985455799=10000100268=1279=1269=148=17359555=6SZ683=356118270=10219.0271=21346=71023=610=144
1128=99=18135=X49=SAMPLE75=2017010134=470652=2017010113441943010817760=201701011344194301081775799=10000100268=1279=1269=048=17359555=6SZ683=356119270=10207.0271=42346=71023=610=139
1128=99=18135=X49=SAMPLE75=2017010134=163652=2017010102012494437781660=201701010201249443778165799=10000100268=1279=1269=148=17359555=6SZ683=356120270=10220.0271=34346=31023=710=100
1128=99=18135=X49=SAMPLE75=2017010134=309752=2017010113073555144263960=201701011307355514426395799=10000100268=1279=1269=048=17359555=6SZ683=356121270=10207.0271=12346=61023=610=118
1128=99=18135=X49=SAMPLE75=2017010134=54452=2017010100493474488104460=201701010049347448810445799=10000100268=1279=1269=048=17359555=6SZ683=356122270=10207.0271=42346=71023=610=118
1128=99=18135=X49=SAMPLE75=2017010134=118152=2017010100015322761098060=201701010001532276109805799=10000100268=1279=1269=048=17359555=6SZ683=356123270=10207.0271=43346=81023=610=136
1128=99=18035=X49=SAMPLE75=2017010134=290852=2017010100014947919901060=201701010001494791990105799=10000100268=1279=1269=148=17359555=6SZ683=356124270=10220.0271=4346=21023=710=093
1128=99=18135=X49=SAMPLE75=2017010134=53152=2017010100221584872549960=201701010022158487254995799=10000100268=1279=1269=148=17359555=6SZ683=356125270=10219.0271=51346=81023=610=168
1128=99=18135=X49=SAMPLE75=2017010134=327552=2017010113181471193575960=201701011318147119357595799=10000100268=1279=1269=048=17359555=6SZ683=356126270=10207.0271=13346=71023=610=141
1128=99=18135=X49=SAMPLE75=2017010134=148952=2017010102092383126675460=201701010209238312667545799=10000100268=1279=1269=048=17359555=6SZ683=356127270=10207.0271=43346=81023=610=128
1128=99=18135=X49=SAMPLE75=2017010134=487352=2017010108454232362668460=201701010845423236266845799=10000100268=1279=1269=048=17359555=6SZ683=356128270=10207.0271=13346=71023=610=141
1128=99=18135=X49=SAMPLE75=2017010134=463652=2017010105574022670388860=201701010557402267038885799=10000100268=1279=1269=148=17359555=6SZ683=356129270=10219.0271=21346=71023=610=154
1128=99=18135=X49=SAMPLE75=2017010134=14952=2017010111533512863246160=201701011153351286324615799=10000100268=1279=1269=148=17359555=6SZ683=356130270=10219.0271=51346=81023=610=166
1128=99=18135=X49=SAMPLE75=2017010134=74252=2017010109272736958685660=201701010927273695868565799=10000100268=1279=1269=048=17359555=6SZ683=356131270=10207.0271=43346=81023=610=142
1128=99=18135=X49=SAMPLE75=2017010134=203052=2017010110105036564132260=201701011010503656413225799=10000100268=1279=1269=148=17359555=6SZ683=356132270=10219.0271=21346=71023=610=109
1128=99=18135=X49=SAMPLE75=2017010134=134652=2017010109474415349405960=201701010947441534940595799=10000100268=1279=1269=148=17359555=6SZ683=356133270=10219.0271=51346=81023=610=154
1128=99=18135=X49=SAMPLE75=2017010134=108152=2017010101281344298554260=201701010128134429855425799=10000100268=1279=1269=148=17359555=6SZ683=356134270=10219.0271=21346=71023=610=158
1128=99=18135=X49=SAMPLE75=2017010134=215952=2017010110105056130582860=201701011010505613058285799=10000100268=1279=1269=148=17359555=6SZ683=356135270=10219.0271=51346=81023=610=160
1128=99=18135=X49=SAMPLE75=2017010134=293552=2017010111454323203549760=201701011145432320354975799=10000100268=1279=1269=148=17359555=6SZ683=356136270=10215.0271=15346=51023=210=140
1128=99=18135=X49=SAMPLE75=2017010134=153052=2017010113213751580011660=201701011321375158001165799=10000100268=1279=1269=148=17359555=6SZ683=356137270=10215.0271=12346=41023=210=148
1128=99=18135=X49=SAMPLE75=2017010134=413252=2017010108250917465718260=201701010825091746571825799=10000100268=1279=1269=148=17359555=6SZ683=356138270=10219.0271=21346=71023=610=161
1128=99=18035=X49=SAMPLE75=2017010134=429452=2017010109250318241989360=201701010925031824198935799=10000100268=1279=1269=148=17359555=6SZ683=356139270=10215.0271=9346=31023=210=099
1128=99=18035=X49=SAMPLE75=2017010134=400552=2017010110113230280231760=201701011011323028023175799=10000100268=1279=1269=148=17359555=6SZ683=356140270=10215.0271=6346=21023=210=106
1128=99=18035=X49=SAMPLE75=2017010134=351852=2017010107545591695107160=201701010754559169510715799=10000100268=1279=1269=148=17359555=6SZ683=356141270=10215.0271=3346=11023=210=075
1128=99=25235=X49=SAMPLE75=2017010134=245652=2017010106422516372810460=201701010642251637281045799=10000100268=2279=1269=048=17359555=6SZ683=356142270=10212.0271=7346=51023=1279=1269=048=17359555=6SZ683=356143270=10208.0271=39346=51023=510=196
1128=99=18135=X49=SAMPLE75=2017010134=34852=2017010107465310360976560=201701010746531036097655799=10000100268=1279=1269=148=17359555=6SZ683=356144270=10219.0271=51346=81023=610=166
1128=99=18135=X49=SAMPLE75=2017010134=486952=2017010110364931146956560=201701011036493114695655799=10000100268=1279=1269=148=17359555=6SZ683=356145270=10219.0271=21346=71023=610=138
1128=99=18135=X49=SAMPLE75=2017010134=194152=2017010111484572982889860=201701011148457298288985799=10000100268=1279=1269=048=17359555=6SZ683=356146270=10207.0271=13346=71023=610=149
1128=99=18135=X49=SAMPLE75=2017010134=7952=2017010111460214724896160=201701011146021472489615799=10000100268=1279=1269=148=17359555=6SZ683=356147270=10220.0271=34346=31023=710=151
1128=99=18135=X49=SAMPLE75=2017010134=433252=2017010100083905264655860=201701010008390526465585799=10000100268=1279=1269=048=17359555=6SZ683=356148270=10207.0271=43346=81023=610=158
1128=99=18035=X49=SAMPLE75=2017010134=412052=2017010113583134317312660=201701011358313431731265799=10000100268=1279=1269=148=17359555=6SZ683=356149270=10220.0271=4346=21023=710=104
1128=99=18135=X49=SAMPLE75=2017010134=208552=2017010107161480583791960=201701010716148058379195799=10000100268=1279=1269=148=17359555=6SZ683=356150270=10220.0271=34346=31023=710=171
1128=99=18135=X49=SAMPLE75=2017010134=307452=2017010110515407499338160=201701011051540749933815799=10000100268=1279=1269=048=17359555=6SZ683=356151270=10207.0271=13346=71023=610=152
1128=99=18135=X49=SAMPLE75=2017010134=166852=2017010100130988467886860=201701010013098846788685799=10000100268=1279=1269=048=17359555=6SZ683=356152270=10207.0271=43346=81023=610=169
1128=99=18035=X49=SAMPLE75=2017010134=450452=2017010103024050388741360=201701010302405038874135799=10000100268=1279=1269=148=17359555=6SZ683=356153270=10220.0271=4346=21023=710=074
1128=99=18135=X49=SAMPLE75=2017010134=189652=2017010108282281577124060=201701010828228157712405799=10000100268=1279=1269=148=17359555=6SZ683=356154270=10220.0271=34346=31023=710=131
1128=99=18035=X49=SAMPLE75=2017010134=377152=2017010110573264092438060=201701011057326409243805799=10000100268=1279=1269=148=17359555=6SZ683=356155270=10220.0271=4346=21023=710=109
1128=99=18135=X49=SAMPLE75=2017010134=254852=2017010102013322746902160=201701010201332274690215799=10000100268=1279=1269=148=17359555=6SZ683=356156270=10220.0271=34346=31023=710=119
1128=99=18135=X49=SAMPLE75=2017010134=431452=2017010112593584197606360=201701011259358419760635799=10000100268=1279=1269=048=17359555=6SZ683=356157270=10207.0271=13346=71023=610=124
1128=99=18135=X49=SAMPLE75=2017010134=346952=2017010106155195528235160=201701010615519552823515799=10000100268=1279=1269=048=17359555=6SZ683=356158270=10207.0271=43346=81023=610=134
1128=99=18035=X49=SAMPLE75=2017010134=452452=2017010109322473948055560=201701010932247394805555799=10000100268=1279=1269=148=17359555=6SZ683=356159270=10220.0271=4346=21023=710=094
1128=99=18135=X49=SAMPLE75=2017010134=200852=2017010110181748719916160=201701011018174871991615799=10000100268=1279=1269=048=17359555=6SZ683=356160270=10207.0271=13346=71023=610=148
1128=99=18135=X49=SAMPLE75=2017010134=454252=2017010103490633659924560=201701010349063365992455799=10000100268=1279=1269=148=17359555=6SZ683=356161270=10220.0271=34346=31023=710=153
1128=99=18135=X49=SAMPLE75=2017010134=45952=2017010103493564364395160=201701010349356436439515799=10000100268=1279=1269=048=17359555=6SZ683=356162270=10207.0271=43346=81023=610=142
1128=99=18135=X49=SAMPLE75=2017010134=377252=2017010100591911954530660=201701010059191195453065799=10000100268=1279=1269=048=17359555=6SZ683=356163270=10207.0271=13346=71023=610=142
1128=99=18035=X49=SAMPLE75=2017010134=345252=2017010113523263745604460=201701011352326374560445799=10000100268=1279=1269=148=17359555=6SZ683=356164270=10220.0271=4346=21023=710=087
1128=99=18135=X49=SAMPLE75=2017010134=180852=2017010102253467884906560=201701010225346788490655799=10000100268=1279=1269=048=17359555=6SZ683=356165270=10207.0271=43346=81023=610=157
1128=99=18135=X49=SAMPLE75=2017010134=58852=2017010114052577458219660=201701011405257745821965799=10000100268=1279=1269=148=17359555=6SZ683=356166270=10220.0271=34346=31023=710=161
1128=99=18035=X49=SAMPLE75=2017010134=468352=2017010100133550401376360=201701010013355040137635799=10000100268=1279=1269=148=17359555=6SZ683=356167270=10220.0271=4346=21023=710=093
1128=99=18135=X49=SAMPLE75=2017010134=17052=2017010100475573269353460=201701010047557326935345799=10000100268=1279=1269=148=17359555=6SZ683=356168270=10220.0271=34346=31023=710=177
1128=99=18035=X49=SAMPLE75=2017010134=73852=2017010113422679429835560=201701011342267942983555799=10000100268=1279=1269=048=17359555=6SZ683=356169270=10209.0271=7346=31023=410=119
1128=99=18135=X49=SAMPLE75=2017010134=269252=2017010104240068277401260=201701010424006827740125799=10000100268=1279=1269=048=17359555=6SZ683=356170270=10209.0271=10346=41023=410=186
1128=99=18035=X49=SAMPLE75=2017010134=274152=2017010110123136371217360=201701011012313637121735799=10000100268=1279=1269=148=17359555=6SZ683=356171270=10220.0271=4346=21023=710=093
1128=99=18135=X49=SAMPLE75=2017010134=283552=2017010100183648348438760=201701010018364834843875799=10000100268=1279=1269=148=17359555=6SZ683=356172270=10220.0271=34346=31023=710=141
1128=99=18135=X49=SAMPLE75=2017010134=350352=2017010102311433269766160=201701010231143326976615799=10000100268=1279=1269=048=17359555=6SZ683=356173270=10207.0271=13346=71023=610=132
1128=99=18135=X49=SAMPLE75=2017010134=420952=2017010111453529381722860=201701011145352938172285799=10000100268=1279=1269=048=17359555=6SZ683=356174270=10207.0271=43346=81023=610=142
1128=99=18035=X49=SAMPLE75=2017010134=316452=2017010110252178257535060=201701011025217825753505799=10000100268=1279=1269=148=17359555=6SZ683=356175270=10220.0271=4346=21023=710=077
1128=99=18135=X49=SAMPLE75=2017010134=174752=2017010109335612379617260=201701010933561237961725799=10000100268=1279=1269=048=17359555=6SZ683=356176270=10207.0271=13346=71023=610=125
1128=99=18135=X49=SAMPLE75=2017010134=60952=2017010111574430582903960=201701011157443058290395799=10000100268=1279=1269=148=17359555=6SZ683=356177270=10220.0271=34346=31023=710=159
1128=99=18135=X49=SAMPLE75=2017010134=257952=2017010114132157058312560=201701011413215705831255799=10000100268=1279=1269=048=17359555=6SZ683=356178270=10207.0271=43346=81023=610=145
1128=99=18135=X49=SAMPLE75=2017010134=354852=2017010108155772496057760=201701010815577249605775799=10000100268=1279=1269=048=17359555=6SZ683=356179270=10207.0271=13346=71023=610=155
1128=99=18135=X49=SAMPLE75=2017010134=476252=2017010110231380311984360=201701011023138031198435799=10000100268=1279=1269=048=17359555=6SZ683=356180270=10207.0271=43346=81023=610=153
1128=99=18035=X49=SAMPLE75=2017010134=113652=2017010105115449357707360=201701010511544935770735799=10000100268=1279=1269=148=17359555=6SZ683=356181270=10220.0271=4346=21023=710=106
1128=99=18135=X49=SAMPLE75=2017010134=15652=2017010106011824902161160=201701010601182490216115799=10000100268=1279=1269=148=17359555=6SZ683=356182270=10220.0271=34346=31023=710=177
1128=99=18135=X49=SAMPLE75=2017010134=17652=2017010107492169201898660=201701010749216920189865799=10000100268=1279=1269=148=17359555=6SZ683=356183270=10216.0271=13346=51023=310=145
1128=99=18035=X49=SAMPLE75=2017010134=285852=2017010112065277290627060=201701011206527729062705799=10000100268=1279=1269=148=17359555=6SZ683=356184270=10215.0271=4346=21023=210=083
1128=99=18035=X49=SAMPLE75=2017010134=157952=2017010109282163120939760=201701010928216312093975799=10000100268=1279=1269=148=17359555=6SZ683=356185270=10220.0271=4346=21023=710=108
1128=99=18135=X49=SAMPLE75=2017010134=236952=2017010111541006856042160=201701011154100685604215799=10000100268=1279=1269=148=17359555=6SZ683=356186270=10220.0271=34346=31023=710=148
1128=99=18035=X49=SAMPLE75=2017010134=23252=2017010113035567875193660=201701011303556787519365799=10000100268=1279=1269=148=17359555=6SZ683=356187270=10220.0271=4346=21023=710=084
1128=99=18135=X49=SAMPLE75=2017010134=121152=2017010111365100315857760=201701011136510031585775799=10000100268=1279=1269=148=17359555=6SZ683=356188270=10220.0271=34346=31023=710=167
1128=99=18035=X49=SAMPLE75=2017010134=2652=2017010108275349224473760=201701010827534922447375799=10000100268=1279=1269=148=17359555=6SZ683=356189270=10220.0271=4346=21023=710=112
1128=99=18135=X49=SAMPLE75=2017010134=165752=2017010112242806399074360=201701011224280639907435799=10000100268=1279=1269=148=17359555=6SZ683=356190270=10220.0271=34346=31023=710=146
1128=99=18135=X49=SAMPLE75=2017010134=149452=2017010106160760245908660=201701010616076024590865799=10000100268=1279=1269=048=17359555=6SZ683=356191270=10207.0271=13346=71023=610=151
1128=99=18035=X49=SAMPLE75=2017010134=132952=2017010102230215287199060=201701010223021528719905799=10000100268=1279=1269=148=17359555=6SZ683=356192270=10220.0271=4346=21023=710=101
1128=99=18135=X49=SAMPLE75=2017010134=186652=2017010112544500768877460=201701011254450076887745799=10000100268=1279=1269=048=17359555=6SZ683=356193270=10207.0271=43346=81023=610=179
1128=99=18135=X49=SAMPLE75=2017010134=41752=2017010104251750002151060=201701010425175000215105799=10000100268=1279=1269=148=17359555=6SZ683=356194270=10220.0271=34346=31023=710=164
1128=99=18035=X49=SAMPLE75=2017010134=172852=2017010103544887790022860=201701010354488779002285799=10000100268=1279=1269=148=17359555=6SZ683=356195270=10220.0271=4346=21023=710=106
1128=99=18135=X49=SAMPLE75=2017010134=426452=2017010101382965522958760=201701010138296552295875799=10000100268=1279=1269=048=17359555=6SZ683=356196270=10207.0271=13346=71023=610=174
1128=99=18135=X49=SAMPLE75=2017010134=112152=2017010110532805058137160=201701011053280505813715799=10000100268=1279=1269=148=17359555=6SZ683=356197270=10220.0271=34346=31023=710=195
1128=99=18135=X49=SAMPLE75=2017010134=202552=2017010108364474466966960=201701010836447446696695799=10000100268=1279=1269=048=17359555=6SZ683=356198270=10207.0271=43346=81023=610=205
1128=99=18135=X49=SAMPLE75=2017010134=312652=2017010100185178421595660=201701010018517842159565799=10000100268=1279=1269=048=17359555=6SZ683=356199270=10207.0271=13346=71023=610=171
1128=99=18135=X49=SAMPLE75=2017010134=409852=2017010100240128286112860=201701010024012828611285799=10000100268=1279=1269=048=17359555=6SZ683=356200270=10207.0271=43346=81023=610=154
1128=99=18135=X49=SAMPLE75=2017010134=466752=2017010110564806881831660=201701011056480688183165799=10000100268=1279=1269=048=17359555=6SZ683=356201270=10207.0271=13346=71023=610=135
1128=99=18135=X49=SAMPLE75=2017010134=317252=2017010108271898077283260=201701010827189807728325799=10000100268=1279=1269=048=17359555=6SZ683=356202270=10207.0271=43346=81023=610=134
1128=99=18035=X49=SAMPLE75=2017010134=1552=2017010103051008217545660=201701010305100821754565799=10000100268=1279=1269=148=17359555=6SZ683=356203270=10220.0271=4346=21023=710=091
1128=99=18135=X49=SAMPLE75=2017010134=169452=2017010109421647570401860=201701010942164757040185799=10000100268=1279=1269=048=17359555=6SZ683=356204270=10207.0271=13346=71023=610=125
1128=99=18135=X49=SAMPLE75=2017010134=343752=2017010103172360300130260=201701010317236030013025799=10000100268=1279=1269=148=17359555=6SZ683=356205270=10220.0271=34346=31023=710=145
1128=99=18135=X49=SAMPLE75=2017010134=247452=2017010106345232398937660=201701010634523239893765799=10000100268=1279=1269=048=17359555=6SZ683=356206270=10207.0271=43346=81023=610=146
1128=99=18135=X49=SAMPLE75=2017010134=952=2017010100252044288825960=201701010025204428882595799=10000100268=1279=1269=048=17359555=6SZ683=356207270=10207.0271=13346=71023=610=156
1128=99=18035=X49=SAMPLE75=2017010134=462252=2017010108484717673150160=201701010848471767315015799=10000100268=1279=1269=148=17359555=6SZ683=356208270=10220.0271=4346=21023=710=092
1128=99=18135=X49=SAMPLE75=2017010134=437752=2017010100174028468914960=201701010017402846891495799=10000100268=1279=1269=048=17359555=6SZ683=356209270=10207.0271=43346=81023=610=146
1128=99=18135=X49=SAMPLE75=2017010134=295252=2017010103413059987105460=201701010341305998710545799=10000100268=1279=1269=148=17359555=6SZ683=356210270=10220.0271=34346=31023=710=140
1128=99=18135=X49=SAMPLE75=2017010134=424652=2017010107015616202519360=201701010701561620251935799=10000100268=1279=1269=048=17359555=6SZ683=356211270=10207.0271=13346=71023=610=126
1128=99=18135=X49=SAMPLE75=2017010134=353852=2017010108492024200354760=201701010849202420035475799=10000100268=1279=1269=048=17359555=6SZ683=356212270=10207.0271=43346=81023=610=172
1128=99=18035=X49=SAMPLE75=2017010134=34352=2017010114190552930786960=201701011419055293078695799=10000100268=1279=1269=148=17359555=6SZ683=356213270=10220.0271=4346=21023=710=092
1128=99=18135=X49=SAMPLE75=2017010134=273052=2017010109134584494742060=201701010913458449474205799=10000100268=1279=1269=148=17359555=6SZ683=356214270=10220.0271=34346=31023=710=172
1128=99=18035=X49=SAMPLE75=2017010134=353152=2017010109103076219186760=201701010910307621918675799=10000100268=1279=1269=148=17359555=6SZ683=356215270=10220.0271=4346=21023=710=129
1128=99=18135=X49=SAMPLE75=2017010134=382052=2017010107473826904440360=201701010747382690444035799=10000100268=1279=1269=148=17359555=6SZ683=356216270=10220.0271=34346=31023=710=148
1128=99=18035=X49=SAMPLE75=2017010134=8552=2017010105334593672900360=201701010533459367290035799=10000100268=1279=1269=148=17359555=6SZ683=356217270=10220.0271=4346=21023=710=098
1128=99=18135=X49=SAMPLE75=2017010134=401152=2017010107241469224626460=201701010724146922462645799=10000100268=1279=1269=048=17359555=6SZ683=356218270=10207.0271=13346=71023=610=146
1128=99=18135=X49=SAMPLE75=2017010134=143952=2017010107305613466810860=201701010730561346681085799=10000100268=1279=1269=148=17359555=6SZ683=356219270=10220.0271=34346=31023=710=156
1128=99=18135=X49=SAMPLE75=2017010134=197052=2017010112311210819821060=201701011231121081982105799=10000100268=1279=1269=048=17359555=6SZ683=356220270=10207.0271=43346=81023=610=164
1128=99=18035=X49=SAMPLE75=2017010134=319152=2017010111283960000551460=201701011128396000055145799=10000100268=1279=1269=148=17359555=6SZ683=356221270=10220.0271=4346=21023=710=106
1128=99=18135=X49=SAMPLE75=2017010134=439752=2017010105405335327664060=201701010540533532766405799=10000100268=1279=1269=148=17359555=6SZ683=356222270=10220.0271=34346=31023=710=178
1128=99=25235=X49=SAMPLE75=2017010134=144152=2017010107233013295567660=201701010723301329556765799=10000100268=2279=1269=048=17359555=6SZ683=356223270=10210.0271=5346=31023=3279=1269=048=17359555=6SZ683=356224270=10209.0271=11346=51023=410=173
1128=99=18035=X49=SAMPLE75=2017010134=298552=2017010114111089008816160=201701011411108900881615799=10000100268=1279=1269=148=17359555=6SZ683=356225270=10220.0271=4346=21023=710=085
1128=99=18135=X49=SAMPLE75=2017010134=369652=2017010110154748378174460=201701011015474837817445799=10000100268=1279=1269=048=17359555=6SZ683=356226270=10207.0271=13346=71023=610=150
1128=99=18135=X49=SAMPLE75=2017010134=299652=2017010110362575914575060=201701011036257591457505799=10000100268=1279=1269=148=17359555=6SZ683=356227270=10220.0271=34346=31023=710=145
1128=99=18035=X49=SAMPLE75=2017010134=496752=2017010107274634226419660=201701010727463422641965799=10000100268=1279=1269=148=17359555=6SZ683=356228270=10220.0271=4346=21023=710=105
1128=99=18135=X49=SAMPLE75=2017010134=206352=2017010101074446669322560=201701010107444666932255799=10000100268=1279=1269=048=17359555=6SZ683=356229270=10207.0271=43346=81023=610=147
1128=99=18135=X49=SAMPLE75=2017010134=46352=2017010103542853593435260=201701010354285359343525799=10000100268=1279=1269=148=17359555=6SZ683=356230270=10220.0271=34346=31023=710=135
1128=99=18035=X49=SAMPLE75=2017010134=32352=2017010112291888377601160=201701011229188837760115799=10000100268=1279=1269=148=17359555=6SZ683=356231270=10220.0271=4346=21023=710=058
1128=99=18135=X49=SAMPLE75=2017010134=91552=2017010110172207461791360=201701011017220746179135799=10000100268=1279=1269=148=17359555=6SZ683=356232270=10220.0271=34346=31023=710=129
1128=99=18035=X49=SAMPLE75=2017010134=396952=2017010113554461449227360=201701011355446144922735799=10000100268=1279=1269=148=17359555=6SZ683=356233270=10220.0271=4346=21023=710=072
1128=99=18135=X49=SAMPLE75=2017010134=308652=2017010113272995975426860=201701011327299597542685799=10000100268=1279=1269=148=17359555=6SZ683=356234270=10220.0271=34346=31023=710=146
1128=99=18035=X49=SAMPLE75=2017010134=20852=2017010103282203304062560=201701010328220330406255799=10000100268=1279=1269=148=17359555=6SZ683=356235270=10220.0271=4346=21023=710=082
1128=99=18135=X49=SAMPLE75=2017010134=43152=2017010106260182593134560=201701010626018259313455799=10000100268=1279=1269=148=17359555=6SZ683=356236270=10221.0271=42346=51023=810=153
1128=99=18135=X49=SAMPLE75=2017010134=332152=2017010112152079816213860=201701011215207981621385799=10000100268=1279=1269=148=17359555=6SZ683=356237270=10221.0271=12346=41023=810=126
1128=99=18135=X49=SAMPLE75=2017010134=114652=2017010102382666932204360=201701010238266693220435799=10000100268=1279=1269=048=17359555=6SZ683=356238270=10207.0271=13346=71023=610=141
1128=99=18135=X49=SAMPLE75=2017010134=436852=2017010114002836016627360=201701011400283601662735799=10000100268=1279=1269=148=17359555=6SZ683=356239270=10220.0271=34346=31023=710=130
1128=99=18135=X49=SAMPLE75=2017010134=30752=2017010112100193832370560=201701011210019383237055799=10000100268=1279=1269=048=17359555=6SZ683=356240270=10207.0271=43346=81023=610=125
1128=99=18135=X49=SAMPLE75=2017010134=380652=2017010110093096825052360=201701011009309682505235799=10000100268=1279=1269=048=17359555=6SZ683=356241270=10207.0271=13346=71023=610=144
1128=99=18035=X49=SAMPLE75=2017010134=360952=2017010108202543042256160=201701010820254304225615799=10000100268=1279=1269=148=17359555=6SZ683=356242270=10220.0271=4346=21023=710=081
1128=99=18135=X49=SAMPLE75=2017010134=197752=2017010113032460982961460=201701011303246098296145799=10000100268=1279=1269=048=17359555=6SZ683=356243270=10207.0271=43346=81023=610=152
1128=99=18135=X49=SAMPLE75=2017010134=133552=2017010108131953494664860=201701010813195349466485799=10000100268=1279=1269=148=17359555=6SZ683=356244270=10221.0271=42346=51023=810=126
1128=99=18135=X49=SAMPLE75=2017010134=92752=2017010103382082535266360=201701010338208253526635799=10000100268=1279=1269=048=17359555=6SZ683=356245270=10207.0271=13346=71023=610=132
1128=99=18135=X49=SAMPLE75=2017010134=233152=2017010100383696757128560=201701010038369675712855799=10000100268=1279=1269=148=17359555=6SZ683=356246270=10221.0271=12346=41023=810=120
1128=99=18135=X49=SAMPLE75=2017010134=158052=2017010103390272248617060=201701010339027224861705799=10000100268=1279=1269=148=17359555=6SZ683=356247270=10220.0271=34346=31023=710=128
1128=99=18135=X49=SAMPLE75=2017010134=115252=2017010108523347993433360=201701010852334799343335799=10000100268=1279=1269=048=17359555=6SZ683=356248270=10207.0271=43346=81023=610=137
1128=99=18135=X49=SAMPLE75=2017010134=339052=2017010108140860007179360=201701010814086000717935799=10000100268=1279=1269=048=17359555=6SZ683=356249270=10207.0271=13346=71023=610=145
1128=99=18035=X49=SAMPLE75=2017010134=489152=2017010109532612871729860=201701010953261287172985799=10000100268=1279=1269=148=17359555=6SZ683=356250270=10220.0271=4346=21023=710=078
1128=99=18135=X49=SAMPLE75=2017010134=95752=2017010105471996545634660=201701010547199654563465799=10000100268=1279=1269=048=17359555=6SZ683=356251270=10207.0271=43346=81023=610=128
1128=99=18135=X49=SAMPLE75=2017010134=110552=2017010103390409051894860=201701010339040905189485799=10000100268=1279=1269=148=17359555=6SZ683=356252270=10220.0271=34346=31023=710=120
1128=99=18035=X49=SAMPLE75=2017010134=445852=2017010106550995109330560=201701010655099510933055799=10000100268=1279=1269=148=17359555=6SZ683=356253270=10220.0271=4346=21023=710=055
1128=99=18135=X49=SAMPLE75=2017010134=311652=2017010102572759510656060=201701010257275951065605799=10000100268=1279=1269=148=17359555=6SZ683=356254270=10220.0271=34346=31023=710=158
1128=99=18135=X49=SAMPLE75=2017010134=489452=2017010114330368701063860=201701011433036870106385799=10000100268=1279=1269=048=17359555=6SZ683=356255270=10207.0271=13346=71023=610=148
1128=99=18035=X49=SAMPLE75=2017010134=340252=2017010102540071785839360=201701010254007178583935799=10000100268=1279=1269=148=17359555=6SZ683=356256270=10220.0271=4346=21023=710=110
1128=99=18135=X49=SAMPLE75=2017010134=70452=2017010103242309573955560=201701010324230957395555799=10000100268=1279=1269=048=17359555=6SZ683=356257270=10207.0271=43346=81023=610=158
1128=99=18135=X49=SAMPLE75=2017010134=291852=2017010105172209420835060=201701010517220942083505799=10000100268=1279=1269=148=17359555=6SZ683=356258270=10220.0271=34346=31023=710=176
1128=99=18135=X49=SAMPLE75=2017010134=33952=2017010100333213621718360=201701010033321362171835799=10000100268=1279=1269=048=17359555=6SZ683=356259270=10207.0271=13346=71023=610=137
1128=99=18035=X49=SAMPLE75=2017010134=215152=2017010111055272104956360=201701011105527210495635799=10000100268=1279=1269=148=17359555=6SZ683=356260270=10220.0271=4346=21023=710=051
1128=99=18135=X49=SAMPLE75=2017010134=255452=2017010113322182627554360=201701011332218262755435799=10000100268=1279=1269=048=17359555=6SZ683=356261270=10207.0271=43346=81023=610=139
1128=99=18135=X49=SAMPLE75=2017010134=85152=2017010107403571869738460=201701010740357186973845799=10000100268=1279=1269=148=17359555=6SZ683=356262270=10220.0271=34346=31023=710=129
1128=99=18135=X49=SAMPLE75=2017010134=7152=2017010108085535361261660=201701010808553536126165799=10000100268=1279=1269=048=17359555=6SZ683=356263270=10207.0271=13346=71023=610=147
1128=99=18035=X49=SAMPLE75=2017010134=261752=2017010114162194456054960=201701011416219445605495799=10000100268=1279=1269=148=17359555=6SZ683=356264270=10220.0271=4346=21023=710=110
1128=99=18135=X49=SAMPLE75=2017010134=406052=2017010107232725409429460=201701010723272540942945799=10000100268=1279=1269=048=17359555=6SZ683=356265270=10207.0271=43346=81023=610=161
1128=99=18135=X49=SAMPLE75=2017010134=70752=2017010114283182658939660=201701011428318265893965799=10000100268=1279=1269=148=17359555=6SZ683=356266270=10220.0271=34346=31023=710=131
1128=99=18135=X49=SAMPLE75=2017010134=78052=2017010102542065099407360=201701010254206509940735799=10000100268=1279=1269=048=17359555=6SZ683=356267270=10207.0271=13346=71023=610=139
1128=99=18135=X49=SAMPLE75=2017010134=480252=2017010103244831610413960=201701010324483161041395799=10000100268=1279=1269=048=17359555=6SZ683=356268270=10207.0271=43346=81023=610=150
1128=99=18035=X49=SAMPLE75=2017010134=415152=2017010114184539454405160=201701011418453945440515799=10000100268=1279=1269=148=17359555=6SZ683=356269270=10220.0271=4346=21023=710=093
1128=99=18135=X49=SAMPLE75=2017010134=115252=2017010104345733696582260=201701010434573369658225799=10000100268=1279=1269=048=17359555=6SZ683=356270270=10207.0271=13346=71023=610=127
1128=99=18135=X49=SAMPLE75=2017010134=341652=2017010112595525318985760=201701011259552531898575799=10000100268=1279=1269=148=17359555=6SZ683=356271270=10220.0271=34346=31023=710=142
1128=99=18135=X49=SAMPLE75=2017010134=446052=2017010113453971426037160=201701011345397142603715799=10000100268=1279=1269=048=17359555=6SZ683=356272270=10207.0271=43346=81023=610=142
1128=99=18135=X49=SAMPLE75=2017010134=452352=2017010101112967134921760=201701010111296713492175799=10000100268=1279=1269=048=17359555=6SZ683=356273270=10207.0271=13346=71023=610=139
1128=99=18035=X49=SAMPLE75=2017010134=137452=2017010111285314631608060=201701011128531463160805799=10000100268=1279=1269=148=17359555=6SZ683=356274270=10220.0271=4346=21023=710=100
1128=99=18135=X49=SAMPLE75=2017010134=274552=2017010109102027824374260=201701010910202782437425799=10000100268=1279=1269=048=17359555=6SZ683=356275270=10207.0271=43346=81023=610=152
1128=99=18135=X49=SAMPLE75=2017010134=476752=2017010108581906914249360=201701010858190691424935799=10000100268=1279=1269=148=17359555=6SZ683=356276270=10220.0271=34346=31023=710=124
1128=99=18135=X49=SAMPLE75=2017010134=195852=2017010105412950093986860=201701010541295009398685799=10000100268=1279=1269=048=17359555=6SZ683=356277270=10207.0271=13346=71023=610=144
1128=99=18035=X49=SAMPLE75=2017010134=426752=2017010109071407722158260=201701010907140772215825799=10000100268=1279=1269=148=17359555=6SZ683=356278270=10220.0271=4346=21023=710=092
1128=99=18135=X49=SAMPLE75=2017010134=292852=2017010102365823904064660=201701010236582390406465799=10000100268=1279=1269=048=17359555=6SZ683=356279270=10207.0271=43346=81023=610=161
1128=99=18135=X49=SAMPLE75=2017010134=172852=2017010109295437155778960=201701010929543715577895799=10000100268=1279=1269=148=17359555=6SZ683=356280270=10220.0271=34346=31023=710=139
1128=99=18035=X49=SAMPLE75=2017010134=106652=2017010102220443505058160=201701010222044350505815799=10000100268=1279=1269=148=17359555=6SZ683=356281270=10220.0271=4346=21023=710=105
1128=99=18135=X49=SAMPLE75=2017010134=428052=2017010111355820075425660=201701011135582007542565799=10000100268=1279=1269=148=17359555=6SZ683=356282270=10220.0271=34346=31023=710=172
1128=99=18135=X49=SAMPLE75=2017010134=319952=2017010106311811367818260=201701010631181136781825799=10000100268=1279=1269=048=17359555=6SZ683=356283270=10207.0271=13346=71023=610=139
1128=99=18035=X49=SAMPLE75=2017010134=287052=2017010105193643661206060=201701010519364366120605799=10000100268=1279=1269=148=17359555=6SZ683=356284270=10220.0271=4346=21023=710=124
1128=99=18135=X49=SAMPLE75=2017010134=415252=2017010103353590362316860=201701010335359036231685799=10000100268=1279=1269=048=17359555=6SZ683=356285270=10207.0271=43346=81023=610=179
1128=99=18135=X49=SAMPLE75=2017010134=185052=2017010112562797720648260=201701011256279772064825799=10000100268=1279=1269=148=17359555=6SZ683=356286270=10220.0271=34346=31023=710=180
1128=99=18035=X49=SAMPLE75=2017010134=33252=2017010104173479905233060=201701010417347990523305799=10000100268=1279=1269=148=17359555=6SZ683=356287270=10220.0271=4346=21023=710=098
1128=99=18135=X49=SAMPLE75=2017010134=348252=2017010110173254130868260=201701011017325413086825799=10000100268=1279=1269=148=17359555=6SZ683=356288270=10220.0271=34346=31023=710=164
1128=99=18035=X49=SAMPLE75=2017010134=452152=2017010113572349069506660=201701011357234906950665799=10000100268=1279=1269=148=17359555=6SZ683=356289270=10220.0271=4346=21023=710=095
1128=99=18135=X49=SAMPLE75=2017010134=151152=2017010103423646463837460=201701010342364646383745799=10000100268=1279=1269=048=17359555=6SZ683=356290270=10207.0271=13346=71023=610=154
1128=99=18135=X49=SAMPLE75=2017010134=22552=2017010112030218645674260=201701011203021864567425799=10000100268=1279=1269=148=17359555=6SZ683=356291270=10220.0271=34346=31023=710=140
1128=99=18135=X49=SAMPLE75=2017010134=322552=2017010103284751574154860=201701010328475157415485799=10000100268=1279=1269=048=17359555=6SZ683=356292270=10207.0271=43346=81023=610=158
1128=99=18035=X49=SAMPLE75=2017010134=459152=2017010102303174680470560=201701010230317468047055799=10000100268=1279=1269=148=17359555=6SZ683=356293270=10220.0271=4346=21023=710=086
1128=99=18135=X49=SAMPLE75=2017010134=105952=2017010111491824675770660=201701011149182467577065799=10000100268=1279=1269=148=17359555=6SZ683=356294270=10220.0271=34346=31023=710=163
1128=99=18035=X49=SAMPLE75=2017010134=332452=2017010103014534005892860=201701010301453400589285799=10000100268=1279=1269=148=17359555=6SZ683=356295270=10220.0271=4346=21023=710=079
1128=99=18135=X49=SAMPLE75=2017010134=425752=2017010102414712450352560=201701010241471245035255799=10000100268=1279=1269=048=17359555=6SZ683=356296270=10207.0271=13346=71023=610=145
1128=99=18135=X49=SAMPLE75=2017010134=143152=2017010105095618230642860=201701010509561823064285799=10000100268=1279=1269=148=17359555=6SZ683=356297270=10220.0271=34346=31023=710=150
1128=99=18135=X49=SAMPLE75=2017010134=399152=2017010107181123150761860=201701010718112315076185799=10000100268=1279=1269=048=17359555=6SZ683=356298270=10207.0271=43346=81023=610=163
1128=99=18135=X49=SAMPLE75=2017010134=60852=2017010104463619091009660=201701010446361909100965799=10000100268=1279=1269=048=17359555=6SZ683=356299270=10207.0271=13346=71023=610=153
1128=99=18035=X49=SAMPLE75=2017010134=104052=2017010105255508097788960=201701010525550809778895799=10000100268=1279=1269=148=17359555=6SZ683=356300270=10220.0271=4346=21023=710=088
1128=99=18135=X49=SAMPLE75=2017010134=253752=2017010109453464467071460=201701010945346446707145799=10000100268=1279=1269=048=17359555=6SZ683=356301270=10207.0271=43346=81023=610=150
1128=99=18135=X49=SAMPLE75=2017010134=338352=2017010100522161831798760=201701010052216183179875799=10000100268=1279=1269=148=17359555=6SZ683=356302270=10220.0271=34346=31023=710=164
1128=99=18135=X49=SAMPLE75=2017010134=202752=2017010112383723707485960=201701011238372370748595799=10000100268=1279=1269=048=17359555=6SZ683=356303270=10207.0271=13346=71023=610=164
1128=99=18035=X49=SAMPLE75=2017010134=76852=2017010109545871959135660=201701010954587195913565799=10000100268=1279=1269=148=17359555=6SZ683=356304270=10220.0271=4346=21023=710=094
1128=99=18135=X49=SAMPLE75=2017010134=261752=2017010100361017257397860=201701010036101725739785799=10000100268=1279=1269=048=17359555=6SZ683=356305270=10207.0271=43346=81023=610=164
1128=99=18135=X49=SAMPLE75=2017010134=292852=2017010100250182920501760=201701010025018292050175799=10000100268=1279=1269=148=17359555=6SZ683=356306270=10220.0271=34346=31023=710=144
1128=99=18135=X49=SAMPLE75=2017010134=118852=2017010108304631080562960=201701010830463108056295799=10000100268=1279=1269=048=17359555=6SZ683=356307270=10207.0271=13346=71023=610=144
1128=99=18035=X49=SAMPLE75=2017010134=417652=2017010103034363154104160=201701010303436315410415799=10000100268=1279=1269=148=17359555=6SZ683=356308270=10220.0271=4346=21023=710=093
1128=99=18135=X49=SAMPLE75=2017010134=350552=2017010112400596837027960=201701011240059683702795799=10000100268=1279=1269=048=17359555=6SZ683=356309270=10207.0271=43346=81023=610=166
1128=99=18135=X49=SAMPLE75=2017010134=381652=2017010106102567816805060=201701010610256781680505799=10000100268=1279=1269=148=17359555=6SZ683=356310270=10220.0271=34346=31023=710=146
1128=99=18035=X49=SAMPLE75=2017010134=52452=2017010113113171323596560=201701011311317132359655799=10000100268=1279=1269=148=17359555=6SZ683=356311270=10220.0271=4346=21023=710=118
1128=99=18135=X49=SAMPLE75=2017010134=331952=2017010112163575070606960=201701011216357507060695799=10000100268=1279=1269=048=17359555=6SZ683=356312270=10207.0271=13346=71023=610=158
1128=99=18135=X49=SAMPLE75=2017010134=3152=2017010103020577095780260=201701010302057709578025799=10000100268=1279=1269=148=17359555=6SZ683=356313270=10220.0271=34346=31023=710=174
1128=99=18135=X49=SAMPLE75=2017010134=358352=2017010110051310417594960=201701011005131041759495799=10000100268=1279=1269=048=17359555=6SZ683=356314270=10207.0271=43346=81023=610=177
1128=99=18035=X49=SAMPLE75=2017010134=392052=2017010109384800020043560=201701010938480002004355799=10000100268=1279=1269=148=17359555=6SZ683=356315270=10220.0271=4346=21023=710=092
1128=99=18135=X49=SAMPLE75=2017010134=247852=2017010106453888158437660=201701010645388815843765799=10000100268=1279=1269=048=17359555=6SZ683=356316270=10207.0271=13346=71023=610=155
1128=99=18135=X49=SAMPLE75=2017010134=147652=2017010105292771524882760=201701010529277152488275799=10000100268=1279=1269=148=17359555=6SZ683=356317270=10220.0271=34346=31023=710=136
1128=99=18135=X49=SAMPLE75=2017010134=480152=2017010101234041354116360=201701010123404135411635799=10000100268=1279=1269=048=17359555=6SZ683=356318270=10207.0271=43346=81023=610=151
1128=99=18035=X49=SAMPLE75=2017010134=273252=2017010103280542596181560=201701010328054259618155799=10000100268=1279=1269=148=17359555=6SZ683=356319270=10220.0271=4346=21023=710=114
1128=99=18135=X49=SAMPLE75=2017010134=439452=2017010100365669756995260=201701010036566975699525799=10000100268=1279=1269=048=17359555=6SZ683=356320270=10207.0271=13346=71023=610=150
1128=99=18135=X49=SAMPLE75=2017010134=260452=2017010110330129217185460=201701011033012921718545799=10000100268=1279=1269=148=17359555=6SZ683=356321270=10220.0271=34346=31023=710=143
1128=99=18135=X49=SAMPLE75=2017010134=358852=2017010107181936593670760=201701010718193659367075799=10000100268=1279=1269=048=17359555=6SZ683=356322270=10207.0271=43346=81023=610=151
1128=99=18035=X49=SAMPLE75=2017010134=78952=2017010112383408670922760=201701011238340867092275799=10000100268=1279=1269=148=17359555=6SZ683=356323270=10220.0271=4346=21023=710=110
1128=99=18135=X49=SAMPLE75=2017010134=101452=2017010100285969545292760=201701010028596954529275799=10000100268=1279=1269=048=17359555=6SZ683=356324270=10207.0271=13346=71023=610=161
1128=99=18135=X49=SAMPLE75=2017010134=369452=2017010113274672186626960=201701011327467218662695799=10000100268=1279=1269=148=17359555=6SZ683=356325270=10220.0271=34346=31023=710=160
1128=99=18135=X49=SAMPLE75=2017010134=452052=2017010105543570034550360=201701010554357003455035799=10000100268=1279=1269=048=17359555=6SZ683=356326270=10207.0271=43346=81023=610=181
1128=99=18035=X49=SAMPLE75=2017010134=128452=2017010110345670568505460=201701011034567056850545799=10000100268=1279=1269=148=17359555=6SZ683=356327270=10220.0271=4346=21023=710=077
1128=99=18135=X49=SAMPLE75=2017010134=435252=2017010104285658164649060=201701010428565816464905799=10000100268=1279=1269=048=17359555=6SZ683=356328270=10207.0271=13346=71023=610=150
1128=99=18135=X49=SAMPLE75=2017010134=366252=2017010110041222585402360=201701011004122258540235799=10000100268=1279=1269=148=17359555=6SZ683=356329270=10220.0271=34346=31023=710=171
1128=99=18135=X49=SAMPLE75=2017010134=452852=2017010102144521655225360=201701010214452165522535799=10000100268=1279=1269=048=17359555=6SZ683=356330270=10207.0271=43346=81023=610=145
1128=99=18135=X49=SAMPLE75=2017010134=204252=2017010105003679063990960=201701010500367906399095799=10000100268=1279=1269=048=17359555=6SZ683=356331270=10207.0271=13346=71023=610=162
1128=99=18135=X49=SAMPLE75=2017010134=20252=2017010103434964944709460=201701010343496494470945799=10000100268=1279=1269=048=17359555=6SZ683=356332270=10207.0271=43346=81023=610=143
1128=99=18035=X49=SAMPLE75=2017010134=451152=2017010110464013692348460=201701011046401369234845799=10000100268=1279=0269=148=17359555=6SZ683=356333270=10213.0271=2346=11023=110=104
1128=99=17935=X49=SAMPLE75=2017010134=353152=2017010113513391230738260=201701011351339123073825799=10000100268=1279=0269=148=17360055=6SH783=99126270=10269.0271=3346=11023=110=048
1128=99=17935=X49=SAMPLE75=2017010134=429752=2017010102172639546221760=201701010217263954622175799=10000100268=1279=0269=148=17360055=6SH783=99127270=10270.0271=3346=11023=210=057
1128=99=20835=X49=SAMPLE75=2017010134=426252=2017010101141558735809960=201701010114155873580995799=00000001268=1279=0269=248=17359555=6SZ683=356334270=10213.0271=2346=25797=137705=237=032=237=032=210=083
1128=99=15635=X49=SAMPLE75=2017010134=35052=2017010113554389029207860=201701011355438902920785799=00000010268=1279=0269=e48=17359555=6SZ683=356335271=3110=083
1128=99=25235=X49=SAMPLE75=2017010134=496452=2017010109350703912952460=201701010935070391295245799=10000100268=2279=2269=148=17359555=6SZ683=356336270=10213.0271=2346=11023=1279=0269=148=17359555=6SZ683=356337270=10223.0271=9346=31023=1010=186
1128=99=17935=X49=SAMPLE75=2017010134=326552=2017010102081321336196060=201701010208132133619605799=10000100268=1279=0269=048=17360055=6SH783=99128270=10266.0271=3346=11023=110=007
1128=99=25035=X49=SAMPLE75=2017010134=493652=2017010101432365767688460=201701010143236576768845799=10000100268=2279=2269=148=17360055=6SH783=99129270=10269.0271=3346=11023=1279=0269=148=17360055=6SH783=99130270=10279.0271=3346=11023=1010=040
1128=99=25135=X49=SAMPLE75=2017010134=488352=2017010109081742605535360=201701010908174260553535799=10000100268=2279=2269=148=17360055=6SH783=99131270=10270.0271=3346=11023=1279=0269=148=17360055=6SH783=99132270=10280.0271=53346=11023=1010=078
1128=99=25135=X49=SAMPLE75=2017010134=218952=2017010100255540756151460=201701010025554075615145799=10000100268=2279=0269=148=17359555=6SZ683=356338270=10213.0271=1346=11023=1279=1269=148=17359555=6SZ683=356339270=10214.0271=2346=21023=210=126
1128=99=25035=X49=SAMPLE75=2017010134=199552=2017010104515227932746360=201701010451522793274635799=10000100268=2279=2269=048=17360055=6SH783=99133270=10266.0271=3346=11023=1279=0269=048=17360055=6SH783=99134270=10256.0271=3346=11023=1010=016
1128=99=18035=X49=SAMPLE75=2017010134=27352=2017010103364923835327560=201701010336492383532755799=10000100268=1279=1269=148=17359555=6SZ683=356340270=10220.0271=4346=21023=810=107
1128=99=17935=X49=SAMPLE75=2017010134=376952=2017010100555445866585760=201701010055544586658575799=10000100268=1279=0269=148=17360055=6SH783=99135270=10270.0271=3346=11023=110=032
1128=99=18135=X49=SAMPLE75=2017010134=361552=2017010114242752796243960=201701011424275279624395799=10000100268=1279=1269=148=17359555=6SZ683=356341270=10220.0271=34346=31023=810=120
1128=99=18035=X49=SAMPLE75=2017010134=106452=2017010112231224859001060=201701011223122485900105799=10000100268=1279=1269=148=17359555=6SZ683=356342270=10220.0271=4346=21023=810=085
1128=99=18135=X49=SAMPLE75=2017010134=322852=2017010107100277414091860=201701010710027741409185799=10000100268=1279=1269=148=17359555=6SZ683=356343270=10220.0271=34346=31023=810=165
1128=99=18035=X49=SAMPLE75=2017010134=200652=2017010100442642802329460=201701010044264280232945799=10000100268=1279=1269=148=17359555=6SZ683=356344270=10220.0271=4346=21023=810=119
1128=99=18135=X49=SAMPLE75=2017010134=120752=2017010110155499596653460=201701011015549959665345799=10000100268=1279=1269=148=17359555=6SZ683=356345270=10220.0271=34346=31023=810=149
1128=99=18035=X49=SAMPLE75=2017010134=324752=2017010112293100972833760=201701011229310097283375799=10000100268=1279=1269=148=17359555=6SZ683=356346270=10220.0271=4346=21023=810=099
1128=99=18135=X49=SAMPLE75=2017010134=133952=2017010102104611871864960=201701010210461187186495799=10000100268=1279=1269=148=17359555=6SZ683=356347270=10220.0271=34346=31023=810=154
1128=99=18035=X49=SAMPLE75=2017010134=450452=2017010105550409242783160=201701010555040924278315799=10000100268=1279=1269=148=17359555=6SZ683=356348270=10220.0271=4346=21023=810=122
1128=99=18135=X49=SAMPLE75=2017010134=460452=2017010114111932158949160=201701011411193215894915799=10000100268=1279=1269=048=17359555=6SZ683=356349270=10207.0271=13346=71023=610=198
1128=99=18135=X49=SAMPLE75=2017010134=297752=2017010106145414454729960=201701010614541445472995799=10000100268=1279=1269=148=17359555=6SZ683=356350270=10220.0271=34346=31023=810=165
1128=99=18135=X49=SAMPLE75=2017010134=299552=2017010106465405258442460=201701010646540525844245799=10000100268=1279=1269=048=17359555=6SZ683=356351270=10207.0271=43346=81023=610=161
1128=99=18035=X49=SAMPLE75=2017010134=324552=2017010110143326918675860=201701011014332691867585799=10000100268=1279=1269=148=17359555=6SZ683=356352270=10220.0271=4346=21023=810=093
1128=99=18135=X49=SAMPLE75=2017010134=213952=2017010105202772739668260=201701010520277273966825799=10000100268=1279=1269=148=17359555=6SZ683=356353270=10220.0271=34346=31023=810=142
1128=99=18035=X49=SAMPLE75=2017010134=439652=2017010112241152307866060=201701011224115230786605799=10000100268=1279=1269=148=17359555=6SZ683=356354270=10220.0271=4346=21023=810=077
1128=99=18135=X49=SAMPLE75=2017010134=207252=2017010108253495807994760=201701010825349580799475799=10000100268=1279=1269=048=17359555=6SZ683=356355270=10207.0271=13346=71023=610=139
1128=99=18135=X49=SAMPLE75=2017010134=37352=2017010104243017600756660=201701010424301760075665799=10000100268=1279=1269=148=17359555=6SZ683=356356270=10220.0271=34346=31023=810=152
1128=99=18135=X49=SAMPLE75=2017010134=188252=2017010113371891050500060=201701011337189105050005799=10000100268=1279=1269=048=17359555=6SZ683=356357270=10207.0271=43346=81023=610=151
1128=99=18135=X49=SAMPLE75=2017010134=70552=2017010104030171944380060=201701010403017194438005799=10000100268=1279=1269=048=17359555=6SZ683=356358270=10207.0271=13346=71023=610=145
1128=99=18035=X49=SAMPLE75=2017010134=301952=2017010109351099021738260=201701010935109902173825799=10000100268=1279=1269=148=17359555=6SZ683=356359270=10220.0271=4346=21023=810=082
1128=99=18135=X49=SAMPLE75=2017010134=41852=2017010101040390468139360=201701010104039046813935799=10000100268=1279=1269=048=17359555=6SZ683=356360270=10207.0271=43346=81023=610=185
1128=99=18135=X49=SAMPLE75=2017010134=40152=2017010101574391077700360=201701010157439107770035799=10000100268=1279=1269=148=17359555=6SZ683=356361270=10220.0271=34346=31023=810=141
1128=99=18135=X49=SAMPLE75=2017010134=115752=2017010107103088922046760=201701010710308892204675799=10000100268=1279=1269=048=17359555=6SZ683=356362270=10207.0271=13346=71023=610=144
1128=99=18135=X49=SAMPLE75=2017010134=191552=2017010100231771455226360=201701010023177145522635799=10000100268=1279=1269=048=17359555=6SZ683=356363270=10207.0271=43346=81023=610=155
1128=99=18135=X49=SAMPLE75=2017010134=56252=2017010102512232938745960=201701010251223293874595799=10000100268=1279=1269=048=17359555=6SZ683=356364270=10207.0271=13346=71023=610=127
1128=99=18035=X49=SAMPLE75=2017010134=22552=2017010109211697087301460=201701010921169708730145799=10000100268=1279=1269=148=17359555=6SZ683=356365270=10220.0271=4346=21023=810=079
1128=99=18135=X49=SAMPLE75=2017010134=130752=2017010107243352615515060=201701010724335261551505799=10000100268=1279=1269=048=17359555=6SZ683=356366270=10207.0271=43346=81023=610=161
1128=99=18135=X49=SAMPLE75=2017010134=358752=2017010108381658940103160=201701010838165894010315799=10000100268=1279=1269=148=17359555=6SZ683=356367270=10220.0271=34346=31023=810=158
1128=99=18135=X49=SAMPLE75=2017010134=101852=2017010110351034652190060=201701011035103465219005799=10000100268=1279=1269=048=17359555=6SZ683=356368270=10207.0271=13346=71023=610=139
1128=99=18035=X49=SAMPLE75=2017010134=132752=2017010108391693096080760=201701010839169309608075799=10000100268=1279=1269=148=17359555=6SZ683=356369270=10220.0271=4346=21023=810=087
1128=99=18135=X49=SAMPLE75=2017010134=245852=2017010110164438801148360=201701011016443880114835799=10000100268=1279=1269=048=17359555=6SZ683=356370270=10207.0271=43346=81023=610=141
1128=99=18135=X49=SAMPLE75=2017010134=242352=2017010114011128310752260=201701011401112831075225799=10000100268=1279=1269=148=17359555=6SZ683=356371270=10220.0271=34346=31023=810=137
1128=99=18035=X49=SAMPLE75=2017010134=53952=2017010114303171059646760=201701011430317105964675799=10000100268=1279=1269=148=17359555=6SZ683=356372270=10220.0271=4346=21023=810=080
1128=99=18135=X49=SAMPLE75=2017010134=352252=2017010101380249006885660=201701010138024900688565799=10000100268=1279=1269=148=17359555=6SZ683=356373270=10220.0271=34346=31023=810=164
1128=99=20835=X49=SAMPLE75=2017010134=400352=2017010105541403577318160=201701010554140357731815799=00000001268=1279=0269=248=17359555=6SZ683=356374270=10213.0271=1346=25797=137705=237=032=137=032=110=050
1128=99=15635=X49=SAMPLE75=2017010134=68752=2017010105042556453052360=201701010504255645305235799=00000010268=1279=0269=e48=17359555=6SZ683=356375271=3210=069
1128=99=25235=X49=SAMPLE75=2017010134=202852=2017010103414367060707460=201701010341436706070745799=10000100268=2279=2269=148=17359555=6SZ683=356376270=10213.0271=1346=11023=1279=0269=148=17359555=6SZ683=356377270=10223.0271=9346=31023=1010=174
1128=99=17935=X49=SAMPLE75=2017010134=246052=2017010101154682894423860=201701010115468289442385799=10000100268=1279=0269=048=17360055=6SH783=99136270=10266.0271=3346=11023=110=010
1128=99=25135=X49=SAMPLE75=2017010134=361952=2017010102543894612454160=201701010254389461245415799=10000100268=2279=2269=148=17360055=6SH783=99137270=10270.0271=3346=11023=1279=0269=148=17360055=6SH783=99138270=10280.0271=53346=11023=1010=070
1128=99=25235=X49=SAMPLE75=2017010134=451052=2017010104100162145070460=201701010410016214507045799=10000100268=2279=1269=048=17359555=6SZ683=356378270=10210.0271=6346=41023=3279=1269=048=17359555=6SZ683=356379270=10209.0271=10346=41023=410=185
1128=99=18035=X49=SAMPLE75=2017010134=210852=2017010102532131191565260=201701010253213119156525799=10000100268=1279=1269=148=17359555=6SZ683=356380270=10214.0271=3346=31023=110=084
1128=99=18035=X49=SAMPLE75=2017010134=105152=2017010102413140661570460=201701010241314066157045799=10000100268=1279=1269=148=17359555=6SZ683=356381270=10220.0271=4346=21023=710=077
1128=99=25035=X49=SAMPLE75=2017010134=352952=2017010111264918593383460=201701011126491859338345799=10000100268=2279=2269=048=17360055=6SH783=99139270=10266.0271=3346=11023=1279=0269=048=17360055=6SH783=99140270=10256.0271=3346=11023=1010=038
1128=99=18135=X49=SAMPLE75=2017010134=491752=2017010106132762705378560=201701010613276270537855799=10000100268=1279=1269=148=17359555=6SZ683=356382270=10220.0271=34346=31023=710=128
1128=99=18035=X49=SAMPLE75=2017010134=168652=2017010107175916709962460=201701010717591670996245799=10000100268=1279=1269=148=17359555=6SZ683=356383270=10220.0271=4346=21023=710=059
1128=99=18135=X49=SAMPLE75=2017010134=335152=2017010104463328363482660=201701010446332836348265799=10000100268=1279=1269=148=17359555=6SZ683=356384270=10220.0271=34346=31023=710=136
1128=99=18035=X49=SAMPLE75=2017010134=37652=2017010111323400140211260=201701011132340014021125799=10000100268=1279=1269=148=17359555=6SZ683=356385270=10220.0271=4346=21023=710=092
1128=99=18135=X49=SAMPLE75=2017010134=127552=2017010101352323382381760=201701010135232338238175799=10000100268=1279=1269=148=17359555=6SZ683=356386270=10220.0271=34346=31023=710=150
1128=99=18035=X49=SAMPLE75=2017010134=473452=2017010108441662258172860=201701010844166225817285799=10000100268=1279=1269=148=17359555=6SZ683=356387270=10220.0271=4346=21023=710=114
1128=99=18135=X49=SAMPLE75=2017010134=385152=2017010105130467556700060=201701010513046755670005799=10000100268=1279=1269=048=17359555=6SZ683=356388270=10207.0271=13346=71023=610=172
1128=99=18135=X49=SAMPLE75=2017010134=451352=2017010107222035313595260=201701010722203531359525799=10000100268=1279=1269=148=17359555=6SZ683=356389270=10220.0271=34346=31023=710=160
1128=99=18135=X49=SAMPLE75=2017010134=45552=2017010110135869380787660=201701011013586938078765799=10000100268=1279=1269=048=17359555=6SZ683=356390270=10207.0271=43346=81023=610=157
1128=99=18035=X49=SAMPLE75=2017010134=57852=2017010104285049911116260=201701010428504991111625799=10000100268=1279=0269=048=17359555=6SZ683=356391270=10213.0271=1346=11023=110=071
1128=99=17935=X49=SAMPLE75=2017010134=366152=2017010101343227343723260=201701010134322734372325799=10000100268=1279=0269=048=17360055=6SH783=99141270=10266.0271=3346=11023=110=040
1128=99=18135=X49=SAMPLE75=2017010134=274152=2017010109562980293531960=201701010956298029353195799=10000100268=1279=1269=048=17359555=6SZ683=356392270=10207.0271=13346=71023=710=160
1128=99=18035=X49=SAMPLE75=2017010134=337552=2017010113540121625673260=201701011354012162567325799=10000100268=1279=1269=048=17359555=6SZ683=356393270=10208.0271=9346=41023=610=105
1128=99=18135=X49=SAMPLE75=2017010134=101552=2017010111185510422169160=201701011118551042216915799=10000100268=1279=1269=048=17359555=6SZ683=356394270=10209.0271=40346=51023=510=157
1128=99=25035=X49=SAMPLE75=2017010134=238552=2017010110085554807954260=201701011008555480795425799=10000100268=2279=2269=048=17360055=6SH783=99142270=10266.0271=3346=11023=1279=0269=048=17360055=6SH783=99143270=10256.0271=3346=11023=1010=012
1128=99=18135=X49=SAMPLE75=2017010134=387052=2017010106090794864167560=201701010609079486416755799=10000100268=1279=1269=048=17359555=6SZ683=356395270=10207.0271=43346=81023=710=166
1128=99=18135=X49=SAMPLE75=2017010134=248352=2017010106533661249373660=201701010653366124937365799=10000100268=1279=1269=048=17359555=6SZ683=356396270=10207.0271=13346=71023=710=165
1128=99=18135=X49=SAMPLE75=2017010134=399152=2017010114094874477397360=201701011409487447739735799=10000100268=1279=1269=048=17359555=6SZ683=356397270=10207.0271=43346=81023=710=182
1128=99=18035=X49=SAMPLE75=2017010134=108252=2017010101154326058700160=201701010115432605870015799=10000100268=1279=1269=148=17359555=6SZ683=356398270=10214.0271=2346=21023=110=126
1128=99=18035=X49=SAMPLE75=2017010134=279652=2017010111193523394683660=201701011119352339468365799=10000100268=1279=1269=148=17359555=6SZ683=356399270=10220.0271=4346=21023=710=104
1128=99=18135=X49=SAMPLE75=2017010134=433252=2017010111314863666193560=201701011131486366619355799=10000100268=1279=1269=048=17359555=6SZ683=356400270=10207.0271=13346=71023=710=159
1128=99=18135=X49=SAMPLE75=2017010134=161652=2017010107305084136536460=201701010730508413653645799=10000100268=1279=1269=148=17359555=6SZ683=356401270=10220.0271=34346=31023=710=138
1128=99=18035=X49=SAMPLE75=2017010134=431752=2017010106375101628976560=201701010637510162897655799=10000100268=1279=1269=148=17359555=6SZ683=356402270=10220.0271=4346=21023=710=097
1128=99=18135=X49=SAMPLE75=2017010134=345552=2017010109073007367068460=201701010907300736706845799=10000100268=1279=1269=048=17359555=6SZ683=356403270=10207.0271=43346=81023=710=169
1128=99=18135=X49=SAMPLE75=2017010134=34152=2017010110532783365002860=201701011053278336500285799=10000100268=1279=1269=148=17359555=6SZ683=356404270=10220.0271=34346=31023=710=151
1128=99=18035=X49=SAMPLE75=2017010134=351952=2017010112165644068414060=201701011216564406841405799=10000100268=1279=1269=148=17359555=6SZ683=356405270=10220.0271=4346=21023=710=071
1128=99=18135=X49=SAMPLE75=2017010134=198652=2017010109463755451442660=201701010946375545144265799=10000100268=1279=1269=148=17359555=6SZ683=356406270=10220.0271=34346=31023=710=147
1128=99=18135=X49=SAMPLE75=2017010134=224152=2017010103033372220280960=201701010303337222028095799=10000100268=1279=1269=048=17359555=6SZ683=356407270=10207.0271=13346=71023=710=177
1128=99=18035=X49=SAMPLE75=2017010134=3552=2017010104131284684052160=201701010413128468405215799=10000100268=1279=1269=148=17359555=6SZ683=356408270=10220.0271=4346=21023=710=097
1128=99=18135=X49=SAMPLE75=2017010134=225052=2017010107303033777180060=201701010730303377718005799=10000100268=1279=1269=048=17359555=6SZ683=356409270=10207.0271=43346=81023=710=160
1128=99=18135=X49=SAMPLE75=2017010134=26252=2017010102454443271607360=201701010245444327160735799=10000100268=1279=1269=148=17359555=6SZ683=356410270=10220.0271=34346=31023=710=135
1128=99=18035=X49=SAMPLE75=2017010134=496252=2017010112481008211495460=201701011248100821149545799=10000100268=1279=1269=148=17359555=6SZ683=356411270=10220.0271=4346=21023=710=085
1128=99=18135=X49=SAMPLE75=2017010134=273852=2017010103584683889753560=201701010358468388975355799=10000100268=1279=1269=148=17359555=6SZ683=356412270=10220.0271=34346=31023=710=174
1128=99=18035=X49=SAMPLE75=2017010134=338652=2017010102170772663265760=201701010217077266326575799=10000100268=1279=1269=148=17359555=6SZ683=356413270=10220.0271=4346=21023=710=095
1128=99=18135=X49=SAMPLE75=2017010134=392452=2017010109042580592751260=201701010904258059275125799=10000100268=1279=1269=148=17359555=6SZ683=356414270=10220.0271=34346=31023=710=147
1128=99=18035=X49=SAMPLE75=2017010134=51952=2017010114031144299659360=201701011403114429965935799=10000100268=1279=1269=148=17359555=6SZ683=356415270=10220.0271=4346=21023=710=107
1128=99=18135=X49=SAMPLE75=2017010134=477752=2017010107200476019686760=201701010720047601968675799=10000100268=1279=1269=048=17359555=6SZ683=356416270=10207.0271=13346=71023=710=155
1128=99=18135=X49=SAMPLE75=2017010134=283152=2017010100454050004098060=201701010045405000409805799=10000100268=1279=1269=148=17359555=6SZ683=356417270=10220.0271=34346=31023=710=161
1128=99=18135=X49=SAMPLE75=2017010134=176952=2017010106214236515165860=201701010621423651516585799=10000100268=1279=1269=048=17359555=6SZ683=356418270=10207.0271=43346=81023=710=168
1128=99=18135=X49=SAMPLE75=2017010134=352352=2017010113194192269554560=201701011319419226955455799=10000100268=1279=1269=048=17359555=6SZ683=356419270=10207.0271=13346=71023=710=144
1128=99=18135=X49=SAMPLE75=2017010134=45452=2017010109205928886095260=201701010920592888609525799=10000100268=1279=1269=048=17359555=6SZ683=356420270=10207.0271=43346=81023=710=171
1128=99=18135=X49=SAMPLE75=2017010134=279252=2017010100235918728612960=201701010023591872861295799=10000100268=1279=1269=048=17359555=6SZ683=356421270=10207.0271=13346=71023=710=152
1128=99=18035=X49=SAMPLE75=2017010134=41952=2017010113210219304413560=201701011321021930441355799=10000100268=1279=1269=148=17359555=6SZ683=356422270=10220.0271=4346=21023=710=089
1128=99=18135=X49=SAMPLE75=2017010134=495852=2017010108512102694140660=201701010851210269414065799=10000100268=1279=1269=048=17359555=6SZ683=356423270=10207.0271=43346=81023=710=176
1128=99=18135=X49=SAMPLE75=2017010134=13952=2017010106540575379693760=201701010654057537969375799=10000100268=1279=1269=148=17359555=6SZ683=356424270=10220.0271=34346=31023=710=164
1128=99=18035=X49=SAMPLE75=2017010134=187252=2017010100004821628591460=201701010000482162859145799=10000100268=1279=1269=148=17359555=6SZ683=356425270=10220.0271=4346=21023=710=090
1128=99=18135=X49=SAMPLE75=2017010134=170952=2017010108322395444157360=201701010832239544415735799=10000100268=1279=1269=048=17359555=6SZ683=356426270=10207.0271=13346=71023=710=157
1128=99=18135=X49=SAMPLE75=2017010134=343352=2017010101420777985474460=201701010142077798547445799=10000100268=1279=1269=148=17359555=6SZ683=356427270=10220.0271=34346=31023=710=164
1128=99=18135=X49=SAMPLE75=2017010134=378752=2017010101373508046575060=201701010137350804657505799=10000100268=1279=1269=048=17359555=6SZ683=356428270=10207.0271=43346=81023=710=145
1128=99=18135=X49=SAMPLE75=2017010134=355652=2017010112342360336565460=201701011234236033656545799=10000100268=1279=1269=048=17359555=6SZ683=356429270=10207.0271=13346=71023=710=174
1128=99=18035=X49=SAMPLE75=2017010134=21252=2017010104082215653375560=201701010408221565337555799=10000100268=1279=1269=148=17359555=6SZ683=356430270=10220.0271=4346=21023=710=101
1128=99=18135=X49=SAMPLE75=2017010134=30652=2017010114162140754449960=201701011416214075444995799=10000100268=1279=1269=048=17359555=6SZ683=356431270=10207.0271=43346=81023=710=182
1128=99=18135=X49=SAMPLE75=2017010134=14052=2017010111513554888112160=201701011151355488811215799=10000100268=1279=1269=148=17359555=6SZ683=356432270=10220.0271=34346=31023=710=154
1128=99=18135=X49=SAMPLE75=2017010134=25452=2017010113212284169029160=201701011321228416902915799=10000100268=1279=1269=048=17359555=6SZ683=356433270=10207.0271=13346=71023=710=157
1128=99=18035=X49=SAMPLE75=2017010134=7252=2017010109310106267167560=201701010931010626716755799=10000100268=1279=1269=148=17359555=6SZ683=356434270=10220.0271=4346=21023=710=093
1128=99=18135=X49=SAMPLE75=2017010134=155052=2017010109195766069098160=201701010919576606909815799=10000100268=1279=1269=048=17359555=6SZ683=356435270=10207.0271=43346=81023=710=182
1128=99=18135=X49=SAMPLE75=2017010134=213552=2017010102303212082831260=201701010230321208283125799=10000100268=1279=1269=148=17359555=6SZ683=356436270=10220.0271=34346=31023=710=156
1128=99=18135=X49=SAMPLE75=2017010134=98452=2017010101040739055260960=201701010104073905526095799=10000100268=1279=1269=048=17359555=6SZ683=356437270=10207.0271=13346=71023=710=172
1128=99=18035=X49=SAMPLE75=2017010134=105552=2017010105285204961268260=201701010528520496126825799=10000100268=1279=1269=148=17359555=6SZ683=356438270=10220.0271=4346=21023=710=102
1128=99=18135=X49=SAMPLE75=2017010134=74352=2017010109002054559545460=201701010900205455954545799=10000100268=1279=1269=048=17359555=6SZ683=356439270=10207.0271=43346=81023=710=182
1128=99=18135=X49=SAMPLE75=2017010134=463452=2017010101251807171898860=201701010125180717189885799=10000100268=1279=1269=148=17359555=6SZ683=356440270=10220.0271=34346=31023=710=161
1128=99=18135=X49=SAMPLE75=2017010134=124052=2017010107310918453978060=201701010731091845397805799=10000100268=1279=1269=048=17359555=6SZ683=356441270=10207.0271=13346=71023=710=170
1128=99=18035=X49=SAMPLE75=2017010134=165452=2017010108090165493885760=201701010809016549388575799=10000100268=1279=1269=148=17359555=6SZ683=356442270=10220.0271=4346=21023=710=105
1128=99=18135=X49=SAMPLE75=2017010134=88952=2017010102540948451717860=201701010254094845171785799=10000100268=1279=1269=048=17359555=6SZ683=356443270=10207.0271=43346=81023=710=158
1128=99=18135=X49=SAMPLE75=2017010134=326452=2017010111250525709792060=201701011125052570979205799=10000100268=1279=1269=148=17359555=6SZ683=356444270=10220.0271=34346=31023=710=144
1128=99=18035=X49=SAMPLE75=2017010134=421652=2017010103333319357672760=201701010333331935767275799=10000100268=1279=1269=148=17359555=6SZ683=356445270=10220.0271=4346=21023=710=083
1128=99=18135=X49=SAMPLE75=2017010134=316052=2017010107181421164972560=201701010718142116497255799=10000100268=1279=1269=148=17359555=6SZ683=356446270=10220.0271=34346=31023=710=155
1128=99=18135=X49=SAMPLE75=2017010134=338252=2017010111210632509254160=201701011121063250925415799=10000100268=1279=1269=048=17359555=6SZ683=356447270=10207.0271=13346=71023=710=174
1128=99=18035=X49=SAMPLE75=2017010134=22552=2017010114132124866733060=201701011413212486673305799=10000100268=1279=1269=148=17359555=6SZ683=356448270=10220.0271=4346=21023=710=124
1128=99=18135=X49=SAMPLE75=2017010134=188852=2017010104565016374242260=201701010456501637424225799=10000100268=1279=1269=048=17359555=6SZ683=356449270=10207.0271=43346=81023=710=182
1128=99=18135=X49=SAMPLE75=2017010134=221052=2017010107454942710131460=201701010745494271013145799=10000100268=1279=1269=148=17359555=6SZ683=356450270=10220.0271=34346=31023=710=170
1128=99=18035=X49=SAMPLE75=2017010134=266352=2017010112355858775628760=201701011235585877562875799=10000100268=1279=1269=148=17359555=6SZ683=356451270=10220.0271=4346=21023=710=118
1128=99=18135=X49=SAMPLE75=2017010134=375952=2017010105562684286518260=201701010556268428651825799=10000100268=1279=1269=048=17359555=6SZ683=356452270=10207.0271=13346=71023=710=153
1128=99=18135=X49=SAMPLE75=2017010134=217652=2017010104300082218782860=201701010430008221878285799=10000100268=1279=1269=148=17359555=6SZ683=356453270=10220.0271=34346=31023=710=164
1128=99=18135=X49=SAMPLE75=2017010134=451152=2017010101440392229628460=201701010144039222962845799=10000100268=1279=1269=048=17359555=6SZ683=356454270=10207.0271=43346=81023=710=163
1128=99=33135=X49=SAMPLE75=2017010134=140352=2017010100394356469139360=201701010039435646913935799=00000001268=2279=0269=248=17359555=6SZ683=356455270=10213.0271=1346=25797=2279=0269=248=17359555=6SZ683=356456270=10212.0271=4346=45797=237705=637=032=137=032=137=032=437=032=137=621180791228032=137=032=210=186
1128=99=15635=X49=SAMPLE75=2017010134=250752=2017010105403177958711660=201701010540317795871165799=00000010268=1279=0269=e48=17359555=6SZ683=356457271=3710=125
1128=99=32335=X49=SAMPLE75=2017010134=272052=2017010107245359413488860=201701010724535941348885799=10000100268=3279=2269=048=17359555=6SZ683=356458270=10213.0271=1346=11023=1279=1269=048=17359555=6SZ683=356459270=10212.0271=3346=31023=1279=0269=048=17359555=6SZ683=356460270=10203.0271=4346=21023=1010=251
1128=99=17935=X49=SAMPLE75=2017010134=470752=2017010102355395233821060=201701010235539523382105799=10000100268=1279=0269=148=17360055=6SH783=99144270=10269.0271=3346=11023=110=042
1128=99=18035=X49=SAMPLE75=2017010134=78252=2017010112034632181607460=201701011203463218160745799=10000100268=1279=1269=048=17359555=6SZ683=356461270=10212.0271=2346=21023=110=095
1128=99=18035=X49=SAMPLE75=2017010134=88952=2017010102051024908554460=201701010205102490855445799=10000100268=1279=1269=148=17359555=6SZ683=356462270=10214.0271=3346=31023=110=113
1128=99=25135=X49=SAMPLE75=2017010134=89052=2017010111054132004738360=201701011105413200473835799=10000100268=2279=2269=048=17360055=6SH783=99145270=10265.0271=3346=11023=1279=0269=048=17360055=6SH783=99146270=10255.0271=53346=21023=1010=086
1128=99=17935=X49=SAMPLE75=2017010134=294652=2017010112175291282026660=201701011217529128202665799=10000100268=1279=0269=148=17360055=6SH783=99147270=10270.0271=3346=11023=210=036
1128=99=18035=X49=SAMPLE75=2017010134=333752=2017010106432514706108560=201701010643251470610855799=10000100268=1279=1269=048=17359555=6SZ683=356463270=10211.0271=3346=21023=210=086
1128=99=18035=X49=SAMPLE75=2017010134=349852=2017010101472608702955760=201701010147260870295575799=10000100268=1279=1269=048=17359555=6SZ683=356464270=10212.0271=3346=31023=110=081
1128=99=24935=X49=SAMPLE75=2017010134=442452=2017010112533685459554560=201701011253368545955455799=10000100268=2279=1269=048=17360055=6SH783=99148270=10264.0271=3346=11023=1279=1269=048=17360055=6SH783=99149270=10261.0271=5346=21023=410=013
1128=99=24935=X49=SAMPLE75=2017010134=384152=2017010109082515544952960=201701010908251554495295799=10000100268=2279=1269=048=17360055=6SH783=99150270=10262.0271=5346=21023=3279=1269=048=17360055=6SH783=99151270=10261.0271=3346=11023=410=007
1128=99=18135=X49=SAMPLE75=2017010134=111552=2017010102150548981676460=201701010215054898167645799=10000100268=1279=1269=048=17359555=6SZ683=356465270=10207.0271=13346=71023=610=179
1128=99=18035=X49=SAMPLE75=2017010134=15552=2017010101501464300049660=201701010150146430004965799=10000100268=1279=1269=148=17359555=6SZ683=356466270=10220.0271=4346=21023=710=126
1128=99=25035=X49=SAMPLE75=2017010134=114452=2017010111245389493515260=201701011124538949351525799=10000100268=2279=2269=148=17360055=6SH783=99152270=10269.0271=3346=11023=1279=0269=148=17360055=6SH783=99153270=10279.0271=3346=11023=1010=066
1128=99=25135=X49=SAMPLE75=2017010134=198252=2017010112362740346483760=201701011236274034648375799=10000100268=2279=2269=148=17360055=6SH783=99154270=10270.0271=3346=11023=1279=0269=148=17360055=6SH783=99155270=10280.0271=53346=11023=1010=108
1128=99=18135=X49=SAMPLE75=2017010134=5852=2017010114305720148725960=201701011430572014872595799=10000100268=1279=1269=048=17359555=6SZ683=356467270=10209.0271=10346=41023=410=146
1128=99=18035=X49=SAMPLE75=2017010134=325052=2017010103084088121495460=201701010308408812149545799=10000100268=1279=1269=048=17359555=6SZ683=356468270=10212.0271=4346=41023=110=111
1128=99=18135=X49=SAMPLE75=2017010134=393852=2017010108320262359858360=201701010832026235985835799=10000100268=1279=1269=048=17359555=6SZ683=356469270=10206.0271=34346=31023=710=195
1128=99=18135=X49=SAMPLE75=2017010134=374952=2017010106565334715777760=201701010656533471577775799=10000100268=1279=1269=148=17359555=6SZ683=356470270=10220.0271=34346=31023=710=171
1128=99=18135=X49=SAMPLE75=2017010134=204952=2017010105065282671150460=201701010506528267115045799=10000100268=1279=1269=048=17359555=6SZ683=356471270=10208.0271=39346=51023=510=211
1128=99=18035=X49=SAMPLE75=2017010134=276652=2017010102375399795713860=201701010237539979571385799=10000100268=1279=1269=048=17359555=6SZ683=356472270=10206.0271=4346=21023=710=118
1128=99=18135=X49=SAMPLE75=2017010134=268552=2017010108462333966925260=201701010846233396692525799=10000100268=1279=1269=048=17359555=6SZ683=356473270=10206.0271=34346=31023=710=150
1128=99=18035=X49=SAMPLE75=2017010134=287152=2017010110322710675808460=201701011032271067580845799=10000100268=1279=1269=048=17359555=6SZ683=356474270=10206.0271=4346=21023=710=133
1128=99=18135=X49=SAMPLE75=2017010134=141652=2017010107012232458472160=201701010701223245847215799=10000100268=1279=1269=048=17359555=6SZ683=356475270=10206.0271=34346=31023=710=182
1128=99=18035=X49=SAMPLE75=2017010134=341752=2017010106070117454015560=201701010607011745401555799=10000100268=1279=1269=048=17359555=6SZ683=356476270=10212.0271=5346=51023=110=094
1128=99=18035=X49=SAMPLE75=2017010134=381052=2017010110063185258314060=201701011006318525831405799=10000100268=1279=1269=048=17359555=6SZ683=356477270=10206.0271=4346=21023=710=135
1128=99=18135=X49=SAMPLE75=2017010134=104352=2017010111224458647152060=201701011122445864715205799=10000100268=1279=1269=048=17359555=6SZ683=356478270=10205.0271=51346=81023=810=179
1128=99=18135=X49=SAMPLE75=2017010134=332452=2017010101075917369156860=201701010107591736915685799=10000100268=1279=1269=048=17359555=6SZ683=356479270=10206.0271=34346=31023=710=176
1128=99=18135=X49=SAMPLE75=2017010134=415352=2017010109483037778017160=201701010948303777801715799=10000100268=1279=1269=048=17359555=6SZ683=356480270=10205.0271=21346=71023=810=165
1128=99=18035=X49=SAMPLE75=2017010134=84852=2017010113484925434756160=201701011348492543475615799=10000100268=1279=1269=148=17359555=6SZ683=356481270=10220.0271=4346=21023=710=102
1128=99=18135=X49=SAMPLE75=2017010134=60152=2017010112140553088520060=201701011214055308852005799=10000100268=1279=1269=148=17359555=6SZ683=356482270=10219.0271=51346=81023=610=153
1128=99=18035=X49=SAMPLE75=2017010134=40152=2017010102260858231966160=201701010226085823196615799=10000100268=1279=1269=048=17359555=6SZ683=356483270=10206.0271=4346=21023=710=114
1128=99=18035=X49=SAMPLE75=2017010134=388752=2017010111331487185024760=201701011133148718502475799=10000100268=1279=1269=048=17359555=6SZ683=356484270=10212.0271=4346=41023=110=105
1128=99=18035=X49=SAMPLE75=2017010134=304152=2017010111472026364548260=201701011147202636454825799=10000100268=1279=1269=048=17359555=6SZ683=356485270=10212.0271=3346=31023=110=118
1128=99=18135=X49=SAMPLE75=2017010134=361052=2017010109230319234654360=201701010923031923465435799=10000100268=1279=1269=148=17359555=6SZ683=356486270=10219.0271=21346=71023=610=150
1128=99=18135=X49=SAMPLE75=2017010134=1552=2017010113482389054673060=201701011348238905467305799=10000100268=1279=1269=048=17359555=6SZ683=356487270=10206.0271=34346=31023=710=167
1128=99=18135=X49=SAMPLE75=2017010134=144052=2017010105020945239523560=201701010502094523952355799=10000100268=1279=1269=148=17359555=6SZ683=356488270=10219.0271=51346=81023=610=179
1128=99=18035=X49=SAMPLE75=2017010134=172552=2017010102055648683115860=201701010205564868311585799=10000100268=1279=1269=048=17359555=6SZ683=356489270=10206.0271=4346=21023=710=092
1128=99=18035=X49=SAMPLE75=2017010134=494552=2017010110421965324450760=201701011042196532445075799=10000100268=1279=1269=048=17359555=6SZ683=356490270=10212.0271=4346=41023=110=119
1128=99=18035=X49=SAMPLE75=2017010134=212852=2017010104221266153804960=201701010422126615380495799=10000100268=1279=1269=048=17359555=6SZ683=356491270=10212.0271=3346=31023=110=099
1128=99=18135=X49=SAMPLE75=2017010134=150252=2017010108164731316963860=201701010816473131696385799=10000100268=1279=1269=148=17359555=6SZ683=356492270=10219.0271=21346=71023=610=155
1128=99=18035=X49=SAMPLE75=2017010134=428752=2017010107504827614209860=201701010750482761420985799=10000100268=1279=1269=048=17359555=6SZ683=356493270=10212.0271=4346=41023=110=119
1128=99=18135=X49=SAMPLE75=2017010134=57252=2017010108161747434051660=201701010816174743405165799=10000100268=1279=1269=048=17359555=6SZ683=356494270=10206.0271=34346=31023=710=154
1128=99=18135=X49=SAMPLE75=2017010134=108352=2017010108321202626200760=201701010832120262620075799=10000100268=1279=1269=148=17359555=6SZ683=356495270=10219.0271=51346=81023=610=174
1128=99=18035=X49=SAMPLE75=2017010134=354652=2017010110012901577474860=201701011001290157747485799=10000100268=1279=1269=048=17359555=6SZ683=356496270=10206.0271=4346=21023=710=112
1128=99=18135=X49=SAMPLE75=2017010134=263552=2017010101091006770406460=201701010109100677040645799=10000100268=1279=1269=148=17359555=6SZ683=356497270=10219.0271=21346=71023=610=180
1128=99=18135=X49=SAMPLE75=2017010134=238852=2017010102495244276145660=201701010249524427614565799=10000100268=1279=1269=048=17359555=6SZ683=356498270=10206.0271=34346=31023=710=188
1128=99=18135=X49=SAMPLE75=2017010134=305652=2017010105472828518650560=201701010547282851865055799=10000100268=1279=1269=148=17359555=6SZ683=356499270=10219.0271=51346=81023=610=162
1128=99=18035=X49=SAMPLE75=2017010134=82052=2017010109571250475713060=201701010957125047571305799=10000100268=1279=1269=048=17359555=6SZ683=356500270=10206.0271=4346=21023=710=071
1128=99=18135=X49=SAMPLE75=2017010134=396352=2017010112091554734583360=201701011209155473458335799=10000100268=1279=1269=048=17359555=6SZ683=356501270=10206.0271=34346=31023=710=137
1128=99=18035=X49=SAMPLE75=2017010134=37052=2017010114102102728027160=201701011410210272802715799=10000100268=1279=1269=048=17359555=6SZ683=356502270=10206.0271=4346=21023=710=108
1128=99=18135=X49=SAMPLE75=2017010134=253652=2017010111550605438918660=201701011155060543891865799=10000100268=1279=1269=148=17359555=6SZ683=356503270=10219.0271=21346=71023=610=168
1128=99=18035=X49=SAMPLE75=2017010134=150352=2017010112194696379723360=201701011219469637972335799=10000100268=1279=1269=048=17359555=6SZ683=356504270=10212.0271=3346=31023=110=101
1128=99=18135=X49=SAMPLE75=2017010134=472552=2017010113535150305857160=201701011353515030585715799=10000100268=1279=1269=048=17359555=6SZ683=356505270=10206.0271=34346=31023=710=169
1128=99=18135=X49=SAMPLE75=2017010134=400752=2017010112421563611073260=201701011242156361107325799=10000100268=1279=1269=148=17359555=6SZ683=356506270=10219.0271=51346=81023=610=152
1128=99=18035=X49=SAMPLE75=2017010134=76052=2017010101022461779807160=201701010102246177980715799=10000100268=1279=1269=048=17359555=6SZ683=356507270=10206.0271=4346=21023=710=120
1128=99=18135=X49=SAMPLE75=2017010134=256652=2017010102443164174219160=201701010244316417421915799=10000100268=1279=1269=048=17359555=6SZ683=356508270=10206.0271=34346=31023=710=155
1128=99=18035=X49=SAMPLE75=2017010134=13952=2017010113040070765522060=201701011304007076552205799=10000100268=1279=1269=048=17359555=6SZ683=356509270=10206.0271=4346=21023=710=122
1128=99=18135=X49=SAMPLE75=2017010134=220952=2017010107350598245760960=201701010735059824576095799=10000100268=1279=1269=048=17359555=6SZ683=356510270=10206.0271=34346=31023=710=141
1128=99=18035=X49=SAMPLE75=2017010134=112852=2017010113344044541304260=201701011334404454130425799=10000100268=1279=1269=048=17359555=6SZ683=356511270=10206.0271=4346=21023=710=112
1128=99=18135=X49=SAMPLE75=2017010134=452952=2017010108020141768861260=201701010802014176886125799=10000100268=1279=1269=048=17359555=6SZ683=356512270=10207.0271=43346=81023=610=170
1128=99=18135=X49=SAMPLE75=2017010134=269852=2017010104193785351576260=201701010419378535157625799=10000100268=1279=1269=048=17359555=6SZ683=356513270=10207.0271=13346=71023=610=178
1128=99=18135=X49=SAMPLE75=2017010134=91352=2017010100325175058659960=201701010032517505865995799=10000100268=1279=1269=048=17359555=6SZ683=356514270=10207.0271=43346=81023=610=171
1128=99=18135=X49=SAMPLE75=2017010134=133952=2017010106193414531781260=201701010619341453178125799=10000100268=1279=1269=048=17359555=6SZ683=356515270=10207.0271=13346=71023=610=175
1128=99=18135=X49=SAMPLE75=2017010134=228652=2017010101362777505554860=201701010136277750555485799=10000100268=1279=1269=148=17359555=6SZ683=356516270=10219.0271=21346=71023=610=161
1128=99=18135=X49=SAMPLE75=2017010134=470252=2017010102520155059784360=201701010252015505978435799=10000100268=1279=1269=048=17359555=6SZ683=356517270=10206.0271=34346=31023=710=151
1128=99=18135=X49=SAMPLE75=2017010134=396652=2017010113493750890746660=201701011349375089074665799=10000100268=1279=1269=148=17359555=6SZ683=356518270=10220.0271=34346=31023=710=149
1128=99=18035=X49=SAMPLE75=2017010134=406952=2017010108132497904906560=201701010813249790490655799=10000100268=1279=1269=048=17359555=6SZ683=356519270=10212.0271=4346=41023=110=098
1128=99=18035=X49=SAMPLE75=2017010134=198252=2017010103374786317542960=201701010337478631754295799=10000100268=1279=1269=048=17359555=6SZ683=356520270=10206.0271=4346=21023=710=108
1128=99=18135=X49=SAMPLE75=2017010134=122852=2017010108092237751768560=201701010809223775176855799=10000100268=1279=1269=048=17359555=6SZ683=356521270=10206.0271=34346=31023=710=152
1128=99=18035=X49=SAMPLE75=2017010134=351552=2017010103250554691759660=201701010325055469175965799=10000100268=1279=1269=048=17359555=6SZ683=356522270=10206.0271=4346=21023=710=084
1128=99=18135=X49=SAMPLE75=2017010134=88352=2017010106215963893040560=201701010621596389304055799=10000100268=1279=1269=048=17359555=6SZ683=356523270=10206.0271=34346=31023=710=133
1128=99=18235=X49=SAMPLE75=2017010134=427252=2017010112422022831920260=201701011242202283192025799=10000100268=1279=1269=148=17359555=6SZ683=356524270=10223.0271=17346=41023=1010=199
1128=99=18135=X49=SAMPLE75=2017010134=32752=2017010107294929752542660=201701010729492975254265799=10000100268=1279=1269=148=17359555=6SZ683=356525270=10223.0271=9346=31023=1010=170
1128=99=18035=X49=SAMPLE75=2017010134=55352=2017010106475595765869360=201701010647559576586935799=10000100268=1279=1269=048=17359555=6SZ683=356526270=10212.0271=3346=31023=110=096
1128=99=18035=X49=SAMPLE75=2017010134=80452=2017010105570065335120360=201701010557006533512035799=10000100268=1279=1269=048=17359555=6SZ683=356527270=10206.0271=4346=21023=710=113
1128=99=18135=X49=SAMPLE75=2017010134=30552=2017010112380065556454560=201701011238006555645455799=10000100268=1279=1269=048=17359555=6SZ683=356528270=10206.0271=34346=31023=710=146
1128=99=18035=X49=SAMPLE75=2017010134=335652=2017010113063236468443660=201701011306323646844365799=10000100268=1279=1269=048=17359555=6SZ683=356529270=10206.0271=4346=21023=710=110
1128=99=18135=X49=SAMPLE75=2017010134=83752=2017010104112353369286360=201701010411235336928635799=10000100268=1279=1269=048=17359555=6SZ683=356530270=10206.0271=34346=31023=710=149
1128=99=18035=X49=SAMPLE75=2017010134=393652=2017010102064058030085460=201701010206405803008545799=10000100268=1279=1269=048=17359555=6SZ683=356531270=10212.0271=4346=41023=110=132
1128=99=18035=X49=SAMPLE75=2017010134=416752=2017010109081852319059160=201701010908185231905915799=10000100268=1279=1269=048=17359555=6SZ683=356532270=10206.0271=4346=21023=710=110
1128=99=18135=X49=SAMPLE75=2017010134=101052=2017010100285082391638860=201701010028508239163885799=10000100268=1279=1269=048=17359555=6SZ683=356533270=10206.0271=34346=31023=710=154
1128=99=18035=X49=SAMPLE75=2017010134=39352=2017010104350904128432160=201701010435090412843215799=10000100268=1279=1269=048=17359555=6SZ683=356534270=10206.0271=4346=21023=710=138
1128=99=18135=X49=SAMPLE75=2017010134=261052=2017010112090710681334560=201701011209071068133455799=10000100268=1279=1269=048=17359555=6SZ683=356535270=10206.0271=34346=31023=710=166
1128=99=18035=X49=SAMPLE75=2017010134=291652=2017010104021782820816260=201701010402178282081625799=10000100268=1279=1269=048=17359555=6SZ683=356536270=10206.0271=4346=21023=710=117
1128=99=18135=X49=SAMPLE75=2017010134=49952=2017010102371825595646260=201701010237182559564625799=10000100268=1279=1269=048=17359555=6SZ683=356537270=10206.0271=34346=31023=710=167
1128=99=18035=X49=SAMPLE75=2017010134=435252=2017010107503519264151460=201701010750351926415145799=10000100268=1279=1269=148=17359555=6SZ683=356538270=10220.0271=4346=21023=710=117
1128=99=18135=X49=SAMPLE75=2017010134=131152=2017010103381323081140960=201701010338132308114095799=10000100268=1279=1269=148=17359555=6SZ683=356539270=10219.0271=51346=81023=610=181
1128=99=18035=X49=SAMPLE75=2017010134=293452=2017010104461044497187360=201701010446104449718735799=10000100268=1279=1269=148=17359555=6SZ683=356540270=10218.0271=4346=21023=510=110
1128=99=18135=X49=SAMPLE75=2017010134=238752=2017010105015197527590960=201701010501519752759095799=10000100268=1279=1269=148=17359555=6SZ683=356541270=10217.0271=34346=31023=410=187
1128=99=18135=X49=SAMPLE75=2017010134=434152=2017010111323719423658960=201701011132371942365895799=10000100268=1279=1269=148=17359555=6SZ683=356542270=10219.0271=21346=71023=610=173
1128=99=18135=X49=SAMPLE75=2017010134=310252=2017010111583361980847060=201701011158336198084705799=10000100268=1279=1269=148=17359555=6SZ683=356543270=10219.0271=51346=81023=610=165
1128=99=18035=X49=SAMPLE75=2017010134=322452=2017010101331540891075160=201701010133154089107515799=10000100268=1279=1269=148=17359555=6SZ683=356544270=10217.0271=4346=21023=410=098
1128=99=18135=X49=SAMPLE75=2017010134=81752=2017010111004688226787960=201701011100468822678795799=10000100268=1279=1269=148=17359555=6SZ683=356545270=10220.0271=34346=31023=710=160
1128=99=18035=X49=SAMPLE75=2017010134=176552=2017010113035651343023060=201701011303565134302305799=10000100268=1279=1269=148=17359555=6SZ683=356546270=10220.0271=4346=21023=710=095
1128=99=18135=X49=SAMPLE75=2017010134=344652=2017010111322535882797860=201701011132253588279785799=10000100268=1279=1269=148=17359555=6SZ683=356547270=10218.0271=34346=31023=510=171
1128=99=18035=X49=SAMPLE75=2017010134=273352=2017010112052446402672060=201701011205244640267205799=10000100268=1279=1269=048=17359555=6SZ683=356548270=10206.0271=4346=21023=710=096
1128=99=18135=X49=SAMPLE75=2017010134=161052=2017010103581975596696760=201701010358197559669675799=10000100268=1279=1269=148=17359555=6SZ683=356549270=10219.0271=21346=71023=610=156
1128=99=18135=X49=SAMPLE75=2017010134=79852=2017010104212362943423760=201701010421236294342375799=10000100268=1279=1269=048=17359555=6SZ683=356550270=10206.0271=34346=31023=710=131
1128=99=18135=X49=SAMPLE75=2017010134=434752=2017010104104822920319460=201701010410482292031945799=10000100268=1279=1269=148=17359555=6SZ683=356551270=10220.0271=34346=31023=710=126
1128=99=18035=X49=SAMPLE75=2017010134=143452=2017010107493019957690960=201701010749301995769095799=10000100268=1279=1269=048=17359555=6SZ683=356552270=10212.0271=5346=51023=110=081
1128=99=18035=X49=SAMPLE75=2017010134=80052=2017010101324759138612260=201701010132475913861225799=10000100268=1279=1269=048=17359555=6SZ683=356553270=10206.0271=4346=21023=710=095
1128=99=18135=X49=SAMPLE75=2017010134=402952=2017010105251816369905560=201701010525181636990555799=10000100268=1279=1269=048=17359555=6SZ683=356554270=10206.0271=34346=31023=710=145
1128=99=18035=X49=SAMPLE75=2017010134=413452=2017010100392280203424260=201701010039228020342425799=10000100268=1279=1269=048=17359555=6SZ683=356555270=10206.0271=4346=21023=710=083
1128=99=18135=X49=SAMPLE75=2017010134=13952=2017010113475593367342760=201701011347559336734275799=10000100268=1279=1269=048=17359555=6SZ683=356556270=10207.0271=43346=81023=610=159
1128=99=18135=X49=SAMPLE75=2017010134=151452=2017010106124077627198660=201701010612407762719865799=10000100268=1279=1269=048=17359555=6SZ683=356557270=10207.0271=13346=71023=610=167
1128=99=18135=X49=SAMPLE75=2017010134=135852=2017010106214470639956360=201701010621447063995635799=10000100268=1279=1269=048=17359555=6SZ683=356558270=10207.0271=43346=81023=610=182
1128=99=18135=X49=SAMPLE75=2017010134=243152=2017010112424436504865060=201701011242443650486505799=10000100268=1279=1269=048=17359555=6SZ683=356559270=10207.0271=13346=71023=610=136
1128=99=18135=X49=SAMPLE75=2017010134=228652=2017010108061254289723760=201701010806125428972375799=10000100268=1279=1269=048=17359555=6SZ683=356560270=10207.0271=43346=81023=610=147
1128=99=18135=X49=SAMPLE75=2017010134=277252=2017010108104875280567060=201701010810487528056705799=10000100268=1279=1269=048=17359555=6SZ683=356561270=10207.0271=13346=71023=610=160
1128=99=18135=X49=SAMPLE75=2017010134=382152=2017010110371016295834060=201701011037101629583405799=10000100268=1279=1269=048=17359555=6SZ683=356562270=10207.0271=43346=81023=610=149
1128=99=18135=X49=SAMPLE75=2017010134=310752=2017010113410248872146060=201701011341024887214605799=10000100268=1279=1269=048=17359555=6SZ683=356563270=10207.0271=13346=71023=610=168
1128=99=18135=X49=SAMPLE75=2017010134=292152=2017010101080177595165660=201701010108017759516565799=10000100268=1279=1269=048=17359555=6SZ683=356564270=10207.0271=43346=81023=610=191
1128=99=18135=X49=SAMPLE75=2017010134=433652=2017010111412237980084960=201701011141223798008495799=10000100268=1279=1269=048=17359555=6SZ683=356565270=10207.0271=13346=71023=610=101
1128=99=18035=X49=SAMPLE75=2017010134=260552=2017010101481854068617160=201701010148185406861715799=10000100268=1279=1269=048=17359555=6SZ683=356566270=10208.0271=9346=41023=510=095
1128=99=18035=X49=SAMPLE75=2017010134=394652=2017010102543724006536560=201701010254372400653655799=10000100268=1279=1269=148=17359555=6SZ683=356567270=10218.0271=4346=21023=510=079
1128=99=18035=X49=SAMPLE75=2017010134=385652=2017010102355251340281960=201701010235525134028195799=10000100268=1279=1269=148=17359555=6SZ683=356568270=10220.0271=4346=21023=710=058
1128=99=18235=X49=SAMPLE75=2017010134=20552=2017010111513219519469760=201701011151321951946975799=10000100268=1279=1269=148=17359555=6SZ683=356569270=10223.0271=17346=41023=1010=183
1128=99=18035=X49=SAMPLE75=2017010134=167852=2017010103523462812181260=201701010352346281218125799=10000100268=1279=1269=048=17359555=6SZ683=356570270=10211.0271=4346=31023=210=070
1128=99=18035=X49=SAMPLE75=2017010134=253652=2017010104294701546053260=201701010429470154605325799=10000100268=1279=1269=148=17359555=6SZ683=356571270=10218.0271=5346=31023=510=083
1128=99=18135=X49=SAMPLE75=2017010134=325152=2017010101160057986486360=201701010116005798648635799=10000100268=1279=1269=148=17359555=6SZ683=356572270=10223.0271=9346=31023=1010=140
1128=99=18035=X49=SAMPLE75=2017010134=256652=2017010107081086311792860=201701010708108631179285799=10000100268=1279=0269=148=17359555=6SZ683=356573270=10213.0271=1346=11023=110=117
1128=99=17935=X49=SAMPLE75=2017010134=327852=2017010105155010576076860=201701010515501057607685799=10000100268=1279=0269=148=17360055=6SH783=99156270=10269.0271=3346=11023=110=075
1128=99=17935=X49=SAMPLE75=2017010134=207452=2017010100472212451426060=201701010047221245142605799=10000100268=1279=0269=148=17360055=6SH783=99157270=10270.0271=3346=11023=210=043
1128=99=25135=X49=SAMPLE75=2017010134=156752=2017010109204636965925060=201701010920463696592505799=10000100268=2279=1269=148=17359555=6SZ683=356574270=10213.0271=2346=21023=1279=1269=148=17359555=6SZ683=356575270=10214.0271=2346=21023=210=125
1128=99=25035=X49=SAMPLE75=2017010134=375152=2017010110393245308004760=201701011039324530800475799=10000100268=2279=2269=148=17360055=6SH783=99158270=10269.0271=3346=11023=1279=0269=148=17360055=6SH783=99159270=10279.0271=3346=11023=1010=062
1128=99=18035=X49=SAMPLE75=2017010134=427052=2017010110205759658230160=201701011020575965823015799=10000100268=1279=1269=148=17359555=6SZ683=356576270=10213.0271=1346=11023=110=113
1128=99=18035=X49=SAMPLE75=2017010134=368152=2017010106102087473658660=201701010610208747365865799=10000100268=1279=1269=048=17359555=6SZ683=356577270=10212.0271=4346=41023=110=102
1128=99=18035=X49=SAMPLE75=2017010134=114752=2017010109422429878305160=201701010942242987830515799=10000100268=1279=1269=148=17359555=6SZ683=356578270=10213.0271=2346=21023=110=126
1128=99=18035=X49=SAMPLE75=2017010134=258352=2017010112495856436611460=201701011249585643661145799=10000100268=1279=1269=148=17359555=6SZ683=356579270=10213.0271=1346=11023=110=111
1128=99=18035=X49=SAMPLE75=2017010134=428352=2017010105431238535598560=201701010543123853559855799=10000100268=1279=1269=048=17359555=6SZ683=356580270=10212.0271=5346=51023=110=125
1128=99=18135=X49=SAMPLE75=2017010134=460052=2017010107064664777740160=201701010706466477774015799=10000100268=1279=1269=148=17359555=6SZ683=356581270=10218.0271=13346=41023=610=216
1128=99=18135=X49=SAMPLE75=2017010134=187652=2017010112195774515257060=201701011219577451525705799=10000100268=1279=1269=148=17359555=6SZ683=356582270=10220.0271=12346=31023=810=176
1128=99=18035=X49=SAMPLE75=2017010134=327352=2017010100271357860907760=201701010027135786090775799=10000100268=1279=1269=148=17360055=6SH783=99160270=10277.0271=11346=21023=810=113
1128=99=18135=X49=SAMPLE75=2017010134=152352=2017010110172120613688960=201701011017212061368895799=10000100268=1279=1269=148=17360055=6SH783=99161270=10279.0271=11346=21023=1010=142
1128=99=20835=X49=SAMPLE75=2017010134=355152=2017010109093746692507760=201701010909374669250775799=00000001268=1279=0269=248=17359555=6SZ683=356583270=10213.0271=1346=25797=137705=237=032=137=032=110=075
1128=99=15635=X49=SAMPLE75=2017010134=312052=2017010106312644290711960=201701010631264429071195799=00000010268=1279=0269=e48=17359555=6SZ683=356584271=3810=124
1128=99=25235=X49=SAMPLE75=2017010134=210952=2017010109291896683318260=201701010929189668331825799=10000100268=2279=2269=148=17359555=6SZ683=356585270=10213.0271=1346=11023=1279=0269=148=17359555=6SZ683=356586270=10223.0271=9346=31023=1010=225
1128=99=17935=X49=SAMPLE75=2017010134=386752=2017010108295256912484760=201701010829525691248475799=10000100268=1279=0269=048=17360055=6SH783=99162270=10266.0271=3346=11023=110=058
1128=99=25135=X49=SAMPLE75=2017010134=347652=2017010108194981970829460=201701010819498197082945799=10000100268=2279=2269=148=17360055=6SH783=99163270=10270.0271=3346=11023=1279=0269=148=17360055=6SH783=99164270=10280.0271=53346=11023=1010=110
1128=99=17935=X49=SAMPLE75=2017010134=73252=2017010107103279215532860=201701010710327921553285799=10000100268=1279=0269=048=17360055=6SH783=99165270=10265.0271=3346=11023=210=053
1128=99=25135=X49=SAMPLE75=2017010134=265752=2017010100365258259070060=201701010036525825907005799=10000100268=2279=1269=048=17359555=6SZ683=356587270=10211.0271=5346=41023=2279=1269=048=17359555=6SZ683=356588270=10210.0271=5346=31023=310=157
1128=99=18035=X49=SAMPLE75=2017010134=278352=2017010103182079694561360=201701010318207969456135799=10000100268=1279=1269=148=17359555=6SZ683=356589270=10214.0271=3346=31023=110=123
1128=99=25035=X49=SAMPLE75=2017010134=491652=2017010100201385531423960=201701010020138553142395799=10000100268=2279=2269=048=17360055=6SH783=99166270=10266.0271=3346=11023=1279=0269=048=17360055=6SH783=99167270=10256.0271=3346=11023=1010=040
1128=99=18035=X49=SAMPLE75=2017010134=358252=2017010101453809579650160=201701010145380957965015799=10000100268=1279=1269=048=17359555=6SZ683=356590270=10212.0271=6346=61023=110=071
1128=99=18035=X49=SAMPLE75=2017010134=432752=2017010103525281455149560=201701010352528145514955799=10000100268=1279=1269=048=17359555=6SZ683=356591270=10211.0271=4346=31023=210=088
1128=99=24935=X49=SAMPLE75=2017010134=457252=2017010100244548584147760=201701010024454858414775799=10000100268=2279=1269=048=17360055=6SH783=99168270=10264.0271=5346=21023=2279=1269=048=17360055=6SH783=99169270=10262.0271=3346=11023=410=240
1128=99=18135=X49=SAMPLE75=2017010134=161852=2017010101163155653997260=201701010116315565399725799=10000100268=1279=1269=048=17359555=6SZ683=356592270=10207.0271=21346=81023=610=157
1128=99=18135=X49=SAMPLE75=2017010134=83152=2017010104394915764082660=201701010439491576408265799=10000100268=1279=1269=048=17359555=6SZ683=356593270=10205.0271=29346=81023=810=172
1128=99=18035=X49=SAMPLE75=2017010134=96552=2017010111404820627121160=201701011140482062712115799=10000100268=1279=1269=048=17360055=6SH783=99170270=10257.0271=11346=21023=910=069
1128=99=18035=X49=SAMPLE75=2017010134=354552=2017010108172663220445760=201701010817266322044575799=10000100268=1279=1269=048=17359555=6SZ683=356594270=10212.0271=5346=51023=110=093
1128=99=25135=X49=SAMPLE75=2017010134=175752=2017010110535588965954460=201701011053558896595445799=10000100268=2279=2269=048=17360055=6SH783=99171270=10265.0271=3346=11023=1279=0269=048=17360055=6SH783=99172270=10255.0271=61346=31023=1010=073
1128=99=18035=X49=SAMPLE75=2017010134=496352=2017010111421618878776960=201701011142161887877695799=10000100268=1279=1269=048=17359555=6SZ683=356595270=10211.0271=5346=41023=210=099
1128=99=25235=X49=SAMPLE75=2017010134=288152=2017010112001540707343860=201701011200154070734385799=10000100268=2279=1269=048=17359555=6SZ683=356596270=10208.0271=6346=31023=5279=1269=048=17359555=6SZ683=356597270=10207.0271=24346=91023=610=214
1128=99=25135=X49=SAMPLE75=2017010134=69752=2017010109081434455823760=201701010908143445582375799=10000100268=2279=1269=048=17359555=6SZ683=356598270=10211.0271=4346=31023=2279=1269=048=17359555=6SZ683=356599270=10210.0271=6346=41023=310=140
1128=99=18135=X49=SAMPLE75=2017010134=471852=2017010100512076653727260=201701010051207665372725799=10000100268=1279=1269=148=17359555=6SZ683=356600270=10222.0271=11346=31023=910=145
1128=99=18235=X49=SAMPLE75=2017010134=236652=2017010109390653805234860=201701010939065380523485799=10000100268=1279=1269=148=17359555=6SZ683=356601270=10223.0271=16346=41023=1010=201
1128=99=18035=X49=SAMPLE75=2017010134=30752=2017010101543697852621260=201701010154369785262125799=10000100268=1279=1269=148=17359555=6SZ683=356602270=10222.0271=4346=21023=910=088
1128=99=18135=X49=SAMPLE75=2017010134=252=2017010100132853073363960=201701010013285307336395799=10000100268=1279=1269=148=17359555=6SZ683=356603270=10223.0271=9346=31023=1010=138
1128=99=18035=X49=SAMPLE75=2017010134=149252=2017010107375091217341860=201701010737509121734185799=10000100268=1279=0269=148=17359555=6SZ683=356604270=10213.0271=1346=11023=110=086
1128=99=17935=X49=SAMPLE75=2017010134=37852=2017010107025664651580960=201701010702566465158095799=10000100268=1279=0269=148=17360055=6SH783=99173270=10269.0271=3346=11023=110=050
1128=99=17935=X49=SAMPLE75=2017010134=372352=2017010108081390902465360=201701010808139090246535799=10000100268=1279=0269=148=17360055=6SH783=99174270=10270.0271=3346=11023=210=017
1128=99=18035=X49=SAMPLE75=2017010134=141652=2017010111395045188569860=201701011139504518856985799=10000100268=1279=1269=048=17359555=6SZ683=356605270=10212.0271=4346=41023=110=089
1128=99=18035=X49=SAMPLE75=2017010134=184352=2017010113364386554741360=201701011336438655474135799=10000100268=1279=1269=148=17359555=6SZ683=356606270=10213.0271=2346=21023=110=112
1128=99=18035=X49=SAMPLE75=2017010134=163652=2017010103495578311323560=201701010349557831132355799=10000100268=1279=1269=048=17359555=6SZ683=356607270=10212.0271=3346=31023=110=098
1128=99=18035=X49=SAMPLE75=2017010134=95152=2017010104440198214392860=201701010444019821439285799=10000100268=1279=1269=048=17359555=6SZ683=356608270=10212.0271=2346=21023=110=111
1128=99=25135=X49=SAMPLE75=2017010134=104752=2017010103442959525956360=201701010344295952595635799=10000100268=2279=1269=148=17359555=6SZ683=356609270=10213.0271=3346=31023=1279=1269=148=17359555=6SZ683=356610270=10214.0271=2346=21023=210=133
1128=99=25135=X49=SAMPLE75=2017010134=315252=2017010105193435910780560=201701010519343591078055799=10000100268=2279=2269=148=17360055=6SH783=99175270=10269.0271=3346=11023=1279=0269=148=17360055=6SH783=99176270=10279.0271=11346=21023=1010=127
1128=99=18035=X49=SAMPLE75=2017010134=72352=2017010112471245701916560=201701011247124570191655799=10000100268=1279=1269=148=17359555=6SZ683=356611270=10213.0271=2346=21023=110=037
1128=99=18035=X49=SAMPLE75=2017010134=433652=2017010106050725819996160=201701010605072581999615799=10000100268=1279=1269=148=17359555=6SZ683=356612270=10214.0271=5346=31023=210=112
1128=99=25135=X49=SAMPLE75=2017010134=361652=2017010109075887129321360=201701010907588712932135799=10000100268=2279=1269=048=17359555=6SZ683=356613270=10212.0271=1346=11023=1279=1269=048=17359555=6SZ683=356614270=10208.0271=7346=41023=510=141
1128=99=24935=X49=SAMPLE75=2017010134=120352=2017010101473292183022460=201701010147329218302245799=10000100268=2279=1269=048=17360055=6SH783=99177270=10264.0271=3346=11023=1279=1269=048=17360055=6SH783=99178270=10261.0271=5346=21023=410=240
1128=99=23035=X49=SAMPLE75=2017010134=495652=2017010100243540991358760=201701010024354099135875799=00000001268=1279=0269=248=17359555=6SZ683=356615270=10213.0271=2346=35797=137705=337=032=237=621180791993932=137=032=110=129
1128=99=15635=X49=SAMPLE75=2017010134=366352=2017010108142857186539360=201701010814285718653935799=00000010268=1279=0269=e48=17359555=6SZ683=356616271=4010=114
1128=99=25235=X49=SAMPLE75=2017010134=53552=2017010113521896187775160=201701011352189618777515799=10000100268=2279=2269=148=17359555=6SZ683=356617270=10213.0271=2346=21023=1279=0269=148=17359555=6SZ683=356618270=10223.0271=9346=31023=1010=220
1128=99=17935=X49=SAMPLE75=2017010134=106352=2017010100225114715912260=201701010022511471591225799=10000100268=1279=0269=048=17360055=6SH783=99179270=10266.0271=3346=11023=110=063
1128=99=18035=X49=SAMPLE75=2017010134=10452=2017010104551335921143860=201701010455133592114385799=10000100268=1279=1269=048=17359555=6SZ683=356619270=10212.0271=2346=21023=110=117
1128=99=25135=X49=SAMPLE75=2017010134=353052=2017010109391999980539560=201701010939199998053955799=10000100268=2279=2269=148=17360055=6SH783=99180270=10270.0271=3346=11023=1279=0269=148=17360055=6SH783=99181270=10280.0271=53346=11023=1010=109
1128=99=17935=X49=SAMPLE75=2017010134=199852=2017010108013950743431660=201701010801395074343165799=10000100268=1279=0269=048=17360055=6SH783=99182270=10265.0271=3346=11023=210=071
1128=99=24935=X49=SAMPLE75=2017010134=25052=2017010109370335302693760=201701010937033530269375799=10000100268=2279=1269=048=17360055=6SH783=99183270=10262.0271=5346=21023=5279=1269=048=17360055=6SH783=99184270=10261.0271=3346=11023=610=023
1128=99=18035=X49=SAMPLE75=2017010134=63652=2017010114124593494055760=201701011412459349405575799=10000100268=1279=1269=148=17359555=6SZ683=356620270=10214.0271=2346=21023=110=117
1128=99=25135=X49=SAMPLE75=2017010134=409652=2017010113182625647151560=201701011318262564715155799=10000100268=2279=1269=048=17359555=6SZ683=356621270=10212.0271=3346=31023=1279=1269=048=17359555=6SZ683=356622270=10208.0271=6346=31023=510=171
1128=99=18035=X49=SAMPLE75=2017010134=413752=2017010112071133857053660=201701011207113385705365799=10000100268=1279=0269=048=17359555=6SZ683=356623270=10213.0271=1346=11023=110=130
1128=99=18035=X49=SAMPLE75=2017010134=271352=2017010113230870799633960=201701011323087079963395799=10000100268=1279=1269=148=17359555=6SZ683=356624270=10214.0271=1346=11023=110=117
1128=99=25335=X49=SAMPLE75=2017010134=23952=2017010100345248554321560=201701010034524855432155799=10000100268=2279=2269=148=17359555=6SZ683=356625270=10214.0271=1346=11023=1279=0269=148=17359555=6SZ683=356626270=10225.0271=18346=61023=1010=009
1128=99=24935=X49=SAMPLE75=2017010134=200752=2017010113572318287498460=201701011357231828749845799=10000100268=2279=1269=148=17360055=6SH783=99185270=10271.0271=3346=11023=1279=1269=148=17360055=6SH783=99186270=10274.0271=5346=21023=410=040
1128=99=25035=X49=SAMPLE75=2017010134=188752=2017010114065273294377360=201701011406527329437735799=10000100268=2279=2269=148=17360055=6SH783=99187270=10271.0271=3346=11023=1279=0269=148=17360055=6SH783=99188270=10281.0271=3346=11023=1010=065
1128=99=18035=X49=SAMPLE75=2017010134=291652=2017010105025449989056460=201701010502544998905645799=10000100268=1279=0269=148=17359555=6SZ683=356627270=10214.0271=1346=11023=110=117
1128=99=25135=X49=SAMPLE75=2017010134=136952=2017010103580109822794560=201701010358010982279455799=10000100268=2279=1269=048=17359555=6SZ683=356628270=10211.0271=5346=41023=3279=1269=048=17359555=6SZ683=356629270=10210.0271=5346=31023=410=175
1128=99=17935=X49=SAMPLE75=2017010134=298652=2017010114161331081539260=201701011416133108153925799=10000100268=1279=0269=148=17360055=6SH783=99189270=10271.0271=3346=11023=110=056
1128=99=18035=X49=SAMPLE75=2017010134=152852=2017010107512746911681360=201701010751274691168135799=10000100268=1279=1269=148=17359555=6SZ683=356630270=10214.0271=2346=21023=110=136
1128=99=24935=X49=SAMPLE75=2017010134=95052=2017010102283497378893860=201701010228349737889385799=10000100268=2279=1269=148=17360055=6SH783=99190270=10273.0271=5346=21023=3279=1269=148=17360055=6SH783=99191270=10274.0271=3346=11023=410=042
1128=99=25235=X49=SAMPLE75=2017010134=403352=2017010102435380642181060=201701010243538064218105799=10000100268=2279=2269=048=17359555=6SZ683=356631270=10213.0271=1346=11023=1279=0269=048=17359555=6SZ683=356632270=10203.0271=4346=21023=1010=175
1128=99=18035=X49=SAMPLE75=2017010134=460552=2017010103520734775203760=201701010352073477520375799=10000100268=1279=1269=148=17359555=6SZ683=356633270=10214.0271=3346=31023=110=093
1128=99=25035=X49=SAMPLE75=2017010134=31052=2017010108125354938999360=201701010812535493899935799=10000100268=2279=2269=048=17360055=6SH783=99192270=10266.0271=3346=11023=1279=0269=048=17360055=6SH783=99193270=10256.0271=3346=11023=1010=032
1128=99=25135=X49=SAMPLE75=2017010134=32352=2017010113533390067480460=201701011353339006748045799=10000100268=2279=2269=048=17360055=6SH783=99194270=10265.0271=3346=11023=1279=0269=048=17360055=6SH783=99195270=10255.0271=61346=31023=1010=111
1128=99=18035=X49=SAMPLE75=2017010134=125652=2017010112322546604287060=201701011232254660428705799=10000100268=1279=1269=048=17359555=6SZ683=356634270=10212.0271=4346=41023=110=075
1128=99=18035=X49=SAMPLE75=2017010134=255952=2017010112471008957051060=201701011247100895705105799=10000100268=1279=1269=148=17359555=6SZ683=356635270=10214.0271=4346=41023=110=108
1128=99=18035=X49=SAMPLE75=2017010134=99852=2017010111575619263136760=201701011157561926313675799=10000100268=1279=1269=048=17359555=6SZ683=356636270=10212.0271=5346=51023=110=084
1128=99=18035=X49=SAMPLE75=2017010134=72752=2017010101150370178340160=201701010115037017834015799=10000100268=1279=1269=048=17359555=6SZ683=356637270=10211.0271=4346=31023=210=064
1128=99=18035=X49=SAMPLE75=2017010134=35452=2017010112050026894541260=201701011205002689454125799=10000100268=1279=1269=048=17359555=6SZ683=356638270=10212.0271=8346=61023=110=064
1128=99=17935=X49=SAMPLE75=2017010134=311752=2017010112155686327661360=201701011215568632766135799=10000100268=1279=0269=048=17360055=6SH783=99196270=10265.0271=3346=11023=110=247
1128=99=24935=X49=SAMPLE75=2017010134=452052=2017010108123926073097060=201701010812392607309705799=10000100268=2279=1269=048=17360055=6SH783=99197270=10264.0271=5346=21023=2279=1269=048=17360055=6SH783=99198270=10262.0271=3346=11023=410=232
1128=99=18035=X49=SAMPLE75=2017010134=191952=2017010114304700132053060=201701011430470013205305799=10000100268=1279=0269=048=17359555=6SZ683=356639270=10213.0271=1346=11023=110=045
1128=99=17935=X49=SAMPLE75=2017010134=113752=2017010103450455077107260=201701010345045507710725799=10000100268=1279=0269=048=17360055=6SH783=99199270=10266.0271=3346=11023=110=004
1128=99=25035=X49=SAMPLE75=2017010134=362452=2017010102271602024141160=201701010227160202414115799=10000100268=2279=2269=048=17360055=6SH783=99200270=10266.0271=3346=11023=1279=0269=048=17360055=6SH783=99201270=10256.0271=3346=11023=1010=009
1128=99=25235=X49=SAMPLE75=2017010134=376152=2017010110081146589593660=201701011008114658959365799=10000100268=2279=2269=048=17359555=6SZ683=356640270=10213.0271=1346=11023=1279=0269=048=17359555=6SZ683=356641270=10203.0271=4346=21023=1010=155
1128=99=25335=X49=SAMPLE75=2017010134=382152=2017010104265257469319260=201701010426525746931925799=10000100268=2279=1269=048=17359555=6SZ683=356642270=10209.0271=18346=51023=4279=1269=048=17359555=6SZ683=356643270=10205.0271=21346=71023=810=237
1128=99=18035=X49=SAMPLE75=2017010134=464252=2017010102135816365735360=201701010213581636573535799=10000100268=1279=1269=048=17360055=6SH783=99202270=10259.0271=11346=21023=710=060
1128=99=18035=X49=SAMPLE75=2017010134=323852=2017010112462493129617060=201701011246249312961705799=10000100268=1279=1269=148=17359555=6SZ683=356644270=10214.0271=3346=31023=110=097
1128=99=25035=X49=SAMPLE75=2017010134=77952=2017010111442084695489060=201701011144208469548905799=10000100268=2279=1269=048=17360055=6SH783=99203270=10261.0271=11346=21023=5279=1269=048=17360055=6SH783=99204270=10257.0271=3346=11023=910=011
1128=99=18135=X49=SAMPLE75=2017010134=122452=2017010111124819485629760=201701011112481948562975799=10000100268=1279=1269=048=17359555=6SZ683=356645270=10209.0271=10346=41023=410=144
1128=99=18135=X49=SAMPLE75=2017010134=192052=2017010108311512362968260=201701010831151236296825799=10000100268=1279=1269=048=17359555=6SZ683=356646270=10207.0271=16346=81023=610=143
1128=99=17935=X49=SAMPLE75=2017010134=384352=2017010102124897442663160=201701010212489744266315799=10000100268=1279=1269=048=17360055=6SH783=99205270=10261.0271=3346=11023=510=254
1128=99=17935=X49=SAMPLE75=2017010134=413152=2017010111490290357719360=201701011149029035771935799=10000100268=1279=1269=048=17360055=6SH783=99206270=10259.0271=3346=11023=710=006
1128=99=18035=X49=SAMPLE75=2017010134=129752=2017010106222750644777160=201701010622275064477715799=10000100268=1279=0269=148=17359555=6SZ683=356647270=10213.0271=1346=11023=110=064
1128=99=17935=X49=SAMPLE75=2017010134=414252=2017010102222033408255660=201701010222203340825565799=10000100268=1279=0269=148=17360055=6SH783=99207270=10269.0271=3346=11023=110=027
1128=99=17935=X49=SAMPLE75=2017010134=102752=2017010105010993651284060=201701010501099365128405799=10000100268=1279=0269=148=17360055=6SH783=99208270=10270.0271=3346=11023=210=001
1128=99=18035=X49=SAMPLE75=2017010134=257852=2017010105591771344767460=201701010559177134476745799=10000100268=1279=1269=048=17359555=6SZ683=356648270=10212.0271=7346=51023=110=087
1128=99=25135=X49=SAMPLE75=2017010134=97752=2017010100115320182005460=201701010011532018200545799=10000100268=2279=2269=148=17360055=6SH783=99209270=10269.0271=3346=11023=1279=0269=148=17360055=6SH783=99210270=10279.0271=11346=21023=1010=082
1128=99=18035=X49=SAMPLE75=2017010134=38752=2017010110150460596014860=201701011015046059601485799=10000100268=1279=1269=048=17359555=6SZ683=356649270=10212.0271=6346=41023=110=097
1128=99=25235=X49=SAMPLE75=2017010134=183852=2017010101050142800543660=201701010105014280054365799=10000100268=2279=2269=148=17359555=6SZ683=356650270=10213.0271=1346=11023=1279=0269=148=17359555=6SZ683=356651270=10223.0271=9346=31023=1010=164
1128=99=18035=X49=SAMPLE75=2017010134=340252=2017010111511405676200660=201701011151140567620065799=10000100268=1279=1269=048=17359555=6SZ683=356652270=10212.0271=7346=51023=110=080
1128=99=25135=X49=SAMPLE75=2017010134=152052=2017010106192923869757360=201701010619292386975735799=10000100268=2279=2269=148=17360055=6SH783=99211270=10270.0271=3346=11023=1279=0269=148=17360055=6SH783=99212270=10280.0271=53346=11023=1010=079
1128=99=18035=X49=SAMPLE75=2017010134=290952=2017010105475931390822760=201701010547593139082275799=10000100268=1279=1269=148=17359555=6SZ683=356653270=10215.0271=3346=11023=210=097
1128=99=18035=X49=SAMPLE75=2017010134=388552=2017010110201221941839460=201701011020122194183945799=10000100268=1279=1269=148=17359555=6SZ683=356654270=10214.0271=4346=41023=110=087
1128=99=18035=X49=SAMPLE75=2017010134=293552=2017010109251559252183960=201701010925155925218395799=10000100268=1279=1269=148=17359555=6SZ683=356655270=10214.0271=3346=31023=110=099
1128=99=18035=X49=SAMPLE75=2017010134=374252=2017010100295977876873660=201701010029597787687365799=10000100268=1279=0269=048=17359555=6SZ683=356656270=10213.0271=1346=11023=110=066
1128=99=17935=X49=SAMPLE75=2017010134=207352=2017010105491165288371860=201701010549116528837185799=10000100268=1279=0269=048=17360055=6SH783=99213270=10266.0271=3346=11023=110=007
1128=99=25035=X49=SAMPLE75=2017010134=37052=2017010107185165280290660=201701010718516528029065799=10000100268=2279=2269=048=17360055=6SH783=99214270=10266.0271=3346=11023=1279=0269=048=17360055=6SH783=99215270=10256.0271=3346=11023=1010=006
1128=99=18035=X49=SAMPLE75=2017010134=2252=2017010104133157491186760=201701010413315749118675799=10000100268=1279=1269=048=17359555=6SZ683=356657270=10211.0271=5346=41023=310=081
1128=99=18035=X49=SAMPLE75=2017010134=259052=2017010112010679172907760=201701011201067917290775799=10000100268=1279=1269=148=17359555=6SZ683=356658270=10215.0271=4346=21023=210=120
1128=99=18035=X49=SAMPLE75=2017010134=350152=2017010110352233780674460=201701011035223378067445799=10000100268=1279=1269=148=17359555=6SZ683=356659270=10215.0271=3346=11023=210=115
1128=99=18035=X49=SAMPLE75=2017010134=168752=2017010110530930399270160=201701011053093039927015799=10000100268=1279=1269=148=17359555=6SZ683=356660270=10214.0271=4346=41023=110=114
1128=99=18035=X49=SAMPLE75=2017010134=93852=2017010101524122266161360=201701010152412226616135799=10000100268=1279=1269=148=17359555=6SZ683=356661270=10214.0271=3346=31023=110=095
1128=99=18035=X49=SAMPLE75=2017010134=419952=2017010102403204419558060=201701010240320441955805799=10000100268=1279=1269=148=17359555=6SZ683=356662270=10215.0271=4346=21023=210=086
1128=99=18035=X49=SAMPLE75=2017010134=161452=2017010106135863832654960=201701010613586383265495799=10000100268=1279=1269=148=17359555=6SZ683=356663270=10215.0271=3346=11023=210=126
1128=99=18035=X49=SAMPLE75=2017010134=363352=2017010110443044246668660=201701011044304424666865799=10000100268=1279=1269=148=17359555=6SZ683=356664270=10214.0271=4346=41023=110=131
1128=99=18035=X49=SAMPLE75=2017010134=24552=2017010108513439393735260=201701010851343939373525799=10000100268=1279=1269=148=17359555=6SZ683=356665270=10214.0271=3346=31023=110=099
1128=99=25235=X49=SAMPLE75=2017010134=84152=2017010111005689077561660=201701011100568907756165799=10000100268=2279=1269=148=17359555=6SZ683=356666270=10218.0271=5346=31023=5279=1269=148=17359555=6SZ683=356667270=10222.0271=12346=31023=910=210
1128=99=18035=X49=SAMPLE75=2017010134=173552=2017010108385126225953960=201701010838512622595395799=10000100268=1279=1269=148=17359555=6SZ683=356668270=10215.0271=4346=21023=210=093
1128=99=20835=X49=SAMPLE75=2017010134=296852=2017010105354189302955360=201701010535418930295535799=00000001268=1279=0269=248=17359555=6SZ683=356669270=10213.0271=1346=25797=237705=237=032=137=032=110=072
1128=99=15635=X49=SAMPLE75=2017010134=61852=2017010106452462676500360=201701010645246267650035799=00000010268=1279=0269=e48=17359555=6SZ683=356670271=4110=088
1128=99=32435=X49=SAMPLE75=2017010134=175252=2017010100493542706345160=201701010049354270634515799=10000100268=3279=2269=048=17359555=6SZ683=356671270=10213.0271=1346=11023=1279=0269=048=17359555=6SZ683=356672270=10203.0271=4346=21023=10279=0269=148=17359555=6SZ683=356673270=10213.0271=13346=11023=110=015
1128=99=17935=X49=SAMPLE75=2017010134=310052=2017010108003445176418260=201701010800344517641825799=10000100268=1279=0269=148=17360055=6SH783=99216270=10269.0271=3346=11023=110=035
1128=99=18035=X49=SAMPLE75=2017010134=119352=2017010106054138060134560=201701010605413806013455799=10000100268=1279=1269=048=17359555=6SZ683=356674270=10212.0271=6346=41023=110=108
1128=99=18135=X49=SAMPLE75=2017010134=235352=2017010105164604936508760=201701010516460493650875799=10000100268=1279=1269=148=17359555=6SZ683=356675270=10213.0271=14346=21023=110=169
1128=99=18035=X49=SAMPLE75=2017010134=353452=2017010112414123622748460=201701011241412362274845799=10000100268=1279=1269=048=17359555=6SZ683=356676270=10212.0271=5346=31023=110=112
1128=99=17935=X49=SAMPLE75=2017010134=393652=2017010100354653054053260=201701010035465305405325799=10000100268=1279=0269=148=17360055=6SH783=99217270=10270.0271=3346=11023=210=040
1128=99=24935=X49=SAMPLE75=2017010134=274352=2017010110291649415821160=201701011029164941582115799=10000100268=2279=1269=148=17360055=6SH783=99218270=10270.0271=5346=21023=2279=1269=148=17360055=6SH783=99219270=10272.0271=3346=11023=410=251
1128=99=24935=X49=SAMPLE75=2017010134=213852=2017010100045557933692660=201701010004555793369265799=10000100268=2279=1269=148=17360055=6SH783=99220270=10271.0271=5346=21023=3279=1269=148=17360055=6SH783=99221270=10273.0271=3346=11023=510=006
1128=99=25135=X49=SAMPLE75=2017010134=296752=2017010111070647278582560=201701011107064727858255799=10000100268=2279=2269=048=17360055=6SH783=99222270=10265.0271=3346=11023=1279=0269=048=17360055=6SH783=99223270=10255.0271=53346=21023=1010=084
1128=99=18035=X49=SAMPLE75=2017010134=15952=2017010107000276211255160=201701010700027621125515799=10000100268=1279=1269=048=17359555=6SZ683=356677270=10212.0271=2346=21023=110=107
1128=99=25135=X49=SAMPLE75=2017010134=474952=2017010107294417764728560=201701010729441776472855799=10000100268=2279=1269=048=17359555=6SZ683=356678270=10212.0271=1346=11023=1279=1269=048=17359555=6SZ683=356679270=10208.0271=7346=41023=510=167
1128=99=18035=X49=SAMPLE75=2017010134=374452=2017010100594733720537260=201701010059473372053725799=10000100268=1279=1269=048=17359555=6SZ683=356680270=10211.0271=4346=31023=210=113
1128=99=24935=X49=SAMPLE75=2017010134=190652=2017010110280380328338460=201701011028038032833845799=10000100268=2279=1269=048=17360055=6SH783=99224270=10264.0271=3346=11023=1279=1269=048=17360055=6SH783=99225270=10261.0271=5346=21023=410=254
1128=99=25335=X49=SAMPLE75=2017010134=68752=2017010112523882311271060=201701011252388231127105799=10000100268=2279=1269=148=17359555=6SZ683=356681270=10218.0271=13346=41023=6279=1269=148=17359555=6SZ683=356682270=10222.0271=4346=21023=1010=008
1128=99=18035=X49=SAMPLE75=2017010134=496852=2017010110274775080974360=201701011027477508097435799=10000100268=1279=1269=148=17359555=6SZ683=356683270=10214.0271=6346=41023=210=126
1128=99=18035=X49=SAMPLE75=2017010134=142052=2017010107133431165860360=201701010713343116586035799=10000100268=1279=1269=148=17359555=6SZ683=356684270=10215.0271=3346=11023=310=093
1128=99=18035=X49=SAMPLE75=2017010134=424652=2017010104020532272666960=201701010402053227266695799=10000100268=1279=1269=148=17359555=6SZ683=356685270=10214.0271=7346=51023=210=118
1128=99=18035=X49=SAMPLE75=2017010134=454052=2017010114093807529490260=201701011409380752949025799=10000100268=1279=1269=048=17359555=6SZ683=356686270=10210.0271=6346=41023=310=096
1128=99=25335=X49=SAMPLE75=2017010134=311752=2017010112133838688395060=201701011213383868839505799=10000100268=2279=1269=048=17359555=6SZ683=356687270=10208.0271=10346=51023=5279=1269=048=17359555=6SZ683=356688270=10207.0271=13346=71023=610=251
1128=99=18035=X49=SAMPLE75=2017010134=231752=2017010104231417061396860=201701010423141706139685799=10000100268=1279=1269=048=17359555=6SZ683=356689270=10210.0271=5346=31023=310=099
1128=99=25335=X49=SAMPLE75=2017010134=334052=2017010113092485510860460=201701011309248551086045799=10000100268=2279=1269=148=17359555=6SZ683=356690270=10219.0271=18346=61023=7279=1269=148=17359555=6SZ683=356691270=10220.0271=15346=41023=810=027
1128=99=25135=X49=SAMPLE75=2017010134=336952=2017010105433313754910560=201701010543331375491055799=10000100268=2279=1269=048=17359555=6SZ683=356692270=10212.0271=2346=21023=1279=1269=048=17359555=6SZ683=356693270=10211.0271=3346=21023=210=131
1128=99=25135=X49=SAMPLE75=2017010134=408552=2017010109451710580410860=201701010945171058041085799=10000100268=2279=1269=148=17359555=6SZ683=356694270=10214.0271=6346=41023=2279=1269=148=17359555=6SZ683=356695270=10215.0271=4346=21023=310=171
1128=99=25135=X49=SAMPLE75=2017010134=341252=2017010105290021348267360=201701010529002134826735799=10000100268=2279=1269=048=17359555=6SZ683=356696270=10206.0271=5346=31023=7279=1269=048=17359555=6SZ683=356697270=10204.0271=3346=11023=910=170
1128=99=25235=X49=SAMPLE75=2017010134=291552=2017010101585304614709460=201701010158530461470945799=10000100268=2279=1269=048=17359555=6SZ683=356698270=10209.0271=13346=51023=4279=1269=048=17359555=6SZ683=356699270=10208.0271=7346=41023=510=224
1128=99=25335=X49=SAMPLE75=2017010134=118652=2017010103074110010320660=201701010307411001032065799=10000100268=2279=1269=048=17359555=6SZ683=356700270=10209.0271=10346=41023=4279=1269=048=17359555=6SZ683=356701270=10208.0271=10346=51023=510=001
1128=99=25235=X49=SAMPLE75=2017010134=405352=2017010102242637465315060=201701010224263746531505799=10000100268=2279=1269=048=17359555=6SZ683=356702270=10209.0271=13346=51023=4279=1269=048=17359555=6SZ683=356703270=10208.0271=7346=41023=510=213
1128=99=25335=X49=SAMPLE75=2017010134=154752=2017010113315570086229860=201701011331557008622985799=10000100268=2279=1269=048=17359555=6SZ683=356704270=10209.0271=10346=41023=4279=1269=048=17359555=6SZ683=356705270=10208.0271=10346=51023=510=252
1128=99=18135=X49=SAMPLE75=2017010134=70552=2017010101091234590661860=201701010109123459066185799=10000100268=1279=1269=048=17359555=6SZ683=356706270=10205.0271=22346=81023=810=167
1128=99=18135=X49=SAMPLE75=2017010134=379852=2017010104514285087433960=201701010451428508743395799=10000100268=1279=1269=048=17359555=6SZ683=356707270=10203.0271=5346=31023=1010=121
1128=99=25335=X49=SAMPLE75=2017010134=247952=2017010107512048978028960=201701010751204897802895799=10000100268=2279=1269=148=17359555=6SZ683=356708270=10219.0271=21346=71023=7279=1269=148=17359555=6SZ683=356709270=10220.0271=12346=31023=810=239
1128=99=25135=X49=SAMPLE75=2017010134=132652=2017010113291207988306060=201701011329120798830605799=10000100268=2279=1269=048=17359555=6SZ683=356710270=10212.0271=1346=11023=1279=1269=048=17359555=6SZ683=356711270=10211.0271=4346=31023=210=111
1128=99=25135=X49=SAMPLE75=2017010134=70452=2017010114024082158188660=201701011402408215818865799=10000100268=2279=1269=148=17359555=6SZ683=356712270=10214.0271=7346=51023=2279=1269=148=17359555=6SZ683=356713270=10215.0271=3346=11023=310=117
1128=99=18035=X49=SAMPLE75=2017010134=283652=2017010108572441237190560=201701010857244123719055799=10000100268=1279=1269=048=17359555=6SZ683=356714270=10210.0271=6346=41023=310=069
1128=99=18135=X49=SAMPLE75=2017010134=331252=2017010113192685219447360=201701011319268521944735799=10000100268=1279=1269=148=17359555=6SZ683=356715270=10216.0271=14346=61023=410=138
1128=99=25235=X49=SAMPLE75=2017010134=482552=2017010112470338297498660=201701011247033829749865799=10000100268=2279=1269=048=17359555=6SZ683=356716270=10209.0271=13346=51023=4279=1269=048=17359555=6SZ683=356717270=10208.0271=7346=41023=510=167
1128=99=25335=X49=SAMPLE75=2017010134=222352=2017010106305484077300260=201701010630548407730025799=10000100268=2279=1269=148=17359555=6SZ683=356718270=10219.0271=18346=61023=7279=1269=148=17359555=6SZ683=356719270=10220.0271=15346=41023=810=002
1128=99=25135=X49=SAMPLE75=2017010134=269852=2017010112065207251848860=201701011206520725184885799=10000100268=2279=1269=148=17359555=6SZ683=356720270=10214.0271=6346=41023=2279=1269=148=17359555=6SZ683=356721270=10215.0271=4346=21023=310=118
1128=99=25135=X49=SAMPLE75=2017010134=311652=2017010109352019593723460=201701010935201959372345799=10000100268=2279=1269=048=17359555=6SZ683=356722270=10212.0271=2346=21023=1279=1269=048=17359555=6SZ683=356723270=10211.0271=3346=21023=210=116
1128=99=18135=X49=SAMPLE75=2017010134=113052=2017010106513537833994760=201701010651353783399475799=10000100268=1279=1269=048=17359555=6SZ683=356724270=10209.0271=14346=61023=410=145
1128=99=18035=X49=SAMPLE75=2017010134=433852=2017010100114599062845360=201701010011459906284535799=10000100268=1279=1269=148=17359555=6SZ683=356725270=10217.0271=5346=31023=510=093
1128=99=25335=X49=SAMPLE75=2017010134=58352=2017010104124602340762460=201701010412460234076245799=10000100268=2279=1269=048=17359555=6SZ683=356726270=10209.0271=11346=51023=4279=1269=048=17359555=6SZ683=356727270=10208.0271=10346=51023=510=225
1128=99=25335=X49=SAMPLE75=2017010134=90052=2017010103240213518688060=201701010324021351868805799=10000100268=2279=1269=148=17359555=6SZ683=356728270=10219.0271=21346=71023=7279=1269=148=17359555=6SZ683=356729270=10220.0271=12346=31023=810=243
1128=99=25135=X49=SAMPLE75=2017010134=327952=2017010106325402169321460=201701010632540216932145799=10000100268=2279=1269=148=17359555=6SZ683=356730270=10214.0271=7346=51023=2279=1269=148=17359555=6SZ683=356731270=10215.0271=3346=11023=310=118
1128=99=25135=X49=SAMPLE75=2017010134=56852=2017010114243652852984060=201701011424365285298405799=10000100268=2279=1269=048=17359555=6SZ683=356732270=10212.0271=1346=11023=1279=1269=048=17359555=6SZ683=356733270=10211.0271=4346=31023=210=112
1128=99=18135=X49=SAMPLE75=2017010134=473652=2017010101452042044985260=201701010145204204498525799=10000100268=1279=1269=048=17359555=6SZ683=356734270=10208.0271=11346=61023=510=127
1128=99=18135=X49=SAMPLE75=2017010134=277052=2017010113084697846553060=201701011308469784655305799=10000100268=1279=1269=148=17359555=6SZ683=356735270=10218.0271=14346=51023=610=140
1128=99=17835=X49=SAMPLE75=2017010134=187652=2017010113030018908344660=201701011303001890834465799=00000100268=1279=0269=048=17364055=6SH883=1592270=10440.0271=5346=11023=110=214
1128=99=16735=X49=SAMPLE75=2017010134=316752=2017010106104152201182360=201701010610415220118235799=10001000268=1279=0269=N48=17364055=6SH883=1593270=10440.0286=25510=032
1128=99=25335=X49=SAMPLE75=2017010134=26752=2017010109440391616198560=201701010944039161619855799=10000100268=2279=1269=148=17359555=6SZ683=356736270=10219.0271=18346=61023=7279=1269=148=17359555=6SZ683=356737270=10220.0271=15346=41023=810=023
1128=99=25135=X49=SAMPLE75=2017010134=420752=2017010101404508663292160=201701010140450866329215799=10000100268=2279=1269=048=17359555=6SZ683=356738270=10212.0271=2346=21023=1279=1269=048=17359555=6SZ683=356739270=10211.0271=3346=21023=210=148
1128=99=25135=X49=SAMPLE75=2017010134=108652=2017010111312185632182760=201701011131218563218275799=10000100268=2279=1269=148=17359555=6SZ683=356740270=10214.0271=6346=41023=2279=1269=148=17359555=6SZ683=356741270=10215.0271=4346=21023=310=143
1128=99=18135=X49=SAMPLE75=2017010134=303652=2017010107304061882384460=201701010730406188238445799=10000100268=1279=1269=048=17359555=6SZ683=356742270=10207.0271=14346=81023=610=165
1128=99=18135=X49=SAMPLE75=2017010134=183052=2017010107582899948735760=201701010758289994873575799=10000100268=1279=1269=148=17359555=6SZ683=356743270=10219.0271=19346=71023=710=171
1128=99=25335=X49=SAMPLE75=2017010134=434852=2017010100504732758584660=201701010050473275858465799=10000100268=2279=1269=148=17359555=6SZ683=356744270=10219.0271=22346=81023=7279=1269=148=17359555=6SZ683=356745270=10220.0271=12346=31023=810=245
1128=99=25135=X49=SAMPLE75=2017010134=401052=2017010107584739786275760=201701010758473978627575799=10000100268=2279=1269=048=17359555=6SZ683=356746270=10212.0271=1346=11023=1279=1269=048=17359555=6SZ683=356747270=10211.0271=4346=31023=210=140
1128=99=25135=X49=SAMPLE75=2017010134=303752=2017010101043216837151960=201701010104321683715195799=10000100268=2279=1269=148=17359555=6SZ683=356748270=10214.0271=7346=51023=2279=1269=148=17359555=6SZ683=356749270=10215.0271=3346=11023=310=163
1128=99=18035=X49=SAMPLE75=2017010134=47252=2017010103032976899896060=201701010303297689989605799=10000100268=1279=1269=048=17359555=6SZ683=356750270=10206.0271=6346=41023=710=096
1128=99=18135=X49=SAMPLE75=2017010134=436452=2017010101330768588498660=201701010133076858849865799=10000100268=1279=1269=148=17359555=6SZ683=356751270=10220.0271=13346=41023=810=129
1128=99=17835=X49=SAMPLE75=2017010134=274452=2017010104100733735245260=201701010410073373524525799=00000100268=1279=0269=148=17364055=6SH883=1594270=10576.0271=5346=11023=110=247
1128=99=16735=X49=SAMPLE75=2017010134=272152=2017010100043246392739860=201701010004324639273985799=10001000268=1279=0269=O48=17364055=6SH883=1595270=10576.0286=25510=065
1128=99=17835=X49=SAMPLE75=2017010134=441552=2017010110105279271664760=201701011010527927166475799=00000100268=1279=0269=048=17362555=6SZ783=1729270=10383.0271=5346=11023=110=012
1128=99=16735=X49=SAMPLE75=2017010134=295852=2017010110352779896673860=201701011035277989667385799=10001000268=1279=0269=N48=17362555=6SZ783=1730270=10383.0286=25510=077
1128=99=17835=X49=SAMPLE75=2017010134=298252=2017010105331617969397660=201701010533161796939765799=00000100268=1279=0269=148=17362555=6SZ783=1731270=10513.0271=5346=11023=110=015
1128=99=16735=X49=SAMPLE75=2017010134=143352=2017010100121888328742360=201701010012188832874235799=10001000268=1279=0269=O48=17362555=6SZ783=1732270=10513.0286=25510=089
1128=99=25235=X49=SAMPLE75=2017010134=45252=2017010112122898573837360=201701011212289857383735799=10000100268=2279=1269=048=17359555=6SZ683=356752270=10208.0271=8346=51023=5279=1269=048=17359555=6SZ683=356753270=10207.0271=17346=91023=610=249
1128=99=25335=X49=SAMPLE75=2017010134=236052=2017010100500891987587260=201701010050089198758725799=10000100268=2279=1269=048=17359555=6SZ683=356754270=10208.0271=11346=61023=5279=1269=048=17359555=6SZ683=356755270=10207.0271=14346=81023=610=018
1128=99=25235=X49=SAMPLE75=2017010134=306052=2017010103114557948140960=201701010311455794814095799=10000100268=2279=1269=048=17359555=6SZ683=356756270=10208.0271=8346=51023=5279=1269=048=17359555=6SZ683=356757270=10207.0271=17346=91023=610=194
1128=99=25335=X49=SAMPLE75=2017010134=391652=2017010109091368099032560=201701010909136809903255799=10000100268=2279=1269=048=17359555=6SZ683=356758270=10208.0271=11346=61023=5279=1269=048=17359555=6SZ683=356759270=10207.0271=14346=81023=610=006
1128=99=25235=X49=SAMPLE75=2017010134=461152=2017010100013400209366960=201701010001340020936695799=10000100268=2279=1269=048=17359555=6SZ683=356760270=10208.0271=8346=51023=5279=1269=048=17359555=6SZ683=356761270=10207.0271=17346=91023=610=207
1128=99=25335=X49=SAMPLE75=2017010134=297052=2017010103424817769848260=201701010342481776984825799=10000100268=2279=1269=048=17359555=6SZ683=356762270=10208.0271=11346=61023=5279=1269=048=17359555=6SZ683=356763270=10207.0271=14346=81023=610=008
1128=99=25235=X49=SAMPLE75=2017010134=258052=2017010108280098233440260=201701010828009823344025799=10000100268=2279=1269=048=17359555=6SZ683=356764270=10208.0271=8346=51023=5279=1269=048=17359555=6SZ683=356765270=10207.0271=17346=91023=610=209
1128=99=25335=X49=SAMPLE75=2017010134=144852=2017010111085195517242360=201701011108519551724235799=10000100268=2279=1269=048=17359555=6SZ683=356766270=10208.0271=11346=61023=5279=1269=048=17359555=6SZ683=356767270=10207.0271=14346=81023=610=010
1128=99=25235=X49=SAMPLE75=2017010134=752=2017010111022018553517160=201701011102201855351715799=10000100268=2279=1269=048=17359555=6SZ683=356768270=10208.0271=8346=51023=5279=1269=048=17359555=6SZ683=356769270=10207.0271=17346=91023=610=253
1128=99=25335=X49=SAMPLE75=2017010134=348352=2017010103582008180155660=201701010358200818015565799=10000100268=2279=1269=048=17359555=6SZ683=356770270=10208.0271=11346=61023=5279=1269=048=17359555=6SZ683=356771270=10207.0271=14346=81023=610=018
1128=99=17835=X49=SAMPLE75=2017010134=92252=2017010110381005827900360=201701011038100582790035799=10000100268=1279=0269=048=17360355=6SM783=7541270=10281.0271=6346=11023=410=254
1128=99=17835=X49=SAMPLE75=2017010134=349352=2017010107153858178480060=201701010715385817848005799=10000100268=1279=0269=148=17360355=6SM783=7542270=10372.0271=6346=11023=410=012
1128=99=25335=X49=SAMPLE75=2017010134=348452=2017010103110523730239260=201701010311052373023925799=10000100268=2279=1269=148=17359555=6SZ683=356772270=10219.0271=19346=71023=7279=1269=148=17359555=6SZ683=356773270=10220.0271=16346=51023=810=051
1128=99=25135=X49=SAMPLE75=2017010134=27952=2017010113203865270294160=201701011320386527029415799=10000100268=2279=1269=048=17359555=6SZ683=356774270=10212.0271=2346=21023=1279=1269=048=17359555=6SZ683=356775270=10211.0271=3346=21023=210=168
1128=99=25135=X49=SAMPLE75=2017010134=99252=2017010106155723340990060=201701010615572334099005799=10000100268=2279=1269=148=17359555=6SZ683=356776270=10214.0271=6346=41023=2279=1269=148=17359555=6SZ683=356777270=10215.0271=4346=21023=310=178
1128=99=18135=X49=SAMPLE75=2017010134=458652=2017010109593999843040060=201701010959399984304005799=10000100268=1279=1269=048=17359555=6SZ683=356778270=10205.0271=23346=91023=810=168
1128=99=25335=X49=SAMPLE75=2017010134=362952=2017010101513729179446960=201701010151372917944695799=10000100268=2279=1269=148=17359555=6SZ683=356779270=10219.0271=22346=81023=7279=1269=148=17359555=6SZ683=356780270=10220.0271=13346=41023=810=039
1128=99=25135=X49=SAMPLE75=2017010134=393652=2017010114032547634825460=201701011403254763482545799=10000100268=2279=1269=048=17359555=6SZ683=356781270=10212.0271=1346=11023=1279=1269=048=17359555=6SZ683=356782270=10211.0271=4346=31023=210=166
1128=99=25135=X49=SAMPLE75=2017010134=347952=2017010106342357437783760=201701010634235743778375799=10000100268=2279=1269=148=17359555=6SZ683=356783270=10214.0271=7346=51023=2279=1269=148=17359555=6SZ683=356784270=10215.0271=3346=11023=310=171
1128=99=18035=X49=SAMPLE75=2017010134=191352=2017010105545155129069360=201701010554515512906935799=10000100268=1279=1269=048=17359555=6SZ683=356785270=10204.0271=4346=21023=910=142
1128=99=25335=X49=SAMPLE75=2017010134=336052=2017010113164939794045460=201701011316493979404545799=10000100268=2279=1269=148=17359555=6SZ683=356786270=10219.0271=19346=71023=7279=1269=148=17359555=6SZ683=356787270=10220.0271=16346=51023=810=037
1128=99=25135=X49=SAMPLE75=2017010134=216552=2017010101334831342328960=201701010133483134232895799=10000100268=2279=1269=148=17359555=6SZ683=356788270=10214.0271=6346=41023=2279=1269=148=17359555=6SZ683=356789270=10215.0271=4346=21023=310=159
1128=99=25135=X49=SAMPLE75=2017010134=294052=2017010106284683251706460=201701010628468325170645799=10000100268=2279=1269=048=17359555=6SZ683=356790270=10212.0271=2346=21023=1279=1269=048=17359555=6SZ683=356791270=10211.0271=3346=21023=210=150
1128=99=18035=X49=SAMPLE75=2017010134=230152=2017010113214870250699760=201701011321487025069975799=10000100268=1279=1269=148=17359555=6SZ683=356792270=10218.0271=6346=41023=610=108
1128=99=17935=X49=SAMPLE75=2017010134=193952=2017010109204726935400760=201701010920472693540075799=10000100268=1279=1269=148=17360055=6SH783=99226270=10277.0271=3346=11023=910=035
1128=99=18035=X49=SAMPLE75=2017010134=327852=2017010105265085851263860=201701010526508585126385799=10000100268=1279=1269=148=17359555=6SZ683=356793270=10220.0271=8346=41023=810=127
1128=99=25235=X49=SAMPLE75=2017010134=460452=2017010108124251394003060=201701010812425139400305799=10000100268=2279=1269=148=17359555=6SZ683=356794270=10219.0271=22346=81023=7279=1269=148=17359555=6SZ683=356795270=10220.0271=5346=31023=810=224
1128=99=25135=X49=SAMPLE75=2017010134=123052=2017010107590927054616860=201701010759092705461685799=10000100268=2279=1269=048=17359555=6SZ683=356796270=10212.0271=1346=11023=1279=1269=048=17359555=6SZ683=356797270=10211.0271=4346=31023=210=141
1128=99=25135=X49=SAMPLE75=2017010134=341152=2017010109180999851473260=201701010918099985147325799=10000100268=2279=1269=148=17359555=6SZ683=356798270=10214.0271=7346=51023=2279=1269=148=17359555=6SZ683=356799270=10215.0271=3346=11023=310=170
1128=99=25235=X49=SAMPLE75=2017010134=253152=2017010111432331056374260=201701011143233105637425799=10000100268=2279=1269=148=17359555=6SZ683=356800270=10219.0271=19346=71023=7279=1269=148=17359555=6SZ683=356801270=10220.0271=8346=41023=810=212
1128=99=25135=X49=SAMPLE75=2017010134=498252=2017010104502044438715260=201701010450204443871525799=10000100268=2279=1269=048=17359555=6SZ683=356802270=10212.0271=2346=21023=1279=1269=048=17359555=6SZ683=356803270=10211.0271=3346=21023=210=113
1128=99=25135=X49=SAMPLE75=2017010134=75852=2017010102124565686155860=201701010212456568615585799=10000100268=2279=1269=148=17359555=6SZ683=356804270=10214.0271=6346=41023=2279=1269=148=17359555=6SZ683=356805270=10215.0271=4346=21023=310=172
1128=99=25235=X49=SAMPLE75=2017010134=391752=2017010108215250576104360=201701010821525057610435799=10000100268=2279=1269=148=17359555=6SZ683=356806270=10219.0271=22346=81023=7279=1269=148=17359555=6SZ683=356807270=10220.0271=5346=31023=810=204
1128=99=25135=X49=SAMPLE75=2017010134=188652=2017010109254430241177360=201701010925443024117735799=10000100268=2279=1269=048=17359555=6SZ683=356808270=10212.0271=1346=11023=1279=1269=048=17359555=6SZ683=356809270=10211.0271=4346=31023=210=151
1128=99=25135=X49=SAMPLE75=2017010134=317552=2017010100384806875864860=201701010038480687586485799=10000100268=2279=1269=148=17359555=6SZ683=356810270=10214.0271=7346=51023=2279=1269=148=17359555=6SZ683=356811270=10215.0271=3346=11023=310=133
1128=99=25235=X49=SAMPLE75=2017010134=461452=2017010108024713430307460=201701010802471343030745799=10000100268=2279=1269=148=17359555=6SZ683=356812270=10219.0271=19346=71023=7279=1269=148=17359555=6SZ683=356813270=10220.0271=8346=41023=810=198
1128=99=25135=X49=SAMPLE75=2017010134=416552=2017010108421484009962160=201701010842148400996215799=10000100268=2279=1269=048=17359555=6SZ683=356814270=10212.0271=2346=21023=1279=1269=048=17359555=6SZ683=356815270=10211.0271=3346=21023=210=117
1128=99=25135=X49=SAMPLE75=2017010134=89652=2017010111502722960955060=201701011150272296095505799=10000100268=2279=1269=148=17359555=6SZ683=356816270=10214.0271=6346=41023=2279=1269=148=17359555=6SZ683=356817270=10215.0271=4346=21023=310=110
1128=99=25235=X49=SAMPLE75=2017010134=453852=2017010105111401614418160=201701010511140161441815799=10000100268=2279=1269=048=17359555=6SZ683=356818270=10209.0271=14346=61023=4279=1269=048=17359555=6SZ683=356819270=10208.0271=8346=51023=510=223
1128=99=25335=X49=SAMPLE75=2017010134=176552=2017010111535511098641860=201701011153551109864185799=10000100268=2279=1269=048=17359555=6SZ683=356820270=10209.0271=11346=51023=4279=1269=048=17359555=6SZ683=356821270=10208.0271=11346=61023=510=222
1128=99=25235=X49=SAMPLE75=2017010134=165252=2017010106361587570071460=201701010636158757007145799=10000100268=2279=1269=148=17359555=6SZ683=356822270=10219.0271=22346=81023=7279=1269=148=17359555=6SZ683=356823270=10220.0271=5346=31023=810=187
1128=99=25135=X49=SAMPLE75=2017010134=102052=2017010112222078490488660=201701011222207849048865799=10000100268=2279=1269=048=17359555=6SZ683=356824270=10212.0271=1346=11023=1279=1269=048=17359555=6SZ683=356825270=10211.0271=4346=31023=210=108
1128=99=25135=X49=SAMPLE75=2017010134=232652=2017010113114618667414360=201701011311461866741435799=10000100268=2279=1269=148=17359555=6SZ683=356826270=10214.0271=7346=51023=2279=1269=148=17359555=6SZ683=356827270=10215.0271=3346=11023=310=160
1128=99=25235=X49=SAMPLE75=2017010134=44952=2017010110321478868932360=201701011032147886893235799=10000100268=2279=1269=148=17359555=6SZ683=356828270=10219.0271=19346=71023=7279=1269=148=17359555=6SZ683=356829270=10220.0271=8346=41023=810=205
1128=99=25135=X49=SAMPLE75=2017010134=351852=2017010105125473814290860=201701010512547381429085799=10000100268=2279=1269=048=17359555=6SZ683=356830270=10212.0271=2346=21023=1279=1269=048=17359555=6SZ683=356831270=10211.0271=3346=21023=210=107
1128=99=25135=X49=SAMPLE75=2017010134=202852=2017010109393073079704060=201701010939307307970405799=10000100268=2279=1269=148=17359555=6SZ683=356832270=10214.0271=6346=41023=2279=1269=148=17359555=6SZ683=356833270=10215.0271=4346=21023=310=122
1128=99=25235=X49=SAMPLE75=2017010134=183952=2017010113585813804750360=201701011358581380475035799=10000100268=2279=1269=048=17359555=6SZ683=356834270=10209.0271=14346=61023=4279=1269=048=17359555=6SZ683=356835270=10208.0271=8346=51023=510=218
1128=99=25335=X49=SAMPLE75=2017010134=448152=2017010110025841171734360=201701011002584117173435799=10000100268=2279=1269=048=17359555=6SZ683=356836270=10209.0271=11346=51023=4279=1269=048=17359555=6SZ683=356837270=10208.0271=11346=61023=510=253
1128=99=25235=X49=SAMPLE75=2017010134=16652=2017010103013702066038260=201701010301370206603825799=10000100268=2279=1269=148=17359555=6SZ683=356838270=10219.0271=22346=81023=7279=1269=148=17359555=6SZ683=356839270=10220.0271=5346=31023=810=253
1128=99=25135=X49=SAMPLE75=2017010134=306352=2017010114260878150749060=201701011426087815074905799=10000100268=2279=1269=048=17359555=6SZ683=356840270=10212.0271=1346=11023=1279=1269=048=17359555=6SZ683=356841270=10211.0271=4346=31023=210=160
1128=99=25135=X49=SAMPLE75=2017010134=6752=2017010114253520865592460=201701011425352086559245799=10000100268=2279=1269=148=17359555=6SZ683=356842270=10214.0271=7346=51023=2279=1269=148=17359555=6SZ683=356843270=10215.0271=3346=11023=310=191
1128=99=25235=X49=SAMPLE75=2017010134=246252=2017010106344416243967860=201701010634441624396785799=10000100268=2279=1269=148=17359555=6SZ683=356844270=10219.0271=19346=71023=7279=1269=148=17359555=6SZ683=356845270=10220.0271=8346=41023=810=238
1128=99=25135=X49=SAMPLE75=2017010134=439652=2017010110053657971407860=201701011005365797140785799=10000100268=2279=1269=148=17359555=6SZ683=356846270=10214.0271=6346=41023=2279=1269=148=17359555=6SZ683=356847270=10215.0271=4346=21023=310=168
1128=99=25135=X49=SAMPLE75=2017010134=478552=2017010103403335301481560=201701010340333530148155799=10000100268=2279=1269=048=17359555=6SZ683=356848270=10212.0271=2346=21023=1279=1269=048=17359555=6SZ683=356849270=10211.0271=3346=21023=210=149
1128=99=18035=X49=SAMPLE75=2017010134=272452=2017010108505334080132560=201701010850533408013255799=10000100268=1279=1269=048=17359555=6SZ683=356850270=10212.0271=3346=31023=110=099
1128=99=24935=X49=SAMPLE75=2017010134=129252=2017010101024379015635960=201701010102437901563595799=10000100268=2279=1269=048=17360055=6SH783=99227270=10262.0271=5346=21023=3279=1269=048=17360055=6SH783=99228270=10261.0271=3346=11023=410=035
1128=99=18035=X49=SAMPLE75=2017010134=428952=2017010105120415463640760=201701010512041546364075799=10000100268=1279=1269=048=17359555=6SZ683=356851270=10212.0271=2346=21023=110=120
1128=99=18035=X49=SAMPLE75=2017010134=373252=2017010106002319973652460=201701010600231997365245799=10000100268=1279=1269=048=17359555=6SZ683=356852270=10208.0271=9346=51023=510=133
1128=99=25235=X49=SAMPLE75=2017010134=480852=2017010102300348377017660=201701010230034837701765799=10000100268=2279=1269=148=17359555=6SZ683=356853270=10219.0271=22346=81023=7279=1269=148=17359555=6SZ683=356854270=10220.0271=5346=31023=810=209
1128=99=25135=X49=SAMPLE75=2017010134=445852=2017010103371281535848760=201701010337128153584875799=10000100268=2279=1269=048=17359555=6SZ683=356855270=10212.0271=1346=11023=1279=1269=048=17359555=6SZ683=356856270=10211.0271=4346=31023=210=129
1128=99=25135=X49=SAMPLE75=2017010134=321652=2017010110332530273085360=201701011033253027308535799=10000100268=2279=1269=148=17359555=6SZ683=356857270=10214.0271=7346=51023=2279=1269=148=17359555=6SZ683=356858270=10215.0271=3346=11023=310=146
1128=99=25235=X49=SAMPLE75=2017010134=1952=2017010113593111666636360=201701011359311166663635799=10000100268=2279=1269=148=17359555=6SZ683=356859270=10219.0271=19346=71023=7279=1269=148=17359555=6SZ683=356860270=10220.0271=8346=41023=810=225
1128=99=25135=X49=SAMPLE75=2017010134=235652=2017010101433277076327560=201701010143327707632755799=10000100268=2279=1269=048=17359555=6SZ683=356861270=10212.0271=2346=21023=1279=1269=048=17359555=6SZ683=356862270=10211.0271=3346=21023=210=135
1128=99=25135=X49=SAMPLE75=2017010134=101952=2017010109253783682987760=201701010925378368298775799=10000100268=2279=1269=148=17359555=6SZ683=356863270=10214.0271=6346=41023=2279=1269=148=17359555=6SZ683=356864270=10215.0271=4346=21023=310=150
1128=99=18135=X49=SAMPLE75=2017010134=70752=2017010111535375063282360=201701011153537506328235799=10000100268=1279=1269=148=17359555=6SZ683=356865270=10216.0271=11346=51023=410=146
1128=99=18035=X49=SAMPLE75=2017010134=376552=2017010108194062896023860=201701010819406289602385799=10000100268=1279=1269=148=17359555=6SZ683=356866270=10216.0271=8346=41023=410=136
1128=99=18035=X49=SAMPLE75=2017010134=384852=2017010112103505331812760=201701011210350533181275799=10000100268=1279=1269=148=17359555=6SZ683=356867270=10216.0271=5346=31023=410=115
1128=99=18035=X49=SAMPLE75=2017010134=443852=2017010102335179592884060=201701010233517959288405799=10000100268=1279=1269=048=17359555=6SZ683=356868270=10209.0271=8346=41023=410=112
1128=99=18035=X49=SAMPLE75=2017010134=435352=2017010107183157244348960=201701010718315724434895799=10000100268=1279=1269=048=17359555=6SZ683=356869270=10209.0271=5346=31023=410=086
1128=99=18135=X49=SAMPLE75=2017010134=160952=2017010100354082085874060=201701010035408208587405799=10000100268=1279=1269=048=17359555=6SZ683=356870270=10207.0271=11346=71023=610=161
1128=99=18135=X49=SAMPLE75=2017010134=195052=2017010108151933698586760=201701010815193369858675799=10000100268=1279=1269=148=17359555=6SZ683=356871270=10219.0271=16346=61023=710=156
1128=99=18135=X49=SAMPLE75=2017010134=397552=2017010108043641577287460=201701010804364157728745799=10000100268=1279=1269=148=17359555=6SZ683=356872270=10219.0271=13346=51023=710=180
1128=99=18135=X49=SAMPLE75=2017010134=195152=2017010101502690094277360=201701010150269009427735799=10000100268=1279=1269=148=17359555=6SZ683=356873270=10219.0271=10346=41023=710=149
1128=99=18035=X49=SAMPLE75=2017010134=164352=2017010104585558555296860=201701010458555855529685799=10000100268=1279=1269=148=17359555=6SZ683=356874270=10219.0271=7346=31023=710=108
1128=99=18035=X49=SAMPLE75=2017010134=381352=2017010101033454687309560=201701010103345468730955799=10000100268=1279=1269=048=17359555=6SZ683=356875270=10207.0271=8346=61023=610=109
1128=99=18035=X49=SAMPLE75=2017010134=201352=2017010104414253192795560=201701010441425319279555799=10000100268=1279=1269=148=17359555=6SZ683=356876270=10219.0271=4346=21023=710=127
1128=99=18135=X49=SAMPLE75=2017010134=73252=2017010108291026625996960=201701010829102662599695799=10000100268=1279=1269=048=17359555=6SZ683=356877270=10205.0271=20346=81023=810=146
1128=99=18135=X49=SAMPLE75=2017010134=307152=2017010107081624931560160=201701010708162493156015799=10000100268=1279=1269=048=17359555=6SZ683=356878270=10205.0271=17346=71023=810=170
1128=99=18135=X49=SAMPLE75=2017010134=314152=2017010101262848273436360=201701010126284827343635799=10000100268=1279=1269=048=17359555=6SZ683=356879270=10205.0271=14346=61023=810=159
1128=99=18135=X49=SAMPLE75=2017010134=141452=2017010110150544307105860=201701011015054430710585799=10000100268=1279=1269=048=17359555=6SZ683=356880270=10205.0271=11346=51023=810=152
1128=99=18035=X49=SAMPLE75=2017010134=363252=2017010103293368905324160=201701010329336890532415799=10000100268=1279=1269=048=17359555=6SZ683=356881270=10205.0271=8346=41023=810=117
1128=99=18035=X49=SAMPLE75=2017010134=404652=2017010101412331214860760=201701010141233121486075799=10000100268=1279=1269=048=17359555=6SZ683=356882270=10205.0271=5346=31023=810=120
1128=99=18035=X49=SAMPLE75=2017010134=228152=2017010112123717902181460=201701011212371790218145799=10000100268=1279=1269=148=17359555=6SZ683=356883270=10221.0271=9346=31023=910=105
1128=99=18035=X49=SAMPLE75=2017010134=406052=2017010101444877992807460=201701010144487799280745799=10000100268=1279=1269=148=17359555=6SZ683=356884270=10221.0271=6346=21023=910=102
1128=99=18035=X49=SAMPLE75=2017010134=146352=2017010105535829404590960=201701010553582940459095799=10000100268=1279=1269=148=17359555=6SZ683=356885270=10221.0271=3346=11023=910=124
1128=99=18035=X49=SAMPLE75=2017010134=264552=2017010110415907380523160=201701011041590738052315799=10000100268=1279=1269=148=17359555=6SZ683=356886270=10218.0271=5346=31023=610=108
1128=99=18035=X49=SAMPLE75=2017010134=441852=2017010109311677404272860=201701010931167740427285799=10000100268=1279=1269=148=17359555=6SZ683=356887270=10218.0271=4346=21023=610=133
1128=99=18035=X49=SAMPLE75=2017010134=458752=2017010101275262029956460=201701010127526202995645799=10000100268=1279=1269=048=17359555=6SZ683=356888270=10204.0271=7346=31023=910=112
1128=99=18035=X49=SAMPLE75=2017010134=268852=2017010107492953428630860=201701010749295342863085799=10000100268=1279=1269=048=17359555=6SZ683=356889270=10212.0271=3346=31023=110=100
1128=99=18035=X49=SAMPLE75=2017010134=157352=2017010112571199879386060=201701011257119987938605799=10000100268=1279=1269=048=17359555=6SZ683=356890270=10205.0271=8346=41023=810=126
1128=99=18135=X49=SAMPLE75=2017010134=391852=2017010111480809225069060=201701011148080922506905799=10000100268=1279=1269=048=17359555=6SZ683=356891270=10205.0271=11346=51023=810=174
1128=99=18035=X49=SAMPLE75=2017010134=62052=2017010112571685370463260=201701011257168537046325799=10000100268=1279=1269=048=17359555=6SZ683=356892270=10204.0271=4346=21023=910=093
1128=99=25135=X49=SAMPLE75=2017010134=93652=2017010113143428070752160=201701011314342807075215799=10000100268=2279=1269=048=17359555=6SZ683=356893270=10209.0271=8346=41023=4279=1269=048=17359555=6SZ683=356894270=10208.0271=6346=41023=510=184
1128=99=25135=X49=SAMPLE75=2017010134=123752=2017010112030934898376360=201701011203093489837635799=10000100268=2279=1269=048=17359555=6SZ683=356895270=10209.0271=5346=31023=4279=1269=048=17359555=6SZ683=356896270=10208.0271=9346=51023=510=164
1128=99=25135=X49=SAMPLE75=2017010134=40952=2017010109430228070535160=201701010943022807053515799=10000100268=2279=1269=048=17359555=6SZ683=356897270=10209.0271=8346=41023=4279=1269=048=17359555=6SZ683=356898270=10208.0271=6346=41023=510=194
1128=99=25135=X49=SAMPLE75=2017010134=456252=2017010107265986939807560=201701010726598693980755799=10000100268=2279=1269=048=17359555=6SZ683=356899270=10209.0271=5346=31023=4279=1269=048=17359555=6SZ683=356900270=10208.0271=9346=51023=510=149
1128=99=25135=X49=SAMPLE75=2017010134=332552=2017010106152254464270660=201701010615225446427065799=10000100268=2279=1269=048=17359555=6SZ683=356901270=10209.0271=8346=41023=4279=1269=048=17359555=6SZ683=356902270=10208.0271=6346=41023=510=153
1128=99=18035=X49=SAMPLE75=2017010134=162752=2017010100321188088728660=201701010032118808872865799=10000100268=1279=1269=148=17359555=6SZ683=356903270=10219.0271=7346=31023=710=111
1128=99=18135=X49=SAMPLE75=2017010134=482152=2017010101243525982157560=201701010124352598215755799=10000100268=1279=1269=148=17359555=6SZ683=356904270=10219.0271=10346=41023=710=118
1128=99=18035=X49=SAMPLE75=2017010134=255252=2017010100454950579336060=201701010045495057933605799=10000100268=1279=1269=148=17359555=6SZ683=356905270=10217.0271=4346=21023=510=127
1128=99=18135=X49=SAMPLE75=2017010134=102752=2017010109504848698801560=201701010950484869880155799=10000100268=1279=1269=148=17359555=6SZ683=356906270=10222.0271=3346=11023=1010=154
1128=99=18035=X49=SAMPLE75=2017010134=202052=2017010112002061410573160=201701011200206141057315799=10000100268=1279=1269=048=17359555=6SZ683=356907270=10207.0271=7346=51023=610=101
1128=99=25135=X49=SAMPLE75=2017010134=68252=2017010103011922137340360=201701010301192213734035799=10000100268=2279=1269=048=17359555=6SZ683=356908270=10209.0271=5346=31023=4279=1269=048=17359555=6SZ683=356909270=10208.0271=9346=51023=510=146
1128=99=25135=X49=SAMPLE75=2017010134=27152=2017010113560171375555860=201701011356017137555585799=10000100268=2279=1269=048=17359555=6SZ683=356910270=10209.0271=8346=41023=4279=1269=048=17359555=6SZ683=356911270=10208.0271=6346=41023=510=147
1128=99=18035=X49=SAMPLE75=2017010134=27452=2017010109074145331862160=201701010907414533186215799=10000100268=1279=1269=048=17359555=6SZ683=356912270=10212.0271=2346=21023=110=070
1128=99=18035=X49=SAMPLE75=2017010134=203052=2017010105154221516859660=201701010515422151685965799=10000100268=1279=1269=148=17359555=6SZ683=356913270=10220.0271=7346=31023=810=099
1128=99=18035=X49=SAMPLE75=2017010134=123052=2017010104261940119330360=201701010426194011933035799=10000100268=1279=1269=148=17359555=6SZ683=356914270=10215.0271=5346=31023=310=088
1128=99=25135=X49=SAMPLE75=2017010134=309452=2017010100303035332229760=201701010030303533222975799=10000100268=2279=1269=048=17359555=6SZ683=356915270=10209.0271=5346=31023=4279=1269=048=17359555=6SZ683=356916270=10208.0271=9346=51023=510=155
1128=99=25135=X49=SAMPLE75=2017010134=377252=2017010114091803003885660=201701011409180300388565799=10000100268=2279=1269=048=17359555=6SZ683=356917270=10209.0271=8346=41023=4279=1269=048=17359555=6SZ683=356918270=10208.0271=6346=41023=510=151
1128=99=25135=X49=SAMPLE75=2017010134=315252=2017010113352126216841960=201701011335212621684195799=10000100268=2279=1269=048=17359555=6SZ683=356919270=10209.0271=5346=31023=4279=1269=048=17359555=6SZ683=356920270=10208.0271=9346=51023=510=175
1128=99=25135=X49=SAMPLE75=2017010134=19552=2017010104471278627672760=201701010447127862767275799=10000100268=2279=1269=048=17359555=6SZ683=356921270=10209.0271=8346=41023=4279=1269=048=17359555=6SZ683=356922270=10208.0271=6346=41023=510=131
1128=99=25135=X49=SAMPLE75=2017010134=486152=2017010104401161650163860=201701010440116165016385799=10000100268=2279=1269=048=17359555=6SZ683=356923270=10209.0271=5346=31023=4279=1269=048=17359555=6SZ683=356924270=10208.0271=9346=51023=510=165
1128=99=25135=X49=SAMPLE75=2017010134=390752=2017010112123357999670460=201701011212335799967045799=10000100268=2279=1269=048=17359555=6SZ683=356925270=10209.0271=8346=41023=4279=1269=048=17359555=6SZ683=356926270=10208.0271=6346=41023=510=171
