1128=99=12735=f49=SAMPLE34=295652=2008112318224700144080060=2008112318224700144080075=201610095799=000000001151=6S326=18327=11174=010=138
1128=99=51135=d49=SAMPLE75=2016100934=128152=200301240454500303974405799=00000000980=A779=201610091605332737526211180=3141300=6255=6SH048=2492922=8200=2020031151=6S6937=6S167=FUT461=FFCXSX9779=N462=4207=XCME15=USD1142=F562=11140=9999969=1.01146=0.09787=1.0E-41141=11022=GBX264=10864=2865=51145=20150316-21:49:00.000000000865=71145=20200316-14:16:00.000000000870=1871=24872=00000000000001000010000000001111996=CHF1147=1250001149=11501.01148=10701.01143=60.01150=11101.0731=0000001110=24060=20030124045450030397440
1128=99=51035=d49=SAMPLE75=2016100934=468152=201307041650442603993605799=00000000980=A779=201610091605332737526211180=3141300=6255=6SH148=264022=8200=2021031151=6S6937=6S167=FUT461=FFCXSX9779=N462=4207=XCME15=USD1142=F562=11140=9999969=1.01146=0.09787=1.0E-41141=11022=GBX264=10864=2865=51145=20160314-21:49:00.000000000865=71145=20210315-14:16:00.000000000870=1871=24872=00000000000001000010000000001111996=CHF1147=1250001149=11799.01148=10999.01143=60.01150=11399.0731=0000001110=21460=20130704165044260399360
1128=99=51135=d49=SAMPLE75=2016100934=291752=200806261219133666309765799=00000000980=A779=201610091605332737526211180=3141300=6255=6SH748=17360022=8200=2017031151=6S6937=6S167=FUT461=FFCXSX9779=N462=4207=XCME15=USD1142=F562=11140=9999969=1.01146=0.09787=1.0E-41141=11022=GBX264=10864=2865=51145=20130809-21:49:00.000000000865=71145=20170313-14:16:00.000000000870=1871=24872=00000000000001000010000000001111996=CHF1147=1250001149=10707.01148=9907.01143=60.01150=10307.0731=0000001110=25260=20080626121913366630976
1128=99=51235=d49=SAMPLE75=2016100934=198352=200106110509447847383205799=00000000980=A779=201610091605332737526211180=3141300=6255=6SH848=17364022=8200=2018031151=6S6937=6S167=FUT461=FFCXSX9779=N462=4207=XCME15=USD1142=F562=11140=9999969=1.01146=0.09787=1.0E-41141=11022=GBX264=10864=2865=51145=20130809-21:49:00.000000000865=71145=20180319-14:16:00.000000000870=1871=24872=00000000000001000010000000001111996=CHF1147=1250001149=10953.01148=10153.01143=60.01150=10553.0731=0000001110=05660=20010611050944784738320
1128=99=50935=d49=SAMPLE75=2016100934=479052=200606181835105457036805799=00000000980=A779=201610091605332737526211180=3141300=6255=6SH948=78722=8200=2019031151=6S6937=6S167=FUT461=FFCXSX9779=N462=4207=XCME15=USD1142=F562=11140=9999969=1.01146=0.09787=1.0E-41141=11022=GBX264=10864=2865=51145=20140317-21:49:00.000000000865=71145=20190318-14:16:00.000000000870=1871=24872=00000000000001000010000000001111996=CHF1147=1250001149=11217.01148=10417.01143=60.01150=10817.0731=0000001110=17660=20060618183510545703680
1128=99=51135=d49=SAMPLE75=2016100934=188952=200902091508532592956485799=00000000980=A779=201610091605332737526211180=3141300=6255=6SM048=8738422=8200=2020061151=6S6937=6S167=FUT461=FFCXSX9779=N462=4207=XCME15=USD1142=F562=11140=9999969=1.01146=0.09787=1.0E-41141=11022=GBX264=10864=2865=51145=20150615-21:49:00.000000000865=71145=20200615-14:16:00.000000000870=1871=24872=00000000000001000010000000001111996=CHF1147=1250001149=11574.01148=10774.01143=60.01150=11174.0731=0000001110=02060=20090209150853259295648
1128=99=51135=d49=SAMPLE75=2016100934=192252=200312201152593188220325799=00000000980=A779=201610091605332737526211180=3141300=6255=6SM148=7610222=8200=2021061151=6S6937=6S167=FUT461=FFCXSX9779=N462=4207=XCME15=USD1142=F562=11140=9999969=1.01146=0.09787=1.0E-41141=11022=GBX264=10864=2865=51145=20160613-21:49:00.000000000865=71145=20210614-14:16:00.000000000870=1871=24872=00000000000001000010000000001111996=CHF1147=1250001149=11876.01148=11076.01143=60.01150=11476.0731=0000001110=25560=20031220115259318822032
1128=99=51135=d49=SAMPLE75=2016100934=416052=200707221152564666033285799=00000000980=A779=201610091605332737526211180=3141300=6255=6SM748=17360322=8200=2017061151=6S6937=6S167=FUT461=FFCXSX9779=N462=4207=XCME15=USD1142=F562=11140=9999969=1.01146=0.09787=1.0E-41141=11022=GBX264=10864=2865=51145=20130809-21:49:00.000000000865=71145=20170619-14:16:00.000000000870=1871=24872=00000000000001000010000000001111996=CHF1147=1250001149=10769.01148=9969.01143=60.01150=10369.0731=0000001110=04660=20070722115256466603328
1128=99=51235=d49=SAMPLE75=2016100934=126252=201003082205211304819845799=00000000980=A779=201610091605332737526211180=3141300=6255=6SM848=17364122=8200=2018061151=6S6937=6S167=FUT461=FFCXSX9779=N462=4207=XCME15=USD1142=F562=11140=9999969=1.01146=0.09787=1.0E-41141=11022=GBX264=10864=2865=51145=20130809-21:49:00.000000000865=71145=20180618-14:16:00.000000000870=1871=24872=00000000000001000010000000001111996=CHF1147=1250001149=11017.01148=10217.01143=60.01150=10617.0731=0000001110=05460=20100308220521130481984
1128=99=13135=f49=SAMPLE34=289852=2006091102280579681174460=2006091102280579681174475=201610115799=000000001151=6S326=21327=01174=410=046
1128=99=18035=X49=SAMPLE75=2016101134=234452=2001052512590258264812860=200105251259025826481285799=10000100268=1279=0269=148=17359555=6SZ683=354045270=10270.0271=3346=11023=310=086
1128=99=18035=X49=SAMPLE75=2016101134=246252=2004021212232018613588860=200402121223201861358885799=10000100268=1279=0269=148=17359555=6SZ683=354046270=10276.0271=3346=11023=410=108
1128=99=18035=X49=SAMPLE75=2016101134=498652=2002091200181776014857660=200209120018177601485765799=10000100268=1279=0269=048=17359555=6SZ683=354047270=10196.0271=4346=11023=110=103
1128=99=18035=X49=SAMPLE75=2016101134=420452=2016033019301025648160060=201603301930102564816005799=10000100268=1279=0269=048=17359555=6SZ683=354048270=10176.0271=2346=11023=210=101
1128=99=18035=X49=SAMPLE75=2016101134=54852=2010070605053654073152060=201007060505365407315205799=10000100268=1279=0269=048=17359555=6SZ683=354049270=10134.0271=2346=11023=810=091
1128=99=18035=X49=SAMPLE75=2016101134=401252=2007011221383762736304060=200701122138376273630405799=10000100268=1279=0269=048=17359555=6SZ683=354050270=10144.0271=2346=11023=710=077
1128=99=18035=X49=SAMPLE75=2016101134=475652=2000032811423417993797860=200003281142341799379785799=10000100268=1279=1269=148=17359555=6SZ683=354051270=10310.0271=4346=21023=810=077
1128=99=18035=X49=SAMPLE75=2016101134=115052=2001072307594472191820860=200107230759447219182085799=10000100268=1279=0269=148=17359555=6SZ683=354052270=10306.0271=2346=11023=710=080
1128=99=18035=X49=SAMPLE75=2016101134=492552=2016011807344176044608060=201601180734417604460805799=10000100268=1279=1269=148=17359555=6SZ683=354053270=10310.0271=6346=31023=910=094
1128=99=18035=X49=SAMPLE75=2016101134=319252=2000122712412027022873660=200012271241202702287365799=10000100268=1279=0269=048=17359555=6SZ683=354054270=10146.0271=4346=11023=710=120
1128=99=18035=X49=SAMPLE75=2016101134=173452=2003122220022310237308860=200312222002231023730885799=10000100268=1279=0269=048=17359555=6SZ683=354055270=10188.0271=1346=11023=210=079
1128=99=18035=X49=SAMPLE75=2016101134=150552=2012071008104431505971260=201207100810443150597125799=10000100268=1279=0269=148=17359555=6SZ683=354056270=10279.0271=2346=11023=510=070
1128=99=18035=X49=SAMPLE75=2016101134=304352=2011110520483466183328060=201111052048346618332805799=10000100268=1279=1269=148=17359555=6SZ683=354057270=10279.0271=3346=21023=510=120
1128=99=18035=X49=SAMPLE75=2016101134=141652=2000081813035964268146060=200008181303596426814605799=10000100268=1279=0269=148=17359555=6SZ683=354058270=10254.0271=1346=11023=110=097
1128=99=18035=X49=SAMPLE75=2016101134=56452=2011090617440315784710460=201109061744031578471045799=10000100268=1279=0269=148=17359555=6SZ683=354059270=10281.0271=2346=11023=710=078
1128=99=18035=X49=SAMPLE75=2016101134=433652=2006082712253847073097660=200608271225384707309765799=10000100268=1279=0269=148=17359555=6SZ683=354060270=10255.0271=2346=11023=210=074
1128=99=18035=X49=SAMPLE75=2016101134=454952=2006121803144823717916860=200612180314482371791685799=10000100268=1279=1269=148=17359555=6SZ683=354061270=10279.0271=4346=31023=710=068
1128=99=96435=X49=SAMPLE75=2016101134=24552=2011012209551574822297660=201101220955157482229765799=00000100268=12279=2269=048=17359555=6SZ683=354062270=10196.0271=4346=11023=1279=2269=048=17359555=6SZ683=354063270=10188.0271=1346=11023=1279=2269=048=17359555=6SZ683=354064270=10176.0271=2346=11023=1279=2269=048=17359555=6SZ683=354065270=10161.0271=1346=11023=1279=2269=048=17359555=6SZ683=354066270=10156.0271=4346=11023=1279=0269=048=17359555=6SZ683=354067270=10154.0271=12346=51023=1279=0269=048=17359555=6SZ683=354068270=10142.0271=1346=11023=7279=0269=048=17359555=6SZ683=354069270=10134.0271=2346=11023=8279=0269=048=17359555=6SZ683=354070270=10125.0271=1346=11023=9279=0269=048=17359555=6SZ683=354071270=10118.0271=1346=11023=10279=0269=148=17359555=6SZ683=354072270=10154.0271=6346=11023=1279=0269=148=17359555=6SZ683=354073270=10180.0271=2346=11023=210=166
1128=99=16735=X49=SAMPLE75=2016101134=277052=2015071613284682865536060=201507161328468286553605799=10001000268=1279=0269=448=17359555=6SZ683=354074270=10154.0286=510=046
1128=99=89435=X49=SAMPLE75=2016101134=399452=2006082901363048426764860=200608290136304842676485799=10000100268=11279=0269=048=17359555=6SZ683=354075270=10196.0271=4346=11023=1279=0269=048=17359555=6SZ683=354076270=10188.0271=1346=11023=2279=0269=048=17359555=6SZ683=354077270=10176.0271=2346=11023=3279=0269=048=17359555=6SZ683=354078270=10161.0271=1346=11023=4279=0269=048=17359555=6SZ683=354079270=10156.0271=4346=11023=5279=2269=048=17359555=6SZ683=354080270=10154.0271=12346=51023=6279=0269=048=17359555=6SZ683=354081270=10143.0271=2346=11023=10279=2269=148=17359555=6SZ683=354082270=10154.0271=6346=11023=1279=2269=148=17359555=6SZ683=354083270=10180.0271=2346=11023=1279=0269=148=17359555=6SZ683=354084270=10300.0271=1346=11023=9279=0269=148=17359555=6SZ683=354085270=10305.0271=2346=11023=1010=205
1128=99=18035=X49=SAMPLE75=2016101134=458552=2000060301252083666643660=200006030125208366664365799=10000100268=1279=1269=048=17359555=6SZ683=354086270=10196.0271=7346=21023=110=105
1128=99=18135=X49=SAMPLE75=2016101134=303752=2006101220302208859673660=200610122030220885967365799=10000100268=1279=1269=048=17359555=6SZ683=354087270=10196.0271=10346=31023=110=185
1128=99=18135=X49=SAMPLE75=2016101134=231852=2005010100323484900380860=200501010032348490038085799=10000100268=1279=1269=048=17359555=6SZ683=354088270=10196.0271=13346=41023=110=140
1128=99=18135=X49=SAMPLE75=2016101134=123052=2005111309211658212854460=200511130921165821285445799=10000100268=1279=1269=048=17359555=6SZ683=354089270=10196.0271=16346=51023=110=165
1128=99=18135=X49=SAMPLE75=2016101134=249852=2001012210514938275942860=200101221051493827594285799=10000100268=1279=1269=048=17359555=6SZ683=354090270=10196.0271=19346=61023=110=158
1128=99=18135=X49=SAMPLE75=2016101134=62752=2015091820134795775923260=201509182013479577592325799=10000100268=1279=1269=048=17359555=6SZ683=354091270=10196.0271=22346=71023=110=174
1128=99=18135=X49=SAMPLE75=2016101134=394852=2008051019483431489017660=200805101948343148901765799=10000100268=1279=1269=048=17359555=6SZ683=354092270=10196.0271=25346=81023=110=171
1128=99=18135=X49=SAMPLE75=2016101134=268552=2005111108013723284928060=200511110801372328492805799=10000100268=1279=1269=048=17359555=6SZ683=354093270=10196.0271=28346=91023=110=146
1128=99=18035=X49=SAMPLE75=2016101134=72552=2009061706590831079398460=200906170659083107939845799=10000100268=1279=0269=148=17359555=6SZ683=354094270=10229.0271=3346=11023=110=098
1128=99=18035=X49=SAMPLE75=2016101134=66352=2009083000380615221856060=200908300038061522185605799=10000100268=1279=1269=148=17359555=6SZ683=354095270=10229.0271=6346=21023=110=100
1128=99=18035=X49=SAMPLE75=2016101134=128652=2013052018141213433580860=201305201814121343358085799=10000100268=1279=1269=148=17359555=6SZ683=354096270=10229.0271=9346=31023=110=119
1128=99=18135=X49=SAMPLE75=2016101134=183152=2011100104432888056883260=201110010443288805688325799=10000100268=1279=1269=148=17359555=6SZ683=354097270=10229.0271=12346=41023=110=156
1128=99=18135=X49=SAMPLE75=2016101134=46852=2009031621325244884812860=200903162132524488481285799=10000100268=1279=1269=148=17359555=6SZ683=354098270=10229.0271=15346=51023=110=172
1128=99=18135=X49=SAMPLE75=2016101134=493452=2000022016053806797854660=200002201605380679785465799=10000100268=1279=1269=148=17359555=6SZ683=354099270=10229.0271=18346=61023=110=183
1128=99=18135=X49=SAMPLE75=2016101134=429752=2001101810404394797214460=200110181040439479721445799=10000100268=1279=1269=148=17359555=6SZ683=354100270=10229.0271=21346=71023=110=146
1128=99=18135=X49=SAMPLE75=2016101134=353052=2008051308081025996387260=200805130808102599638725799=10000100268=1279=1269=148=17359555=6SZ683=354101270=10229.0271=24346=81023=110=159
1128=99=18135=X49=SAMPLE75=2016101134=233052=2007042118441350019328060=200704211844135001932805799=10000100268=1279=1269=148=17359555=6SZ683=354102270=10229.0271=27346=91023=110=166
1128=99=18235=X49=SAMPLE75=2016101134=17852=2007091018395350189059260=200709101839535018905925799=10000100268=1279=1269=148=17359555=6SZ683=354103270=10229.0271=30346=101023=110=193
1128=99=18035=X49=SAMPLE75=2016101134=7552=2000011819232268136011660=200001181923226813601165799=10000100268=1279=0269=048=17359555=6SZ683=354104270=10197.0271=1346=11023=110=104
1128=99=18035=X49=SAMPLE75=2016101134=94252=2013031610104310743475260=201303161010431074347525799=10000100268=1279=1269=048=17359555=6SZ683=354105270=10197.0271=4346=21023=110=101
1128=99=18035=X49=SAMPLE75=2016101134=321452=2007070207112090570192060=200707020711209057019205799=10000100268=1279=1269=048=17359555=6SZ683=354106270=10197.0271=7346=31023=110=093
1128=99=18135=X49=SAMPLE75=2016101134=487352=2007041419091240171673660=200704141909124017167365799=10000100268=1279=1269=048=17359555=6SZ683=354107270=10197.0271=10346=41023=110=152
1128=99=18135=X49=SAMPLE75=2016101134=340252=2003052410061084304796860=200305241006108430479685799=10000100268=1279=1269=048=17359555=6SZ683=354108270=10197.0271=13346=51023=110=168
1128=99=18135=X49=SAMPLE75=2016101134=203952=2009070102042971097216060=200907010204297109721605799=10000100268=1279=0269=148=17359555=6SZ683=354109270=10277.0271=12346=11023=810=170
1128=99=18035=X49=SAMPLE75=2016101134=290652=2016022512091364806227260=201602251209136480622725799=10000100268=1279=0269=148=17359555=6SZ683=354110270=10216.0271=1346=11023=110=110
1128=99=18135=X49=SAMPLE75=2016101134=98552=2007080609043982400956860=200708060904398240095685799=10000100268=1279=0269=148=17359555=6SZ683=354111270=10250.0271=10346=11023=310=117
1128=99=18035=X49=SAMPLE75=2016101134=461952=2012101514260083365881660=201210151426008336588165799=10000100268=1279=0269=048=17359555=6SZ683=354112270=10157.0271=3346=11023=610=090
1128=99=18035=X49=SAMPLE75=2016101134=27552=2000041004191097136390660=200004100419109713639065799=10000100268=1279=0269=148=17359555=6SZ683=354113270=10228.0271=3346=11023=210=094
1128=99=18135=X49=SAMPLE75=2016101134=103552=2000060902173646587058460=200006090217364658705845799=10000100268=1279=0269=048=17359555=6SZ683=354114270=10155.0271=10346=11023=810=143
1128=99=18035=X49=SAMPLE75=2016101134=406052=2000082916291420468831660=200008291629142046883165799=10000100268=1279=1269=148=17359555=6SZ683=354115270=10228.0271=6346=21023=210=123
1128=99=18035=X49=SAMPLE75=2016101134=326452=2003070408580972441932860=200307040858097244193285799=10000100268=1279=0269=148=17359555=6SZ683=354116270=10227.0271=3346=11023=210=124
1128=99=18035=X49=SAMPLE75=2016101134=468252=2001031201165078774556060=200103120116507877455605799=10000100268=1279=1269=148=17359555=6SZ683=354117270=10228.0271=9346=31023=310=129
1128=99=18135=X49=SAMPLE75=2016101134=356252=2004010901562174115662460=200401090156217411566245799=10000100268=1279=1269=148=17359555=6SZ683=354118270=10228.0271=12346=41023=310=148
1128=99=18135=X49=SAMPLE75=2016101134=424652=2002052423494171756246460=200205242349417175624645799=10000100268=1279=1269=148=17359555=6SZ683=354119270=10228.0271=15346=51023=310=181
1128=99=18135=X49=SAMPLE75=2016101134=102852=2010120907152868847769660=201012090715286884776965799=10000100268=1279=1269=148=17359555=6SZ683=354120270=10228.0271=18346=61023=310=167
1128=99=18035=X49=SAMPLE75=2016101134=89052=2001060100501159425536060=200106010050115942553605799=10000100268=1279=1269=148=17359555=6SZ683=354121270=10227.0271=6346=21023=210=095
1128=99=25235=X49=SAMPLE75=2016101134=458052=2008070613333238532812860=200807061333323853281285799=10000100268=2279=0269=148=17359555=6SZ683=354122270=10226.0271=3346=11023=2279=1269=148=17359555=6SZ683=354123270=10228.0271=15346=51023=410=198
1128=99=18035=X49=SAMPLE75=2016101134=158852=2011011414575400567180860=201101141457540056718085799=10000100268=1279=1269=148=17359555=6SZ683=354124270=10227.0271=9346=31023=310=112
1128=99=18135=X49=SAMPLE75=2016101134=375252=2005041802420022411177660=200504180242002241117765799=10000100268=1279=1269=148=17359555=6SZ683=354125270=10227.0271=12346=41023=310=166
1128=99=18135=X49=SAMPLE75=2016101134=245652=2016070218330837786451260=201607021833083778645125799=10000100268=1279=1269=148=17359555=6SZ683=354126270=10227.0271=15346=51023=310=159
1128=99=18135=X49=SAMPLE75=2016101134=402652=2010112211264422881926460=201011221126442288192645799=10000100268=1279=1269=148=17359555=6SZ683=354127270=10227.0271=18346=61023=310=173
1128=99=18035=X49=SAMPLE75=2016101134=209252=2006051121350675394627260=200605112135067539462725799=10000100268=1279=1269=148=17359555=6SZ683=354128270=10226.0271=6346=21023=210=123
1128=99=25235=X49=SAMPLE75=2016101134=370052=2015112112575585015814460=201511211257558501581445799=10000100268=2279=0269=148=17359555=6SZ683=354129270=10225.0271=3346=11023=2279=1269=148=17359555=6SZ683=354130270=10227.0271=15346=51023=410=205
1128=99=18035=X49=SAMPLE75=2016101134=289852=2012062202022026673062460=201206220202202667306245799=10000100268=1279=1269=148=17359555=6SZ683=354131270=10226.0271=9346=31023=310=108
1128=99=18135=X49=SAMPLE75=2016101134=166652=2009122020415597974233660=200912202041559797423365799=10000100268=1279=1269=148=17359555=6SZ683=354132270=10226.0271=12346=41023=310=168
1128=99=18135=X49=SAMPLE75=2016101134=34952=2003061805133395944025660=200306180513339594402565799=10000100268=1279=1269=148=17359555=6SZ683=354133270=10226.0271=15346=51023=310=164
1128=99=18135=X49=SAMPLE75=2016101134=223452=2010042200224983881395260=201004220022498388139525799=10000100268=1279=1269=148=17359555=6SZ683=354134270=10226.0271=18346=61023=310=151
1128=99=18135=X49=SAMPLE75=2016101134=256752=2015070115055922623699260=201507011505592262369925799=10000100268=1279=1269=148=17359555=6SZ683=354135270=10229.0271=27346=91023=610=180
1128=99=18135=X49=SAMPLE75=2016101134=478952=2014020622535091891481660=201402062253509189148165799=10000100268=1279=1269=148=17359555=6SZ683=354136270=10229.0271=24346=81023=610=164
1128=99=18135=X49=SAMPLE75=2016101134=297652=2000080711225801988507260=200008071122580198850725799=10000100268=1279=1269=148=17359555=6SZ683=354137270=10229.0271=21346=71023=610=167
1128=99=18135=X49=SAMPLE75=2016101134=417752=2011112713430335385600060=201111271343033538560005799=10000100268=1279=1269=148=17359555=6SZ683=354138270=10229.0271=18346=61023=610=189
1128=99=18135=X49=SAMPLE75=2016101134=235952=2005110906282673008224060=200511090628267300822405799=10000100268=1279=1269=148=17359555=6SZ683=354139270=10229.0271=15346=51023=610=174
1128=99=18135=X49=SAMPLE75=2016101134=198152=2016040910100042084844860=201604091010004208484485799=10000100268=1279=1269=148=17359555=6SZ683=354140270=10229.0271=12346=41023=610=176
1128=99=18035=X49=SAMPLE75=2016101134=361252=2005051106522131679638460=200505110652213167963845799=10000100268=1279=1269=148=17359555=6SZ683=354141270=10229.0271=9346=31023=610=120
1128=99=18035=X49=SAMPLE75=2016101134=39652=2002032222410564593481660=200203222241056459348165799=10000100268=1279=1269=148=17359555=6SZ683=354142270=10229.0271=6346=21023=610=112
1128=99=18035=X49=SAMPLE75=2016101134=67052=2015031713375284669196860=201503171337528466919685799=10000100268=1279=1269=148=17359555=6SZ683=354143270=10229.0271=3346=11023=610=128
1128=99=25235=X49=SAMPLE75=2016101134=1452=2011072403280648046771260=201107240328064804677125799=10000100268=2279=2269=148=17359555=6SZ683=354144270=10229.0271=3346=11023=6279=0269=148=17359555=6SZ683=354145270=10265.0271=1346=11023=1010=224
1128=99=18135=X49=SAMPLE75=2016101134=337152=2014071004062192682720060=201407100406219268272005799=10000100268=1279=1269=148=17359555=6SZ683=354146270=10227.0271=12346=41023=410=163
1128=99=18035=X49=SAMPLE75=2016101134=84452=2001050212364515980147260=200105021236451598014725799=10000100268=1279=1269=148=17359555=6SZ683=354147270=10227.0271=9346=31023=410=099
1128=99=18035=X49=SAMPLE75=2016101134=455552=2016101715450242687315260=201610171545024268731525799=10000100268=1279=1269=148=17359555=6SZ683=354148270=10227.0271=6346=21023=410=107
1128=99=18035=X49=SAMPLE75=2016101134=497552=2012042815301129656736060=201204281530112965673605799=10000100268=1279=1269=148=17359555=6SZ683=354149270=10227.0271=3346=11023=410=137
1128=99=25235=X49=SAMPLE75=2016101134=461452=2015010510091113452582460=201501051009111345258245799=10000100268=2279=2269=148=17359555=6SZ683=354150270=10227.0271=3346=11023=4279=0269=148=17359555=6SZ683=354151270=10270.0271=3346=11023=1010=185
1128=99=18135=X49=SAMPLE75=2016101134=326352=2006052318014641547897660=200605231801464154789765799=10000100268=1279=1269=148=17359555=6SZ683=354152270=10226.0271=15346=51023=310=186
1128=99=18135=X49=SAMPLE75=2016101134=313452=2010022305140122980262460=201002230514012298026245799=10000100268=1279=1269=148=17359555=6SZ683=354153270=10226.0271=12346=41023=310=171
1128=99=18035=X49=SAMPLE75=2016101134=236052=2010080610413223672934460=201008061041322367293445799=10000100268=1279=1269=148=17359555=6SZ683=354154270=10226.0271=9346=31023=310=134
1128=99=18035=X49=SAMPLE75=2016101134=159952=2006032200162761774160060=200603220016276177416005799=10000100268=1279=1269=148=17359555=6SZ683=354155270=10226.0271=6346=21023=310=118
1128=99=18035=X49=SAMPLE75=2016101134=184352=2003072006200298390936060=200307200620029839093605799=10000100268=1279=1269=148=17359555=6SZ683=354156270=10226.0271=3346=11023=310=120
1128=99=18135=X49=SAMPLE75=2016101134=176552=2008123009141570795820860=200812300914157079582085799=10000100268=1279=1269=148=17359555=6SZ683=354157270=10228.0271=12346=41023=410=171
1128=99=18035=X49=SAMPLE75=2016101134=484052=2007021818305438047587260=200702181830543804758725799=10000100268=1279=1269=148=17359555=6SZ683=354158270=10228.0271=9346=31023=410=139
1128=99=18035=X49=SAMPLE75=2016101134=34052=2005111605191577547552060=200511160519157754755205799=10000100268=1279=1269=148=17359555=6SZ683=354159270=10228.0271=6346=21023=410=131
1128=99=18035=X49=SAMPLE75=2016101134=463952=2002010423322588214432060=200201042332258821443205799=10000100268=1279=1269=148=17359555=6SZ683=354160270=10228.0271=3346=11023=410=126
1128=99=25135=X49=SAMPLE75=2016101134=281652=2010062508291091302272060=201006250829109130227205799=10000100268=2279=2269=148=17359555=6SZ683=354161270=10225.0271=3346=11023=2279=0269=148=17359555=6SZ683=354162270=10249.0271=1346=11023=410=166
1128=99=25235=X49=SAMPLE75=2016101134=186552=2007032105455438998339260=200703210545543899833925799=10000100268=2279=2269=148=17359555=6SZ683=354163270=10228.0271=3346=11023=3279=0269=148=17359555=6SZ683=354164270=10276.0271=3346=11023=1010=221
1128=99=25335=X49=SAMPLE75=2016101134=20052=2001021503020201485410060=200102150302020148541005799=10000100268=2279=2269=148=17359555=6SZ683=354165270=10226.0271=3346=11023=2279=0269=148=17359555=6SZ683=354166270=10277.0271=12346=11023=1010=023
1128=99=18035=X49=SAMPLE75=2016101134=249652=2003100214452981049251260=200310021445298104925125799=10000100268=1279=0269=148=17359555=6SZ683=354167270=10227.0271=3346=11023=210=119
1128=99=18035=X49=SAMPLE75=2016101134=170152=2007031002502421476841660=200703100250242147684165799=10000100268=1279=1269=148=17359555=6SZ683=354168270=10227.0271=6346=21023=210=128
1128=99=18035=X49=SAMPLE75=2016101134=176152=2015012811311022685529660=201501281131102268552965799=10000100268=1279=0269=148=17359555=6SZ683=354169270=10226.0271=3346=11023=210=127
1128=99=18035=X49=SAMPLE75=2016101134=19152=2010051719381301784659260=201005171938130178465925799=10000100268=1279=1269=148=17359555=6SZ683=354170270=10227.0271=9346=31023=310=128
1128=99=18035=X49=SAMPLE75=2016101134=321452=2004042011102351727712060=200404201110235172771205799=10000100268=1279=1269=148=17359555=6SZ683=354171270=10227.0271=6346=21023=310=108
1128=99=18035=X49=SAMPLE75=2016101134=234152=2005062517035491825478460=200506251703549182547845799=10000100268=1279=1269=148=17359555=6SZ683=354172270=10227.0271=3346=11023=310=061
1128=99=25235=X49=SAMPLE75=2016101134=48352=2016020300314052850803260=201602030031405285080325799=10000100268=2279=2269=148=17359555=6SZ683=354173270=10227.0271=3346=11023=3279=0269=148=17359555=6SZ683=354174270=10276.0271=3346=11023=1010=204
1128=99=25335=X49=SAMPLE75=2016101134=282852=2016040610184136601600060=201604061018413660160005799=10000100268=2279=2269=148=17359555=6SZ683=354175270=10226.0271=3346=11023=2279=0269=148=17359555=6SZ683=354176270=10277.0271=12346=11023=1010=227
1128=99=18035=X49=SAMPLE75=2016101134=174052=2000011417292544430010960=200001141729254443001095799=10000100268=1279=1269=148=17359555=6SZ683=354177270=10216.0271=4346=21023=110=128
1128=99=18035=X49=SAMPLE75=2016101134=194852=2007052706141743511673660=200705270614174351167365799=10000100268=1279=1269=148=17359555=6SZ683=354178270=10216.0271=7346=31023=110=137
1128=99=18035=X49=SAMPLE75=2016101134=200752=2009020100340148543427260=200902010034014854342725799=10000100268=1279=0269=148=17359555=6SZ683=354179270=10225.0271=3346=11023=210=104
1128=99=18035=X49=SAMPLE75=2016101134=38452=2004060301434635697950460=200406030143463569795045799=10000100268=1279=1269=148=17359555=6SZ683=354180270=10225.0271=6346=21023=210=110
1128=99=18035=X49=SAMPLE75=2016101134=205952=2014041318143273587622460=201404131814327358762245799=10000100268=1279=1269=148=17359555=6SZ683=354181270=10225.0271=9346=31023=210=070
1128=99=18135=X49=SAMPLE75=2016101134=118252=2007101110592647162742460=200710111059264716274245799=10000100268=1279=1269=148=17359555=6SZ683=354182270=10225.0271=12346=41023=210=136
1128=99=18135=X49=SAMPLE75=2016101134=179452=2014032915263521466496060=201403291526352146649605799=10000100268=1279=1269=148=17359555=6SZ683=354183270=10225.0271=15346=51023=210=158
1128=99=18035=X49=SAMPLE75=2016101134=220452=2006050407124192800505660=200605040712419280050565799=10000100268=1279=0269=148=17359555=6SZ683=354184270=10224.0271=3346=11023=210=094
1128=99=18135=X49=SAMPLE75=2016101134=1152=2008030202043123405840060=200803020204312340584005799=10000100268=1279=1269=148=17359555=6SZ683=354185270=10225.0271=18346=61023=310=144
1128=99=18035=X49=SAMPLE75=2016101134=81952=2009012916385209383894460=200901291638520938389445799=10000100268=1279=0269=148=17359555=6SZ683=354186270=10223.0271=3346=11023=210=119
1128=99=18035=X49=SAMPLE75=2016101134=45252=2000041420320833628966860=200004142032083362896685799=10000100268=1279=1269=148=17359555=6SZ683=354187270=10223.0271=6346=21023=210=113
1128=99=18035=X49=SAMPLE75=2016101134=370852=2012011106521268882028860=201201110652126888202885799=10000100268=1279=0269=148=17359555=6SZ683=354188270=10222.0271=2346=11023=210=075
1128=99=18035=X49=SAMPLE75=2016101134=263052=2000012818100449600159960=200001281810044960015995799=10000100268=1279=0269=148=17359555=6SZ683=354189270=10221.0271=3346=11023=210=104
1128=99=18035=X49=SAMPLE75=2016101134=46052=2006020105235558248547260=200602010523555824854725799=10000100268=1279=1269=148=17359555=6SZ683=354190270=10221.0271=6346=21023=210=074
1128=99=18035=X49=SAMPLE75=2016101134=383652=2005042221564669823939260=200504222156466982393925799=10000100268=1279=1269=148=17359555=6SZ683=354191270=10221.0271=9346=31023=210=119
1128=99=32335=X49=SAMPLE75=2016101134=21152=2010032011062761106598460=201003201106276110659845799=10000100268=3279=0269=148=17359555=6SZ683=354192270=10220.0271=3346=11023=2279=2269=148=17359555=6SZ683=354193270=10224.0271=3346=11023=6279=0269=148=17359555=6SZ683=354194270=10255.0271=2346=11023=1010=009
1128=99=18035=X49=SAMPLE75=2016101134=233652=2002022217361543773213660=200202221736154377321365799=10000100268=1279=0269=148=17359555=6SZ683=354195270=10219.0271=3346=11023=210=123
1128=99=25235=X49=SAMPLE75=2016101134=201752=2012012918111507103200060=201201291811150710320005799=10000100268=2279=2269=148=17359555=6SZ683=354196270=10222.0271=2346=11023=5279=0269=148=17359555=6SZ683=354197270=10255.0271=2346=11023=1010=228
1128=99=18035=X49=SAMPLE75=2016101134=291252=2008040403191321635206460=200804040319132163520645799=10000100268=1279=1269=148=17359555=6SZ683=354198270=10219.0271=6346=21023=210=115
1128=99=18035=X49=SAMPLE75=2016101134=247952=2006111401262252366764860=200611140126225236676485799=10000100268=1279=1269=148=17359555=6SZ683=354199270=10219.0271=9346=31023=210=132
1128=99=25235=X49=SAMPLE75=2016101134=364952=2008052822255432746336060=200805282225543274633605799=10000100268=2279=2269=148=17359555=6SZ683=354200270=10220.0271=3346=11023=3279=0269=148=17359555=6SZ683=354201270=10263.0271=2346=11023=1010=170
1128=99=18035=X49=SAMPLE75=2016101134=166052=2000062515252331168504860=200006251525233116850485799=10000100268=1279=0269=148=17359555=6SZ683=354202270=10231.0271=3346=11023=610=061
1128=99=18035=X49=SAMPLE75=2016101134=401852=2009050501420870061171260=200905050142087006117125799=10000100268=1279=1269=148=17359555=6SZ683=354203270=10231.0271=6346=21023=610=078
1128=99=18035=X49=SAMPLE75=2016101134=304352=2002081422491162555438460=200208142249116255543845799=10000100268=1279=1269=148=17359555=6SZ683=354204270=10231.0271=9346=31023=610=083
1128=99=18135=X49=SAMPLE75=2016101134=421952=2013072316491842078252860=201307231649184207825285799=10000100268=1279=1269=148=17359555=6SZ683=354205270=10231.0271=12346=41023=610=147
1128=99=18135=X49=SAMPLE75=2016101134=38752=2008042804153358884259260=200804280415335888425925799=10000100268=1279=1269=148=17359555=6SZ683=354206270=10231.0271=15346=51023=610=161
1128=99=18135=X49=SAMPLE75=2016101134=275052=2010022803564007931302460=201002280356400793130245799=10000100268=1279=1269=148=17359555=6SZ683=354207270=10231.0271=18346=61023=610=162
1128=99=18135=X49=SAMPLE75=2016101134=304952=2000091818101259428836060=200009181810125942883605799=10000100268=1279=1269=148=17359555=6SZ683=354208270=10231.0271=21346=71023=610=152
1128=99=18135=X49=SAMPLE75=2016101134=285352=2011112307075636858368060=201111230707563685836805799=10000100268=1279=1269=148=17359555=6SZ683=354209270=10231.0271=24346=81023=610=183
1128=99=18135=X49=SAMPLE75=2016101134=321752=2010112805031810071417660=201011280503181007141765799=10000100268=1279=1269=148=17359555=6SZ683=354210270=10231.0271=27346=91023=610=156
1128=99=18035=X49=SAMPLE75=2016101134=163652=2007080615205053436764860=200708061520505343676485799=10000100268=1279=1269=148=17359555=6SZ683=354211270=10216.0271=6346=21023=110=132
1128=99=18035=X49=SAMPLE75=2016101134=230752=2012060121470643126272060=201206012147064312627205799=10000100268=1279=0269=148=17359555=6SZ683=354212270=10218.0271=3346=11023=210=107
1128=99=18035=X49=SAMPLE75=2016101134=192752=2013012217251224919532860=201301221725122491953285799=10000100268=1279=0269=048=17359555=6SZ683=354213270=10201.0271=3346=11023=110=071
1128=99=18035=X49=SAMPLE75=2016101134=430952=2013080116321530327347260=201308011632153032734725799=10000100268=1279=1269=048=17359555=6SZ683=354214270=10201.0271=6346=21023=110=113
1128=99=18035=X49=SAMPLE75=2016101134=416752=2002070709081691135345660=200207070908169113534565799=10000100268=1279=1269=048=17359555=6SZ683=354215270=10201.0271=9346=31023=110=130
1128=99=18135=X49=SAMPLE75=2016101134=435452=2003122304112889398924860=200312230411288939892485799=10000100268=1279=1269=048=17359555=6SZ683=354216270=10201.0271=12346=41023=110=170
1128=99=18135=X49=SAMPLE75=2016101134=149352=2009082714591530324851260=200908271459153032485125799=10000100268=1279=1269=048=17359555=6SZ683=354217270=10201.0271=15346=51023=110=142
1128=99=18135=X49=SAMPLE75=2016101134=334652=2004090902530080479926460=200409090253008047992645799=10000100268=1279=1269=048=17359555=6SZ683=354218270=10201.0271=18346=61023=110=145
1128=99=18135=X49=SAMPLE75=2016101134=317752=2008090611180021754246460=200809061118002175424645799=10000100268=1279=1269=048=17359555=6SZ683=354219270=10201.0271=21346=71023=110=180
1128=99=18135=X49=SAMPLE75=2016101134=62052=2008080809322426762876860=200808080932242676287685799=10000100268=1279=1269=048=17359555=6SZ683=354220270=10201.0271=24346=81023=110=146
1128=99=18135=X49=SAMPLE75=2016101134=499652=2013030611430368667699260=201303061143036866769925799=10000100268=1279=1269=048=17359555=6SZ683=354221270=10201.0271=27346=91023=110=162
1128=99=18135=X49=SAMPLE75=2016101134=458852=2016112716571260591744060=201611271657126059174405799=10000100268=1279=1269=148=17359555=6SZ683=354222270=10219.0271=10346=41023=310=141
1128=99=18135=X49=SAMPLE75=2016101134=329052=2009091308500682028416060=200909130850068202841605799=10000100268=1279=1269=148=17359555=6SZ683=354223270=10219.0271=13346=51023=310=174
1128=99=18135=X49=SAMPLE75=2016101134=484552=2015112507452179267596860=201511250745217926759685799=10000100268=1279=1269=148=17359555=6SZ683=354224270=10219.0271=16346=61023=310=169
1128=99=18035=X49=SAMPLE75=2016101134=91352=2013082405454817287987260=201308240545481728798725799=10000100268=1279=1269=148=17359555=6SZ683=354225270=10218.0271=4346=21023=210=133
1128=99=25235=X49=SAMPLE75=2016101134=244352=2007020610474984645881660=200702061047498464588165799=10000100268=2279=0269=048=17359555=6SZ683=354226270=10202.0271=1346=11023=1279=1269=048=17359555=6SZ683=354227270=10197.0271=12346=41023=310=233
1128=99=18035=X49=SAMPLE75=2016101134=143252=2012110722585469743104060=201211072258546974310405799=10000100268=1279=0269=048=17359555=6SZ683=354228270=10170.0271=1346=11023=710=130
1128=99=18035=X49=SAMPLE75=2016101134=225152=2011103115095829617907260=201110311509582961790725799=10000100268=1279=1269=048=17359555=6SZ683=354229270=10202.0271=4346=21023=110=099
1128=99=18035=X49=SAMPLE75=2016101134=277652=2016021009194383787744060=201602100919438378774405799=10000100268=1279=1269=048=17359555=6SZ683=354230270=10202.0271=7346=31023=110=076
1128=99=18135=X49=SAMPLE75=2016101134=241652=2007090117475197374640060=200709011747519737464005799=10000100268=1279=1269=048=17359555=6SZ683=354231270=10202.0271=10346=41023=110=127
1128=99=18135=X49=SAMPLE75=2016101134=5952=2016112307053582248774460=201611230705358224877445799=10000100268=1279=1269=048=17359555=6SZ683=354232270=10202.0271=13346=51023=110=145
1128=99=18135=X49=SAMPLE75=2016101134=21352=2010012818573965067808060=201001281857396506780805799=10000100268=1279=1269=048=17359555=6SZ683=354233270=10202.0271=16346=61023=110=161
1128=99=18135=X49=SAMPLE75=2016101134=353152=2013041400182425449958460=201304140018242544995845799=10000100268=1279=1269=048=17359555=6SZ683=354234270=10202.0271=19346=71023=110=154
1128=99=18035=X49=SAMPLE75=2016101134=121452=2016110605372654683424060=201611060537265468342405799=10000100268=1279=0269=048=17359555=6SZ683=354235270=10205.0271=3346=11023=110=085
1128=99=18035=X49=SAMPLE75=2016101134=155752=2002072919453625099184060=200207291945362509918405799=10000100268=1279=1269=148=17359555=6SZ683=354236270=10218.0271=1346=11023=210=098
1128=99=18035=X49=SAMPLE75=2016101134=430152=2001101504534570606829660=200110150453457060682965799=10000100268=1279=1269=048=17359555=6SZ683=354237270=10205.0271=6346=21023=110=099
1128=99=18035=X49=SAMPLE75=2016101134=44752=2011011923140266922105660=201101192314026692210565799=10000100268=1279=1269=048=17359555=6SZ683=354238270=10205.0271=9346=31023=110=132
1128=99=18135=X49=SAMPLE75=2016101134=105852=2002111207341540602488060=200211120734154060248805799=10000100268=1279=1269=048=17359555=6SZ683=354239270=10205.0271=12346=41023=110=155
1128=99=18135=X49=SAMPLE75=2016101134=41552=2010110314111828255334460=201011031411182825533445799=10000100268=1279=1269=048=17359555=6SZ683=354240270=10205.0271=15346=51023=110=172
1128=99=18135=X49=SAMPLE75=2016101134=16452=2011040909132367625107260=201104090913236762510725799=10000100268=1279=1269=048=17359555=6SZ683=354241270=10205.0271=18346=61023=110=132
1128=99=18035=X49=SAMPLE75=2016101134=177352=2005051106091260400614460=200505110609126040061445799=10000100268=1279=1269=148=17359555=6SZ683=354242270=10216.0271=9346=31023=110=101
1128=99=18035=X49=SAMPLE75=2016101134=161552=2012100915522939476460860=201210091552293947646085799=10000100268=1279=0269=048=17359555=6SZ683=354243270=10200.0271=1346=11023=410=108
1128=99=18035=X49=SAMPLE75=2016101134=197152=2012030403051974238592060=201203040305197423859205799=10000100268=1279=0269=048=17359555=6SZ683=354244270=10195.0271=1346=11023=710=138
1128=99=18135=X49=SAMPLE75=2016101134=209152=2006090610232225639014460=200609061023222563901445799=10000100268=1279=1269=148=17359555=6SZ683=354245270=10221.0271=10346=41023=410=141
1128=99=18035=X49=SAMPLE75=2016101134=69652=2001050720134304343011260=200105072013430434301125799=10000100268=1279=0269=148=17359555=6SZ683=354246270=10226.0271=1346=11023=710=103
1128=99=13135=f49=SAMPLE34=488352=2005071207492493011494460=2005071207492493011494475=201610115799=000000001151=6S326=21327=01174=110=067
1128=99=18035=X49=SAMPLE75=2016101134=34352=2010111719211011775174460=201011171921101177517445799=10000100268=1279=0269=048=17359555=6SZ683=354247270=10206.0271=5346=11023=110=124
1128=99=18035=X49=SAMPLE75=2016101134=254452=2008072512362774090310460=200807251236277409031045799=10000100268=1279=0269=048=17359555=6SZ683=354248270=10207.0271=3346=11023=110=075
1128=99=18035=X49=SAMPLE75=2016101134=131252=2013070609293699703545660=201307060929369970354565799=10000100268=1279=1269=048=17359555=6SZ683=354249270=10207.0271=6346=21023=110=134
1128=99=18035=X49=SAMPLE75=2016101134=76052=2006012112374801497091260=200601211237480149709125799=10000100268=1279=0269=148=17359555=6SZ683=354250270=10215.0271=2346=11023=110=099
1128=99=18035=X49=SAMPLE75=2016101134=106252=2007121608155000039907260=200712160815500003990725799=10000100268=1279=1269=148=17359555=6SZ683=354251270=10215.0271=5346=21023=110=126
1128=99=18035=X49=SAMPLE75=2016101134=378952=2000120308374865402821660=200012030837486540282165799=10000100268=1279=1269=148=17359555=6SZ683=354252270=10215.0271=8346=31023=110=127
1128=99=18135=X49=SAMPLE75=2016101134=157652=2012060806272548120876860=201206080627254812087685799=10000100268=1279=1269=148=17359555=6SZ683=354253270=10215.0271=11346=41023=110=176
1128=99=18135=X49=SAMPLE75=2016101134=435852=2017020115361105071123260=201702011536110507112325799=10000100268=1279=1269=148=17359555=6SZ683=354254270=10215.0271=14346=51023=110=168
1128=99=18035=X49=SAMPLE75=2016101134=341552=2004061709424153463678460=200406170942415346367845799=10000100268=1279=0269=048=17359555=6SZ683=354255270=10208.0271=2346=11023=110=141
1128=99=18135=X49=SAMPLE75=2016101134=127652=2010062711075000139372860=201006271107500013937285799=10000100268=1279=1269=148=17359555=6SZ683=354256270=10215.0271=17346=61023=110=162
1128=99=18035=X49=SAMPLE75=2016101134=92352=2016122603050348308774460=201612260305034830877445799=10000100268=1279=1269=048=17359555=6SZ683=354257270=10206.0271=6346=21023=310=123
1128=99=18035=X49=SAMPLE75=2016101134=26952=2014122616484637315097660=201412261648463731509765799=10000100268=1279=1269=048=17359555=6SZ683=354258270=10207.0271=7346=31023=210=119
1128=99=18235=X49=SAMPLE75=2016101134=190552=2002031307420259846564060=200203130742025984656405799=10000100268=1279=0269=148=17359555=6SZ683=354259270=10233.0271=32346=11023=1010=196
1128=99=18035=X49=SAMPLE75=2016101134=452552=2002052413505478432240060=200205241350547843224005799=10000100268=1279=0269=148=17359555=6SZ683=354260270=10220.0271=8346=11023=510=101
1128=99=18135=X49=SAMPLE75=2016101134=105152=2006080908551857622969660=200608090855185762296965799=10000100268=1279=1269=148=17359555=6SZ683=354261270=10225.0271=34346=71023=810=160
1128=99=18135=X49=SAMPLE75=2016101134=62252=2009040603465751323852860=200904060346575132385285799=10000100268=1279=1269=148=17359555=6SZ683=354262270=10225.0271=50346=81023=810=158
1128=99=18135=X49=SAMPLE75=2016101134=459152=2003051409321049558816060=200305140932104955881605799=10000100268=1279=1269=148=17359555=6SZ683=354263270=10220.0271=16346=21023=510=148
1128=99=18135=X49=SAMPLE75=2016101134=302652=2003070604185481132704060=200307060418548113270405799=10000100268=1279=1269=148=17359555=6SZ683=354264270=10220.0271=24346=31023=510=138
1128=99=18035=X49=SAMPLE75=2016101134=452452=2002090615414149559081660=200209061541414955908165799=10000100268=1279=0269=048=17359555=6SZ683=354265270=10211.0271=4346=11023=110=114
1128=99=18035=X49=SAMPLE75=2016101134=319452=2011011917114523883379260=201101191711452388337925799=00000100268=1279=0269=048=17359555=6SZ683=354266270=10215.0271=4346=11023=110=135
1128=99=16735=X49=SAMPLE75=2016101134=364752=2001112720385590414245660=200111272038559041424565799=10001000268=1279=0269=448=17359555=6SZ683=354267270=10215.0286=510=088
1128=99=18035=X49=SAMPLE75=2016101134=142352=2008062321393320813267260=200806232139332081326725799=10000100268=1279=1269=148=17359555=6SZ683=354268270=10218.0271=9346=21023=310=123
1128=99=18135=X49=SAMPLE75=2016101134=39152=2014052011145129871622460=201405201114512987162245799=10000100268=1279=1269=148=17359555=6SZ683=354269270=10220.0271=32346=41023=510=165
1128=99=18135=X49=SAMPLE75=2016101134=347952=2014052120013913644102460=201405212001391364410245799=10000100268=1279=1269=148=17359555=6SZ683=354270270=10223.0271=22346=31023=710=177
1128=99=18135=X49=SAMPLE75=2016101134=436452=2016020609054858385593660=201602060905485838559365799=10000100268=1279=1269=148=17359555=6SZ683=354271270=10215.0271=18346=71023=110=192
1128=99=18135=X49=SAMPLE75=2016101134=286452=2004072121242749649571260=200407212124274964957125799=10000100268=1279=1269=148=17359555=6SZ683=354272270=10215.0271=19346=81023=110=174
1128=99=18135=X49=SAMPLE75=2016101134=314452=2006110316024646384688060=200611031602464638468805799=10000100268=1279=1269=148=17359555=6SZ683=354273270=10215.0271=20346=91023=110=193
1128=99=39435=X49=SAMPLE75=2016101134=79152=2015011615373723718534460=201501161537372371853445799=00000100268=4279=2269=048=17359555=6SZ683=354274270=10215.0271=4346=11023=1279=0269=048=17359555=6SZ683=354275270=10214.0271=4346=11023=1279=0269=148=17359555=6SZ683=354276270=10214.0271=4346=41023=1279=1269=148=17359555=6SZ683=354277270=10215.0271=17346=61023=210=046
1128=99=16735=X49=SAMPLE75=2016101134=7152=2004082320392742962243260=200408232039274296224325799=10001000268=1279=0269=448=17359555=6SZ683=354278270=10214.0286=510=066
1128=99=18035=X49=SAMPLE75=2016101134=106552=2015022108234062798732860=201502210823406279873285799=10000100268=1279=1269=148=17359555=6SZ683=354279270=10214.0271=5346=51023=110=149
1128=99=18035=X49=SAMPLE75=2016101134=446852=2004100611154638172268860=200410061115463817226885799=10000100268=1279=1269=148=17359555=6SZ683=354280270=10214.0271=6346=61023=110=129
1128=99=18035=X49=SAMPLE75=2016101134=181852=2012032606130404560339260=201203260613040456033925799=10000100268=1279=1269=148=17359555=6SZ683=354281270=10214.0271=7346=71023=110=136
1128=99=18035=X49=SAMPLE75=2016101134=6152=2014092906343387806400060=201409290634338780640005799=10000100268=1279=1269=148=17359555=6SZ683=354282270=10214.0271=8346=81023=110=131
1128=99=18035=X49=SAMPLE75=2016101134=94952=2013100620331288916953660=201310062033128891695365799=10000100268=1279=1269=148=17359555=6SZ683=354283270=10214.0271=9346=91023=110=156
1128=99=18235=X49=SAMPLE75=2016101134=439452=2013081722172672367142460=201308172217267236714245799=10000100268=1279=1269=148=17359555=6SZ683=354284270=10214.0271=10346=101023=110=221
1128=99=18235=X49=SAMPLE75=2016101134=75152=2007071405135601882928060=200707140513560188292805799=10000100268=1279=1269=148=17359555=6SZ683=354285270=10214.0271=11346=111023=110=211
1128=99=18135=X49=SAMPLE75=2016101134=449052=2016041223391517139052860=201604122339151713905285799=10000100268=1279=1269=048=17359555=6SZ683=354286270=10208.0271=23346=21023=310=174
1128=99=32335=X49=SAMPLE75=2016101134=401452=2001112001582810316548060=200111200158281031654805799=00000100268=3279=2269=048=17359555=6SZ683=354287270=10214.0271=4346=11023=1279=0269=048=17359555=6SZ683=354288270=10212.0271=4346=11023=1279=0269=148=17359555=6SZ683=354289270=10212.0271=21346=11023=110=253
1128=99=16735=X49=SAMPLE75=2016101134=327652=2008120407153635330646460=200812040715363533064645799=10001000268=1279=0269=448=17359555=6SZ683=354290270=10212.0286=510=067
1128=99=18135=X49=SAMPLE75=2016101134=477852=2013032804002107366963260=201303280400210736696325799=10000100268=1279=1269=048=17359555=6SZ683=354291270=10207.0271=28346=41023=410=167
1128=99=18135=X49=SAMPLE75=2016101134=111252=2000031819460473982021160=200003181946047398202115799=10000100268=1279=0269=148=17359555=6SZ683=354292270=10213.0271=21346=11023=210=155
1128=99=18135=X49=SAMPLE75=2016101134=498552=2012080205244639951321660=201208020524463995132165799=10000100268=1279=1269=048=17359555=6SZ683=354293270=10206.0271=27346=31023=510=177
1128=99=18235=X49=SAMPLE75=2016101134=130552=2014041620001638519686460=201404162000163851968645799=10000100268=1279=1269=148=17359555=6SZ683=354294270=10214.0271=32346=121023=310=238
1128=99=18135=X49=SAMPLE75=2016101134=84452=2014052622550896020582460=201405262255089602058245799=10000100268=1279=0269=048=17359555=6SZ683=354295270=10204.0271=30346=11023=710=182
1128=99=18135=X49=SAMPLE75=2016101134=372052=2009052220123769324787260=200905222012376932478725799=10000100268=1279=0269=048=17359555=6SZ683=354296270=10203.0271=30346=11023=810=185
1128=99=18135=X49=SAMPLE75=2016101134=336752=2003042820471830770460860=200304282047183077046085799=10000100268=1279=1269=148=17359555=6SZ683=354297270=10220.0271=62346=51023=810=180
1128=99=18135=X49=SAMPLE75=2016101134=155352=2007100311120462014902460=200710031112046201490245799=10000100268=1279=0269=148=17359555=6SZ683=354298270=10217.0271=30346=11023=610=193
1128=99=18135=X49=SAMPLE75=2016101134=451552=2006091305021155147446460=200609130502115514744645799=10000100268=1279=1269=148=17359555=6SZ683=354299270=10216.0271=39346=41023=510=206
1128=99=18235=X49=SAMPLE75=2016101134=187652=2016102406331394117542460=201610240633139411754245799=10000100268=1279=1269=148=17359555=6SZ683=354300270=10214.0271=33346=131023=310=225
1128=99=13135=f49=SAMPLE34=200352=2015121108484136403110460=2015121108484136403110475=201610115799=000000001151=6S326=15327=01174=010=027
1128=99=22035=X49=SAMPLE75=2016101134=493452=2014053116021839974956860=201405311602183997495685799=00000001268=1279=0269=248=17359555=6SZ683=354301270=10212.0271=4346=25797=037705=237=032=437=621180788979332=410=153
1128=99=15535=X49=SAMPLE75=2016101134=98752=2001082305351727433206460=200108230535172743320645799=00000010268=1279=0269=e48=17359555=6SZ683=354302271=410=241
1128=99=32535=X49=SAMPLE75=2016101134=320552=2001042615002405512547260=200104261500240551254725799=00000100268=3279=2269=048=17359555=6SZ683=354303270=10212.0271=4346=11023=1279=0269=048=17359555=6SZ683=354304270=10200.0271=31346=21023=10279=1269=148=17359555=6SZ683=354305270=10212.0271=17346=11023=110=249
1128=99=28735=X49=SAMPLE75=2016101134=349452=2004041206551687498424060=200404120655168749842405799=00001000268=3279=0269=748=17359555=6SZ683=354306270=10212.0286=255279=0269=848=17359555=6SZ683=354307270=10212.0286=255279=0269=448=17359555=6SZ683=354308270=10212.0286=010=161
1128=99=13135=f49=SAMPLE34=284752=2001020418264327565349660=2001020418264327565349675=201610115799=000000001151=6S326=17327=01174=010=033
1128=99=18235=X49=SAMPLE75=2016101134=120952=2009053105122901120940860=200905310512290112094085799=00000100268=1279=1269=148=17359555=6SZ683=354309270=10214.0271=32346=121023=310=138
1128=99=22935=X49=SAMPLE75=2016101134=354452=2002020711250216332384060=200202071125021633238405799=10001000268=2279=0269=N48=17359555=6SZ683=354310270=10211.0286=255279=0269=O48=17359555=6SZ683=354311270=10212.0286=25510=205
1128=99=18235=X49=SAMPLE75=2016101134=30552=2003090910353944033833660=200309091035394403383365799=10000100268=1279=1269=148=17359555=6SZ683=354312270=10214.0271=31346=111023=310=155
1128=99=18235=X49=SAMPLE75=2016101134=259352=2001041113570766615156060=200104111357076661515605799=10000100268=1279=1269=148=17359555=6SZ683=354313270=10214.0271=30346=101023=310=133
1128=99=18135=X49=SAMPLE75=2016101134=272752=2009122106470826450572860=200912210647082645057285799=10000100268=1279=1269=148=17359555=6SZ683=354314270=10214.0271=29346=91023=310=110
1128=99=18135=X49=SAMPLE75=2016101134=69152=2006082110521714340860860=200608211052171434086085799=10000100268=1279=1269=148=17359555=6SZ683=354315270=10214.0271=28346=81023=310=105
1128=99=18135=X49=SAMPLE75=2016101134=292752=2004111102574336618006460=200411110257433661800645799=10000100268=1279=1269=148=17359555=6SZ683=354316270=10214.0271=27346=71023=310=083
1128=99=18135=X49=SAMPLE75=2016101134=337852=2004070417281067550284860=200407041728106755028485799=10000100268=1279=1269=148=17359555=6SZ683=354317270=10214.0271=26346=61023=310=111
1128=99=18135=X49=SAMPLE75=2016101134=171952=2002031703293170066657660=200203170329317006665765799=10000100268=1279=1269=148=17359555=6SZ683=354318270=10214.0271=25346=51023=310=094
1128=99=18135=X49=SAMPLE75=2016101134=156052=2002012216042754312592860=200201221604275431259285799=10000100268=1279=1269=148=17359555=6SZ683=354319270=10215.0271=47346=71023=410=133
1128=99=18135=X49=SAMPLE75=2016101134=273452=2000063017394754016227460=200006301739475401622745799=10000100268=1279=1269=148=17359555=6SZ683=354320270=10215.0271=17346=61023=410=104
1128=99=18035=X49=SAMPLE75=2016101134=105152=2002051611544636285392060=200205161154463628539205799=10000100268=1279=1269=148=17359555=6SZ683=354321270=10218.0271=1346=11023=710=062
1128=99=18135=X49=SAMPLE75=2016101134=442752=2008091204113650152240060=200809120411365015224005799=10000100268=1279=1269=048=17359555=6SZ683=354322270=10206.0271=28346=41023=410=134
1128=99=18135=X49=SAMPLE75=2016101134=64952=2004041620290826410670460=200404162029082641067045799=10000100268=1279=1269=148=17359555=6SZ683=354323270=10220.0271=63346=61023=910=101
1128=99=18035=X49=SAMPLE75=2016101134=237652=2007122614104096662883260=200712261410409666288325799=10000100268=1279=1269=048=17359555=6SZ683=354324270=10206.0271=7346=31023=410=053
1128=99=25335=X49=SAMPLE75=2016101134=32752=2001120421010744421268860=200112042101074442126885799=10000100268=2279=2269=148=17359555=6SZ683=354325270=10213.0271=21346=11023=2279=0269=148=17359555=6SZ683=354326270=10222.0271=8346=11023=1010=188
1128=99=18135=X49=SAMPLE75=2016101134=296252=2002070301152060734184060=200207030115206073418405799=10000100268=1279=1269=048=17359555=6SZ683=354327270=10200.0271=1346=11023=1010=101
1128=99=18035=X49=SAMPLE75=2016101134=473752=2004032304420794957216060=200403230442079495721605799=10000100268=1279=1269=148=17359555=6SZ683=354328270=10216.0271=9346=31023=410=097
1128=99=18135=X49=SAMPLE75=2016101134=22752=2010051721200183272339260=201005172120018327233925799=10000100268=1279=1269=148=17359555=6SZ683=354329270=10216.0271=39346=41023=410=126
1128=99=18035=X49=SAMPLE75=2016101134=129552=2001072215424621547948060=200107221542462154794805799=10000100268=1279=1269=048=17359555=6SZ683=354330270=10208.0271=2346=11023=210=049
1128=99=25335=X49=SAMPLE75=2016101134=95752=2016063005120810997523260=201606300512081099752325799=10000100268=2279=2269=148=17359555=6SZ683=354331270=10212.0271=17346=11023=1279=0269=148=17359555=6SZ683=354332270=10223.0271=6346=21023=1010=199
1128=99=18035=X49=SAMPLE75=2016101134=442352=2010090622300624640339260=201009062230062464033925799=10000100268=1279=1269=148=17359555=6SZ683=354333270=10214.0271=4346=41023=110=064
1128=99=18035=X49=SAMPLE75=2016101134=9652=2003121704250587038587260=200312170425058703858725799=10000100268=1279=1269=048=17359555=6SZ683=354334270=10207.0271=7346=31023=310=083
1128=99=18135=X49=SAMPLE75=2016101134=396252=2005042006590040617715260=200504200659004061771525799=10000100268=1279=1269=148=17359555=6SZ683=354335270=10220.0271=33346=51023=710=111
1128=99=25435=X49=SAMPLE75=2016101134=208252=2007120422231808186915260=200712042223180818691525799=10000100268=2279=2269=048=17359555=6SZ683=354336270=10203.0271=30346=11023=7279=0269=048=17359555=6SZ683=354337270=10199.0271=30346=11023=1010=249
1128=99=25435=X49=SAMPLE75=2016101134=3752=2010082307424590467526460=201008230742459046752645799=10000100268=2279=2269=148=17359555=6SZ683=354338270=10217.0271=30346=11023=4279=0269=148=17359555=6SZ683=354339270=10225.0271=50346=81023=1010=009
1128=99=25435=X49=SAMPLE75=2016101134=476252=2000121308131825874290060=200012130813182587429005799=10000100268=2279=2269=048=17359555=6SZ683=354340270=10204.0271=30346=11023=6279=0269=048=17359555=6SZ683=354341270=10197.0271=12346=41023=1010=001
1128=99=18135=X49=SAMPLE75=2016101134=314352=2011101201574159750572860=201110120157415975057285799=10000100268=1279=1269=148=17359555=6SZ683=354342270=10222.0271=38346=21023=810=131
1128=99=18135=X49=SAMPLE75=2016101134=395752=2003041112121358812584060=200304111212135881258405799=10000100268=1279=0269=148=17359555=6SZ683=354343270=10217.0271=30346=11023=410=117
1128=99=18135=X49=SAMPLE75=2016101134=356552=2001061905442643499640860=200106190544264349964085799=10000100268=1279=0269=048=17359555=6SZ683=354344270=10203.0271=30346=11023=610=113
1128=99=18135=X49=SAMPLE75=2016101134=36152=2004082805423399702518460=200408280542339970251845799=10000100268=1279=0269=048=17359555=6SZ683=354345270=10204.0271=30346=11023=610=109
1128=99=18035=X49=SAMPLE75=2016101134=321552=2005072402353037129180860=200507240235303712918085799=10000100268=1279=1269=148=17359555=6SZ683=354346270=10222.0271=8346=11023=910=077
1128=99=18235=X49=SAMPLE75=2016101134=47952=2001111207243513292806460=200111120724351329280645799=10000100268=1279=1269=048=17359555=6SZ683=354347270=10200.0271=31346=21023=1010=170
1128=99=18035=X49=SAMPLE75=2016101134=391952=2006110315343335787385660=200611031534333578738565799=10000100268=1279=1269=048=17359555=6SZ683=354348270=10207.0271=8346=41023=310=104
1128=99=18235=X49=SAMPLE75=2016101134=454452=2004032122433149272172860=200403212243314927217285799=10000100268=1279=1269=148=17359555=6SZ683=354349270=10223.0271=36346=31023=1010=182
1128=99=18135=X49=SAMPLE75=2016101134=207852=2011121520125316639289660=201112152012531663928965799=10000100268=1279=1269=048=17359555=6SZ683=354350270=10200.0271=1346=11023=1010=107
1128=99=18235=X49=SAMPLE75=2016101134=310752=2009060602325319285702460=200906060232531928570245799=10000100268=1279=1269=048=17359555=6SZ683=354351270=10200.0271=31346=21023=1010=175
1128=99=18135=X49=SAMPLE75=2016101134=26352=2010102219571566771353660=201010221957156677135365799=10000100268=1279=0269=148=17359555=6SZ683=354352270=10212.0271=21346=11023=110=115
1128=99=18135=X49=SAMPLE75=2016101134=433052=2000062723315578703688460=200006272331557870368845799=10000100268=1279=0269=148=17359555=6SZ683=354353270=10213.0271=21346=11023=210=127
1128=99=18135=X49=SAMPLE75=2016101134=120652=2009111913375299620025660=200911191337529962002565799=10000100268=1279=1269=148=17359555=6SZ683=354354270=10214.0271=25346=51023=310=140
1128=99=18135=X49=SAMPLE75=2016101134=298052=2012122020292217128460860=201212202029221712846085799=10000100268=1279=1269=048=17359555=6SZ683=354355270=10200.0271=1346=11023=1010=111
1128=99=25335=X49=SAMPLE75=2016101134=348752=2016022615152612903763260=201602261515261290376325799=10000100268=2279=2269=148=17359555=6SZ683=354356270=10212.0271=21346=11023=1279=0269=148=17359555=6SZ683=354357270=10222.0271=8346=11023=1010=238
1128=99=18135=X49=SAMPLE75=2016101134=109552=2002102505012430473707260=200210250501243047370725799=10000100268=1279=1269=148=17359555=6SZ683=354358270=10215.0271=38346=71023=310=153
1128=99=18035=X49=SAMPLE75=2016101134=11352=2010031801190966523116860=201003180119096652311685799=00000100268=1279=0269=048=17359555=6SZ683=354359270=10212.0271=1346=11023=110=083
1128=99=16935=X49=SAMPLE75=2016101134=363352=2016051711094083255545660=201605171109408325554565799=10001000268=1279=0269=N48=17359555=6SZ683=354360270=10212.0286=25510=161
1128=99=25335=X49=SAMPLE75=2016101134=195352=2013071217311460084806460=201307121731146008480645799=10000100268=2279=2269=148=17359555=6SZ683=354361270=10217.0271=30346=11023=5279=0269=148=17359555=6SZ683=354362270=10223.0271=6346=21023=1010=218
1128=99=25335=X49=SAMPLE75=2016101134=169452=2013110706450201493740860=201311070645020149374085799=10000100268=2279=2269=048=17359555=6SZ683=354363270=10203.0271=30346=11023=8279=0269=048=17359555=6SZ683=354364270=10200.0271=1346=11023=1010=204
1128=99=18135=X49=SAMPLE75=2016101134=415152=2016112619430275122547260=201611261943027512254725799=10000100268=1279=0269=148=17359555=6SZ683=354365270=10217.0271=30346=11023=510=137
1128=99=18135=X49=SAMPLE75=2016101134=228852=2000103114420957536326860=200010311442095753632685799=10000100268=1279=0269=048=17359555=6SZ683=354366270=10203.0271=30346=11023=810=134
1128=99=18035=X49=SAMPLE75=2016101134=155652=2014022317531156144480060=201402231753115614448005799=10000100268=1279=1269=048=17359555=6SZ683=354367270=10207.0271=9346=51023=410=113
1128=99=29935=X49=SAMPLE75=2016101134=422952=2011021104365686850694460=201102110436568685069445799=00000001268=2279=0269=248=17359555=6SZ683=354368270=10212.0271=1346=25797=2279=0269=248=17359555=6SZ683=354369270=10211.0271=1346=25797=237705=437=032=137=032=137=032=137=032=110=212
1128=99=15535=X49=SAMPLE75=2016101134=357552=2007101122415221117840060=200710112241522111784005799=00000010268=1279=0269=e48=17359555=6SZ683=354370271=610=019
1128=99=32435=X49=SAMPLE75=2016101134=52352=2002030417324640222732860=200203041732464022273285799=00000100268=3279=2269=048=17359555=6SZ683=354371270=10212.0271=1346=11023=1279=1269=048=17359555=6SZ683=354372270=10211.0271=3346=11023=1279=0269=048=17359555=6SZ683=354373270=10200.0271=31346=21023=1010=232
1128=99=16935=X49=SAMPLE75=2016101134=74352=2013101600302922527475260=201310160030292252747525799=10001000268=1279=0269=848=17359555=6SZ683=354374270=10211.0286=25510=134
1128=99=20835=X49=SAMPLE75=2016101134=497552=2008031416442171160304060=200803141644217116030405799=00000001268=1279=0269=248=17359555=6SZ683=354375270=10211.0271=3346=25797=237705=237=032=337=032=310=040
1128=99=15535=X49=SAMPLE75=2016101134=243452=2010072721092581131443260=201007272109258113144325799=00000010268=1279=0269=e48=17359555=6SZ683=354376271=910=026
1128=99=25335=X49=SAMPLE75=2016101134=134252=2003092600264081556011260=200309260026408155601125799=10000100268=2279=2269=048=17359555=6SZ683=354377270=10211.0271=3346=11023=1279=0269=048=17359555=6SZ683=354378270=10197.0271=12346=41023=1010=227
1128=99=18035=X49=SAMPLE75=2016101134=386852=2010031705545485735635260=201003170554548573563525799=10000100268=1279=0269=048=17359555=6SZ683=354379270=10209.0271=1346=11023=110=092
1128=99=18135=X49=SAMPLE75=2016101134=289152=2001031620492367120265660=200103162049236712026565799=10000100268=1279=1269=048=17359555=6SZ683=354380270=10209.0271=22346=21023=110=118
1128=99=18035=X49=SAMPLE75=2016101134=315852=2014031518485455813004860=201403151848545581300485799=10000100268=1279=0269=048=17359555=6SZ683=354381270=10210.0271=1346=11023=110=050
1128=99=18135=X49=SAMPLE75=2016101134=153752=2015100607103981115193660=201510060710398111519365799=10000100268=1279=1269=048=17359555=6SZ683=354382270=10208.0271=23346=21023=310=110
1128=99=18135=X49=SAMPLE75=2016101134=327352=2008080518511952887472060=200808051851195288747205799=10000100268=1279=1269=048=17359555=6SZ683=354383270=10209.0271=21346=11023=210=119
1128=99=18335=X49=SAMPLE75=2016101134=446752=2004080702405749001302460=200408070240574900130245799=10000100268=1279=1269=048=17359555=6SZ683=354384270=10201.0271=35346=101023=1010=242
1128=99=18335=X49=SAMPLE75=2016101134=246852=2005010413591864483116860=200501041359186448311685799=10000100268=1279=1269=048=17359555=6SZ683=354385270=10201.0271=65346=111023=1010=221
1128=99=18335=X49=SAMPLE75=2016101134=44852=2001092908054677944851260=200109290805467794485125799=10000100268=1279=1269=048=17359555=6SZ683=354386270=10201.0271=35346=101023=1010=233
1128=99=18335=X49=SAMPLE75=2016101134=114552=2005041003204277747424060=200504100320427774742405799=10000100268=1279=1269=048=17359555=6SZ683=354387270=10201.0271=65346=111023=1010=235
1128=99=18335=X49=SAMPLE75=2016101134=246452=2013070101192309099449660=201307010119230909944965799=10000100268=1279=1269=048=17359555=6SZ683=354388270=10201.0271=35346=101023=1010=217
1128=99=18335=X49=SAMPLE75=2016101134=168852=2012061715255628742611260=201206171525562874261125799=10000100268=1279=1269=048=17359555=6SZ683=354389270=10201.0271=65346=111023=1010=244
1128=99=18335=X49=SAMPLE75=2016101134=77152=2012043000513405352915260=201204300051340535291525799=10000100268=1279=1269=048=17359555=6SZ683=354390270=10201.0271=35346=101023=1010=237
1128=99=18335=X49=SAMPLE75=2016101134=206452=2015041709575464926496060=201504170957546492649605799=10000100268=1279=1269=048=17359555=6SZ683=354391270=10201.0271=65346=111023=1010=240
1128=99=18335=X49=SAMPLE75=2016101134=399052=2011042903095635482950460=201104290309563548295045799=10000100268=1279=1269=048=17359555=6SZ683=354392270=10201.0271=35346=101023=1010=233
1128=99=18335=X49=SAMPLE75=2016101134=279352=2009120320213726855302460=200912032021372685530245799=10000100268=1279=1269=048=17359555=6SZ683=354393270=10201.0271=65346=111023=1010=247
1128=99=17835=X49=SAMPLE75=2016101134=146552=2011042404382554483737660=201104240438255448373765799=00000100268=1279=0269=048=17362455=6SU783=2565270=10363.0271=2346=11023=110=231
1128=99=16735=X49=SAMPLE75=2016101134=219852=2013082207201306437574460=201308220720130643757445799=10001000268=1279=0269=N48=17362455=6SU783=2566270=10363.0286=25510=052
1128=99=17835=X49=SAMPLE75=2016101134=320352=2005031320235136550880060=200503132023513655088005799=00000100268=1279=0269=148=17362455=6SU783=2567270=10414.0271=2346=11023=110=225
1128=99=16735=X49=SAMPLE75=2016101134=450952=2012011420210733766924860=201201142021073376692485799=10001000268=1279=0269=O48=17362455=6SU783=2568270=10414.0286=25510=046
1128=99=18335=X49=SAMPLE75=2016101134=454252=2006062110443471817984060=200606211044347181798405799=10000100268=1279=1269=048=17359555=6SZ683=354394270=10201.0271=35346=101023=1010=230
1128=99=18335=X49=SAMPLE75=2016101134=98752=2008081900345240167526460=200808190034524016752645799=10000100268=1279=1269=048=17359555=6SZ683=354395270=10201.0271=65346=111023=1010=226
1128=99=17835=X49=SAMPLE75=2016101134=160952=2009120812142776408972860=200912081214277640897285799=00000100268=1279=0269=048=17360355=6SM783=7518270=10251.0271=2346=11023=110=219
1128=99=22535=X49=SAMPLE75=2016101134=446452=2013122410461110396089660=201312241046111039608965799=10001000268=2279=0269=N48=17360355=6SM783=7519270=10251.0286=255279=0269=O48=17360355=6SM783=7520270=14000.0286=25510=016
1128=99=17835=X49=SAMPLE75=2016101134=180252=2016073003075573061702460=201607300307557306170245799=00000100268=1279=0269=148=17360355=6SM783=7521270=10408.0271=2346=11023=110=238
1128=99=16735=X49=SAMPLE75=2016101134=153852=2011120205043022180608060=201112020504302218060805799=10001000268=1279=0269=O48=17360355=6SM783=7522270=10408.0286=25510=059
1128=99=18335=X49=SAMPLE75=2016101134=296252=2010030423335868943808060=201003042333586894380805799=10000100268=1279=1269=048=17359555=6SZ683=354396270=10201.0271=35346=101023=1010=221
1128=99=18335=X49=SAMPLE75=2016101134=92352=2013112512340395074291260=201311251234039507429125799=10000100268=1279=1269=048=17359555=6SZ683=354397270=10201.0271=65346=111023=1010=245
1128=99=25235=X49=SAMPLE75=2016101134=81952=2005041317570838805987260=200504131757083880598725799=10000100268=2279=1269=048=17359555=6SZ683=354398270=10206.0271=6346=21023=5279=1269=048=17359555=6SZ683=354399270=10204.0271=31346=21023=710=198
1128=99=18135=X49=SAMPLE75=2016101134=48752=2016020418330224025728060=201602041833022402572805799=10000100268=1279=1269=048=17359555=6SZ683=354400270=10203.0271=31346=21023=810=121
1128=99=17935=X49=SAMPLE75=2016101134=124952=2016121913354678266438460=201612191335467826643845799=00000100268=1279=0269=048=17360055=6SH783=98999270=10262.0271=3346=11023=110=030
1128=99=22735=X49=SAMPLE75=2016101134=41752=2005042613353302400204860=200504261335330240020485799=10001000268=2279=0269=N48=17360055=6SH783=99000270=10262.0286=255279=0269=O48=17360055=6SH783=99001270=10500.0286=25510=102
1128=99=17935=X49=SAMPLE75=2016101134=381652=2009091600195808904268860=200909160019580890426885799=00000100268=1279=0269=148=17360055=6SH783=99002270=10269.0271=3346=11023=110=025
1128=99=16835=X49=SAMPLE75=2016101134=456252=2008010505003203632579260=200801050500320363257925799=10001000268=1279=0269=O48=17360055=6SH783=99003270=10269.0286=25510=101
1128=99=17935=X49=SAMPLE75=2016101134=132952=2011012513010260430899260=201101251301026043089925799=10000100268=1279=0269=048=17360055=6SH783=99004270=10261.0271=3346=11023=210=005
1128=99=17935=X49=SAMPLE75=2016101134=60952=2006100704431406609766460=200610070443140660976645799=10000100268=1279=0269=148=17360055=6SH783=99005270=10270.0271=3346=11023=210=021
1128=99=17935=X49=SAMPLE75=2016101134=459752=2010070823412168294092860=201007082341216829409285799=10000100268=1279=0269=148=17360055=6SH783=99006270=10271.0271=3346=11023=310=016
1128=99=17935=X49=SAMPLE75=2016101134=192052=2004021813343479562748860=200402181334347956274885799=10000100268=1279=0269=048=17360055=6SH783=99007270=10260.0271=3346=11023=310=029
1128=99=17935=X49=SAMPLE75=2016101134=90152=2009072919205806161856060=200907291920580616185605799=10000100268=1279=0269=048=17360055=6SH783=99008270=10259.0271=3346=11023=410=032
1128=99=17935=X49=SAMPLE75=2016101134=42152=2012041317163213647827260=201204131716321364782725799=10000100268=1279=0269=148=17360055=6SH783=99009270=10272.0271=3346=11023=410=034
1128=99=17935=X49=SAMPLE75=2016101134=409352=2015122412332503641708860=201512241233250364170885799=10000100268=1279=0269=048=17360055=6SH783=99010270=10258.0271=3346=11023=510=017
1128=99=17935=X49=SAMPLE75=2016101134=224652=2015050501404310870854460=201505050140431087085445799=10000100268=1279=0269=048=17360055=6SH783=99011270=10257.0271=3346=11023=610=007
1128=99=17935=X49=SAMPLE75=2016101134=272452=2007040318323653171401660=200704031832365317140165799=10000100268=1279=0269=148=17360055=6SH783=99012270=10273.0271=3346=11023=510=009
1128=99=17935=X49=SAMPLE75=2016101134=77752=2005121007273033533452860=200512100727303353345285799=10000100268=1279=0269=148=17360055=6SH783=99013270=10274.0271=3346=11023=610=029
1128=99=17935=X49=SAMPLE75=2016101134=493452=2010101821043327878950460=201010182104332787895045799=10000100268=1279=0269=048=17360055=6SH783=99014270=10256.0271=3346=11023=710=025
1128=99=17935=X49=SAMPLE75=2016101134=364552=2004020615224947527564860=200402061522494752756485799=10000100268=1279=0269=148=17360055=6SH783=99015270=10275.0271=3346=11023=710=039
1128=99=17935=X49=SAMPLE75=2016101134=211952=2013110302522113909984060=201311030252211390998405799=10000100268=1279=0269=148=17360055=6SH783=99016270=10276.0271=3346=11023=810=030
1128=99=17935=X49=SAMPLE75=2016101134=75052=2009100819385979956179260=200910081938597995617925799=10000100268=1279=0269=048=17360055=6SH783=99017270=10255.0271=3346=11023=810=042
1128=99=17935=X49=SAMPLE75=2016101134=299252=2008040120321474300448060=200804012032147430044805799=10000100268=1279=0269=148=17360055=6SH783=99018270=10277.0271=3346=11023=910=022
1128=99=17935=X49=SAMPLE75=2016101134=48352=2011021911035188307827260=201102191103518830782725799=10000100268=1279=0269=048=17360055=6SH783=99019270=10254.0271=3346=11023=910=032
1128=99=18035=X49=SAMPLE75=2016101134=379152=2012051712383119105030460=201205171238311910503045799=10000100268=1279=0269=148=17360055=6SH783=99020270=10278.0271=3346=11023=1010=081
1128=99=18035=X49=SAMPLE75=2016101134=132352=2014041914195398131904060=201404191419539813190405799=10000100268=1279=0269=048=17360055=6SH783=99021270=10253.0271=3346=11023=1010=057
1128=99=17935=X49=SAMPLE75=2016101134=320352=2007121716190915108918460=200712171619091510891845799=00000100268=1279=0269=148=17360355=6SM783=7523270=10352.0271=15346=11023=110=025
1128=99=16735=X49=SAMPLE75=2016101134=31552=2007091513171147975228860=200709151317114797522885799=10001000268=1279=0269=O48=17360355=6SM783=7524270=10352.0286=25510=049
1128=99=17935=X49=SAMPLE75=2016101134=482852=2011042021522002232876860=201104202152200223287685799=10000100268=1279=0269=148=17360355=6SM783=7525270=10356.0271=10346=11023=210=032
1128=99=17935=X49=SAMPLE75=2016101134=41552=2002110222265854119014460=200211022226585411901445799=00000100268=1279=0269=048=17360355=6SM783=7526270=10303.0271=15346=11023=110=009
1128=99=16735=X49=SAMPLE75=2016101134=80552=2001120502392752997361660=200112050239275299736165799=10001000268=1279=0269=N48=17360355=6SM783=7527270=10303.0286=25510=033
1128=99=17935=X49=SAMPLE75=2016101134=411752=2002102308570686352750460=200210230857068635275045799=10000100268=1279=0269=148=17360355=6SM783=7528270=10366.0271=30346=11023=310=030
1128=99=17935=X49=SAMPLE75=2016101134=312652=2002091804000631669339260=200209180400063166933925799=10000100268=1279=0269=048=17360355=6SM783=7529270=10299.0271=10346=11023=210=048
1128=99=17935=X49=SAMPLE75=2016101134=79652=2011072009321053992876860=201107200932105399287685799=10000100268=1279=0269=048=17360355=6SM783=7530270=10289.0271=30346=11023=310=024
1128=99=24735=X49=SAMPLE75=2016101134=124452=2007010205384133661036860=200701020538413366103685799=00000100268=2279=0269=048=17360355=6SM783=7531270=10304.0271=2346=11023=1279=2269=048=17360355=6SM783=7532270=10251.0271=2346=11023=510=122
1128=99=16735=X49=SAMPLE75=2016101134=228552=2011090410173684173267260=201109041017368417326725799=10001000268=1279=0269=N48=17360355=6SM783=7533270=10304.0286=25510=031
1128=99=24735=X49=SAMPLE75=2016101134=389952=2007072708080987396832060=200707270808098739683205799=00000100268=2279=0269=148=17360355=6SM783=7534270=10351.0271=2346=11023=1279=2269=148=17360355=6SM783=7535270=10408.0271=2346=11023=510=150
1128=99=16735=X49=SAMPLE75=2016101134=2952=2009112320061036117990460=200911232006103611799045799=10001000268=1279=0269=O48=17360355=6SM783=7536270=10351.0286=25510=051
1128=99=18335=X49=SAMPLE75=2016101134=167852=2006062500475290100662460=200606250047529010066245799=10000100268=1279=1269=048=17359555=6SZ683=354401270=10201.0271=35346=101023=1010=239
1128=99=24935=X49=SAMPLE75=2016101134=53752=2015030908215133972025660=201503090821513397202565799=10000100268=2279=1269=048=17360355=6SM783=7537270=10304.0271=17346=21023=1279=2269=048=17360355=6SM783=7538270=10303.0271=15346=11023=210=245
1128=99=18335=X49=SAMPLE75=2016101134=243952=2005121710342313499852860=200512171034231349985285799=10000100268=1279=1269=048=17359555=6SZ683=354402270=10201.0271=65346=111023=1010=234
1128=99=18335=X49=SAMPLE75=2016101134=93052=2011022421492596962892860=201102242149259696289285799=10000100268=1279=1269=048=17359555=6SZ683=354403270=10201.0271=35346=101023=1010=224
1128=99=18335=X49=SAMPLE75=2016101134=496552=2009051918304376538009660=200905191830437653800965799=10000100268=1279=1269=048=17359555=6SZ683=354404270=10201.0271=65346=111023=1010=211
1128=99=18335=X49=SAMPLE75=2016101134=143152=2008071820345531823376060=200807182034553182337605799=10000100268=1279=1269=048=17359555=6SZ683=354405270=10201.0271=35346=101023=1010=214
1128=99=18335=X49=SAMPLE75=2016101134=190152=2008080217260373885392060=200808021726037388539205799=10000100268=1279=1269=048=17359555=6SZ683=354406270=10201.0271=65346=111023=1010=237
1128=99=18035=X49=SAMPLE75=2016101134=293852=2009102705204518681427260=200910270520451868142725799=10000100268=1279=1269=048=17359555=6SZ683=354407270=10210.0271=2346=21023=110=056
1128=99=18135=X49=SAMPLE75=2016101134=413452=2008010420595688347705660=200801042059568834770565799=10000100268=1279=1269=148=17359555=6SZ683=354408270=10213.0271=22346=21023=110=112
1128=99=18335=X49=SAMPLE75=2016101134=162752=2012071122054649192064060=201207112205464919206405799=10000100268=1279=1269=048=17359555=6SZ683=354409270=10201.0271=35346=101023=1010=224
1128=99=18335=X49=SAMPLE75=2016101134=121552=2003060517420666628937660=200306051742066662893765799=10000100268=1279=1269=048=17359555=6SZ683=354410270=10201.0271=65346=111023=1010=205
1128=99=18335=X49=SAMPLE75=2016101134=226152=2008072711410023207616060=200807271141002320761605799=10000100268=1279=1269=048=17359555=6SZ683=354411270=10201.0271=35346=101023=1010=229
1128=99=18335=X49=SAMPLE75=2016101134=329152=2003113005543714913414460=200311300554371491341445799=10000100268=1279=1269=048=17359555=6SZ683=354412270=10201.0271=65346=111023=1010=231
1128=99=18335=X49=SAMPLE75=2016101134=361352=2006012107021456159667260=200601210702145615966725799=10000100268=1279=1269=048=17359555=6SZ683=354413270=10201.0271=35346=101023=1010=200
1128=99=18335=X49=SAMPLE75=2016101134=102652=2011080811454801821523260=201108081145480182152325799=10000100268=1279=1269=048=17359555=6SZ683=354414270=10201.0271=65346=111023=1010=223
1128=99=18335=X49=SAMPLE75=2016101134=401752=2009111501405319201728060=200911150140531920172805799=10000100268=1279=1269=048=17359555=6SZ683=354415270=10201.0271=35346=101023=1010=225
1128=99=18335=X49=SAMPLE75=2016101134=273652=2008091000082593470416060=200809100008259347041605799=10000100268=1279=1269=048=17359555=6SZ683=354416270=10201.0271=65346=111023=1010=238
1128=99=22035=X49=SAMPLE75=2016101134=174652=2003073107501477489702460=200307310750147748970245799=00000001268=1279=0269=248=17359555=6SZ683=354417270=10213.0271=1346=25797=137705=237=032=137=621180789248332=110=187
1128=99=15635=X49=SAMPLE75=2016101134=122352=2003032110001025856873660=200303211000102585687365799=00000010268=1279=0269=e48=17359555=6SZ683=354418271=1010=094
1128=99=18135=X49=SAMPLE75=2016101134=153652=2007090914563035695408060=200709091456303569540805799=00000100268=1279=1269=148=17359555=6SZ683=354419270=10213.0271=21346=21023=110=154
1128=99=16935=X49=SAMPLE75=2016101134=249752=2010112407232805619987260=201011240723280561998725799=10001000268=1279=0269=748=17359555=6SZ683=354420270=10213.0286=25510=155
1128=99=17935=X49=SAMPLE75=2016101134=472352=2013082508163883333145660=201308250816388333314565799=00000100268=1279=0269=048=17360055=6SH783=99022270=10264.0271=3346=11023=110=015
1128=99=16835=X49=SAMPLE75=2016101134=1152=2006071018241268593065660=200607101824126859306565799=10001000268=1279=0269=N48=17360055=6SH783=99023270=10264.0286=25510=091
1128=99=17935=X49=SAMPLE75=2016101134=473352=2009080101100789472832060=200908010110078947283205799=10000100268=1279=0269=048=17360055=6SH783=99024270=10263.0271=3346=11023=210=015
1128=99=25035=X49=SAMPLE75=2016101134=370352=2010020111465267619289660=201002011146526761928965799=10000100268=2279=2269=048=17360055=6SH783=99025270=10264.0271=3346=11023=1279=0269=048=17360055=6SH783=99026270=10254.0271=3346=11023=1010=011
1128=99=18135=X49=SAMPLE75=2016101134=182052=2000090501503111607950860=200009050150311160795085799=10000100268=1279=1269=048=17359555=6SZ683=354421270=10207.0271=30346=61023=410=114
1128=99=18335=X49=SAMPLE75=2016101134=346752=2007102719390412971225660=200710271939041297122565799=10000100268=1279=1269=048=17359555=6SZ683=354422270=10201.0271=35346=101023=1010=234
1128=99=18335=X49=SAMPLE75=2016101134=31052=2013051711594011098009660=201305171159401109800965799=10000100268=1279=1269=048=17359555=6SZ683=354423270=10201.0271=65346=111023=1010=217
1128=99=18335=X49=SAMPLE75=2016101134=7752=2014050907512951328819260=201405090751295132881925799=10000100268=1279=1269=048=17359555=6SZ683=354424270=10201.0271=35346=101023=1010=234
1128=99=18335=X49=SAMPLE75=2016101134=250052=2013080607195757433644860=201308060719575743364485799=10000100268=1279=1269=048=17359555=6SZ683=354425270=10201.0271=65346=111023=1010=213
1128=99=20835=X49=SAMPLE75=2016101134=410852=2010101100391094504064060=201010110039109450406405799=00000001268=1279=0269=248=17359555=6SZ683=354426270=10210.0271=1346=25797=237705=237=032=137=032=110=063
1128=99=15635=X49=SAMPLE75=2016101134=68452=2015081002362183239347260=201508100236218323934725799=00000010268=1279=0269=e48=17359555=6SZ683=354427271=1110=064
1128=99=18035=X49=SAMPLE75=2016101134=136552=2014082415063030261798460=201408241506303026179845799=00000100268=1279=1269=048=17359555=6SZ683=354428270=10210.0271=1346=11023=110=067
1128=99=16935=X49=SAMPLE75=2016101134=340952=2014070108534749549523260=201407010853474954952325799=10001000268=1279=0269=848=17359555=6SZ683=354429270=10210.0286=25510=131
1128=99=17935=X49=SAMPLE75=2016101134=46252=2014070605261506946982460=201407060526150694698245799=00000100268=1279=0269=148=17360055=6SH783=99027270=10268.0271=3346=11023=110=013
1128=99=16835=X49=SAMPLE75=2016101134=189652=2012042010360576466848060=201204201036057646684805799=10001000268=1279=0269=O48=17360055=6SH783=99028270=10268.0286=25510=089
1128=99=25235=X49=SAMPLE75=2016101134=363852=2001102018163299615584860=200110201816329961558485799=10000100268=2279=2269=048=17359555=6SZ683=354430270=10210.0271=1346=11023=1279=0269=048=17359555=6SZ683=354431270=10200.0271=1346=11023=1010=165
1128=99=25035=X49=SAMPLE75=2016101134=48452=2002012115371535461537660=200201211537153546153765799=10000100268=2279=2269=048=17360055=6SH783=99029270=10263.0271=3346=11023=1279=0269=048=17360055=6SH783=99030270=10253.0271=3346=11023=1010=039
1128=99=24935=X49=SAMPLE75=2016101134=5452=2002073000491017003876860=200207300049101700387685799=10000100268=2279=1269=148=17360355=6SM783=7539270=10351.0271=17346=21023=1279=2269=148=17360355=6SM783=7540270=10352.0271=15346=11023=210=004
1128=99=18035=X49=SAMPLE75=2016101134=321252=2006081004435399421596860=200608100443539942159685799=10000100268=1279=0269=048=17359555=6SZ683=354432270=10210.0271=1346=11023=110=080
1128=99=18135=X49=SAMPLE75=2016101134=452652=2013042816471242667161660=201304281647124266716165799=10000100268=1279=1269=048=17359555=6SZ683=354433270=10209.0271=22346=21023=210=160
1128=99=25035=X49=SAMPLE75=2016101134=324952=2012062211474414390220860=201206221147441439022085799=10000100268=2279=2269=148=17360055=6SH783=99031270=10268.0271=3346=11023=1279=0269=148=17360055=6SH783=99032270=10278.0271=3346=11023=1010=011
1128=99=18035=X49=SAMPLE75=2016101134=243652=2000050404541683617434660=200005040454168361743465799=10000100268=1279=1269=048=17359555=6SZ683=354434270=10210.0271=2346=21023=110=064
1128=99=18335=X49=SAMPLE75=2016101134=369752=2010052322293176118009660=201005232229317611800965799=10000100268=1279=1269=048=17359555=6SZ683=354435270=10201.0271=35346=101023=1010=210
1128=99=18335=X49=SAMPLE75=2016101134=497752=2000110200250820240471260=200011020025082024047125799=10000100268=1279=1269=048=17359555=6SZ683=354436270=10201.0271=65346=111023=1010=219
1128=99=18335=X49=SAMPLE75=2016101134=90152=2014011118482851935609660=201401111848285193560965799=10000100268=1279=1269=048=17359555=6SZ683=354437270=10201.0271=35346=101023=1010=243
1128=99=18335=X49=SAMPLE75=2016101134=266552=2008010613170046801913660=200801061317004680191365799=10000100268=1279=1269=048=17359555=6SZ683=354438270=10201.0271=65346=111023=1010=220
1128=99=18335=X49=SAMPLE75=2016101134=396652=2001092017333556615040060=200109201733355661504005799=10000100268=1279=1269=048=17359555=6SZ683=354439270=10201.0271=35346=101023=1010=001
1128=99=18335=X49=SAMPLE75=2016101134=382752=2007112308512539552268860=200711230851253955226885799=10000100268=1279=1269=048=17359555=6SZ683=354440270=10201.0271=65346=111023=1010=244
1128=99=18035=X49=SAMPLE75=2016101134=133752=2015092713495256616070460=201509271349525661607045799=10000100268=1279=1269=148=17359555=6SZ683=354441270=10216.0271=9346=31023=410=087
1128=99=18135=X49=SAMPLE75=2016101134=331052=2014070921160930639916860=201407092116093063991685799=10000100268=1279=1269=148=17359555=6SZ683=354442270=10216.0271=39346=41023=410=155
1128=99=18335=X49=SAMPLE75=2016101134=288152=2005090306291090509862460=200509030629109050986245799=10000100268=1279=1269=048=17359555=6SZ683=354443270=10201.0271=35346=101023=1010=231
1128=99=18135=X49=SAMPLE75=2016101134=26352=2006040217203539856400060=200604021720353985640005799=10000100268=1279=1269=048=17359555=6SZ683=354444270=10205.0271=48346=71023=610=173
1128=99=18035=X49=SAMPLE75=2016101134=100252=2010031122471076708524860=201003112247107670852485799=10000100268=1279=1269=048=17359555=6SZ683=354445270=10204.0271=1346=11023=710=092
1128=99=25335=X49=SAMPLE75=2016101134=234952=2001022514121223367816860=200102251412122336781685799=10000100268=2279=2269=148=17359555=6SZ683=354446270=10217.0271=30346=11023=5279=0269=148=17359555=6SZ683=354447270=10223.0271=6346=21023=1010=235
1128=99=18335=X49=SAMPLE75=2016101134=45552=2012052121541037758022460=201205212154103775802245799=10000100268=1279=1269=048=17359555=6SZ683=354448270=10201.0271=65346=111023=1010=249
1128=99=18135=X49=SAMPLE75=2016101134=66152=2015090904461841084857660=201509090446184108485765799=10000100268=1279=1269=048=17359555=6SZ683=354449270=10205.0271=18346=61023=610=154
1128=99=18135=X49=SAMPLE75=2016101134=252152=2002090813325256543452860=200209081332525654345285799=10000100268=1279=1269=148=17359555=6SZ683=354450270=10218.0271=31346=21023=510=150
1128=99=18135=X49=SAMPLE75=2016101134=181952=2007081007204492162451260=200708100720449216245125799=10000100268=1279=1269=048=17359555=6SZ683=354451270=10205.0271=48346=71023=610=159
1128=99=18035=X49=SAMPLE75=2016101134=133752=2009041118052487328019260=200904111805248732801925799=10000100268=1279=1269=148=17359555=6SZ683=354452270=10218.0271=1346=11023=510=071
1128=99=18135=X49=SAMPLE75=2016101134=157352=2016090222541857602163260=201609022254185760216325799=10000100268=1279=0269=148=17359555=6SZ683=354453270=10217.0271=30346=11023=510=128
1128=99=18335=X49=SAMPLE75=2016101134=402652=2012050405421546015609660=201205040542154601560965799=10000100268=1279=1269=048=17359555=6SZ683=354454270=10201.0271=35346=101023=1010=244
1128=99=18335=X49=SAMPLE75=2016101134=1752=2014061804314986609420860=201406180431498660942085799=10000100268=1279=1269=048=17359555=6SZ683=354455270=10201.0271=65346=111023=1010=248
1128=99=18335=X49=SAMPLE75=2016101134=53452=2011092823385184199200060=201109282338518419920005799=10000100268=1279=1269=048=17359555=6SZ683=354456270=10201.0271=35346=101023=1010=234
1128=99=18335=X49=SAMPLE75=2016101134=212752=2014101812124183228473660=201410181212418322847365799=10000100268=1279=1269=048=17359555=6SZ683=354457270=10201.0271=65346=111023=1010=250
1128=99=18335=X49=SAMPLE75=2016101134=49852=2010061123093159462713660=201006112309315946271365799=10000100268=1279=1269=048=17359555=6SZ683=354458270=10201.0271=35346=101023=1010=235
1128=99=18335=X49=SAMPLE75=2016101134=235052=2014053105410274994784060=201405310541027499478405799=10000100268=1279=1269=048=17359555=6SZ683=354459270=10201.0271=65346=111023=1010=238
1128=99=18335=X49=SAMPLE75=2016101134=91152=2009092215214378940748860=200909221521437894074885799=10000100268=1279=1269=048=17359555=6SZ683=354460270=10201.0271=66346=121023=1010=246
1128=99=18335=X49=SAMPLE75=2016101134=409452=2011031005245045855769660=201103100524504585576965799=10000100268=1279=1269=048=17359555=6SZ683=354461270=10201.0271=36346=111023=1010=243
1128=99=18335=X49=SAMPLE75=2016101134=395652=2005090406211897432739260=200509040621189743273925799=10000100268=1279=1269=048=17359555=6SZ683=354462270=10201.0271=66346=121023=1010=222
1128=99=25435=X49=SAMPLE75=2016101134=83852=2013020415570484379520060=201302041557048437952005799=10000100268=2279=2269=148=17359555=6SZ683=354463270=10222.0271=8346=11023=10279=0269=148=17359555=6SZ683=354464270=10223.0271=36346=31023=1010=025
1128=99=18335=X49=SAMPLE75=2016101134=391452=2014091210061095716089660=201409121006109571608965799=10000100268=1279=1269=048=17359555=6SZ683=354465270=10201.0271=58346=111023=1010=232
1128=99=18135=X49=SAMPLE75=2016101134=76352=2009070400114645255385660=200907040011464525538565799=10000100268=1279=1269=148=17359555=6SZ683=354466270=10220.0271=25346=41023=810=143
1128=99=18135=X49=SAMPLE75=2016101134=387552=2012032023531629188633660=201203202353162918863365799=10000100268=1279=1269=148=17359555=6SZ683=354467270=10223.0271=6346=21023=1010=169
1128=99=18235=X49=SAMPLE75=2016101134=393252=2009122203195257598060860=200912220319525759806085799=10000100268=1279=1269=148=17359555=6SZ683=354468270=10223.0271=36346=31023=1010=175
1128=99=18135=X49=SAMPLE75=2016101134=217052=2006040209465673751593660=200604020946567375159365799=10000100268=1279=1269=148=17359555=6SZ683=354469270=10223.0271=6346=21023=1010=147
1128=99=18235=X49=SAMPLE75=2016101134=85252=2005122807025466462931260=200512280702546646293125799=10000100268=1279=1269=148=17359555=6SZ683=354470270=10223.0271=36346=31023=1010=204
1128=99=18135=X49=SAMPLE75=2016101134=334452=2003060408552654095660860=200306040855265409566085799=10000100268=1279=1269=148=17359555=6SZ683=354471270=10223.0271=6346=21023=1010=153
1128=99=18235=X49=SAMPLE75=2016101134=351752=2011100114181518865260860=201110011418151886526085799=10000100268=1279=1269=148=17359555=6SZ683=354472270=10223.0271=36346=31023=1010=214
1128=99=18135=X49=SAMPLE75=2016101134=154452=2003062820460658184744060=200306282046065818474405799=10000100268=1279=1269=148=17359555=6SZ683=354473270=10223.0271=6346=21023=1010=155
1128=99=18335=X49=SAMPLE75=2016101134=488652=2001111120522446262280860=200111112052244626228085799=10000100268=1279=1269=048=17359555=6SZ683=354474270=10201.0271=28346=101023=1010=007
1128=99=18235=X49=SAMPLE75=2016101134=482252=2011062715274914117350460=201106271527491411735045799=10000100268=1279=1269=148=17359555=6SZ683=354475270=10223.0271=36346=31023=1010=218
1128=99=18335=X49=SAMPLE75=2016101134=484852=2004071319473651303889660=200407131947365130388965799=10000100268=1279=1269=048=17359555=6SZ683=354476270=10201.0271=58346=111023=1010=021
1128=99=18135=X49=SAMPLE75=2016101134=161452=2000112119065235262978460=200011211906523526297845799=10000100268=1279=1269=148=17359555=6SZ683=354477270=10223.0271=6346=21023=1010=160
1128=99=18335=X49=SAMPLE75=2016101134=83152=2008032304451536210435260=200803230445153621043525799=10000100268=1279=1269=048=17359555=6SZ683=354478270=10201.0271=28346=101023=1010=246
1128=99=18335=X49=SAMPLE75=2016101134=135452=2012030618085649515238460=201203061808564951523845799=10000100268=1279=1269=048=17359555=6SZ683=354479270=10201.0271=58346=111023=1010=008
1128=99=18035=X49=SAMPLE75=2016101134=71352=2010093013171627795123260=201009301317162779512325799=10000100268=1279=1269=148=17359555=6SZ683=354480270=10216.0271=9346=31023=410=130
1128=99=18235=X49=SAMPLE75=2016101134=334652=2005020705511131281756860=200502070551113128175685799=10000100268=1279=1269=148=17359555=6SZ683=354481270=10223.0271=36346=31023=1010=213
1128=99=18135=X49=SAMPLE75=2016101134=48352=2005100514534669973692860=200510051453466997369285799=10000100268=1279=1269=148=17359555=6SZ683=354482270=10216.0271=39346=41023=410=181
1128=99=18135=X49=SAMPLE75=2016101134=65852=2015080111293633699545660=201508011129363369954565799=10000100268=1279=1269=148=17359555=6SZ683=354483270=10223.0271=6346=21023=1010=170
1128=99=18235=X49=SAMPLE75=2016101134=247252=2010022213492379995929660=201002221349237999592965799=10000100268=1279=1269=148=17359555=6SZ683=354484270=10223.0271=36346=31023=1010=217
1128=99=18335=X49=SAMPLE75=2016101134=175752=2000060607572928874771260=200006060757292887477125799=10000100268=1279=1269=048=17359555=6SZ683=354485270=10201.0271=28346=101023=1010=014
1128=99=18335=X49=SAMPLE75=2016101134=212652=2000102623240904022211260=200010262324090402221125799=10000100268=1279=1269=048=17359555=6SZ683=354486270=10201.0271=58346=111023=1010=212
1128=99=18035=X49=SAMPLE75=2016101134=42652=2000100903431587922285660=200010090343158792228565799=10000100268=1279=1269=048=17359555=6SZ683=354487270=10207.0271=9346=51023=410=079
1128=99=18035=X49=SAMPLE75=2016101134=378752=2005112403420008134185660=200511240342000813418565799=10000100268=1279=1269=148=17359555=6SZ683=354488270=10214.0271=4346=41023=210=073
1128=99=18035=X49=SAMPLE75=2016101134=148552=2008060316151447448819260=200806031615144744881925799=10000100268=1279=1269=048=17359555=6SZ683=354489270=10209.0271=1346=11023=210=058
1128=99=18035=X49=SAMPLE75=2016101134=218552=2004100201135023528524860=200410020113502352852485799=10000100268=1279=1269=048=17359555=6SZ683=354490270=10208.0271=2346=11023=310=056
1128=99=18035=X49=SAMPLE75=2016101134=244052=2010030210453019472633660=201003021045301947263365799=10000100268=1279=1269=148=17359555=6SZ683=354491270=10213.0271=1346=11023=110=042
1128=99=18135=X49=SAMPLE75=2016101134=474852=2013041200091122967180860=201304120009112296718085799=10000100268=1279=1269=148=17359555=6SZ683=354492270=10215.0271=17346=61023=310=122
1128=99=25335=X49=SAMPLE75=2016101134=221252=2015111411261590388422460=201511141126159038842245799=10000100268=2279=2269=148=17359555=6SZ683=354493270=10213.0271=1346=11023=1279=0269=148=17359555=6SZ683=354494270=10225.0271=50346=81023=1010=182
1128=99=25035=X49=SAMPLE75=2016101134=131752=2009050617404883672844860=200905061740488367284485799=10000100268=2279=2269=148=17360055=6SH783=99033270=10269.0271=3346=11023=1279=0269=148=17360055=6SH783=99034270=10279.0271=3346=11023=1010=250
1128=99=18035=X49=SAMPLE75=2016101134=208552=2004082604355988539331260=200408260435598853933125799=10000100268=1279=0269=048=17359555=6SZ683=354495270=10211.0271=1346=11023=110=059
1128=99=18035=X49=SAMPLE75=2016101134=308552=2008050913575752612518460=200805091357575261251845799=10000100268=1279=1269=048=17359555=6SZ683=354496270=10208.0271=3346=21023=410=059
1128=99=25135=X49=SAMPLE75=2016101134=499352=2008121311284986771142460=200812131128498677114245799=10000100268=2279=2269=148=17360055=6SH783=99035270=10270.0271=3346=11023=1279=0269=148=17360055=6SH783=99036270=10280.0271=53346=11023=1010=058
1128=99=17935=X49=SAMPLE75=2016101134=499752=2013110403151301795660860=201311040315130179566085799=10000100268=1279=0269=048=17360055=6SH783=99037270=10264.0271=3346=11023=110=254
1128=99=18035=X49=SAMPLE75=2016101134=491052=2007113012050225545398460=200711301205022554539845799=10000100268=1279=1269=048=17359555=6SZ683=354497270=10210.0271=1346=11023=210=066
1128=99=17935=X49=SAMPLE75=2016101134=59252=2011012510095928545369660=201101251009592854536965799=10000100268=1279=0269=048=17360055=6SH783=99038270=10263.0271=3346=11023=210=243
1128=99=18035=X49=SAMPLE75=2016101134=108252=2010082201370099077843260=201008220137009907784325799=10000100268=1279=1269=048=17359555=6SZ683=354498270=10211.0271=2346=21023=110=047
1128=99=18035=X49=SAMPLE75=2016101134=258552=2007022706092626626720060=200702270609262662672005799=10000100268=1279=1269=148=17359555=6SZ683=354499270=10214.0271=5346=51023=110=083
1128=99=25035=X49=SAMPLE75=2016101134=394352=2009121906143796925004860=200912190614379692500485799=10000100268=2279=2269=048=17360055=6SH783=99039270=10264.0271=3346=11023=1279=0269=048=17360055=6SH783=99040270=10254.0271=3346=11023=1010=245
1128=99=18035=X49=SAMPLE75=2016101134=368152=2004102512323185721120060=200410251232318572112005799=10000100268=1279=1269=148=17359555=6SZ683=354500270=10223.0271=6346=21023=910=082
1128=99=18035=X49=SAMPLE75=2016101134=351352=2007042016380520203366460=200704201638052020336645799=10000100268=1279=1269=148=17359555=6SZ683=354501270=10216.0271=9346=31023=310=056
1128=99=18135=X49=SAMPLE75=2016101134=447652=2009091508543387806483260=200909150854338780648325799=10000100268=1279=1269=148=17359555=6SZ683=354502270=10223.0271=36346=31023=910=127
1128=99=18135=X49=SAMPLE75=2016101134=185952=2013062614590399946636860=201306261459039994663685799=10000100268=1279=1269=148=17359555=6SZ683=354503270=10216.0271=39346=41023=310=124
1128=99=18035=X49=SAMPLE75=2016101134=369852=2002021706550280301488060=200202170655028030148805799=10000100268=1279=1269=148=17359555=6SZ683=354504270=10223.0271=6346=21023=910=071
1128=99=18135=X49=SAMPLE75=2016101134=134952=2007110817390285222176060=200711081739028522217605799=10000100268=1279=1269=148=17359555=6SZ683=354505270=10223.0271=36346=31023=910=137
1128=99=18035=X49=SAMPLE75=2016101134=437852=2002031121345828294973660=200203112134582829497365799=10000100268=1279=1269=148=17359555=6SZ683=354506270=10223.0271=6346=21023=910=063
1128=99=18135=X49=SAMPLE75=2016101134=284852=2005040821124675718704060=200504082112467571870405799=10000100268=1279=1269=148=17359555=6SZ683=354507270=10223.0271=36346=31023=910=146
1128=99=18035=X49=SAMPLE75=2016101134=97852=2009071201495342070105660=200907120149534207010565799=10000100268=1279=1269=148=17359555=6SZ683=354508270=10223.0271=6346=21023=910=079
1128=99=18135=X49=SAMPLE75=2016101134=459252=2007032709175354778480060=200703270917535477848005799=10000100268=1279=1269=148=17359555=6SZ683=354509270=10223.0271=36346=31023=910=117
1128=99=18135=X49=SAMPLE75=2016101134=115052=2014041210431629224518460=201404121043162922451845799=10000100268=1279=1269=148=17359555=6SZ683=354510270=10220.0271=17346=31023=710=136
1128=99=18235=X49=SAMPLE75=2016101134=354752=2014053123320633757568060=201405312332063375756805799=10000100268=1279=1269=148=17359555=6SZ683=354511270=10225.0271=34346=71023=1010=183
1128=99=18035=X49=SAMPLE75=2016101134=457052=2012010820523022006227260=201201082052302200622725799=10000100268=1279=1269=148=17359555=6SZ683=354512270=10220.0271=9346=21023=710=087
1128=99=18235=X49=SAMPLE75=2016101134=461552=2002121513470209255336060=200212151347020925533605799=10000100268=1279=1269=148=17359555=6SZ683=354513270=10225.0271=18346=61023=1010=178
1128=99=18035=X49=SAMPLE75=2016101134=456952=2005111314160090266601660=200511131416009026660165799=10000100268=1279=1269=148=17359555=6SZ683=354514270=10220.0271=1346=11023=710=082
1128=99=18035=X49=SAMPLE75=2016101134=438352=2010022309582555570560060=201002230958255557056005799=10000100268=1279=1269=148=17359555=6SZ683=354515270=10223.0271=6346=21023=910=078
1128=99=18135=X49=SAMPLE75=2016101134=300252=2005031114454628610867260=200503111445462861086725799=10000100268=1279=1269=148=17359555=6SZ683=354516270=10223.0271=36346=31023=910=143
1128=99=18035=X49=SAMPLE75=2016101134=442852=2013091413412993759673660=201309141341299375967365799=10000100268=1279=1269=148=17359555=6SZ683=354517270=10223.0271=6346=21023=910=083
1128=99=18135=X49=SAMPLE75=2016101134=261052=2005011611095658035008060=200501161109565803500805799=10000100268=1279=1269=148=17359555=6SZ683=354518270=10223.0271=36346=31023=910=173
1128=99=18035=X49=SAMPLE75=2016101134=138252=2002012913300326045799260=200201291330032604579925799=10000100268=1279=0269=148=17359555=6SZ683=354519270=10213.0271=1346=11023=110=081
1128=99=18035=X49=SAMPLE75=2016101134=161352=2015101802042178297638460=201510180204217829763845799=10000100268=1279=1269=148=17359555=6SZ683=354520270=10213.0271=2346=21023=110=087
1128=99=17935=X49=SAMPLE75=2016101134=426752=2004102015061686212835260=200410201506168621283525799=10000100268=1279=0269=148=17360055=6SH783=99041270=10270.0271=3346=11023=110=029
1128=99=18135=X49=SAMPLE75=2016101134=50852=2009121914081679974214460=200912191408167997421445799=10000100268=1279=1269=148=17359555=6SZ683=354521270=10223.0271=6346=21023=1010=125
1128=99=18235=X49=SAMPLE75=2016101134=113352=2001012510172160812180460=200101251017216081218045799=10000100268=1279=1269=148=17359555=6SZ683=354522270=10223.0271=36346=31023=1010=192
1128=99=18135=X49=SAMPLE75=2016101134=292552=2002121918384076850262460=200212191838407685026245799=10000100268=1279=1269=148=17359555=6SZ683=354523270=10223.0271=6346=21023=1010=141
1128=99=18235=X49=SAMPLE75=2016101134=486852=2013080617030237831910460=201308061703023783191045799=10000100268=1279=1269=148=17359555=6SZ683=354524270=10223.0271=36346=31023=1010=192
1128=99=18035=X49=SAMPLE75=2016101134=324152=2015071503352202102566460=201507150335220210256645799=10000100268=1279=1269=048=17359555=6SZ683=354525270=10207.0271=8346=41023=510=092
1128=99=18135=X49=SAMPLE75=2016101134=350052=2009011211214921501916860=200901121121492150191685799=10000100268=1279=1269=148=17359555=6SZ683=354526270=10223.0271=6346=21023=1010=148
1128=99=18235=X49=SAMPLE75=2016101134=93952=2002012414462992175478460=200201241446299217547845799=10000100268=1279=1269=148=17359555=6SZ683=354527270=10223.0271=36346=31023=1010=200
1128=99=18135=X49=SAMPLE75=2016101134=66252=2015090113081979783155260=201509011308197978315525799=10000100268=1279=1269=148=17359555=6SZ683=354528270=10223.0271=6346=21023=1010=135
1128=99=18235=X49=SAMPLE75=2016101134=284352=2000120808404878621761660=200012080840487862176165799=10000100268=1279=1269=148=17359555=6SZ683=354529270=10223.0271=36346=31023=1010=183
1128=99=18135=X49=SAMPLE75=2016101134=180452=2011021309262313909241660=201102130926231390924165799=10000100268=1279=1269=148=17359555=6SZ683=354530270=10223.0271=6346=21023=1010=128
1128=99=18235=X49=SAMPLE75=2016101134=212552=2003070701462014776116860=200307070146201477611685799=10000100268=1279=1269=148=17359555=6SZ683=354531270=10223.0271=36346=31023=1010=165
1128=99=18035=X49=SAMPLE75=2016101134=322552=2009101300334470435584060=200910130033447043558405799=10000100268=1279=1269=148=17359555=6SZ683=354532270=10216.0271=9346=31023=410=084
1128=99=18135=X49=SAMPLE75=2016101134=468252=2011020507062116490342460=201102050706211649034245799=10000100268=1279=1269=148=17359555=6SZ683=354533270=10216.0271=39346=41023=410=153
1128=99=18035=X49=SAMPLE75=2016101134=187052=2011052317552311610272060=201105231755231161027205799=10000100268=1279=1269=148=17359555=6SZ683=354534270=10216.0271=9346=31023=410=096
1128=99=18135=X49=SAMPLE75=2016101134=80552=2005022104043629798604860=200502210404362979860485799=10000100268=1279=1269=148=17359555=6SZ683=354535270=10216.0271=39346=41023=410=155
1128=99=18135=X49=SAMPLE75=2016101134=58352=2013091611380908430758460=201309161138090843075845799=10000100268=1279=1269=148=17359555=6SZ683=354536270=10223.0271=6346=21023=1010=143
1128=99=18235=X49=SAMPLE75=2016101134=226052=2005053012222366477923260=200505301222236647792325799=10000100268=1279=1269=148=17359555=6SZ683=354537270=10223.0271=36346=31023=1010=185
1128=99=18035=X49=SAMPLE75=2016101134=302552=2001072402214981652816060=200107240221498165281605799=10000100268=1279=1269=048=17359555=6SZ683=354538270=10207.0271=9346=51023=510=077
1128=99=18135=X49=SAMPLE75=2016101134=439752=2009080213423616234784060=200908021342361623478405799=10000100268=1279=1269=148=17359555=6SZ683=354539270=10223.0271=6346=21023=1010=148
1128=99=18235=X49=SAMPLE75=2016101134=494052=2015080222151830952838460=201508022215183095283845799=10000100268=1279=1269=148=17359555=6SZ683=354540270=10223.0271=36346=31023=1010=196
1128=99=18135=X49=SAMPLE75=2016101134=455352=2012041203403653329561660=201204120340365332956165799=10000100268=1279=1269=148=17359555=6SZ683=354541270=10223.0271=6346=21023=1010=152
1128=99=18235=X49=SAMPLE75=2016101134=105252=2002010906402714939289660=200201090640271493928965799=10000100268=1279=1269=148=17359555=6SZ683=354542270=10223.0271=36346=31023=1010=218
1128=99=18135=X49=SAMPLE75=2016101134=20552=2005032606124218618390460=200503260612421861839045799=10000100268=1279=1269=148=17359555=6SZ683=354543270=10223.0271=6346=21023=1010=156
1128=99=18235=X49=SAMPLE75=2016101134=62852=2011050807105482453676860=201105080710548245367685799=10000100268=1279=1269=148=17359555=6SZ683=354544270=10223.0271=36346=31023=1010=227
1128=99=18135=X49=SAMPLE75=2016101134=318952=2016070408201532107904060=201607040820153210790405799=10000100268=1279=1269=148=17359555=6SZ683=354545270=10223.0271=6346=21023=1010=144
1128=99=18235=X49=SAMPLE75=2016101134=44652=2002020421214033543032060=200202042121403354303205799=10000100268=1279=1269=148=17359555=6SZ683=354546270=10223.0271=36346=31023=1010=185
1128=99=18135=X49=SAMPLE75=2016101134=340852=2015032213150489299481660=201503221315048929948165799=10000100268=1279=1269=148=17359555=6SZ683=354547270=10223.0271=6346=21023=1010=122
1128=99=18235=X49=SAMPLE75=2016101134=469852=2010022214160588041209660=201002221416058804120965799=10000100268=1279=1269=148=17359555=6SZ683=354548270=10223.0271=36346=31023=1010=171
1128=99=18135=X49=SAMPLE75=2016101134=480452=2003112221513886792878460=200311222151388679287845799=10000100268=1279=1269=148=17359555=6SZ683=354549270=10223.0271=6346=21023=1010=118
1128=99=18235=X49=SAMPLE75=2016101134=489352=2001042821295597121105660=200104282129559712110565799=10000100268=1279=1269=148=17359555=6SZ683=354550270=10223.0271=36346=31023=1010=179
1128=99=18135=X49=SAMPLE75=2016101134=450952=2013110205220803971827260=201311020522080397182725799=10000100268=1279=1269=148=17359555=6SZ683=354551270=10223.0271=6346=21023=1010=111
1128=99=18235=X49=SAMPLE75=2016101134=227652=2007020120465830283494460=200702012046583028349445799=10000100268=1279=1269=148=17359555=6SZ683=354552270=10223.0271=36346=31023=1010=207
1128=99=18135=X49=SAMPLE75=2016101134=350352=2009051007270283719955260=200905100727028371995525799=10000100268=1279=1269=148=17359555=6SZ683=354553270=10223.0271=6346=21023=1010=152
1128=99=18235=X49=SAMPLE75=2016101134=37252=2006062616164687759843260=200606261616468775984325799=10000100268=1279=1269=148=17359555=6SZ683=354554270=10223.0271=36346=31023=1010=190
1128=99=18135=X49=SAMPLE75=2016101134=166052=2008092820231597856336060=200809282023159785633605799=10000100268=1279=1269=148=17359555=6SZ683=354555270=10223.0271=6346=21023=1010=112
1128=99=18235=X49=SAMPLE75=2016101134=262052=2004063005230956528190460=200406300523095652819045799=10000100268=1279=1269=148=17359555=6SZ683=354556270=10223.0271=36346=31023=1010=181
1128=99=18135=X49=SAMPLE75=2016101134=199752=2008091617472281605248060=200809161747228160524805799=10000100268=1279=1269=148=17359555=6SZ683=354557270=10223.0271=6346=21023=1010=128
1128=99=18235=X49=SAMPLE75=2016101134=395652=2015080700363416371020860=201508070036341637102085799=10000100268=1279=1269=148=17359555=6SZ683=354558270=10223.0271=36346=31023=1010=182
1128=99=18035=X49=SAMPLE75=2016101134=59052=2014070421493534808460860=201407042149353480846085799=10000100268=1279=1269=048=17359555=6SZ683=354559270=10203.0271=1346=11023=910=087
1128=99=18135=X49=SAMPLE75=2016101134=230652=2008022621214861238985660=200802262121486123898565799=10000100268=1279=1269=048=17359555=6SZ683=354560270=10204.0271=31346=21023=810=114
1128=99=18135=X49=SAMPLE75=2016101134=169952=2012031911450585441196860=201203191145058544119685799=10000100268=1279=1269=148=17359555=6SZ683=354561270=10223.0271=6346=21023=1010=143
1128=99=18235=X49=SAMPLE75=2016101134=168052=2016102321412068411187260=201610232141206841118725799=10000100268=1279=1269=148=17359555=6SZ683=354562270=10223.0271=36346=31023=1010=210
1128=99=18135=X49=SAMPLE75=2016101134=473752=2006102716581362541603260=200610271658136254160325799=10000100268=1279=1269=148=17359555=6SZ683=354563270=10223.0271=6346=21023=1010=141
1128=99=18035=X49=SAMPLE75=2016101134=126152=2010031313564161812070460=201003131356416181207045799=10000100268=1279=1269=048=17359555=6SZ683=354564270=10204.0271=1346=11023=810=097
1128=99=18235=X49=SAMPLE75=2016101134=245252=2013112823103360790323260=201311282310336079032325799=10000100268=1279=1269=148=17359555=6SZ683=354565270=10223.0271=36346=31023=1010=195
1128=99=18135=X49=SAMPLE75=2016101134=29952=2001112417404001814131260=200111241740400181413125799=10000100268=1279=1269=048=17359555=6SZ683=354566270=10204.0271=31346=21023=810=149
1128=99=18135=X49=SAMPLE75=2016101134=250752=2008092706432231076713660=200809270643223107671365799=10000100268=1279=1269=148=17359555=6SZ683=354567270=10223.0271=6346=21023=1010=142
1128=99=18235=X49=SAMPLE75=2016101134=217052=2004102307551949774265660=200410230755194977426565799=10000100268=1279=1269=148=17359555=6SZ683=354568270=10223.0271=36346=31023=1010=201
1128=99=18035=X49=SAMPLE75=2016101134=39452=2006122512031481320374460=200612251203148132037445799=10000100268=1279=1269=048=17359555=6SZ683=354569270=10206.0271=1346=11023=610=099
1128=99=18135=X49=SAMPLE75=2016101134=150952=2016062122271898185017660=201606212227189818501765799=10000100268=1279=1269=148=17359555=6SZ683=354570270=10223.0271=6346=21023=1010=123
1128=99=18235=X49=SAMPLE75=2016101134=87452=2000071818393766104552460=200007181839376610455245799=10000100268=1279=1269=148=17359555=6SZ683=354571270=10223.0271=36346=31023=1010=176
1128=99=18135=X49=SAMPLE75=2016101134=477652=2010032908254472590905660=201003290825447259090565799=10000100268=1279=1269=148=17359555=6SZ683=354572270=10223.0271=6346=21023=1010=100
1128=99=18235=X49=SAMPLE75=2016101134=196952=2000012312555581562683760=200001231255558156268375799=10000100268=1279=1269=148=17359555=6SZ683=354573270=10223.0271=36346=31023=1010=171
1128=99=18035=X49=SAMPLE75=2016101134=165952=2014072007011378457561660=201407200701137845756165799=10000100268=1279=1269=148=17359555=6SZ683=354574270=10213.0271=1346=11023=110=045
1128=99=25335=X49=SAMPLE75=2016101134=292852=2003050901173008129662460=200305090117300812966245799=10000100268=2279=2269=148=17359555=6SZ683=354575270=10213.0271=1346=11023=1279=0269=148=17359555=6SZ683=354576270=10225.0271=18346=61023=1010=220
1128=99=25135=X49=SAMPLE75=2016101134=66052=2006111003364813527148860=200611100336481352714885799=10000100268=2279=2269=148=17360055=6SH783=99042270=10270.0271=3346=11023=1279=0269=148=17360055=6SH783=99043270=10280.0271=53346=11023=1010=057
1128=99=18035=X49=SAMPLE75=2016101134=189152=2001061901423770529240060=200106190142377052924005799=10000100268=1279=1269=148=17359555=6SZ683=354577270=10223.0271=6346=21023=910=079
1128=99=18135=X49=SAMPLE75=2016101134=201152=2015011010263097811360060=201501101026309781136005799=10000100268=1279=1269=148=17359555=6SZ683=354578270=10223.0271=36346=31023=910=148
1128=99=18035=X49=SAMPLE75=2016101134=76652=2014092601562094704160060=201409260156209470416005799=00000100268=1279=0269=048=17359555=6SZ683=354579270=10213.0271=1346=11023=110=080
1128=99=16935=X49=SAMPLE75=2016101134=215252=2014032823524517737536060=201403282352451773753605799=10001000268=1279=0269=N48=17359555=6SZ683=354580270=10213.0286=25510=158
1128=99=17935=X49=SAMPLE75=2016101134=13052=2005030710034361084531260=200503071003436108453125799=00000100268=1279=0269=048=17360055=6SH783=99044270=10265.0271=3346=11023=110=008
1128=99=16835=X49=SAMPLE75=2016101134=439152=2010030120522486415174460=201003012052248641517445799=10001000268=1279=0269=N48=17360055=6SH783=99045270=10265.0286=25510=084
1128=99=17935=X49=SAMPLE75=2016101134=7852=2002050722364360091153660=200205072236436009115365799=10000100268=1279=0269=048=17360055=6SH783=99046270=10264.0271=3346=11023=210=005
1128=99=18035=X49=SAMPLE75=2016101134=340352=2000082123094738506950460=200008212309473850695045799=10000100268=1279=1269=148=17359555=6SZ683=354581270=10223.0271=6346=21023=910=090
1128=99=18135=X49=SAMPLE75=2016101134=197252=2016012318141984194124860=201601231814198419412485799=10000100268=1279=1269=048=17359555=6SZ683=354582270=10205.0271=18346=61023=810=144
1128=99=18135=X49=SAMPLE75=2016101134=89652=2012022411131531944979260=201202241113153194497925799=10000100268=1279=1269=148=17359555=6SZ683=354583270=10223.0271=36346=31023=910=154
1128=99=18035=X49=SAMPLE75=2016101134=114452=2009052918485376662707260=200905291848537666270725799=10000100268=1279=1269=148=17359555=6SZ683=354584270=10223.0271=6346=21023=910=104
1128=99=18135=X49=SAMPLE75=2016101134=476452=2000040923272099735993560=200004092327209973599355799=10000100268=1279=1269=048=17359555=6SZ683=354585270=10205.0271=48346=71023=810=159
1128=99=18035=X49=SAMPLE75=2016101134=457452=2007031514133514920467260=200703151413351492046725799=10000100268=1279=1269=048=17359555=6SZ683=354586270=10204.0271=1346=11023=910=102
1128=99=18135=X49=SAMPLE75=2016101134=480252=2013120422421948407526460=201312042242194840752645799=10000100268=1279=1269=148=17359555=6SZ683=354587270=10223.0271=36346=31023=910=173
1128=99=18135=X49=SAMPLE75=2016101134=68252=2012082900241457702387260=201208290024145770238725799=10000100268=1279=1269=048=17359555=6SZ683=354588270=10205.0271=18346=61023=810=164
1128=99=18235=X49=SAMPLE75=2016101134=203452=2008090901524543040505660=200809090152454304050565799=10000100268=1279=1269=048=17359555=6SZ683=354589270=10203.0271=31346=21023=1010=213
1128=99=18135=X49=SAMPLE75=2016101134=193052=2010101305351571192569660=201010130535157119256965799=10000100268=1279=1269=048=17359555=6SZ683=354590270=10204.0271=31346=21023=910=147
1128=99=18035=X49=SAMPLE75=2016101134=499852=2002052323440161143832060=200205232344016114383205799=10000100268=1279=1269=048=17359555=6SZ683=354591270=10204.0271=1346=11023=910=096
1128=99=18135=X49=SAMPLE75=2016101134=480552=2002081805031053356248060=200208180503105335624805799=10000100268=1279=1269=048=17359555=6SZ683=354592270=10205.0271=48346=71023=810=160
1128=99=18035=X49=SAMPLE75=2016101134=428152=2014050308481179285132860=201405030848117928513285799=10000100268=1279=1269=148=17359555=6SZ683=354593270=10223.0271=6346=21023=910=106
1128=99=18135=X49=SAMPLE75=2016101134=93052=2003051019101659922201660=200305101910165992220165799=10000100268=1279=1269=148=17359555=6SZ683=354594270=10223.0271=36346=31023=910=166
1128=99=18035=X49=SAMPLE75=2016101134=339152=2015032704234535908934460=201503270423453590893445799=10000100268=1279=1269=148=17359555=6SZ683=354595270=10223.0271=6346=21023=910=116
1128=99=18135=X49=SAMPLE75=2016101134=151952=2013020821105239365811260=201302082110523936581125799=10000100268=1279=1269=148=17359555=6SZ683=354596270=10223.0271=36346=31023=910=141
1128=99=20835=X49=SAMPLE75=2016101134=49752=2010100620020044433299260=201010062002004443329925799=00000001268=1279=0269=248=17359555=6SZ683=354597270=10213.0271=1346=25797=237705=237=032=137=032=110=055
1128=99=15635=X49=SAMPLE75=2016101134=242852=2001120506300885426745660=200112050630088542674565799=00000010268=1279=0269=e48=17359555=6SZ683=354598271=1210=066
1128=99=25335=X49=SAMPLE75=2016101134=179352=2004030704551880962305660=200403070455188096230565799=10000100268=2279=2269=048=17359555=6SZ683=354599270=10213.0271=1346=11023=1279=0269=048=17359555=6SZ683=354600270=10202.0271=19346=71023=1010=209
1128=99=17935=X49=SAMPLE75=2016101134=362052=2003041709274736857337660=200304170927473685733765799=10000100268=1279=0269=148=17360055=6SH783=99047270=10269.0271=3346=11023=110=032
1128=99=18035=X49=SAMPLE75=2016101134=299652=2004032900270765728094460=200403290027076572809445799=10000100268=1279=0269=048=17359555=6SZ683=354601270=10212.0271=1346=11023=110=055
1128=99=25135=X49=SAMPLE75=2016101134=230052=2002111723103107134625660=200211172310310713462565799=10000100268=2279=2269=048=17360055=6SH783=99048270=10265.0271=3346=11023=1279=0269=048=17360055=6SH783=99049270=10255.0271=53346=21023=1010=081
1128=99=17935=X49=SAMPLE75=2016101134=73852=2006092904250196081168060=200609290425019608116805799=10000100268=1279=0269=148=17360055=6SH783=99050270=10270.0271=3346=11023=210=001
1128=99=25035=X49=SAMPLE75=2016101134=376152=2009010105413790769830460=200901010541379076983045799=10000100268=2279=2269=048=17360055=6SH783=99051270=10264.0271=3346=11023=1279=0269=048=17360055=6SH783=99052270=10254.0271=3346=11023=1010=011
1128=99=18035=X49=SAMPLE75=2016101134=484952=2006122911510452653737660=200612291151045265373765799=10000100268=1279=1269=048=17359555=6SZ683=354602270=10212.0271=2346=21023=110=070
1128=99=17935=X49=SAMPLE75=2016101134=446752=2011041505490496273542460=201104150549049627354245799=10000100268=1279=0269=048=17360055=6SH783=99053270=10264.0271=3346=11023=110=000
1128=99=25035=X49=SAMPLE75=2016101134=256752=2009022213560219720601660=200902221356021972060165799=10000100268=2279=2269=148=17360055=6SH783=99054270=10269.0271=3346=11023=1279=0269=148=17360055=6SH783=99055270=10279.0271=3346=11023=1010=031
1128=99=25135=X49=SAMPLE75=2016101134=454552=2011052013145250030297660=201105201314525003029765799=10000100268=2279=2269=148=17360055=6SH783=99056270=10270.0271=3346=11023=1279=0269=148=17360055=6SH783=99057270=10280.0271=53346=11023=1010=095
1128=99=18035=X49=SAMPLE75=2016101134=160852=2005101300061794970611260=200510130006179497061125799=10000100268=1279=1269=148=17359555=6SZ683=354603270=10223.0271=6346=21023=910=076
1128=99=18035=X49=SAMPLE75=2016101134=458252=2008053000474729621884860=200805300047472962188485799=10000100268=1279=1269=048=17359555=6SZ683=354604270=10208.0271=4346=31023=510=095
1128=99=18035=X49=SAMPLE75=2016101134=78152=2003122704013034612086460=200312270401303461208645799=10000100268=1279=1269=148=17359555=6SZ683=354605270=10214.0271=6346=61023=110=091
1128=99=17935=X49=SAMPLE75=2016101134=148052=2005080321431457604732860=200508032143145760473285799=10000100268=1279=0269=148=17360055=6SH783=99058270=10270.0271=3346=11023=110=018
1128=99=18135=X49=SAMPLE75=2016101134=46852=2012051605113644758521660=201205160511364475852165799=10000100268=1279=1269=148=17359555=6SZ683=354606270=10223.0271=36346=31023=910=154
1128=99=18035=X49=SAMPLE75=2016101134=145852=2003101614332807048897660=200310161433280704889765799=10000100268=1279=1269=148=17359555=6SZ683=354607270=10223.0271=6346=21023=910=104
1128=99=18135=X49=SAMPLE75=2016101134=5452=2001102701003847449401660=200110270100384744940165799=10000100268=1279=1269=148=17359555=6SZ683=354608270=10223.0271=36346=31023=910=165
1128=99=18035=X49=SAMPLE75=2016101134=202652=2012020809370589565427260=201202080937058956542725799=10000100268=1279=1269=148=17359555=6SZ683=354609270=10223.0271=6346=21023=910=095
1128=99=18135=X49=SAMPLE75=2016101134=467252=2011050205513347543091260=201105020551334754309125799=10000100268=1279=1269=148=17359555=6SZ683=354610270=10223.0271=36346=31023=910=160
1128=99=18035=X49=SAMPLE75=2016101134=449052=2017011303052951822566460=201701130305295182256645799=10000100268=1279=1269=148=17359555=6SZ683=354611270=10223.0271=6346=21023=910=076
1128=99=18135=X49=SAMPLE75=2016101134=165952=2014012118492915549574460=201401211849291554957445799=10000100268=1279=1269=148=17359555=6SZ683=354612270=10223.0271=36346=31023=910=101
1128=99=18035=X49=SAMPLE75=2016101134=307752=2000121518270463263499260=200012151827046326349925799=10000100268=1279=1269=148=17359555=6SZ683=354613270=10223.0271=6346=21023=910=080
1128=99=18135=X49=SAMPLE75=2016101134=105352=2016122413150158657248060=201612241315015865724805799=10000100268=1279=1269=148=17359555=6SZ683=354614270=10223.0271=36346=31023=910=133
1128=99=18035=X49=SAMPLE75=2016101134=121152=2009122616563590787686460=200912261656359078768645799=10000100268=1279=0269=148=17359555=6SZ683=354615270=10213.0271=1346=11023=110=080
1128=99=17935=X49=SAMPLE75=2016101134=30252=2017010323452524775936060=201701032345252477593605799=10000100268=1279=0269=148=17360055=6SH783=99059270=10269.0271=3346=11023=110=037
1128=99=25135=X49=SAMPLE75=2016101134=104752=2008021118102269836108860=200802111810226983610885799=10000100268=2279=1269=148=17359555=6SZ683=354616270=10213.0271=2346=21023=1279=1269=148=17359555=6SZ683=354617270=10214.0271=5346=51023=210=104
1128=99=25035=X49=SAMPLE75=2016101134=45752=2007100214484873042598460=200710021448487304259845799=10000100268=2279=2269=148=17360055=6SH783=99060270=10269.0271=3346=11023=1279=0269=148=17360055=6SH783=99061270=10279.0271=3346=11023=1010=049
1128=99=18035=X49=SAMPLE75=2016101134=438352=2003081616015550718945660=200308161601555071894565799=10000100268=1279=1269=048=17359555=6SZ683=354618270=10212.0271=1346=11023=110=082
1128=99=25335=X49=SAMPLE75=2016101134=348752=2005051216290509263728060=200505121629050926372805799=10000100268=2279=2269=048=17359555=6SZ683=354619270=10212.0271=1346=11023=1279=0269=048=17359555=6SZ683=354620270=10202.0271=19346=71023=1010=224
1128=99=18035=X49=SAMPLE75=2016101134=13252=2006102600180756592662460=200610260018075659266245799=10000100268=1279=1269=148=17359555=6SZ683=354621270=10213.0271=3346=31023=110=078
1128=99=25035=X49=SAMPLE75=2016101134=13052=2012011020020234251193660=201201102002023425119365799=10000100268=2279=2269=048=17360055=6SH783=99062270=10264.0271=3346=11023=1279=0269=048=17360055=6SH783=99063270=10254.0271=3346=11023=1010=024
1128=99=18135=X49=SAMPLE75=2016101134=313752=2009052401593678582969660=200905240159367858296965799=10000100268=1279=1269=148=17359555=6SZ683=354622270=10223.0271=6346=21023=1010=123
1128=99=18135=X49=SAMPLE75=2016101134=340152=2002060714444564808534460=200206071444456480853445799=10000100268=1279=1269=048=17359555=6SZ683=354623270=10204.0271=31346=21023=810=145
1128=99=18035=X49=SAMPLE75=2016101134=412052=2010122003550459877267260=201012200355045987726725799=10000100268=1279=1269=048=17359555=6SZ683=354624270=10203.0271=1346=11023=910=086
1128=99=18235=X49=SAMPLE75=2016101134=6552=2011091214225332940262460=201109121422533294026245799=10000100268=1279=1269=148=17359555=6SZ683=354625270=10223.0271=36346=31023=1010=195
1128=99=18035=X49=SAMPLE75=2016101134=253152=2010102505132136802163260=201010250513213680216325799=10000100268=1279=1269=048=17359555=6SZ683=354626270=10204.0271=1346=11023=810=084
1128=99=18135=X49=SAMPLE75=2016101134=408352=2011051603452218638470460=201105160345221863847045799=10000100268=1279=1269=148=17359555=6SZ683=354627270=10223.0271=6346=21023=1010=142
1128=99=18135=X49=SAMPLE75=2016101134=490452=2013021817402420913011260=201302181740242091301125799=10000100268=1279=1269=048=17359555=6SZ683=354628270=10204.0271=31346=21023=810=162
1128=99=18235=X49=SAMPLE75=2016101134=150752=2000122613355470312546460=200012261335547031254645799=10000100268=1279=1269=148=17359555=6SZ683=354629270=10223.0271=36346=31023=1010=205
1128=99=18135=X49=SAMPLE75=2016101134=86352=2001020418444928179921660=200102041844492817992165799=10000100268=1279=1269=148=17359555=6SZ683=354630270=10223.0271=6346=21023=1010=133
1128=99=18035=X49=SAMPLE75=2016101134=251552=2005072017271812740793660=200507201727181274079365799=10000100268=1279=1269=148=17359555=6SZ683=354631270=10213.0271=2346=21023=110=117
1128=99=18035=X49=SAMPLE75=2016101134=469252=2006092423371376129209660=200609242337137612920965799=10000100268=1279=1269=048=17359555=6SZ683=354632270=10204.0271=1346=11023=810=062
1128=99=18235=X49=SAMPLE75=2016101134=50852=2016012718452838413760060=201601271845283841376005799=10000100268=1279=1269=148=17359555=6SZ683=354633270=10223.0271=36346=31023=1010=168
1128=99=18135=X49=SAMPLE75=2016101134=133752=2009070805003635149529660=200907080500363514952965799=10000100268=1279=1269=048=17359555=6SZ683=354634270=10204.0271=31346=21023=810=138
1128=99=18235=X49=SAMPLE75=2016101134=96252=2014022513120742204889660=201402251312074220488965799=10000100268=1279=1269=048=17359555=6SZ683=354635270=10202.0271=49346=81023=1010=187
1128=99=18135=X49=SAMPLE75=2016101134=319852=2010021823061716663488060=201002182306171666348805799=10000100268=1279=1269=148=17359555=6SZ683=354636270=10223.0271=6346=21023=1010=121
1128=99=18235=X49=SAMPLE75=2016101134=218352=2002092616503112082353660=200209261650311208235365799=10000100268=1279=1269=148=17359555=6SZ683=354637270=10223.0271=36346=31023=1010=221
1128=99=18235=X49=SAMPLE75=2016101134=454952=2004092414183871937804860=200409241418387193780485799=10000100268=1279=1269=048=17359555=6SZ683=354638270=10202.0271=19346=71023=1010=194
1128=99=18135=X49=SAMPLE75=2016101134=241352=2003011320203513937283260=200301132020351393728325799=10000100268=1279=1269=148=17359555=6SZ683=354639270=10223.0271=6346=21023=1010=160
1128=99=18035=X49=SAMPLE75=2016101134=228452=2007040808524564535289660=200704080852456453528965799=10000100268=1279=1269=048=17359555=6SZ683=354640270=10204.0271=1346=11023=810=087
1128=99=18235=X49=SAMPLE75=2016101134=356152=2008012708513314736438460=200801270851331473643845799=10000100268=1279=1269=048=17359555=6SZ683=354641270=10202.0271=49346=81023=1010=200
1128=99=18235=X49=SAMPLE75=2016101134=219852=2010101304160396478144060=201010130416039647814405799=10000100268=1279=1269=148=17359555=6SZ683=354642270=10223.0271=36346=31023=1010=181
1128=99=18135=X49=SAMPLE75=2016101134=94952=2002080315020728132908860=200208031502072813290885799=10000100268=1279=1269=048=17359555=6SZ683=354643270=10204.0271=31346=21023=810=141
1128=99=18135=X49=SAMPLE75=2016101134=361152=2009081719315662381529660=200908171931566238152965799=10000100268=1279=1269=148=17359555=6SZ683=354644270=10223.0271=6346=21023=1010=130
1128=99=18235=X49=SAMPLE75=2016101134=29352=2006091711343810638444860=200609171134381063844485799=10000100268=1279=1269=148=17359555=6SZ683=354645270=10223.0271=36346=31023=1010=198
1128=99=18135=X49=SAMPLE75=2016101134=273252=2008122812373395709184060=200812281237339570918405799=10000100268=1279=1269=148=17359555=6SZ683=354646270=10223.0271=6346=21023=1010=157
1128=99=18235=X49=SAMPLE75=2016101134=339852=2011052002093591954950460=201105200209359195495045799=10000100268=1279=1269=148=17359555=6SZ683=354647270=10223.0271=36346=31023=1010=180
1128=99=18135=X49=SAMPLE75=2016101134=123752=2015052801490852440320060=201505280149085244032005799=10000100268=1279=1269=148=17359555=6SZ683=354648270=10223.0271=6346=21023=1010=158
1128=99=18235=X49=SAMPLE75=2016101134=143552=2004062320204038128214460=200406232020403812821445799=10000100268=1279=1269=148=17359555=6SZ683=354649270=10223.0271=36346=31023=1010=194
1128=99=18135=X49=SAMPLE75=2016101134=336852=2002031102001020393784060=200203110200102039378405799=10000100268=1279=1269=148=17359555=6SZ683=354650270=10223.0271=6346=21023=1010=128
1128=99=18235=X49=SAMPLE75=2016101134=155152=2003021218435679933144060=200302121843567993314405799=10000100268=1279=1269=148=17359555=6SZ683=354651270=10223.0271=36346=31023=1010=208
1128=99=18135=X49=SAMPLE75=2016101134=226652=2015122313411014839180860=201512231341101483918085799=10000100268=1279=1269=148=17359555=6SZ683=354652270=10223.0271=6346=21023=1010=148
1128=99=18235=X49=SAMPLE75=2016101134=175652=2000022617113585025903860=200002261711358502590385799=10000100268=1279=1269=148=17359555=6SZ683=354653270=10223.0271=36346=31023=1010=193
1128=99=18135=X49=SAMPLE75=2016101134=114052=2009080907375942487340860=200908090737594248734085799=10000100268=1279=1269=148=17359555=6SZ683=354654270=10223.0271=6346=21023=1010=157
1128=99=18235=X49=SAMPLE75=2016101134=11152=2005091400453320507219260=200509140045332050721925799=10000100268=1279=1269=048=17359555=6SZ683=354655270=10202.0271=19346=71023=1010=179
1128=99=18235=X49=SAMPLE75=2016101134=493652=2006102009331254253728060=200610200933125425372805799=10000100268=1279=1269=148=17359555=6SZ683=354656270=10223.0271=36346=31023=1010=216
1128=99=18235=X49=SAMPLE75=2016101134=497452=2007020413034458778304060=200702041303445877830405799=10000100268=1279=1269=048=17359555=6SZ683=354657270=10202.0271=49346=81023=1010=215
1128=99=18135=X49=SAMPLE75=2016101134=433252=2005110208311221549561660=200511020831122154956165799=10000100268=1279=1269=148=17359555=6SZ683=354658270=10223.0271=6346=21023=1010=150
1128=99=18235=X49=SAMPLE75=2016101134=303552=2009050522595892737529660=200905052259589273752965799=10000100268=1279=1269=148=17359555=6SZ683=354659270=10223.0271=36346=31023=1010=211
1128=99=18135=X49=SAMPLE75=2016101134=391152=2009033013455821994956860=200903301345582199495685799=10000100268=1279=1269=148=17359555=6SZ683=354660270=10223.0271=6346=21023=1010=131
1128=99=18235=X49=SAMPLE75=2016101134=84152=2010101514394037199750460=201010151439403719975045799=10000100268=1279=1269=148=17359555=6SZ683=354661270=10223.0271=36346=31023=1010=215
1128=99=18135=X49=SAMPLE75=2016101134=327152=2010120810524023847750460=201012081052402384775045799=10000100268=1279=1269=148=17359555=6SZ683=354662270=10223.0271=6346=21023=1010=143
1128=99=18235=X49=SAMPLE75=2016101134=25652=2011062105022519506265660=201106210502251950626565799=10000100268=1279=1269=148=17359555=6SZ683=354663270=10223.0271=36346=31023=1010=205
1128=99=18235=X49=SAMPLE75=2016101134=8552=2007070521235651020537660=200707052123565102053765799=10000100268=1279=1269=048=17359555=6SZ683=354664270=10202.0271=19346=71023=1010=203
1128=99=18135=X49=SAMPLE75=2016101134=20852=2005012915285607637923260=200501291528560763792325799=10000100268=1279=1269=148=17359555=6SZ683=354665270=10223.0271=6346=21023=1010=142
1128=99=18235=X49=SAMPLE75=2016101134=134152=2004042019013443160331260=200404201901344316033125799=10000100268=1279=1269=048=17359555=6SZ683=354666270=10202.0271=49346=81023=1010=192
1128=99=18235=X49=SAMPLE75=2016101134=329652=2003092313594377142803260=200309231359437714280325799=10000100268=1279=1269=148=17359555=6SZ683=354667270=10223.0271=36346=31023=1010=205
1128=99=18235=X49=SAMPLE75=2016101134=262152=2012030721465207605120060=201203072146520760512005799=10000100268=1279=1269=048=17359555=6SZ683=354668270=10202.0271=19346=71023=1010=209
1128=99=18235=X49=SAMPLE75=2016101134=69152=2015010410301450928108860=201501041030145092810885799=10000100268=1279=1269=048=17359555=6SZ683=354669270=10202.0271=49346=81023=1010=238
1128=99=18135=X49=SAMPLE75=2016101134=97952=2006052019453629021232060=200605201945362902123205799=10000100268=1279=1269=148=17359555=6SZ683=354670270=10223.0271=6346=21023=1010=172
1128=99=18235=X49=SAMPLE75=2016101134=64252=2017022115371669931699260=201702211537166993169925799=10000100268=1279=1269=148=17359555=6SZ683=354671270=10223.0271=36346=31023=1010=189
1128=99=18135=X49=SAMPLE75=2016101134=432152=2013041407055885811884860=201304140705588581188485799=10000100268=1279=1269=148=17359555=6SZ683=354672270=10223.0271=6346=21023=1010=161
1128=99=18235=X49=SAMPLE75=2016101134=280152=2006052902383280032236860=200605290238328003223685799=10000100268=1279=1269=148=17359555=6SZ683=354673270=10223.0271=36346=31023=1010=198
1128=99=18235=X49=SAMPLE75=2016101134=491152=2013122718285169735699260=201312271828516973569925799=10000100268=1279=1269=048=17359555=6SZ683=354674270=10202.0271=19346=71023=1010=185
1128=99=18135=X49=SAMPLE75=2016101134=336452=2006111203374835562748860=200611120337483556274885799=10000100268=1279=1269=148=17359555=6SZ683=354675270=10223.0271=6346=21023=1010=143
1128=99=18235=X49=SAMPLE75=2016101134=398752=2000032120421419852591060=200003212042141985259105799=10000100268=1279=1269=048=17359555=6SZ683=354676270=10202.0271=49346=81023=1010=215
1128=99=18235=X49=SAMPLE75=2016101134=305752=2001060817102190557605660=200106081710219055760565799=10000100268=1279=1269=148=17359555=6SZ683=354677270=10223.0271=36346=31023=1010=197
1128=99=18135=X49=SAMPLE75=2016101134=17952=2016053107435390950841660=201605310743539095084165799=10000100268=1279=1269=148=17359555=6SZ683=354678270=10223.0271=6346=21023=1010=178
1128=99=18235=X49=SAMPLE75=2016101134=362052=2001121522574525814104860=200112152257452581410485799=10000100268=1279=1269=048=17359555=6SZ683=354679270=10202.0271=19346=71023=1010=210
1128=99=18235=X49=SAMPLE75=2016101134=171152=2002110319322701666964860=200211031932270166696485799=10000100268=1279=1269=148=17359555=6SZ683=354680270=10223.0271=36346=31023=1010=223
1128=99=18235=X49=SAMPLE75=2016101134=118652=2000041322224597211947060=200004132222459721194705799=10000100268=1279=1269=048=17359555=6SZ683=354681270=10202.0271=49346=81023=1010=229
1128=99=18235=X49=SAMPLE75=2016101134=440952=2014070502161970953772860=201407050216197095377285799=10000100268=1279=1269=048=17359555=6SZ683=354682270=10202.0271=19346=71023=1010=220
1128=99=18135=X49=SAMPLE75=2016101134=297952=2009042614255454720857660=200904261425545472085765799=10000100268=1279=1269=148=17359555=6SZ683=354683270=10223.0271=6346=21023=1010=177
1128=99=18235=X49=SAMPLE75=2016101134=370252=2013011506522655466688060=201301150652265546668805799=10000100268=1279=1269=048=17359555=6SZ683=354684270=10202.0271=49346=81023=1010=224
1128=99=18235=X49=SAMPLE75=2016101134=367052=2015090215142620820915260=201509021514262082091525799=10000100268=1279=1269=148=17359555=6SZ683=354685270=10223.0271=36346=31023=1010=226
1128=99=18135=X49=SAMPLE75=2016101134=351052=2014022411254639369798460=201402241125463936979845799=10000100268=1279=1269=148=17359555=6SZ683=354686270=10223.0271=6346=21023=1010=176
1128=99=18235=X49=SAMPLE75=2016101134=71552=2006123007462842828425660=200612300746284282842565799=10000100268=1279=1269=048=17359555=6SZ683=354687270=10202.0271=19346=71023=1010=206
1128=99=18235=X49=SAMPLE75=2016101134=53052=2014032000244529528960060=201403200024452952896005799=10000100268=1279=1269=148=17359555=6SZ683=354688270=10223.0271=36346=31023=1010=230
1128=99=18235=X49=SAMPLE75=2016101134=159552=2005091305434016401961660=200509130543401640196165799=10000100268=1279=1269=048=17359555=6SZ683=354689270=10202.0271=49346=81023=1010=220
1128=99=18235=X49=SAMPLE75=2016101134=416852=2005020304421569007779260=200502030442156900777925799=10000100268=1279=1269=048=17359555=6SZ683=354690270=10202.0271=19346=71023=1010=181
1128=99=18135=X49=SAMPLE75=2016101134=159052=2008112909502735890256060=200811290950273589025605799=10000100268=1279=1269=148=17359555=6SZ683=354691270=10223.0271=6346=21023=1010=119
1128=99=18235=X49=SAMPLE75=2016101134=42052=2004120100083486489696060=200412010008348648969605799=10000100268=1279=1269=048=17359555=6SZ683=354692270=10202.0271=49346=81023=1010=181
1128=99=18235=X49=SAMPLE75=2016101134=467352=2008031909290458475292860=200803190929045847529285799=10000100268=1279=1269=148=17359555=6SZ683=354693270=10223.0271=36346=31023=1010=171
1128=99=18235=X49=SAMPLE75=2016101134=56952=2003120315362527178360060=200312031536252717836005799=10000100268=1279=1269=048=17359555=6SZ683=354694270=10202.0271=19346=71023=1010=176
1128=99=18135=X49=SAMPLE75=2016101134=230352=2013081410094937763193660=201308141009493776319365799=10000100268=1279=1269=148=17359555=6SZ683=354695270=10223.0271=6346=21023=1010=124
1128=99=18235=X49=SAMPLE75=2016101134=446152=2012112303023309717049660=201211230302330971704965799=10000100268=1279=1269=048=17359555=6SZ683=354696270=10202.0271=49346=81023=1010=190
1128=99=18235=X49=SAMPLE75=2016101134=111552=2003011314330863787033660=200301131433086378703365799=10000100268=1279=1269=148=17359555=6SZ683=354697270=10223.0271=36346=31023=1010=201
1128=99=18235=X49=SAMPLE75=2016101134=69352=2009040305204180538304060=200904030520418053830405799=10000100268=1279=1269=048=17359555=6SZ683=354698270=10202.0271=19346=71023=1010=173
1128=99=18135=X49=SAMPLE75=2016101134=498852=2010092619345528336998460=201009261934552833699845799=10000100268=1279=1269=148=17359555=6SZ683=354699270=10223.0271=6346=21023=1010=130
1128=99=18235=X49=SAMPLE75=2016101134=491852=2002091901101735590184060=200209190110173559018405799=10000100268=1279=1269=048=17359555=6SZ683=354700270=10202.0271=49346=81023=1010=165
1128=99=18235=X49=SAMPLE75=2016101134=66252=2013092419190850657516860=201309241919085065751685799=10000100268=1279=1269=148=17359555=6SZ683=354701270=10223.0271=36346=31023=1010=155
1128=99=18135=X49=SAMPLE75=2016101134=339552=2013091107545066347609660=201309110754506634760965799=10000100268=1279=1269=148=17359555=6SZ683=354702270=10223.0271=6346=21023=1010=131
1128=99=18235=X49=SAMPLE75=2016101134=91252=2014122821042931811360060=201412282104293181136005799=10000100268=1279=1269=148=17359555=6SZ683=354703270=10223.0271=36346=31023=1010=164
1128=99=18235=X49=SAMPLE75=2016101134=325652=2007122822592956711625660=200712282259295671162565799=10000100268=1279=1269=048=17359555=6SZ683=354704270=10202.0271=19346=71023=1010=188
1128=99=18135=X49=SAMPLE75=2016101134=297952=2011021106101871668972860=201102110610187166897285799=10000100268=1279=1269=148=17359555=6SZ683=354705270=10223.0271=6346=21023=1010=162
1128=99=18235=X49=SAMPLE75=2016101134=338052=2014112820255207429440060=201411282025520742944005799=10000100268=1279=1269=048=17359555=6SZ683=354706270=10202.0271=49346=81023=1010=221
1128=99=18235=X49=SAMPLE75=2016101134=321052=2014092404285294040044860=201409240428529404004485799=10000100268=1279=1269=148=17359555=6SZ683=354707270=10223.0271=36346=31023=1010=212
1128=99=18235=X49=SAMPLE75=2016101134=146852=2010082512314297403744060=201008251231429740374405799=10000100268=1279=1269=048=17359555=6SZ683=354708270=10202.0271=19346=71023=1010=200
1128=99=18135=X49=SAMPLE75=2016101134=217552=2014040419572446749376060=201404041957244674937605799=10000100268=1279=1269=148=17359555=6SZ683=354709270=10223.0271=6346=21023=1010=149
1128=99=18235=X49=SAMPLE75=2016101134=101452=2001070716242562525883260=200107071624256252588325799=10000100268=1279=1269=048=17359555=6SZ683=354710270=10202.0271=49346=81023=1010=219
1128=99=18235=X49=SAMPLE75=2016101134=463352=2014030119111023739577660=201403011911102373957765799=10000100268=1279=1269=148=17359555=6SZ683=354711270=10223.0271=36346=31023=1010=220
1128=99=18135=X49=SAMPLE75=2016101134=122252=2012091620021051041849660=201209162002105104184965799=10000100268=1279=1269=148=17359555=6SZ683=354712270=10223.0271=6346=21023=1010=147
1128=99=18235=X49=SAMPLE75=2016101134=85652=2015042809124024389689660=201504280912402438968965799=10000100268=1279=1269=148=17359555=6SZ683=354713270=10223.0271=36346=31023=1010=182
1128=99=18235=X49=SAMPLE75=2016101134=403952=2016061601212006914067260=201606160121200691406725799=10000100268=1279=1269=048=17359555=6SZ683=354714270=10202.0271=19346=71023=1010=196
1128=99=18135=X49=SAMPLE75=2016101134=395252=2004032503195912035440060=200403250319591203544005799=10000100268=1279=1269=148=17359555=6SZ683=354715270=10223.0271=6346=21023=1010=126
1128=99=18235=X49=SAMPLE75=2016101134=377652=2003101719563284718982460=200310171956328471898245799=10000100268=1279=1269=048=17359555=6SZ683=354716270=10202.0271=49346=81023=1010=171
1128=99=18235=X49=SAMPLE75=2016101134=486452=2015110622311083867680060=201511062231108386768005799=10000100268=1279=1269=148=17359555=6SZ683=354717270=10223.0271=36346=31023=1010=169
1128=99=18135=X49=SAMPLE75=2016101134=450052=2008111503115080999609660=200811150311508099960965799=10000100268=1279=1269=148=17359555=6SZ683=354718270=10223.0271=6346=21023=1010=134
1128=99=18235=X49=SAMPLE75=2016101134=408052=2003040406410650257708860=200304040641065025770885799=10000100268=1279=1269=148=17359555=6SZ683=354719270=10223.0271=36346=31023=1010=199
1128=99=18235=X49=SAMPLE75=2016101134=247852=2007080116130253612988860=200708011613025361298885799=10000100268=1279=1269=048=17359555=6SZ683=354720270=10202.0271=19346=71023=1010=183
1128=99=18135=X49=SAMPLE75=2016101134=2052=2006100305022447295174460=200610030502244729517445799=10000100268=1279=1269=148=17359555=6SZ683=354721270=10223.0271=6346=21023=1010=129
1128=99=18235=X49=SAMPLE75=2016101134=427752=2002122518210813429115260=200212251821081342911525799=10000100268=1279=1269=048=17359555=6SZ683=354722270=10202.0271=49346=81023=1010=191
1128=99=18235=X49=SAMPLE75=2016101134=132252=2010101114315289329472060=201010111431528932947205799=10000100268=1279=1269=148=17359555=6SZ683=354723270=10223.0271=36346=31023=1010=196
1128=99=18235=X49=SAMPLE75=2016101134=297052=2000052805561261887747060=200005280556126188774705799=10000100268=1279=1269=048=17359555=6SZ683=354724270=10202.0271=19346=71023=1010=166
1128=99=18135=X49=SAMPLE75=2016101134=471952=2000081716342320481140860=200008171634232048114085799=10000100268=1279=1269=148=17359555=6SZ683=354725270=10223.0271=6346=21023=1010=125
1128=99=18235=X49=SAMPLE75=2016101134=342252=2000022919593009705032560=200002291959300970503255799=10000100268=1279=1269=048=17359555=6SZ683=354726270=10202.0271=49346=81023=1010=181
1128=99=18235=X49=SAMPLE75=2016101134=410252=2016092810091078073926460=201609281009107807392645799=10000100268=1279=1269=148=17359555=6SZ683=354727270=10223.0271=36346=31023=1010=183
1128=99=18135=X49=SAMPLE75=2016101134=282252=2005052407514264350569660=200505240751426435056965799=10000100268=1279=1269=148=17359555=6SZ683=354728270=10223.0271=6346=21023=1010=151
1128=99=18235=X49=SAMPLE75=2016101134=98252=2012110116203513369164860=201211011620351336916485799=10000100268=1279=1269=048=17359555=6SZ683=354729270=10202.0271=19346=71023=1010=188
1128=99=18235=X49=SAMPLE75=2016101134=115552=2015021407541495008806460=201502140754149500880645799=10000100268=1279=1269=148=17359555=6SZ683=354730270=10223.0271=36346=31023=1010=193
1128=99=18235=X49=SAMPLE75=2016101134=240152=2012040610021229578835260=201204061002122957883525799=10000100268=1279=1269=048=17359555=6SZ683=354731270=10202.0271=49346=81023=1010=221
1128=99=18135=X49=SAMPLE75=2016101134=140652=2004060811593606046332860=200406081159360604633285799=10000100268=1279=1269=148=17359555=6SZ683=354732270=10223.0271=6346=21023=1010=138
1128=99=18235=X49=SAMPLE75=2016101134=321052=2001010501003509668504860=200101050100350966850485799=10000100268=1279=1269=048=17359555=6SZ683=354733270=10202.0271=19346=71023=1010=171
1128=99=18235=X49=SAMPLE75=2016101134=330152=2002122801273858593675260=200212280127385859367525799=10000100268=1279=1269=148=17359555=6SZ683=354734270=10223.0271=36346=31023=1010=203
1128=99=18235=X49=SAMPLE75=2016101134=297052=2000120405250404348448460=200012040525040434844845799=10000100268=1279=1269=048=17359555=6SZ683=354735270=10202.0271=49346=81023=1010=205
1128=99=18135=X49=SAMPLE75=2016101134=119652=2012070722331148291200060=201207072233114829120005799=10000100268=1279=1269=148=17359555=6SZ683=354736270=10223.0271=6346=21023=1010=147
1128=99=18235=X49=SAMPLE75=2016101134=311852=2016120122353923347884860=201612012235392334788485799=10000100268=1279=1269=048=17359555=6SZ683=354737270=10202.0271=19346=71023=1010=159
1128=99=18235=X49=SAMPLE75=2016101134=367252=2017021623054399955142460=201702162305439995514245799=10000100268=1279=1269=148=17359555=6SZ683=354738270=10223.0271=36346=31023=1010=205
1128=99=18235=X49=SAMPLE75=2016101134=134252=2015110609550084095052860=201511060955008409505285799=10000100268=1279=1269=048=17359555=6SZ683=354739270=10202.0271=49346=81023=1010=223
1128=99=18135=X49=SAMPLE75=2016101134=221852=2010022221092574881260860=201002222109257488126085799=10000100268=1279=1269=148=17359555=6SZ683=354740270=10223.0271=6346=21023=1010=143
1128=99=18035=X49=SAMPLE75=2016101134=460452=2005060119341536842889660=200506011934153684288965799=10000100268=1279=1269=048=17359555=6SZ683=354741270=10204.0271=1346=11023=810=081
1128=99=18235=X49=SAMPLE75=2016101134=469252=2016091806355303620192060=201609180635530362019205799=10000100268=1279=1269=148=17359555=6SZ683=354742270=10223.0271=36346=31023=1010=198
1128=99=18135=X49=SAMPLE75=2016101134=99352=2013011205341606440345660=201301120534160644034565799=10000100268=1279=1269=048=17359555=6SZ683=354743270=10204.0271=31346=21023=810=139
1128=99=18135=X49=SAMPLE75=2016101134=430952=2016102107493736791110460=201610210749373679111045799=10000100268=1279=1269=148=17359555=6SZ683=354744270=10223.0271=6346=21023=1010=139
1128=99=18235=X49=SAMPLE75=2016101134=308752=2005030615424109999516860=200503061542410999951685799=10000100268=1279=1269=148=17359555=6SZ683=354745270=10223.0271=36346=31023=1010=221
1128=99=18135=X49=SAMPLE75=2016101134=281152=2012031113591086216147260=201203111359108621614725799=10000100268=1279=1269=148=17359555=6SZ683=354746270=10223.0271=6346=21023=1010=154
1128=99=18235=X49=SAMPLE75=2016101134=237852=2013011611201452690355260=201301161120145269035525799=10000100268=1279=1269=048=17359555=6SZ683=354747270=10202.0271=19346=71023=1010=208
1128=99=18235=X49=SAMPLE75=2016101134=37552=2013102622155141933504060=201310262215514193350405799=10000100268=1279=1269=148=17359555=6SZ683=354748270=10223.0271=36346=31023=1010=216
1128=99=18235=X49=SAMPLE75=2016101134=464352=2002121809554795912526460=200212180955479591252645799=10000100268=1279=1269=048=17359555=6SZ683=354749270=10202.0271=49346=81023=1010=200
1128=99=18135=X49=SAMPLE75=2016101134=115952=2014082922150219146086460=201408292215021914608645799=10000100268=1279=1269=148=17359555=6SZ683=354750270=10223.0271=6346=21023=1010=126
1128=99=18235=X49=SAMPLE75=2016101134=426152=2015030703032797803955260=201503070303279780395525799=10000100268=1279=1269=148=17359555=6SZ683=354751270=10223.0271=36346=31023=1010=196
1128=99=18135=X49=SAMPLE75=2016101134=5152=2001081221203208162979260=200108122120320816297925799=10000100268=1279=1269=148=17359555=6SZ683=354752270=10223.0271=6346=21023=1010=153
1128=99=18235=X49=SAMPLE75=2016101134=249552=2010041700325128713638460=201004170032512871363845799=10000100268=1279=1269=148=17359555=6SZ683=354753270=10223.0271=36346=31023=1010=194
1128=99=18135=X49=SAMPLE75=2016101134=366552=2013060100393139047724860=201306010039313904772485799=10000100268=1279=1269=148=17359555=6SZ683=354754270=10223.0271=6346=21023=1010=156
1128=99=18235=X49=SAMPLE75=2016101134=306552=2005060221052637841436860=200506022105263784143685799=10000100268=1279=1269=048=17359555=6SZ683=354755270=10202.0271=19346=71023=1010=199
1128=99=18235=X49=SAMPLE75=2016101134=488752=2008051915440837224195260=200805191544083722419525799=10000100268=1279=1269=148=17359555=6SZ683=354756270=10223.0271=36346=31023=1010=197
1128=99=18235=X49=SAMPLE75=2016101134=230252=2007101722231687360656060=200710172223168736065605799=10000100268=1279=1269=048=17359555=6SZ683=354757270=10202.0271=49346=81023=1010=199
1128=99=18135=X49=SAMPLE75=2016101134=191952=2011070720392292775398460=201107072039229277539845799=10000100268=1279=1269=148=17359555=6SZ683=354758270=10223.0271=6346=21023=1010=147
1128=99=18235=X49=SAMPLE75=2016101134=242752=2007080316115582329648060=200708031611558232964805799=10000100268=1279=1269=048=17359555=6SZ683=354759270=10202.0271=19346=71023=1010=179
1128=99=18235=X49=SAMPLE75=2016101134=329452=2009082016445003523878460=200908201644500352387845799=10000100268=1279=1269=148=17359555=6SZ683=354760270=10223.0271=36346=31023=1010=204
1128=99=18235=X49=SAMPLE75=2016101134=231652=2010081204140110271782460=201008120414011027178245799=10000100268=1279=1269=048=17359555=6SZ683=354761270=10202.0271=49346=81023=1010=195
1128=99=18135=X49=SAMPLE75=2016101134=311252=2012010918362560733273660=201201091836256073327365799=10000100268=1279=1269=048=17359555=6SZ683=354762270=10207.0271=12346=61023=510=145
1128=99=18135=X49=SAMPLE75=2016101134=287652=2009012801501464758041660=200901280150146475804165799=10000100268=1279=1269=148=17359555=6SZ683=354763270=10219.0271=19346=71023=710=160
1128=99=18135=X49=SAMPLE75=2016101134=392052=2012083015485962137081660=201208301548596213708165799=10000100268=1279=1269=148=17359555=6SZ683=354764270=10223.0271=6346=21023=1010=146
1128=99=18235=X49=SAMPLE75=2016101134=11652=2001060205343922283242460=200106020534392228324245799=10000100268=1279=1269=048=17359555=6SZ683=354765270=10202.0271=19346=71023=1010=223
1128=99=18235=X49=SAMPLE75=2016101134=131652=2007092123101250828716860=200709212310125082871685799=10000100268=1279=1269=148=17359555=6SZ683=354766270=10223.0271=36346=31023=1010=201
1128=99=18235=X49=SAMPLE75=2016101134=179352=2002030223282137827471260=200203022328213782747125799=10000100268=1279=1269=048=17359555=6SZ683=354767270=10202.0271=49346=81023=1010=221
1128=99=18235=X49=SAMPLE75=2016101134=319252=2013081509545859641798460=201308150954585964179845799=10000100268=1279=1269=048=17359555=6SZ683=354768270=10202.0271=19346=71023=1010=194
1128=99=18235=X49=SAMPLE75=2016101134=235652=2011071720332888049542460=201107172033288804954245799=10000100268=1279=1269=048=17359555=6SZ683=354769270=10202.0271=49346=81023=1010=173
1128=99=18135=X49=SAMPLE75=2016101134=470752=2007021621112793696496060=200702162111279369649605799=10000100268=1279=1269=148=17359555=6SZ683=354770270=10223.0271=6346=21023=1010=143
1128=99=18235=X49=SAMPLE75=2016101134=42652=2013060419315430771750460=201306041931543077175045799=10000100268=1279=1269=148=17359555=6SZ683=354771270=10223.0271=36346=31023=1010=192
1128=99=18135=X49=SAMPLE75=2016101134=136552=2005090202031659458752060=200509020203165945875205799=10000100268=1279=1269=148=17359555=6SZ683=354772270=10223.0271=6346=21023=1010=132
1128=99=18235=X49=SAMPLE75=2016101134=155252=2014111703380663338976060=201411170338066333897605799=10000100268=1279=1269=148=17359555=6SZ683=354773270=10223.0271=36346=31023=1010=182
1128=99=18135=X49=SAMPLE75=2016101134=344852=2000022001471460403888060=200002200147146040388805799=10000100268=1279=1269=148=17359555=6SZ683=354774270=10223.0271=6346=21023=1010=148
1128=99=18235=X49=SAMPLE75=2016101134=285352=2003090113135999812417660=200309011313599981241765799=10000100268=1279=1269=048=17359555=6SZ683=354775270=10202.0271=19346=71023=1010=200
1128=99=18235=X49=SAMPLE75=2016101134=84552=2016121107452199647398460=201612110745219964739845799=10000100268=1279=1269=148=17359555=6SZ683=354776270=10223.0271=36346=31023=1010=199
1128=99=18235=X49=SAMPLE75=2016101134=100452=2005033012413330785424060=200503301241333078542405799=10000100268=1279=1269=048=17359555=6SZ683=354777270=10202.0271=49346=81023=1010=210
1128=99=18135=X49=SAMPLE75=2016101134=90352=2001041012114605830073660=200104101211460583007365799=10000100268=1279=1269=148=17359555=6SZ683=354778270=10219.0271=27346=81023=710=157
1128=99=18135=X49=SAMPLE75=2016101134=42052=2007012502363752143750460=200701250236375214375045799=10000100268=1279=1269=148=17359555=6SZ683=354779270=10221.0271=18346=51023=910=167
1128=99=18135=X49=SAMPLE75=2016101134=304352=2005032911285763451792060=200503291128576345179205799=10000100268=1279=1269=148=17359555=6SZ683=354780270=10223.0271=6346=21023=1010=165
1128=99=18235=X49=SAMPLE75=2016101134=464852=2006042415064445860022460=200604241506444586002245799=10000100268=1279=1269=148=17359555=6SZ683=354781270=10223.0271=36346=31023=1010=224
1128=99=18135=X49=SAMPLE75=2016101134=215252=2006020915295063658707260=200602091529506365870725799=10000100268=1279=1269=148=17359555=6SZ683=354782270=10223.0271=6346=21023=1010=141
1128=99=18235=X49=SAMPLE75=2016101134=294952=2009112902471554051392060=200911290247155405139205799=10000100268=1279=1269=148=17359555=6SZ683=354783270=10223.0271=36346=31023=1010=201
1128=99=18135=X49=SAMPLE75=2016101134=63052=2009071522373340042092860=200907152237334004209285799=10000100268=1279=1269=148=17359555=6SZ683=354784270=10223.0271=6346=21023=1010=148
1128=99=18235=X49=SAMPLE75=2016101134=390352=2014091513483068709779260=201409151348306870977925799=10000100268=1279=1269=048=17359555=6SZ683=354785270=10202.0271=19346=71023=1010=214
1128=99=18235=X49=SAMPLE75=2016101134=360252=2006120419025922976528060=200612041902592297652805799=10000100268=1279=1269=148=17359555=6SZ683=354786270=10223.0271=36346=31023=1010=199
1128=99=18235=X49=SAMPLE75=2016101134=102752=2006070921434654430051260=200607092143465443005125799=10000100268=1279=1269=048=17359555=6SZ683=354787270=10202.0271=49346=81023=1010=208
1128=99=18135=X49=SAMPLE75=2016101134=335652=2005101606383272450416060=200510160638327245041605799=10000100268=1279=1269=148=17359555=6SZ683=354788270=10223.0271=6346=21023=1010=164
1128=99=18235=X49=SAMPLE75=2016101134=284752=2009031905371395599379260=200903190537139559937925799=10000100268=1279=1269=048=17359555=6SZ683=354789270=10202.0271=19346=71023=1010=225
1128=99=18235=X49=SAMPLE75=2016101134=97052=2004060112165843540187260=200406011216584354018725799=10000100268=1279=1269=148=17359555=6SZ683=354790270=10223.0271=36346=31023=1010=213
1128=99=18235=X49=SAMPLE75=2016101134=375252=2014082411375659433286460=201408241137565943328645799=10000100268=1279=1269=048=17359555=6SZ683=354791270=10202.0271=49346=81023=1010=196
1128=99=18135=X49=SAMPLE75=2016101134=118452=2011020608515858158515260=201102060851585815851525799=10000100268=1279=1269=148=17359555=6SZ683=354792270=10223.0271=6346=21023=1010=152
1128=99=18235=X49=SAMPLE75=2016101134=183352=2005081811141751366608060=200508181114175136660805799=10000100268=1279=1269=048=17359555=6SZ683=354793270=10202.0271=19346=71023=1010=188
1128=99=18235=X49=SAMPLE75=2016101134=442652=2014031406520923538092860=201403140652092353809285799=10000100268=1279=1269=148=17359555=6SZ683=354794270=10223.0271=36346=31023=1010=216
1128=99=18235=X49=SAMPLE75=2016101134=102952=2016030304285108451795260=201603030428510845179525799=10000100268=1279=1269=048=17359555=6SZ683=354795270=10202.0271=49346=81023=1010=211
1128=99=18135=X49=SAMPLE75=2016101134=316452=2009011100261582357331260=200901110026158235733125799=10000100268=1279=1269=148=17359555=6SZ683=354796270=10223.0271=6346=21023=1010=157
1128=99=18235=X49=SAMPLE75=2016101134=87752=2012013118003274855776060=201201311800327485577605799=10000100268=1279=1269=048=17359555=6SZ683=354797270=10202.0271=19346=71023=1010=214
1128=99=18235=X49=SAMPLE75=2016101134=15452=2001021612091543431173260=200102161209154343117325799=10000100268=1279=1269=148=17359555=6SZ683=354798270=10223.0271=36346=31023=1010=202
1128=99=18235=X49=SAMPLE75=2016101134=422252=2008040310515421498003260=200804031051542149800325799=10000100268=1279=1269=048=17359555=6SZ683=354799270=10202.0271=49346=81023=1010=202
1128=99=18135=X49=SAMPLE75=2016101134=491752=2009112800390561552844860=200911280039056155284485799=10000100268=1279=1269=148=17359555=6SZ683=354800270=10223.0271=6346=21023=1010=158
1128=99=18235=X49=SAMPLE75=2016101134=376052=2002062806484753755164860=200206280648475375516485799=10000100268=1279=1269=048=17359555=6SZ683=354801270=10202.0271=19346=71023=1010=194
1128=99=18235=X49=SAMPLE75=2016101134=21352=2003031107242586147264060=200303110724258614726405799=10000100268=1279=1269=148=17359555=6SZ683=354802270=10223.0271=36346=31023=1010=231
1128=99=18235=X49=SAMPLE75=2016101134=276552=2009062308583317003577660=200906230858331700357765799=10000100268=1279=1269=048=17359555=6SZ683=354803270=10202.0271=49346=81023=1010=248
1128=99=18235=X49=SAMPLE75=2016101134=5152=2013051212080876000403260=201305121208087600040325799=10000100268=1279=1269=048=17359555=6SZ683=354804270=10202.0271=19346=71023=1010=212
1128=99=18235=X49=SAMPLE75=2016101134=431152=2004081106083958159577660=200408110608395815957765799=10000100268=1279=1269=048=17359555=6SZ683=354805270=10202.0271=49346=81023=1010=232
1128=99=18235=X49=SAMPLE75=2016101134=372652=2005050602530749113657660=200505060253074911365765799=10000100268=1279=1269=048=17359555=6SZ683=354806270=10202.0271=19346=71023=1010=210
1128=99=18135=X49=SAMPLE75=2016101134=415152=2008081223274306808585660=200808122327430680858565799=10000100268=1279=1269=148=17359555=6SZ683=354807270=10223.0271=6346=21023=1010=134
1128=99=18235=X49=SAMPLE75=2016101134=462852=2011111410063035858905660=201111141006303585890565799=10000100268=1279=1269=048=17359555=6SZ683=354808270=10202.0271=49346=81023=1010=198
1128=99=18235=X49=SAMPLE75=2016101134=490352=2007080221561532045708860=200708022156153204570885799=10000100268=1279=1269=148=17359555=6SZ683=354809270=10223.0271=36346=31023=1010=190
1128=99=17935=X49=SAMPLE75=2016101134=350952=2014112607113270321881660=201411260711327032188165799=10000100268=1279=1269=048=17360055=6SH783=99064270=10260.0271=5346=21023=410=034
1128=99=17935=X49=SAMPLE75=2016101134=181352=2001042709102889667031260=200104270910288966703125799=10000100268=1279=1269=048=17360055=6SH783=99065270=10259.0271=5346=21023=510=058
1128=99=17935=X49=SAMPLE75=2016101134=487252=2008011502195789397529660=200801150219578939752965799=10000100268=1279=1269=148=17360055=6SH783=99066270=10271.0271=5346=21023=210=040
1128=99=17935=X49=SAMPLE75=2016101134=146652=2005090910380935681494460=200509091038093568149445799=10000100268=1279=1269=148=17360055=6SH783=99067270=10272.0271=5346=21023=310=058
1128=99=18235=X49=SAMPLE75=2016101134=317652=2004122121551373917139260=200412212155137391713925799=10000100268=1279=1269=048=17359555=6SZ683=354810270=10202.0271=19346=71023=1010=210
1128=99=18235=X49=SAMPLE75=2016101134=211652=2016091703540458373145660=201609170354045837314565799=10000100268=1279=1269=048=17359555=6SZ683=354811270=10202.0271=49346=81023=1010=234
1128=99=18135=X49=SAMPLE75=2016101134=45152=2010041300503066388992060=201004130050306638899205799=10000100268=1279=1269=148=17359555=6SZ683=354812270=10223.0271=6346=21023=1010=165
1128=99=18235=X49=SAMPLE75=2016101134=349752=2011071113352709071942460=201107111335270907194245799=10000100268=1279=1269=048=17359555=6SZ683=354813270=10202.0271=19346=71023=1010=209
1128=99=18235=X49=SAMPLE75=2016101134=277452=2000110103422273522647260=200011010342227352264725799=10000100268=1279=1269=148=17359555=6SZ683=354814270=10223.0271=36346=31023=1010=217
1128=99=18235=X49=SAMPLE75=2016101134=141452=2005021514510655258028860=200502151451065525802885799=10000100268=1279=1269=048=17359555=6SZ683=354815270=10202.0271=49346=81023=1010=214
1128=99=18135=X49=SAMPLE75=2016101134=65952=2002013016192457616787260=200201301619245761678725799=10000100268=1279=1269=148=17359555=6SZ683=354816270=10223.0271=6346=21023=1010=145
1128=99=18235=X49=SAMPLE75=2016101134=415352=2007052815402465582358460=200705281540246558235845799=10000100268=1279=1269=148=17359555=6SZ683=354817270=10223.0271=36346=31023=1010=195
1128=99=18135=X49=SAMPLE75=2016101134=19452=2013070118471536142944060=201307011847153614294405799=10000100268=1279=1269=148=17359555=6SZ683=354818270=10223.0271=6346=21023=1010=146
1128=99=18235=X49=SAMPLE75=2016101134=276652=2008041312445771469376060=200804131244577146937605799=10000100268=1279=1269=148=17359555=6SZ683=354819270=10223.0271=36346=31023=1010=197
1128=99=18135=X49=SAMPLE75=2016101134=26752=2010062522104849467769660=201006252210484946776965799=10000100268=1279=1269=148=17359555=6SZ683=354820270=10223.0271=6346=21023=1010=150
1128=99=18235=X49=SAMPLE75=2016101134=2152=2002102900481535454648060=200210290048153545464805799=10000100268=1279=1269=148=17359555=6SZ683=354821270=10223.0271=36346=31023=1010=188
1128=99=18135=X49=SAMPLE75=2016101134=347952=2011101923224940336038460=201110192322494033603845799=10000100268=1279=1269=148=17359555=6SZ683=354822270=10223.0271=6346=21023=1010=157
1128=99=18235=X49=SAMPLE75=2016101134=249252=2015112414510883523494460=201511241451088352349445799=10000100268=1279=1269=148=17359555=6SZ683=354823270=10223.0271=36346=31023=1010=206
1128=99=18135=X49=SAMPLE75=2016101134=274252=2000052403490900766733460=200005240349090076673345799=10000100268=1279=1269=148=17359555=6SZ683=354824270=10223.0271=6346=21023=1010=122
1128=99=18235=X49=SAMPLE75=2016101134=154152=2016121213353514995564860=201612121335351499556485799=10000100268=1279=1269=048=17359555=6SZ683=354825270=10202.0271=19346=71023=1010=215
1128=99=18235=X49=SAMPLE75=2016101134=40752=2008081911095072065680060=200808191109507206568005799=10000100268=1279=1269=148=17359555=6SZ683=354826270=10223.0271=36346=31023=1010=189
1128=99=18235=X49=SAMPLE75=2016101134=251152=2015091708555192886745660=201509170855519288674565799=10000100268=1279=1269=048=17359555=6SZ683=354827270=10202.0271=49346=81023=1010=204
1128=99=18135=X49=SAMPLE75=2016101134=112352=2005050317572965279497660=200505031757296527949765799=10000100268=1279=1269=148=17359555=6SZ683=354828270=10223.0271=6346=21023=1010=137
1128=99=18235=X49=SAMPLE75=2016101134=158452=2008080910214925552787260=200808091021492555278725799=10000100268=1279=1269=048=17359555=6SZ683=354829270=10202.0271=19346=71023=1010=221
1128=99=18235=X49=SAMPLE75=2016101134=469952=2010032618145598287782460=201003261814559828778245799=10000100268=1279=1269=148=17359555=6SZ683=354830270=10223.0271=36346=31023=1010=197
1128=99=18235=X49=SAMPLE75=2016101134=102352=2013032407224644098886460=201303240722464409888645799=10000100268=1279=1269=048=17359555=6SZ683=354831270=10202.0271=49346=81023=1010=194
1128=99=18135=X49=SAMPLE75=2016101134=490252=2003121807500152430054460=200312180750015243005445799=10000100268=1279=1269=148=17359555=6SZ683=354832270=10223.0271=6346=21023=1010=142
1128=99=18235=X49=SAMPLE75=2016101134=121552=2016082313225727508083260=201608231322572750808325799=10000100268=1279=1269=048=17359555=6SZ683=354833270=10202.0271=19346=71023=1010=203
1128=99=18235=X49=SAMPLE75=2016101134=170552=2015012115284812877209660=201501211528481287720965799=10000100268=1279=1269=148=17359555=6SZ683=354834270=10223.0271=36346=31023=1010=196
1128=99=18235=X49=SAMPLE75=2016101134=446752=2003050619411865955486460=200305061941186595548645799=10000100268=1279=1269=048=17359555=6SZ683=354835270=10202.0271=49346=81023=1010=222
1128=99=18235=X49=SAMPLE75=2016101134=97252=2003031603465644863971260=200303160346564486397125799=10000100268=1279=1269=048=17359555=6SZ683=354836270=10202.0271=19346=71023=1010=211
1128=99=18135=X49=SAMPLE75=2016101134=346752=2008022506015928726227260=200802250601592872622725799=10000100268=1279=1269=148=17359555=6SZ683=354837270=10223.0271=6346=21023=1010=169
1128=99=18235=X49=SAMPLE75=2016101134=437252=2013090219505951441081660=201309021950595144108165799=10000100268=1279=1269=048=17359555=6SZ683=354838270=10202.0271=49346=81023=1010=221
1128=99=18235=X49=SAMPLE75=2016101134=224252=2010032409114907676307260=201003240911490767630725799=10000100268=1279=1269=148=17359555=6SZ683=354839270=10223.0271=36346=31023=1010=238
1128=99=18135=X49=SAMPLE75=2016101134=163652=2016100608170011162451260=201610060817001116245125799=10000100268=1279=1269=148=17359555=6SZ683=354840270=10223.0271=6346=21023=1010=165
1128=99=18235=X49=SAMPLE75=2016101134=203652=2009032509133936521785660=200903250913393652178565799=10000100268=1279=1269=148=17359555=6SZ683=354841270=10223.0271=36346=31023=1010=238
1128=99=18235=X49=SAMPLE75=2016101134=93152=2004011216051141900268860=200401121605114190026885799=10000100268=1279=1269=048=17359555=6SZ683=354842270=10202.0271=19346=71023=1010=211
1128=99=18135=X49=SAMPLE75=2016101134=61352=2003092003345932786985660=200309200334593278698565799=10000100268=1279=1269=148=17359555=6SZ683=354843270=10223.0271=6346=21023=1010=154
1128=99=18235=X49=SAMPLE75=2016101134=31052=2010102719232485793164860=201010271923248579316485799=10000100268=1279=1269=048=17359555=6SZ683=354844270=10202.0271=49346=81023=1010=199
1128=99=18235=X49=SAMPLE75=2016101134=375352=2000110202232655752512860=200011020223265575251285799=10000100268=1279=1269=148=17359555=6SZ683=354845270=10223.0271=36346=31023=1010=190
1128=99=18235=X49=SAMPLE75=2016101134=240852=2008082520494638202960060=200808252049463820296005799=10000100268=1279=1269=048=17359555=6SZ683=354846270=10202.0271=19346=71023=1010=198
1128=99=18235=X49=SAMPLE75=2016101134=368652=2000042512145033395242460=200004251214503339524245799=10000100268=1279=1269=048=17359555=6SZ683=354847270=10202.0271=49346=81023=1010=228
1128=99=18135=X49=SAMPLE75=2016101134=400652=2009090707084760752448060=200909070708476075244805799=10000100268=1279=1269=148=17359555=6SZ683=354848270=10223.0271=6346=21023=1010=177
1128=99=18235=X49=SAMPLE75=2016101134=267452=2016030315175228539596860=201603031517522853959685799=10000100268=1279=1269=048=17359555=6SZ683=354849270=10202.0271=52346=91023=1010=218
1128=99=18035=X49=SAMPLE75=2016101134=157052=2005013012072894485193660=200501301207289448519365799=10000100268=1279=1269=048=17359555=6SZ683=354850270=10203.0271=4346=21023=910=100
1128=99=18135=X49=SAMPLE75=2016101134=172752=2003070604255910273374460=200307060425591027337445799=10000100268=1279=1269=048=17359555=6SZ683=354851270=10204.0271=34346=31023=810=161
1128=99=18135=X49=SAMPLE75=2016101134=482552=2007061303250799355696060=200706130325079935569605799=10000100268=1279=1269=048=17359555=6SZ683=354852270=10205.0271=51346=81023=710=175
1128=99=18035=X49=SAMPLE75=2016101134=339152=2007042519523436593344060=200704251952343659334405799=10000100268=1279=1269=048=17359555=6SZ683=354853270=10206.0271=4346=21023=610=105
1128=99=18135=X49=SAMPLE75=2016101134=306652=2015042120454994623334460=201504212045499462333445799=10000100268=1279=1269=048=17359555=6SZ683=354854270=10207.0271=15346=71023=510=172
1128=99=18035=X49=SAMPLE75=2016101134=8252=2001042201112719911463260=200104220111271991146325799=10000100268=1279=1269=048=17359555=6SZ683=354855270=10208.0271=7346=41023=410=118
1128=99=18035=X49=SAMPLE75=2016101134=225652=2011033013520923646854460=201103301352092364685445799=10000100268=1279=1269=048=17359555=6SZ683=354856270=10209.0271=4346=21023=310=106
1128=99=18035=X49=SAMPLE75=2016101134=456352=2009052306463532965196860=200905230646353296519685799=10000100268=1279=1269=048=17359555=6SZ683=354857270=10210.0271=4346=21023=210=116
1128=99=18035=X49=SAMPLE75=2016101134=49752=2005102002382331986873660=200510200238233198687365799=10000100268=1279=1269=048=17359555=6SZ683=354858270=10211.0271=5346=31023=110=120
1128=99=18035=X49=SAMPLE75=2016101134=95052=2005051322565180299244860=200505132256518029924485799=10000100268=1279=1269=148=17359555=6SZ683=354859270=10214.0271=8346=61023=210=136
1128=99=18035=X49=SAMPLE75=2016101134=337552=2012081305392251574848060=201208130539225157484805799=10000100268=1279=1269=148=17359555=6SZ683=354860270=10213.0271=1346=11023=110=105
1128=99=18135=X49=SAMPLE75=2016101134=82052=2002011100472730142660060=200201110047273014266005799=10000100268=1279=1269=148=17359555=6SZ683=354861270=10215.0271=20346=71023=310=143
1128=99=18135=X49=SAMPLE75=2016101134=210152=2016070113363899962944060=201607011336389996294405799=10000100268=1279=1269=148=17359555=6SZ683=354862270=10216.0271=42346=51023=410=162
1128=99=18135=X49=SAMPLE75=2016101134=247052=2009090712200260415840060=200909071220026041584005799=10000100268=1279=1269=148=17359555=6SZ683=354863270=10217.0271=33346=21023=510=156
1128=99=18035=X49=SAMPLE75=2016101134=47352=2012111917431774540582460=201211191743177454058245799=10000100268=1279=1269=148=17359555=6SZ683=354864270=10218.0271=4346=21023=610=108
1128=99=18235=X49=SAMPLE75=2016101134=488152=2017021218144363417273660=201702121814436341727365799=10000100268=1279=1269=148=17359555=6SZ683=354865270=10223.0271=36346=31023=1010=217
1128=99=18135=X49=SAMPLE75=2016101134=341052=2007112703421210691859260=200711270342121069185925799=10000100268=1279=1269=148=17359555=6SZ683=354866270=10219.0271=30346=91023=710=192
1128=99=18035=X49=SAMPLE75=2016101134=356652=2005022804571483309945660=200502280457148330994565799=10000100268=1279=1269=148=17359555=6SZ683=354867270=10220.0271=4346=21023=810=106
1128=99=18135=X49=SAMPLE75=2016101134=218352=2010091214070085891462460=201009121407008589146245799=10000100268=1279=1269=148=17359555=6SZ683=354868270=10221.0271=21346=61023=910=160
1128=99=18135=X49=SAMPLE75=2016101134=418952=2011062308191665483123260=201106230819166548312325799=10000100268=1279=0269=148=17359555=6SZ683=354869270=10222.0271=3346=11023=1010=153
1128=99=24935=X49=SAMPLE75=2016101134=36452=2004091110091901910992060=200409111009190191099205799=10000100268=2279=1269=048=17360055=6SH783=99068270=10261.0271=5346=21023=3279=1269=048=17360055=6SH783=99069270=10259.0271=3346=11023=510=044
1128=99=24935=X49=SAMPLE75=2016101134=274452=2006100609001836398694460=200610060900183639869445799=10000100268=2279=1269=048=17360055=6SH783=99070270=10262.0271=5346=21023=2279=1269=048=17360055=6SH783=99071270=10260.0271=3346=11023=410=003
1128=99=18035=X49=SAMPLE75=2016101134=151752=2006022408394273539529660=200602240839427353952965799=10000100268=1279=1269=048=17359555=6SZ683=354870270=10204.0271=4346=21023=810=121
1128=99=18135=X49=SAMPLE75=2016101134=358352=2001080408421574964599260=200108040842157496459925799=10000100268=1279=1269=048=17359555=6SZ683=354871270=10205.0271=21346=71023=710=189
1128=99=18135=X49=SAMPLE75=2016101134=83852=2010122910114431764345660=201012291011443176434565799=10000100268=1279=1269=048=17359555=6SZ683=354872270=10206.0271=34346=31023=610=186
1128=99=18235=X49=SAMPLE75=2016101134=361452=2005040207030000841036860=200504020703000084103685799=10000100268=1279=1269=048=17359555=6SZ683=354873270=10202.0271=22346=81023=1010=197
1128=99=18135=X49=SAMPLE75=2016101134=17252=2015052420473630023353660=201505242047363002335365799=10000100268=1279=1269=048=17359555=6SZ683=354874270=10204.0271=34346=31023=810=155
1128=99=18235=X49=SAMPLE75=2016101134=455952=2008090200372642390524860=200809020037264239052485799=10000100268=1279=1269=048=17359555=6SZ683=354875270=10202.0271=52346=91023=1010=189
1128=99=18035=X49=SAMPLE75=2016101134=48852=2001022202550975232628860=200102220255097523262885799=10000100268=1279=1269=048=17359555=6SZ683=354876270=10206.0271=4346=21023=610=133
1128=99=18235=X49=SAMPLE75=2016101134=343052=2006032907032986723155260=200603290703298672315525799=10000100268=1279=1269=048=17359555=6SZ683=354877270=10202.0271=22346=81023=1010=220
1128=99=18135=X49=SAMPLE75=2016101134=289252=2011102100044379896550460=201110210004437989655045799=10000100268=1279=1269=048=17359555=6SZ683=354878270=10203.0271=34346=31023=910=196
1128=99=18035=X49=SAMPLE75=2016101134=171352=2000102019053244289483660=200010201905324428948365799=10000100268=1279=1269=048=17359555=6SZ683=354879270=10203.0271=4346=21023=910=114
1128=99=18135=X49=SAMPLE75=2016101134=324552=2005031609182549260131260=200503160918254926013125799=10000100268=1279=1269=048=17359555=6SZ683=354880270=10206.0271=34346=31023=610=156
1128=99=18235=X49=SAMPLE75=2016101134=151952=2016040710121238925804860=201604071012123892580485799=10000100268=1279=1269=048=17359555=6SZ683=354881270=10202.0271=52346=91023=1010=220
1128=99=18235=X49=SAMPLE75=2016101134=492052=2004103102522493440374460=200410310252249344037445799=10000100268=1279=1269=048=17359555=6SZ683=354882270=10202.0271=22346=81023=1010=203
1128=99=18235=X49=SAMPLE75=2016101134=261252=2008042318293513209558460=200804231829351320955845799=10000100268=1279=1269=048=17359555=6SZ683=354883270=10202.0271=52346=91023=1010=214
1128=99=18235=X49=SAMPLE75=2016101134=379752=2003033021454076175713660=200303302145407617571365799=10000100268=1279=1269=048=17359555=6SZ683=354884270=10202.0271=22346=81023=1010=241
1128=99=18235=X49=SAMPLE75=2016101134=204552=2002030806105315426036860=200203080610531542603685799=10000100268=1279=1269=048=17359555=6SZ683=354885270=10202.0271=52346=91023=1010=228
1128=99=18235=X49=SAMPLE75=2016101134=397052=2010122210363816224217660=201012221036381622421765799=10000100268=1279=1269=048=17359555=6SZ683=354886270=10202.0271=22346=81023=1010=205
1128=99=18235=X49=SAMPLE75=2016101134=230252=2007011005524413629760060=200701100552441362976005799=10000100268=1279=1269=048=17359555=6SZ683=354887270=10202.0271=52346=91023=1010=220
1128=99=25235=X49=SAMPLE75=2016101134=441452=2016011603493089670675260=201601160349308967067525799=10000100268=2279=1269=148=17359555=6SZ683=354888270=10218.0271=7346=31023=6279=1269=148=17359555=6SZ683=354889270=10219.0271=27346=81023=710=207
1128=99=25235=X49=SAMPLE75=2016101134=89852=2001112412114619890179260=200111241211461989017925799=10000100268=2279=1269=148=17359555=6SZ683=354890270=10218.0271=4346=21023=6279=1269=148=17359555=6SZ683=354891270=10219.0271=30346=91023=710=178
1128=99=18235=X49=SAMPLE75=2016101134=397252=2005053102323141267283260=200505310232314126728325799=10000100268=1279=1269=048=17359555=6SZ683=354892270=10202.0271=22346=81023=1010=180
1128=99=18235=X49=SAMPLE75=2016101134=215452=2004060120083602297668860=200406012008360229766885799=10000100268=1279=1269=048=17359555=6SZ683=354893270=10202.0271=52346=91023=1010=189
1128=99=18235=X49=SAMPLE75=2016101134=407552=2015031018475401408275260=201503101847540140827525799=10000100268=1279=1269=048=17359555=6SZ683=354894270=10202.0271=22346=81023=1010=212
1128=99=18235=X49=SAMPLE75=2016101134=483752=2013050222560970845414460=201305022256097084541445799=10000100268=1279=1269=048=17359555=6SZ683=354895270=10202.0271=52346=91023=1010=188
1128=99=24035=X49=SAMPLE75=2016101134=294852=2004062618294483475990460=200406261829448347599045799=00000001268=1279=0269=248=17359555=6SZ683=354896270=10211.0271=3346=45797=237705=437=032=337=032=137=621180789662432=137=032=110=029
1128=99=15635=X49=SAMPLE75=2016101134=487152=2003011014322723715574460=200301101432272371557445799=00000010268=1279=0269=e48=17359555=6SZ683=354897271=1510=074
1128=99=18035=X49=SAMPLE75=2016101134=77452=2016040303191279895897660=201604030319127989589765799=10000100268=1279=1269=048=17359555=6SZ683=354898270=10211.0271=2346=11023=110=076
1128=99=17935=X49=SAMPLE75=2016101134=107852=2011042411004302774348860=201104241100430277434885799=10000100268=1279=0269=148=17360055=6SH783=99072270=10268.0271=3346=11023=110=019
1128=99=17935=X49=SAMPLE75=2016101134=22252=2015042815350555984537660=201504281535055598453765799=10000100268=1279=0269=148=17360055=6SH783=99073270=10269.0271=3346=11023=210=031
1128=99=25035=X49=SAMPLE75=2016101134=477952=2002011303554938459884860=200201130355493845988485799=10000100268=2279=2269=148=17360055=6SH783=99074270=10268.0271=3346=11023=1279=0269=148=17360055=6SH783=99075270=10278.0271=3346=11023=1010=041
1128=99=25035=X49=SAMPLE75=2016101134=273052=2012010500121881377420860=201201050012188137742085799=10000100268=2279=2269=148=17360055=6SH783=99076270=10269.0271=3346=11023=1279=0269=148=17360055=6SH783=99077270=10279.0271=3346=11023=1010=066
1128=99=18035=X49=SAMPLE75=2016101134=98852=2009082020104116921209660=200908202010411692120965799=10000100268=1279=1269=048=17359555=6SZ683=354899270=10206.0271=4346=21023=610=111
1128=99=18035=X49=SAMPLE75=2016101134=30052=2014123005090849945152060=201412300509084994515205799=10000100268=1279=1269=048=17359555=6SZ683=354900270=10211.0271=3346=21023=110=098
1128=99=18135=X49=SAMPLE75=2016101134=164652=2011031709182930680441660=201103170918293068044165799=10000100268=1279=1269=048=17359555=6SZ683=354901270=10205.0271=51346=81023=710=162
1128=99=18235=X49=SAMPLE75=2016101134=326052=2013100516145802429286460=201310051614580242928645799=10000100268=1279=1269=048=17359555=6SZ683=354902270=10202.0271=22346=81023=1010=172
1128=99=18235=X49=SAMPLE75=2016101134=234752=2016100215262630430643260=201610021526263043064325799=10000100268=1279=1269=048=17359555=6SZ683=354903270=10202.0271=52346=91023=1010=199
1128=99=18035=X49=SAMPLE75=2016101134=221452=2007040518324112913254460=200704051832411291325445799=10000100268=1279=1269=048=17359555=6SZ683=354904270=10204.0271=4346=21023=810=120
1128=99=18135=X49=SAMPLE75=2016101134=412752=2004121504534611827712060=200412150453461182771205799=10000100268=1279=1269=048=17359555=6SZ683=354905270=10204.0271=34346=31023=810=164
1128=99=18035=X49=SAMPLE75=2016101134=148752=2014062423110660553440060=201406242311066055344005799=10000100268=1279=1269=048=17359555=6SZ683=354906270=10204.0271=4346=21023=810=116
1128=99=18135=X49=SAMPLE75=2016101134=69152=2007051116582640356864060=200705111658264035686405799=10000100268=1279=1269=048=17359555=6SZ683=354907270=10205.0271=21346=71023=710=145
1128=99=18135=X49=SAMPLE75=2016101134=339252=2015061614450845806572860=201506161445084580657285799=10000100268=1279=1269=048=17359555=6SZ683=354908270=10206.0271=34346=31023=610=146
1128=99=18135=X49=SAMPLE75=2016101134=184452=2016112514474834041702460=201611251447483404170245799=10000100268=1279=1269=048=17359555=6SZ683=354909270=10204.0271=34346=31023=810=120
1128=99=18035=X49=SAMPLE75=2016101134=95252=2007061615063196925065660=200706161506319692506565799=10000100268=1279=1269=048=17359555=6SZ683=354910270=10204.0271=4346=21023=810=066
1128=99=18135=X49=SAMPLE75=2016101134=80552=2013090310302092591712060=201309031030209259171205799=10000100268=1279=1269=048=17359555=6SZ683=354911270=10204.0271=34346=31023=810=134
1128=99=18235=X49=SAMPLE75=2016101134=326352=2000082308525726428040060=200008230852572642804005799=10000100268=1279=1269=048=17359555=6SZ683=354912270=10202.0271=22346=81023=1010=161
1128=99=18235=X49=SAMPLE75=2016101134=178852=2011110509511813798700860=201111050951181379870085799=10000100268=1279=1269=048=17359555=6SZ683=354913270=10202.0271=52346=91023=1010=187
1128=99=18235=X49=SAMPLE75=2016101134=245752=2015122418144832773600060=201512241814483277360005799=10000100268=1279=1269=048=17359555=6SZ683=354914270=10202.0271=22346=81023=1010=211
1128=99=18235=X49=SAMPLE75=2016101134=293752=2013092503433595260217660=201309250343359526021765799=10000100268=1279=1269=048=17359555=6SZ683=354915270=10202.0271=52346=91023=1010=172
1128=99=18235=X49=SAMPLE75=2016101134=250852=2008031921492777602403260=200803192149277760240325799=10000100268=1279=1269=048=17359555=6SZ683=354916270=10202.0271=22346=81023=1010=175
1128=99=18235=X49=SAMPLE75=2016101134=312952=2012080201190594183788860=201208020119059418378885799=10000100268=1279=1269=048=17359555=6SZ683=354917270=10202.0271=52346=91023=1010=192
1128=99=18135=X49=SAMPLE75=2016101134=244852=2011121123130106497216060=201112112313010649721605799=10000100268=1279=1269=148=17359555=6SZ683=354918270=10219.0271=29346=81023=710=171
1128=99=18235=X49=SAMPLE75=2016101134=416752=2005100109402962539817660=200510010940296253981765799=10000100268=1279=1269=048=17359555=6SZ683=354919270=10202.0271=22346=81023=1010=196
1128=99=18235=X49=SAMPLE75=2016101134=376452=2002091005344764909857660=200209100534476490985765799=10000100268=1279=1269=048=17359555=6SZ683=354920270=10202.0271=52346=91023=1010=206
1128=99=18235=X49=SAMPLE75=2016101134=159352=2014112613180185225920060=201411261318018522592005799=10000100268=1279=1269=148=17359555=6SZ683=354921270=10222.0271=33346=21023=1010=170
1128=99=18235=X49=SAMPLE75=2016101134=472052=2014042103193607163475260=201404210319360716347525799=10000100268=1279=1269=048=17359555=6SZ683=354922270=10202.0271=22346=81023=1010=163
1128=99=18135=X49=SAMPLE75=2016101134=142052=2015112517320469837721660=201511251732046983772165799=10000100268=1279=1269=148=17359555=6SZ683=354923270=10222.0271=3346=11023=1010=138
1128=99=18235=X49=SAMPLE75=2016101134=358052=2013040201101513766169660=201304020110151376616965799=10000100268=1279=1269=048=17359555=6SZ683=354924270=10202.0271=52346=91023=1010=180
1128=99=18235=X49=SAMPLE75=2016101134=340052=2016022009350646543968060=201602200935064654396805799=10000100268=1279=1269=148=17359555=6SZ683=354925270=10222.0271=33346=21023=1010=209
1128=99=18235=X49=SAMPLE75=2016101134=33852=2007070301151368193040060=200707030115136819304005799=10000100268=1279=1269=048=17359555=6SZ683=354926270=10202.0271=22346=81023=1010=194
1128=99=18135=X49=SAMPLE75=2016101134=194852=2014011622342739012844860=201401162234273901284485799=10000100268=1279=1269=148=17359555=6SZ683=354927270=10222.0271=3346=11023=1010=120
1128=99=18235=X49=SAMPLE75=2016101134=378652=2012092622155286940723260=201209262215528694072325799=10000100268=1279=1269=048=17359555=6SZ683=354928270=10202.0271=52346=91023=1010=185
1128=99=18235=X49=SAMPLE75=2016101134=467652=2004050913522333622096060=200405091352233362209605799=10000100268=1279=1269=148=17359555=6SZ683=354929270=10222.0271=33346=21023=1010=176
1128=99=18235=X49=SAMPLE75=2016101134=232252=2015091112442734027020860=201509111244273402702085799=10000100268=1279=1269=048=17359555=6SZ683=354930270=10202.0271=22346=81023=1010=184
1128=99=18235=X49=SAMPLE75=2016101134=310852=2003041503110754272865660=200304150311075427286565799=10000100268=1279=1269=048=17359555=6SZ683=354931270=10202.0271=52346=91023=1010=191
1128=99=18135=X49=SAMPLE75=2016101134=104052=2012060611594522407276860=201206061159452240727685799=10000100268=1279=1269=148=17359555=6SZ683=354932270=10222.0271=3346=11023=1010=128
1128=99=18235=X49=SAMPLE75=2016101134=467752=2015012215061867226988860=201501221506186722698885799=10000100268=1279=1269=048=17359555=6SZ683=354933270=10202.0271=22346=81023=1010=196
1128=99=18235=X49=SAMPLE75=2016101134=100852=2012111408130885211993660=201211140813088521199365799=10000100268=1279=1269=148=17359555=6SZ683=354934270=10222.0271=33346=21023=1010=199
1128=99=18235=X49=SAMPLE75=2016101134=423352=2012032814090338880729660=201203281409033888072965799=10000100268=1279=1269=048=17359555=6SZ683=354935270=10202.0271=52346=91023=1010=203
1128=99=18135=X49=SAMPLE75=2016101134=134452=2002031615322338037420860=200203161532233803742085799=10000100268=1279=1269=148=17359555=6SZ683=354936270=10222.0271=3346=11023=1010=153
1128=99=18235=X49=SAMPLE75=2016101134=25352=2005112307445491696822460=200511230744549169682245799=10000100268=1279=1269=148=17359555=6SZ683=354937270=10222.0271=33346=21023=1010=191
1128=99=18135=X49=SAMPLE75=2016101134=93352=2013070420040456285241660=201307042004045628524165799=10000100268=1279=1269=148=17359555=6SZ683=354938270=10222.0271=3346=11023=1010=126
1128=99=18035=X49=SAMPLE75=2016101134=415552=2004112109532743668041660=200411210953274366804165799=10000100268=1279=1269=048=17359555=6SZ683=354939270=10204.0271=4346=21023=810=091
1128=99=18135=X49=SAMPLE75=2016101134=258352=2012102504064524903584060=201210250406452490358405799=10000100268=1279=1269=048=17359555=6SZ683=354940270=10205.0271=51346=81023=710=133
1128=99=18235=X49=SAMPLE75=2016101134=652=2007010301503971591459260=200701030150397159145925799=10000100268=1279=1269=148=17359555=6SZ683=354941270=10222.0271=33346=21023=1010=182
1128=99=18135=X49=SAMPLE75=2016101134=121952=2006100821294586033235260=200610082129458603323525799=10000100268=1279=1269=148=17359555=6SZ683=354942270=10222.0271=3346=11023=1010=117
1128=99=18135=X49=SAMPLE75=2016101134=265452=2004072909495640348438460=200407290949564034843845799=10000100268=1279=1269=048=17359555=6SZ683=354943270=10205.0271=21346=71023=710=140
1128=99=18235=X49=SAMPLE75=2016101134=246152=2011061408315984049324860=201106140831598404932485799=10000100268=1279=1269=148=17359555=6SZ683=354944270=10222.0271=33346=21023=1010=195
1128=99=18135=X49=SAMPLE75=2016101134=470152=2003100311101054152828860=200310031110105415282885799=10000100268=1279=1269=048=17359555=6SZ683=354945270=10204.0271=34346=31023=810=143
1128=99=18135=X49=SAMPLE75=2016101134=108352=2009112109452565023443260=200911210945256502344325799=10000100268=1279=1269=148=17359555=6SZ683=354946270=10222.0271=3346=11023=1010=136
1128=99=18235=X49=SAMPLE75=2016101134=397752=2009092022071925667942460=200909202207192566794245799=10000100268=1279=1269=148=17359555=6SZ683=354947270=10222.0271=33346=21023=1010=196
1128=99=18135=X49=SAMPLE75=2016101134=317852=2010051616462721011820860=201005161646272101182085799=10000100268=1279=1269=148=17359555=6SZ683=354948270=10222.0271=3346=11023=1010=150
1128=99=18235=X49=SAMPLE75=2016101134=217452=2005111915215173533913660=200511191521517353391365799=10000100268=1279=1269=148=17359555=6SZ683=354949270=10222.0271=33346=21023=1010=204
1128=99=18135=X49=SAMPLE75=2016101134=186352=2011092210424143739244860=201109221042414373924485799=10000100268=1279=1269=148=17359555=6SZ683=354950270=10222.0271=3346=11023=1010=131
1128=99=18235=X49=SAMPLE75=2016101134=292252=2016050122112673580710460=201605012211267358071045799=10000100268=1279=1269=048=17359555=6SZ683=354951270=10202.0271=22346=81023=1010=183
1128=99=18235=X49=SAMPLE75=2016101134=342852=2016081601505683328953660=201608160150568332895365799=10000100268=1279=1269=148=17359555=6SZ683=354952270=10222.0271=33346=21023=1010=201
1128=99=18235=X49=SAMPLE75=2016101134=2752=2009100922101271538982460=200910092210127153898245799=10000100268=1279=1269=048=17359555=6SZ683=354953270=10202.0271=52346=91023=1010=207
1128=99=18135=X49=SAMPLE75=2016101134=366952=2000121602383897534935260=200012160238389753493525799=10000100268=1279=1269=148=17359555=6SZ683=354954270=10222.0271=3346=11023=1010=149
1128=99=18235=X49=SAMPLE75=2016101134=155552=2013040714420214341958460=201304071442021434195845799=10000100268=1279=1269=148=17359555=6SZ683=354955270=10222.0271=33346=21023=1010=186
1128=99=18135=X49=SAMPLE75=2016101134=268152=2016022218111498396595260=201602221811149839659525799=10000100268=1279=1269=148=17359555=6SZ683=354956270=10222.0271=3346=11023=1010=140
1128=99=18235=X49=SAMPLE75=2016101134=72652=2014051608364063353708860=201405160836406335370885799=10000100268=1279=1269=148=17359555=6SZ683=354957270=10222.0271=33346=21023=1010=191
1128=99=18135=X49=SAMPLE75=2016101134=114352=2012043019275848111276860=201204301927584811127685799=10000100268=1279=1269=148=17359555=6SZ683=354958270=10222.0271=3346=11023=1010=160
1128=99=18235=X49=SAMPLE75=2016101134=14252=2002053021534129138345660=200205302153412913834565799=10000100268=1279=1269=148=17359555=6SZ683=354959270=10222.0271=33346=21023=1010=190
1128=99=18135=X49=SAMPLE75=2016101134=246152=2015062221014874613670460=201506222101487461367045799=10000100268=1279=1269=148=17359555=6SZ683=354960270=10222.0271=3346=11023=1010=164
1128=99=18235=X49=SAMPLE75=2016101134=202552=2002022021222920501720060=200202202122292050172005799=10000100268=1279=1269=148=17359555=6SZ683=354961270=10222.0271=33346=21023=1010=191
1128=99=18135=X49=SAMPLE75=2016101134=452852=2010030907155341233785660=201003090715534123378565799=10000100268=1279=1269=148=17359555=6SZ683=354962270=10222.0271=3346=11023=1010=142
1128=99=18235=X49=SAMPLE75=2016101134=31052=2001010506595097911534860=200101050659509791153485799=10000100268=1279=1269=148=17359555=6SZ683=354963270=10222.0271=33346=21023=1010=210
1128=99=18135=X49=SAMPLE75=2016101134=239352=2010040811163561080486460=201004081116356108048645799=10000100268=1279=1269=148=17359555=6SZ683=354964270=10222.0271=3346=11023=1010=137
1128=99=18235=X49=SAMPLE75=2016101134=380152=2013070903033443332179260=201307090303344333217925799=10000100268=1279=1269=148=17359555=6SZ683=354965270=10222.0271=33346=21023=1010=184
