1128=99=18235=X49=SAMPLE75=2016101134=139052=2006070511354113350950460=200607051135411335095045799=10000100268=1279=1269=048=17359555=6SZ683=357902270=10212.0271=33346=111023=510=187
1128=99=18235=X49=SAMPLE75=2016101134=445952=2011011801191660887315260=201101180119166088731525799=10000100268=1279=1269=048=17359555=6SZ683=357903270=10212.0271=26346=101023=510=201
1128=99=18135=X49=SAMPLE75=2016101134=371652=2013022604435783008524860=201302260443578300852485799=10000100268=1279=1269=148=17359555=6SZ683=357904270=10221.0271=26346=91023=510=181
1128=99=18035=X49=SAMPLE75=2016101134=490452=2014082120234613627308860=201408212023461362730885799=10000100268=1279=1269=048=17359555=6SZ683=357905270=10216.0271=7346=71023=110=125
1128=99=18135=X49=SAMPLE75=2016101134=361352=2009102913232976570656060=200910291323297657065605799=10000100268=1279=1269=048=17359555=6SZ683=357906270=10215.0271=20346=91023=210=152
1128=99=18235=X49=SAMPLE75=2016101134=340152=2000091702365312712094060=200009170236531271209405799=10000100268=1279=1269=048=17359555=6SZ683=357907270=10212.0271=33346=111023=510=193
1128=99=20835=X49=SAMPLE75=2016101134=326652=2014020410273769394028860=201402041027376939402885799=00000001268=1279=0269=248=17359555=6SZ683=357908270=10216.0271=1346=25797=237705=237=032=137=032=110=104
1128=99=15635=X49=SAMPLE75=2016101134=428352=2012010416153608585248060=201201041615360858524805799=00000010268=1279=0269=e48=17359555=6SZ683=357909271=8010=117
1128=99=18035=X49=SAMPLE75=2016101134=293652=2009061714335352623769660=200906171433535262376965799=10000100268=1279=1269=048=17359555=6SZ683=357910270=10216.0271=6346=61023=110=122
1128=99=18035=X49=SAMPLE75=2016101134=370052=2003060401190531236017660=200306040119053123601765799=10000100268=1279=1269=148=17359555=6SZ683=357911270=10217.0271=2346=21023=110=127
1128=99=18035=X49=SAMPLE75=2016101134=184052=2011012707401802729612860=201101270740180272961285799=10000100268=1279=1269=148=17359555=6SZ683=357912270=10217.0271=3346=31023=110=120
1128=99=18035=X49=SAMPLE75=2016101134=59752=2001091722221584902505660=200109172222158490250565799=10000100268=1279=1269=148=17359555=6SZ683=357913270=10217.0271=4346=41023=110=118
1128=99=18035=X49=SAMPLE75=2016101134=183952=2007062314235250699974460=200706231423525069997445799=10000100268=1279=1269=048=17359555=6SZ683=357914270=10216.0271=5346=51023=110=131
1128=99=18035=X49=SAMPLE75=2016101134=335152=2000122619243858280439260=200012261924385828043925799=10000100268=1279=1269=048=17359555=6SZ683=357915270=10216.0271=4346=41023=110=115
1128=99=18035=X49=SAMPLE75=2016101134=123952=2017022506345487649484860=201702250634548764948485799=10000100268=1279=1269=048=17359555=6SZ683=357916270=10216.0271=3346=31023=110=124
1128=99=25035=X49=SAMPLE75=2016101134=314052=2015013006412680367033660=201501300641268036703365799=10000100268=2279=2269=048=17360055=6SH783=99398270=10269.0271=3346=11023=1279=0269=048=17360055=6SH783=99399270=10259.0271=3346=11023=1010=070
1128=99=18035=X49=SAMPLE75=2016101134=206252=2001063022443464231216060=200106302244346423121605799=10000100268=1279=1269=048=17359555=6SZ683=357917270=10216.0271=2346=21023=110=111
1128=99=18035=X49=SAMPLE75=2016101134=462252=2012070218275701473011260=201207021827570147301125799=10000100268=1279=1269=148=17359555=6SZ683=357918270=10217.0271=5346=51023=110=133
1128=99=18035=X49=SAMPLE75=2016101134=123952=2008081617470567635891260=200808161747056763589125799=10000100268=1279=1269=048=17359555=6SZ683=357919270=10216.0271=3346=31023=110=113
1128=99=18035=X49=SAMPLE75=2016101134=149252=2002072521551104899131260=200207252155110489913125799=10000100268=1279=1269=048=17359555=6SZ683=357920270=10216.0271=4346=41023=110=099
1128=99=18035=X49=SAMPLE75=2016101134=431652=2014111100372068667270460=201411110037206866727045799=10000100268=1279=1269=048=17359555=6SZ683=357921270=10216.0271=5346=51023=110=090
1128=99=18035=X49=SAMPLE75=2016101134=202152=2011091919305015924339260=201109191930501592433925799=10000100268=1279=1269=148=17359555=6SZ683=357922270=10217.0271=4346=41023=110=101
1128=99=18035=X49=SAMPLE75=2016101134=357552=2001012410270391492967660=200101241027039149296765799=10000100268=1279=1269=048=17359555=6SZ683=357923270=10216.0271=6346=61023=110=110
1128=99=17935=X49=SAMPLE75=2016101134=91452=2001060212582039802172860=200106021258203980217285799=10000100268=1279=0269=048=17360055=6SH783=99400270=10269.0271=3346=11023=110=012
1128=99=18235=X49=SAMPLE75=2016101134=174252=2013022021213140636089660=201302202121314063608965799=10000100268=1279=1269=048=17359555=6SZ683=357924270=10214.0271=19346=101023=310=225
1128=99=18235=X49=SAMPLE75=2016101134=115452=2001051516313050216035260=200105151631305021603525799=10000100268=1279=1269=048=17359555=6SZ683=357925270=10215.0271=21346=101023=210=227
1128=99=18035=X49=SAMPLE75=2016101134=304352=2003081118111789878243260=200308111811178987824325799=10000100268=1279=1269=048=17359555=6SZ683=357926270=10216.0271=5346=51023=110=115
1128=99=25035=X49=SAMPLE75=2016101134=183952=2003090317250329311494460=200309031725032931149445799=10000100268=2279=2269=048=17360055=6SH783=99401270=10269.0271=3346=11023=1279=0269=048=17360055=6SH783=99402270=10259.0271=3346=11023=1010=051
1128=99=18135=X49=SAMPLE75=2016101134=20752=2006040400405003820265660=200604040040500382026565799=10000100268=1279=1269=048=17359555=6SZ683=357927270=10208.0271=19346=41023=910=185
1128=99=18235=X49=SAMPLE75=2016101134=396652=2014062218143548251731260=201406221814354825173125799=10000100268=1279=1269=048=17359555=6SZ683=357928270=10215.0271=22346=111023=210=214
1128=99=18235=X49=SAMPLE75=2016101134=109452=2008020805115445274745660=200802080511544527474565799=10000100268=1279=1269=148=17359555=6SZ683=357929270=10221.0271=27346=101023=510=198
1128=99=18135=X49=SAMPLE75=2016101134=455952=2000070600441339783910460=200007060044133978391045799=10000100268=1279=1269=148=17359555=6SZ683=357930270=10223.0271=20346=51023=710=162
1128=99=18035=X49=SAMPLE75=2016101134=65452=2016080708222137385587260=201608070822213738558725799=10000100268=1279=1269=048=17359555=6SZ683=357931270=10216.0271=4346=41023=110=115
1128=99=18235=X49=SAMPLE75=2016101134=199752=2014111623224719770284860=201411162322471977028485799=10000100268=1279=1269=048=17359555=6SZ683=357932270=10215.0271=21346=101023=210=217
1128=99=18135=X49=SAMPLE75=2016101134=34352=2004011309314809456750460=200401130931480945675045799=10000100268=1279=1269=048=17359555=6SZ683=357933270=10208.0271=20346=51023=910=163
1128=99=20835=X49=SAMPLE75=2016101134=107252=2011121100323433864569660=201112110032343386456965799=00000001268=1279=0269=248=17359555=6SZ683=357934270=10217.0271=1346=25797=137705=237=032=137=032=110=073
1128=99=15635=X49=SAMPLE75=2016101134=195252=2002081409483901121265660=200208140948390112126565799=00000010268=1279=0269=e48=17359555=6SZ683=357935271=8110=089
1128=99=18035=X49=SAMPLE75=2016101134=284352=2001071310554508084272060=200107131055450808427205799=00000100268=1279=1269=148=17359555=6SZ683=357936270=10217.0271=3346=31023=110=097
1128=99=16935=X49=SAMPLE75=2016101134=57552=2011110709542066442617660=201111070954206644261765799=10001000268=1279=0269=748=17359555=6SZ683=357937270=10217.0286=25510=155
1128=99=18035=X49=SAMPLE75=2016101134=466852=2001031806552642429405660=200103180655264242940565799=10000100268=1279=1269=048=17359555=6SZ683=357938270=10216.0271=5346=51023=110=111
1128=99=18035=X49=SAMPLE75=2016101134=319252=2002070405112776624392060=200207040511277662439205799=10000100268=1279=1269=148=17359555=6SZ683=357939270=10217.0271=2346=21023=110=114
1128=99=18035=X49=SAMPLE75=2016101134=167252=2015032008511807402726460=201503200851180740272645799=10000100268=1279=1269=148=17359555=6SZ683=357940270=10217.0271=1346=11023=110=104
1128=99=18035=X49=SAMPLE75=2016101134=446952=2002101702322591694452860=200210170232259169445285799=10000100268=1279=1269=048=17359555=6SZ683=357941270=10216.0271=6346=61023=110=120
1128=99=17935=X49=SAMPLE75=2016101134=278952=2012013111482609871244860=201201311148260987124485799=10000100268=1279=0269=048=17360055=6SH783=99403270=10269.0271=3346=11023=110=043
1128=99=25435=X49=SAMPLE75=2016101134=162052=2002041404563331787947260=200204140456333178794725799=10000100268=2279=1269=048=17359555=6SZ683=357942270=10215.0271=22346=111023=2279=1269=048=17359555=6SZ683=357943270=10214.0271=18346=91023=310=037
1128=99=18035=X49=SAMPLE75=2016101134=433152=2005010919273074475865660=200501091927307447586565799=10000100268=1279=1269=148=17359555=6SZ683=357944270=10217.0271=2346=21023=110=114
1128=99=18035=X49=SAMPLE75=2016101134=5152=2016030302533768320217660=201603030253376832021765799=10000100268=1279=1269=148=17359555=6SZ683=357945270=10217.0271=1346=11023=110=107
1128=99=18035=X49=SAMPLE75=2016101134=194652=2005070605142198318016060=200507060514219831801605799=10000100268=1279=1269=148=17359555=6SZ683=357946270=10217.0271=2346=21023=110=127
1128=99=18035=X49=SAMPLE75=2016101134=473652=2002112706511636450844860=200211270651163645084485799=10000100268=1279=1269=148=17359555=6SZ683=357947270=10217.0271=3346=31023=110=139
1128=99=18035=X49=SAMPLE75=2016101134=118152=2011072717461768038182460=201107271746176803818245799=10000100268=1279=1269=148=17359555=6SZ683=357948270=10217.0271=4346=41023=110=144
1128=99=18035=X49=SAMPLE75=2016101134=188052=2002110605451739675686460=200211060545173967568645799=10000100268=1279=1269=048=17359555=6SZ683=357949270=10216.0271=5346=51023=110=113
1128=99=18035=X49=SAMPLE75=2016101134=253052=2016080817164042900102460=201608081716404290010245799=10000100268=1279=1269=048=17359555=6SZ683=357950270=10216.0271=4346=41023=110=123
1128=99=25035=X49=SAMPLE75=2016101134=333352=2004071323480207792305660=200407132348020779230565799=10000100268=2279=2269=048=17360055=6SH783=99404270=10269.0271=3346=11023=1279=0269=048=17360055=6SH783=99405270=10259.0271=3346=11023=1010=074
1128=99=18035=X49=SAMPLE75=2016101134=291352=2012012404463444443507260=201201240446344444350725799=10000100268=1279=1269=048=17359555=6SZ683=357951270=10216.0271=3346=31023=110=128
1128=99=18035=X49=SAMPLE75=2016101134=320452=2006050323014150380240060=200605032301415038024005799=10000100268=1279=1269=148=17359555=6SZ683=357952270=10217.0271=5346=51023=110=076
1128=99=18035=X49=SAMPLE75=2016101134=200552=2013080908330863200851260=201308090833086320085125799=10000100268=1279=1269=148=17359555=6SZ683=357953270=10217.0271=6346=61023=110=131
1128=99=17935=X49=SAMPLE75=2016101134=177552=2016021619405375967392060=201602161940537596739205799=10000100268=1279=0269=148=17360055=6SH783=99406270=10273.0271=3346=11023=110=053
1128=99=24935=X49=SAMPLE75=2016101134=360252=2016062814403922623571260=201606281440392262357125799=10000100268=2279=1269=148=17360055=6SH783=99407270=10274.0271=5346=21023=2279=1269=148=17360055=6SH783=99408270=10276.0271=3346=11023=410=028
1128=99=18035=X49=SAMPLE75=2016101134=153452=2013081423393940333619260=201308142339394033361925799=10000100268=1279=1269=148=17359555=6SZ683=357954270=10217.0271=5346=51023=110=152
1128=99=25135=X49=SAMPLE75=2016101134=287552=2016090919421475454950460=201609091942147545495045799=10000100268=2279=2269=148=17360055=6SH783=99409270=10273.0271=3346=11023=1279=0269=148=17360055=6SH783=99410270=10283.0271=61346=31023=1010=154
1128=99=18035=X49=SAMPLE75=2016101134=103652=2003082621263504857444860=200308262126350485744485799=10000100268=1279=1269=048=17359555=6SZ683=357955270=10216.0271=2346=21023=110=112
1128=99=25535=X49=SAMPLE75=2016101134=197852=2006031300300431574675260=200603130030043157467525799=10000100268=2279=1269=048=17359555=6SZ683=357956270=10215.0271=21346=101023=2279=1269=048=17359555=6SZ683=357957270=10214.0271=19346=101023=310=112
1128=99=21835=X49=SAMPLE75=2016101134=219952=2008100912052426419392060=200810091205242641939205799=00000001268=1279=0269=248=17359555=6SZ683=357958270=10216.0271=2346=35797=237705=337=032=237=032=137=032=110=006
1128=99=15635=X49=SAMPLE75=2016101134=370452=2009013115591106426336060=200901311559110642633605799=00000010268=1279=0269=e48=17359555=6SZ683=357959271=8310=101
1128=99=25335=X49=SAMPLE75=2016101134=271552=2017030108220186021420860=201703010822018602142085799=10000100268=2279=2269=048=17359555=6SZ683=357960270=10216.0271=2346=21023=1279=0269=048=17359555=6SZ683=357961270=10206.0271=39346=51023=1010=249
1128=99=17935=X49=SAMPLE75=2016101134=19052=2008091423424506540816060=200809142342450654081605799=10000100268=1279=0269=148=17360055=6SH783=99411270=10272.0271=3346=11023=110=009
1128=99=18035=X49=SAMPLE75=2016101134=474252=2015031714231907267904060=201503171423190726790405799=10000100268=1279=0269=148=17359555=6SZ683=357962270=10216.0271=1346=11023=110=086
1128=99=17935=X49=SAMPLE75=2016101134=330652=2003080511063761133696060=200308051106376113369605799=10000100268=1279=0269=148=17360055=6SH783=99412270=10273.0271=3346=11023=210=012
1128=99=18135=X49=SAMPLE75=2016101134=125652=2013092407395045222220860=201309240739504522222085799=10000100268=1279=1269=048=17359555=6SZ683=357963270=10215.0271=20346=91023=110=142
1128=99=25335=X49=SAMPLE75=2016101134=491552=2017020703091185594259260=201702070309118559425925799=10000100268=2279=1269=148=17359555=6SZ683=357964270=10220.0271=19346=81023=5279=1269=148=17359555=6SZ683=357965270=10221.0271=24346=91023=610=021
1128=99=18135=X49=SAMPLE75=2016101134=431952=2005020421120152545600060=200502042112015254560005799=10000100268=1279=1269=048=17359555=6SZ683=357966270=10215.0271=19346=81023=110=161
1128=99=22035=X49=SAMPLE75=2016101134=325852=2000070109244752442507260=200007010924475244250725799=00000001268=1279=0269=248=17359555=6SZ683=357967270=10216.0271=1346=25797=137705=237=032=137=621180795608032=110=176
1128=99=15635=X49=SAMPLE75=2016101134=394252=2002032619012056977321660=200203261901205697732165799=00000010268=1279=0269=e48=17359555=6SZ683=357968271=8410=104
1128=99=25335=X49=SAMPLE75=2016101134=408252=2016061202593939149939260=201606120259393914993925799=10000100268=2279=2269=148=17359555=6SZ683=357969270=10216.0271=1346=11023=1279=0269=148=17359555=6SZ683=357970270=10226.0271=15346=21023=1010=253
1128=99=18135=X49=SAMPLE75=2016101134=17952=2016032315411597062643260=201603231541159706264325799=10000100268=1279=1269=048=17359555=6SZ683=357971270=10215.0271=16346=71023=110=155
1128=99=25035=X49=SAMPLE75=2016101134=418752=2009112221365571892486460=200911222136557189248645799=10000100268=2279=2269=148=17360055=6SH783=99413270=10272.0271=3346=11023=1279=0269=148=17360055=6SH783=99414270=10282.0271=3346=11023=1010=029
1128=99=18135=X49=SAMPLE75=2016101134=71252=2015061402510651811315260=201506140251065181131525799=10000100268=1279=1269=048=17359555=6SZ683=357972270=10215.0271=17346=81023=110=166
1128=99=18035=X49=SAMPLE75=2016101134=415752=2004100704402283349824060=200410070440228334982405799=10000100268=1279=1269=148=17359555=6SZ683=357973270=10217.0271=6346=61023=110=113
1128=99=18135=X49=SAMPLE75=2016101134=234352=2016082214272320828793660=201608221427232082879365799=10000100268=1279=1269=148=17359555=6SZ683=357974270=10218.0271=17346=81023=210=167
1128=99=18135=X49=SAMPLE75=2016101134=10052=2015080400550673768883260=201508040055067376888325799=10000100268=1279=1269=148=17359555=6SZ683=357975270=10220.0271=18346=71023=410=170
1128=99=18035=X49=SAMPLE75=2016101134=41452=2000121105174713098916460=200012110517471309891645799=10000100268=1279=0269=148=17359555=6SZ683=357976270=10216.0271=1346=11023=110=117
1128=99=18135=X49=SAMPLE75=2016101134=83952=2014070618331830699641660=201407061833183069964165799=10000100268=1279=1269=048=17359555=6SZ683=357977270=10215.0271=16346=71023=110=172
1128=99=17935=X49=SAMPLE75=2016101134=122352=2011061305063111718361660=201106130506311171836165799=10000100268=1279=0269=148=17360055=6SH783=99415270=10272.0271=3346=11023=110=008
1128=99=18235=X49=SAMPLE75=2016101134=370652=2002082313520350063896060=200208231352035006389605799=10000100268=1279=1269=048=17359555=6SZ683=357978270=10212.0271=26346=101023=410=204
1128=99=18235=X49=SAMPLE75=2016101134=105752=2010111321392255332748860=201011132139225533274885799=10000100268=1279=1269=048=17359555=6SZ683=357979270=10212.0271=33346=111023=410=201
1128=99=22035=X49=SAMPLE75=2016101134=344852=2005111913093292218032060=200511191309329221803205799=00000001268=1279=0269=248=17359555=6SZ683=357980270=10216.0271=1346=25797=137705=237=032=137=621180795610232=110=211
1128=99=15635=X49=SAMPLE75=2016101134=453552=2007061423570949791532860=200706142357094979153285799=00000010268=1279=0269=e48=17359555=6SZ683=357981271=8510=134
1128=99=25335=X49=SAMPLE75=2016101134=393352=2007072713213222244076860=200707271321322224407685799=10000100268=2279=2269=148=17359555=6SZ683=357982270=10216.0271=1346=11023=1279=0269=148=17359555=6SZ683=357983270=10226.0271=15346=21023=1010=030
1128=99=18035=X49=SAMPLE75=2016101134=302852=2001072118493304766544060=200107211849330476654405799=10000100268=1279=0269=148=17359555=6SZ683=357984270=10216.0271=1346=11023=110=116
1128=99=25035=X49=SAMPLE75=2016101134=132952=2016121211050810823750460=201612121105081082375045799=10000100268=2279=2269=148=17360055=6SH783=99416270=10272.0271=3346=11023=1279=0269=148=17360055=6SH783=99417270=10282.0271=3346=11023=1010=069
1128=99=18135=X49=SAMPLE75=2016101134=353752=2004050720562037168316860=200405072056203716831685799=10000100268=1279=1269=048=17359555=6SZ683=357985270=10215.0271=17346=81023=110=190
1128=99=18135=X49=SAMPLE75=2016101134=99652=2004080508421624371705660=200408050842162437170565799=10000100268=1279=1269=048=17359555=6SZ683=357986270=10215.0271=16346=71023=110=174
1128=99=18135=X49=SAMPLE75=2016101134=435952=2012062909310254294944060=201206290931025429494405799=10000100268=1279=1269=048=17359555=6SZ683=357987270=10215.0271=17346=81023=110=184
1128=99=18135=X49=SAMPLE75=2016101134=37652=2001012323413903161301260=200101232341390316130125799=10000100268=1279=1269=048=17359555=6SZ683=357988270=10215.0271=16346=71023=110=171
1128=99=22035=X49=SAMPLE75=2016101134=455752=2013042813154747210854460=201304281315474721085445799=00000001268=1279=0269=248=17359555=6SZ683=357989270=10216.0271=1346=25797=137705=237=032=137=621180795613632=110=228
1128=99=15635=X49=SAMPLE75=2016101134=309552=2003041515434882524137660=200304151543488252413765799=00000010268=1279=0269=e48=17359555=6SZ683=357990271=8610=139
1128=99=25335=X49=SAMPLE75=2016101134=242652=2002050607145127087188860=200205060714512708718885799=10000100268=2279=2269=148=17359555=6SZ683=357991270=10216.0271=1346=11023=1279=0269=148=17359555=6SZ683=357992270=10226.0271=15346=21023=1010=034
1128=99=18135=X49=SAMPLE75=2016101134=198852=2001040203441059234000060=200104020344105923400005799=10000100268=1279=1269=048=17359555=6SZ683=357993270=10215.0271=15346=61023=110=174
1128=99=18135=X49=SAMPLE75=2016101134=188452=2000102120055244287782460=200010212005524428778245799=10000100268=1279=1269=048=17359555=6SZ683=357994270=10215.0271=16346=71023=110=168
1128=99=18035=X49=SAMPLE75=2016101134=314352=2001080516593121851582460=200108051659312185158245799=10000100268=1279=1269=148=17359555=6SZ683=357995270=10217.0271=5346=51023=110=121
1128=99=18035=X49=SAMPLE75=2016101134=476152=2004122905243225142598460=200412290524322514259845799=10000100268=1279=0269=048=17359555=6SZ683=357996270=10216.0271=1346=11023=110=128
1128=99=18135=X49=SAMPLE75=2016101134=266552=2001022711563735257105660=200102271156373525710565799=10000100268=1279=1269=048=17359555=6SZ683=357997270=10215.0271=17346=81023=210=180
1128=99=18035=X49=SAMPLE75=2016101134=414752=2002121422350740505880060=200212142235074050588005799=10000100268=1279=1269=148=17359555=6SZ683=357998270=10217.0271=4346=41023=110=116
1128=99=25135=X49=SAMPLE75=2016101134=405952=2011110714015138019232060=201111071401513801923205799=10000100268=2279=2269=148=17360055=6SH783=99418270=10273.0271=3346=11023=1279=0269=148=17360055=6SH783=99419270=10283.0271=61346=31023=1010=112
1128=99=20835=X49=SAMPLE75=2016101134=458152=2008043013071303385449660=200804301307130338544965799=00000001268=1279=0269=248=17359555=6SZ683=357999270=10216.0271=1346=25797=237705=237=032=137=032=110=106
1128=99=15635=X49=SAMPLE75=2016101134=373952=2013021909451936771948860=201302190945193677194885799=00000010268=1279=0269=e48=17359555=6SZ683=358000271=8710=102
1128=99=25335=X49=SAMPLE75=2016101134=168952=2008012602274871244227260=200801260227487124422725799=10000100268=2279=2269=048=17359555=6SZ683=358001270=10216.0271=1346=11023=1279=0269=048=17359555=6SZ683=358002270=10206.0271=39346=51023=1010=240
1128=99=18035=X49=SAMPLE75=2016101134=2352=2011051021195920148608060=201105102119592014860805799=10000100268=1279=0269=048=17359555=6SZ683=358003270=10216.0271=1346=11023=110=104
1128=99=20835=X49=SAMPLE75=2016101134=25252=2004061221570837752188860=200406122157083775218885799=00000001268=1279=0269=248=17359555=6SZ683=358004270=10216.0271=1346=25797=237705=237=032=137=032=110=067
1128=99=15635=X49=SAMPLE75=2016101134=223552=2014040105325791502124860=201404010532579150212485799=00000010268=1279=0269=e48=17359555=6SZ683=358005271=8810=109
1128=99=25335=X49=SAMPLE75=2016101134=465652=2000062607083393686636260=200006260708339368663625799=10000100268=2279=2269=048=17359555=6SZ683=358006270=10216.0271=1346=11023=1279=0269=048=17359555=6SZ683=358007270=10206.0271=39346=51023=1010=251
1128=99=18035=X49=SAMPLE75=2016101134=319652=2010081903515457176883260=201008190351545717688325799=10000100268=1279=1269=148=17359555=6SZ683=358008270=10217.0271=5346=51023=110=109
1128=99=18135=X49=SAMPLE75=2016101134=492252=2006083119310945447827260=200608311931094544782725799=10000100268=1279=1269=148=17359555=6SZ683=358009270=10217.0271=13346=61023=110=139
1128=99=18235=X49=SAMPLE75=2016101134=308752=2011080215472316268268860=201108021547231626826885799=10000100268=1279=1269=048=17359555=6SZ683=358010270=10212.0271=26346=101023=410=180
1128=99=17935=X49=SAMPLE75=2016101134=345652=2008081221131607268086460=200808122113160726808645799=10000100268=1279=0269=148=17360055=6SH783=99420270=10273.0271=3346=11023=110=025
1128=99=18035=X49=SAMPLE75=2016101134=45352=2010121706250781936128060=201012170625078193612805799=10000100268=1279=1269=148=17359555=6SZ683=358011270=10217.0271=5346=51023=110=105
1128=99=25135=X49=SAMPLE75=2016101134=49952=2016012810011692992627260=201601281001169299262725799=10000100268=2279=2269=148=17360055=6SH783=99421270=10273.0271=3346=11023=1279=0269=148=17360055=6SH783=99422270=10283.0271=61346=31023=1010=074
1128=99=18135=X49=SAMPLE75=2016101134=12652=2002062405343042163702460=200206240534304216370245799=10000100268=1279=1269=148=17359555=6SZ683=358012270=10217.0271=13346=61023=110=140
1128=99=17935=X49=SAMPLE75=2016101134=331752=2010070212045860033408060=201007021204586003340805799=10000100268=1279=0269=148=17360055=6SH783=99423270=10273.0271=3346=11023=110=054
1128=99=18035=X49=SAMPLE75=2016101134=338552=2016052717104130692832060=201605271710413069283205799=10000100268=1279=1269=148=17359555=6SZ683=358013270=10217.0271=5346=51023=110=114
1128=99=25135=X49=SAMPLE75=2016101134=423152=2003053100241194317960060=200305310024119431796005799=10000100268=2279=2269=148=17360055=6SH783=99424270=10273.0271=3346=11023=1279=0269=148=17360055=6SH783=99425270=10283.0271=61346=31023=1010=105
1128=99=18035=X49=SAMPLE75=2016101134=128852=2009110314134729414361660=200911031413472941436165799=10000100268=1279=0269=148=17359555=6SZ683=358014270=10216.0271=1346=11023=110=118
1128=99=17935=X49=SAMPLE75=2016101134=4352=2000022015195865463344260=200002201519586546334425799=10000100268=1279=0269=148=17360055=6SH783=99426270=10272.0271=3346=11023=110=056
1128=99=18035=X49=SAMPLE75=2016101134=232452=2016110411525584358771260=201611041152558435877125799=10000100268=1279=1269=148=17359555=6SZ683=358015270=10217.0271=6346=61023=210=131
1128=99=17935=X49=SAMPLE75=2016101134=394452=2003062211054540082027260=200306221105454008202725799=10000100268=1279=0269=148=17360055=6SH783=99427270=10273.0271=3346=11023=210=062
1128=99=25035=X49=SAMPLE75=2016101134=440952=2004011218561463254963260=200401121856146325496325799=10000100268=2279=2269=148=17360055=6SH783=99428270=10272.0271=3346=11023=1279=0269=148=17360055=6SH783=99429270=10282.0271=3346=11023=1010=070
1128=99=18135=X49=SAMPLE75=2016101134=351952=2009020400530917306582460=200902040053091730658245799=10000100268=1279=1269=148=17359555=6SZ683=358016270=10217.0271=14346=71023=210=169
1128=99=18135=X49=SAMPLE75=2016101134=274852=2000121803064846000471660=200012180306484600047165799=10000100268=1279=1269=148=17359555=6SZ683=358017270=10220.0271=25346=81023=510=181
1128=99=18035=X49=SAMPLE75=2016101134=267452=2008010522330222620035260=200801052233022262003525799=10000100268=1279=1269=148=17359555=6SZ683=358018270=10216.0271=2346=21023=110=113
1128=99=18035=X49=SAMPLE75=2016101134=374952=2006120818490581164000060=200612081849058116400005799=10000100268=1279=1269=048=17359555=6SZ683=358019270=10215.0271=9346=71023=110=102
1128=99=18035=X49=SAMPLE75=2016101134=438252=2013041913114455321356860=201304191311445532135685799=10000100268=1279=1269=048=17359555=6SZ683=358020270=10215.0271=8346=61023=110=100
1128=99=18035=X49=SAMPLE75=2016101134=322952=2016060110464873481164860=201606011046487348116485799=10000100268=1279=1269=048=17359555=6SZ683=358021270=10215.0271=7346=51023=110=090
1128=99=18035=X49=SAMPLE75=2016101134=343652=2010111421154823845139260=201011142115482384513925799=10000100268=1279=1269=048=17359555=6SZ683=358022270=10215.0271=6346=41023=110=090
1128=99=18035=X49=SAMPLE75=2016101134=159152=2007110114043289225948860=200711011404328922594885799=10000100268=1279=1269=148=17359555=6SZ683=358023270=10216.0271=3346=31023=110=109
1128=99=18035=X49=SAMPLE75=2016101134=386352=2002040606062850216217660=200204060606285021621765799=10000100268=1279=1269=048=17359555=6SZ683=358024270=10215.0271=5346=31023=110=106
1128=99=18035=X49=SAMPLE75=2016101134=388152=2016022622294137434476860=201602262229413743447685799=10000100268=1279=1269=148=17359555=6SZ683=358025270=10216.0271=4346=41023=110=107
1128=99=18035=X49=SAMPLE75=2016101134=201852=2013090805381038071673660=201309080538103807167365799=10000100268=1279=1269=048=17359555=6SZ683=358026270=10215.0271=6346=41023=110=103
1128=99=18035=X49=SAMPLE75=2016101134=255252=2007062113235752457808060=200706211323575245780805799=10000100268=1279=1269=148=17359555=6SZ683=358027270=10216.0271=5346=51023=110=129
1128=99=25335=X49=SAMPLE75=2016101134=433152=2014062618521266126681660=201406261852126612668165799=10000100268=2279=1269=048=17359555=6SZ683=358028270=10209.0271=39346=51023=7279=1269=048=17359555=6SZ683=358029270=10208.0271=23346=61023=810=030
1128=99=17935=X49=SAMPLE75=2016101134=499352=2015061614273450964601660=201506161427345096460165799=10000100268=1279=1269=048=17360055=6SH783=99430270=10268.0271=2346=11023=110=040
1128=99=32135=X49=SAMPLE75=2016101134=299552=2006012514582483727798460=200601251458248372779845799=10000100268=3279=2269=048=17360055=6SH783=99431270=10268.0271=2346=11023=1279=1269=048=17360055=6SH783=99432270=10265.0271=5346=21023=3279=0269=048=17360055=6SH783=99433270=10258.0271=53346=21023=1010=076
1128=99=17935=X49=SAMPLE75=2016101134=429452=2012082518064586694828860=201208251806458669482885799=10000100268=1279=0269=048=17360055=6SH783=99434270=10268.0271=3346=11023=110=043
1128=99=24935=X49=SAMPLE75=2016101134=329152=2005062514560413515664060=200506251456041351566405799=10000100268=2279=1269=048=17360055=6SH783=99435270=10266.0271=5346=21023=3279=1269=048=17360055=6SH783=99436270=10265.0271=3346=11023=410=015
1128=99=18035=X49=SAMPLE75=2016101134=98052=2015080900081498272960060=201508090008149827296005799=10000100268=1279=1269=048=17359555=6SZ683=358030270=10215.0271=5346=31023=110=109
1128=99=25135=X49=SAMPLE75=2016101134=148552=2015081801483623558809660=201508180148362355880965799=10000100268=2279=2269=048=17360055=6SH783=99437270=10268.0271=3346=11023=1279=0269=048=17360055=6SH783=99438270=10258.0271=53346=21023=1010=107
1128=99=18035=X49=SAMPLE75=2016101134=164952=2011123103024530009651260=201112310302453000965125799=10000100268=1279=1269=048=17359555=6SZ683=358031270=10215.0271=6346=41023=110=113
1128=99=17935=X49=SAMPLE75=2016101134=276552=2015042100280321282688060=201504210028032128268805799=10000100268=1279=0269=048=17360055=6SH783=99439270=10268.0271=3346=11023=110=064
1128=99=18135=X49=SAMPLE75=2016101134=205152=2002111409261327257286460=200211140926132725728645799=10000100268=1279=1269=148=17359555=6SZ683=358032270=10220.0271=18346=71023=510=149
1128=99=18035=X49=SAMPLE75=2016101134=404552=2007102820080508777049660=200710282008050877704965799=10000100268=1279=1269=048=17359555=6SZ683=358033270=10215.0271=5346=31023=110=082
1128=99=25135=X49=SAMPLE75=2016101134=375552=2016030522074454785606460=201603052207445478560645799=10000100268=2279=2269=048=17360055=6SH783=99440270=10268.0271=3346=11023=1279=0269=048=17360055=6SH783=99441270=10258.0271=53346=21023=1010=087
1128=99=25035=X49=SAMPLE75=2016101134=218552=2001081709372283483568060=200108170937228348356805799=10000100268=2279=1269=048=17360055=6SH783=99442270=10263.0271=3346=11023=5279=1269=048=17360055=6SH783=99443270=10259.0271=11346=21023=910=063
1128=99=18035=X49=SAMPLE75=2016101134=81452=2012012804120251890086460=201201280412025189008645799=10000100268=1279=1269=148=17359555=6SZ683=358034270=10216.0271=4346=41023=110=120
1128=99=18035=X49=SAMPLE75=2016101134=79952=2012110304355586596486460=201211030435558659648645799=10000100268=1279=1269=048=17359555=6SZ683=358035270=10215.0271=6346=41023=110=108
1128=99=18035=X49=SAMPLE75=2016101134=148452=2005122819390153403235260=200512281939015340323525799=10000100268=1279=1269=048=17359555=6SZ683=358036270=10215.0271=7346=51023=110=125
1128=99=17935=X49=SAMPLE75=2016101134=307552=2012072816142056714252860=201207281614205671425285799=10000100268=1279=0269=048=17360055=6SH783=99444270=10268.0271=3346=11023=110=057
1128=99=18035=X49=SAMPLE75=2016101134=204452=2005071807224414027424060=200507180722441402742405799=10000100268=1279=1269=048=17359555=6SZ683=358037270=10215.0271=6346=41023=110=127
1128=99=18035=X49=SAMPLE75=2016101134=176552=2013112819253750110105660=201311281925375011010565799=10000100268=1279=1269=148=17359555=6SZ683=358038270=10216.0271=3346=31023=110=118
1128=99=18035=X49=SAMPLE75=2016101134=36552=2002032408042257528473660=200203240804225752847365799=10000100268=1279=1269=148=17359555=6SZ683=358039270=10216.0271=2346=21023=110=136
1128=99=25335=X49=SAMPLE75=2016101134=356652=2003101015590481361972860=200310101559048136197285799=10000100268=2279=1269=048=17359555=6SZ683=358040270=10209.0271=42346=61023=7279=1269=048=17359555=6SZ683=358041270=10208.0271=20346=51023=810=010
1128=99=18035=X49=SAMPLE75=2016101134=89752=2004011100192137154851260=200401110019213715485125799=10000100268=1279=1269=148=17359555=6SZ683=358042270=10216.0271=1346=11023=110=106
1128=99=18135=X49=SAMPLE75=2016101134=384252=2005092418080444414851260=200509241808044441485125799=10000100268=1279=1269=048=17359555=6SZ683=358043270=10215.0271=14346=51023=110=146
1128=99=18135=X49=SAMPLE75=2016101134=77752=2008112821205792475660860=200811282120579247566085799=10000100268=1279=1269=048=17359555=6SZ683=358044270=10215.0271=15346=61023=110=166
1128=99=18135=X49=SAMPLE75=2016101134=177652=2015082402550284355321660=201508240255028435532165799=10000100268=1279=1269=048=17359555=6SZ683=358045270=10215.0271=16346=71023=110=158
1128=99=18135=X49=SAMPLE75=2016101134=359552=2016022319390049781689660=201602231939004978168965799=10000100268=1279=1269=148=17359555=6SZ683=358046270=10220.0271=25346=81023=510=155
1128=99=20835=X49=SAMPLE75=2016101134=199552=2010103103291644232531260=201010310329164423253125799=00000001268=1279=0269=248=17359555=6SZ683=358047270=10216.0271=1346=25797=137705=237=032=137=032=110=100
1128=99=15635=X49=SAMPLE75=2016101134=430852=2012091816475621900377660=201209181647562190037765799=00000010268=1279=0269=e48=17359555=6SZ683=358048271=8910=139
1128=99=25335=X49=SAMPLE75=2016101134=45752=2011013119522709655289660=201101311952270965528965799=10000100268=2279=2269=148=17359555=6SZ683=358049270=10216.0271=1346=11023=1279=0269=148=17359555=6SZ683=358050270=10226.0271=15346=21023=1010=017
1128=99=17935=X49=SAMPLE75=2016101134=132752=2003110313182399291875260=200311031318239929187525799=10000100268=1279=0269=048=17360055=6SH783=99445270=10269.0271=3346=11023=110=067
1128=99=18135=X49=SAMPLE75=2016101134=435452=2012031318171646509011260=201203131817164650901125799=10000100268=1279=1269=148=17359555=6SZ683=358051270=10217.0271=13346=61023=110=160
1128=99=18135=X49=SAMPLE75=2016101134=145052=2008052101431180238688060=200805210143118023868805799=10000100268=1279=1269=148=17359555=6SZ683=358052270=10217.0271=14346=71023=110=173
1128=99=18135=X49=SAMPLE75=2016101134=45052=2005062115411729907785660=200506211541172990778565799=10000100268=1279=1269=148=17359555=6SZ683=358053270=10218.0271=16346=71023=210=161
1128=99=25135=X49=SAMPLE75=2016101134=257652=2002020113100821972806460=200202011310082197280645799=10000100268=2279=2269=048=17360055=6SH783=99446270=10269.0271=3346=11023=1279=0269=048=17360055=6SH783=99447270=10259.0271=11346=21023=1010=124
1128=99=18135=X49=SAMPLE75=2016101134=478252=2007022801511310903798460=200702280151131090379845799=10000100268=1279=1269=148=17359555=6SZ683=358054270=10220.0271=18346=71023=410=172
1128=99=25335=X49=SAMPLE75=2016101134=133352=2009070618151465690393660=200907061815146569039365799=10000100268=2279=1269=148=17359555=6SZ683=358055270=10220.0271=26346=81023=4279=1269=148=17359555=6SZ683=358056270=10224.0271=36346=41023=810=018
1128=99=18035=X49=SAMPLE75=2016101134=425852=2008010404502394788003260=200801040450239478800325799=10000100268=1279=1269=148=17360055=6SH783=99448270=10279.0271=11346=21023=710=094
1128=99=25435=X49=SAMPLE75=2016101134=493952=2000081713092391094652060=200008171309239109465205799=10000100268=2279=1269=148=17359555=6SZ683=358057270=10220.0271=23346=71023=4279=1269=148=17359555=6SZ683=358058270=10221.0271=27346=101023=510=047
1128=99=18035=X49=SAMPLE75=2016101134=105552=2015082515124637552934460=201508251512463755293445799=10000100268=1279=1269=148=17359555=6SZ683=358059270=10217.0271=6346=61023=110=107
1128=99=18035=X49=SAMPLE75=2016101134=435352=2015010315232519908371260=201501031523251990837125799=10000100268=1279=1269=148=17359555=6SZ683=358060270=10217.0271=5346=51023=110=096
1128=99=25135=X49=SAMPLE75=2016101134=193352=2002050615495261635129660=200205061549526163512965799=10000100268=2279=2269=148=17360055=6SH783=99449270=10273.0271=3346=11023=1279=0269=148=17360055=6SH783=99450270=10283.0271=53346=21023=1010=090
1128=99=25335=X49=SAMPLE75=2016101134=482552=2016062823413448535219260=201606282341344853521925799=10000100268=2279=1269=148=17359555=6SZ683=358061270=10220.0271=15346=61023=4279=1269=148=17359555=6SZ683=358062270=10224.0271=44346=51023=810=251
1128=99=18135=X49=SAMPLE75=2016101134=127352=2003100703145749455065660=200310070314574945506565799=10000100268=1279=1269=048=17359555=6SZ683=358063270=10214.0271=18346=91023=210=166
1128=99=18135=X49=SAMPLE75=2016101134=409852=2002051703584634749968060=200205170358463474996805799=10000100268=1279=1269=048=17359555=6SZ683=358064270=10207.0271=21346=61023=910=151
1128=99=25135=X49=SAMPLE75=2016101134=343952=2011031910452374296569660=201103191045237429656965799=10000100268=2279=1269=148=17360055=6SH783=99451270=10279.0271=3346=11023=6279=1269=148=17360055=6SH783=99452270=10283.0271=61346=31023=1010=121
1128=99=18135=X49=SAMPLE75=2016101134=112852=2016012820543857020582460=201601282054385702058245799=10000100268=1279=1269=048=17359555=6SZ683=358065270=10215.0271=17346=81023=110=153
1128=99=18035=X49=SAMPLE75=2016101134=28952=2014051901024060600684860=201405190102406060068485799=10000100268=1279=0269=048=17359555=6SZ683=358066270=10216.0271=1346=11023=110=105
1128=99=17935=X49=SAMPLE75=2016101134=337952=2017030905561278903596860=201703090556127890359685799=10000100268=1279=0269=048=17360055=6SH783=99453270=10269.0271=3346=11023=110=068
1128=99=18035=X49=SAMPLE75=2016101134=77852=2000100522332515343406460=200010052233251534340645799=10000100268=1279=1269=148=17359555=6SZ683=358067270=10217.0271=4346=41023=110=128
1128=99=18135=X49=SAMPLE75=2016101134=140352=2004080717505502081513660=200408071750550208151365799=10000100268=1279=1269=048=17359555=6SZ683=358068270=10212.0271=25346=91023=510=180
1128=99=18035=X49=SAMPLE75=2016101134=5752=2000012010455396298554160=200001201045539629855415799=10000100268=1279=1269=048=17359555=6SZ683=358069270=10216.0271=2346=21023=110=088
1128=99=25135=X49=SAMPLE75=2016101134=55952=2010061410401677170841660=201006141040167717084165799=10000100268=2279=2269=048=17360055=6SH783=99454270=10269.0271=3346=11023=1279=0269=048=17360055=6SH783=99455270=10259.0271=11346=21023=1010=107
1128=99=18035=X49=SAMPLE75=2016101134=299152=2016041719404815820000060=201604171940481582000005799=10000100268=1279=1269=048=17359555=6SZ683=358070270=10216.0271=3346=31023=110=104
1128=99=18235=X49=SAMPLE75=2016101134=121552=2006022809260625537897660=200602280926062553789765799=10000100268=1279=1269=048=17359555=6SZ683=358071270=10212.0271=32346=101023=510=213
1128=99=18135=X49=SAMPLE75=2016101134=346252=2003041913424253018270460=200304191342425301827045799=10000100268=1279=1269=048=17359555=6SZ683=358072270=10212.0271=25346=91023=510=165
1128=99=18235=X49=SAMPLE75=2016101134=289152=2015041201325179308652860=201504120132517930865285799=10000100268=1279=1269=048=17359555=6SZ683=358073270=10212.0271=32346=101023=510=194
1128=99=18235=X49=SAMPLE75=2016101134=438752=2006031822020435089638460=200603182202043508963845799=10000100268=1279=1269=048=17359555=6SZ683=358074270=10207.0271=20346=51023=1010=188
1128=99=18235=X49=SAMPLE75=2016101134=445552=2010122020280842987507260=201012202028084298750725799=10000100268=1279=1269=048=17359555=6SZ683=358075270=10214.0271=19346=101023=310=196
1128=99=18035=X49=SAMPLE75=2016101134=130752=2008090711393552966924860=200809071139355296692485799=10000100268=1279=1269=048=17359555=6SZ683=358076270=10216.0271=4346=41023=110=110
1128=99=18135=X49=SAMPLE75=2016101134=43352=2016010409571219465350460=201601040957121946535045799=10000100268=1279=1269=048=17359555=6SZ683=358077270=10215.0271=20346=91023=210=192
1128=99=18035=X49=SAMPLE75=2016101134=480052=2008100802473909337328060=200810080247390933732805799=10000100268=1279=1269=048=17359555=6SZ683=358078270=10216.0271=5346=51023=110=120
1128=99=18135=X49=SAMPLE75=2016101134=88552=2008072907080274905990460=200807290708027490599045799=10000100268=1279=1269=148=17359555=6SZ683=358079270=10218.0271=17346=81023=210=173
1128=99=18035=X49=SAMPLE75=2016101134=228552=2015022718291031121555260=201502271829103112155525799=10000100268=1279=1269=048=17359555=6SZ683=358080270=10216.0271=4346=41023=110=130
1128=99=18035=X49=SAMPLE75=2016101134=318952=2001101211240203398567260=200110121124020339856725799=10000100268=1279=1269=048=17359555=6SZ683=358081270=10216.0271=3346=31023=110=120
1128=99=18035=X49=SAMPLE75=2016101134=208852=2004100217495457313862460=200410021749545731386245799=10000100268=1279=1269=048=17359555=6SZ683=358082270=10216.0271=2346=21023=110=127
1128=99=25135=X49=SAMPLE75=2016101134=131552=2003011802333339648067260=200301180233333964806725799=10000100268=2279=1269=048=17360055=6SH783=99456270=10263.0271=11346=21023=6279=1269=048=17360055=6SH783=99457270=10259.0271=3346=11023=1010=107
1128=99=25335=X49=SAMPLE75=2016101134=396352=2014110423330442927366460=201411042333044292736645799=10000100268=2279=1269=148=17359555=6SZ683=358083270=10220.0271=18346=71023=4279=1269=148=17359555=6SZ683=358084270=10221.0271=24346=91023=510=255
1128=99=25435=X49=SAMPLE75=2016101134=272352=2002092209545742992080060=200209220954574299208005799=10000100268=2279=1269=148=17359555=6SZ683=358085270=10220.0271=15346=61023=4279=1269=148=17359555=6SZ683=358086270=10221.0271=27346=101023=510=050
1128=99=18035=X49=SAMPLE75=2016101134=460252=2013022607141635779942460=201302260714163577994245799=10000100268=1279=1269=048=17359555=6SZ683=358087270=10216.0271=3346=31023=110=090
1128=99=18035=X49=SAMPLE75=2016101134=225952=2012071420434950652742460=201207142043495065274245799=10000100268=1279=1269=048=17359555=6SZ683=358088270=10216.0271=4346=41023=110=134
1128=99=18035=X49=SAMPLE75=2016101134=290952=2012020221054449202662460=201202022105444920266245799=10000100268=1279=1269=048=17359555=6SZ683=358089270=10216.0271=3346=31023=110=130
1128=99=25335=X49=SAMPLE75=2016101134=424152=2003031305531960504507260=200303130553196050450725799=10000100268=2279=1269=148=17359555=6SZ683=358090270=10220.0271=18346=71023=4279=1269=148=17359555=6SZ683=358091270=10221.0271=24346=91023=510=036
1128=99=18035=X49=SAMPLE75=2016101134=253652=2001112004331832859011260=200111200433183285901125799=10000100268=1279=1269=048=17359555=6SZ683=358092270=10216.0271=2346=21023=110=134
1128=99=18035=X49=SAMPLE75=2016101134=16652=2013102520223552598361660=201310252022355259836165799=10000100268=1279=1269=048=17359555=6SZ683=358093270=10216.0271=3346=31023=110=125
1128=99=18035=X49=SAMPLE75=2016101134=115152=2012030623363224934131260=201203062336322493413125799=10000100268=1279=1269=048=17359555=6SZ683=358094270=10216.0271=4346=41023=110=090
1128=99=18035=X49=SAMPLE75=2016101134=53852=2008010315412889963366460=200801031541288996336645799=10000100268=1279=1269=048=17359555=6SZ683=358095270=10216.0271=5346=51023=110=107
1128=99=18035=X49=SAMPLE75=2016101134=469152=2009121617230494290150460=200912161723049429015045799=10000100268=1279=1269=148=17359555=6SZ683=358096270=10217.0271=3346=31023=110=091
1128=99=18035=X49=SAMPLE75=2016101134=185652=2012062123104680381171260=201206212310468038117125799=10000100268=1279=1269=148=17359555=6SZ683=358097270=10217.0271=2346=21023=110=108
1128=99=18035=X49=SAMPLE75=2016101134=240952=2003090300220008767228860=200309030022000876722885799=10000100268=1279=1269=148=17359555=6SZ683=358098270=10217.0271=1346=11023=110=093
1128=99=18035=X49=SAMPLE75=2016101134=20552=2000032114334216642645960=200003211433421664264595799=10000100268=1279=1269=048=17359555=6SZ683=358099270=10216.0271=6346=61023=110=110
1128=99=17935=X49=SAMPLE75=2016101134=6252=2012061522304470240524860=201206152230447024052485799=10000100268=1279=0269=048=17360055=6SH783=99458270=10269.0271=3346=11023=110=050
1128=99=24935=X49=SAMPLE75=2016101134=330952=2012021813595498422880060=201202181359549842288005799=10000100268=2279=1269=048=17360055=6SH783=99459270=10268.0271=5346=21023=2279=1269=048=17360055=6SH783=99460270=10266.0271=3346=11023=410=049
1128=99=25435=X49=SAMPLE75=2016101134=430652=2001111309301854016930460=200111130930185401693045799=10000100268=2279=1269=148=17359555=6SZ683=358100270=10220.0271=15346=61023=4279=1269=148=17359555=6SZ683=358101270=10221.0271=27346=101023=510=023
1128=99=25335=X49=SAMPLE75=2016101134=301052=2001032600582737012468060=200103260058273701246805799=10000100268=2279=1269=148=17359555=6SZ683=358102270=10220.0271=18346=71023=4279=1269=148=17359555=6SZ683=358103270=10221.0271=24346=91023=510=233
1128=99=25435=X49=SAMPLE75=2016101134=177652=2005070403464094952521660=200507040346409495252165799=10000100268=2279=1269=148=17359555=6SZ683=358104270=10220.0271=15346=61023=4279=1269=148=17359555=6SZ683=358105270=10221.0271=27346=101023=510=042
1128=99=18035=X49=SAMPLE75=2016101134=151952=2003110220453602158622460=200311022045360215862245799=10000100268=1279=1269=148=17359555=6SZ683=358106270=10217.0271=2346=21023=110=105
1128=99=18035=X49=SAMPLE75=2016101134=456552=2012021821145350487539260=201202182114535048753925799=10000100268=1279=1269=148=17359555=6SZ683=358107270=10217.0271=3346=31023=110=104
1128=99=18035=X49=SAMPLE75=2016101134=83352=2016072620401526978112060=201607262040152697811205799=10000100268=1279=1269=048=17359555=6SZ683=358108270=10216.0271=5346=51023=110=119
1128=99=18035=X49=SAMPLE75=2016101134=217352=2014100422521719878470460=201410042252171987847045799=10000100268=1279=1269=048=17359555=6SZ683=358109270=10216.0271=4346=41023=110=111
1128=99=25035=X49=SAMPLE75=2016101134=471152=2012111622243356510528060=201211162224335651052805799=10000100268=2279=2269=048=17360055=6SH783=99461270=10269.0271=3346=11023=1279=0269=048=17360055=6SH783=99462270=10259.0271=3346=11023=1010=058
1128=99=18035=X49=SAMPLE75=2016101134=385952=2001061619395331318804860=200106161939533131880485799=10000100268=1279=1269=048=17359555=6SZ683=358110270=10216.0271=5346=51023=110=099
1128=99=18035=X49=SAMPLE75=2016101134=112152=2015052514292241872531260=201505251429224187253125799=10000100268=1279=1269=148=17359555=6SZ683=358111270=10217.0271=2346=21023=110=112
1128=99=18035=X49=SAMPLE75=2016101134=343852=2015010811441881808172860=201501081144188180817285799=10000100268=1279=1269=148=17359555=6SZ683=358112270=10217.0271=3346=31023=110=113
1128=99=18035=X49=SAMPLE75=2016101134=372452=2016070700131635768051260=201607070013163576805125799=10000100268=1279=1269=048=17359555=6SZ683=358113270=10216.0271=4346=41023=110=109
1128=99=18035=X49=SAMPLE75=2016101134=53752=2010061412252495999379260=201006141225249599937925799=10000100268=1279=1269=048=17359555=6SZ683=358114270=10216.0271=5346=51023=110=129
1128=99=18035=X49=SAMPLE75=2016101134=25752=2004071720314057978540860=200407172031405797854085799=10000100268=1279=1269=148=17359555=6SZ683=358115270=10217.0271=4346=41023=110=132
1128=99=18035=X49=SAMPLE75=2016101134=400352=2007011216013141777193660=200701121601314177719365799=10000100268=1279=1269=048=17359555=6SZ683=358116270=10216.0271=4346=41023=110=099
1128=99=18035=X49=SAMPLE75=2016101134=257152=2015072602161095556819260=201507260216109555681925799=10000100268=1279=1269=148=17359555=6SZ683=358117270=10217.0271=5346=51023=110=109
1128=99=18035=X49=SAMPLE75=2016101134=67752=2004052612554029012524860=200405261255402901252485799=10000100268=1279=1269=048=17359555=6SZ683=358118270=10216.0271=3346=31023=110=114
1128=99=18035=X49=SAMPLE75=2016101134=412952=2009120414385391212243260=200912041438539121224325799=10000100268=1279=1269=048=17359555=6SZ683=358119270=10216.0271=2346=21023=110=115
1128=99=18035=X49=SAMPLE75=2016101134=101652=2003121116213275376521660=200312111621327537652165799=10000100268=1279=1269=048=17359555=6SZ683=358120270=10216.0271=1346=11023=110=101
1128=99=18035=X49=SAMPLE75=2016101134=361252=2012011707171268024256060=201201170717126802425605799=10000100268=1279=1269=048=17359555=6SZ683=358121270=10216.0271=2346=21023=110=094
1128=99=18035=X49=SAMPLE75=2016101134=458652=2003030607430237779371260=200303060743023777937125799=10000100268=1279=1269=148=17359555=6SZ683=358122270=10217.0271=4346=41023=110=065
1128=99=18035=X49=SAMPLE75=2016101134=286352=2005090601410201604390460=200509060141020160439045799=10000100268=1279=1269=048=17359555=6SZ683=358123270=10216.0271=3346=31023=110=072
1128=99=18035=X49=SAMPLE75=2016101134=391752=2009012301511489819020860=200901230151148981902085799=10000100268=1279=1269=048=17359555=6SZ683=358124270=10216.0271=4346=41023=110=102
1128=99=18035=X49=SAMPLE75=2016101134=161252=2004043023513830337180860=200404302351383033718085799=10000100268=1279=1269=048=17359555=6SZ683=358125270=10216.0271=5346=51023=110=102
1128=99=18135=X49=SAMPLE75=2016101134=299352=2011070315301319757811260=201107031530131975781125799=10000100268=1279=1269=048=17359555=6SZ683=358126270=10212.0271=25346=91023=510=160
1128=99=18235=X49=SAMPLE75=2016101134=172652=2006071209341631577596860=200607120934163157759685799=10000100268=1279=1269=048=17359555=6SZ683=358127270=10212.0271=32346=101023=510=208
1128=99=18235=X49=SAMPLE75=2016101134=421852=2010091305450899393497660=201009130545089939349765799=10000100268=1279=1269=048=17359555=6SZ683=358128270=10207.0271=19346=51023=1010=235
1128=99=18135=X49=SAMPLE75=2016101134=327452=2002092708071788347544060=200209270807178834754405799=10000100268=1279=1269=048=17359555=6SZ683=358129270=10208.0271=19346=51023=910=188
1128=99=18135=X49=SAMPLE75=2016101134=107352=2010030902451293663014460=201003090245129366301445799=10000100268=1279=1269=048=17359555=6SZ683=358130270=10209.0271=41346=61023=810=192
1128=99=18135=X49=SAMPLE75=2016101134=445952=2016100800311196363251260=201610080031119636325125799=10000100268=1279=1269=048=17359555=6SZ683=358131270=10210.0271=29346=81023=710=204
1128=99=18235=X49=SAMPLE75=2016101134=492552=2001091408255525463913660=200109140825552546391365799=10000100268=1279=1269=048=17359555=6SZ683=358132270=10212.0271=31346=101023=510=235
1128=99=18135=X49=SAMPLE75=2016101134=104752=2007050213402770954928060=200705021340277095492805799=10000100268=1279=1269=048=17359555=6SZ683=358133270=10213.0271=17346=91023=410=183
1128=99=18235=X49=SAMPLE75=2016101134=483052=2006031321412906221008060=200603132141290622100805799=10000100268=1279=1269=048=17359555=6SZ683=358134270=10214.0271=18346=101023=310=254
1128=99=18135=X49=SAMPLE75=2016101134=402052=2001051012420834834229660=200105101242083483422965799=10000100268=1279=1269=048=17359555=6SZ683=358135270=10215.0271=19346=91023=210=238
1128=99=18135=X49=SAMPLE75=2016101134=246852=2001072411391702492272860=200107241139170249227285799=10000100268=1279=1269=148=17359555=6SZ683=358136270=10218.0271=16346=81023=210=186
1128=99=18135=X49=SAMPLE75=2016101134=353152=2008031710032850280467260=200803171003285028046725799=10000100268=1279=1269=148=17359555=6SZ683=358137270=10219.0271=14346=61023=310=215
1128=99=18135=X49=SAMPLE75=2016101134=60852=2012062202070682458713660=201206220207068245871365799=10000100268=1279=1269=148=17359555=6SZ683=358138270=10220.0271=14346=61023=410=197
1128=99=18235=X49=SAMPLE75=2016101134=349152=2000112012073177675905660=200011201207317767590565799=10000100268=1279=1269=148=17359555=6SZ683=358139270=10221.0271=26346=101023=510=239
1128=99=18135=X49=SAMPLE75=2016101134=337852=2016111521071059317990460=201611152107105931799045799=10000100268=1279=1269=148=17359555=6SZ683=358140270=10222.0271=29346=81023=610=217
1128=99=18135=X49=SAMPLE75=2016101134=279052=2015051708593319041830460=201505170859331904183045799=10000100268=1279=1269=148=17359555=6SZ683=358141270=10223.0271=19346=51023=710=165
1128=99=18035=X49=SAMPLE75=2016101134=308652=2002121203004368649724860=200212120300436864972485799=10000100268=1279=1269=048=17359555=6SZ683=358142270=10216.0271=4346=41023=110=068
1128=99=18035=X49=SAMPLE75=2016101134=223452=2002091704550061288611260=200209170455006128861125799=10000100268=1279=1269=148=17359555=6SZ683=358143270=10217.0271=5346=51023=110=089
1128=99=18035=X49=SAMPLE75=2016101134=134552=2007010407361931394707260=200701040736193139470725799=10000100268=1279=1269=148=17359555=6SZ683=358144270=10217.0271=4346=41023=110=121
1128=99=18035=X49=SAMPLE75=2016101134=320152=2002042319565639473324860=200204231956563947332485799=10000100268=1279=1269=048=17359555=6SZ683=358145270=10216.0271=5346=51023=110=115
1128=99=18035=X49=SAMPLE75=2016101134=144352=2015010211010669799635260=201501021101066979963525799=10000100268=1279=1269=048=17359555=6SZ683=358146270=10216.0271=4346=41023=110=108
1128=99=25335=X49=SAMPLE75=2016101134=353252=2006070905434883912566460=200607090543488391256645799=10000100268=2279=1269=148=17359555=6SZ683=358147270=10220.0271=17346=71023=4279=1269=148=17359555=6SZ683=358148270=10221.0271=23346=91023=510=016
1128=99=18035=X49=SAMPLE75=2016101134=307252=2015052313262930046438460=201505231326293004643845799=10000100268=1279=1269=048=17359555=6SZ683=358149270=10216.0271=3346=31023=110=088
1128=99=18035=X49=SAMPLE75=2016101134=491952=2007050613114990360326460=200705061311499036032645799=10000100268=1279=1269=048=17359555=6SZ683=358150270=10216.0271=2346=21023=110=101
1128=99=18035=X49=SAMPLE75=2016101134=357452=2002080218201821341196860=200208021820182134119685799=10000100268=1279=1269=048=17359555=6SZ683=358151270=10216.0271=1346=11023=110=087
1128=99=18035=X49=SAMPLE75=2016101134=450752=2006082014480405877520060=200608201448040587752005799=10000100268=1279=1269=048=17359555=6SZ683=358152270=10216.0271=2346=21023=110=118
1128=99=18035=X49=SAMPLE75=2016101134=194052=2000101317161417332510060=200010131716141733251005799=10000100268=1279=1269=048=17359555=6SZ683=358153270=10216.0271=3346=31023=110=100
1128=99=18035=X49=SAMPLE75=2016101134=462452=2006081217583148324108860=200608121758314832410885799=10000100268=1279=1269=048=17359555=6SZ683=358154270=10216.0271=4346=41023=110=104
1128=99=18035=X49=SAMPLE75=2016101134=292452=2001080309074512137732060=200108030907451213773205799=10000100268=1279=1269=048=17359555=6SZ683=358155270=10216.0271=3346=31023=110=118
1128=99=18035=X49=SAMPLE75=2016101134=285952=2005021219503845529100860=200502121950384552910085799=10000100268=1279=1269=148=17359555=6SZ683=358156270=10217.0271=5346=51023=110=138
1128=99=18035=X49=SAMPLE75=2016101134=223152=2010091918530891484128060=201009191853089148412805799=10000100268=1279=1269=048=17359555=6SZ683=358157270=10216.0271=2346=21023=110=142
1128=99=18035=X49=SAMPLE75=2016101134=425152=2002011822285428270060060=200201182228542827006005799=10000100268=1279=1269=048=17359555=6SZ683=358158270=10216.0271=1346=11023=110=131
1128=99=18035=X49=SAMPLE75=2016101134=426552=2005042000430818566118460=200504200043081856611845799=10000100268=1279=1269=048=17359555=6SZ683=358159270=10216.0271=2346=21023=110=139
1128=99=18035=X49=SAMPLE75=2016101134=144952=2014091613101853788198460=201409161310185378819845799=10000100268=1279=1269=048=17359555=6SZ683=358160270=10216.0271=3346=31023=110=125
1128=99=18035=X49=SAMPLE75=2016101134=442852=2014032911471819740614460=201403291147181974061445799=10000100268=1279=1269=048=17359555=6SZ683=358161270=10216.0271=4346=41023=110=119
1128=99=25435=X49=SAMPLE75=2016101134=35852=2003021908090812519582460=200302190809081251958245799=10000100268=2279=1269=148=17359555=6SZ683=358162270=10220.0271=14346=61023=4279=1269=148=17359555=6SZ683=358163270=10221.0271=26346=101023=510=050
1128=99=18035=X49=SAMPLE75=2016101134=242152=2005051608210717482697660=200505160821071748269765799=10000100268=1279=1269=148=17359555=6SZ683=358164270=10217.0271=4346=41023=110=119
1128=99=18035=X49=SAMPLE75=2016101134=298952=2001010105284231602741260=200101010528423160274125799=10000100268=1279=1269=048=17359555=6SZ683=358165270=10216.0271=5346=51023=110=123
1128=99=18035=X49=SAMPLE75=2016101134=375652=2011122620560027265056060=201112262056002726505605799=10000100268=1279=1269=048=17359555=6SZ683=358166270=10216.0271=4346=41023=110=111
1128=99=18135=X49=SAMPLE75=2016101134=27352=2007050518302686797756860=200705051830268679775685799=10000100268=1279=1269=148=17359555=6SZ683=358167270=10218.0271=15346=71023=210=192
1128=99=18235=X49=SAMPLE75=2016101134=109352=2001092111460909399056060=200109211146090939905605799=10000100268=1279=1269=048=17359555=6SZ683=358168270=10207.0271=18346=41023=1010=215
1128=99=18135=X49=SAMPLE75=2016101134=27652=2002041211160032870153660=200204121116003287015365799=10000100268=1279=1269=148=17359555=6SZ683=358169270=10223.0271=21346=61023=710=177
1128=99=18135=X49=SAMPLE75=2016101134=278552=2007102716162963506854460=200710271616296350685445799=10000100268=1279=1269=148=17359555=6SZ683=358170270=10225.0271=17346=31023=910=189
1128=99=18135=X49=SAMPLE75=2016101134=222152=2007042806460240189564860=200704280646024018956485799=10000100268=1279=1269=048=17359555=6SZ683=358171270=10211.0271=24346=91023=610=177
1128=99=18135=X49=SAMPLE75=2016101134=414052=2016040106460288452032060=201604010646028845203205799=10000100268=1279=1269=048=17359555=6SZ683=358172270=10209.0271=43346=71023=810=185
1128=99=18235=X49=SAMPLE75=2016101134=163952=2012121702000648292128060=201212170200064829212805799=10000100268=1279=1269=048=17359555=6SZ683=358173270=10207.0271=20346=51023=1010=215
1128=99=17935=X49=SAMPLE75=2016101134=356652=2002082312591385718918460=200208231259138571891845799=10000100268=1279=1269=148=17360055=6SH783=99463270=10274.0271=6346=31023=110=028
1128=99=17935=X49=SAMPLE75=2016101134=166552=2002121103275950191609660=200212110327595019160965799=10000100268=1279=1269=148=17360055=6SH783=99464270=10276.0271=4346=21023=310=034
1128=99=17935=X49=SAMPLE75=2016101134=57552=2002092810584170589982460=200209281058417058998245799=10000100268=1279=1269=148=17360055=6SH783=99465270=10278.0271=4346=21023=510=043
1128=99=17935=X49=SAMPLE75=2016101134=430252=2005110914454372413459260=200511091445437241345925799=10000100268=1279=1269=048=17360055=6SH783=99466270=10268.0271=6346=31023=110=063
1128=99=17935=X49=SAMPLE75=2016101134=187752=2001030709523692148727260=200103070952369214872725799=10000100268=1279=1269=048=17360055=6SH783=99467270=10266.0271=4346=21023=310=035
1128=99=17935=X49=SAMPLE75=2016101134=33952=2008040415514934991225660=200804041551493499122565799=10000100268=1279=1269=048=17360055=6SH783=99468270=10264.0271=4346=21023=510=038
1128=99=17935=X49=SAMPLE75=2016101134=53752=2010082402401629289510460=201008240240162928951045799=10000100268=1279=1269=148=17360055=6SH783=99469270=10275.0271=6346=31023=210=100
1128=99=17935=X49=SAMPLE75=2016101134=194752=2005091001105217173500860=200509100110521717350085799=10000100268=1279=1269=148=17360055=6SH783=99470270=10277.0271=4346=21023=410=078
1128=99=17935=X49=SAMPLE75=2016101134=15152=2015021507090382646451260=201502150709038264645125799=10000100268=1279=1269=048=17360055=6SH783=99471270=10267.0271=6346=31023=210=074
1128=99=17935=X49=SAMPLE75=2016101134=239952=2001060702584704006113660=200106070258470400611365799=10000100268=1279=1269=048=17360055=6SH783=99472270=10265.0271=4346=21023=410=085
1128=99=18035=X49=SAMPLE75=2016101134=7552=2007042909270825047296060=200704290927082504729605799=10000100268=1279=1269=148=17360055=6SH783=99473270=10280.0271=36346=21023=710=104
1128=99=18035=X49=SAMPLE75=2016101134=166252=2006022003134055271520060=200602200313405527152005799=10000100268=1279=1269=048=17360055=6SH783=99474270=10264.0271=37346=31023=510=092
1128=99=18035=X49=SAMPLE75=2016101134=452=2014012502130312601817660=201401250213031260181765799=10000100268=1279=1269=048=17360055=6SH783=99475270=10260.0271=36346=21023=910=093
1128=99=18135=X49=SAMPLE75=2016101134=342352=2016071905321823728953660=201607190532182372895365799=10000100268=1279=1269=148=17359555=6SZ683=358174270=10224.0271=43346=41023=810=153
1128=99=18135=X49=SAMPLE75=2016101134=241252=2012042122325635001459260=201204212232563500145925799=10000100268=1279=1269=148=17359555=6SZ683=358175270=10225.0271=18346=41023=910=153
1128=99=18035=X49=SAMPLE75=2016101134=22252=2007120816354374135686460=200712081635437413568645799=10000100268=1279=1269=148=17359555=6SZ683=358176270=10217.0271=5346=51023=110=114
1128=99=18035=X49=SAMPLE75=2016101134=244852=2005033002590241494742460=200503300259024149474245799=10000100268=1279=1269=048=17359555=6SZ683=358177270=10216.0271=3346=31023=110=112
1128=99=18035=X49=SAMPLE75=2016101134=90652=2007082310524172963945660=200708231052417296394565799=10000100268=1279=1269=048=17359555=6SZ683=358178270=10216.0271=2346=21023=110=095
1128=99=18035=X49=SAMPLE75=2016101134=134252=2014040717444110852275260=201404071744411085227525799=10000100268=1279=1269=048=17359555=6SZ683=358179270=10216.0271=1346=11023=110=116
1128=99=18035=X49=SAMPLE75=2016101134=412052=2001092617235969586372060=200109261723596958637205799=10000100268=1279=1269=048=17359555=6SZ683=358180270=10216.0271=2346=21023=110=093
1128=99=18035=X49=SAMPLE75=2016101134=133152=2000051216503702589945860=200005121650370258994585799=10000100268=1279=1269=048=17359555=6SZ683=358181270=10216.0271=3346=31023=110=098
1128=99=18035=X49=SAMPLE75=2016101134=346352=2005100919255836253257660=200510091925583625325765799=10000100268=1279=1269=048=17359555=6SZ683=358182270=10216.0271=4346=41023=110=099
1128=99=18035=X49=SAMPLE75=2016101134=489152=2012080714530929613529660=201208071453092961352965799=10000100268=1279=1269=148=17359555=6SZ683=358183270=10217.0271=4346=41023=110=111
1128=99=18135=X49=SAMPLE75=2016101134=207352=2007053109535084474579260=200705310953508447457925799=10000100268=1279=1269=048=17359555=6SZ683=358184270=10208.0271=18346=41023=910=175
1128=99=18235=X49=SAMPLE75=2016101134=139052=2014032217292722858304060=201403221729272285830405799=10000100268=1279=1269=048=17359555=6SZ683=358185270=10215.0271=20346=101023=210=199
1128=99=18135=X49=SAMPLE75=2016101134=421952=2013012810042271359776060=201301281004227135977605799=10000100268=1279=1269=148=17359555=6SZ683=358186270=10220.0271=15346=71023=410=146
1128=99=18135=X49=SAMPLE75=2016101134=215052=2015072006495657583116860=201507200649565758311685799=10000100268=1279=1269=048=17359555=6SZ683=358187270=10212.0271=24346=91023=510=174
1128=99=18235=X49=SAMPLE75=2016101134=88952=2004011910321501981225660=200401191032150198122565799=10000100268=1279=1269=048=17359555=6SZ683=358188270=10212.0271=31346=101023=510=225
1128=99=18135=X49=SAMPLE75=2016101134=288052=2004041808465359075865660=200404180846535907586565799=10000100268=1279=1269=048=17359555=6SZ683=358189270=10212.0271=24346=91023=510=188
1128=99=18235=X49=SAMPLE75=2016101134=467752=2014052110473936121708860=201405211047393612170885799=10000100268=1279=1269=048=17359555=6SZ683=358190270=10212.0271=31346=101023=510=188
1128=99=18135=X49=SAMPLE75=2016101134=258552=2008122917184984227984060=200812291718498422798405799=10000100268=1279=1269=048=17359555=6SZ683=358191270=10212.0271=24346=91023=510=188
1128=99=18235=X49=SAMPLE75=2016101134=427852=2001013006530881579824860=200101300653088157982485799=10000100268=1279=1269=048=17359555=6SZ683=358192270=10212.0271=31346=101023=510=211
1128=99=25435=X49=SAMPLE75=2016101134=276252=2007051314405764182224060=200705131440576418222405799=10000100268=2279=1269=048=17359555=6SZ683=358193270=10215.0271=21346=111023=2279=1269=048=17359555=6SZ683=358194270=10214.0271=17346=91023=310=049
1128=99=18135=X49=SAMPLE75=2016101134=203252=2007022522321307835043260=200702252232130783504325799=10000100268=1279=1269=048=17359555=6SZ683=358195270=10212.0271=24346=91023=510=161
1128=99=18235=X49=SAMPLE75=2016101134=208252=2006080420550702038934460=200608042055070203893445799=10000100268=1279=1269=048=17359555=6SZ683=358196270=10212.0271=31346=101023=510=209
1128=99=18135=X49=SAMPLE75=2016101134=492952=2007041302484291320313660=200704130248429132031365799=10000100268=1279=1269=048=17359555=6SZ683=358197270=10212.0271=24346=91023=510=168
1128=99=18235=X49=SAMPLE75=2016101134=9352=2008080515322919471036860=200808051532291947103685799=10000100268=1279=1269=048=17359555=6SZ683=358198270=10212.0271=31346=101023=510=228
1128=99=18035=X49=SAMPLE75=2016101134=258952=2009050217334312961318460=200905021733431296131845799=10000100268=1279=1269=148=17359555=6SZ683=358199270=10217.0271=3346=31023=110=141
1128=99=18035=X49=SAMPLE75=2016101134=54152=2013112523594454937222460=201311252359445493722245799=10000100268=1279=1269=048=17359555=6SZ683=358200270=10216.0271=5346=51023=110=116
1128=99=18035=X49=SAMPLE75=2016101134=160252=2004012204494960025792060=200401220449496002579205799=10000100268=1279=1269=148=17359555=6SZ683=358201270=10217.0271=4346=41023=110=097
1128=99=18035=X49=SAMPLE75=2016101134=223252=2004010608515672114705660=200401060851567211470565799=10000100268=1279=1269=048=17359555=6SZ683=358202270=10216.0271=4346=41023=110=100
1128=99=18035=X49=SAMPLE75=2016101134=217952=2015081400032304160985660=201508140003230416098565799=10000100268=1279=1269=048=17359555=6SZ683=358203270=10216.0271=3346=31023=110=097
1128=99=18035=X49=SAMPLE75=2016101134=167752=2005092902450142498025660=200509290245014249802565799=10000100268=1279=1269=148=17359555=6SZ683=358204270=10217.0271=5346=51023=110=115
1128=99=18035=X49=SAMPLE75=2016101134=487852=2014101912340238505510460=201410191234023850551045799=10000100268=1279=1269=048=17359555=6SZ683=358205270=10216.0271=2346=21023=110=119
1128=99=25535=X49=SAMPLE75=2016101134=317452=2001110109270094793175260=200111010927009479317525799=10000100268=2279=1269=048=17359555=6SZ683=358206270=10215.0271=20346=101023=2279=1269=048=17359555=6SZ683=358207270=10214.0271=18346=101023=310=097
1128=99=18035=X49=SAMPLE75=2016101134=352752=2010121707260901437056060=201012170726090143705605799=10000100268=1279=1269=048=17359555=6SZ683=358208270=10216.0271=3346=31023=110=112
1128=99=18035=X49=SAMPLE75=2016101134=469652=2012062319085267944742460=201206231908526794474245799=10000100268=1279=1269=048=17359555=6SZ683=358209270=10216.0271=4346=41023=110=101
1128=99=25435=X49=SAMPLE75=2016101134=360052=2000082715081685412205260=200008271508168541220525799=10000100268=2279=1269=048=17359555=6SZ683=358210270=10215.0271=21346=111023=2279=1269=048=17359555=6SZ683=358211270=10214.0271=17346=91023=310=049
1128=99=18035=X49=SAMPLE75=2016101134=167452=2010031918400783117651260=201003191840078311765125799=10000100268=1279=1269=148=17359555=6SZ683=358212270=10217.0271=4346=41023=110=129
1128=99=25535=X49=SAMPLE75=2016101134=54252=2000122319034828935333260=200012231903482893533325799=10000100268=2279=1269=048=17359555=6SZ683=358213270=10215.0271=20346=101023=2279=1269=048=17359555=6SZ683=358214270=10214.0271=18346=101023=310=076
1128=99=18035=X49=SAMPLE75=2016101134=70352=2000021108101399777945660=200002110810139977794565799=10000100268=1279=1269=048=17359555=6SZ683=358215270=10216.0271=3346=31023=110=105
1128=99=18035=X49=SAMPLE75=2016101134=202352=2012072111231761338067260=201207211123176133806725799=10000100268=1279=1269=148=17359555=6SZ683=358216270=10217.0271=5346=51023=110=085
1128=99=18035=X49=SAMPLE75=2016101134=413152=2003050204492343015817660=200305020449234301581765799=10000100268=1279=1269=048=17359555=6SZ683=358217270=10216.0271=4346=41023=110=104
1128=99=25435=X49=SAMPLE75=2016101134=363252=2009082013581554687398460=200908201358155468739845799=10000100268=2279=1269=048=17359555=6SZ683=358218270=10215.0271=21346=111023=2279=1269=048=17359555=6SZ683=358219270=10214.0271=17346=91023=310=025
1128=99=25535=X49=SAMPLE75=2016101134=377752=2006020218143393633008060=200602021814339363300805799=10000100268=2279=1269=048=17359555=6SZ683=358220270=10215.0271=20346=101023=2279=1269=048=17359555=6SZ683=358221270=10214.0271=18346=101023=310=075
1128=99=18035=X49=SAMPLE75=2016101134=212352=2004103120520563010316860=200410312052056301031685799=10000100268=1279=1269=148=17359555=6SZ683=358222270=10217.0271=4346=41023=110=108
1128=99=18035=X49=SAMPLE75=2016101134=19352=2000080307054781517201260=200008030705478151720125799=10000100268=1279=1269=148=17359555=6SZ683=358223270=10217.0271=5346=51023=110=123
1128=99=25335=X49=SAMPLE75=2016101134=459352=2008050706553580238425660=200805070655358023842565799=10000100268=2279=1269=148=17359555=6SZ683=358224270=10220.0271=18346=81023=4279=1269=148=17359555=6SZ683=358225270=10221.0271=23346=91023=510=008
1128=99=18035=X49=SAMPLE75=2016101134=302752=2014012401454385812595260=201401240145438581259525799=10000100268=1279=1269=148=17359555=6SZ683=358226270=10217.0271=4346=41023=110=112
1128=99=18035=X49=SAMPLE75=2016101134=265352=2007111409391565205120060=200711140939156520512005799=10000100268=1279=1269=048=17359555=6SZ683=358227270=10216.0271=3346=31023=110=095
1128=99=18035=X49=SAMPLE75=2016101134=113852=2008022412162091135702460=200802241216209113570245799=10000100268=1279=1269=048=17359555=6SZ683=358228270=10216.0271=2346=21023=110=083
1128=99=18035=X49=SAMPLE75=2016101134=410252=2006102110353482952806460=200610211035348295280645799=10000100268=1279=1269=048=17359555=6SZ683=358229270=10216.0271=1346=11023=110=101
1128=99=20835=X49=SAMPLE75=2016101134=147752=2009090622481043759334460=200909062248104375933445799=00000001268=1279=0269=248=17359555=6SZ683=358230270=10216.0271=1346=25797=237705=237=032=137=032=110=060
1128=99=15635=X49=SAMPLE75=2016101134=122452=2009120810245805716320060=200912081024580571632005799=00000010268=1279=0269=e48=17359555=6SZ683=358231271=9010=098
1128=99=25335=X49=SAMPLE75=2016101134=441852=2012051201413927582585660=201205120141392758258565799=10000100268=2279=2269=048=17359555=6SZ683=358232270=10216.0271=1346=11023=1279=0269=048=17359555=6SZ683=358233270=10206.0271=39346=61023=1010=249
1128=99=17935=X49=SAMPLE75=2016101134=57952=2000051615574695608368060=200005161557469560836805799=10000100268=1279=0269=148=17360055=6SH783=99476270=10272.0271=3346=11023=110=039
1128=99=17935=X49=SAMPLE75=2016101134=80752=2016102112413627909043260=201610211241362790904325799=10000100268=1279=0269=148=17360055=6SH783=99477270=10273.0271=1346=11023=210=055
1128=99=17935=X49=SAMPLE75=2016101134=284252=2016052610572062738681660=201605261057206273868165799=10000100268=1279=1269=048=17360055=6SH783=99478270=10268.0271=5346=21023=110=066
1128=99=18135=X49=SAMPLE75=2016101134=189252=2001030120401822566913660=200103012040182256691365799=10000100268=1279=1269=048=17359555=6SZ683=358234270=10211.0271=22346=81023=510=170
1128=99=18035=X49=SAMPLE75=2016101134=78152=2008090807151885982694460=200809080715188598269445799=10000100268=1279=1269=148=17360055=6SH783=99479270=10276.0271=37346=31023=510=115
1128=99=17935=X49=SAMPLE75=2016101134=460452=2016021014205714026380860=201602101420571402638085799=10000100268=1279=1269=148=17360055=6SH783=99480270=10273.0271=4346=21023=210=027
1128=99=25035=X49=SAMPLE75=2016101134=362452=2002100611103845312686460=200210061110384531268645799=10000100268=2279=2269=148=17360055=6SH783=99481270=10272.0271=3346=11023=1279=0269=148=17360055=6SH783=99482270=10282.0271=3346=11023=1010=053
1128=99=17935=X49=SAMPLE75=2016101134=145752=2016080320374776704076860=201608032037477670407685799=10000100268=1279=1269=148=17360055=6SH783=99483270=10273.0271=1346=11023=110=028
1128=99=18135=X49=SAMPLE75=2016101134=457252=2014101320211991909017660=201410132021199190901765799=10000100268=1279=1269=048=17359555=6SZ683=358235270=10212.0271=24346=91023=410=157
1128=99=25135=X49=SAMPLE75=2016101134=23652=2007072217203865027484860=200707221720386502748485799=10000100268=2279=1269=048=17360055=6SH783=99484270=10263.0271=3346=11023=6279=1269=048=17360055=6SH783=99485270=10259.0271=11346=21023=1010=125
1128=99=25135=X49=SAMPLE75=2016101134=361852=2010022517155133343372860=201002251715513334337285799=10000100268=2279=2269=148=17360055=6SH783=99486270=10273.0271=1346=11023=1279=0269=148=17360055=6SH783=99487270=10283.0271=61346=31023=1010=114
1128=99=17935=X49=SAMPLE75=2016101134=426352=2008060323090536156889660=200806032309053615688965799=10000100268=1279=1269=148=17360055=6SH783=99488270=10276.0271=4346=21023=310=065
1128=99=18035=X49=SAMPLE75=2016101134=176752=2004060510231326535283260=200406051023132653528325799=10000100268=1279=0269=048=17359555=6SZ683=358236270=10216.0271=1346=11023=110=109
1128=99=17935=X49=SAMPLE75=2016101134=429852=2007070618212131565264060=200707061821213156526405799=10000100268=1279=0269=048=17360055=6SH783=99489270=10269.0271=3346=11023=110=064
1128=99=17935=X49=SAMPLE75=2016101134=124052=2015051917094501860307260=201505191709450186030725799=10000100268=1279=1269=048=17360055=6SH783=99490270=10268.0271=6346=31023=210=069
1128=99=18135=X49=SAMPLE75=2016101134=120852=2003091603321149826563260=200309160332114982656325799=10000100268=1279=1269=048=17359555=6SZ683=358237270=10211.0271=24346=91023=610=174
1128=99=25335=X49=SAMPLE75=2016101134=203552=2014081500582193425267260=201408150058219342526725799=10000100268=2279=2269=048=17359555=6SZ683=358238270=10216.0271=1346=11023=1279=0269=048=17359555=6SZ683=358239270=10206.0271=39346=61023=1010=024
1128=99=17935=X49=SAMPLE75=2016101134=189652=2002071607501375555307260=200207160750137555530725799=10000100268=1279=1269=048=17360055=6SH783=99491270=10268.0271=5346=21023=210=071
1128=99=18035=X49=SAMPLE75=2016101134=182552=2004040803260188848648060=200404080326018884864805799=10000100268=1279=1269=148=17359555=6SZ683=358240270=10217.0271=5346=51023=110=130
1128=99=18135=X49=SAMPLE75=2016101134=164152=2003071319012589625833660=200307131901258962583365799=10000100268=1279=1269=048=17359555=6SZ683=358241270=10211.0271=22346=81023=510=176
1128=99=25135=X49=SAMPLE75=2016101134=137652=2004022514593463445083260=200402251459346344508325799=10000100268=2279=2269=048=17360055=6SH783=99492270=10269.0271=3346=11023=1279=0269=048=17360055=6SH783=99493270=10259.0271=11346=21023=1010=122
1128=99=18035=X49=SAMPLE75=2016101134=178252=2008051517194899369270460=200805151719489936927045799=10000100268=1279=0269=048=17359555=6SZ683=358242270=10216.0271=1346=11023=110=104
1128=99=17935=X49=SAMPLE75=2016101134=310752=2000062901062566904478060=200006290106256690447805799=10000100268=1279=1269=048=17360055=6SH783=99494270=10268.0271=6346=31023=110=078
1128=99=18135=X49=SAMPLE75=2016101134=298752=2007091720014878162284860=200709172001487816228485799=10000100268=1279=1269=048=17359555=6SZ683=358243270=10211.0271=24346=91023=610=164
1128=99=25335=X49=SAMPLE75=2016101134=443652=2008021311225096976275260=200802131122509697627525799=10000100268=2279=2269=048=17359555=6SZ683=358244270=10216.0271=1346=11023=1279=0269=048=17359555=6SZ683=358245270=10206.0271=39346=61023=1010=019
1128=99=17935=X49=SAMPLE75=2016101134=333752=2008053120302878318819260=200805312030287831881925799=10000100268=1279=1269=048=17360055=6SH783=99495270=10268.0271=5346=21023=110=084
1128=99=18135=X49=SAMPLE75=2016101134=116052=2008011109575139254732860=200801110957513925473285799=10000100268=1279=1269=048=17359555=6SZ683=358246270=10211.0271=22346=81023=510=176
1128=99=18035=X49=SAMPLE75=2016101134=195852=2001040106401415738372060=200104010640141573837205799=10000100268=1279=0269=048=17359555=6SZ683=358247270=10216.0271=1346=11023=110=121
1128=99=25335=X49=SAMPLE75=2016101134=406052=2007030212314801192912060=200703021231480119291205799=10000100268=2279=2269=048=17359555=6SZ683=358248270=10216.0271=1346=11023=1279=0269=048=17359555=6SZ683=358249270=10206.0271=39346=61023=1010=016
1128=99=17935=X49=SAMPLE75=2016101134=85752=2003051500483905888724860=200305150048390588872485799=10000100268=1279=1269=048=17360055=6SH783=99496270=10268.0271=6346=31023=110=075
1128=99=18035=X49=SAMPLE75=2016101134=408852=2012013120304362236800060=201201312030436223680005799=10000100268=1279=0269=048=17359555=6SZ683=358250270=10216.0271=1346=11023=110=093
1128=99=18135=X49=SAMPLE75=2016101134=46752=2002030409465055953421660=200203040946505595342165799=10000100268=1279=1269=048=17359555=6SZ683=358251270=10211.0271=24346=91023=610=190
1128=99=25335=X49=SAMPLE75=2016101134=117052=2005092017414782477961660=200509201741478247796165799=10000100268=2279=2269=048=17359555=6SZ683=358252270=10216.0271=1346=11023=1279=0269=048=17359555=6SZ683=358253270=10206.0271=39346=61023=1010=008
1128=99=17935=X49=SAMPLE75=2016101134=134152=2008040206394968261148860=200804020639496826114885799=10000100268=1279=1269=048=17360055=6SH783=99497270=10268.0271=5346=21023=110=091
1128=99=18135=X49=SAMPLE75=2016101134=224452=2016122408501970132928060=201612240850197013292805799=10000100268=1279=1269=048=17359555=6SZ683=358254270=10211.0271=22346=81023=510=199
1128=99=18035=X49=SAMPLE75=2016101134=186052=2012120421011615426867260=201212042101161542686725799=10000100268=1279=0269=048=17359555=6SZ683=358255270=10216.0271=1346=11023=110=117
1128=99=17935=X49=SAMPLE75=2016101134=62152=2004071704031747316393660=200407170403174731639365799=10000100268=1279=0269=048=17360055=6SH783=99498270=10269.0271=3346=11023=110=058
1128=99=17935=X49=SAMPLE75=2016101134=372752=2008051310473158576406460=200805131047315857640645799=10000100268=1279=1269=048=17360055=6SH783=99499270=10268.0271=6346=31023=210=083
1128=99=18135=X49=SAMPLE75=2016101134=272352=2017012200205055460435260=201701220020505546043525799=10000100268=1279=1269=048=17359555=6SZ683=358256270=10211.0271=24346=91023=610=187
1128=99=25335=X49=SAMPLE75=2016101134=11452=2011101111495501467520060=201110111149550146752005799=10000100268=2279=2269=048=17359555=6SZ683=358257270=10216.0271=1346=11023=1279=0269=048=17359555=6SZ683=358258270=10206.0271=39346=61023=1010=011
1128=99=17935=X49=SAMPLE75=2016101134=395152=2012111609220816676166460=201211160922081667616645799=10000100268=1279=1269=048=17360055=6SH783=99500270=10268.0271=5346=21023=210=069
1128=99=18135=X49=SAMPLE75=2016101134=355752=2001042704260243418976860=200104270426024341897685799=10000100268=1279=1269=048=17359555=6SZ683=358259270=10211.0271=22346=81023=510=202
1128=99=25135=X49=SAMPLE75=2016101134=80352=2006123021542232458121660=200612302154223245812165799=10000100268=2279=2269=048=17360055=6SH783=99501270=10269.0271=3346=11023=1279=0269=048=17360055=6SH783=99502270=10259.0271=11346=21023=1010=108
1128=99=18035=X49=SAMPLE75=2016101134=467452=2006031306134843608889660=200603130613484360888965799=10000100268=1279=0269=048=17359555=6SZ683=358260270=10216.0271=1346=11023=110=144
1128=99=17935=X49=SAMPLE75=2016101134=263352=2016080311393307392806460=201608031139330739280645799=10000100268=1279=1269=048=17360055=6SH783=99503270=10268.0271=6346=31023=110=066
1128=99=18135=X49=SAMPLE75=2016101134=469552=2014081002232087716563260=201408100223208771656325799=10000100268=1279=1269=048=17359555=6SZ683=358261270=10211.0271=24346=91023=610=193
1128=99=25335=X49=SAMPLE75=2016101134=221152=2012042605491902630060860=201204260549190263006085799=10000100268=2279=2269=048=17359555=6SZ683=358262270=10216.0271=1346=11023=1279=0269=048=17359555=6SZ683=358263270=10206.0271=39346=61023=1010=002
1128=99=17935=X49=SAMPLE75=2016101134=145352=2008122201355880330275260=200812220135588033027525799=10000100268=1279=1269=048=17360055=6SH783=99504270=10268.0271=5346=21023=110=055
1128=99=18135=X49=SAMPLE75=2016101134=293952=2005020215520776270464060=200502021552077627046405799=10000100268=1279=1269=048=17359555=6SZ683=358264270=10211.0271=22346=81023=510=180
1128=99=18035=X49=SAMPLE75=2016101134=263152=2010072014132303056320060=201007201413230305632005799=10000100268=1279=0269=048=17359555=6SZ683=358265270=10216.0271=1346=11023=110=105
1128=99=17935=X49=SAMPLE75=2016101134=364652=2000021318521057006352060=200002131852105700635205799=10000100268=1279=1269=048=17360055=6SH783=99505270=10268.0271=6346=31023=110=066
1128=99=18135=X49=SAMPLE75=2016101134=489652=2015082303214048375353660=201508230321404837535365799=10000100268=1279=1269=048=17359555=6SZ683=358266270=10211.0271=24346=91023=610=168
1128=99=18235=X49=SAMPLE75=2016101134=245252=2016061818301752424224060=201606181830175242422405799=10000100268=1279=1269=048=17359555=6SZ683=358267270=10212.0271=31346=101023=510=208
1128=99=25335=X49=SAMPLE75=2016101134=401752=2015061916040934475884860=201506191604093447588485799=10000100268=2279=2269=048=17359555=6SZ683=358268270=10216.0271=1346=11023=1279=0269=048=17359555=6SZ683=358269270=10206.0271=39346=61023=1010=023
1128=99=17935=X49=SAMPLE75=2016101134=497952=2003062702182835382001660=200306270218283538200165799=10000100268=1279=1269=048=17360055=6SH783=99506270=10268.0271=5346=21023=110=057
1128=99=18135=X49=SAMPLE75=2016101134=307552=2013010700424527550816060=201301070042452755081605799=10000100268=1279=1269=048=17359555=6SZ683=358270270=10211.0271=22346=81023=510=164
1128=99=18035=X49=SAMPLE75=2016101134=258852=2011100708080245413459260=201110070808024541345925799=10000100268=1279=0269=048=17359555=6SZ683=358271270=10216.0271=1346=11023=110=113
1128=99=17935=X49=SAMPLE75=2016101134=305252=2003111816372542497513660=200311181637254249751365799=10000100268=1279=1269=048=17360055=6SH783=99507270=10268.0271=6346=31023=110=054
1128=99=18135=X49=SAMPLE75=2016101134=60252=2013070807165577592640060=201307080716557759264005799=10000100268=1279=1269=048=17359555=6SZ683=358272270=10211.0271=24346=91023=610=181
1128=99=25335=X49=SAMPLE75=2016101134=52152=2006042307564912223129660=200604230756491222312965799=10000100268=2279=2269=048=17359555=6SZ683=358273270=10216.0271=1346=11023=1279=0269=048=17359555=6SZ683=358274270=10206.0271=39346=61023=1010=249
1128=99=17935=X49=SAMPLE75=2016101134=207952=2002121519230615956251260=200212151923061595625125799=10000100268=1279=1269=048=17360055=6SH783=99508270=10268.0271=5346=21023=110=058
1128=99=18135=X49=SAMPLE75=2016101134=174152=2001032410243136287048860=200103241024313628704885799=10000100268=1279=1269=048=17359555=6SZ683=358275270=10211.0271=22346=81023=510=166
1128=99=18035=X49=SAMPLE75=2016101134=33252=2005110718132215337504060=200511071813221533750405799=10000100268=1279=0269=048=17359555=6SZ683=358276270=10216.0271=1346=11023=110=117
1128=99=17935=X49=SAMPLE75=2016101134=255352=2005112016592875524441660=200511201659287552444165799=10000100268=1279=1269=048=17360055=6SH783=99509270=10268.0271=6346=31023=110=051
1128=99=25335=X49=SAMPLE75=2016101134=464952=2007031621205517992291260=200703162120551799229125799=10000100268=2279=2269=048=17359555=6SZ683=358277270=10216.0271=1346=11023=1279=0269=048=17359555=6SZ683=358278270=10206.0271=39346=61023=1010=018
1128=99=17935=X49=SAMPLE75=2016101134=88052=2007061311580358228041660=200706131158035822804165799=10000100268=1279=1269=048=17360055=6SH783=99510270=10268.0271=5346=21023=110=039
1128=99=18035=X49=SAMPLE75=2016101134=320752=2005081715274412877619260=200508171527441287761925799=10000100268=1279=0269=048=17359555=6SZ683=358279270=10216.0271=1346=11023=110=114
1128=99=17935=X49=SAMPLE75=2016101134=272452=2015020915021434606406460=201502091502143460640645799=10000100268=1279=1269=048=17360055=6SH783=99511270=10268.0271=6346=31023=110=048
1128=99=18135=X49=SAMPLE75=2016101134=103052=2015030513274699072172860=201503051327469907217285799=10000100268=1279=1269=048=17359555=6SZ683=358280270=10211.0271=24346=91023=610=166
1128=99=25335=X49=SAMPLE75=2016101134=350152=2004081321132095761286460=200408132113209576128645799=10000100268=2279=2269=048=17359555=6SZ683=358281270=10216.0271=1346=11023=1279=0269=048=17359555=6SZ683=358282270=10206.0271=39346=61023=1010=243
1128=99=17935=X49=SAMPLE75=2016101134=290552=2012091809243174374681660=201209180924317437468165799=10000100268=1279=1269=048=17360055=6SH783=99512270=10268.0271=5346=21023=110=058
1128=99=18135=X49=SAMPLE75=2016101134=214852=2011072014282847991712060=201107201428284799171205799=10000100268=1279=1269=048=17359555=6SZ683=358283270=10211.0271=22346=81023=510=162
1128=99=18035=X49=SAMPLE75=2016101134=280152=2004070200124280265672060=200407020012428026567205799=10000100268=1279=0269=048=17359555=6SZ683=358284270=10216.0271=1346=11023=110=117
1128=99=17935=X49=SAMPLE75=2016101134=2552=2001071916525174952662460=200107191652517495266245799=10000100268=1279=1269=048=17360055=6SH783=99513270=10268.0271=6346=31023=110=054
1128=99=18135=X49=SAMPLE75=2016101134=107352=2000022219305839273385260=200002221930583927338525799=10000100268=1279=1269=048=17359555=6SZ683=358285270=10211.0271=24346=91023=610=168
1128=99=25335=X49=SAMPLE75=2016101134=255452=2004032015363074394934460=200403201536307439493445799=10000100268=2279=2269=048=17359555=6SZ683=358286270=10216.0271=1346=11023=1279=0269=048=17359555=6SZ683=358287270=10206.0271=39346=61023=1010=005
1128=99=17935=X49=SAMPLE75=2016101134=237852=2001101423435643791475260=200110142343564379147525799=10000100268=1279=1269=048=17360055=6SH783=99514270=10268.0271=5346=21023=110=040
1128=99=18135=X49=SAMPLE75=2016101134=14552=2012110705523661987916860=201211070552366198791685799=10000100268=1279=1269=048=17359555=6SZ683=358288270=10211.0271=22346=81023=510=157
1128=99=18035=X49=SAMPLE75=2016101134=392752=2017010200591162689728060=201701020059116268972805799=10000100268=1279=0269=048=17359555=6SZ683=358289270=10216.0271=1346=11023=110=138
1128=99=17935=X49=SAMPLE75=2016101134=491352=2013040922165524979571260=201304092216552497957125799=10000100268=1279=1269=048=17360055=6SH783=99515270=10268.0271=6346=31023=110=079
1128=99=18135=X49=SAMPLE75=2016101134=84352=2010071417453888569203260=201007141745388856920325799=10000100268=1279=1269=048=17359555=6SZ683=358290270=10211.0271=24346=91023=610=172
1128=99=25335=X49=SAMPLE75=2016101134=287952=2001030517051784993595260=200103051705178499359525799=10000100268=2279=2269=048=17359555=6SZ683=358291270=10216.0271=1346=11023=1279=0269=048=17359555=6SZ683=358292270=10206.0271=39346=61023=1010=002
1128=99=17935=X49=SAMPLE75=2016101134=465152=2015080907251525915910460=201508090725152591591045799=10000100268=1279=1269=048=17360055=6SH783=99516270=10268.0271=5346=21023=110=077
1128=99=18135=X49=SAMPLE75=2016101134=26752=2009010709312213012371260=200901070931221301237125799=10000100268=1279=1269=048=17359555=6SZ683=358293270=10211.0271=22346=81023=510=186
1128=99=18135=X49=SAMPLE75=2016101134=388552=2002051500255417544779260=200205150025541754477925799=10000100268=1279=1269=048=17359555=6SZ683=358294270=10212.0271=24346=91023=410=189
1128=99=18235=X49=SAMPLE75=2016101134=383952=2012032615441878289676860=201203261544187828967685799=10000100268=1279=1269=048=17359555=6SZ683=358295270=10212.0271=31346=101023=410=245
1128=99=18035=X49=SAMPLE75=2016101134=390452=2003041405315208550940860=200304140531520855094085799=10000100268=1279=0269=048=17359555=6SZ683=358296270=10216.0271=1346=11023=110=122
1128=99=17935=X49=SAMPLE75=2016101134=109452=2003071102093068882404860=200307110209306888240485799=10000100268=1279=0269=048=17360055=6SH783=99517270=10269.0271=3346=11023=110=053
1128=99=17935=X49=SAMPLE75=2016101134=307252=2011041316274087817894460=201104131627408781789445799=10000100268=1279=1269=048=17360055=6SH783=99518270=10268.0271=6346=31023=210=061
1128=99=18135=X49=SAMPLE75=2016101134=323252=2005021617241782181996860=200502161724178218199685799=10000100268=1279=1269=048=17359555=6SZ683=358297270=10211.0271=24346=91023=610=163
1128=99=25335=X49=SAMPLE75=2016101134=470352=2007062605442863854723260=200706260544286385472325799=10000100268=2279=2269=048=17359555=6SZ683=358298270=10216.0271=1346=11023=1279=0269=048=17359555=6SZ683=358299270=10206.0271=39346=61023=1010=025
1128=99=17935=X49=SAMPLE75=2016101134=4952=2006112911000304690300860=200611291100030469030085799=10000100268=1279=1269=048=17360055=6SH783=99519270=10268.0271=5346=21023=210=043
1128=99=18135=X49=SAMPLE75=2016101134=75352=2007010613265461283257660=200701061326546128325765799=10000100268=1279=1269=048=17359555=6SZ683=358300270=10211.0271=22346=81023=510=156
1128=99=25135=X49=SAMPLE75=2016101134=38552=2005121608354216499388860=200512160835421649938885799=10000100268=2279=2269=048=17360055=6SH783=99520270=10269.0271=3346=11023=1279=0269=048=17360055=6SH783=99521270=10259.0271=11346=21023=1010=096
1128=99=18035=X49=SAMPLE75=2016101134=149352=2001080611070207207319260=200108061107020720731925799=10000100268=1279=0269=048=17359555=6SZ683=358301270=10216.0271=1346=11023=110=122
1128=99=17935=X49=SAMPLE75=2016101134=466852=2013112106092349116505660=201311210609234911650565799=10000100268=1279=1269=048=17360055=6SH783=99522270=10268.0271=6346=31023=110=083
1128=99=18135=X49=SAMPLE75=2016101134=145852=2009022505014099775276860=200902250501409977527685799=10000100268=1279=1269=048=17359555=6SZ683=358302270=10211.0271=24346=91023=610=184
1128=99=18035=X49=SAMPLE75=2016101134=2652=2011061604550923800531260=201106160455092380053125799=10000100268=1279=1269=048=17359555=6SZ683=358303270=10216.0271=2346=21023=110=105
1128=99=18135=X49=SAMPLE75=2016101134=283352=2008071104145314957945660=200807110414531495794565799=10000100268=1279=1269=048=17359555=6SZ683=358304270=10212.0271=24346=91023=510=175
1128=99=18235=X49=SAMPLE75=2016101134=174252=2001050900200147027667260=200105090020014702766725799=10000100268=1279=1269=048=17359555=6SZ683=358305270=10212.0271=31346=101023=510=216
1128=99=25435=X49=SAMPLE75=2016101134=248452=2002061605594030334518460=200206160559403033451845799=10000100268=2279=1269=148=17359555=6SZ683=358306270=10220.0271=15346=71023=4279=1269=148=17359555=6SZ683=358307270=10221.0271=26346=101023=510=065
1128=99=18035=X49=SAMPLE75=2016101134=231252=2010041404493511328774460=201004140449351132877445799=10000100268=1279=1269=148=17359555=6SZ683=358308270=10217.0271=4346=41023=110=122
1128=99=18035=X49=SAMPLE75=2016101134=327152=2014041200245392444627260=201404120024539244462725799=10000100268=1279=1269=048=17359555=6SZ683=358309270=10216.0271=3346=31023=110=148
1128=99=18035=X49=SAMPLE75=2016101134=414052=2001120509115148359798460=200112050911514835979845799=10000100268=1279=1269=048=17359555=6SZ683=358310270=10216.0271=2346=21023=110=119
1128=99=18035=X49=SAMPLE75=2016101134=412952=2008083007480802982115260=200808300748080298211525799=10000100268=1279=1269=048=17359555=6SZ683=358311270=10216.0271=1346=11023=110=097
1128=99=25335=X49=SAMPLE75=2016101134=432452=2015110800523063689152060=201511080052306368915205799=10000100268=2279=1269=148=17359555=6SZ683=358312270=10220.0271=18346=81023=4279=1269=148=17359555=6SZ683=358313270=10221.0271=23346=91023=510=009
1128=99=18035=X49=SAMPLE75=2016101134=188552=2015081216461618102278460=201508121646161810227845799=10000100268=1279=1269=148=17359555=6SZ683=358314270=10217.0271=5346=51023=110=118
1128=99=18035=X49=SAMPLE75=2016101134=411552=2012080809201035745587260=201208080920103574558725799=10000100268=1279=1269=048=17359555=6SZ683=358315270=10216.0271=2346=21023=110=108
1128=99=18035=X49=SAMPLE75=2016101134=152852=2008121408341333621635260=200812140834133362163525799=10000100268=1279=1269=048=17359555=6SZ683=358316270=10216.0271=3346=31023=110=114
1128=99=25435=X49=SAMPLE75=2016101134=9352=2014071912500214621273660=201407191250021462127365799=10000100268=2279=1269=148=17359555=6SZ683=358317270=10220.0271=15346=71023=4279=1269=148=17359555=6SZ683=358318270=10221.0271=26346=101023=510=057
1128=99=25335=X49=SAMPLE75=2016101134=136952=2000090806301268362762860=200009080630126836276285799=10000100268=2279=1269=148=17359555=6SZ683=358319270=10220.0271=18346=81023=4279=1269=148=17359555=6SZ683=358320270=10221.0271=23346=91023=510=007
1128=99=25435=X49=SAMPLE75=2016101134=318852=2002081003064986309227260=200208100306498630922725799=10000100268=2279=1269=148=17359555=6SZ683=358321270=10220.0271=15346=71023=4279=1269=148=17359555=6SZ683=358322270=10221.0271=26346=101023=510=057
1128=99=18035=X49=SAMPLE75=2016101134=167552=2005041410194575015193660=200504141019457501519365799=10000100268=1279=1269=148=17359555=6SZ683=358323270=10217.0271=4346=41023=110=136
1128=99=18035=X49=SAMPLE75=2016101134=277852=2006050511521830765612860=200605051152183076561285799=10000100268=1279=1269=048=17359555=6SZ683=358324270=10216.0271=4346=41023=110=130
1128=99=18035=X49=SAMPLE75=2016101134=367952=2016010413303189516633660=201601041330318951663365799=10000100268=1279=1269=148=17359555=6SZ683=358325270=10217.0271=5346=51023=110=129
1128=99=18235=X49=SAMPLE75=2016101134=384852=2006122122104410135657660=200612212210441013565765799=10000100268=1279=1269=048=17359555=6SZ683=358326270=10213.0271=18346=101023=410=218
1128=99=18235=X49=SAMPLE75=2016101134=290752=2000112123574430213788460=200011212357443021378845799=10000100268=1279=1269=148=17359555=6SZ683=358327270=10221.0271=27346=111023=510=227
1128=99=18035=X49=SAMPLE75=2016101134=197452=2005030704085805823772860=200503070408580582377285799=10000100268=1279=1269=048=17359555=6SZ683=358328270=10216.0271=3346=31023=110=132
1128=99=18035=X49=SAMPLE75=2016101134=380252=2015120503280425151404860=201512050328042515140485799=10000100268=1279=1269=148=17359555=6SZ683=358329270=10217.0271=4346=41023=110=119
1128=99=18035=X49=SAMPLE75=2016101134=134652=2016080720014544742246460=201608072001454474224645799=10000100268=1279=1269=148=17359555=6SZ683=358330270=10217.0271=5346=51023=110=088
1128=99=18035=X49=SAMPLE75=2016101134=234552=2005012719301660130224060=200501271930166013022405799=10000100268=1279=1269=148=17359555=6SZ683=358331270=10217.0271=4346=41023=110=123
1128=99=18135=X49=SAMPLE75=2016101134=54652=2009061404484009509516860=200906140448400950951685799=10000100268=1279=1269=048=17359555=6SZ683=358332270=10212.0271=24346=91023=510=161
1128=99=18235=X49=SAMPLE75=2016101134=203452=2014122104582197622944060=201412210458219762294405799=10000100268=1279=1269=048=17359555=6SZ683=358333270=10212.0271=31346=101023=510=217
1128=99=18135=X49=SAMPLE75=2016101134=48952=2003052907195577027436860=200305290719557702743685799=10000100268=1279=1269=048=17359555=6SZ683=358334270=10212.0271=24346=91023=510=139
1128=99=25135=X49=SAMPLE75=2016101134=267252=2004060721254502743379260=200406072125450274337925799=10000100268=2279=1269=048=17360055=6SH783=99523270=10263.0271=11346=21023=6279=1269=048=17360055=6SH783=99524270=10259.0271=3346=11023=1010=095
1128=99=18235=X49=SAMPLE75=2016101134=119652=2013122323420565776377660=201312232342056577637765799=10000100268=1279=1269=048=17359555=6SZ683=358335270=10212.0271=31346=101023=510=193
1128=99=18135=X49=SAMPLE75=2016101134=261452=2010091417305729098528060=201009141730572909852805799=10000100268=1279=1269=048=17359555=6SZ683=358336270=10212.0271=24346=91023=510=181
1128=99=18235=X49=SAMPLE75=2016101134=30752=2017011118463705603641660=201701111846370560364165799=10000100268=1279=1269=048=17359555=6SZ683=358337270=10212.0271=31346=101023=510=221
1128=99=18135=X49=SAMPLE75=2016101134=200452=2006112908202849898793660=200611290820284989879365799=10000100268=1279=1269=048=17359555=6SZ683=358338270=10212.0271=24346=91023=510=177
1128=99=18235=X49=SAMPLE75=2016101134=91652=2006021920303208877315260=200602192030320887731525799=10000100268=1279=1269=048=17359555=6SZ683=358339270=10212.0271=31346=101023=510=209
1128=99=18135=X49=SAMPLE75=2016101134=187152=2012120603035573171219260=201212060303557317121925799=10000100268=1279=1269=048=17359555=6SZ683=358340270=10212.0271=24346=91023=510=177
1128=99=18135=X49=SAMPLE75=2016101134=7852=2006031708033598128569660=200603170803359812856965799=10000100268=1279=1269=148=17359555=6SZ683=358341270=10220.0271=14346=61023=410=125
1128=99=18035=X49=SAMPLE75=2016101134=185552=2010042923394425886854460=201004292339442588685445799=10000100268=1279=1269=048=17359555=6SZ683=358342270=10216.0271=2346=21023=110=099
1128=99=18035=X49=SAMPLE75=2016101134=245552=2011061117182742799232060=201106111718274279923205799=10000100268=1279=1269=148=17359555=6SZ683=358343270=10217.0271=5346=51023=110=118
1128=99=18035=X49=SAMPLE75=2016101134=133252=2016070620002161782252860=201607062000216178225285799=10000100268=1279=1269=048=17359555=6SZ683=358344270=10216.0271=1346=11023=110=103
1128=99=25335=X49=SAMPLE75=2016101134=132052=2004032611452653123289660=200403261145265312328965799=10000100268=2279=2269=048=17359555=6SZ683=358345270=10216.0271=1346=11023=1279=0269=048=17359555=6SZ683=358346270=10206.0271=39346=61023=1010=011
1128=99=17935=X49=SAMPLE75=2016101134=246252=2014092721141076279097660=201409272114107627909765799=10000100268=1279=1269=048=17360055=6SH783=99525270=10268.0271=5346=21023=110=047
1128=99=18135=X49=SAMPLE75=2016101134=347652=2000010405491136962464460=200001040549113696246445799=10000100268=1279=1269=048=17359555=6SZ683=358347270=10211.0271=22346=81023=510=174
1128=99=18235=X49=SAMPLE75=2016101134=487252=2010051111015095769856060=201005111101509576985605799=10000100268=1279=1269=048=17359555=6SZ683=358348270=10212.0271=25346=101023=410=214
1128=99=18135=X49=SAMPLE75=2016101134=208352=2011082023261598245932860=201108202326159824593285799=10000100268=1279=1269=048=17359555=6SZ683=358349270=10213.0271=17346=91023=310=150
1128=99=18135=X49=SAMPLE75=2016101134=137652=2008050823023506867392060=200805082302350686739205799=10000100268=1279=1269=148=17359555=6SZ683=358350270=10220.0271=15346=71023=410=174
1128=99=25435=X49=SAMPLE75=2016101134=479352=2011052016221581883046460=201105201622158188304645799=10000100268=2279=1269=148=17359555=6SZ683=358351270=10220.0271=18346=81023=4279=1269=148=17359555=6SZ683=358352270=10221.0271=24346=101023=510=064
1128=99=18035=X49=SAMPLE75=2016101134=433852=2016121110450653917766460=201612111045065391776645799=10000100268=1279=1269=048=17360055=6SH783=99526270=10263.0271=12346=31023=610=067
1128=99=25135=X49=SAMPLE75=2016101134=401952=2005111311495956486464060=200511131149595648646405799=10000100268=2279=1269=048=17360055=6SH783=99527270=10263.0271=4346=21023=6279=1269=048=17360055=6SH783=99528270=10259.0271=11346=21023=1010=124
1128=99=18135=X49=SAMPLE75=2016101134=493652=2007040902071564214435260=200704090207156421443525799=10000100268=1279=1269=048=17359555=6SZ683=358353270=10215.0271=12346=91023=110=170
1128=99=18235=X49=SAMPLE75=2016101134=106052=2001032504492814398765660=200103250449281439876565799=10000100268=1279=1269=048=17359555=6SZ683=358354270=10215.0271=13346=101023=110=214
1128=99=18135=X49=SAMPLE75=2016101134=88052=2016080321314720240102460=201608032131472024010245799=10000100268=1279=1269=048=17359555=6SZ683=358355270=10215.0271=12346=91023=110=172
1128=99=18135=X49=SAMPLE75=2016101134=431352=2008022903084055981590460=200802290308405598159045799=10000100268=1279=1269=048=17359555=6SZ683=358356270=10214.0271=17346=91023=210=165
1128=99=18135=X49=SAMPLE75=2016101134=414452=2007072112293138986550460=200707211229313898655045799=10000100268=1279=1269=048=17359555=6SZ683=358357270=10208.0271=19346=51023=810=175
1128=99=25335=X49=SAMPLE75=2016101134=453852=2017022209535064932025660=201702220953506493202565799=10000100268=2279=1269=048=17359555=6SZ683=358358270=10212.0271=17346=91023=4279=1269=048=17359555=6SZ683=358359270=10208.0271=27346=61023=810=012
1128=99=18135=X49=SAMPLE75=2016101134=88952=2006080902483657524105660=200608090248365752410565799=10000100268=1279=1269=048=17359555=6SZ683=358360270=10215.0271=11346=81023=110=138
1128=99=18135=X49=SAMPLE75=2016101134=26652=2016012406395299347635260=201601240639529934763525799=10000100268=1279=1269=048=17359555=6SZ683=358361270=10207.0271=21346=61023=910=148
1128=99=18035=X49=SAMPLE75=2016101134=116452=2015032009505393815744060=201503200950539381574405799=10000100268=1279=0269=048=17359555=6SZ683=358362270=10216.0271=1346=11023=110=099
1128=99=17935=X49=SAMPLE75=2016101134=478752=2009042210555811856473660=200904221055581185647365799=10000100268=1279=0269=048=17360055=6SH783=99529270=10269.0271=3346=11023=110=052
1128=99=17935=X49=SAMPLE75=2016101134=316352=2011052702410822533145660=201105270241082253314565799=10000100268=1279=1269=048=17360055=6SH783=99530270=10268.0271=6346=31023=210=046
1128=99=18035=X49=SAMPLE75=2016101134=142352=2001072515060936802251260=200107251506093680225125799=10000100268=1279=1269=148=17359555=6SZ683=358363270=10217.0271=4346=41023=110=125
1128=99=18135=X49=SAMPLE75=2016101134=308852=2001111414004631544992060=200111141400463154499205799=10000100268=1279=1269=048=17359555=6SZ683=358364270=10211.0271=24346=91023=610=154
1128=99=18035=X49=SAMPLE75=2016101134=431852=2004052407593894135374460=200405240759389413537445799=10000100268=1279=1269=048=17359555=6SZ683=358365270=10216.0271=2346=21023=110=104
1128=99=18235=X49=SAMPLE75=2016101134=404652=2016050422444935219545660=201605042244493521954565799=10000100268=1279=1269=048=17359555=6SZ683=358366270=10207.0271=20346=51023=1010=206
1128=99=18135=X49=SAMPLE75=2016101134=122952=2011113023043583143366460=201111302304358314336645799=10000100268=1279=1269=048=17359555=6SZ683=358367270=10215.0271=12346=91023=210=160
1128=99=18035=X49=SAMPLE75=2016101134=38352=2003101418342380930265660=200310141834238093026565799=10000100268=1279=1269=048=17359555=6SZ683=358368270=10216.0271=3346=31023=110=109
1128=99=18035=X49=SAMPLE75=2016101134=32152=2017012414505117889932860=201701241450511788993285799=10000100268=1279=1269=048=17359555=6SZ683=358369270=10216.0271=4346=41023=110=103
1128=99=18035=X49=SAMPLE75=2016101134=134452=2014092601092854218739260=201409260109285421873925799=10000100268=1279=1269=048=17359555=6SZ683=358370270=10216.0271=5346=51023=110=105
1128=99=25135=X49=SAMPLE75=2016101134=439152=2005091618491264222883260=200509161849126422288325799=10000100268=2279=2269=048=17360055=6SH783=99531270=10269.0271=3346=11023=1279=0269=048=17360055=6SH783=99532270=10259.0271=11346=21023=1010=102
1128=99=18235=X49=SAMPLE75=2016101134=234452=2001022513161320898472060=200102251316132089847205799=10000100268=1279=1269=048=17359555=6SZ683=358371270=10215.0271=20346=101023=210=191
1128=99=18235=X49=SAMPLE75=2016101134=219852=2003112621152708583233660=200311262115270858323365799=10000100268=1279=1269=048=17359555=6SZ683=358372270=10212.0271=24346=101023=510=190
1128=99=25435=X49=SAMPLE75=2016101134=290552=2010050104143664497881660=201005010414366449788165799=10000100268=2279=1269=048=17359555=6SZ683=358373270=10212.0271=32346=111023=5279=1269=048=17359555=6SZ683=358374270=10208.0271=19346=51023=910=079
1128=99=18235=X49=SAMPLE75=2016101134=477052=2008020622185783600982460=200802062218578360098245799=10000100268=1279=1269=048=17359555=6SZ683=358375270=10212.0271=25346=101023=510=200
1128=99=25435=X49=SAMPLE75=2016101134=375152=2013101515195767382080060=201310151519576738208005799=10000100268=2279=1269=148=17359555=6SZ683=358376270=10220.0271=15346=71023=4279=1269=148=17359555=6SZ683=358377270=10221.0271=27346=111023=510=067
1128=99=18235=X49=SAMPLE75=2016101134=173952=2014032012080496912761660=201403201208049691276165799=10000100268=1279=1269=048=17359555=6SZ683=358378270=10215.0271=21346=111023=210=211
1128=99=18035=X49=SAMPLE75=2016101134=473452=2011042406391846144704060=201104240639184614470405799=10000100268=1279=1269=048=17359555=6SZ683=358379270=10216.0271=4346=41023=110=115
1128=99=18035=X49=SAMPLE75=2016101134=65852=2006102423452468296144060=200610242345246829614405799=10000100268=1279=1269=148=17359555=6SZ683=358380270=10217.0271=5346=51023=110=135
1128=99=18235=X49=SAMPLE75=2016101134=47452=2003122012330537162563260=200312201233053716256325799=10000100268=1279=1269=048=17359555=6SZ683=358381270=10215.0271=24346=121023=210=205
1128=99=18135=X49=SAMPLE75=2016101134=220652=2012011114501633276512060=201201111450163327651205799=10000100268=1279=1269=148=17359555=6SZ683=358382270=10219.0271=15346=71023=310=169
1128=99=18135=X49=SAMPLE75=2016101134=149852=2009041002592331514585660=200904100259233151458565799=10000100268=1279=1269=148=17359555=6SZ683=358383270=10218.0271=17346=81023=210=180
1128=99=18035=X49=SAMPLE75=2016101134=499352=2013062607365128179680060=201306260736512817968005799=10000100268=1279=1269=048=17359555=6SZ683=358384270=10216.0271=3346=31023=110=100
1128=99=18235=X49=SAMPLE75=2016101134=90352=2011051817041596958233660=201105181704159695823365799=10000100268=1279=1269=048=17359555=6SZ683=358385270=10215.0271=25346=131023=210=233
1128=99=18235=X49=SAMPLE75=2016101134=110252=2011060915070316559993660=201106091507031655999365799=10000100268=1279=1269=048=17359555=6SZ683=358386270=10213.0271=18346=101023=410=234
1128=99=25135=X49=SAMPLE75=2016101134=249752=2009021423520732274550460=200902142352073227455045799=10000100268=2279=1269=048=17360055=6SH783=99533270=10263.0271=12346=31023=6279=1269=048=17360055=6SH783=99534270=10259.0271=3346=11023=1010=104
1128=99=25435=X49=SAMPLE75=2016101134=142352=2016070108484047341600060=201607010848404734160005799=10000100268=2279=1269=048=17359555=6SZ683=358387270=10215.0271=26346=141023=2279=1269=048=17359555=6SZ683=358388270=10214.0271=16346=81023=310=086
1128=99=18035=X49=SAMPLE75=2016101134=356352=2007032309052228225638460=200703230905222822563845799=10000100268=1279=1269=148=17359555=6SZ683=358389270=10217.0271=4346=41023=110=139
1128=99=18035=X49=SAMPLE75=2016101134=129652=2008062819133906949369660=200806281913390694936965799=10000100268=1279=1269=048=17359555=6SZ683=358390270=10216.0271=4346=41023=110=119
1128=99=18135=X49=SAMPLE75=2016101134=119452=2002052222453339001888060=200205222245333900188805799=10000100268=1279=1269=048=17359555=6SZ683=358391270=10214.0271=17346=91023=310=180
1128=99=18235=X49=SAMPLE75=2016101134=204152=2015022603510841138265660=201502260351084113826565799=10000100268=1279=1269=048=17359555=6SZ683=358392270=10212.0271=32346=111023=510=193
1128=99=18235=X49=SAMPLE75=2016101134=184952=2002032121450471225560860=200203212145047122556085799=10000100268=1279=1269=048=17359555=6SZ683=358393270=10212.0271=25346=101023=510=196
1128=99=18035=X49=SAMPLE75=2016101134=435452=2005060808134084578816060=200506080813408457881605799=10000100268=1279=1269=048=17359555=6SZ683=358394270=10216.0271=3346=31023=110=080
1128=99=18235=X49=SAMPLE75=2016101134=318752=2007100909570323877785660=200710090957032387778565799=10000100268=1279=1269=048=17359555=6SZ683=358395270=10214.0271=20346=101023=310=186
1128=99=18135=X49=SAMPLE75=2016101134=72152=2013111601532924713267260=201311160153292471326725799=10000100268=1279=1269=148=17359555=6SZ683=358396270=10219.0271=17346=81023=310=160
1128=99=18135=X49=SAMPLE75=2016101134=133252=2007022012562751162054460=200702201256275116205445799=10000100268=1279=1269=148=17359555=6SZ683=358397270=10222.0271=30346=91023=610=178
1128=99=25535=X49=SAMPLE75=2016101134=159852=2012030622360026864851260=201203062236002686485125799=10000100268=2279=1269=048=17359555=6SZ683=358398270=10215.0271=25346=131023=2279=1269=048=17359555=6SZ683=358399270=10214.0271=21346=111023=310=101
1128=99=18235=X49=SAMPLE75=2016101134=171852=2009112702370921155366460=200911270237092115536645799=10000100268=1279=1269=048=17359555=6SZ683=358400270=10213.0271=19346=111023=410=183
1128=99=18035=X49=SAMPLE75=2016101134=75452=2009081322061078074572860=200908132206107807457285799=10000100268=1279=1269=148=17359555=6SZ683=358401270=10217.0271=5346=51023=110=104
1128=99=18235=X49=SAMPLE75=2016101134=207152=2002011207510833196667260=200201120751083319666725799=10000100268=1279=1269=048=17359555=6SZ683=358402270=10213.0271=22346=121023=410=212
1128=99=18135=X49=SAMPLE75=2016101134=351052=2016060718564219271347260=201606071856421927134725799=10000100268=1279=1269=148=17359555=6SZ683=358403270=10220.0271=17346=81023=410=153
1128=99=18235=X49=SAMPLE75=2016101134=371452=2003102219273649731755260=200310221927364973175525799=10000100268=1279=1269=048=17359555=6SZ683=358404270=10212.0271=26346=111023=510=208
1128=99=18135=X49=SAMPLE75=2016101134=329452=2012021016580989832076860=201202101658098983207685799=10000100268=1279=1269=148=17359555=6SZ683=358405270=10223.0271=22346=71023=710=167
1128=99=18035=X49=SAMPLE75=2016101134=441052=2014091519004164384620860=201409151900416438462085799=10000100268=1279=1269=048=17359555=6SZ683=358406270=10216.0271=4346=41023=110=094
1128=99=18035=X49=SAMPLE75=2016101134=74652=2005060410324100998496060=200506041032410099849605799=10000100268=1279=1269=148=17359555=6SZ683=358407270=10217.0271=4346=41023=110=099
1128=99=18035=X49=SAMPLE75=2016101134=304552=2003122311485982636233660=200312231148598263623365799=10000100268=1279=1269=148=17359555=6SZ683=358408270=10217.0271=3346=31023=110=086
1128=99=18235=X49=SAMPLE75=2016101134=280952=2010080212440975402035260=201008021244097540203525799=10000100268=1279=1269=048=17359555=6SZ683=358409270=10212.0271=29346=121023=510=184
1128=99=18135=X49=SAMPLE75=2016101134=412752=2015031606280693090009660=201503160628069309000965799=10000100268=1279=1269=148=17359555=6SZ683=358410270=10224.0271=44346=51023=810=146
1128=99=18235=X49=SAMPLE75=2016101134=322752=2016062621381014742080060=201606262138101474208005799=10000100268=1279=1269=148=17359555=6SZ683=358411270=10221.0271=29346=121023=510=184
1128=99=25235=X49=SAMPLE75=2016101134=92052=2012061710434618238624060=201206171043461823862405799=10000100268=2279=1269=148=17359555=6SZ683=358412270=10217.0271=2346=21023=1279=1269=148=17359555=6SZ683=358413270=10218.0271=18346=91023=210=196
1128=99=25535=X49=SAMPLE75=2016101134=8252=2011092719390579540979260=201109271939057954097925799=10000100268=2279=1269=048=17359555=6SZ683=358414270=10215.0271=26346=141023=2279=1269=048=17359555=6SZ683=358415270=10214.0271=20346=101023=310=092
1128=99=25335=X49=SAMPLE75=2016101134=490152=2004111310080141613324860=200411131008014161332485799=10000100268=2279=1269=048=17359555=6SZ683=358416270=10210.0271=32346=91023=7279=1269=048=17359555=6SZ683=358417270=10209.0271=40346=61023=810=010
1128=99=18235=X49=SAMPLE75=2016101134=359252=2008122923153995766195260=200812292315399576619525799=10000100268=1279=1269=048=17359555=6SZ683=358418270=10211.0271=25346=101023=610=201
1128=99=25435=X49=SAMPLE75=2016101134=411552=2010071423451057313920060=201007142345105731392005799=10000100268=2279=1269=148=17359555=6SZ683=358419270=10221.0271=28346=111023=5279=1269=148=17359555=6SZ683=358420270=10223.0271=23346=81023=710=038
1128=99=18135=X49=SAMPLE75=2016101134=258252=2009033107464455909388860=200903310746445590938885799=10000100268=1279=1269=148=17359555=6SZ683=358421270=10220.0271=16346=71023=410=151
1128=99=18035=X49=SAMPLE75=2016101134=74552=2007011916013181438326460=200701191601318143832645799=10000100268=1279=1269=148=17359555=6SZ683=358422270=10217.0271=3346=31023=110=112
1128=99=18235=X49=SAMPLE75=2016101134=359952=2007020416285947515209660=200702041628594751520965799=10000100268=1279=1269=048=17359555=6SZ683=358423270=10212.0271=36346=131023=510=179
1128=99=18035=X49=SAMPLE75=2016101134=222452=2007071614192103028105660=200707161419210302810565799=10000100268=1279=1269=148=17359555=6SZ683=358424270=10217.0271=4346=41023=110=098
1128=99=18235=X49=SAMPLE75=2016101134=251752=2007101913325547757459260=200710191332554775745925799=10000100268=1279=1269=048=17359555=6SZ683=358425270=10212.0271=29346=121023=510=197
1128=99=18035=X49=SAMPLE75=2016101134=56552=2001112618160492309184860=200111261816049230918485799=10000100268=1279=1269=048=17359555=6SZ683=358426270=10216.0271=3346=31023=110=105
1128=99=25335=X49=SAMPLE75=2016101134=399152=2008042221223251406243260=200804222122325140624325799=10000100268=2279=1269=048=17359555=6SZ683=358427270=10210.0271=29346=81023=7279=1269=048=17359555=6SZ683=358428270=10209.0271=43346=71023=810=033
1128=99=18235=X49=SAMPLE75=2016101134=482852=2000111305491437440716060=200011130549143744071605799=10000100268=1279=1269=148=17359555=6SZ683=358429270=10226.0271=16346=31023=1010=216
1128=99=18235=X49=SAMPLE75=2016101134=265652=2004093019494214756332860=200409301949421475633285799=10000100268=1279=1269=048=17359555=6SZ683=358430270=10212.0271=36346=131023=510=203
1128=99=18135=X49=SAMPLE75=2016101134=78152=2003020105392400965248060=200302010539240096524805799=10000100268=1279=1269=048=17359555=6SZ683=358431270=10210.0271=30346=91023=710=166
1128=99=18235=X49=SAMPLE75=2016101134=752=2000032110525163493805060=200003211052516349380505799=10000100268=1279=1269=048=17359555=6SZ683=358432270=10212.0271=29346=121023=510=207
1128=99=18135=X49=SAMPLE75=2016101134=35152=2017011206241934727737660=201701120624193472773765799=10000100268=1279=1269=048=17359555=6SZ683=358433270=10208.0271=20346=61023=910=143
1128=99=25435=X49=SAMPLE75=2016101134=382252=2004120202202745507577660=200412020220274550757765799=10000100268=2279=1269=048=17359555=6SZ683=358434270=10210.0271=33346=101023=7279=1269=048=17359555=6SZ683=358435270=10209.0271=40346=61023=810=061
1128=99=18235=X49=SAMPLE75=2016101134=63352=2007022722174482246963260=200702272217448224696325799=10000100268=1279=1269=048=17359555=6SZ683=358436270=10207.0271=21346=61023=1010=214
1128=99=25335=X49=SAMPLE75=2016101134=116252=2000012921102474730663060=200001292110247473066305799=10000100268=2279=1269=048=17359555=6SZ683=358437270=10210.0271=30346=91023=7279=1269=048=17359555=6SZ683=358438270=10209.0271=43346=71023=810=023
1128=99=25435=X49=SAMPLE75=2016101134=334652=2007072107142490696352060=200707210714249069635205799=10000100268=2279=1269=048=17359555=6SZ683=358439270=10210.0271=33346=101023=7279=1269=048=17359555=6SZ683=358440270=10209.0271=40346=61023=810=060
1128=99=25335=X49=SAMPLE75=2016101134=359952=2005101612572352170140860=200510161257235217014085799=10000100268=2279=1269=048=17359555=6SZ683=358441270=10210.0271=30346=91023=7279=1269=048=17359555=6SZ683=358442270=10209.0271=43346=71023=810=035
1128=99=25435=X49=SAMPLE75=2016101134=317452=2012071805462862603174460=201207180546286260317445799=10000100268=2279=1269=048=17359555=6SZ683=358443270=10210.0271=33346=101023=7279=1269=048=17359555=6SZ683=358444270=10209.0271=40346=61023=810=053
1128=99=25335=X49=SAMPLE75=2016101134=115952=2010022419380448816294460=201002241938044881629445799=10000100268=2279=1269=048=17359555=6SZ683=358445270=10210.0271=30346=91023=7279=1269=048=17359555=6SZ683=358446270=10209.0271=43346=71023=810=249
1128=99=18235=X49=SAMPLE75=2016101134=372452=2013010807100379425350460=201301080710037942535045799=10000100268=1279=1269=048=17359555=6SZ683=358447270=10212.0271=36346=131023=510=227
1128=99=18235=X49=SAMPLE75=2016101134=127352=2004110618162079470076860=200411061816207947007685799=10000100268=1279=1269=048=17359555=6SZ683=358448270=10212.0271=29346=121023=510=229
1128=99=18035=X49=SAMPLE75=2016101134=349952=2013092115401051143264060=201309211540105114326405799=10000100268=1279=1269=048=17359555=6SZ683=358449270=10216.0271=2346=21023=110=127
1128=99=18035=X49=SAMPLE75=2016101134=242552=2011030207375345397324860=201103020737534539732485799=10000100268=1279=1269=048=17359555=6SZ683=358450270=10216.0271=1346=11023=110=139
1128=99=18235=X49=SAMPLE75=2016101134=178052=2011062214174908746752060=201106221417490874675205799=10000100268=1279=1269=048=17359555=6SZ683=358451270=10211.0271=28346=111023=610=234
1128=99=18235=X49=SAMPLE75=2016101134=399652=2003091207194108010307260=200309120719410801030725799=10000100268=1279=1269=148=17359555=6SZ683=358452270=10222.0271=32346=101023=610=224
1128=99=25235=X49=SAMPLE75=2016101134=296552=2005092614192503964451260=200509261419250396445125799=10000100268=2279=1269=148=17359555=6SZ683=358453270=10217.0271=5346=51023=1279=1269=148=17359555=6SZ683=358454270=10218.0271=17346=81023=210=237
1128=99=25335=X49=SAMPLE75=2016101134=39252=2015070805002847381894460=201507080500284738189445799=10000100268=2279=2269=048=17359555=6SZ683=358455270=10216.0271=1346=11023=1279=0269=048=17359555=6SZ683=358456270=10206.0271=39346=61023=1010=027
1128=99=17935=X49=SAMPLE75=2016101134=289752=2007100100113946073686460=200710010011394607368645799=10000100268=1279=1269=048=17360055=6SH783=99535270=10268.0271=5346=21023=110=074
1128=99=18235=X49=SAMPLE75=2016101134=338552=2007071719553850219068860=200707171955385021906885799=10000100268=1279=1269=048=17359555=6SZ683=358457270=10211.0271=26346=101023=510=241
1128=99=18235=X49=SAMPLE75=2016101134=33352=2001032501254255396793660=200103250125425539679365799=10000100268=1279=1269=048=17359555=6SZ683=358458270=10206.0271=40346=71023=1010=246
1128=99=25535=X49=SAMPLE75=2016101134=443252=2003040106522183216950460=200304010652218321695045799=10000100268=2279=1269=048=17359555=6SZ683=358459270=10215.0271=25346=131023=1279=1269=048=17359555=6SZ683=358460270=10214.0271=21346=111023=210=111
1128=99=18135=X49=SAMPLE75=2016101134=100752=2009101405513612614675260=200910140551361261467525799=10000100268=1279=1269=148=17359555=6SZ683=358461270=10220.0271=17346=81023=410=181
1128=99=18035=X49=SAMPLE75=2016101134=228852=2012120611102349131558460=201212061110234913155845799=10000100268=1279=0269=048=17359555=6SZ683=358462270=10216.0271=1346=11023=110=154
1128=99=17935=X49=SAMPLE75=2016101134=406352=2009042611275912754707260=200904261127591275470725799=10000100268=1279=0269=048=17360055=6SH783=99536270=10269.0271=3346=11023=110=088
1128=99=17935=X49=SAMPLE75=2016101134=441252=2015102510410475595078460=201510251041047559507845799=10000100268=1279=1269=048=17360055=6SH783=99537270=10268.0271=6346=31023=210=087
1128=99=18235=X49=SAMPLE75=2016101134=400252=2013080207553861311116860=201308020755386131111685799=10000100268=1279=1269=048=17359555=6SZ683=358463270=10211.0271=28346=111023=610=247
1128=99=18035=X49=SAMPLE75=2016101134=267352=2000120212431962835840860=200012021243196283584085799=10000100268=1279=1269=048=17359555=6SZ683=358464270=10216.0271=2346=21023=110=129
1128=99=18035=X49=SAMPLE75=2016101134=305052=2002061821025480078590460=200206182102548007859045799=10000100268=1279=1269=048=17359555=6SZ683=358465270=10216.0271=1346=11023=110=131
1128=99=18035=X49=SAMPLE75=2016101134=447252=2001061419535262092501660=200106141953526209250165799=10000100268=1279=1269=048=17359555=6SZ683=358466270=10216.0271=2346=21023=110=138
1128=99=18035=X49=SAMPLE75=2016101134=229452=2001061704542326378330460=200106170454232637833045799=10000100268=1279=1269=048=17359555=6SZ683=358467270=10216.0271=3346=31023=110=144
1128=99=18035=X49=SAMPLE75=2016101134=294852=2011011018045398979225660=201101101804539897922565799=10000100268=1279=1269=048=17359555=6SZ683=358468270=10216.0271=2346=21023=110=114
1128=99=18035=X49=SAMPLE75=2016101134=93952=2010093001505701052115260=201009300150570105211525799=10000100268=1279=1269=048=17359555=6SZ683=358469270=10216.0271=1346=11023=110=130
1128=99=18235=X49=SAMPLE75=2016101134=136852=2009071600171432174220860=200907160017143217422085799=10000100268=1279=1269=048=17359555=6SZ683=358470270=10212.0271=36346=131023=510=223
1128=99=25335=X49=SAMPLE75=2016101134=296452=2015072111463065782547260=201507211146306578254725799=10000100268=2279=2269=048=17359555=6SZ683=358471270=10216.0271=1346=11023=1279=0269=048=17359555=6SZ683=358472270=10206.0271=40346=71023=1010=255
1128=99=17935=X49=SAMPLE75=2016101134=50552=2009071400110309284915260=200907140011030928491525799=10000100268=1279=1269=048=17360055=6SH783=99538270=10268.0271=5346=21023=210=061
1128=99=18235=X49=SAMPLE75=2016101134=258652=2007050510112649592144060=200705051011264959214405799=10000100268=1279=1269=048=17359555=6SZ683=358473270=10211.0271=26346=101023=510=215
1128=99=25035=X49=SAMPLE75=2016101134=483052=2007022604022187272598460=200702260402218727259845799=10000100268=2279=2269=048=17360055=6SH783=99539270=10269.0271=3346=11023=1279=0269=048=17360055=6SH783=99540270=10259.0271=3346=11023=1010=055
1128=99=18035=X49=SAMPLE75=2016101134=362352=2009072616480529630265660=200907261648052963026565799=10000100268=1279=0269=048=17359555=6SZ683=358474270=10216.0271=1346=11023=110=120
1128=99=17935=X49=SAMPLE75=2016101134=281752=2007012408595443424867260=200701240859544342486725799=10000100268=1279=1269=048=17360055=6SH783=99541270=10268.0271=6346=31023=110=064
1128=99=18235=X49=SAMPLE75=2016101134=445352=2003101913251925957329660=200310191325192595732965799=10000100268=1279=1269=048=17359555=6SZ683=358475270=10211.0271=28346=111023=610=211
1128=99=18235=X49=SAMPLE75=2016101134=103752=2012030917174686118451260=201203091717468611845125799=10000100268=1279=1269=048=17359555=6SZ683=358476270=10212.0271=29346=121023=510=214
1128=99=20835=X49=SAMPLE75=2016101134=271652=2007030601520494259689660=200703060152049425968965799=00000001268=1279=0269=248=17359555=6SZ683=358477270=10216.0271=1346=25797=237705=237=032=137=032=110=098
1128=99=15635=X49=SAMPLE75=2016101134=3552=2015111003332740641408060=201511100333274064140805799=00000010268=1279=0269=e48=17359555=6SZ683=358478271=9110=112
1128=99=25335=X49=SAMPLE75=2016101134=105352=2005070906200706742291260=200507090620070674229125799=10000100268=2279=2269=048=17359555=6SZ683=358479270=10216.0271=1346=11023=1279=0269=048=17359555=6SZ683=358480270=10206.0271=40346=71023=1010=003
1128=99=17935=X49=SAMPLE75=2016101134=9052=2016100103004206131731260=201610010300420613173125799=10000100268=1279=0269=148=17360055=6SH783=99542270=10272.0271=3346=11023=110=055
1128=99=17935=X49=SAMPLE75=2016101134=493852=2010051413013104603539260=201005141301310460353925799=10000100268=1279=1269=048=17360055=6SH783=99543270=10268.0271=5346=21023=110=055
1128=99=17935=X49=SAMPLE75=2016101134=75352=2016011312354991510291260=201601131235499151029125799=10000100268=1279=0269=148=17360055=6SH783=99544270=10273.0271=1346=11023=210=050
1128=99=18235=X49=SAMPLE75=2016101134=145852=2015081218382398269036860=201508121838239826903685799=10000100268=1279=1269=048=17359555=6SZ683=358481270=10211.0271=26346=101023=510=226
1128=99=18035=X49=SAMPLE75=2016101134=432252=2002052520285227557921660=200205252028522755792165799=10000100268=1279=1269=148=17360055=6SH783=99545270=10276.0271=37346=31023=510=114
1128=99=17935=X49=SAMPLE75=2016101134=299352=2017021605411930127168060=201702160541193012716805799=10000100268=1279=1269=148=17360055=6SH783=99546270=10273.0271=4346=21023=210=065
1128=99=18035=X49=SAMPLE75=2016101134=76452=2001080104045920611844060=200108010404592061184405799=10000100268=1279=0269=048=17359555=6SZ683=358482270=10216.0271=1346=11023=110=120
1128=99=17935=X49=SAMPLE75=2016101134=13052=2013012722223845014297660=201301272222384501429765799=10000100268=1279=0269=048=17360055=6SH783=99547270=10269.0271=3346=11023=110=084
1128=99=17935=X49=SAMPLE75=2016101134=52152=2001051120535788257411260=200105112053578825741125799=10000100268=1279=1269=048=17360055=6SH783=99548270=10268.0271=6346=31023=210=073
1128=99=18235=X49=SAMPLE75=2016101134=409752=2000101120212919156290060=200010112021291915629005799=10000100268=1279=1269=048=17359555=6SZ683=358483270=10211.0271=28346=111023=610=238
1128=99=25035=X49=SAMPLE75=2016101134=113852=2016070713223935661619260=201607071322393566161925799=10000100268=2279=2269=148=17360055=6SH783=99549270=10272.0271=3346=11023=1279=0269=148=17360055=6SH783=99550270=10282.0271=3346=11023=1010=053
1128=99=17935=X49=SAMPLE75=2016101134=494452=2016112106060597989811260=201611210606059798981125799=10000100268=1279=1269=148=17360055=6SH783=99551270=10273.0271=1346=11023=110=055
1128=99=18235=X49=SAMPLE75=2016101134=240652=2016100922504487238854460=201610092250448723885445799=10000100268=1279=1269=048=17359555=6SZ683=358484270=10212.0271=36346=131023=510=254
1128=99=25035=X49=SAMPLE75=2016101134=127852=2001053003550500242361660=200105300355050024236165799=10000100268=2279=2269=048=17360055=6SH783=99552270=10269.0271=3346=11023=1279=0269=048=17360055=6SH783=99553270=10259.0271=3346=11023=1010=093
1128=99=18235=X49=SAMPLE75=2016101134=151952=2007121210332045256278460=200712121033204525627845799=10000100268=1279=1269=048=17359555=6SZ683=358485270=10212.0271=29346=121023=510=225
1128=99=18235=X49=SAMPLE75=2016101134=284152=2009122010275845994182460=200912201027584599418245799=10000100268=1279=1269=048=17359555=6SZ683=358486270=10212.0271=36346=131023=510=238
1128=99=25135=X49=SAMPLE75=2016101134=150652=2014040818504082051628860=201404081850408205162885799=10000100268=2279=2269=148=17360055=6SH783=99554270=10273.0271=1346=11023=1279=0269=148=17360055=6SH783=99555270=10283.0271=61346=31023=1010=148
1128=99=17935=X49=SAMPLE75=2016101134=41652=2014060820215189488256060=201406082021518948825605799=10000100268=1279=1269=148=17360055=6SH783=99556270=10276.0271=4346=21023=310=093
1128=99=18035=X49=SAMPLE75=2016101134=345452=2001071603063635970545660=200107160306363597054565799=10000100268=1279=1269=048=17359555=6SZ683=358487270=10216.0271=2346=21023=110=152
1128=99=18035=X49=SAMPLE75=2016101134=374452=2005103100291993529561660=200510310029199352956165799=10000100268=1279=1269=048=17359555=6SZ683=358488270=10216.0271=3346=31023=110=136
1128=99=18235=X49=SAMPLE75=2016101134=32852=2014112306141948133478460=201411230614194813347845799=10000100268=1279=1269=048=17359555=6SZ683=358489270=10212.0271=29346=121023=510=253
1128=99=18035=X49=SAMPLE75=2016101134=221152=2007021106165720560534460=200702110616572056053445799=10000100268=1279=1269=048=17359555=6SZ683=358490270=10216.0271=4346=41023=110=149
1128=99=25535=X49=SAMPLE75=2016101134=102152=2010070503134586068697660=201007050313458606869765799=10000100268=2279=1269=048=17359555=6SZ683=358491270=10215.0271=26346=141023=2279=1269=048=17359555=6SZ683=358492270=10214.0271=20346=101023=310=126
1128=99=18235=X49=SAMPLE75=2016101134=324052=2008062319192285133808060=200806231919228513380805799=10000100268=1279=1269=048=17359555=6SZ683=358493270=10212.0271=36346=131023=510=244
1128=99=18235=X49=SAMPLE75=2016101134=28052=2004120409402918747593660=200412040940291874759365799=10000100268=1279=1269=048=17359555=6SZ683=358494270=10212.0271=29346=121023=510=231
1128=99=18235=X49=SAMPLE75=2016101134=216252=2014020610244315236492860=201402061024431523649285799=10000100268=1279=1269=048=17359555=6SZ683=358495270=10212.0271=36346=131023=510=232
1128=99=18135=X49=SAMPLE75=2016101134=230352=2016061413250453972870460=201606141325045397287045799=10000100268=1279=1269=148=17359555=6SZ683=358496270=10218.0271=18346=91023=210=196
1128=99=18235=X49=SAMPLE75=2016101134=58252=2002011007574906489445660=200201100757490648944565799=10000100268=1279=1269=048=17359555=6SZ683=358497270=10212.0271=29346=121023=510=237
1128=99=18235=X49=SAMPLE75=2016101134=485652=2004030615463541665593660=200403061546354166559365799=10000100268=1279=1269=048=17359555=6SZ683=358498270=10210.0271=33346=101023=710=000
1128=99=18135=X49=SAMPLE75=2016101134=188852=2005103110154208928278460=200510311015420892827845799=10000100268=1279=1269=148=17359555=6SZ683=358499270=10223.0271=25346=91023=710=217
1128=99=18235=X49=SAMPLE75=2016101134=134652=2004121814234640263529660=200412181423464026352965799=10000100268=1279=1269=048=17359555=6SZ683=358500270=10211.0271=29346=121023=610=236
1128=99=18235=X49=SAMPLE75=2016101134=186752=2000060719222039730301860=200006071922203973030185799=10000100268=1279=1269=048=17359555=6SZ683=358501270=10212.0271=36346=131023=510=180
1128=99=18235=X49=SAMPLE75=2016101134=96952=2006031200472150606668860=200603120047215060666885799=10000100268=1279=1269=048=17359555=6SZ683=358502270=10210.0271=34346=111023=710=181
1128=99=18035=X49=SAMPLE75=2016101134=80052=2003101507003176427769660=200310150700317642776965799=10000100268=1279=1269=048=17359555=6SZ683=358503270=10216.0271=3346=31023=110=080
1128=99=18135=X49=SAMPLE75=2016101134=24152=2004111414231335612576060=200411141423133561257605799=10000100268=1279=1269=048=17359555=6SZ683=358504270=10209.0271=46346=81023=810=167
1128=99=18135=X49=SAMPLE75=2016101134=403652=2007102823354583765872060=200710282335458376587205799=10000100268=1279=1269=148=17359555=6SZ683=358505270=10224.0271=46346=61023=810=159
1128=99=18135=X49=SAMPLE75=2016101134=127252=2014041011491083934444860=201404101149108393444485799=10000100268=1279=1269=148=17359555=6SZ683=358506270=10220.0271=18346=91023=410=160
1128=99=18035=X49=SAMPLE75=2016101134=344552=2001122022220180452342460=200112202222018045234245799=10000100268=1279=1269=048=17359555=6SZ683=358507270=10216.0271=2346=21023=110=110
1128=99=18035=X49=SAMPLE75=2016101134=459852=2014092013250487779404860=201409201325048777940485799=10000100268=1279=1269=048=17359555=6SZ683=358508270=10216.0271=3346=31023=110=101
1128=99=18235=X49=SAMPLE75=2016101134=251952=2013120607130656081708860=201312060713065608170885799=10000100268=1279=1269=048=17359555=6SZ683=358509270=10212.0271=29346=121023=510=228
1128=99=18035=X49=SAMPLE75=2016101134=67652=2017012107163996951564860=201701210716399695156485799=10000100268=1279=1269=048=17359555=6SZ683=358510270=10216.0271=2346=21023=110=086
1128=99=18135=X49=SAMPLE75=2016101134=47552=2016103006034571185222460=201610300603457118522245799=10000100268=1279=1269=048=17359555=6SZ683=358511270=10208.0271=23346=71023=910=156
1128=99=18135=X49=SAMPLE75=2016101134=432852=2015051304574919348966460=201505130457491934896645799=10000100268=1279=1269=148=17359555=6SZ683=358512270=10225.0271=20346=51023=910=164
1128=99=18135=X49=SAMPLE75=2016101134=123752=2016111219010731771795260=201611121901073177179525799=10000100268=1279=1269=048=17359555=6SZ683=358513270=10208.0271=24346=81023=910=179
1128=99=18235=X49=SAMPLE75=2016101134=49252=2011020604202400933907260=201102060420240093390725799=10000100268=1279=1269=148=17359555=6SZ683=358514270=10221.0271=29346=121023=510=223
1128=99=18035=X49=SAMPLE75=2016101134=202552=2000112616204788349876460=200011261620478834987645799=10000100268=1279=1269=048=17359555=6SZ683=358515270=10216.0271=1346=11023=110=106
1128=99=18035=X49=SAMPLE75=2016101134=200252=2010081208145818420083260=201008120814581842008325799=10000100268=1279=1269=048=17359555=6SZ683=358516270=10216.0271=2346=21023=110=081
1128=99=25535=X49=SAMPLE75=2016101134=54752=2016092609160033100147260=201609260916003310014725799=10000100268=2279=1269=048=17359555=6SZ683=358517270=10215.0271=25346=131023=2279=1269=048=17359555=6SZ683=358518270=10214.0271=21346=111023=310=072
1128=99=18035=X49=SAMPLE75=2016101134=85052=2009040515282968559430460=200904051528296855943045799=10000100268=1279=1269=048=17359555=6SZ683=358519270=10216.0271=1346=11023=110=083
1128=99=18135=X49=SAMPLE75=2016101134=332552=2001051903550832202620060=200105190355083220262005799=10000100268=1279=1269=048=17359555=6SZ683=358520270=10209.0271=47346=91023=810=193
1128=99=18235=X49=SAMPLE75=2016101134=137752=2002091321424525079608060=200209132142452507960805799=10000100268=1279=1269=048=17359555=6SZ683=358521270=10207.0271=24346=71023=1010=212
1128=99=18235=X49=SAMPLE75=2016101134=498852=2011111617120638635872060=201111161712063863587205799=10000100268=1279=1269=148=17359555=6SZ683=358522270=10226.0271=18346=41023=1010=216
1128=99=18135=X49=SAMPLE75=2016101134=305052=2013030223253511915289660=201303022325351191528965799=10000100268=1279=1269=148=17359555=6SZ683=358523270=10225.0271=21346=61023=910=150
1128=99=25335=X49=SAMPLE75=2016101134=410352=2006030123040816659561660=200603012304081665956165799=10000100268=2279=2269=048=17359555=6SZ683=358524270=10216.0271=1346=11023=1279=0269=048=17359555=6SZ683=358525270=10206.0271=40346=71023=1010=224
1128=99=17935=X49=SAMPLE75=2016101134=94552=2013021722132208859872060=201302172213220885987205799=10000100268=1279=1269=048=17360055=6SH783=99557270=10268.0271=5346=21023=110=037
1128=99=18235=X49=SAMPLE75=2016101134=471752=2007090403221548169344060=200709040322154816934405799=10000100268=1279=1269=048=17359555=6SZ683=358526270=10211.0271=27346=111023=510=209
1128=99=25535=X49=SAMPLE75=2016101134=440752=2000052201593971101228660=200005220159397110122865799=10000100268=2279=1269=148=17359555=6SZ683=358527270=10220.0271=21346=101023=4279=1269=148=17359555=6SZ683=358528270=10221.0271=26346=111023=510=103
1128=99=18235=X49=SAMPLE75=2016101134=158852=2009012210293383422115260=200901221029338342211525799=10000100268=1279=1269=048=17359555=6SZ683=358529270=10206.0271=43346=81023=1010=228
1128=99=18135=X49=SAMPLE75=2016101134=200752=2011050203341936978035260=201105020334193697803525799=10000100268=1279=1269=048=17359555=6SZ683=358530270=10207.0271=25346=81023=910=177
1128=99=25435=X49=SAMPLE75=2016101134=221352=2014103112053321759257660=201410311205332175925765799=10000100268=2279=1269=148=17359555=6SZ683=358531270=10221.0271=27346=121023=5279=1269=148=17359555=6SZ683=358532270=10223.0271=24346=81023=710=026
1128=99=18235=X49=SAMPLE75=2016101134=455752=2016110922024018418585660=201611092202401841858565799=10000100268=1279=1269=048=17359555=6SZ683=358533270=10215.0271=17346=121023=110=189
1128=99=18235=X49=SAMPLE75=2016101134=304952=2007091217562604229660860=200709121756260422966085799=10000100268=1279=1269=048=17359555=6SZ683=358534270=10215.0271=25346=131023=110=209
1128=99=18035=X49=SAMPLE75=2016101134=331752=2003041310354950021531260=200304131035495002153125799=10000100268=1279=0269=048=17359555=6SZ683=358535270=10216.0271=1346=11023=110=101
1128=99=17935=X49=SAMPLE75=2016101134=365052=2012042823010176550707260=201204282301017655070725799=10000100268=1279=0269=048=17360055=6SH783=99558270=10269.0271=3346=11023=110=064
1128=99=17935=X49=SAMPLE75=2016101134=373952=2010101219345655061772860=201010121934565506177285799=10000100268=1279=1269=048=17360055=6SH783=99559270=10268.0271=6346=31023=210=066
1128=99=18235=X49=SAMPLE75=2016101134=470452=2013092608325961911904060=201309260832596191190405799=10000100268=1279=1269=048=17359555=6SZ683=358536270=10211.0271=29346=121023=610=219
1128=99=25335=X49=SAMPLE75=2016101134=1352=2002051805251024411792060=200205180525102441179205799=10000100268=2279=2269=048=17359555=6SZ683=358537270=10216.0271=1346=11023=1279=0269=048=17359555=6SZ683=358538270=10206.0271=43346=81023=1010=011
1128=99=17935=X49=SAMPLE75=2016101134=382352=2012033011103565746534460=201203301110356574653445799=10000100268=1279=1269=048=17360055=6SH783=99560270=10268.0271=5346=21023=210=067
1128=99=18235=X49=SAMPLE75=2016101134=357652=2008112710114630284800060=200811271011463028480005799=10000100268=1279=1269=048=17359555=6SZ683=358539270=10211.0271=27346=111023=510=221
1128=99=25035=X49=SAMPLE75=2016101134=495252=2002102212562754567644860=200210221256275456764485799=10000100268=2279=2269=048=17360055=6SH783=99561270=10269.0271=3346=11023=1279=0269=048=17360055=6SH783=99562270=10259.0271=3346=11023=1010=061
1128=99=18035=X49=SAMPLE75=2016101134=9052=2009041722095118216966460=200904172209511821696645799=10000100268=1279=0269=048=17359555=6SZ683=358540270=10216.0271=1346=11023=110=116
1128=99=17935=X49=SAMPLE75=2016101134=50152=2014091301260743589088060=201409130126074358908805799=10000100268=1279=1269=048=17360055=6SH783=99563270=10268.0271=6346=31023=110=050
1128=99=18235=X49=SAMPLE75=2016101134=497552=2006042301585301804848060=200604230158530180484805799=10000100268=1279=1269=048=17359555=6SZ683=358541270=10211.0271=29346=121023=610=213
1128=99=25335=X49=SAMPLE75=2016101134=136052=2016081320513897853619260=201608132051389785361925799=10000100268=2279=2269=048=17359555=6SZ683=358542270=10216.0271=1346=11023=1279=0269=048=17359555=6SZ683=358543270=10206.0271=43346=81023=1010=002
1128=99=17935=X49=SAMPLE75=2016101134=76352=2010122819240547901152060=201012281924054790115205799=10000100268=1279=1269=048=17360055=6SH783=99564270=10268.0271=5346=21023=110=073
1128=99=18235=X49=SAMPLE75=2016101134=411852=2006110116353139212275260=200611011635313921227525799=10000100268=1279=1269=048=17359555=6SZ683=358544270=10211.0271=27346=111023=510=222
1128=99=18035=X49=SAMPLE75=2016101134=451852=2001030805091773197913660=200103080509177319791365799=10000100268=1279=0269=048=17359555=6SZ683=358545270=10216.0271=1346=11023=110=104
1128=99=17935=X49=SAMPLE75=2016101134=228852=2008040902270127535228860=200804090227012753522885799=10000100268=1279=1269=048=17360055=6SH783=99565270=10268.0271=6346=31023=110=064
1128=99=18235=X49=SAMPLE75=2016101134=160252=2003051009044828062497660=200305100904482806249765799=10000100268=1279=1269=048=17359555=6SZ683=358546270=10211.0271=29346=121023=610=211
1128=99=25335=X49=SAMPLE75=2016101134=101852=2000012411000173433348560=200001241100017343334855799=10000100268=2279=2269=048=17359555=6SZ683=358547270=10216.0271=1346=11023=1279=0269=048=17359555=6SZ683=358548270=10206.0271=43346=81023=1010=023
1128=99=17935=X49=SAMPLE75=2016101134=65352=2016021513224407847296060=201602151322440784729605799=10000100268=1279=1269=048=17360055=6SH783=99566270=10268.0271=5346=21023=110=065
1128=99=18235=X49=SAMPLE75=2016101134=41552=2006032006371608785145660=200603200637160878514565799=10000100268=1279=1269=048=17359555=6SZ683=358549270=10211.0271=27346=111023=510=230
1128=99=18035=X49=SAMPLE75=2016101134=294252=2012110109525559864518460=201211010952555986451845799=10000100268=1279=0269=048=17359555=6SZ683=358550270=10216.0271=1346=11023=110=097
1128=99=17935=X49=SAMPLE75=2016101134=244152=2010042317385950833625660=201004231738595083362565799=10000100268=1279=0269=048=17360055=6SH783=99567270=10269.0271=3346=11023=110=065
1128=99=17935=X49=SAMPLE75=2016101134=379052=2003062502593287775872060=200306250259328777587205799=10000100268=1279=1269=048=17360055=6SH783=99568270=10268.0271=6346=31023=210=098
1128=99=18235=X49=SAMPLE75=2016101134=432152=2016051602535321554252860=201605160253532155425285799=10000100268=1279=1269=048=17359555=6SZ683=358551270=10211.0271=29346=121023=610=220
1128=99=25335=X49=SAMPLE75=2016101134=50252=2009110820560479230355260=200911082056047923035525799=10000100268=2279=2269=048=17359555=6SZ683=358552270=10216.0271=1346=11023=1279=0269=048=17359555=6SZ683=358553270=10206.0271=43346=81023=1010=242
1128=99=17935=X49=SAMPLE75=2016101134=469152=2009040321563327569836860=200904032156332756983685799=10000100268=1279=1269=048=17360055=6SH783=99569270=10268.0271=5346=21023=210=038
1128=99=18235=X49=SAMPLE75=2016101134=455652=2007020109455916863113660=200702010945591686311365799=10000100268=1279=1269=048=17359555=6SZ683=358554270=10211.0271=27346=111023=510=195
1128=99=25035=X49=SAMPLE75=2016101134=393452=2015082717231021927808060=201508271723102192780805799=10000100268=2279=2269=048=17360055=6SH783=99570270=10269.0271=3346=11023=1279=0269=048=17360055=6SH783=99571270=10259.0271=3346=11023=1010=050
1128=99=18035=X49=SAMPLE75=2016101134=9752=2004060203020488883585660=200406020302048888358565799=10000100268=1279=0269=048=17359555=6SZ683=358555270=10216.0271=1346=11023=110=098
1128=99=17935=X49=SAMPLE75=2016101134=48652=2000112202514537950770060=200011220251453795077005799=10000100268=1279=1269=048=17360055=6SH783=99572270=10268.0271=6346=31023=110=057
1128=99=18235=X49=SAMPLE75=2016101134=216352=2003010708431752770225660=200301070843175277022565799=10000100268=1279=1269=048=17359555=6SZ683=358556270=10211.0271=29346=121023=610=202
1128=99=25335=X49=SAMPLE75=2016101134=109052=2010072720550769406323260=201007272055076940632325799=10000100268=2279=2269=048=17359555=6SZ683=358557270=10216.0271=1346=11023=1279=0269=048=17359555=6SZ683=358558270=10206.0271=43346=81023=1010=010
1128=99=18035=X49=SAMPLE75=2016101134=290352=2005062711412728174601660=200506271141272817460165799=10000100268=1279=0269=048=17359555=6SZ683=358559270=10216.0271=1346=11023=110=109
1128=99=17935=X49=SAMPLE75=2016101134=378352=2016040710102261421113660=201604071010226142111365799=10000100268=1279=1269=048=17360055=6SH783=99573270=10268.0271=5346=21023=110=045
1128=99=18235=X49=SAMPLE75=2016101134=438952=2003031213041903505854460=200303121304190350585445799=10000100268=1279=1269=048=17359555=6SZ683=358560270=10211.0271=27346=111023=610=191
1128=99=25335=X49=SAMPLE75=2016101134=112252=2015091205460883416147260=201509120546088341614725799=10000100268=2279=2269=048=17359555=6SZ683=358561270=10216.0271=1346=11023=1279=0269=048=17359555=6SZ683=358562270=10206.0271=43346=81023=1010=243
1128=99=18035=X49=SAMPLE75=2016101134=119852=2012041817371584749388860=201204181737158474938885799=10000100268=1279=0269=048=17359555=6SZ683=358563270=10216.0271=1346=11023=110=117
1128=99=17935=X49=SAMPLE75=2016101134=385952=2004090906584901822534460=200409090658490182253445799=10000100268=1279=0269=048=17360055=6SH783=99574270=10269.0271=3346=11023=110=058
1128=99=17935=X49=SAMPLE75=2016101134=331952=2012011020033432581254460=201201102003343258125445799=10000100268=1279=1269=048=17360055=6SH783=99575270=10268.0271=6346=31023=210=078
1128=99=18235=X49=SAMPLE75=2016101134=288952=2010031620575444088403260=201003162057544408840325799=10000100268=1279=1269=048=17359555=6SZ683=358564270=10211.0271=29346=121023=610=239
1128=99=25335=X49=SAMPLE75=2016101134=234352=2009121518305688225644860=200912151830568822564485799=10000100268=2279=2269=048=17359555=6SZ683=358565270=10216.0271=1346=11023=1279=0269=048=17359555=6SZ683=358566270=10206.0271=43346=81023=1010=017
1128=99=17935=X49=SAMPLE75=2016101134=24852=2006101206373538718825660=200610120637353871882565799=10000100268=1279=1269=048=17360055=6SH783=99576270=10268.0271=5346=21023=210=083
1128=99=18235=X49=SAMPLE75=2016101134=133152=2001091820102231683924860=200109182010223168392485799=10000100268=1279=1269=048=17359555=6SZ683=358567270=10211.0271=27346=111023=510=243
1128=99=25035=X49=SAMPLE75=2016101134=47752=2009032114510366800377660=200903211451036680037765799=10000100268=2279=2269=048=17360055=6SH783=99577270=10269.0271=3346=11023=1279=0269=048=17360055=6SH783=99578270=10259.0271=3346=11023=1010=092
1128=99=18035=X49=SAMPLE75=2016101134=249352=2005070601251257741065660=200507060125125774106565799=10000100268=1279=0269=048=17359555=6SZ683=358568270=10216.0271=1346=11023=110=097
1128=99=17935=X49=SAMPLE75=2016101134=345752=2007012910515967856236860=200701291051596785623685799=10000100268=1279=0269=048=17360055=6SH783=99579270=10269.0271=3346=11023=110=058
1128=99=17935=X49=SAMPLE75=2016101134=96252=2003092912411224251011260=200309291241122425101125799=10000100268=1279=1269=048=17360055=6SH783=99580270=10268.0271=6346=31023=210=049
1128=99=18235=X49=SAMPLE75=2016101134=422052=2015092501384533382598460=201509250138453338259845799=10000100268=1279=1269=048=17359555=6SZ683=358569270=10211.0271=29346=121023=610=230
1128=99=25335=X49=SAMPLE75=2016101134=396752=2001061622583206683370460=200106162258320668337045799=10000100268=2279=2269=048=17359555=6SZ683=358570270=10216.0271=1346=11023=1279=0269=048=17359555=6SZ683=358571270=10206.0271=43346=81023=1010=001
1128=99=17935=X49=SAMPLE75=2016101134=14552=2002120222465098495732860=200212022246509849573285799=10000100268=1279=1269=048=17360055=6SH783=99581270=10268.0271=5346=21023=210=050
1128=99=18235=X49=SAMPLE75=2016101134=343552=2007082823431646531872060=200708282343164653187205799=10000100268=1279=1269=048=17359555=6SZ683=358572270=10211.0271=27346=111023=510=226
1128=99=25035=X49=SAMPLE75=2016101134=116652=2017022516043676087456060=201702251604367608745605799=10000100268=2279=2269=048=17360055=6SH783=99582270=10269.0271=3346=11023=1279=0269=048=17360055=6SH783=99583270=10259.0271=3346=11023=1010=076
1128=99=18035=X49=SAMPLE75=2016101134=361152=2015030105590371566272060=201503010559037156627205799=10000100268=1279=0269=048=17359555=6SZ683=358573270=10216.0271=1346=11023=110=090
1128=99=17935=X49=SAMPLE75=2016101134=298852=2014032714285421155507260=201403271428542115550725799=10000100268=1279=1269=048=17360055=6SH783=99584270=10268.0271=6346=31023=110=039
1128=99=18235=X49=SAMPLE75=2016101134=334052=2000022313312432530721060=200002231331243253072105799=10000100268=1279=1269=048=17359555=6SZ683=358574270=10211.0271=29346=121023=610=212
1128=99=25335=X49=SAMPLE75=2016101134=120752=2002081309210811385254460=200208130921081138525445799=10000100268=2279=2269=048=17359555=6SZ683=358575270=10216.0271=1346=11023=1279=0269=048=17359555=6SZ683=358576270=10206.0271=43346=81023=1010=022
1128=99=17935=X49=SAMPLE75=2016101134=134552=2007052806120121652627260=200705280612012165262725799=10000100268=1279=1269=048=17360055=6SH783=99585270=10268.0271=5346=21023=110=062
1128=99=18235=X49=SAMPLE75=2016101134=449352=2014031112584839021913660=201403111258483902191365799=10000100268=1279=1269=048=17359555=6SZ683=358577270=10211.0271=27346=111023=510=219
1128=99=18035=X49=SAMPLE75=2016101134=34252=2014102322241700056313660=201410232224170005631365799=10000100268=1279=0269=048=17359555=6SZ683=358578270=10216.0271=1346=11023=110=119
1128=99=17935=X49=SAMPLE75=2016101134=113252=2000091513100532843152860=200009151310053284315285799=10000100268=1279=1269=048=17360055=6SH783=99586270=10268.0271=6346=31023=110=063
1128=99=18235=X49=SAMPLE75=2016101134=381952=2002090706061591326664060=200209070606159132666405799=10000100268=1279=1269=048=17359555=6SZ683=358579270=10211.0271=29346=121023=610=231
1128=99=25335=X49=SAMPLE75=2016101134=53252=2006042002022737814428860=200604200202273781442885799=10000100268=2279=2269=048=17359555=6SZ683=358580270=10216.0271=1346=11023=1279=0269=048=17359555=6SZ683=358581270=10206.0271=43346=81023=1010=008
1128=99=17935=X49=SAMPLE75=2016101134=448452=2016031823384152656633660=201603182338415265663365799=10000100268=1279=1269=048=17360055=6SH783=99587270=10268.0271=5346=21023=110=078
1128=99=18235=X49=SAMPLE75=2016101134=420352=2005082407282927303430460=200508240728292730343045799=10000100268=1279=1269=048=17359555=6SZ683=358582270=10211.0271=27346=111023=510=219
1128=99=18035=X49=SAMPLE75=2016101134=494852=2011010102212346679584060=201101010221234667958405799=10000100268=1279=0269=048=17359555=6SZ683=358583270=10216.0271=1346=11023=110=115
1128=99=17935=X49=SAMPLE75=2016101134=393152=2003122506015182414052860=200312250601518241405285799=10000100268=1279=0269=048=17360055=6SH783=99588270=10269.0271=3346=11023=110=070
1128=99=17935=X49=SAMPLE75=2016101134=299652=2002013010544121909515260=200201301054412190951525799=10000100268=1279=1269=048=17360055=6SH783=99589270=10268.0271=6346=31023=210=087
1128=99=18235=X49=SAMPLE75=2016101134=387452=2001012908310738606151260=200101290831073860615125799=10000100268=1279=1269=048=17359555=6SZ683=358584270=10211.0271=29346=121023=610=225
1128=99=25335=X49=SAMPLE75=2016101134=1652=2015041902245835253747260=201504190224583525374725799=10000100268=2279=2269=048=17359555=6SZ683=358585270=10216.0271=1346=11023=1279=0269=048=17359555=6SZ683=358586270=10206.0271=43346=81023=1010=027
1128=99=17935=X49=SAMPLE75=2016101134=97552=2000092505261951359479260=200009250526195135947925799=10000100268=1279=1269=048=17360055=6SH783=99590270=10268.0271=5346=21023=210=075
1128=99=18235=X49=SAMPLE75=2016101134=300852=2015100804592470567321660=201510080459247056732165799=10000100268=1279=1269=048=17359555=6SZ683=358587270=10211.0271=27346=111023=510=206
1128=99=25035=X49=SAMPLE75=2016101134=320052=2003011804000131944171260=200301180400013194417125799=10000100268=2279=2269=048=17360055=6SH783=99591270=10269.0271=3346=11023=1279=0269=048=17360055=6SH783=99592270=10259.0271=3346=11023=1010=068
1128=99=18035=X49=SAMPLE75=2016101134=322452=2003080213062769535033660=200308021306276953503365799=10000100268=1279=0269=048=17359555=6SZ683=358588270=10216.0271=1346=11023=110=142
1128=99=17935=X49=SAMPLE75=2016101134=334952=2009110802443094818892860=200911080244309481889285799=10000100268=1279=1269=048=17360055=6SH783=99593270=10268.0271=6346=31023=110=074
1128=99=18235=X49=SAMPLE75=2016101134=104652=2015012310455888040960060=201501231045588804096005799=10000100268=1279=1269=048=17359555=6SZ683=358589270=10211.0271=29346=121023=610=248
1128=99=25335=X49=SAMPLE75=2016101134=124752=2002010822365083896787260=200201082236508389678725799=10000100268=2279=2269=048=17359555=6SZ683=358590270=10216.0271=1346=11023=1279=0269=048=17359555=6SZ683=358591270=10206.0271=43346=81023=1010=040
1128=99=17935=X49=SAMPLE75=2016101134=7552=2007011418494423484131260=200701141849442348413125799=10000100268=1279=1269=048=17360055=6SH783=99594270=10268.0271=5346=21023=110=063
1128=99=18235=X49=SAMPLE75=2016101134=101452=2014012915233649821452860=201401291523364982145285799=10000100268=1279=1269=048=17359555=6SZ683=358592270=10211.0271=27346=111023=510=229
1128=99=18035=X49=SAMPLE75=2016101134=80852=2011082619474350729964860=201108261947435072996485799=10000100268=1279=0269=048=17359555=6SZ683=358593270=10216.0271=1346=11023=110=102
1128=99=17935=X49=SAMPLE75=2016101134=16852=2013101814184795049644860=201310181418479504964485799=10000100268=1279=0269=048=17360055=6SH783=99595270=10269.0271=3346=11023=110=062
1128=99=17935=X49=SAMPLE75=2016101134=332252=2016080120360280283366460=201608012036028028336645799=10000100268=1279=1269=048=17360055=6SH783=99596270=10268.0271=6346=31023=210=053
1128=99=18235=X49=SAMPLE75=2016101134=480052=2001040305491669439873660=200104030549166943987365799=10000100268=1279=1269=048=17359555=6SZ683=358594270=10211.0271=29346=121023=610=208
1128=99=25335=X49=SAMPLE75=2016101134=233452=2007021013551853830963260=200702101355185383096325799=10000100268=2279=2269=048=17359555=6SZ683=358595270=10216.0271=1346=11023=1279=0269=048=17359555=6SZ683=358596270=10206.0271=43346=81023=1010=251
1128=99=17935=X49=SAMPLE75=2016101134=346252=2013060713365748503859260=201306071336574850385925799=10000100268=1279=1269=048=17360055=6SH783=99597270=10268.0271=5346=21023=210=051
1128=99=18235=X49=SAMPLE75=2016101134=193852=2014121508192208655846460=201412150819220865584645799=10000100268=1279=1269=048=17359555=6SZ683=358597270=10211.0271=27346=111023=510=217
1128=99=25035=X49=SAMPLE75=2016101134=163852=2001120400360384709844860=200112040036038470984485799=10000100268=2279=2269=048=17360055=6SH783=99598270=10269.0271=3346=11023=1279=0269=048=17360055=6SH783=99599270=10259.0271=3346=11023=1010=065
1128=99=25435=X49=SAMPLE75=2016101134=434952=2015121800461482063072060=201512180046148206307205799=10000100268=2279=1269=048=17359555=6SZ683=358598270=10212.0271=21346=111023=4279=1269=048=17359555=6SZ683=358599270=10208.0271=32346=91023=810=085
1128=99=25135=X49=SAMPLE75=2016101134=61452=2010072622262587112384060=201007262226258711238405799=10000100268=2279=1269=048=17360055=6SH783=99600270=10263.0271=4346=21023=6279=1269=048=17360055=6SH783=99601270=10259.0271=11346=21023=1010=104
1128=99=18035=X49=SAMPLE75=2016101134=64852=2008111920181984482355260=200811192018198448235525799=10000100268=1279=0269=048=17359555=6SZ683=358600270=10216.0271=1346=11023=110=104
1128=99=17935=X49=SAMPLE75=2016101134=23852=2013041120345042780076860=201304112034504278007685799=10000100268=1279=0269=048=17360055=6SH783=99602270=10269.0271=3346=11023=110=051
1128=99=17935=X49=SAMPLE75=2016101134=328252=2007042722525177031468860=200704272252517703146885799=10000100268=1279=1269=048=17360055=6SH783=99603270=10268.0271=6346=31023=210=064
1128=99=18235=X49=SAMPLE75=2016101134=490152=2002092415241430220390460=200209241524143022039045799=10000100268=1279=1269=048=17359555=6SZ683=358601270=10211.0271=29346=121023=610=211
1128=99=18235=X49=SAMPLE75=2016101134=9452=2011011810211825183468860=201101181021182518346885799=10000100268=1279=1269=048=17359555=6SZ683=358602270=10208.0271=33346=101023=910=226
1128=99=25335=X49=SAMPLE75=2016101134=410352=2016071007034031063116860=201607100703403106311685799=10000100268=2279=2269=048=17359555=6SZ683=358603270=10216.0271=1346=11023=1279=0269=048=17359555=6SZ683=358604270=10206.0271=43346=81023=1010=238
1128=99=17935=X49=SAMPLE75=2016101134=258952=2017031223301732517427260=201703122330173251742725799=10000100268=1279=1269=048=17360055=6SH783=99604270=10268.0271=5346=21023=210=049
1128=99=18235=X49=SAMPLE75=2016101134=96752=2000052510341519889423260=200005251034151988942325799=10000100268=1279=1269=048=17359555=6SZ683=358605270=10211.0271=27346=111023=510=212
1128=99=18235=X49=SAMPLE75=2016101134=139652=2008072417512831941068860=200807241751283194106885799=10000100268=1279=1269=048=17359555=6SZ683=358606270=10215.0271=17346=121023=110=210
1128=99=25135=X49=SAMPLE75=2016101134=49152=2004012423150602021032060=200401242315060202103205799=10000100268=2279=2269=048=17360055=6SH783=99605270=10269.0271=3346=11023=1279=0269=048=17360055=6SH783=99606270=10259.0271=11346=21023=1010=112
1128=99=18235=X49=SAMPLE75=2016101134=176552=2009021117093773980636860=200902111709377398063685799=10000100268=1279=1269=048=17359555=6SZ683=358607270=10215.0271=25346=131023=110=219
1128=99=18235=X49=SAMPLE75=2016101134=381452=2008010518052679933081660=200801051805267993308165799=10000100268=1279=1269=048=17359555=6SZ683=358608270=10215.0271=17346=121023=110=235
1128=99=18235=X49=SAMPLE75=2016101134=425552=2007120410490963228563260=200712041049096322856325799=10000100268=1279=1269=048=17359555=6SZ683=358609270=10215.0271=16346=111023=110=226
1128=99=18235=X49=SAMPLE75=2016101134=486852=2007030804381309919305660=200703080438130991930565799=10000100268=1279=1269=048=17359555=6SZ683=358610270=10215.0271=13346=101023=110=215
1128=99=18135=X49=SAMPLE75=2016101134=21352=2016051620512569260819260=201605162051256926081925799=10000100268=1279=1269=048=17359555=6SZ683=358611270=10215.0271=12346=91023=110=187
1128=99=18135=X49=SAMPLE75=2016101134=118252=2015112005223638849651260=201511200522363884965125799=10000100268=1279=1269=048=17359555=6SZ683=358612270=10207.0271=26346=91023=910=201
1128=99=18135=X49=SAMPLE75=2016101134=339852=2007051606133478524163260=200705160613347852416325799=10000100268=1279=1269=148=17359555=6SZ683=358613270=10217.0271=13346=61023=110=155
1128=99=18135=X49=SAMPLE75=2016101134=330152=2000032805531060868718760=200003280553106086871875799=10000100268=1279=1269=048=17359555=6SZ683=358614270=10215.0271=11346=81023=110=183
1128=99=18035=X49=SAMPLE75=2016101134=210052=2016101219583283928153660=201610121958328392815365799=10000100268=1279=0269=148=17359555=6SZ683=358615270=10216.0271=1346=11023=110=121
1128=99=17935=X49=SAMPLE75=2016101134=71852=2004051317124738015952060=200405131712473801595205799=10000100268=1279=0269=148=17360055=6SH783=99607270=10272.0271=3346=11023=110=064
1128=99=17935=X49=SAMPLE75=2016101134=4552=2005031805153058410108860=200503180515305841010885799=10000100268=1279=0269=148=17360055=6SH783=99608270=10273.0271=3346=11023=210=059
1128=99=17935=X49=SAMPLE75=2016101134=291752=2009060705440510846758460=200906070544051084675845799=10000100268=1279=1269=148=17360055=6SH783=99609270=10272.0271=6346=21023=110=076
1128=99=17935=X49=SAMPLE75=2016101134=176552=2011092213241527097868860=201109221324152709786885799=10000100268=1279=1269=148=17360055=6SH783=99610270=10273.0271=4346=21023=210=058
1128=99=18235=X49=SAMPLE75=2016101134=417452=2016011219155454046560060=201601121915545404656005799=10000100268=1279=1269=148=17359555=6SZ683=358616270=10221.0271=29346=131023=610=250
1128=99=18135=X49=SAMPLE75=2016101134=52052=2013071121305773105907260=201307112130577310590725799=10000100268=1279=1269=048=17359555=6SZ683=358617270=10215.0271=10346=71023=110=168
1128=99=18035=X49=SAMPLE75=2016101134=329652=2009100915004333768345660=200910091500433376834565799=10000100268=1279=1269=148=17360055=6SH783=99611270=10276.0271=37346=31023=510=104
1128=99=18135=X49=SAMPLE75=2016101134=181452=2016050507493976887180860=201605050749397688718085799=10000100268=1279=1269=148=17359555=6SZ683=358618270=10217.0271=14346=71023=210=176
1128=99=18135=X49=SAMPLE75=2016101134=367452=2016100607514270739513660=201610060751427073951365799=10000100268=1279=1269=148=17359555=6SZ683=358619270=10223.0271=23346=71023=810=196
1128=99=18235=X49=SAMPLE75=2016101134=185152=2013102501071121661798460=201310250107112166179845799=10000100268=1279=1269=148=17359555=6SZ683=358620270=10218.0271=19346=101023=310=212
1128=99=18035=X49=SAMPLE75=2016101134=64452=2000120419175812898884860=200012041917581289888485799=10000100268=1279=1269=048=17359555=6SZ683=358621270=10215.0271=9346=61023=110=132
1128=99=18035=X49=SAMPLE75=2016101134=12752=2003011610262149215892860=200301161026214921589285799=10000100268=1279=1269=148=17359555=6SZ683=358622270=10216.0271=2346=21023=110=119
1128=99=18135=X49=SAMPLE75=2016101134=73252=2005112019204617590073660=200511201920461759007365799=10000100268=1279=1269=148=17359555=6SZ683=358623270=10217.0271=16346=81023=210=185
1128=99=18035=X49=SAMPLE75=2016101134=332952=2006110900094711138950460=200611090009471113895045799=10000100268=1279=1269=148=17359555=6SZ683=358624270=10216.0271=3346=31023=110=103
1128=99=17935=X49=SAMPLE75=2016101134=28052=2007060918125557838198460=200706091812555783819845799=10000100268=1279=1269=148=17360055=6SH783=99612270=10272.0271=3346=11023=110=038
1128=99=18035=X49=SAMPLE75=2016101134=487652=2005101403094610578992060=200510140309461057899205799=10000100268=1279=1269=048=17359555=6SZ683=358625270=10215.0271=7346=51023=110=136
1128=99=18235=X49=SAMPLE75=2016101134=101452=2013061007533542705497660=201306100753354270549765799=10000100268=1279=1269=048=17359555=6SZ683=358626270=10213.0271=21346=111023=310=198
1128=99=18035=X49=SAMPLE75=2016101134=226852=2007010811463838842358460=200701081146383884235845799=10000100268=1279=1269=148=17359555=6SZ683=358627270=10216.0271=4346=41023=110=127
1128=99=18035=X49=SAMPLE75=2016101134=344652=2003060908134922931220860=200306090813492293122085799=10000100268=1279=1269=148=17359555=6SZ683=358628270=10216.0271=5346=51023=110=145
1128=99=18135=X49=SAMPLE75=2016101134=27952=2005092423220127239958460=200509242322012723995845799=10000100268=1279=1269=148=17359555=6SZ683=358629270=10219.0271=18346=91023=410=187
1128=99=25035=X49=SAMPLE75=2016101134=303052=2008050513100976107219260=200805051310097610721925799=10000100268=2279=2269=148=17360055=6SH783=99613270=10272.0271=3346=11023=1279=0269=148=17360055=6SH783=99614270=10282.0271=3346=11023=1010=052
1128=99=18235=X49=SAMPLE75=2016101134=276452=2005091305345261923097660=200509130534526192309765799=10000100268=1279=1269=148=17359555=6SZ683=358630270=10220.0271=28346=111023=510=198
1128=99=18035=X49=SAMPLE75=2016101134=68752=2013080904004293706406460=201308090400429370640645799=10000100268=1279=1269=148=17359555=6SZ683=358631270=10216.0271=4346=41023=110=132
1128=99=25435=X49=SAMPLE75=2016101134=168052=2010030414094901266624060=201003041409490126662405799=10000100268=2279=1269=148=17359555=6SZ683=358632270=10220.0271=36346=121023=5279=1269=148=17359555=6SZ683=358633270=10224.0271=38346=51023=910=075
1128=99=18035=X49=SAMPLE75=2016101134=410552=2012031803153618184652860=201203180315361818465285799=10000100268=1279=1269=148=17360055=6SH783=99615270=10279.0271=11346=21023=710=105
1128=99=18135=X49=SAMPLE75=2016101134=226352=2012030513570603037427260=201203051357060303742725799=10000100268=1279=1269=148=17359555=6SZ683=358634270=10217.0271=17346=91023=210=197
1128=99=18135=X49=SAMPLE75=2016101134=268152=2000091917101856038510060=200009191710185603851005799=10000100268=1279=1269=048=17359555=6SZ683=358635270=10207.0271=25346=81023=910=187
1128=99=18235=X49=SAMPLE75=2016101134=164252=2012052907095400021196860=201205290709540002119685799=10000100268=1279=1269=048=17359555=6SZ683=358636270=10214.0271=22346=121023=210=229
1128=99=18235=X49=SAMPLE75=2016101134=393352=2015012704271097775840060=201501270427109777584005799=10000100268=1279=1269=048=17359555=6SZ683=358637270=10214.0271=19346=111023=210=210
1128=99=18235=X49=SAMPLE75=2016101134=306052=2009011006393715352246460=200901100639371535224645799=10000100268=1279=1269=148=17359555=6SZ683=358638270=10217.0271=19346=101023=210=004
1128=99=18235=X49=SAMPLE75=2016101134=260252=2001052216030931971861660=200105221603093197186165799=10000100268=1279=1269=048=17359555=6SZ683=358639270=10214.0271=20346=121023=210=255
1128=99=18135=X49=SAMPLE75=2016101134=23952=2008022318023154285081660=200802231802315428508165799=10000100268=1279=1269=148=17359555=6SZ683=358640270=10218.0271=18346=91023=310=213
1128=99=18235=X49=SAMPLE75=2016101134=8752=2015052500364124791340860=201505250036412479134085799=10000100268=1279=1269=148=17359555=6SZ683=358641270=10217.0271=20346=111023=210=233
1128=99=18035=X49=SAMPLE75=2016101134=205852=2004041102125886356702460=200404110212588635670245799=10000100268=1279=1269=148=17359555=6SZ683=358642270=10216.0271=3346=31023=110=084
1128=99=18035=X49=SAMPLE75=2016101134=290952=2010081708332616427596860=201008170833261642759685799=10000100268=1279=1269=048=17359555=6SZ683=358643270=10215.0271=8346=61023=110=104
1128=99=18035=X49=SAMPLE75=2016101134=413752=2002052410333316808921660=200205241033331680892165799=10000100268=1279=1269=148=17359555=6SZ683=358644270=10216.0271=2346=21023=110=092
1128=99=18035=X49=SAMPLE75=2016101134=55052=2015031223071802799424060=201503122307180279942405799=10000100268=1279=1269=148=17359555=6SZ683=358645270=10216.0271=1346=11023=110=100
1128=99=25335=X49=SAMPLE75=2016101134=372352=2006092003483994943276860=200609200348399494327685799=10000100268=2279=2269=148=17359555=6SZ683=358646270=10216.0271=1346=11023=1279=0269=148=17359555=6SZ683=358647270=10226.0271=18346=41023=1010=224
1128=99=17935=X49=SAMPLE75=2016101134=57452=2013011207265263799520060=201301120726526379952005799=10000100268=1279=1269=148=17360055=6SH783=99616270=10273.0271=3346=11023=110=019
1128=99=18235=X49=SAMPLE75=2016101134=458352=2002100100304293948452860=200210010030429394845285799=10000100268=1279=1269=148=17359555=6SZ683=358648270=10221.0271=27346=121023=510=197
1128=99=17935=X49=SAMPLE75=2016101134=282152=2015093010153664641696060=201509301015366464169605799=10000100268=1279=1269=148=17360055=6SH783=99617270=10276.0271=4346=21023=410=033
1128=99=18035=X49=SAMPLE75=2016101134=214352=2005071706030051811481660=200507170603005181148165799=10000100268=1279=1269=048=17359555=6SZ683=358649270=10215.0271=9346=71023=110=091
1128=99=18235=X49=SAMPLE75=2016101134=329252=2010010503515030741772860=201001050351503074177285799=10000100268=1279=1269=148=17359555=6SZ683=358650270=10217.0271=19346=101023=110=195
1128=99=18235=X49=SAMPLE75=2016101134=15052=2003012921355510716563260=200301292135551071656325799=10000100268=1279=1269=048=17359555=6SZ683=358651270=10214.0271=23346=131023=210=197
1128=99=25435=X49=SAMPLE75=2016101134=168952=2004032000112612960556860=200403200011261296055685799=10000100268=2279=1269=148=17359555=6SZ683=358652270=10220.0271=28346=111023=4279=1269=148=17359555=6SZ683=358653270=10224.0271=46346=61023=810=045
1128=99=17935=X49=SAMPLE75=2016101134=283552=2006122419093437524656060=200612241909343752465605799=10000100268=1279=1269=148=17360055=6SH783=99618270=10279.0271=3346=11023=710=043
1128=99=18135=X49=SAMPLE75=2016101134=124652=2002100505035816306780860=200210050503581630678085799=10000100268=1279=1269=148=17359555=6SZ683=358654270=10217.0271=11346=91023=110=178
1128=99=18135=X49=SAMPLE75=2016101134=98652=2002122301594322382808060=200212230159432238280805799=10000100268=1279=1269=148=17359555=6SZ683=358655270=10219.0271=17346=81023=310=154
1128=99=18135=X49=SAMPLE75=2016101134=438952=2009102704155383575974460=200910270415538357597445799=10000100268=1279=1269=148=17359555=6SZ683=358656270=10217.0271=10346=81023=110=151
1128=99=18035=X49=SAMPLE75=2016101134=379452=2005030400145919877686460=200503040014591987768645799=10000100268=1279=1269=148=17359555=6SZ683=358657270=10217.0271=8346=71023=110=089
1128=99=18135=X49=SAMPLE75=2016101134=164452=2006052811132607269926460=200605281113260726992645799=10000100268=1279=1269=148=17359555=6SZ683=358658270=10218.0271=16346=81023=210=160
1128=99=18135=X49=SAMPLE75=2016101134=311552=2008032310010437739808060=200803231001043773980805799=10000100268=1279=1269=048=17359555=6SZ683=358659270=10215.0271=10346=81023=110=156
1128=99=18235=X49=SAMPLE75=2016101134=495152=2000101522352647137527660=200010152235264713752765799=10000100268=1279=1269=048=17359555=6SZ683=358660270=10214.0271=22346=121023=210=197
1128=99=18135=X49=SAMPLE75=2016101134=469452=2006082816262127272672060=200608281626212727267205799=10000100268=1279=1269=048=17359555=6SZ683=358661270=10207.0271=26346=91023=910=171
1128=99=18135=X49=SAMPLE75=2016101134=398252=2001082313543333787738460=200108231354333378773845799=10000100268=1279=1269=148=17359555=6SZ683=358662270=10218.0271=15346=71023=210=179
1128=99=18135=X49=SAMPLE75=2016101134=379852=2016060320394565072179260=201606032039456507217925799=10000100268=1279=1269=148=17359555=6SZ683=358663270=10223.0271=24346=81023=710=172
1128=99=18135=X49=SAMPLE75=2016101134=348852=2016121510261586762662460=201612151026158676266245799=10000100268=1279=1269=048=17359555=6SZ683=358664270=10215.0271=12346=91023=110=146
1128=99=18235=X49=SAMPLE75=2016101134=353052=2004082304314257632944060=200408230431425763294405799=10000100268=1279=1269=148=17359555=6SZ683=358665270=10220.0271=21346=101023=410=226
1128=99=18235=X49=SAMPLE75=2016101134=477552=2005122713404202450953660=200512271340420245095365799=10000100268=1279=1269=048=17359555=6SZ683=358666270=10214.0271=21346=111023=210=222
1128=99=18235=X49=SAMPLE75=2016101134=83952=2002042617484579312136060=200204261748457931213605799=10000100268=1279=1269=048=17359555=6SZ683=358667270=10215.0271=13346=101023=110=213
1128=99=18135=X49=SAMPLE75=2016101134=177052=2010030821032615268595260=201003082103261526859525799=10000100268=1279=1269=148=17359555=6SZ683=358668270=10218.0271=17346=81023=210=170
1128=99=18135=X49=SAMPLE75=2016101134=4252=2001051409540046249778460=200105140954004624977845799=10000100268=1279=1269=148=17359555=6SZ683=358669270=10218.0271=15346=71023=210=173
1128=99=18135=X49=SAMPLE75=2016101134=400252=2016030220391673194195260=201603022039167319419525799=10000100268=1279=1269=148=17359555=6SZ683=358670270=10218.0271=16346=81023=210=186
1128=99=18035=X49=SAMPLE75=2016101134=60352=2011031420175948295897660=201103142017594829589765799=10000100268=1279=0269=048=17359555=6SZ683=358671270=10216.0271=1346=11023=110=098
1128=99=17935=X49=SAMPLE75=2016101134=257652=2005091103563818657251260=200509110356381865725125799=10000100268=1279=0269=048=17360055=6SH783=99619270=10269.0271=3346=11023=110=048
1128=99=17935=X49=SAMPLE75=2016101134=169952=2014040701370736145254460=201404070137073614525445799=10000100268=1279=1269=048=17360055=6SH783=99620270=10268.0271=6346=31023=210=050
1128=99=18235=X49=SAMPLE75=2016101134=109652=2015091500110843986067260=201509150011084398606725799=10000100268=1279=1269=048=17359555=6SZ683=358672270=10211.0271=29346=121023=610=227
1128=99=18235=X49=SAMPLE75=2016101134=134352=2004031210161511569204860=200403121016151156920485799=10000100268=1279=1269=048=17359555=6SZ683=358673270=10207.0271=25346=81023=1010=211
1128=99=18235=X49=SAMPLE75=2016101134=374252=2004102307061694579782460=200410230706169457978245799=10000100268=1279=1269=048=17359555=6SZ683=358674270=10214.0271=22346=121023=310=228
1128=99=25335=X49=SAMPLE75=2016101134=78152=2008011922392419785462460=200801192239241978546245799=10000100268=2279=2269=048=17359555=6SZ683=358675270=10216.0271=1346=11023=1279=0269=048=17359555=6SZ683=358676270=10206.0271=43346=81023=1010=025
1128=99=18235=X49=SAMPLE75=2016101134=64852=2012123103584965599897660=201212310358496559989765799=10000100268=1279=1269=048=17359555=6SZ683=358677270=10215.0271=16346=111023=110=212
1128=99=18135=X49=SAMPLE75=2016101134=240252=2002122518032401842166460=200212251803240184216645799=10000100268=1279=1269=148=17359555=6SZ683=358678270=10218.0271=18346=91023=210=185
1128=99=17935=X49=SAMPLE75=2016101134=100552=2009110515294831555987260=200911051529483155598725799=10000100268=1279=1269=048=17360055=6SH783=99621270=10268.0271=5346=21023=210=030
1128=99=18235=X49=SAMPLE75=2016101134=169452=2015081118462122915660860=201508111846212291566085799=10000100268=1279=1269=048=17359555=6SZ683=358679270=10211.0271=27346=111023=510=215
1128=99=25135=X49=SAMPLE75=2016101134=355952=2003122409031031829097660=200312240903103182909765799=10000100268=2279=2269=048=17360055=6SH783=99622270=10269.0271=3346=11023=1279=0269=048=17360055=6SH783=99623270=10259.0271=11346=21023=1010=084
1128=99=18035=X49=SAMPLE75=2016101134=466352=2001022105424723725269660=200102210542472372526965799=10000100268=1279=1269=148=17359555=6SZ683=358680270=10217.0271=6346=61023=110=109
1128=99=18235=X49=SAMPLE75=2016101134=210252=2010092611251592762502460=201009261125159276250245799=10000100268=1279=1269=048=17359555=6SZ683=358681270=10211.0271=28346=121023=510=217
1128=99=18235=X49=SAMPLE75=2016101134=357352=2011082316445517256070460=201108231644551725607045799=10000100268=1279=1269=048=17359555=6SZ683=358682270=10215.0271=24346=121023=110=222
1128=99=18035=X49=SAMPLE75=2016101134=205552=2000061314430834522454260=200006131443083452245425799=10000100268=1279=0269=048=17359555=6SZ683=358683270=10216.0271=1346=11023=110=109
1128=99=17935=X49=SAMPLE75=2016101134=112252=2012103113441951129715260=201210311344195112971525799=10000100268=1279=0269=048=17360055=6SH783=99624270=10269.0271=3346=11023=110=050
1128=99=17935=X49=SAMPLE75=2016101134=427252=2000021106383241274849560=200002110638324127484955799=10000100268=1279=1269=048=17360055=6SH783=99625270=10268.0271=6346=31023=210=057
1128=99=18235=X49=SAMPLE75=2016101134=176952=2014081516374588458675260=201408151637458845867525799=10000100268=1279=1269=048=17359555=6SZ683=358684270=10211.0271=30346=131023=610=227
1128=99=25335=X49=SAMPLE75=2016101134=380152=2005012321022137180198460=200501232102213718019845799=10000100268=2279=2269=048=17359555=6SZ683=358685270=10216.0271=1346=11023=1279=0269=048=17359555=6SZ683=358686270=10206.0271=43346=81023=1010=018
1128=99=17935=X49=SAMPLE75=2016101134=398852=2000032920084000325990560=200003292008400032599055799=10000100268=1279=1269=048=17360055=6SH783=99626270=10268.0271=5346=21023=210=067
1128=99=18235=X49=SAMPLE75=2016101134=387152=2001070621014779554136860=200107062101477955413685799=10000100268=1279=1269=048=17359555=6SZ683=358687270=10211.0271=28346=121023=510=224
1128=99=25135=X49=SAMPLE75=2016101134=449452=2010091123401073837472060=201009112340107383747205799=10000100268=2279=2269=048=17360055=6SH783=99627270=10269.0271=3346=11023=1279=0269=048=17360055=6SH783=99628270=10259.0271=11346=21023=1010=120
1128=99=18135=X49=SAMPLE75=2016101134=223252=2001052423550148588172860=200105242355014858817285799=10000100268=1279=1269=148=17359555=6SZ683=358688270=10220.0271=20346=91023=410=185
1128=99=18035=X49=SAMPLE75=2016101134=289852=2012122419434330269324860=201212241943433026932485799=10000100268=1279=0269=048=17359555=6SZ683=358689270=10216.0271=1346=11023=110=124
1128=99=17935=X49=SAMPLE75=2016101134=203852=2016102705155248360595260=201610270515524836059525799=10000100268=1279=1269=048=17360055=6SH783=99629270=10268.0271=6346=31023=110=080
1128=99=18235=X49=SAMPLE75=2016101134=161852=2008032309301639850384060=200803230930163985038405799=10000100268=1279=1269=048=17359555=6SZ683=358690270=10211.0271=30346=131023=610=230
1128=99=25335=X49=SAMPLE75=2016101134=25052=2012113005572154955545660=201211300557215495554565799=10000100268=2279=2269=048=17359555=6SZ683=358691270=10216.0271=1346=11023=1279=0269=048=17359555=6SZ683=358692270=10206.0271=43346=81023=1010=029
1128=99=17935=X49=SAMPLE75=2016101134=124652=2001110601274617730366460=200111060127461773036645799=10000100268=1279=1269=048=17360055=6SH783=99630270=10268.0271=5346=21023=110=057
1128=99=18235=X49=SAMPLE75=2016101134=488052=2006102802511267555187260=200610280251126755518725799=10000100268=1279=1269=048=17359555=6SZ683=358693270=10211.0271=28346=121023=510=210
1128=99=18035=X49=SAMPLE75=2016101134=452452=2000052402271973403758060=200005240227197340375805799=10000100268=1279=0269=048=17359555=6SZ683=358694270=10216.0271=1346=11023=110=121
1128=99=17935=X49=SAMPLE75=2016101134=185452=2000050115155063765251660=200005011515506376525165799=10000100268=1279=1269=048=17360055=6SH783=99631270=10268.0271=6346=31023=110=063
1128=99=18235=X49=SAMPLE75=2016101134=335652=2014080717395189928748860=201408071739518992874885799=10000100268=1279=1269=048=17359555=6SZ683=358695270=10211.0271=30346=131023=610=234
1128=99=25335=X49=SAMPLE75=2016101134=192752=2009082110202545413318460=200908211020254541331845799=10000100268=2279=2269=048=17359555=6SZ683=358696270=10216.0271=1346=11023=1279=0269=048=17359555=6SZ683=358697270=10206.0271=43346=81023=1010=049
1128=99=17935=X49=SAMPLE75=2016101134=354252=2013091007320177768166460=201309100732017776816645799=10000100268=1279=1269=048=17360055=6SH783=99632270=10268.0271=5346=21023=110=067
1128=99=18235=X49=SAMPLE75=2016101134=97352=2016030100353153009683260=201603010035315300968325799=10000100268=1279=1269=048=17359555=6SZ683=358698270=10211.0271=28346=121023=510=241
1128=99=18035=X49=SAMPLE75=2016101134=154352=2017011315352843308409660=201701131535284330840965799=10000100268=1279=0269=048=17359555=6SZ683=358699270=10216.0271=1346=11023=110=127
1128=99=17935=X49=SAMPLE75=2016101134=154352=2009110100255926450604860=200911010025592645060485799=10000100268=1279=1269=048=17360055=6SH783=99633270=10268.0271=6346=31023=110=041
1128=99=18235=X49=SAMPLE75=2016101134=190252=2012032505015960857478460=201203250501596085747845799=10000100268=1279=1269=048=17359555=6SZ683=358700270=10211.0271=30346=131023=610=203
1128=99=25335=X49=SAMPLE75=2016101134=221152=2012102703581649454457660=201210270358164945445765799=10000100268=2279=2269=048=17359555=6SZ683=358701270=10216.0271=1346=11023=1279=0269=048=17359555=6SZ683=358702270=10206.0271=43346=81023=1010=010
1128=99=17935=X49=SAMPLE75=2016101134=331952=2000081512485538311570460=200008151248553831157045799=10000100268=1279=1269=048=17360055=6SH783=99634270=10268.0271=5346=21023=110=050
1128=99=18235=X49=SAMPLE75=2016101134=447352=2007080212503552267753660=200708021250355226775365799=10000100268=1279=1269=048=17359555=6SZ683=358703270=10211.0271=28346=121023=510=228
1128=99=18235=X49=SAMPLE75=2016101134=14452=2007091209195974083638460=200709120919597408363845799=10000100268=1279=1269=048=17359555=6SZ683=358704270=10211.0271=27346=111023=510=221
1128=99=18035=X49=SAMPLE75=2016101134=339252=2000062604423471504220460=200006260442347150422045799=10000100268=1279=0269=048=17359555=6SZ683=358705270=10216.0271=1346=11023=110=132
1128=99=17935=X49=SAMPLE75=2016101134=14352=2016060523512104153696060=201606052351210415369605799=10000100268=1279=0269=048=17360055=6SH783=99635270=10269.0271=3346=11023=110=046
1128=99=17935=X49=SAMPLE75=2016101134=291552=2002031200071085744072860=200203120007108574407285799=10000100268=1279=1269=048=17360055=6SH783=99636270=10268.0271=6346=31023=210=066
1128=99=18235=X49=SAMPLE75=2016101134=126452=2013053103022242376435260=201305310302224237643525799=10000100268=1279=1269=048=17359555=6SZ683=358706270=10211.0271=29346=121023=610=226
1128=99=25335=X49=SAMPLE75=2016101134=239552=2013042408512452125664060=201304240851245212566405799=10000100268=2279=2269=048=17359555=6SZ683=358707270=10216.0271=1346=11023=1279=0269=048=17359555=6SZ683=358708270=10206.0271=43346=81023=1010=010
1128=99=17935=X49=SAMPLE75=2016101134=205652=2002070801114744246387260=200207080111474424638725799=10000100268=1279=1269=048=17360055=6SH783=99637270=10268.0271=5346=21023=210=068
1128=99=18235=X49=SAMPLE75=2016101134=27952=2010022106423940017760060=201002210642394001776005799=10000100268=1279=1269=048=17359555=6SZ683=358709270=10211.0271=27346=111023=510=238
1128=99=25135=X49=SAMPLE75=2016101134=340852=2008061817470286202854460=200806181747028620285445799=10000100268=2279=2269=048=17360055=6SH783=99638270=10269.0271=3346=11023=1279=0269=048=17360055=6SH783=99639270=10259.0271=11346=21023=1010=147
1128=99=18235=X49=SAMPLE75=2016101134=116452=2008091406011230662742460=200809140601123066274245799=10000100268=1279=1269=048=17359555=6SZ683=358710270=10211.0271=26346=101023=510=229
1128=99=18235=X49=SAMPLE75=2016101134=327652=2002021016062627314971260=200202101606262731497125799=10000100268=1279=1269=048=17359555=6SZ683=358711270=10215.0271=16346=111023=110=196
1128=99=18235=X49=SAMPLE75=2016101134=443152=2010100614374558876102460=201010061437455887610245799=10000100268=1279=1269=048=17359555=6SZ683=358712270=10215.0271=15346=101023=110=249
1128=99=18135=X49=SAMPLE75=2016101134=42952=2002020521271931877724860=200202052127193187772485799=10000100268=1279=1269=048=17359555=6SZ683=358713270=10215.0271=12346=91023=110=139
1128=99=18135=X49=SAMPLE75=2016101134=57252=2003040115231399181307260=200304011523139918130725799=10000100268=1279=1269=148=17359555=6SZ683=358714270=10218.0271=16346=81023=210=152
1128=99=18235=X49=SAMPLE75=2016101134=486352=2003060613514106203419260=200306061351410620341925799=10000100268=1279=1269=048=17359555=6SZ683=358715270=10214.0271=21346=111023=210=197
1128=99=18135=X49=SAMPLE75=2016101134=121552=2006111121555212244608060=200611112155521224460805799=10000100268=1279=1269=048=17359555=6SZ683=358716270=10207.0271=26346=91023=910=165
1128=99=18235=X49=SAMPLE75=2016101134=261352=2006100812015276033686460=200610081201527603368645799=10000100268=1279=1269=048=17359555=6SZ683=358717270=10211.0271=27346=111023=510=206
1128=99=18135=X49=SAMPLE75=2016101134=300852=2008082216110530119494460=200808221611053011949445799=10000100268=1279=1269=048=17359555=6SZ683=358718270=10215.0271=11346=81023=110=183
1128=99=25435=X49=SAMPLE75=2016101134=159952=2014032623361100713113660=201403262336110071311365799=10000100268=2279=1269=048=17359555=6SZ683=358719270=10209.0271=44346=81023=7279=1269=048=17359555=6SZ683=358720270=10208.0271=36346=111023=810=084
1128=99=18035=X49=SAMPLE75=2016101134=233152=2006111903503127033225660=200611190350312703322565799=10000100268=1279=1269=148=17359555=6SZ683=358721270=10217.0271=8346=71023=110=148
1128=99=18135=X49=SAMPLE75=2016101134=385452=2012082719004231939353660=201208271900423193935365799=10000100268=1279=1269=148=17359555=6SZ683=358722270=10218.0271=18346=91023=210=199
1128=99=18135=X49=SAMPLE75=2016101134=222752=2010070602540645017920060=201007060254064501792005799=10000100268=1279=1269=048=17359555=6SZ683=358723270=10215.0271=10346=71023=110=182
1128=99=18035=X49=SAMPLE75=2016101134=324152=2002041707314230678766460=200204170731423067876645799=10000100268=1279=0269=148=17359555=6SZ683=358724270=10216.0271=1346=11023=110=132
1128=99=17935=X49=SAMPLE75=2016101134=317452=2011042106112312752819260=201104210611231275281925799=10000100268=1279=0269=148=17360055=6SH783=99640270=10272.0271=3346=11023=110=072
1128=99=17935=X49=SAMPLE75=2016101134=143752=2002021304033564721988060=200202130403356472198805799=10000100268=1279=1269=148=17360055=6SH783=99641270=10273.0271=4346=21023=210=060
1128=99=18035=X49=SAMPLE75=2016101134=321452=2015052721275120053491260=201505272127512005349125799=10000100268=1279=1269=148=17360055=6SH783=99642270=10276.0271=37346=31023=510=121
1128=99=18235=X49=SAMPLE75=2016101134=196952=2016080708341848849664060=201608070834184884966405799=10000100268=1279=1269=148=17359555=6SZ683=358725270=10221.0271=29346=131023=610=254
1128=99=18035=X49=SAMPLE75=2016101134=227052=2013020619214795671372860=201302061921479567137285799=10000100268=1279=1269=148=17359555=6SZ683=358726270=10216.0271=2346=21023=110=142
1128=99=18035=X49=SAMPLE75=2016101134=284952=2001092610120613922469660=200109261012061392246965799=10000100268=1279=1269=148=17359555=6SZ683=358727270=10216.0271=3346=31023=110=141
1128=99=18035=X49=SAMPLE75=2016101134=496452=2005110101553043136630460=200511010155304313663045799=10000100268=1279=1269=148=17359555=6SZ683=358728270=10217.0271=9346=81023=210=150
1128=99=18035=X49=SAMPLE75=2016101134=65552=2016012521402186140646460=201601252140218614064645799=10000100268=1279=1269=148=17359555=6SZ683=358729270=10216.0271=2346=21023=110=116
1128=99=18035=X49=SAMPLE75=2016101134=7852=2005012204035792799040060=200501220403579279904005799=10000100268=1279=1269=048=17359555=6SZ683=358730270=10215.0271=8346=61023=110=119
1128=99=18135=X49=SAMPLE75=2016101134=253952=2005042518263686774700860=200504251826368677470085799=10000100268=1279=1269=048=17359555=6SZ683=358731270=10207.0271=25346=81023=910=180
1128=99=18235=X49=SAMPLE75=2016101134=308152=2005072615011160052086460=200507261501116005208645799=10000100268=1279=1269=048=17359555=6SZ683=358732270=10214.0271=22346=121023=210=217
1128=99=18135=X49=SAMPLE75=2016101134=98752=2000041714392848480108460=200004171439284848010845799=10000100268=1279=1269=148=17359555=6SZ683=358733270=10223.0271=23346=71023=810=194
1128=99=18235=X49=SAMPLE75=2016101134=484452=2006080821050598993574460=200608082105059899357445799=10000100268=1279=1269=148=17359555=6SZ683=358734270=10218.0271=19346=101023=310=239
1128=99=18035=X49=SAMPLE75=2016101134=398052=2014070615263843539276860=201407061526384353927685799=10000100268=1279=1269=148=17359555=6SZ683=358735270=10216.0271=3346=31023=110=130
1128=99=25535=X49=SAMPLE75=2016101134=198052=2001100720311166768024060=200110072031116676802405799=10000100268=2279=1269=048=17359555=6SZ683=358736270=10214.0271=21346=111023=2279=1269=048=17359555=6SZ683=358737270=10213.0271=22346=121023=310=131
1128=99=25135=X49=SAMPLE75=2016101134=493352=2010082214561547257344060=201008221456154725734405799=10000100268=2279=1269=148=17359555=6SZ683=358738270=10216.0271=4346=41023=1279=1269=148=17359555=6SZ683=358739270=10217.0271=8346=71023=210=181
1128=99=18035=X49=SAMPLE75=2016101134=248952=2011011604532646968454460=201101160453264696845445799=10000100268=1279=1269=048=17359555=6SZ683=358740270=10215.0271=7346=51023=110=156
1128=99=25335=X49=SAMPLE75=2016101134=195752=2008020415595199057430460=200802041559519905743045799=10000100268=2279=1269=148=17359555=6SZ683=358741270=10219.0271=20346=91023=4279=1269=148=17359555=6SZ683=358742270=10220.0271=17346=81023=510=039
1128=99=18135=X49=SAMPLE75=2016101134=330252=2001112311133782390623260=200111231113378239062325799=10000100268=1279=1269=148=17359555=6SZ683=358743270=10220.0271=18346=91023=510=196
1128=99=18035=X49=SAMPLE75=2016101134=315652=2015123019420260681408060=201512301942026068140805799=10000100268=1279=1269=148=17359555=6SZ683=358744270=10216.0271=5346=51023=110=145
1128=99=25035=X49=SAMPLE75=2016101134=466352=2011051106562501479264060=201105110656250147926405799=10000100268=2279=2269=148=17360055=6SH783=99643270=10272.0271=3346=11023=1279=0269=148=17360055=6SH783=99644270=10282.0271=3346=11023=1010=082
1128=99=18135=X49=SAMPLE75=2016101134=480452=2000050106394456201697460=200005010639445620169745799=10000100268=1279=1269=148=17359555=6SZ683=358745270=10217.0271=16346=81023=210=206
1128=99=18035=X49=SAMPLE75=2016101134=101952=2012101116431109682220860=201210111643110968222085799=10000100268=1279=1269=048=17359555=6SZ683=358746270=10215.0271=6346=41023=110=164
1128=99=18035=X49=SAMPLE75=2016101134=423852=2010072922115788809318460=201007292211578880931845799=10000100268=1279=1269=048=17359555=6SZ683=358747270=10215.0271=5346=31023=110=150
1128=99=18035=X49=SAMPLE75=2016101134=82052=2009072009030128671539260=200907200903012867153925799=10000100268=1279=1269=148=17359555=6SZ683=358748270=10216.0271=6346=61023=110=156
1128=99=17935=X49=SAMPLE75=2016101134=400752=2015022711351253488268860=201502271135125348826885799=10000100268=1279=1269=048=17360055=6SH783=99645270=10268.0271=2346=11023=110=069
1128=99=32135=X49=SAMPLE75=2016101134=373352=2000051506085370254494460=200005150608537025449445799=10000100268=3279=2269=048=17360055=6SH783=99646270=10268.0271=2346=11023=1279=1269=048=17360055=6SH783=99647270=10265.0271=6346=31023=3279=0269=048=17360055=6SH783=99648270=10258.0271=53346=21023=1010=132
1128=99=17935=X49=SAMPLE75=2016101134=81052=2010121810085702571027260=201012181008570257102725799=10000100268=1279=0269=148=17360055=6SH783=99649270=10272.0271=3346=11023=110=087
